Workbook

Sheet 0. Resumen Ejecutivo
B2: CELI S.A. - DASHBOARD EJECUTIVO DE INSTALACIONES Y SERVICIOS INDUSTRIALES
B3: Proyecto Final UTN FRBA - Grupo 8 | Planta Industrial Pilar (Nave 720 m²) | Régimen: 3 Turnos (24/5) - 5.712 h/año
B5: POTENCIA INSTALADA | D5: POTENCIA DEMANDADA MÁX. | F5: CONSUMO ELÉCTRICO ANUAL | H5: POTENCIA TÉRMICA GAS
B6: ='1. Potencia Eléctrica'!L35 | D6: ='1. Potencia Eléctrica'!O35 | F6: ='1. Potencia Eléctrica'!Q35 | H6: ='3. Instalación de Gas'!H9
B7: kW | D7: kW | F7: kWh/año | H7: kcal/h
B9: CONSUMO ANUAL GAS | D9: CAUDAL AIRE COMPRIMIDO | F9: CONSUMO DIARIO AGUA | H9: PRESUPUESTO ANUAL SERVICIOS
B10: ='3. Instalación de Gas'!O9 | D10: ='4. Aire Comprimido'!C17 | F10: ='5. Agua y Saneamiento'!G18 | H10: ='6. Costos Tarifarios'!G34
B11: m³/año | D11: L/min | F11: m³/día | H11: $/año (Oficial ENRE/ENARGAS)
B13: MATRIZ CONSOLIDADA DE SERVICIOS INDUSTRIALES E INSTALACIONES
B14: Servicio / Instalación | C14: Parámetro Técnico Clave | D14: Unidad | E14: Valor Mensual | F14: Valor Anual | G14: Proveedor / Ente | H14: Costo Mensual Est. ($) | I14: Costo Anual Est. ($) | J14: Hoja de Detalle
B15: Energía Eléctrica (Fuerza Motriz) | C15: Potencia Demandada Máxima | D15: kW | E15: ='1. Potencia Eléctrica'!O35 | F15: ='1. Potencia Eléctrica'!L35 | G15: EDENOR (Tarifa T3 MT) | H15: ='6. Costos Tarifarios'!E31 | I15: ='6. Costos Tarifarios'!G31 | J15: 1. Potencia Eléctrica
B16: Sistema de Iluminación (Dec. 351/79) | C16: Artefactos LED Instalados | D16: unid. | E16: ='2. Luminarias y Lux'!T30 | F16: ='2. Luminarias y Lux'!W30 | G16: Campanas High Bay / Paneles | H16: - | I16: (Incluido en Eléctrico) | J16: 2. Luminarias y Lux
B17: Gas Natural de Red | C17: Caudal Medio Operativo | D17: m³/h | E17: ='3. Instalación de Gas'!C15 | F17: ='3. Instalación de Gas'!O9 | G17: Naturgy BAN (SGP3) | H17: ='6. Costos Tarifarios'!E32 | I17: ='6. Costos Tarifarios'!G32 | J17: 3. Instalación de Gas
B18: Aire Comprimido Industrial | C18: Caudal Libre Entregado (8 bar) | D18: L/min | E18: ='4. Aire Comprimido'!C17 | F18: ='4. Aire Comprimido'!C18*60*5712 | G18: Compresor Schulz 5.5 HP | H18: - | I18: (Incluido en Eléctrico) | J18: 4. Aire Comprimido
B19: Agua de Proceso y Saneamiento | C19: Consumo Medio de Planta | D19: m³/mes | E19: ='5. Agua y Saneamiento'!G18*22 | F19: ='5. Agua y Saneamiento'!H18 | G19: Red PIP + Cisterna 40m³ | H19: ='6. Costos Tarifarios'!E33 | I19: ='6. Costos Tarifarios'!G33 | J19: 5. Agua y Saneamiento
B20: TOTAL PRESUPUESTO ANUAL ESTIMADO DE SERVICIOS E INSTALACIONES | H20: ='6. Costos Tarifarios'!E34 | I20: ='6. Costos Tarifarios'!G34 | J20: 100% INTEGRADO

Sheet 1. Potencia Eléctrica
B2: PLANTA CELI S.A. - RELEVAMIENTO DE POTENCIA ELÉCTRICA Y CONSUMO ENERGÉTICO
B3: Relevamiento de Fuerza Motriz, Servicios Auxiliares e Iluminación | Parque Industrial Pilar | Régimen: 3 Turnos (24/5) - 5.712 h/año
B5: ID | C5: Sector / Área | D5: Línea | E5: Equipo | F5: Marca y Modelo Relevado | G5: Cant. | H5: Pot. Unit. (kW) | I5: Pot. Unit. (HP) | J5: Tensión (V) | K5: Fases / Frec. | L5: Pot. Inst. (kW) | M5: Factor Utiliz. (Fu) | N5: Factor Simult. (Fs) | O5: Pot. Dem. (kW) | P5: Hs Operat./Año | Q5: Consumo Anual (kWh/año) | R5: Fuente / Referencia Técnica
B6: LÍNEA A: GALLETITAS DULCES Y CRACKERS (PROCESO CONTINUO)
B7: 1 | C7: Amasado | D7: Línea A | E7: Amasadora rápida | F7: Catania HJ25B espiral | G7: 1 | H7: 1.5 | I7: =H7*1.3596 | J7: 220 V | K7: Monofásica 50Hz | L7: =G7*H7 | M7: 0.75 | N7: 0.85 | O7: =L7*M7*N7 | P7: 5712 | Q7: =O7*P7 | R7: Calculos vf.xlsx Hoja 'BOM y balanceo' R5
B8: 2 | C8: Moldeado | D8: Línea A | E8: Laminadora / Rotativa | F8: Ralem R800 formadora | G8: 1 | H8: 2.5 | I8: =H8*1.3596 | J8: 380 V | K8: Trifásica 50Hz | L8: =G8*H8 | M8: 0.8 | N8: 0.9 | O8: =L8*M8*N8 | P8: 5712 | Q8: =O8*P8 | R8: Calculos vf.xlsx Hoja 'BOM y balanceo' R6
B9: 3 | C9: Horneado | D9: Línea A | E9: Horno túnel continuo | F9: Polin Túnel Gas 12m (Tracción/Turbinas) | G9: 1 | H9: 52 | I9: =H9*1.3596 | J9: 380 V | K9: Trifásica 50Hz | L9: =G9*H9 | M9: 0.7 | N9: 0.95 | O9: =L9*M9*N9 | P9: 5712 | Q9: =O9*P9 | R9: Calculos vf.xlsx Hoja 'BOM y balanceo' R7
B10: 4 | C10: Enfriado | D10: Línea A | E10: Cinta de enfriamiento | F10: Golden Way Cintas modulares 7m | G10: 1 | H10: 2.2 | I10: =H10*1.3596 | J10: 380 V | K10: Trifásica 50Hz | L10: =G10*H10 | M10: 0.65 | N10: 0.9 | O10: =L10*M10*N10 | P10: 5712 | Q10: =O10*P10 | R10: Calculos vf.xlsx Hoja 'BOM y balanceo' R8
B11: 5 | C11: Empaque | D11: Línea A | E11: Envasadora Flowpack | F11: Zon Pack Flowpack horizontal servomotor | G11: 1 | H11: 6.5 | I11: =H11*1.3596 | J11: 380 V | K11: Trifásica 50Hz | L11: =G11*H11 | M11: 0.7 | N11: 0.85 | O11: =L11*M11*N11 | P11: 5712 | Q11: =O11*P11 | R11: Calculos vf.xlsx Hoja 'BOM y balanceo' R9
B12: 6 | C12: Fraccionamiento | D12: Línea A | E12: Balanza / Fraccionadora | F12: Moretti Ultra 60 macro y micro pesaje | G12: 1 | H12: 0.25 | I12: =H12*1.3596 | J12: 220 V | K12: Monofásica 50Hz | L12: =G12*H12 | M12: 0.5 | N12: 0.6 | O12: =L12*M12*N12 | P12: 5712 | Q12: =O12*P12 | R12: Calculos vf.xlsx Hoja 'BOM y balanceo' R4
B13: 7 | C13: Final de Línea | D13: Línea A | E13: Cosedora de bolsas / Cajas | F13: Fischbein D-Series cerradora bolsas | G13: 1 | H13: 0.4 | I13: =H13*1.3596 | J13: 220 V | K13: Monofásica 50Hz | L13: =G13*H13 | M13: 0.4 | N13: 0.5 | O13: =L13*M13*N13 | P13: 5712 | Q13: =O13*P13 | R13: Manual empaque secundario
B14: SUBTOTAL LÍNEA A (GALLETITAS) | G14: =SUM(G7:G13) | L14: =SUM(L7:L13) | O14: =SUM(O7:O13) | Q14: =SUM(Q7:Q13)
B15: LÍNEA B: PANIFICADOS Y BUDINES (PROCESO POR BATCH)
B16: 8 | C16: Pesado | D16: Línea B | E16: Balanza de precisión | F16: Moretti Ultra 60 macro/micro | G16: 1 | H16: 0.25 | I16: =H16*1.3596 | J16: 220 V | K16: Monofásica 50Hz | L16: =G16*H16 | M16: 0.5 | N16: 0.6 | O16: =L16*M16*N16 | P16: 5712 | Q16: =O16*P16 | R16: Calculos vf.xlsx Hoja 'BOM y balanceo' R12
B17: 9 | C17: Batido | D17: Línea B | E17: Batidora planetaria | F17: Moretti Planeta 60 industrial | G17: 1 | H17: 2.5 | I17: =H17*1.3596 | J17: 380 V | K17: Trifásica 50Hz | L17: =G17*H17 | M17: 0.7 | N17: 0.85 | O17: =L17*M17*N17 | P17: 5712 | Q17: =O17*P17 | R17: Calculos vf.xlsx Hoja 'BOM y balanceo' R13
B18: 10 | C18: Dosificado | D18: Línea B | E18: Dosificadora de tolva | F18: Indurpack G1WGD-1000 neumática/eléc | G18: 1 | H18: 0.1 | I18: =H18*1.3596 | J18: 220 V | K18: Monofásica 50Hz | L18: =G18*H18 | M18: 0.6 | N18: 0.8 | O18: =L18*M18*N18 | P18: 5712 | Q18: =O18*P18 | R18: Calculos vf.xlsx Hoja 'BOM y balanceo' R14
B19: 11 | C19: Fermentación | D19: Línea B | E19: Cámara fermentadora | F19: Nick Tech CF-240 calor/humedad | G19: 1 | H19: 1.8 | I19: =H19*1.3596 | J19: 220 V | K19: Monofásica 50Hz | L19: =G19*H19 | M19: 0.65 | N19: 0.9 | O19: =L19*M19*N19 | P19: 5712 | Q19: =O19*P19 | R19: Calculos vf.xlsx Hoja 'BOM y balanceo' R15
B20: 12 | C20: Horneado | D20: Línea B | E20: Horno rotativo a gas | F20: Pauna SIGMA rotativo carro (Horno 1) | G20: 1 | H20: 1.84 | I20: =H20*1.3596 | J20: 380 V | K20: Trifásica 50Hz | L20: =G20*H20 | M20: 0.75 | N20: 0.9 | O20: =L20*M20*N20 | P20: 5712 | Q20: =O20*P20 | R20: Calculos vf.xlsx Hoja 'BOM y balanceo' R16
B21: 13 | C21: Horneado | D21: Línea B | E21: Horno rotativo a gas | F21: Pauna SIGMA rotativo carro (Horno 2) | G21: 1 | H21: 1.84 | I21: =H21*1.3596 | J21: 380 V | K21: Trifásica 50Hz | L21: =G21*H21 | M21: 0.75 | N21: 0.9 | O21: =L21*M21*N21 | P21: 5712 | Q21: =O21*P21 | R21: Calculos vf.xlsx Hoja 'BOM y balanceo' R16
B22: 14 | C22: Desmolde/Corte | D22: Línea B | E22: Cortadora / Rebanadora | F22: Braesi FB-12 rebanadora industrial | G22: 1 | H22: 0.5 | I22: =H22*1.3596 | J22: 220 V | K22: Monofásica 50Hz | L22: =G22*H22 | M22: 0.4 | N22: 0.6 | O22: =L22*M22*N22 | P22: 5712 | Q22: =O22*P22 | R22: Calculos vf.xlsx Hoja 'BOM y balanceo' R18
B23: 15 | C23: Envasado | D23: Línea B | E23: Envasadora Flowpack | F23: Brunetti EFH700X servocontrolada | G23: 1 | H23: 3.6 | I23: =H23*1.3596 | J23: 380 V | K23: Trifásica 50Hz | L23: =G23*H23 | M23: 0.7 | N23: 0.85 | O23: =L23*M23*N23 | P23: 5712 | Q23: =O23*P23 | R23: Calculos vf.xlsx Hoja 'BOM y balanceo' R19
B24: SUBTOTAL LÍNEA B (PANIFICADOS) | G24: =SUM(G16:G23) | L24: =SUM(L16:L23) | O24: =SUM(O16:O23) | Q24: =SUM(Q16:Q23)
B25: SERVICIOS AUXILIARES, ILUMINACIÓN GENERAL E INSTALACIONES
B26: 16 | C26: Servicios | D26: Auxiliares | E26: Compresor tornillo aire | F26: Schulz SRP 4008 / Kaeser SX 6 (5,5 HP) | G26: 1 | H26: 4 | I26: =H26*1.3596 | J26: 380 V | K26: Trifásica 50Hz | L26: =G26*H26 | M26: 0.65 | N26: 0.7 | O26: =L26*M26*N26 | P26: 5712 | Q26: =O26*P26 | R26: Hoja '4. Aire Comprimido'
B27: 17 | C27: Servicios | D27: Auxiliares | E27: Secador frigorífico aire | F27: Schulz ADS 20 (+3°C rocío) | G27: 1 | H27: 0.45 | I27: =H27*1.3596 | J27: 220 V | K27: Monofásica 50Hz | L27: =G27*H27 | M27: 0.7 | N27: 0.8 | O27: =L27*M27*N27 | P27: 5712 | Q27: =O27*P27 | R27: Hoja '4. Aire Comprimido'
B28: 18 | C28: Almacén | D28: Auxiliares | E28: Cargador autoelevador | F28: HELI Cargador batería Litio 80V | G28: 1 | H28: 7.5 | I28: =H28*1.3596 | J28: 380 V | K28: Trifásica 50Hz | L28: =G28*H28 | M28: 0.6 | N28: 0.5 | O28: =L28*M28*N28 | P28: 2000 | Q28: =O28*P28 | R28: Calculos vf.xlsx Hoja 'Inversiones' R4
B29: 19 | C29: Servicios | D29: Auxiliares | E29: Bombas presurizadoras agua | F29: Rowa / Motorarg 2 HP (1 activa + 1 res) | G29: 1 | H29: 1.5 | I29: =H29*1.3596 | J29: 380 V | K29: Trifásica 50Hz | L29: =G29*H29 | M29: 0.5 | N29: 0.6 | O29: =L29*M29*N29 | P29: 5712 | Q29: =O29*P29 | R29: Hoja '5. Agua y Saneamiento'
B30: 20 | C30: Administración | D30: Auxiliares | E30: Climatización Oficinas | F30: Split Inverter Frío/Calor 4500 fg | G30: 1 | H30: 1.6 | I30: =H30*1.3596 | J30: 220 V | K30: Monofásica 50Hz | L30: =G30*H30 | M30: 0.4 | N30: 0.6 | O30: =L30*M30*N30 | P30: 2500 | Q30: =O30*P30 | R30: Confort térmico oficinas 60m²
B31: 21 | C31: Calidad | D31: Auxiliares | E31: Climatización Laboratorios | F31: Split Inverter Frío/Calor 3000 fg | G31: 1 | H31: 1.1 | I31: =H31*1.3596 | J31: 220 V | K31: Monofásica 50Hz | L31: =G31*H31 | M31: 0.5 | N31: 0.7 | O31: =L31*M31*N31 | P31: 5712 | Q31: =O31*P31 | R31: Laboratorio calidad crudo/cocido
B32: 22 | C32: Administración | D32: Auxiliares | E32: Equipos Informática y Red | F32: 8 PC + Servidor + Impresora | G32: 1 | H32: 2.5 | I32: =H32*1.3596 | J32: 220 V | K32: Monofásica 50Hz | L32: =G32*H32 | M32: 0.6 | N32: 0.7 | O32: =L32*M32*N32 | P32: 2500 | Q32: =O32*P32 | R32: Calculos vf.xlsx Hoja 'Inversiones' R10
B33: 23 | C33: Iluminación | D33: Planta | E33: Sistema Iluminación LED | F33: Luminarias nave, depósitos y oficinas | G33: 1 | H33: ='2. Luminarias y Lux'!U30 | I33: =H33*1.3596 | J33: 220 V | K33: Monofásica 50Hz | L33: =G33*H33 | M33: 1 | N33: 1 | O33: =L33*M33*N33 | P33: 5712 | Q33: =O33*P33 | R33: Hoja '2. Luminarias y Lux'
B34: SUBTOTAL SERVICIOS AUXILIARES E INSTALACIONES | G34: =SUM(G26:G33) | L34: =SUM(L26:L33) | O34: =SUM(O26:O33) | Q34: =SUM(Q26:Q33)
B35: TOTAL GENERAL PLANTA INDUSTRIAL CELI S.A. | G35: =G14+G24+G34 | L35: =L14+L24+L34 | O35: =O14+O24+O34 | Q35: =Q14+Q24+Q34
B37: PARÁMETROS ELÉCTRICOS DE DISEÑO Y DIMENSIONAMIENTO DE ACOMETIDA
B38: Potencia Total Instalada (P_inst): | C38: =L35 | D38: kW
B39: Factor de Potencia de Planta adoptado (cos φ): | C39: 0.92 | D39: -
B40: Potencia Aparente Instalada (S_inst): | C40: =C38/C39 | D40: kVA
B41: Potencia Máxima Demandada Simultánea (P_dem): | C41: =O35 | D41: kW
B42: Potencia Aparente Demandada Simultánea (S_dem): | C42: =C41/C39 | D42: kVA
B43: Capacidad de Transformador Industrial Recomendada: | C43: 100 | D43: kVA (Norma IRAM 2250)
...

Sheet 2. Luminarias y Lux
B2: PLANTA CELI S.A. - CÁLCULO LUMINOTÉCNICO Y CUMPLIMIENTO DECRETO 351/79
B3: Articulado con 'Iluminación + Matafuegos.xlsx' | Método del Flujo Luminoso para Niveles de Diseño y Protocolo Res. SRT 84/12
B5: ID | C5: Sector / Puesto | D5: Tipo de Área | E5: Largo a (m) | F5: Ancho b (m) | G5: Alto H (m) | H5: Superficie S (m²) | I5: Índice Local (IL) | J5: Puntos Med. (Res. SRT 84/12) | K5: Lux Mín. Dto. 351/79 | L5: Nivel Diseño Adoptado (lx) | M5: Coef. Utiliz. (μ) | N5: Factor Mant. (fm) | O5: Flujo Total Req. (lm) | P5: Artefacto Seleccionado | Q5: Pot. Unit. (W) | R5: Flujo Lámpara (lm) | S5: Cant. Calc. | T5: Cant. Adop. | U5: Pot. Total (kW) | V5: Hs Encendido/Año | W5: Consumo Anual (kWh/año) | X5: Nivel Medio Logrado (lx) | Y5: Cumplimiento Normativo
B6: 1 | C6: Deposito MP | D6: Almacén Materias Primas | E6: 8.3 | F6: 6.3 | G6: 6.5 | H6: =E6*F6 | I6: =(E6*F6)/(G6*(E6+F6)) | J6: =(I6+2)^2 | K6: 100 | L6: 200 | M6: 0.65 | N6: 0.8 | O6: =(L6*H6)/(M6*N6) | P6: Campana LED High Bay IP65 100W | Q6: 100 | R6: 13500 | S6: =O6/R6 | T6: =ROUNDUP(S6,0) | U6: =T6*Q6/1000 | V6: 5712 | W6: =U6*V6 | X6: =(T6*R6*M6*N6)/H6 | Y6: =IF(X6>=K6,"CUMPLE DTO 351/79","NO CUMPLE")
B7: 2 | C7: Aduana MP (recepcion y control) | D7: Control y Desinfección | E7: 3.8 | F7: 3.8 | G7: 6.5 | H7: =E7*F7 | I7: =(E7*F7)/(G7*(E7+F7)) | J7: =(I7+2)^2 | K7: 300 | L7: 500 | M7: 0.6 | N7: 0.8 | O7: =(L7*H7)/(M7*N7) | P7: Artefacto Lineal Estanco LED 2x18W | Q7: 36 | R7: 3600 | S7: =O7/R7 | T7: =ROUNDUP(S7,0) | U7: =T7*Q7/1000 | V7: 5712 | W7: =U7*V7 | X7: =(T7*R7*M7*N7)/H7 | Y7: =IF(X7>=K7,"CUMPLE DTO 351/79","NO CUMPLE")
B8: 3 | C8: Seccion Pesado (macro y micro) | D8: Pesaje y Fraccionamiento | E8: 2 | F8: 3.8 | G8: 6.5 | H8: =E8*F8 | I8: =(E8*F8)/(G8*(E8+F8)) | J8: =(I8+2)^2 | K8: 400 | L8: 500 | M8: 0.6 | N8: 0.8 | O8: =(L8*H8)/(M8*N8) | P8: Artefacto Lineal Estanco LED 2x18W | Q8: 36 | R8: 3600 | S8: =O8/R8 | T8: =ROUNDUP(S8,0) | U8: =T8*Q8/1000 | V8: 5712 | W8: =U8*V8 | X8: =(T8*R8*M8*N8)/H8 | Y8: =IF(X8>=K8,"CUMPLE DTO 351/79","NO CUMPLE")
B9: 4 | C9: Amasado | D9: Elaboración Galletitas | E9: 2.4 | F9: 2.2 | G9: 6.5 | H9: =E9*F9 | I9: =(E9*F9)/(G9*(E9+F9)) | J9: =(I9+2)^2 | K9: 200 | L9: 300 | M9: 0.6 | N9: 0.8 | O9: =(L9*H9)/(M9*N9) | P9: Artefacto Lineal Estanco LED 2x18W | Q9: 36 | R9: 3600 | S9: =O9/R9 | T9: =ROUNDUP(S9,0) | U9: =T9*Q9/1000 | V9: 5712 | W9: =U9*V9 | X9: =(T9*R9*M9*N9)/H9 | Y9: =IF(X9>=K9,"CUMPLE DTO 351/79","NO CUMPLE")
B10: 5 | C10: Moldeado | D10: Moldeo y Formado | E10: 2.5 | F10: 2.3 | G10: 6.5 | H10: =E10*F10 | I10: =(E10*F10)/(G10*(E10+F10)) | J10: =(I10+2)^2 | K10: 400 | L10: 500 | M10: 0.6 | N10: 0.8 | O10: =(L10*H10)/(M10*N10) | P10: Artefacto Lineal Estanco LED 2x18W | Q10: 36 | R10: 3600 | S10: =O10/R10 | T10: =ROUNDUP(S10,0) | U10: =T10*Q10/1000 | V10: 5712 | W10: =U10*V10 | X10: =(T10*R10*M10*N10)/H10 | Y10: =IF(X10>=K10,"CUMPLE DTO 351/79","NO CUMPLE")
B11: 6 | C11: Horno Tunel | D11: Horneado Continuo Galletitas | E11: 8.6 | F11: 2.3 | G11: 6.5 | H11: =E11*F11 | I11: =(E11*F11)/(G11*(E11+F11)) | J11: =(I11+2)^2 | K11: 300 | L11: 500 | M11: 0.6 | N11: 0.8 | O11: =(L11*H11)/(M11*N11) | P11: Campana LED High Bay IP65 100W | Q11: 100 | R11: 13500 | S11: =O11/R11 | T11: =ROUNDUP(S11,0) | U11: =T11*Q11/1000 | V11: 5712 | W11: =U11*V11 | X11: =(T11*R11*M11*N11)/H11 | Y11: =IF(X11>=K11,"CUMPLE DTO 351/79","NO CUMPLE")
B12: 7 | C12: Cinta Enfriado | D12: Enfriamiento Galletitas | E12: 7 | F12: 1.2 | G12: 6.5 | H12: =E12*F12 | I12: =(E12*F12)/(G12*(E12+F12)) | J12: =(I12+2)^2 | K12: 300 | L12: 750 | M12: 0.6 | N12: 0.8 | O12: =(L12*H12)/(M12*N12) | P12: Artefacto Lineal Estanco LED 2x18W | Q12: 36 | R12: 3600 | S12: =O12/R12 | T12: =ROUNDUP(S12,0) | U12: =T12*Q12/1000 | V12: 5712 | W12: =U12*V12 | X12: =(T12*R12*M12*N12)/H12 | Y12: =IF(X12>=K12,"CUMPLE DTO 351/79","NO CUMPLE")
B13: 8 | C13: Envasado 1 | D13: Envasado Primario Galletitas | E13: 4.3 | F13: 4 | G13: 6.5 | H13: =E13*F13 | I13: =(E13*F13)/(G13*(E13+F13)) | J13: =(I13+2)^2 | K13: 300 | L13: 500 | M13: 0.65 | N13: 0.8 | O13: =(L13*H13)/(M13*N13) | P13: Artefacto Lineal Estanco LED 2x18W | Q13: 36 | R13: 3600 | S13: =O13/R13 | T13: =ROUNDUP(S13,0) | U13: =T13*Q13/1000 | V13: 5712 | W13: =U13*V13 | X13: =(T13*R13*M13*N13)/H13 | Y13: =IF(X13>=K13,"CUMPLE DTO 351/79","NO CUMPLE")
B14: 9 | C14: Batido Panif. | D14: Batido de Masas Panificados | E14: 2.2 | F14: 1.6 | G14: 6.5 | H14: =E14*F14 | I14: =(E14*F14)/(G14*(E14+F14)) | J14: =(I14+2)^2 | K14: 400 | L14: 500 | M14: 0.6 | N14: 0.8 | O14: =(L14*H14)/(M14*N14) | P14: Artefacto Lineal Estanco LED 2x18W | Q14: 36 | R14: 3600 | S14: =O14/R14 | T14: =ROUNDUP(S14,0) | U14: =T14*Q14/1000 | V14: 5712 | W14: =U14*V14 | X14: =(T14*R14*M14*N14)/H14 | Y14: =IF(X14>=K14,"CUMPLE DTO 351/79","NO CUMPLE")
B15: 10 | C15: Dosificado | D15: Dosificación en Molde | E15: 2 | F15: 1.5 | G15: 6.5 | H15: =E15*F15 | I15: =(E15*F15)/(G15*(E15+F15)) | J15: =(I15+2)^2 | K15: 400 | L15: 500 | M15: 0.6 | N15: 0.8 | O15: =(L15*H15)/(M15*N15) | P15: Artefacto Lineal Estanco LED 2x18W | Q15: 36 | R15: 3600 | S15: =O15/R15 | T15: =ROUNDUP(S15,0) | U15: =T15*Q15/1000 | V15: 5712 | W15: =U15*V15 | X15: =(T15*R15*M15*N15)/H15 | Y15: =IF(X15>=K15,"CUMPLE DTO 351/79","NO CUMPLE")
B16: 11 | C16: Fermentador | D16: Cámara Fermentación | E16: 1.5 | F16: 1.2 | G16: 6.5 | H16: =E16*F16 | I16: =(E16*F16)/(G16*(E16+F16)) | J16: =(I16+2)^2 | K16: 100 | L16: 200 | M16: 0.6 | N16: 0.8 | O16: =(L16*H16)/(M16*N16) | P16: Plafon Downlight LED IP44 18W | Q16: 18 | R16: 1600 | S16: =O16/R16 | T16: =ROUNDUP(S16,0) | U16: =T16*Q16/1000 | V16: 5712 | W16: =U16*V16 | X16: =(T16*R16*M16*N16)/H16 | Y16: =IF(X16>=K16,"CUMPLE DTO 351/79","NO CUMPLE")
B17: 12 | C17: Hornos Rotativos | D17: Horneado Panificados | E17: 5.2 | F17: 3.7 | G17: 6.5 | H17: =E17*F17 | I17: =(E17*F17)/(G17*(E17+F17)) | J17: =(I17+2)^2 | K17: 300 | L17: 500 | M17: 0.65 | N17: 0.8 | O17: =(L17*H17)/(M17*N17) | P17: Campana LED High Bay IP65 100W | Q17: 100 | R17: 13500 | S17: =O17/R17 | T17: =ROUNDUP(S17,0) | U17: =T17*Q17/1000 | V17: 5712 | W17: =U17*V17 | X17: =(T17*R17*M17*N17)/H17 | Y17: =IF(X17>=K17,"CUMPLE DTO 351/79","NO CUMPLE")
... B29: 24 | C29: Circulaciones y Pasillos | D29: Circulación Interna | E29: 25 | F29: 2 | G29: 4 | H29: =E29*F29 | I29: =(E29*F29)/(G29*(E29+F29)) | J29: =(I29+2)^2 | K29: 100 | L29: 150 | M29: 0.5 | N29: 0.8 | O29: =(L29*H29)/(M29*N29) | P29: Artefacto Lineal Estanco LED 1x18W | Q29: 18 | R29: 1800 | S29: =O29/R29 | T29: =ROUNDUP(S29,0) | U29: =T29*Q29/1000 | V29: 5712 | W29: =U29*V29 | X29: =(T29*R29*M29*N29)/H29 | Y29: =IF(X29>=K29,"CUMPLE DTO 351/79","NO CUMPLE")
B30: TOTALES SISTEMA DE ILUMINACIÓN PLANTA CELI | H30: =SUM(H6:H29) | J30: =SUM(J6:J29) | O30: =SUM(O6:O29) | T30: =SUM(T6:T29) | U30: =SUM(U6:U29) | W30: =SUM(W6:W29) | Y30: 100% CUMPLE

Sheet 3. Instalación de Gas
B2: PLANTA CELI S.A. - RELEVAMIENTO DE GAS NATURAL DE RED Y CONSUMO TÉRMICO
B3: Gasoducto Industrial Parque Industrial Pilar | Distribuidora: Naturgy BAN S.A. | Norma NAG-200
B5: ID | C5: Equipo Consumidor | D5: Línea | E5: Ubicación | F5: Tipo Quemador | G5: Combustible | H5: Pot. Térmica (kcal/h) | I5: Pot. Térmica (kW) | J5: Rendimiento (η) | K5: P.C.S. (kcal/m³) | L5: Caudal Pico (m³/h) | M5: Hs Uso/Día | N5: Días/Año | O5: Consumo Anual (m³/año) | P5: Fuente / Referencia
B6: 1 | C6: Horno Túnel Continuo Polin | D6: Línea A Galletitas | E6: Nave Producción Sector [6] | F6: Atmosférico multigas con control mod. | G6: Gas Natural de Red | H6: 85000 | I6: =H6*0.001163 | J6: 0.88 | K6: 9300 | L6: =H6/(K6*J6) | M6: 16 | N6: 238 | O6: =L6*M6*N6 | P6: Calculos vf.xlsx Hoja 'BOM y balanceo' R7
B7: 2 | C7: Horno Rotativo Pauna SIGMA (Horno 1) | D7: Línea B Panificados | E7: Nave Producción Sector [12] | F7: Quemador presurizado automático | G7: Gas Natural de Red | H7: 70000 | I7: =H7*0.001163 | J7: 0.88 | K7: 9300 | L7: =H7/(K7*J7) | M7: 14 | N7: 238 | O7: =L7*M7*N7 | P7: Calculos vf.xlsx Hoja 'BOM y balanceo' R16
B8: 3 | C8: Horno Rotativo Pauna SIGMA (Horno 2) | D8: Línea B Panificados | E8: Nave Producción Sector [12] | F8: Quemador presurizado automático | G8: Gas Natural de Red | H8: 70000 | I8: =H8*0.001163 | J8: 0.88 | K8: 9300 | L8: =H8/(K8*J8) | M8: 14 | N8: 238 | O8: =L8*M8*N8 | P8: Calculos vf.xlsx Hoja 'BOM y balanceo' R16
B9: TOTAL CONSUMO TÉRMICO Y GAS NATURAL | H9: =SUM(H6:H8) | I9: =SUM(I6:I8) | L9: =SUM(L6:L8) | O9: =SUM(O6:O8)
B11: PARÁMETROS DE DISEÑO DE LA INSTALACIÓN INTERNA DE GAS (NAG-200)
B12: Potencia Térmica Total Instalada: | C12: =H9 | D12: kcal/h
B13: Potencia Térmica Total en kW: | C13: =I9 | D13: kW
B14: Poder Calorífico Superior del Gas (PCS): | C14: 9300 | D14: kcal/m³ (Naturgy BAN)
B15: Caudal Máximo Simultáneo de Diseño: | C15: =L9 | D15: m³/h
B16: Presión de Suministro en Red Externa (Media Presión): | C16: 1.5 | D16: bar (Red Industrial PIP)
B17: Presión de Trabajo en Quemadores Internos: | C17: 20 | D17: mbar (Baja Presión Regulada)
B18: Medidor de Gas Industrial Recomendado: | C18: Medidor rotativo G-25 (Capacidad: hasta 40 m³/h) | D18: -
B19: Diámetro Cañería Colectora Principal de Gas: | C19: 1.1/2" (Ø 40 mm) ASTM A-53 con revestimiento epoxi | D19: -

Sheet 4. Aire Comprimido
B2: PLANTA CELI S.A. - RELEVAMIENTO DE AIRE COMPRIMIDO INDUSTRIAL (ISO 8573-1)
B3: Central Compresora a Tornillo, Tratamiento Grado Alimenticio y Red Neumática de Planta
B5: ID | C5: Equipo Consumidor Neumático | D5: Línea / Proceso | E5: Sector | F5: Presión Trabajo (bar) | G5: Caudal Nom. (L/min) | H5: Caudal (m³/h) | I5: Ciclos/min | J5: Factor Simult. (Fs) | K5: Caudal Requerido (L/min) | L5: Caudal Requerido (m³/h) | M5: Tipo de Consumo / Aplicación
B6: 1 | C6: Dosificadora Indurpack G1WGD-1000 | D6: Línea B Panificados | E6: Dosificado Sector [10] | F6: 6 | G6: 140 | H6: =G6*0.06 | I6: 30 | J6: 0.85 | K6: =G6*J6 | L6: =K6*0.06 | M6: Calculos vf.xlsx Hoja 'BOM y balanceo' R14. Cilindros neumáticos.
B7: 2 | C7: Envasadora Flowpack Zon Pack | D7: Línea A Galletitas | E7: Envasado 1 Sector [8] | F7: 6 | G7: 80 | H7: =G7*0.06 | I7: 45 | J7: 0.8 | K7: =G7*J7 | L7: =K7*0.06 | M7: Calculos vf.xlsx Hoja 'BOM y balanceo' R9. Mordazas neumáticas.
B8: 3 | C8: Envasadora Flowpack Brunetti | D8: Línea B Panificados | E8: Envasado Sector [14] | F8: 6 | G8: 80 | H8: =G8*0.06 | I8: 40 | J8: 0.8 | K8: =G8*J8 | L8: =K8*0.06 | M8: Calculos vf.xlsx Hoja 'BOM y balanceo' R19. Sellado y corte.
B9: 4 | C9: Limpieza por soplado y desmolde | D9: Línea A y B | E9: Moldeado y Desmolde | F9: 6 | G9: 60 | H9: =G9*0.06 | I9: 10 | J9: 0.5 | K9: =G9*J9 | L9: =K9*0.06 | M9: Pistolas de aire con filtro sanitario para desmolde y limpieza.
B10: 5 | C10: Actuadores y válvulas neumáticas | D10: Servicios Generales | E10: Nave Producción | F10: 6 | G10: 30 | H10: =G10*0.06 | I10: 5 | J10: 0.6 | K10: =G10*J10 | L10: =K10*0.06 | M10: Válvulas de corte de proceso, dosificación de agua y vapor.
B11: SUBTOTAL CONSUMO NEUMÁTICO BASE | G11: =SUM(G6:G10) | H11: =SUM(H6:H10) | K11: =SUM(K6:K10) | L11: =SUM(L6:L10)
B13: DIMENSIONAMIENTO DE LA CENTRAL COMPRESORA Y TRATAMIENTO DE AIRE
B14: Consumo Simultáneo Base de Equipos: | C14: =K11 | D14: L/min
B15: Factor por Fugas en Red y Acoples (15%): | C15: =C14*0.15 | D15: L/min
B16: Margen de Seguridad y Ampliación Futura (20%): | C16: =(C14+C15)*0.20 | D16: L/min
B17: Caudal Total Requerido de Central Compresora: | C17: =C14+C15+C16 | D17: L/min
B18: Caudal Requerido en m³/h: | C18: =C17*0.06 | D18: m³/h
B19: Presión de Trabajo Efectiva de Red: | C19: 8 | D19: bar (Manométrica)
B20: Compresor Industrial Seleccionado: | C20: Compresor de tornillo rotativo Schulz SRP 4008 (5,5 HP / 4,0 kW) | D20: -
B21: Caudal Libre Entregado (FAD) del Compresor: | C21: 580 | D21: L/min a 8 bar (opera al 69% de factor de carga)
B22: Tanque Acumulador / Pulmón Requerido: | C22: 300 | D22: Litros (Vertical, con válvula de seguridad y purga)
B23: Calidad de Aire Alimentario (Norma ISO 8573-1): | C23: Clase 1.4.1 (Filtro 0.01 µm + Secador frigorífico rocío +3°C) | D23: -

Sheet 5. Agua y Saneamiento
B2: PLANTA CELI S.A. - BALANCE HÍDRICO, AGUA DE PROCESO Y SANEAMIENTO
B3: Consumo de Receta (BOM), Limpieza BPM Libre de Gluten, Dotación Sanitaria y Cisterna
B4: 1. CONSUMO DE AGUA DE PROCESO COMO MATERIA PRIMA (RECETA BOM)
B5: Línea de Producto | C5: Producción Anual (kg) | D5: Agua en Receta (%) | E5: Agua Requerida (kg/año) | F5: Agua Requerida (m³/año) | G5: Fuente BOM
B6: Pan de Molde Blanco Sin TACC | C6: 117855.9 | D6: 0.38 | E6: =C6*D6 | F6: =E6/1000 | G6: Calculos vf.xlsx Hoja 'Produccion' R50 (Año 10) y 'BOM' (38% agua receta)
B7: Budines Tradicionales Sin TACC | C7: 141427.2 | D7: 0.11 | E7: =C7*D7 | F7: =E7/1000 | G7: Calculos vf.xlsx Hoja 'Produccion' R51 (Año 10) y 'BOM' (11% agua receta)
B8: Budines Frutos Secos / Free Sin TACC | C8: 60611.6 | D8: 0.1 | E8: =C8*D8 | F8: =E8/1000 | G8: Calculos vf.xlsx Hoja 'Produccion' R52 (Año 10) y 'BOM' (10% agua receta)
B9: Galletitas Dulces y Saladas Sin TACC | C9: 358619.2 | D9: 0.07 | E9: =C9*D9 | F9: =E9/1000 | G9: Calculos vf.xlsx Hoja 'Produccion' R42:R49 (Año 10) y 'BOM' (7% agua receta)
B10: SUBTOTAL AGUA DE PROCESO (RECETA) | C10: =SUM(C6:C9) | E10: =SUM(E6:E9) | F10: =SUM(F6:F9) | G10: Consumo directo en mezclado y amasado
B12: 2. BALANCE TOTAL DE AGUA DIARIO Y ANUAL DE PLANTA (PROCESO + BPM + SANITARIO)
B13: Destino / Uso del Agua | C13: Criterio Técnico / Base de Cálculo | D13: Dotación Unitaria | E13: Unidades | F13: Consumo Diario (L/día) | G13: Consumo Diario (m³/día) | H13: Consumo Anual (m³/año)
B14: Agua de Proceso en Recetas | C14: Promedio diario sobre 238 días de producción activa | D14: =F10*1000/238 | E14: L/día | F14: =D14 | G14: =F14/1000 | H14: =G14*238
B15: Limpieza y Sanitización BPM Sin TACC | C15: Lavado CIP de tolvas, líneas, carros, bandejas y pisos | D15: 1800 | E15: L/día | F15: =D15 | G15: =F15/1000 | H15: =G15*238
B16: Consumo Sanitario del Personal | C16: Dotación reglamentaria OSN / Dto. 351/79: 45 L/persona-día | D16: 45 | E16: 55 personas | F16: =D16*55 | G16: =F16/1000 | H16: =G16*238
B17: Servicios Auxiliares y Mantenimiento | C17: Riego, purgas y limpieza externa | D17: 475 | E17: L/día | F17: =D17 | G17: =F17/1000 | H17: =G17*238
B18: TOTAL CONSUMO MEDIO DE AGUA PLANTA CELI S.A. | F18: =SUM(F14:F17) | G18: =SUM(G14:G17) | H18: =SUM(H14:H17)
B20: DIMENSIONAMIENTO DE RESERVA HÍDRICA Y CISTERNA DE PLANTA
B21: Consumo Diario Medio de Planta: | C21: =G18 | D21: m³/día
B22: Días de Autonomía de Consumo Requeridos: | C22: 2 | D22: Días de producción continua
B23: Reserva Técnica de Proceso y Sanitaria: | C23: =C21*C22 | D23: m³ (10.000 Litros)
B24: Reserva Técnica Contra Incendio Reglamentaria (Dec. 351/79): | C24: 30 | D24: m³ (2 hidrantes x 250 L/min x 60 min)
B25: Capacidad Total Recomendada de Cisterna Unificada: | C25: =C23+C24 | D25: m³ (40.000 Litros)
B26: Sistema de Bombeo Presurizado: | C26: 2 electrobombas centrífugas 2 HP (1 activa + 1 reserva) | D26: -
B27: Tratamiento de Agua de Red Requerido: | C27: Filtro de sedimentos 5 µm + Carbón activado + Cloración en línea | D27: -

Sheet 6. Costos Tarifarios
B2: PLANTA CELI S.A. - CUADROS TARIFARIOS Y COSTOS DE SERVICIOS INDUSTRIALES
B3: Tarifas Vigentes en Parque Industrial Pilar (EDENOR T3 MT y Naturgy BAN SGP3) | Enlaces Oficiales ENRE y ENARGAS
B5: 1. ENERGÍA ELÉCTRICA - EDENOR S.A. (TARIFA T3 GRAN DEMANDA - MEDIA TENSIÓN)
B6: Marco Regulatorio: ENRE (Resoluciones Cuadros Tarifarios Edenor) | Enlace Oficial: https://www.argentina.gob.ar/enre/tarifas/cuadros-tarifarios-edenor
B7: Concepto de Facturación | C7: Unidad | D7: Tarifa Unitaria ($) | E7: Consumo Base Mensual | F7: Costo Mensual ($) | G7: Costo Anual ($) | H7: Observaciones y Fuente
B8: Cargo Fijo Mensual | C8: $/mes | D8: 91428.31 | E8: 1 | F8: =D8*E8 | G8: =F8*12 | H8: Cargo fijo comercial reglamentario ENRE T3 MT
B9: Cargo por Potencia Contratada | C9: $/kW-mes | D9: 4557.97 | E9: ='1. Potencia Eléctrica'!O35 | F9: =D9*E9 | G9: =F9*12 | H9: Facturación sobre Potencia Demandada Máxima (65,4 kW)
B10: Cargo por Potencia Adquirida | C10: $/kW-mes | D10: 3053.31 | E10: ='1. Potencia Eléctrica'!O35 | F10: =D10*E10 | G10: =F10*12 | H10: Cargo por capacidad de transporte y compra en MEM
B11: Energía Activa - Horas Pico (18:00 a 23:00) | C11: $/kWh | D11: 70.02 | E11: =('1. Potencia Eléctrica'!Q35/12)*0.35 | F11: =D11*E11 | G11: =F11*12 | H11: 35% del consumo en banda pico (alta exigencia del sistema)
B12: Energía Activa - Horas Resto (05:00 a 18:00) | C12: $/kWh | D12: 67.68 | E12: =('1. Potencia Eléctrica'!Q35/12)*0.45 | F12: =D12*E12 | G12: =F12*12 | H12: 45% del consumo en banda resto (jornada diurna continua)
B13: Energía Activa - Horas Valle (23:00 a 05:00) | C13: $/kWh | D13: 66.34 | E13: =('1. Potencia Eléctrica'!Q35/12)*0.20 | F13: =D13*E13 | G13: =F13*12 | H13: 20% del consumo en banda valle nocturna (tarifa reducida)
B14: SUBTOTAL SERVICIO ELÉCTRICO EDENOR S.A. | F14: =SUM(F8:F13) | G14: =SUM(G8:G13) | H14: Factura eléctrica mensual media estimada (sin impuestos)
B16: 2. GAS NATURAL DE RED - NATURGY BAN S.A. (TARIFA SGP3 INDUSTRIAL)
B17: Marco Regulatorio: ENARGAS (Cuadros Tarifarios Distribución) | Enlace Oficial: https://www.enargas.gob.ar/secciones/tarifas/cuadros-tarifarios.php
B18: Concepto de Facturación | C18: Unidad | D18: Tarifa Unitaria ($) | E18: Consumo Base Mensual | F18: Costo Mensual ($) | G18: Costo Anual ($) | H18: Observaciones y Fuente
B19: Cargo Fijo Mensual Comercial | C19: $/mes | D19: 45850 | E19: 1 | F19: =D19*E19 | G19: =F19*12 | H19: Cargo fijo reglamentario ENARGAS para usuarios SGP3
B20: Cargo por m³ Consumido | C20: $/m³ | D20: 215 | E20: ='3. Instalación de Gas'!O9/12 | F20: =D20*E20 | G20: =F20*12 | H20: Caudal mensual medio de hornos (7.515 m³/mes)
B21: SUBTOTAL SERVICIO GAS NATURGY BAN | F21: =SUM(F19:F20) | G21: =SUM(G19:G20) | H21: Factura mensual media de gas natural estimada
B23: 3. PROVISIÓN DE AGUA Y SERVICIOS SANITARIOS - PARQUE INDUSTRIAL PILAR
B24: Proveedor: Consorcio Parque Industrial Pilar | Web Oficial: http://www.parqueindustrialpilar.org/
B25: Concepto de Facturación | C25: Unidad | D25: Tarifa Unitaria ($) | E25: Consumo Base Mensual | F25: Costo Mensual ($) | G25: Costo Anual ($) | H25: Observaciones y Fuente
B26: Abono Red de Agua Industrial y Control Hídrico | C26: $/mes | D26: 450000 | E26: 1 | F26: =D26*E26 | G26: =F26*12 | H26: Canon mensual red PIP, cloración y controles bacteriológicos
B27: SUBTOTAL PROVISIÓN DE AGUA Y SANEAMIENTO | F27: =F26 | G27: =G26 | H27: Costo mensual de provisión hídrica y control sanitario
B29: 4. RESUMEN CONSOLIDADO DE COSTOS DE SERVICIOS E INSTALACIONES
B30: Servicio / Suministro | C30: Proveedor / Ente Regulador | D30: Enlace Oficial Web | E30: Costo Mensual ($) | F30: % Costo Mensual | G30: Costo Anual ($) | H30: % Costo Anual | I30: Impacto Operativo
B31: Energía Eléctrica (Fuerza Motriz + Iluminación + Auxiliares) | C31: EDENOR S.A. / ENRE | D31: https://www.argentina.gob.ar/enre/tarifas/cuadros-tarifarios-edenor | E31: =F14 | F31: =E31/$E$34 | G31: =G14 | H31: =G31/$G$34 | I31: Costo Operativo Directo/Indirecto
B32: Gas Natural de Red (Hornos Túnel y Rotativos) | C32: Naturgy BAN S.A. / ENARGAS | D32: https://www.enargas.gob.ar/secciones/tarifas/cuadros-tarifarios.php | E32: =F21 | F32: =E32/$E$34 | G32: =G21 | H32: =G32/$G$34 | I32: Costo Operativo de Horneado
B33: Provisión de Agua y Mantenimiento Hídrico | C33: Consorcio Parque Industrial Pilar | D33: http://www.parqueindustrialpilar.org/ | E33: =F27 | F33: =E33/$E$34 | G33: =G27 | H33: =G33/$G$34 | I33: Costo Operativo Sanitario/BPM
B34: TOTAL PRESUPUESTO ANUAL DE SERVICIOS E INSTALACIONES | E34: =SUM(E31:E33) | F34: =SUM(F31:F33) | G34: =SUM(G31:G33) | H34: =SUM(H31:H33) | I34: Costo consolidado para Hoja 'Costos' y Flujo
