Workbook

Sheet DATOS Iniciales y ACLARACIONES
A1: ESTA SOLAPA NO DEBE IMPRIMIRSE
A2: Como Referencia, se usa la siguiente configuración de Referencia:
B4: Las casillas en Amarillo son para Completar datos Numéricos
B5: Las casillas Grises son de Fórmulas.Si bien en reglas generales están correctas, puede llegar a ser modificadas
B6: Las casillas en Verde son Datos Cualitativos. | O6: =1.04^10-1 -> 0.48024428
B7: Las celdas cruzadas no deben completarse | Q7: Base | R7: 0.0527
B8: Los Rubros de Activos Fijos y Costos son generales y DEBEN ser modificados de manera de reflejar los del proyecto Propio | Q8: Crecimiento | R8: 0.005
B9: Demostrar los datos de Inversiones y Costos | Q9: Años | R9: 5
A11: Datos de Referencias: Se agregan los más comunes, se recomienda agregar más para usarlos con referencias | R11: =R7+R8*R9 -> 0.0777
A14: Fecha del Proyecto | B14: 46154
A15: IVA Gastos | B15: 0.21 | C15: General
B16: 0.105 | C16: Tasa Reducida (Maquinas y Alimentos)
B17: 0.27 | C17: Servicios
A18: IVA Ventas | B18: 0.21 | C18: Si se brindan algunos productos o servicios con tasas diferenciales, colocar el promedio ponderado o hacer tabla auxiliar
A19: Imp. A las Ganancias*1 | B19: 0.35 | C19: Tasa General
A20: Hon.al Directorio*2*3 | B20: 0.05 | C20: VARIABLE | D20: ajusto Mateo
A21: Tipos de Cambios | B21: 1400 | C21: $ por USD
C22: $ por Euro
A24: % Imprevistos | B24: 0.05 | C24: Sobre Inversiones
B25: 0.03 | C25: Sobre Costos
A27: Alicuota de Prorrateo de Gastos Indirectos
B28: Principal | C28: Alt1 | D28: Alt2
A29: Area de Producción | B29: 0.4 | C29: 0.95 | D29: 0.95
A30: Area Administrativa | B30: 0.4 | C30: 0.03 | D30: 0.03
A31: Area Comercial | B31: =IF((1-B30-B29)>0,(1-B30-B29), "ERROR") -> 0.2 | C31: =IF((1-C30-C29)>0,(1-C30-C29), "ERROR") -> 0.02 | D31: =IF((1-D30-D29)>0,(1-D30-D29), "ERROR") -> 0.02
A33: *1 En Argentina existen distintas escalas para Pequeñas y Medianas Empresas. Verificar estas escalas al momento de llenar esta información
A34: *2 Solo aplicable a Sociedades Anónimas. En caso de ser SRL o SAS, colocar valor 0 (Cero)
A35: *3 Colocar FIJO o VARIABLE en la Segunda Casilla. En el primer caso poner el valor Anual si es fijo, o el Porcentaje si es Variable
A37: Información de Dimensionamiento Físico
A39: Bienes de Cambio | C39: Año 0 | D39: Año 1 | E39: Año 2 | F39: Año 3 | G39: Año 4 | H39: Año 5 | I39: Año 6 | J39: Año 7 | K39: Año 8 | L39: Año 9 | M39: Año 10
A40: Stock MP | B40: Ueq PT al fin Ej.
A41: Stock MCySE | B41: Ueq PT al fin Ej.
A42: Stock PT | B42: Ueq PT al fin Ej.
A43: Créditos por Ventas | B43: días Prom Pond | D43: 180 | E43: 120 | F43: 90 | G43: 80 | H43: 70 | I43: 60 | J43: 50 | K43: 50 | L43: 100 | M43: 180
A44: Unidades Producción | B44: Totales Ueq | D44: 4139 | E44: 4730 | F44: 4926 | G44: 5136 | H44: 5381 | I44: 5635 | J44: 5905 | K44: 6184 | L44: 6475 | M44: 6780
A45: Ventas | B45: Totales Ueq | D45: 4139 | E45: 4730 | F45: 4926 | G45: 5136 | H45: 5381 | I45: 5635 | J45: 5905 | K45: 6184 | L45: 6475 | M45: 6780
A47: Min. en Caja y Bancos | B47: 0.02 | C47: Ventas Año 1
A55: COMO MODELIZAR
A56: VER COMO AFECTA EL IIGG en el CASHFLOW, VER SI HACER UN CUADRO DIFERENCIADO TIPO EL IVA

Sheet Inv AF
A2: Inversión en Activo Fijo | B2: Plazo Amort. | C2: IVA | D2: Año 0 | E2: Año 1 | F2: Año 2 | G2: Año 3 | H2: Año 4 | I2: Año 5 | J2: Año 6 | K2: Año 7 | L2: Año 8 | M2: Año 9 | N2: Año 10
A3: a) Bienes de Uso
A4: Terreno y Mejoras | B4: 0 | C4: 0 | D4: 1224000000
A5: Edificios y Obras Complementarias | B5: 30 | C5: ='DATOS Iniciales y ACLARACIONES'!B15 -> 0.21 | D5: 186000000
A6: Infraestructura en predio propio | B6: 30 | C6: ='DATOS Iniciales y ACLARACIONES'!B15 -> 0.21
A7: Instalaciones industriales | B7: 10 | C7: ='DATOS Iniciales y ACLARACIONES'!B16 -> 0.105
A8: Máquinas operativas Importadas | B8: 10 | C8: ='DATOS Iniciales y ACLARACIONES'!B16 -> 0.105 | D8: 337000000
A9: Gastos Conexos de Importación | B9: 10 | C9: ='DATOS Iniciales y ACLARACIONES'!B16 -> 0.105
A10: Maquinas Operativas Nacionales | B10: 10 | C10: ='DATOS Iniciales y ACLARACIONES'!B16 -> 0.105
A11: Transporte y montaje de la maquinaria: | B11: 10 | C11: ='DATOS Iniciales y ACLARACIONES'!$B$15 -> 0.21
A12: Repuestos Iniciales | B12: 3 | C12: ='DATOS Iniciales y ACLARACIONES'!$B$15 -> 0.21
A13: Rodados | B13: 5 | C13: ='DATOS Iniciales y ACLARACIONES'!$B$15 -> 0.21 | D13: 22000000
A14: Equipos Auxiliares de Fabricación | B14: 5 | C14: ='DATOS Iniciales y ACLARACIONES'!$B$15 -> 0.21
A15: Equipos Auxiliares de Logística | B15: 5 | C15: ='DATOS Iniciales y ACLARACIONES'!$B$15 -> 0.21
A16: Muebles y Herramental Operativo | B16: 5 | C16: ='DATOS Iniciales y ACLARACIONES'!$B$15 -> 0.21 | D16: 10000000
A17: Equipamiento e Instalac. Sistemas | B17: 5 | C17: ='DATOS Iniciales y ACLARACIONES'!$B$15 -> 0.21
A18: Muebles y Útiles Administrativos | B18: 5 | C18: ='DATOS Iniciales y ACLARACIONES'!$B$15 -> 0.21
A19: Otros 1 | B19: 5 | C19: ='DATOS Iniciales y ACLARACIONES'!$B$15 -> 0.21
A20: Otros 2 | B20: 5 | C20: ='DATOS Iniciales y ACLARACIONES'!$B$15 -> 0.21
A21: Otros3 | B21: 5 | C21: ='DATOS Iniciales y ACLARACIONES'!$B$15 -> 0.21
A22: Imprevistos | B22: 5 | C22: ='DATOS Iniciales y ACLARACIONES'!$B$15 -> 0.21 | D22: =SUM(D4:D21)*'DATOS Iniciales y ACLARACIONES'!$B$24 -> 88950000 | E22: =SUM(E4:E21)*'DATOS Iniciales y ACLARACIONES'!$B$24 -> 0 | F22: =SUM(F4:F21)*'DATOS Iniciales y ACLARACIONES'!$B$24 -> 0 | G22: =SUM(G4:G21)*'DATOS Iniciales y ACLARACIONES'!$B$24 -> 0 | H22: =SUM(H4:H21)*'DATOS Iniciales y ACLARACIONES'!$B$24 -> 0 | I22: =SUM(I4:I21)*'DATOS Iniciales y ACLARACIONES'!$B$24 -> 0 | J22: =SUM(J4:J21)*'DATOS Iniciales y ACLARACIONES'!$B$24 -> 0 | K22: =SUM(K4:K21)*'DATOS Iniciales y ACLARACIONES'!$B$24 -> 0 | ... N22: =SUM(N4:N21)*'DATOS Iniciales y ACLARACIONES'!$B$24 -> 0
A23: Total Bienes de uso: | D23: =SUM(D4:D22) -> 1867950000 | E23: =SUM(E4:E22) -> 0 | F23: =SUM(F4:F22) -> 0 | G23: =SUM(G4:G22) -> 0 | H23: =SUM(H4:H22) -> 0 | I23: =SUM(I4:I22) -> 0 | J23: =SUM(J4:J22) -> 0 | K23: =SUM(K4:K22) -> 0 | ... N23: =SUM(N4:N22) -> 0
A25: b) Gastos asimilables
A26: Investigaciones y estudios | B26: 5 | C26: ='DATOS Iniciales y ACLARACIONES'!$B$15 -> 0.21
A27: Constitución y Org.de la empresa | B27: 5 | C27: ='DATOS Iniciales y ACLARACIONES'!$B$15 -> 0.21
A28: Adm.e Ing. en Período de Instalación | B28: 5 | C28: ='DATOS Iniciales y ACLARACIONES'!$B$15 -> 0.21
A29: Gastos de puesta en marcha: | B29: 5 | C29: ='DATOS Iniciales y ACLARACIONES'!$B$15 -> 0.21
A30: Patentes y Licencias: | B30: 5 | C30: ='DATOS Iniciales y ACLARACIONES'!$B$15 -> 0.21
A31: Promocion y Publicidad Preoperativas | B31: 5 | C31: ='DATOS Iniciales y ACLARACIONES'!$B$15 -> 0.21
A32: Infraestructura en predio ajeno | B32: 5 | C32: ='DATOS Iniciales y ACLARACIONES'!$B$15 -> 0.21
A33: Intereses y Gastos Preoperativos | B33: 3 | C33: 0.21
A34: Imprevistos: | B34: 5 | C34: ='DATOS Iniciales y ACLARACIONES'!$B$15 -> 0.21 | D34: =SUM(D26:D32)*'DATOS Iniciales y ACLARACIONES'!$B$24 -> 0 | E34: =SUM(E26:E32)*'DATOS Iniciales y ACLARACIONES'!$B$24 -> 0 | F34: =SUM(F26:F32)*'DATOS Iniciales y ACLARACIONES'!$B$24 -> 0 | G34: =SUM(G26:G32)*'DATOS Iniciales y ACLARACIONES'!$B$24 -> 0 | H34: =SUM(H26:H32)*'DATOS Iniciales y ACLARACIONES'!$B$24 -> 0 | I34: =SUM(I26:I32)*'DATOS Iniciales y ACLARACIONES'!$B$24 -> 0 | J34: =SUM(J26:J32)*'DATOS Iniciales y ACLARACIONES'!$B$24 -> 0 | K34: =SUM(K26:K32)*'DATOS Iniciales y ACLARACIONES'!$B$24 -> 0 | ... N34: =SUM(N26:N32)*'DATOS Iniciales y ACLARACIONES'!$B$24 -> 0
A35: Total gastos asimilables | D35: =SUM(D26:D34) -> 0 | E35: =SUM(E26:E34) -> 0 | F35: =SUM(F26:F34) -> 0 | G35: =SUM(G26:G34) -> 0 | H35: =SUM(H26:H34) -> 0 | I35: =SUM(I26:I34) -> 0 | J35: =SUM(J26:J34) -> 0 | K35: =SUM(K26:K34) -> 0 | ... N35: =SUM(N26:N34) -> 0
A37: c) Total Inversión sin IVA | D37: =+D23+D35 -> 1867950000 | E37: =+E23+E35 -> 0 | F37: =+F23+F35 -> 0 | G37: =+G23+G35 -> 0 | H37: =+H23+H35 -> 0 | I37: =+I23+I35 -> 0 | J37: =+J23+J35 -> 0 | K37: =+K23+K35 -> 0 | ... N37: =+N23+N35 -> 0
A39: d) IVA | D39: =SUMPRODUCT($C$4:$C$22,D4:D22)+SUMPRODUCT($C$26:$C$34,D26:D34) -> 99844500 | E39: =SUMPRODUCT($C$4:$C$22,E4:E22)+SUMPRODUCT($C$26:$C$34,E26:E34) -> 0 | F39: =SUMPRODUCT($C$4:$C$22,F4:F22)+SUMPRODUCT($C$26:$C$34,F26:F34) -> 0 | G39: =SUMPRODUCT($C$4:$C$22,G4:G22)+SUMPRODUCT($C$26:$C$34,G26:G34) -> 0 | H39: =SUMPRODUCT($C$4:$C$22,H4:H22)+SUMPRODUCT($C$26:$C$34,H26:H34) -> 0 | I39: =SUMPRODUCT($C$4:$C$22,I4:I22)+SUMPRODUCT($C$26:$C$34,I26:I34) -> 0 | J39: =SUMPRODUCT($C$4:$C$22,J4:J22)+SUMPRODUCT($C$26:$C$34,J26:J34) -> 0 | K39: =SUMPRODUCT($C$4:$C$22,K4:K22)+SUMPRODUCT($C$26:$C$34,K26:K34) -> 0 | ... N39: =SUMPRODUCT($C$4:$C$22,N4:N22)+SUMPRODUCT($C$26:$C$34,N26:N34) -> 0
A41: e) TOTAL INV. ACTIVO FIJO | D41: =+D37+D39 -> 1967794500 | E41: =+E37+E39 -> 0 | F41: =+F37+F39 -> 0 | G41: =+G37+G39 -> 0 | H41: =+H37+H39 -> 0 | I41: =+I37+I39 -> 0 | J41: =+J37+J39 -> 0 | K41: =+K37+K39 -> 0 | ... N41: =+N37+N39 -> 0
D44: Inversión Inicial | E44: Alícuotas de amortización
A45: Rubro | D45: Año 0 y 1 | E45: Año 1 | F45: Año 2 | G45: Año 3 | H45: Año 4 | I45: Año 5 | J45: Año 6 | K45: Año 7 | L45: Año 8 | M45: Año 9 | N45: Año 10 | O45: V. Resid
A46: a) Bienes de Uso
A47: Terreno y Mejoras | B47: 0 | D47: =D4+E4 -> 1224000000 | E47: =(E4+D4)*$B47 -> 0 | F47: =SUM(D4:F4)*$B47 -> 0 | G47: =SUM(D4:G4)*$B47 -> 0 | H47: =SUM(D4:H4)*$B47 -> 0 | I47: =SUM($D4:I4)*$B47 -> 0 | J47: =SUM($D4:J4)*$B47 -> 0 | K47: =SUM($D4:K4)*$B47 -> 0 | L47: =SUM($D4:L4)*$B47 -> 0 | M47: =SUM($D4:M4)*$B47 -> 0 | N47: =SUM($D4:N4)*$B47 -> 0 | O47: =SUM(D4:N4)-SUM(E47:N47) -> 1224000000
...

Sheet InvAT
A1: INVERSIONES EN ACTIVO DE TRABAJO
A2: Rubros | B2: Año 0 | C2: Año 1 | D2: Año 2 | E2: Año 3 | F2: Año 4 | G2: Año 5 | H2: Año 6 | I2: Año 7 | J2: Año 8 | K2: Año 9 | L2: Año 10
A3: 1. Activo de Trabajo: (valor contable)
A4: a) Disponibilidad Mínima en Caja y Bancos: | B4: ='CTV y CResult'!$B$13*'DATOS Iniciales y ACLARACIONES'!$B$47 -> 79464000 | C4: =B4 -> 79464000 | D4: =C4 -> 79464000 | E4: =D4 -> 79464000 | F4: =E4 -> 79464000 | G4: =F4 -> 79464000 | H4: =G4 -> 79464000 | I4: =H4 -> 79464000 | J4: =I4 -> 79464000 | ... L4: =K4 -> 79464000
A5: b) Crédito por Ventas | B5: 0 | C5: ='CTV y CResult'!B13*'DATOS Iniciales y ACLARACIONES'!D43/365 -> 1959386301 | D5: ='CTV y CResult'!C13*'DATOS Iniciales y ACLARACIONES'!E43/365 -> 1492668493 | E5: ='CTV y CResult'!D13*'DATOS Iniciales y ACLARACIONES'!F43/365 -> 1166104110 | F5: ='CTV y CResult'!E13*'DATOS Iniciales y ACLARACIONES'!G43/365 -> 1081183562 | G5: ='CTV y CResult'!F13*'DATOS Iniciales y ACLARACIONES'!H43/365 -> 9.9114247e+08 | H5: ='CTV y CResult'!G13*'DATOS Iniciales y ACLARACIONES'!I43/365 -> 8.8959452e+08 | I5: ='CTV y CResult'!H13*'DATOS Iniciales y ACLARACIONES'!J43/365 -> 7.7671233e+08 | J5: ='CTV y CResult'!I13*'DATOS Iniciales y ACLARACIONES'!K43/365 -> 8.1353425e+08 | ... L5: ='CTV y CResult'!K13*'DATOS Iniciales y ACLARACIONES'!M43/365 -> 3211446575
A7: c) Bienes de cambio: | B7: =SUM(B8:B11) -> 0 | C7: =SUM(C8:C11) -> 0 | D7: =SUM(D8:D11) -> 0 | E7: =SUM(E8:E11) -> 0 | F7: =SUM(F8:F11) -> 0 | G7: =SUM(G8:G11) -> 0 | H7: =SUM(H8:H11) -> 0 | I7: =SUM(I8:I11) -> 0 | ... L7: =SUM(L8:L11) -> 0
A8: Stock de materias prima:
A9: Stock de materiales:
A10: Mercadería en curso y semielaborada | B10: 0 | C10: =CostoPROD!B40 -> 0 | D10: =CostoPROD!C40 -> 0 | E10: =CostoPROD!D40 -> 0 | F10: =CostoPROD!E40 -> 0 | G10: =CostoPROD!F40 -> 0 | H10: =CostoPROD!G40 -> 0 | I10: =CostoPROD!H40 -> 0 | J10: =CostoPROD!I40 -> 0 | ... L10: =CostoPROD!K40 -> 0
A11: Stock de elaborados | B11: 0 | C11: ='CTV y CResult'!B25 -> 0 | D11: ='CTV y CResult'!C25 -> 0 | E11: ='CTV y CResult'!D25 -> 0 | F11: ='CTV y CResult'!E25 -> 0 | G11: ='CTV y CResult'!F25 -> 0 | H11: ='CTV y CResult'!G25 -> 0 | I11: ='CTV y CResult'!H25 -> 0 | J11: ='CTV y CResult'!I25 -> 0 | ... L11: ='CTV y CResult'!K25 -> 0
A13: d) Total Activo de Trabajo, sin IVA: | B13: =SUM(B4:B7) -> 79464000 | C13: =SUM(C4:C7) -> 2038850301 | D13: =SUM(D4:D7) -> 1572132493 | E13: =SUM(E4:E7) -> 1245568110 | F13: =SUM(F4:F7) -> 1160647562 | G13: =SUM(G4:G7) -> 1070606466 | H13: =SUM(H4:H7) -> 9.6905852e+08 | I13: =SUM(I4:I7) -> 8.5617633e+08 | ... L13: =SUM(L4:L7) -> 3290910575
A14: 2. Menos:
A15: Amortizaciones en Mercadería en proceso | B15: 0 | C15: =CostoPROD!B28 -> 0 | D15: =CostoPROD!C28 -> 0 | E15: =CostoPROD!D28 -> 0 | F15: =CostoPROD!E28 -> 0 | G15: =CostoPROD!F28 -> 0 | H15: =CostoPROD!G28 -> 0 | I15: =CostoPROD!H28 -> 0 | J15: =CostoPROD!I28 -> 0 | ... L15: =CostoPROD!K28 -> 0
A16: Amortizaciones en Stock de elaborado | B16: 0 | C16: =(CostoPROD!B6-C15)/CostoPROD!B49*InvAT!C11 -> 0 | D16: =(CostoPROD!C6-D15)/CostoPROD!C49*InvAT!D11 -> 0 | E16: =(CostoPROD!D6-E15)/CostoPROD!D49*InvAT!E11 -> 0 | F16: =(CostoPROD!E6-F15)/CostoPROD!E49*InvAT!F11 -> 0 | G16: =(CostoPROD!F6-G15)/CostoPROD!F49*InvAT!G11 -> 0 | H16: =(CostoPROD!G6-H15)/CostoPROD!G49*InvAT!H11 -> 0 | I16: =(CostoPROD!H6-I15)/CostoPROD!H49*InvAT!I11 -> 0 | J16: =(CostoPROD!I6-J15)/CostoPROD!I49*InvAT!J11 -> 0 | ... L16: =(CostoPROD!K6-L15)/CostoPROD!K49*InvAT!L11 -> 0
A17: Utilidades en Crédito por ventas | B17: 0 | C17: ='CTV y CResult'!B41*InvAT!C5 -> 1.9969549e+08 | D17: ='CTV y CResult'!C41*InvAT!D5 -> 233109505 | E17: ='CTV y CResult'!D41*InvAT!E5 -> 1.9916323e+08 | F17: ='CTV y CResult'!E41*InvAT!F5 -> 2.003438e+08 | G17: ='CTV y CResult'!F41*InvAT!G5 -> 1.9885095e+08 | H17: ='CTV y CResult'!G41*InvAT!H5 -> 1.938792e+08 | I17: ='CTV y CResult'!H41*InvAT!I5 -> 1.8003989e+08 | J17: ='CTV y CResult'!I41*InvAT!J5 -> 1.9926448e+08 | ... L17: ='CTV y CResult'!K41*InvAT!L5 -> 864960880
A18: Amortizaciones en Crédito por ventas | B18: 0 | C18: =('Inv AF'!E80-InvAT!C15-InvAT!C16)/'CTV y CResult'!B13*C5 -> 31606027 | D18: =('Inv AF'!F80-InvAT!D15-InvAT!D16)/'CTV y CResult'!C13*D5 -> 21070685 | E18: =('Inv AF'!G80-InvAT!E15-InvAT!E16)/'CTV y CResult'!D13*E5 -> 15803014 | F18: =('Inv AF'!H80-InvAT!F15-InvAT!F16)/'CTV y CResult'!E13*F5 -> 14047123 | G18: =('Inv AF'!I80-InvAT!G15-InvAT!G16)/'CTV y CResult'!F13*G5 -> 12291233 | H18: =('Inv AF'!J80-InvAT!H15-InvAT!H16)/'CTV y CResult'!G13*H5 -> 6558904.1 | I18: =('Inv AF'!K80-InvAT!I15-InvAT!I16)/'CTV y CResult'!H13*I5 -> 5465753.4 | J18: =('Inv AF'!L80-InvAT!J15-InvAT!J16)/'CTV y CResult'!I13*J5 -> 5465753.4 | ... L18: =('Inv AF'!N80-InvAT!L15-InvAT!L16)/'CTV y CResult'!K13*L5 -> 19676712
A20: 3. Inversiones en Activo de Trabajo, sin IVA | B20: =+B13-B15-B16-B17-B18 -> 79464000 | C20: =+C13-C15-C16-C17-C18 -> 1807548784 | D20: =+D13-D15-D16-D17-D18 -> 1317952303 | E20: =+E13-E15-E16-E17-E18 -> 1030601870 | F20: =+F13-F15-F16-F17-F18 -> 9.4625663e+08 | G20: =+G13-G15-G16-G17-G18 -> 859464287 | H20: =+H13-H15-H16-H17-H18 -> 7.6862041e+08 | I20: =+I13-I15-I16-I17-I18 -> 6.7067069e+08 | ... L20: =+L13-L15-L16-L17-L18 -> 2406272983
A22: 4. Incrementos de Activo de Trabajo | B22: =+B13 -> 79464000 | C22: =+C13-B13 -> 1959386301 | D22: =+D13-C13 -> -4.6671781e+08 | E22: =+E13-D13 -> -3.2656438e+08 | F22: =+F13-E13 -> -84920548 | G22: =+G13-F13 -> -90041096 | H22: =+H13-G13 -> -1.0154795e+08 | I22: =+I13-H13 -> -1.1288219e+08 | J22: =+J13-I13 -> 36821918 | ... L22: =+L13-K13 -> 1507857534
A23: Incrementos de Inversión en Activo de Trabajo | B23: =+B20 -> 79464000 | C23: =+C20-B20 -> 1728084784 | D23: =+D20-C20 -> -4.8959648e+08 | E23: =+E20-D20 -> -287350433 | F23: =+F20-E20 -> -84345236 | G23: =+G20-F20 -> -86792347 | H23: =+H20-G20 -> -90843872 | I23: =+I20-H20 -> -97949730 | J23: =+J20-I20 -> 17597333 | ... L23: =+L20-K20 -> 1072631491
A25: 5. Incrementos IVA sobre Inversiones
A26: Crédito por Ventas
A27: Bienes de cambio:
A28: Stock de materia prima | B28: =+B8*'DATOS Iniciales y ACLARACIONES'!$B$15 -> 0 | C28: =(+C8-B8)*'DATOS Iniciales y ACLARACIONES'!$B$15 -> 0 | D28: =(+D8-C8)*'DATOS Iniciales y ACLARACIONES'!$B$15 -> 0 | E28: =(+E8-D8)*'DATOS Iniciales y ACLARACIONES'!$B$15 -> 0 | F28: =(+F8-E8)*'DATOS Iniciales y ACLARACIONES'!$B$15 -> 0 | G28: =(+G8-F8)*'DATOS Iniciales y ACLARACIONES'!$B$15 -> 0 | H28: =(+H8-G8)*'DATOS Iniciales y ACLARACIONES'!$B$15 -> 0 | I28: =(+I8-H8)*'DATOS Iniciales y ACLARACIONES'!$B$15 -> 0 | J28: =(+J8-I8)*'DATOS Iniciales y ACLARACIONES'!$B$15 -> 0 | ... L28: =(+L8-K8)*'DATOS Iniciales y ACLARACIONES'!$B$15 -> 0
A29: Stock de materiales | B29: =+B9*'DATOS Iniciales y ACLARACIONES'!B15 -> 0 | C29: =(+C9-B9)*'DATOS Iniciales y ACLARACIONES'!$B$15 -> 0 | D29: =(+D9-C9)*'DATOS Iniciales y ACLARACIONES'!$B$15 -> 0 | E29: =(+E9-D9)*'DATOS Iniciales y ACLARACIONES'!$B$15 -> 0 | F29: =(+F9-E9)*'DATOS Iniciales y ACLARACIONES'!$B$15 -> 0 | G29: =(+G9-F9)*'DATOS Iniciales y ACLARACIONES'!$B$15 -> 0 | H29: =(+H9-G9)*'DATOS Iniciales y ACLARACIONES'!$B$15 -> 0 | I29: =(+I9-H9)*'DATOS Iniciales y ACLARACIONES'!$B$15 -> 0 | J29: =(+J9-I9)*'DATOS Iniciales y ACLARACIONES'!$B$15 -> 0 | ... L29: =(+L9-K9)*'DATOS Iniciales y ACLARACIONES'!$B$15 -> 0
A30: Mercadería en proceso | B30: 0 | C30: =IVA!D5/'CTV y CResult'!B22*C10 -> 0 | D30: =IVA!E5/'CTV y CResult'!C22*D10-(IVA!D5/'CTV y CResult'!B22*C10) -> 0 | E30: =IVA!F5/'CTV y CResult'!D22*E10-(IVA!E5/'CTV y CResult'!C22*D10) -> 0 | F30: =IVA!G5/'CTV y CResult'!E22*F10-(IVA!F5/'CTV y CResult'!D22*E10) -> 0 | G30: =IVA!H5/'CTV y CResult'!F22*G10-(IVA!G5/'CTV y CResult'!E22*F10) -> 0 | H30: =IVA!I5/'CTV y CResult'!G22*H10-(IVA!H5/'CTV y CResult'!F22*G10) -> 0 | I30: =IVA!J5/'CTV y CResult'!H22*I10-(IVA!I5/'CTV y CResult'!G22*H10) -> 0 | J30: =IVA!K5/'CTV y CResult'!I22*J10-(IVA!J5/'CTV y CResult'!H22*I10) -> 0 | K30: =IVA!L5/'CTV y CResult'!J22*K10-(IVA!K5/'CTV y CResult'!I22*J10) -> 0 | L30: =IVA!M5/'CTV y CResult'!K22*L10-(IVA!L5/'CTV y CResult'!J22*K10) -> 0
A31: Stock de elaborados | B31: 0 | C31: =IVA!D5/'CTV y CResult'!B22*C11 -> 0 | D31: =IVA!E5/'CTV y CResult'!C22*D11-(IVA!D5/'CTV y CResult'!B22*C11) -> 0 | E31: =IVA!F5/'CTV y CResult'!D22*E11-(IVA!E5/'CTV y CResult'!C22*D11) -> 0 | F31: =IVA!G5/'CTV y CResult'!E22*F11-(IVA!F5/'CTV y CResult'!D22*E11) -> 0 | G31: =IVA!H5/'CTV y CResult'!F22*G11-(IVA!G5/'CTV y CResult'!E22*F11) -> 0 | H31: =IVA!I5/'CTV y CResult'!G22*H11-(IVA!H5/'CTV y CResult'!F22*G11) -> 0 | I31: =IVA!J5/'CTV y CResult'!H22*I11-(IVA!I5/'CTV y CResult'!G22*H11) -> 0 | J31: =IVA!K5/'CTV y CResult'!I22*J11-(IVA!J5/'CTV y CResult'!H22*I11) -> 0 | K31: =IVA!L5/'CTV y CResult'!J22*K11-(IVA!K5/'CTV y CResult'!I22*J11) -> 0 | L31: =IVA!M5/'CTV y CResult'!K22*L11-(IVA!L5/'CTV y CResult'!J22*K11) -> 0
A32: Total incrementos IVA sobre inversiones | B32: =SUM(B26:B31) -> 0 | C32: =SUM(C26:C31) -> 0 | D32: =SUM(D26:D31) -> 0 | E32: =SUM(E26:E31) -> 0 | F32: =SUM(F26:F31) -> 0 | G32: =SUM(G26:G31) -> 0 | H32: =SUM(H26:H31) -> 0 | I32: =SUM(I26:I31) -> 0 | ... L32: =SUM(L26:L31) -> 0
A34: 6. Incrementos Inversiones en Activo de Trabajo | B34: =+B23+B32 -> 79464000 | C34: =+C23+C32 -> 1728084784 | D34: =+D23+D32 -> -4.8959648e+08 | E34: =+E23+E32 -> -287350433 | F34: =+F23+F32 -> -84345236 | G34: =+G23+G32 -> -86792347 | H34: =+H23+H32 -> -90843872 | I34: =+I23+I32 -> -97949730 | ... L34: =+L23+L32 -> 1072631491

Sheet CostoPROD
A1: COSTO TOTAL DE PRODUCCION
B2: Gastos en el Area de Producción
A3: Rubros | B3: Año 1 | C3: Año 2 | D3: Año 3 | E3: Año 4 | F3: Año 5 | G3: Año 6 | H3: Año 7 | I3: Año 8 | J3: Año 9 | K3: Año 10 | L3: Tipo de Gasto
A4: Materia prima | B4: 1004000000 | C4: 1004000000 | D4: 1004000000 | E4: 1004000000 | F4: 1004000000 | G4: 1004000000 | H4: 1004000000 | I4: 1004000000 | J4: 1004000000 | K4: 1004000000 | L4: FIJO
A5: Mano de obra directa | B5: 850000000 | C5: =B5 -> 850000000 | D5: =C5 -> 850000000 | E5: =D5 -> 850000000 | F5: =E5 -> 850000000 | G5: =F5 -> 850000000 | H5: =G5 -> 850000000 | I5: =H5 -> 850000000 | J5: =I5 -> 850000000 | K5: =J5 -> 850000000 | L5: FIJO
A6: Amortizaciones | B6: ='Inv AF'!E81 -> 25636000 | C6: ='Inv AF'!F81 -> 25636000 | D6: ='Inv AF'!G81 -> 25636000 | E6: ='Inv AF'!H81 -> 25636000 | F6: ='Inv AF'!I81 -> 25636000 | G6: ='Inv AF'!J81 -> 15960000 | H6: ='Inv AF'!K81 -> 15960000 | I6: ='Inv AF'!L81 -> 15960000 | ... K6: ='Inv AF'!N81 -> 15960000 | L6: FIJO
A7: Personal indirecto | L7: VARIABLE
A8: Materiales | L8: FIJO
A9: Energía eléctrica | L9: FIJO
A10: Telefono, Gas, Agua | L10: FIJO
A11: Tasas e impuestos | L11: FIJO
A12: Seguros | L12: FIJO
A13: Procesos y Servicios Tercerizados | L13: FIJO
A14: Regalias Patentes y Licencias | L14: FIJO
A15: Tratamiento de residuos | L15: FIJO
A16: Gastos Logísticos | B16: 34 | D16: 123 | G16: 3123 | L16: FIJO
A17: Imprevistos | B17: =SUM(B3:B12)*'DATOS Iniciales y ACLARACIONES'!$B$25 -> 56389080 | C17: =SUM(C3:C12)*'DATOS Iniciales y ACLARACIONES'!$B$25 -> 56389080 | D17: =SUM(D3:D12)*'DATOS Iniciales y ACLARACIONES'!$B$25 -> 56389080 | E17: =SUM(E3:E12)*'DATOS Iniciales y ACLARACIONES'!$B$25 -> 56389080 | F17: =SUM(F3:F12)*'DATOS Iniciales y ACLARACIONES'!$B$25 -> 56389080 | G17: =SUM(G3:G12)*'DATOS Iniciales y ACLARACIONES'!$B$25 -> 56098800 | H17: =SUM(H3:H12)*'DATOS Iniciales y ACLARACIONES'!$B$25 -> 56098800 | I17: =SUM(I3:I12)*'DATOS Iniciales y ACLARACIONES'!$B$25 -> 56098800 | ... K17: =SUM(K3:K12)*'DATOS Iniciales y ACLARACIONES'!$B$25 -> 56098800 | L17: FIJO
A18: Gastos Total de Producción | B18: =SUM(B4:B17) -> 1936025114 | C18: =SUM(C4:C17) -> 1936025080 | D18: =SUM(D4:D17) -> 1936025203 | E18: =SUM(E4:E17) -> 1936025080 | F18: =SUM(F4:F17) -> 1936025080 | G18: =SUM(G4:G17) -> 1926061923 | H18: =SUM(H4:H17) -> 1926058800 | I18: =SUM(I4:I17) -> 1926058800 | ... K18: =SUM(K4:K17) -> 1926058800
A20: Gasto Variable | B20: =SUMIF($L$4:$L$17,"VARIABLE",B4:B17) -> 0 | C20: =SUMIF($L$4:$L$17,"VARIABLE",C4:C17) -> 0 | D20: =SUMIF($L$4:$L$17,"VARIABLE",D4:D17) -> 0 | E20: =SUMIF($L$4:$L$17,"VARIABLE",E4:E17) -> 0 | F20: =SUMIF($L$4:$L$17,"VARIABLE",F4:F17) -> 0 | G20: =SUMIF($L$4:$L$17,"VARIABLE",G4:G17) -> 0 | H20: =SUMIF($L$4:$L$17,"VARIABLE",H4:H17) -> 0 | I20: =SUMIF($L$4:$L$17,"VARIABLE",I4:I17) -> 0 | ... K20: =SUMIF($L$4:$L$17,"VARIABLE",K4:K17) -> 0
A21: Gasto Constante | B21: =SUMIF($L$4:$L$17,"FIJO",B4:B17) -> 1936025114 | C21: =SUMIF($L$4:$L$17,"FIJO",C4:C17) -> 1936025080 | D21: =SUMIF($L$4:$L$17,"FIJO",D4:D17) -> 1936025203 | E21: =SUMIF($L$4:$L$17,"FIJO",E4:E17) -> 1936025080 | F21: =SUMIF($L$4:$L$17,"FIJO",F4:F17) -> 1936025080 | G21: =SUMIF($L$4:$L$17,"FIJO",G4:G17) -> 1926061923 | H21: =SUMIF($L$4:$L$17,"FIJO",H4:H17) -> 1926058800 | I21: =SUMIF($L$4:$L$17,"FIJO",I4:I17) -> 1926058800 | ... K21: =SUMIF($L$4:$L$17,"FIJO",K4:K17) -> 1926058800
B23: Gastos a activar
B24: Mercadería en Curso y Semielaborada*1
A25: Rubros | B25: Año 1 | C25: Año 2 | D25: Año 3 | E25: Año 4 | F25: Año 5 | G25: Año 6 | H25: Año 7 | I25: Año 8 | J25: Año 9 | K25: Año 10
A26: Materia prima | B26: =B4/'DATOS Iniciales y ACLARACIONES'!D$44*'DATOS Iniciales y ACLARACIONES'!D$41/2 -> 0 | C26: =C4/'DATOS Iniciales y ACLARACIONES'!E$44*'DATOS Iniciales y ACLARACIONES'!E$41/2 -> 0 | D26: =D4/'DATOS Iniciales y ACLARACIONES'!F$44*'DATOS Iniciales y ACLARACIONES'!F$41/2 -> 0 | E26: =E4/'DATOS Iniciales y ACLARACIONES'!G$44*'DATOS Iniciales y ACLARACIONES'!G$41/2 -> 0 | F26: =F4/'DATOS Iniciales y ACLARACIONES'!H$44*'DATOS Iniciales y ACLARACIONES'!H$41/2 -> 0 | G26: =G4/'DATOS Iniciales y ACLARACIONES'!I$44*'DATOS Iniciales y ACLARACIONES'!I$41/2 -> 0 | H26: =H4/'DATOS Iniciales y ACLARACIONES'!J$44*'DATOS Iniciales y ACLARACIONES'!J$41/2 -> 0 | I26: =I4/'DATOS Iniciales y ACLARACIONES'!K$44*'DATOS Iniciales y ACLARACIONES'!K$41/2 -> 0 | ... K26: =K4/'DATOS Iniciales y ACLARACIONES'!M$44*'DATOS Iniciales y ACLARACIONES'!M$41/2 -> 0
A27: Mano de obra directa | B27: =B5/'DATOS Iniciales y ACLARACIONES'!D$44*'DATOS Iniciales y ACLARACIONES'!D$41/2 -> 0 | C27: =C5/'DATOS Iniciales y ACLARACIONES'!E$44*'DATOS Iniciales y ACLARACIONES'!E$41/2 -> 0 | D27: =D5/'DATOS Iniciales y ACLARACIONES'!F$44*'DATOS Iniciales y ACLARACIONES'!F$41/2 -> 0 | E27: =E5/'DATOS Iniciales y ACLARACIONES'!G$44*'DATOS Iniciales y ACLARACIONES'!G$41/2 -> 0 | F27: =F5/'DATOS Iniciales y ACLARACIONES'!H$44*'DATOS Iniciales y ACLARACIONES'!H$41/2 -> 0 | G27: =G5/'DATOS Iniciales y ACLARACIONES'!I$44*'DATOS Iniciales y ACLARACIONES'!I$41/2 -> 0 | H27: =H5/'DATOS Iniciales y ACLARACIONES'!J$44*'DATOS Iniciales y ACLARACIONES'!J$41/2 -> 0 | I27: =I5/'DATOS Iniciales y ACLARACIONES'!K$44*'DATOS Iniciales y ACLARACIONES'!K$41/2 -> 0 | ... K27: =K5/'DATOS Iniciales y ACLARACIONES'!M$44*'DATOS Iniciales y ACLARACIONES'!M$41/2 -> 0
A28: Amortizaciones | B28: =B6/'DATOS Iniciales y ACLARACIONES'!D$44*'DATOS Iniciales y ACLARACIONES'!D$41/2 -> 0 | C28: =C6/'DATOS Iniciales y ACLARACIONES'!E$44*'DATOS Iniciales y ACLARACIONES'!E$41/2 -> 0 | D28: =D6/'DATOS Iniciales y ACLARACIONES'!F$44*'DATOS Iniciales y ACLARACIONES'!F$41/2 -> 0 | E28: =E6/'DATOS Iniciales y ACLARACIONES'!G$44*'DATOS Iniciales y ACLARACIONES'!G$41/2 -> 0 | F28: =F6/'DATOS Iniciales y ACLARACIONES'!H$44*'DATOS Iniciales y ACLARACIONES'!H$41/2 -> 0 | G28: =G6/'DATOS Iniciales y ACLARACIONES'!I$44*'DATOS Iniciales y ACLARACIONES'!I$41/2 -> 0 | H28: =H6/'DATOS Iniciales y ACLARACIONES'!J$44*'DATOS Iniciales y ACLARACIONES'!J$41/2 -> 0 | I28: =I6/'DATOS Iniciales y ACLARACIONES'!K$44*'DATOS Iniciales y ACLARACIONES'!K$41/2 -> 0 | ... K28: =K6/'DATOS Iniciales y ACLARACIONES'!M$44*'DATOS Iniciales y ACLARACIONES'!M$41/2 -> 0
A29: Personal indirecto | B29: =B7/'DATOS Iniciales y ACLARACIONES'!D$44*'DATOS Iniciales y ACLARACIONES'!D$41/2 -> 0 | C29: =C7/'DATOS Iniciales y ACLARACIONES'!E$44*'DATOS Iniciales y ACLARACIONES'!E$41/2 -> 0 | D29: =D7/'DATOS Iniciales y ACLARACIONES'!F$44*'DATOS Iniciales y ACLARACIONES'!F$41/2 -> 0 | E29: =E7/'DATOS Iniciales y ACLARACIONES'!G$44*'DATOS Iniciales y ACLARACIONES'!G$41/2 -> 0 | F29: =F7/'DATOS Iniciales y ACLARACIONES'!H$44*'DATOS Iniciales y ACLARACIONES'!H$41/2 -> 0 | G29: =G7/'DATOS Iniciales y ACLARACIONES'!I$44*'DATOS Iniciales y ACLARACIONES'!I$41/2 -> 0 | H29: =H7/'DATOS Iniciales y ACLARACIONES'!J$44*'DATOS Iniciales y ACLARACIONES'!J$41/2 -> 0 | I29: =I7/'DATOS Iniciales y ACLARACIONES'!K$44*'DATOS Iniciales y ACLARACIONES'!K$41/2 -> 0 | ... K29: =K7/'DATOS Iniciales y ACLARACIONES'!M$44*'DATOS Iniciales y ACLARACIONES'!M$41/2 -> 0
A30: Materiales | B30: =B8/'DATOS Iniciales y ACLARACIONES'!D$44*'DATOS Iniciales y ACLARACIONES'!D$41/2 -> 0 | C30: =C8/'DATOS Iniciales y ACLARACIONES'!E$44*'DATOS Iniciales y ACLARACIONES'!E$41/2 -> 0 | D30: =D8/'DATOS Iniciales y ACLARACIONES'!F$44*'DATOS Iniciales y ACLARACIONES'!F$41/2 -> 0 | E30: =E8/'DATOS Iniciales y ACLARACIONES'!G$44*'DATOS Iniciales y ACLARACIONES'!G$41/2 -> 0 | F30: =F8/'DATOS Iniciales y ACLARACIONES'!H$44*'DATOS Iniciales y ACLARACIONES'!H$41/2 -> 0 | G30: =G8/'DATOS Iniciales y ACLARACIONES'!I$44*'DATOS Iniciales y ACLARACIONES'!I$41/2 -> 0 | H30: =H8/'DATOS Iniciales y ACLARACIONES'!J$44*'DATOS Iniciales y ACLARACIONES'!J$41/2 -> 0 | I30: =I8/'DATOS Iniciales y ACLARACIONES'!K$44*'DATOS Iniciales y ACLARACIONES'!K$41/2 -> 0 | ... K30: =K8/'DATOS Iniciales y ACLARACIONES'!M$44*'DATOS Iniciales y ACLARACIONES'!M$41/2 -> 0
A31: Energía eléctrica | B31: =B9/'DATOS Iniciales y ACLARACIONES'!D$44*'DATOS Iniciales y ACLARACIONES'!D$41/2 -> 0 | C31: =C9/'DATOS Iniciales y ACLARACIONES'!E$44*'DATOS Iniciales y ACLARACIONES'!E$41/2 -> 0 | D31: =D9/'DATOS Iniciales y ACLARACIONES'!F$44*'DATOS Iniciales y ACLARACIONES'!F$41/2 -> 0 | E31: =E9/'DATOS Iniciales y ACLARACIONES'!G$44*'DATOS Iniciales y ACLARACIONES'!G$41/2 -> 0 | F31: =F9/'DATOS Iniciales y ACLARACIONES'!H$44*'DATOS Iniciales y ACLARACIONES'!H$41/2 -> 0 | G31: =G9/'DATOS Iniciales y ACLARACIONES'!I$44*'DATOS Iniciales y ACLARACIONES'!I$41/2 -> 0 | H31: =H9/'DATOS Iniciales y ACLARACIONES'!J$44*'DATOS Iniciales y ACLARACIONES'!J$41/2 -> 0 | I31: =I9/'DATOS Iniciales y ACLARACIONES'!K$44*'DATOS Iniciales y ACLARACIONES'!K$41/2 -> 0 | ... K31: =K9/'DATOS Iniciales y ACLARACIONES'!M$44*'DATOS Iniciales y ACLARACIONES'!M$41/2 -> 0
A32: Combustibles | B32: =B10/'DATOS Iniciales y ACLARACIONES'!D$44*'DATOS Iniciales y ACLARACIONES'!D$41/2 -> 0 | C32: =C10/'DATOS Iniciales y ACLARACIONES'!E$44*'DATOS Iniciales y ACLARACIONES'!E$41/2 -> 0 | D32: =D10/'DATOS Iniciales y ACLARACIONES'!F$44*'DATOS Iniciales y ACLARACIONES'!F$41/2 -> 0 | E32: =E10/'DATOS Iniciales y ACLARACIONES'!G$44*'DATOS Iniciales y ACLARACIONES'!G$41/2 -> 0 | F32: =F10/'DATOS Iniciales y ACLARACIONES'!H$44*'DATOS Iniciales y ACLARACIONES'!H$41/2 -> 0 | G32: =G10/'DATOS Iniciales y ACLARACIONES'!I$44*'DATOS Iniciales y ACLARACIONES'!I$41/2 -> 0 | H32: =H10/'DATOS Iniciales y ACLARACIONES'!J$44*'DATOS Iniciales y ACLARACIONES'!J$41/2 -> 0 | I32: =I10/'DATOS Iniciales y ACLARACIONES'!K$44*'DATOS Iniciales y ACLARACIONES'!K$41/2 -> 0 | ... K32: =K10/'DATOS Iniciales y ACLARACIONES'!M$44*'DATOS Iniciales y ACLARACIONES'!M$41/2 -> 0
A33: Tasas e impuestos | B33: =B11/'DATOS Iniciales y ACLARACIONES'!D$44*'DATOS Iniciales y ACLARACIONES'!D$41/2 -> 0 | C33: =C11/'DATOS Iniciales y ACLARACIONES'!E$44*'DATOS Iniciales y ACLARACIONES'!E$41/2 -> 0 | D33: =D11/'DATOS Iniciales y ACLARACIONES'!F$44*'DATOS Iniciales y ACLARACIONES'!F$41/2 -> 0 | E33: =E11/'DATOS Iniciales y ACLARACIONES'!G$44*'DATOS Iniciales y ACLARACIONES'!G$41/2 -> 0 | F33: =F11/'DATOS Iniciales y ACLARACIONES'!H$44*'DATOS Iniciales y ACLARACIONES'!H$41/2 -> 0 | G33: =G11/'DATOS Iniciales y ACLARACIONES'!I$44*'DATOS Iniciales y ACLARACIONES'!I$41/2 -> 0 | H33: =H11/'DATOS Iniciales y ACLARACIONES'!J$44*'DATOS Iniciales y ACLARACIONES'!J$41/2 -> 0 | I33: =I11/'DATOS Iniciales y ACLARACIONES'!K$44*'DATOS Iniciales y ACLARACIONES'!K$41/2 -> 0 | ... K33: =K11/'DATOS Iniciales y ACLARACIONES'!M$44*'DATOS Iniciales y ACLARACIONES'!M$41/2 -> 0
A34: Seguros | B34: =B12/'DATOS Iniciales y ACLARACIONES'!D$44*'DATOS Iniciales y ACLARACIONES'!D$41/2 -> 0 | C34: =C12/'DATOS Iniciales y ACLARACIONES'!E$44*'DATOS Iniciales y ACLARACIONES'!E$41/2 -> 0 | D34: =D12/'DATOS Iniciales y ACLARACIONES'!F$44*'DATOS Iniciales y ACLARACIONES'!F$41/2 -> 0 | E34: =E12/'DATOS Iniciales y ACLARACIONES'!G$44*'DATOS Iniciales y ACLARACIONES'!G$41/2 -> 0 | F34: =F12/'DATOS Iniciales y ACLARACIONES'!H$44*'DATOS Iniciales y ACLARACIONES'!H$41/2 -> 0 | G34: =G12/'DATOS Iniciales y ACLARACIONES'!I$44*'DATOS Iniciales y ACLARACIONES'!I$41/2 -> 0 | H34: =H12/'DATOS Iniciales y ACLARACIONES'!J$44*'DATOS Iniciales y ACLARACIONES'!J$41/2 -> 0 | I34: =I12/'DATOS Iniciales y ACLARACIONES'!K$44*'DATOS Iniciales y ACLARACIONES'!K$41/2 -> 0 | ... K34: =K12/'DATOS Iniciales y ACLARACIONES'!M$44*'DATOS Iniciales y ACLARACIONES'!M$41/2 -> 0
A35: Procesos y Servicios Tercerizados | B35: =B13/'DATOS Iniciales y ACLARACIONES'!D$44*'DATOS Iniciales y ACLARACIONES'!D$41/2 -> 0 | C35: =C13/'DATOS Iniciales y ACLARACIONES'!E$44*'DATOS Iniciales y ACLARACIONES'!E$41/2 -> 0 | D35: =D13/'DATOS Iniciales y ACLARACIONES'!F$44*'DATOS Iniciales y ACLARACIONES'!F$41/2 -> 0 | E35: =E13/'DATOS Iniciales y ACLARACIONES'!G$44*'DATOS Iniciales y ACLARACIONES'!G$41/2 -> 0 | F35: =F13/'DATOS Iniciales y ACLARACIONES'!H$44*'DATOS Iniciales y ACLARACIONES'!H$41/2 -> 0 | G35: =G13/'DATOS Iniciales y ACLARACIONES'!I$44*'DATOS Iniciales y ACLARACIONES'!I$41/2 -> 0 | H35: =H13/'DATOS Iniciales y ACLARACIONES'!J$44*'DATOS Iniciales y ACLARACIONES'!J$41/2 -> 0 | I35: =I13/'DATOS Iniciales y ACLARACIONES'!K$44*'DATOS Iniciales y ACLARACIONES'!K$41/2 -> 0 | ... K35: =K13/'DATOS Iniciales y ACLARACIONES'!M$44*'DATOS Iniciales y ACLARACIONES'!M$41/2 -> 0
A36: Regalias Patentes y Licencias | B36: =B14/'DATOS Iniciales y ACLARACIONES'!D$44*'DATOS Iniciales y ACLARACIONES'!D$41/2 -> 0 | C36: =C14/'DATOS Iniciales y ACLARACIONES'!E$44*'DATOS Iniciales y ACLARACIONES'!E$41/2 -> 0 | D36: =D14/'DATOS Iniciales y ACLARACIONES'!F$44*'DATOS Iniciales y ACLARACIONES'!F$41/2 -> 0 | E36: =E14/'DATOS Iniciales y ACLARACIONES'!G$44*'DATOS Iniciales y ACLARACIONES'!G$41/2 -> 0 | F36: =F14/'DATOS Iniciales y ACLARACIONES'!H$44*'DATOS Iniciales y ACLARACIONES'!H$41/2 -> 0 | G36: =G14/'DATOS Iniciales y ACLARACIONES'!I$44*'DATOS Iniciales y ACLARACIONES'!I$41/2 -> 0 | H36: =H14/'DATOS Iniciales y ACLARACIONES'!J$44*'DATOS Iniciales y ACLARACIONES'!J$41/2 -> 0 | I36: =I14/'DATOS Iniciales y ACLARACIONES'!K$44*'DATOS Iniciales y ACLARACIONES'!K$41/2 -> 0 | ... K36: =K14/'DATOS Iniciales y ACLARACIONES'!M$44*'DATOS Iniciales y ACLARACIONES'!M$41/2 -> 0
A37: Tratamiento de residuos | B37: =B15/'DATOS Iniciales y ACLARACIONES'!D$44*'DATOS Iniciales y ACLARACIONES'!D$41/2 -> 0 | C37: =C15/'DATOS Iniciales y ACLARACIONES'!E$44*'DATOS Iniciales y ACLARACIONES'!E$41/2 -> 0 | D37: =D15/'DATOS Iniciales y ACLARACIONES'!F$44*'DATOS Iniciales y ACLARACIONES'!F$41/2 -> 0 | E37: =E15/'DATOS Iniciales y ACLARACIONES'!G$44*'DATOS Iniciales y ACLARACIONES'!G$41/2 -> 0 | F37: =F15/'DATOS Iniciales y ACLARACIONES'!H$44*'DATOS Iniciales y ACLARACIONES'!H$41/2 -> 0 | G37: =G15/'DATOS Iniciales y ACLARACIONES'!I$44*'DATOS Iniciales y ACLARACIONES'!I$41/2 -> 0 | H37: =H15/'DATOS Iniciales y ACLARACIONES'!J$44*'DATOS Iniciales y ACLARACIONES'!J$41/2 -> 0 | I37: =I15/'DATOS Iniciales y ACLARACIONES'!K$44*'DATOS Iniciales y ACLARACIONES'!K$41/2 -> 0 | ... K37: =K15/'DATOS Iniciales y ACLARACIONES'!M$44*'DATOS Iniciales y ACLARACIONES'!M$41/2 -> 0
... A39: Imprevistos | B39: =B17/'DATOS Iniciales y ACLARACIONES'!D$44*'DATOS Iniciales y ACLARACIONES'!D$41/2 -> 0 | C39: =C17/'DATOS Iniciales y ACLARACIONES'!E$44*'DATOS Iniciales y ACLARACIONES'!E$41/2 -> 0 | D39: =D17/'DATOS Iniciales y ACLARACIONES'!F$44*'DATOS Iniciales y ACLARACIONES'!F$41/2 -> 0 | E39: =E17/'DATOS Iniciales y ACLARACIONES'!G$44*'DATOS Iniciales y ACLARACIONES'!G$41/2 -> 0 | F39: =F17/'DATOS Iniciales y ACLARACIONES'!H$44*'DATOS Iniciales y ACLARACIONES'!H$41/2 -> 0 | G39: =G17/'DATOS Iniciales y ACLARACIONES'!I$44*'DATOS Iniciales y ACLARACIONES'!I$41/2 -> 0 | H39: =H17/'DATOS Iniciales y ACLARACIONES'!J$44*'DATOS Iniciales y ACLARACIONES'!J$41/2 -> 0 | I39: =I17/'DATOS Iniciales y ACLARACIONES'!K$44*'DATOS Iniciales y ACLARACIONES'!K$41/2 -> 0 | ... K39: =K17/'DATOS Iniciales y ACLARACIONES'!M$44*'DATOS Iniciales y ACLARACIONES'!M$41/2 -> 0
A40: Total gastos a activar MCySE | B40: =SUM(B26:B39) -> 0 | C40: =SUM(C26:C39) -> 0 | D40: =SUM(D26:D39) -> 0 | E40: =SUM(E26:E39) -> 0 | F40: =SUM(F26:F39) -> 0 | G40: =SUM(G26:G39) -> 0 | H40: =SUM(H26:H39) -> 0 | I40: =SUM(I26:I39) -> 0 | ... K40: =SUM(K26:K39) -> 0
A41: Total de Gasto a Activar Gasto P. Marcha | B41: 4500
B43: Costo en el Area de Producción
B44: Año 1 | C44: Año 2 | D44: Año 3 | E44: Año 4 | F44: Año 5 | G44: Año 6 | H44: Año 7 | I44: Año 8 | J44: Año 9 | K44: Año 10
...

Sheet CostoAdmComFin
B2: Gastos en el Area de Administración
A3: Rubros | B3: Año 1 | C3: Año 2 | D3: Año 3 | E3: Año 4 | F3: Año 5 | G3: Año 6 | H3: Año 7 | I3: Año 8 | J3: Año 9 | K3: Año 10 | L3: Tipo de Gasto
A4: Personal | B4: 507000000 | C4: 507000000 | D4: 507000000 | E4: 507000000 | F4: 507000000 | G4: 507000000 | H4: 507000000 | I4: 507000000 | J4: 507000000 | K4: 507000000 | L4: VARIABLE
A5: Amortizaciones de A. Fijo | B5: ='Inv AF'!E83 -> 12818000 | C5: ='Inv AF'!F83 -> 12818000 | D5: ='Inv AF'!G83 -> 12818000 | E5: ='Inv AF'!H83 -> 12818000 | F5: ='Inv AF'!I83 -> 12818000 | G5: ='Inv AF'!J83 -> 7980000 | H5: ='Inv AF'!K83 -> 7980000 | I5: ='Inv AF'!L83 -> 7980000 | ... K5: ='Inv AF'!N83 -> 7980000 | L5: FIJO
A6: Materiales | L6: FIJO
A7: Electricidad | L7: FIJO
A8: Combustible | L8: FIJO
A9: Sistema y Tecnologías de la Información | L9: FIJO
A10: Servicios Tercerizados
A11: Tasas e impuestos | L11: FIJO
A12: Seguros | L12: FIJO
A13: Imprevistos | B13: =SUM(B4:B12)*'DATOS Iniciales y ACLARACIONES'!$B$25 -> 15594540 | C13: =SUM(C4:C12)*'DATOS Iniciales y ACLARACIONES'!$B$25 -> 15594540 | D13: =SUM(D4:D12)*'DATOS Iniciales y ACLARACIONES'!$B$25 -> 15594540 | E13: =SUM(E4:E12)*'DATOS Iniciales y ACLARACIONES'!$B$25 -> 15594540 | F13: =SUM(F4:F12)*'DATOS Iniciales y ACLARACIONES'!$B$25 -> 15594540 | G13: =SUM(G4:G12)*'DATOS Iniciales y ACLARACIONES'!$B$25 -> 15449400 | H13: =SUM(H4:H12)*'DATOS Iniciales y ACLARACIONES'!$B$25 -> 15449400 | I13: =SUM(I4:I12)*'DATOS Iniciales y ACLARACIONES'!$B$25 -> 15449400 | ... K13: =SUM(K4:K12)*'DATOS Iniciales y ACLARACIONES'!$B$25 -> 15449400 | L13: VARIABLE
A15: Costo total de Admistración | B15: =SUM(B4:B13) -> 535412540 | C15: =SUM(C4:C13) -> 535412540 | D15: =SUM(D4:D13) -> 535412540 | E15: =SUM(E4:E13) -> 535412540 | F15: =SUM(F4:F13) -> 535412540 | G15: =SUM(G4:G13) -> 530429400 | H15: =SUM(H4:H13) -> 530429400 | I15: =SUM(I4:I13) -> 530429400 | ... K15: =SUM(K4:K13) -> 530429400
A17: % Costo Variable | B17: =SUMIF($L$4:$L$13,"VARIABLE",B4:B13) -> 522594540 | C17: =SUMIF($L$4:$L$13,"VARIABLE",C4:C13) -> 522594540 | D17: =SUMIF($L$4:$L$13,"VARIABLE",D4:D13) -> 522594540 | E17: =SUMIF($L$4:$L$13,"VARIABLE",E4:E13) -> 522594540 | F17: =SUMIF($L$4:$L$13,"VARIABLE",F4:F13) -> 522594540 | G17: =SUMIF($L$4:$L$13,"VARIABLE",G4:G13) -> 522449400 | H17: =SUMIF($L$4:$L$13,"VARIABLE",H4:H13) -> 522449400 | I17: =SUMIF($L$4:$L$13,"VARIABLE",I4:I13) -> 522449400 | ... K17: =SUMIF($L$4:$L$13,"VARIABLE",K4:K13) -> 522449400
A18: % Costo Constante | B18: =B15-B17 -> 12818000 | C18: =C15-C17 -> 12818000 | D18: =D15-D17 -> 12818000 | E18: =E15-E17 -> 12818000 | F18: =F15-F17 -> 12818000 | G18: =G15-G17 -> 7980000 | H18: =H15-H17 -> 7980000 | I18: =I15-I17 -> 7980000 | ... K18: =K15-K17 -> 7980000
B21: Gastos en el Area de Comercialización
A22: Rubros | B22: Año 1 | C22: Año 2 | D22: Año 3 | E22: Año 4 | F22: Año 5 | G22: Año 6 | H22: Año 7 | I22: Año 8 | J22: Año 9 | K22: Año 10 | L22: Tipo de Gasto
A23: Personal (Fijo) | B23: =(2*13*1.25*3000000)+(4*13*1.25*1200000) -> 175500000 | C23: =(2*13*1.25*3000000)+(4*13*1.25*1200000) -> 175500000 | D23: =(2*13*1.25*3000000)+(4*13*1.25*1200000) -> 175500000 | E23: =(2*13*1.25*3000000)+(4*13*1.25*1200000) -> 175500000 | F23: =(2*13*1.25*3000000)+(4*13*1.25*1200000) -> 175500000 | G23: =(2*13*1.25*3000000)+(4*13*1.25*1200000) -> 175500000 | H23: =(2*13*1.25*3000000)+(4*13*1.25*1200000) -> 175500000 | I23: =(2*13*1.25*3000000)+(4*13*1.25*1200000) -> 175500000 | ... K23: =(2*13*1.25*3000000)+(4*13*1.25*1200000) -> 175500000 | L23: FIJO
A24: Amortizaciones de A. Fijo | B24: ='Inv AF'!E82 -> 25636000 | C24: ='Inv AF'!F82 -> 25636000 | D24: ='Inv AF'!G82 -> 25636000 | E24: ='Inv AF'!H82 -> 25636000 | F24: ='Inv AF'!I82 -> 25636000 | G24: ='Inv AF'!J82 -> 15960000 | H24: ='Inv AF'!K82 -> 15960000 | I24: ='Inv AF'!L82 -> 15960000 | ... K24: ='Inv AF'!N82 -> 15960000 | L24: FIJO
A25: Comisiones por Ventas | B25: ='CTV y CResult'!B13*0.15 -> 595980000 | C25: ='CTV y CResult'!C13*0.15 -> 681030000 | D25: ='CTV y CResult'!D13*0.15 -> 709380000 | E25: ='CTV y CResult'!E13*0.15 -> 739935000 | F25: ='CTV y CResult'!F13*0.15 -> 775215000 | G25: ='CTV y CResult'!G13*0.15 -> 811755000 | H25: ='CTV y CResult'!H13*0.15 -> 850500000 | I25: ='CTV y CResult'!I13*0.15 -> 890820000 | ... K25: ='CTV y CResult'!K13*0.15 -> 976815000 | L25: VARIABLE
A26: Promoción y Publicidad | B26: =9600000+3*1300000 + 7920000 + 2820000 -> 24240000 | C26: =800000+7920000 + 2820000 -> 11540000 | D26: =800000+7920000 + 2820000 -> 11540000 | E26: =800000+7920000 + 2820000 -> 11540000 | F26: =800000+7920000 + 2820000 -> 11540000 | G26: =800000+7920000 + 2820000 -> 11540000 | H26: =800000+7920000 + 2820000 -> 11540000 | I26: =800000+7920000 + 2820000 -> 11540000 | J26: =800000+7920000 + 2820000 -> 11540000 | K26: =800000+7920000 + 2820000 -> 11540000 | L26: FIJO
A27: Servicio Técnico y Postventa | L27: FIJO
A28: Tasas e impuestos | L28: FIJO
A29: Logística y Combustibles | L29: FIJO
A30: Energía Eléctrica | L30: FIJO
A31: Seguros | L31: FIJO
A32: Servicios Tercerizados | L32: FIJO
A33: Imprevistos | B33: =SUM(B23:B32)*'DATOS Iniciales y ACLARACIONES'!$B$25 -> 24640680 | C33: =SUM(C23:C32)*'DATOS Iniciales y ACLARACIONES'!$B$25 -> 26811180 | D33: =SUM(D23:D32)*'DATOS Iniciales y ACLARACIONES'!$B$25 -> 27661680 | E33: =SUM(E23:E32)*'DATOS Iniciales y ACLARACIONES'!$B$25 -> 28578330 | F33: =SUM(F23:F32)*'DATOS Iniciales y ACLARACIONES'!$B$25 -> 29636730 | G33: =SUM(G23:G32)*'DATOS Iniciales y ACLARACIONES'!$B$25 -> 30442650 | H33: =SUM(H23:H32)*'DATOS Iniciales y ACLARACIONES'!$B$25 -> 31605000 | I33: =SUM(I23:I32)*'DATOS Iniciales y ACLARACIONES'!$B$25 -> 32814600 | ... K33: =SUM(K23:K32)*'DATOS Iniciales y ACLARACIONES'!$B$25 -> 35394450 | L33: FIJO
A35: Costo total de Comercialización | B35: =SUM(B23:B33) -> 845996680 | C35: =SUM(C23:C33) -> 920517180 | D35: =SUM(D23:D33) -> 949717680 | E35: =SUM(E23:E33) -> 981189330 | F35: =SUM(F23:F33) -> 1017527730 | G35: =SUM(G23:G33) -> 1045197650 | H35: =SUM(H23:H33) -> 1085105000 | I35: =SUM(I23:I33) -> 1126634600 | ... K35: =SUM(K23:K33) -> 1215209450
A37: % Costo Variable | B37: =SUMIF($L$23:$L$33,"VARIABLE",B23:B33) -> 595980000 | C37: =SUMIF($L$23:$L$33,"VARIABLE",C23:C33) -> 681030000 | D37: =SUMIF($L$23:$L$33,"VARIABLE",D23:D33) -> 709380000 | E37: =SUMIF($L$23:$L$33,"VARIABLE",E23:E33) -> 739935000 | F37: =SUMIF($L$23:$L$33,"VARIABLE",F23:F33) -> 775215000 | G37: =SUMIF($L$23:$L$33,"VARIABLE",G23:G33) -> 811755000 | H37: =SUMIF($L$23:$L$33,"VARIABLE",H23:H33) -> 850500000 | I37: =SUMIF($L$23:$L$33,"VARIABLE",I23:I33) -> 890820000 | ... K37: =SUMIF($L$23:$L$33,"VARIABLE",K23:K33) -> 976815000
A38: % Costo Constante | B38: =B35-B37 -> 250016680 | C38: =C35-C37 -> 239487180 | D38: =D35-D37 -> 240337680 | E38: =E35-E37 -> 241254330 | F38: =F35-F37 -> 242312730 | G38: =G35-G37 -> 233442650 | H38: =H35-H37 -> 234605000 | I38: =I35-I37 -> 235814600 | ... K38: =K35-K37 -> 238394450
B40: Gastos en el Area de Financiera
A41: Rubros | B41: Año 1 | C41: Año 2 | D41: Año 3 | E41: Año 4 | F41: Año 5 | G41: Año 6 | H41: Año 7 | I41: Año 8 | J41: Año 9 | K41: Año 10
A42: Intereses Devengados año a año
A43: Alicuotas de Amortización de IGPO | B43: ='Inv AF'!E84 -> 0 | C43: ='Inv AF'!F84 -> 0 | D43: ='Inv AF'!G84 -> 0 | E43: ='Inv AF'!H84 -> 0 | F43: ='Inv AF'!I84 -> 0 | G43: ='Inv AF'!J84 -> 0 | H43: ='Inv AF'!K84 -> 0 | I43: ='Inv AF'!L84 -> 0 | ... K43: ='Inv AF'!N84 -> 0
A44: Gastos Bancarios Año a Año
A45: Gastos de la Oficina Financiera
A46: Costo total Financiero | B46: =SUM(B42:B45) -> 0 | C46: =SUM(C42:C45) -> 0 | D46: =SUM(D42:D45) -> 0 | E46: =SUM(E42:E45) -> 0 | F46: =SUM(F42:F45) -> 0 | G46: =SUM(G42:G45) -> 0 | H46: =SUM(H42:H45) -> 0 | I46: =SUM(I42:I45) -> 0 | ... K46: =SUM(K42:K45) -> 0
A48: % Costo Constante | B48: 1 | C48: 1 | D48: 1 | E48: 1 | F48: 1 | G48: 1 | H48: 1 | I48: 1 | J48: 1 | K48: 1

Sheet CTV y CResult
B1: =B4*1000 -> 1892000000 | C1: =C4*1000 -> 2162000000 | D1: =D4*1000 -> 2252000000 | E1: =E4*1000 -> 2349000000 | F1: =F4*1000 -> 2461000000 | G1: =G4*1000 -> 2577000000 | H1: =H4*1000 -> 2700000000 | I1: =I4*1000 -> 2828000000 | ... K1: =K4*1000 -> 3101000000
A2: COSTO TOTAL de lo VENDIDO
B3: Año 1 | C3: Año 2 | D3: Año 3 | E3: Año 4 | F3: Año 5 | G3: Año 6 | H3: Año 7 | I3: Año 8 | J3: Año 9 | K3: Año 10
A4: Venta anual, en Unidades Producto 1 | B4: 1892000 | C4: 2162000 | D4: 2252000 | E4: 2349000 | F4: 2461000 | G4: 2577000 | H4: 2700000 | I4: 2828000 | J4: 2961000 | K4: 3101000
A5: Precio de venta Producto 1 | B5: 2100 | C5: 2100 | D5: 2100 | E5: 2100 | F5: 2100 | G5: 2100 | H5: 2100 | I5: 2100 | J5: 2100 | K5: 2100
A6: Venta anual, en Unidades Producto 2
A7: Precio de venta Producto 2
A8: Venta anual, en Unidades Producto 3
A9: Precio de venta Producto 3
A10: Venta anual, en Unidades Producto 4
A11: Precio de venta Producto 4
A12: Otros Ingresos Ordinarios (en $)
A13: VENTAS ANUALES | B13: =+B4*B5+B6*B7+B8*B9+B10*B11+B12 -> 3973200000 | C13: =+C4*C5+C6*C7+C8*C9+C10*C11+C12 -> 4540200000 | D13: =+D4*D5+D6*D7+D8*D9+D10*D11+D12 -> 4729200000 | E13: =+E4*E5+E6*E7+E8*E9+E10*E11+E12 -> 4932900000 | F13: =+F4*F5+F6*F7+F8*F9+F10*F11+F12 -> 5168100000 | G13: =+G4*G5+G6*G7+G8*G9+G10*G11+G12 -> 5411700000 | H13: =+H4*H5+H6*H7+H8*H9+H10*H11+H12 -> 5670000000 | I13: =+I4*I5+I6*I7+I8*I9+I10*I11+I12 -> 5938800000 | ... K13: =+K4*K5+K6*K7+K8*K9+K10*K11+K12 -> 6512100000
A15: Consumo de materia prima | B15: =CostoPROD!B4 -> 1004000000 | C15: =CostoPROD!C4 -> 1004000000 | D15: =CostoPROD!D4 -> 1004000000 | E15: =CostoPROD!E4 -> 1004000000 | F15: =CostoPROD!F4 -> 1004000000 | G15: =CostoPROD!G4 -> 1004000000 | H15: =CostoPROD!H4 -> 1004000000 | I15: =CostoPROD!I4 -> 1004000000 | ... K15: =CostoPROD!K4 -> 1004000000
A16: Mano de obra directa | B16: =CostoPROD!B5 -> 850000000 | C16: =CostoPROD!C5 -> 850000000 | D16: =CostoPROD!D5 -> 850000000 | E16: =CostoPROD!E5 -> 850000000 | F16: =CostoPROD!F5 -> 850000000 | G16: =CostoPROD!G5 -> 850000000 | H16: =CostoPROD!H5 -> 850000000 | I16: =CostoPROD!I5 -> 850000000 | ... K16: =CostoPROD!K5 -> 850000000
A17: Gastos de fabricación | B17: =CostoPROD!B18-CostoPROD!B4-CostoPROD!B5 -> 82025114 | C17: =CostoPROD!C18-CostoPROD!C4-CostoPROD!C5 -> 82025080 | D17: =CostoPROD!D18-CostoPROD!D4-CostoPROD!D5 -> 82025203 | E17: =CostoPROD!E18-CostoPROD!E4-CostoPROD!E5 -> 82025080 | F17: =CostoPROD!F18-CostoPROD!F4-CostoPROD!F5 -> 82025080 | G17: =CostoPROD!G18-CostoPROD!G4-CostoPROD!G5 -> 72061923 | H17: =CostoPROD!H18-CostoPROD!H4-CostoPROD!H5 -> 72058800 | I17: =CostoPROD!I18-CostoPROD!I4-CostoPROD!I5 -> 72058800 | ... K17: =CostoPROD!K18-CostoPROD!K4-CostoPROD!K5 -> 72058800
A18: Gastos de Producción | B18: =SUM(B15:B17) -> 1936025114 | C18: =SUM(C15:C17) -> 1936025080 | D18: =SUM(D15:D17) -> 1936025203 | E18: =SUM(E15:E17) -> 1936025080 | F18: =SUM(F15:F17) -> 1936025080 | G18: =SUM(G15:G17) -> 1926061923 | H18: =SUM(H15:H17) -> 1926058800 | I18: =SUM(I15:I17) -> 1926058800 | ... K18: =SUM(K15:K17) -> 1926058800
A20: (-) Puesta en marcha | B20: =CostoPROD!B41 -> 4500 | C20: =CostoPROD!C41 | D20: =CostoPROD!D41 | E20: =CostoPROD!E41 | F20: =CostoPROD!F41 | G20: =CostoPROD!G41 | H20: =CostoPROD!H41 | I20: =CostoPROD!I41 | ... K20: =CostoPROD!K41
A21: (-) Variación Mercadería en proceso | B21: =CostoPROD!B48 -> 0 | C21: =CostoPROD!C48 -> 0 | D21: =CostoPROD!D48 -> 0 | E21: =CostoPROD!E48 -> 0 | F21: =CostoPROD!F48 -> 0 | G21: =CostoPROD!G48 -> 0 | H21: =CostoPROD!H48 -> 0 | I21: =CostoPROD!I48 -> 0 | ... K21: =CostoPROD!K48 -> 0
A22: COSTO DE PRODUCCION ANUAL | B22: =+B18-B20-B21 -> 1936020614 | C22: =+C18-C20-C21 -> 1936025080 | D22: =+D18-D20-D21 -> 1936025203 | E22: =+E18-E20-E21 -> 1936025080 | F22: =+F18-F20-F21 -> 1936025080 | G22: =+G18-G20-G21 -> 1926061923 | H22: =+H18-H20-H21 -> 1926058800 | I22: =+I18-I20-I21 -> 1926058800 | ... K22: =+K18-K20-K21 -> 1926058800
A23: Producción anual en Unidades Equivalentes | B23: =+B4+B6+B8+B10 -> 1892000 | C23: =+C4+C6+C8+C10 -> 2162000 | D23: =+D4+D6+D8+D10 -> 2252000 | E23: =+E4+E6+E8+E10 -> 2349000 | F23: =+F4+F6+F8+F10 -> 2461000 | G23: =+G4+G6+G8+G10 -> 2577000 | H23: =+H4+H6+H8+H10 -> 2700000 | I23: =+I4+I6+I8+I10 -> 2828000 | ... K23: =+K4+K6+K8+K10 -> 3101000
A24: Costo de producción unitario Promedio Equiv | B24: =B22/B23 -> 1023.2667 | C24: =C22/C23 -> 895.47876 | D24: =D22/D23 -> 859.69148 | E24: =E22/E23 -> 824.19118 | F24: =F22/F23 -> 786.68228 | G24: =G22/G23 -> 747.4047 | H24: =H22/H23 -> 713.35511 | I24: =I22/I23 -> 681.06747 | ... K24: =K22/K23 -> 621.10893
A25: Stock de Elaborados Valorizado | B25: =B24*'DATOS Iniciales y ACLARACIONES'!D42 -> 0 | C25: =C24*'DATOS Iniciales y ACLARACIONES'!E42 -> 0 | D25: =D24*'DATOS Iniciales y ACLARACIONES'!F42 -> 0 | E25: =E24*'DATOS Iniciales y ACLARACIONES'!G42 -> 0 | F25: =F24*'DATOS Iniciales y ACLARACIONES'!H42 -> 0 | G25: =G24*'DATOS Iniciales y ACLARACIONES'!I42 -> 0 | H25: =H24*'DATOS Iniciales y ACLARACIONES'!J42 -> 0 | I25: =I24*'DATOS Iniciales y ACLARACIONES'!K42 -> 0 | ... K25: =K24*'DATOS Iniciales y ACLARACIONES'!M42 -> 0
A27: (-) Variación de Stock de Elaborado | B27: =B25 -> 0 | C27: =C25-B25 -> 0 | D27: =D25-C25 -> 0 | E27: =E25-D25 -> 0 | F27: =F25-E25 -> 0 | G27: =G25-F25 -> 0 | H27: =H25-G25 -> 0 | I27: =I25-H25 -> 0 | J27: =J25-I25 -> 0 | K27: =K25-J25 -> 0
A28: COSTO DE PRODUCCION DE LO VENDIDO | B28: =+B22-B27 -> 1936020614 | C28: =+C22-C27 -> 1936025080 | D28: =+D22-D27 -> 1936025203 | E28: =+E22-E27 -> 1936025080 | F28: =+F22-F27 -> 1936025080 | G28: =+G22-G27 -> 1926061923 | H28: =+H22-H27 -> 1926058800 | I28: =+I22-I27 -> 1926058800 | ... K28: =+K22-K27 -> 1926058800
A29: GASTO DE ADMINISTRACION | B29: =CostoAdmComFin!B15 -> 535412540 | C29: =CostoAdmComFin!C15 -> 535412540 | D29: =CostoAdmComFin!D15 -> 535412540 | E29: =CostoAdmComFin!E15 -> 535412540 | F29: =CostoAdmComFin!F15 -> 535412540 | G29: =CostoAdmComFin!G15 -> 530429400 | H29: =CostoAdmComFin!H15 -> 530429400 | I29: =CostoAdmComFin!I15 -> 530429400 | ... K29: =CostoAdmComFin!K15 -> 530429400
A30: GASTO DE COMERCIALIZACION | B30: =CostoAdmComFin!B35 -> 845996680 | C30: =CostoAdmComFin!C35 -> 920517180 | D30: =CostoAdmComFin!D35 -> 949717680 | E30: =CostoAdmComFin!E35 -> 981189330 | F30: =CostoAdmComFin!F35 -> 1017527730 | G30: =CostoAdmComFin!G35 -> 1045197650 | H30: =CostoAdmComFin!H35 -> 1085105000 | I30: =CostoAdmComFin!I35 -> 1126634600 | ... K30: =CostoAdmComFin!K35 -> 1215209450
A31: GASTO DE FINANCIACION | B31: =CostoAdmComFin!B46 -> 0 | C31: =CostoAdmComFin!C46 -> 0 | D31: =CostoAdmComFin!D46 -> 0 | E31: =CostoAdmComFin!E46 -> 0 | F31: =CostoAdmComFin!F46 -> 0 | G31: =CostoAdmComFin!G46 -> 0 | H31: =CostoAdmComFin!H46 -> 0 | I31: =CostoAdmComFin!I46 -> 0 | ... K31: =CostoAdmComFin!K46 -> 0
A32: COSTO ANUAL DE LO VENDIDO | B32: =+B28+B29+B30 -> 3317429834 | C32: =+C28+C29+C30 -> 3391954800 | D32: =+D28+D29+D30 -> 3421155423 | E32: =+E28+E29+E30 -> 3452626950 | F32: =+F28+F29+F30 -> 3488965350 | G32: =+G28+G29+G30 -> 3501688973 | H32: =+H28+H29+H30 -> 3541593200 | I32: =+I28+I29+I30 -> 3583122800 | ... K32: =+K28+K29+K30 -> 3671697650
A34: Costo total unitario promedio | B34: =B32/(B10+B4+B6+B8) -> 1753.3984 | C34: =C32/(C10+C4+C6+C8) -> 1568.8968 | D34: =D32/(D10+D4+D6+D8) -> 1519.1632 | E34: =E32/(E10+E4+E6+E8) -> 1469.8284 | F34: =F32/(F10+F4+F6+F8) -> 1417.7023 | G34: =G32/(G10+G4+G6+G8) -> 1358.8238 | H34: =H32/(H10+H4+H6+H8) -> 1311.7012 | I34: =I32/(I10+I4+I6+I8) -> 1267.0165 | ... K34: =K32/(K10+K4+K6+K8) -> 1184.0366
A36: UTILIDAD (a/H. D. e Impuesto) | B36: =+B13-B32 -> 655770166 | C36: =+C13-C32 -> 1148245200 | D36: =+D13-D32 -> 1308044577 | E36: =+E13-E32 -> 1480273050 | F36: =+F13-F32 -> 1679134650 | G36: =+G13-G32 -> 1910011027 | H36: =+H13-H32 -> 2128406800 | I36: =+I13-I32 -> 2355677200 | ... K36: =+K13-K32 -> 2840402350
A37: Honorarios al Directorio | B37: =IF('DATOS Iniciales y ACLARACIONES'!$C$20="FIJO",'DATOS Iniciales y ACLARACIONES'!$B$20,'DATOS Iniciales y ACLARACIONES'!$B$20*'CTV y CResult'!B36) -> 32788508 | C37: =IF('DATOS Iniciales y ACLARACIONES'!$C$20="FIJO",'DATOS Iniciales y ACLARACIONES'!$B$20,'DATOS Iniciales y ACLARACIONES'!$B$20*'CTV y CResult'!C36) -> 57412260 | D37: =IF('DATOS Iniciales y ACLARACIONES'!$C$20="FIJO",'DATOS Iniciales y ACLARACIONES'!$B$20,'DATOS Iniciales y ACLARACIONES'!$B$20*'CTV y CResult'!D36) -> 65402229 | E37: =IF('DATOS Iniciales y ACLARACIONES'!$C$20="FIJO",'DATOS Iniciales y ACLARACIONES'!$B$20,'DATOS Iniciales y ACLARACIONES'!$B$20*'CTV y CResult'!E36) -> 74013652 | F37: =IF('DATOS Iniciales y ACLARACIONES'!$C$20="FIJO",'DATOS Iniciales y ACLARACIONES'!$B$20,'DATOS Iniciales y ACLARACIONES'!$B$20*'CTV y CResult'!F36) -> 83956732 | G37: =IF('DATOS Iniciales y ACLARACIONES'!$C$20="FIJO",'DATOS Iniciales y ACLARACIONES'!$B$20,'DATOS Iniciales y ACLARACIONES'!$B$20*'CTV y CResult'!G36) -> 95500551 | H37: =IF('DATOS Iniciales y ACLARACIONES'!$C$20="FIJO",'DATOS Iniciales y ACLARACIONES'!$B$20,'DATOS Iniciales y ACLARACIONES'!$B$20*'CTV y CResult'!H36) -> 106420340 | I37: =IF('DATOS Iniciales y ACLARACIONES'!$C$20="FIJO",'DATOS Iniciales y ACLARACIONES'!$B$20,'DATOS Iniciales y ACLARACIONES'!$B$20*'CTV y CResult'!I36) -> 117783860 | ... K37: =IF('DATOS Iniciales y ACLARACIONES'!$C$20="FIJO",'DATOS Iniciales y ACLARACIONES'!$B$20,'DATOS Iniciales y ACLARACIONES'!$B$20*'CTV y CResult'!K36) -> 1.4202012e+08
A38: Impuesto a la ganancia | B38: =(B36-B37)*'DATOS Iniciales y ACLARACIONES'!$B$19 -> 2.1804358e+08 | C38: =(C36-C37)*'DATOS Iniciales y ACLARACIONES'!$B$19 -> 381791529 | D38: =(D36-D37)*'DATOS Iniciales y ACLARACIONES'!$B$19 -> 4.3492482e+08 | E38: =(E36-E37)*'DATOS Iniciales y ACLARACIONES'!$B$19 -> 4.9219079e+08 | F38: =(F36-F37)*'DATOS Iniciales y ACLARACIONES'!$B$19 -> 5.5831227e+08 | G38: =(G36-G37)*'DATOS Iniciales y ACLARACIONES'!$B$19 -> 6.3507867e+08 | H38: =(H36-H37)*'DATOS Iniciales y ACLARACIONES'!$B$19 -> 707695261 | I38: =(I36-I37)*'DATOS Iniciales y ACLARACIONES'!$B$19 -> 783262669 | ... K38: =(K36-K37)*'DATOS Iniciales y ACLARACIONES'!$B$19 -> 9.4443378e+08
A40: UTILIDAD (d/H.D. e Impuesto) | B40: =B36-B37-B38 -> 4.0493808e+08 | C40: =C36-C37-C38 -> 709041411 | D40: =D36-D37-D38 -> 8.0771753e+08 | E40: =E36-E37-E38 -> 9.1406861e+08 | F40: =F36-F37-F38 -> 1036865646 | G40: =G36-G37-G38 -> 1179431809 | H40: =H36-H37-H38 -> 1314291199 | I40: =I36-I37-I38 -> 1454630671 | ... K40: =K36-K37-K38 -> 1753948451
A41: % sobre VENTAS | B41: =+B40/B13 -> 0.10191737 | C41: =+C40/C13 -> 0.15616964 | D41: =+D40/D13 -> 0.17079369 | E41: =+E40/E13 -> 0.18530045 | F41: =+F40/F13 -> 0.20062802 | G41: =+G40/G13 -> 0.21794109 | H41: =+H40/H13 -> 0.23179739 | I41: =+I40/I13 -> 0.2449368 | ... K41: =+K40/K13 -> 0.26933684
A43: FONDOS AUTOGENERADOS | B43: =+B44+B45 -> 4.6902808e+08 | C43: =+C44+C45 -> 773131411 | D43: =+D44+D45 -> 8.7180753e+08 | E43: =+E44+E45 -> 9.7815861e+08 | F43: =+F44+F45 -> 1100955646 | G43: =+G44+G45 -> 1219331809 | H43: =+H44+H45 -> 1354191199 | I43: =+I44+I45 -> 1494530671 | ... K43: =+K44+K45 -> 1793848451
A44: Utilidad Económica (d/H.D. e Impuesto) | B44: =+B40 -> 4.0493808e+08 | C44: =+C40 -> 709041411 | D44: =+D40 -> 8.0771753e+08 | E44: =+E40 -> 9.1406861e+08 | F44: =+F40 -> 1036865646 | G44: =+G40 -> 1179431809 | H44: =+H40 -> 1314291199 | I44: =+I40 -> 1454630671 | ... K44: =+K40 -> 1753948451
A45: Amortización anual | B45: =+'Inv AF'!E80 -> 64090000 | C45: =+'Inv AF'!F80 -> 64090000 | D45: =+'Inv AF'!G80 -> 64090000 | E45: =+'Inv AF'!H80 -> 64090000 | F45: =+'Inv AF'!I80 -> 64090000 | G45: =+'Inv AF'!J80 -> 39900000 | H45: =+'Inv AF'!K80 -> 39900000 | I45: =+'Inv AF'!L80 -> 39900000 | ... K45: =+'Inv AF'!N80 -> 39900000
A47: Costo Variable | B47: =CostoPROD!B20+CostoAdmComFin!B17+CostoAdmComFin!B37 -> 1118574540 | C47: =CostoPROD!C20+CostoAdmComFin!C17+CostoAdmComFin!C37 -> 1203624540 | D47: =CostoPROD!D20+CostoAdmComFin!D17+CostoAdmComFin!D37 -> 1231974540 | E47: =CostoPROD!E20+CostoAdmComFin!E17+CostoAdmComFin!E37 -> 1262529540 | F47: =CostoPROD!F20+CostoAdmComFin!F17+CostoAdmComFin!F37 -> 1297809540 | G47: =CostoPROD!G20+CostoAdmComFin!G17+CostoAdmComFin!G37 -> 1334204400 | H47: =CostoPROD!H20+CostoAdmComFin!H17+CostoAdmComFin!H37 -> 1372949400 | I47: =CostoPROD!I20+CostoAdmComFin!I17+CostoAdmComFin!I37 -> 1413269400 | ... K47: =CostoPROD!K20+CostoAdmComFin!K17+CostoAdmComFin!K37 -> 1499264400
A48: Costo Constante | B48: =CostoPROD!B21+CostoAdmComFin!B18+CostoAdmComFin!B38+CostoAdmComFin!B48 -> 2198859795 | C48: =CostoPROD!C21+CostoAdmComFin!C18+CostoAdmComFin!C38+CostoAdmComFin!C48 -> 2188330261 | D48: =CostoPROD!D21+CostoAdmComFin!D18+CostoAdmComFin!D38+CostoAdmComFin!D48 -> 2189180884 | E48: =CostoPROD!E21+CostoAdmComFin!E18+CostoAdmComFin!E38+CostoAdmComFin!E48 -> 2190097411 | F48: =CostoPROD!F21+CostoAdmComFin!F18+CostoAdmComFin!F38+CostoAdmComFin!F48 -> 2191155811 | G48: =CostoPROD!G21+CostoAdmComFin!G18+CostoAdmComFin!G38+CostoAdmComFin!G48 -> 2167484574 | H48: =CostoPROD!H21+CostoAdmComFin!H18+CostoAdmComFin!H38+CostoAdmComFin!H48 -> 2168643801 | I48: =CostoPROD!I21+CostoAdmComFin!I18+CostoAdmComFin!I38+CostoAdmComFin!I48 -> 2169853401 | ... K48: =CostoPROD!K21+CostoAdmComFin!K18+CostoAdmComFin!K38+CostoAdmComFin!K48 -> 2172433251
...

Sheet IVA
A1: IVA plan de Explotación, Cancelación del Credito Fiscal y pago al Fisco por IVA
C2: TOTALES PARA LAS TRES AREAS
A3: Rubros | C3: Año 0 | D3: Año 1 | E3: Año 2 | F3: Año 3 | G3: Año 4 | H3: Año 5 | I3: Año 6 | J3: Año 7 | K3: Año 8 | L3: Año 9 | M3: Año 10
A4: a) IVA pagado Costo Total de lo Vendido*1 | B4: Tasa
A5: Total Pagado en Producción | D5: =SUM(D6:D9) -> 2.2268171e+08 | E5: =SUM(E6:E9) -> 2.2268171e+08 | F5: =SUM(F6:F9) -> 2.2268173e+08 | G5: =SUM(G6:G9) -> 2.2268171e+08 | H5: =SUM(H6:H9) -> 2.2268171e+08 | I5: =SUM(I6:I9) -> 2.226214e+08 | J5: =SUM(J6:J9) -> 222620748 | K5: =SUM(K6:K9) -> 222620748 | ... M5: =SUM(M6:M9) -> 222620748
A6: Materia Prima con tarifa Normal | B6: ='DATOS Iniciales y ACLARACIONES'!B15 -> 0.21 | D6: =(CostoPROD!B4)*$B$6 -> 210840000 | E6: =(CostoPROD!C4)*$B$6 -> 210840000 | F6: =(CostoPROD!D4)*$B$6 -> 210840000 | G6: =(CostoPROD!E4)*$B$6 -> 210840000 | H6: =(CostoPROD!F4)*$B$6 -> 210840000 | I6: =(CostoPROD!G4)*$B$6 -> 210840000 | J6: =(CostoPROD!H4)*$B$6 -> 210840000 | K6: =(CostoPROD!I4)*$B$6 -> 210840000 | ... M6: =(CostoPROD!K4)*$B$6 -> 210840000
A7: Materia Prima con tarifa Reducida | B7: ='DATOS Iniciales y ACLARACIONES'!B16 -> 0.105
A8: Servicios | B8: ='DATOS Iniciales y ACLARACIONES'!B17 -> 0.27 | D8: =(CostoPROD!B9+CostoPROD!B10)*IVA!$B$8 -> 0 | E8: =(CostoPROD!C9+CostoPROD!C10)*IVA!$B$8 -> 0 | F8: =(CostoPROD!D9+CostoPROD!D10)*IVA!$B$8 -> 0 | G8: =(CostoPROD!E9+CostoPROD!E10)*IVA!$B$8 -> 0 | H8: =(CostoPROD!F9+CostoPROD!F10)*IVA!$B$8 -> 0 | I8: =(CostoPROD!G9+CostoPROD!G10)*IVA!$B$8 -> 0 | J8: =(CostoPROD!H9+CostoPROD!H10)*IVA!$B$8 -> 0 | K8: =(CostoPROD!I9+CostoPROD!I10)*IVA!$B$8 -> 0 | ... M8: =(CostoPROD!K9+CostoPROD!K10)*IVA!$B$8 -> 0
A9: Otros Gastos tarifa normal | B9: ='DATOS Iniciales y ACLARACIONES'!B15 -> 0.21 | D9: =(CostoPROD!B8+CostoPROD!B12+CostoPROD!B13+CostoPROD!B14+CostoPROD!B15+CostoPROD!B16+CostoPROD!B17)*$B$9 -> 11841714 | E9: =(CostoPROD!C8+CostoPROD!C12+CostoPROD!C13+CostoPROD!C14+CostoPROD!C15+CostoPROD!C16+CostoPROD!C17)*$B$9 -> 11841707 | F9: =(CostoPROD!D8+CostoPROD!D12+CostoPROD!D13+CostoPROD!D14+CostoPROD!D15+CostoPROD!D16+CostoPROD!D17)*$B$9 -> 11841733 | G9: =(CostoPROD!E8+CostoPROD!E12+CostoPROD!E13+CostoPROD!E14+CostoPROD!E15+CostoPROD!E16+CostoPROD!E17)*$B$9 -> 11841707 | H9: =(CostoPROD!F8+CostoPROD!F12+CostoPROD!F13+CostoPROD!F14+CostoPROD!F15+CostoPROD!F16+CostoPROD!F17)*$B$9 -> 11841707 | I9: =(CostoPROD!G8+CostoPROD!G12+CostoPROD!G13+CostoPROD!G14+CostoPROD!G15+CostoPROD!G16+CostoPROD!G17)*$B$9 -> 11781404 | J9: =(CostoPROD!H8+CostoPROD!H12+CostoPROD!H13+CostoPROD!H14+CostoPROD!H15+CostoPROD!H16+CostoPROD!H17)*$B$9 -> 11780748 | K9: =(CostoPROD!I8+CostoPROD!I12+CostoPROD!I13+CostoPROD!I14+CostoPROD!I15+CostoPROD!I16+CostoPROD!I17)*$B$9 -> 11780748 | ... M9: =(CostoPROD!K8+CostoPROD!K12+CostoPROD!K13+CostoPROD!K14+CostoPROD!K15+CostoPROD!K16+CostoPROD!K17)*$B$9 -> 11780748
A10: Total Pagado por Administración | D10: =SUM(D11:D12) -> 0 | E10: =SUM(E11:E12) -> 0 | F10: =SUM(F11:F12) -> 0 | G10: =SUM(G11:G12) -> 0 | H10: =SUM(H11:H12) -> 0 | I10: =SUM(I11:I12) -> 0 | J10: =SUM(J11:J12) -> 0 | K10: =SUM(K11:K12) -> 0 | ... M10: =SUM(M11:M12) -> 0
A11: Servicios | B11: ='DATOS Iniciales y ACLARACIONES'!B17 -> 0.27 | D11: =$B$11*(CostoAdmComFin!B7) -> 0 | E11: =$B$11*(CostoAdmComFin!C7) -> 0 | F11: =$B$11*(CostoAdmComFin!D7) -> 0 | G11: =$B$11*(CostoAdmComFin!E7) -> 0 | H11: =$B$11*(CostoAdmComFin!F7) -> 0 | I11: =$B$11*(CostoAdmComFin!G7) -> 0 | J11: =$B$11*(CostoAdmComFin!H7) -> 0 | K11: =$B$11*(CostoAdmComFin!I7) -> 0 | ... M11: =$B$11*(CostoAdmComFin!K7) -> 0
