Workbook

Sheet EJ 1
A1: EJERCICIO 1
A7: Producto | B7: Ventas estimadas | C7: Región (participación) | E7: Región (precio de vta)
C8: Norte | D8: Sur | E8: Norte | F8: Sur
A9: A | B9: 12000 | C9: 0.5 | D9: 0.5 | E9: 15 | F9: 16.5
A10: B | B10: 15000 | C10: 0.4 | D10: 0.6 | E10: 24 | F10: 27
A11: C | B11: 22000 | C11: 0.7 | D11: 0.3 | E11: 12.5 | F11: 14
A13: Realizar el presupuesto de ventas
B15: PRODUCTO A | C15: PRODUCTO B | D15: PRODUCTO C
A16: Unidades | B16: 12000 | C16: =B10 -> 15000 | D16: =B11 -> 22000
A17: Región Norte | B17: =B16*C9 -> 6000 | C17: =C16*C10 -> 6000 | D17: =D16*C11 -> 15400
A18: Región Sur | B18: =B16*D9 -> 6000 | C18: =B10*D10 -> 9000 | D18: =D16*D11 -> 6600
A20: Precio de venta
A21: Región Norte | B21: =E9 -> 15 | C21: =E10 -> 24 | D21: =E11 -> 12.5
A22: Región Sur | B22: =F9 -> 16.5 | C22: =F10 -> 27 | D22: =F11 -> 14
A24: Importes | B24: =SUM(B25:B26) -> 189000 | C24: =SUM(C25:C26) -> 387000 | D24: =SUM(D25:D26) -> 284900 | E24: OK
A25: Región Norte | B25: =B17*B21 -> 90000 | C25: =C17*C21 -> 144000 | D25: =D17*D21 -> 192500
A26: Región Sur | B26: =B18*B22 -> 99000 | C26: =C18*C22 -> 243000 | D26: =D18*D22 -> 92400

Sheet EJ 2
A1: EJERCICIO 2
A6: Producto | B6: Ventas estimadas | C6: Región (participación) | E6: Región (precio de vta) | G6: Participación distribuidores | I6: Distribuidores (precio de vta)
C7: Norte | D7: Sur | E7: Norte | F7: Sur | G7: Norte | H7: Sur | I7: Norte | J7: Sur
A8: A | B8: 35000 | C8: 0.5 | D8: 0.5 | E8: 23 | F8: 22 | G8: 0.2 | H8: 0.25 | I8: =E8-E8*(1-0.18) -> 4.14 | J8: =F8-F8*(1-0.18) -> 3.96
A9: B | B9: 52000 | C9: 0.6 | D9: 0.4 | E9: 31 | F9: 33 | G9: 0.3 | H9: 0.15 | I9: =E9-E9*(1-0.21) -> 6.51 | J9: =F9-F9*(1-0.21) -> 6.93
B16: PRODUCTO A | C16: PRODUCTO B
A17: Consumidores finales
A18: Unidades | B18: =B8 -> 35000 | C18: =B9 -> 52000
A19: Región Norte | B19: =B18*C8 -> 17500 | C19: =C18*C9 -> 31200
A20: Región Sur | B20: =B18*D8 -> 17500 | C20: =C18*D9 -> 20800
A22: Precio de venta C.F
A23: Región Norte | B23: =E8 -> 23 | C23: 31
A24: Región Sur | B24: =F8 -> 22 | C24: =F9 -> 33
A26: Importes (C.F) | B26: =SUM(B27:B28) -> 787500 | C26: =SUM(C27:C28) -> 1653600
A27: Región Norte | B27: =B19*B23 -> 402500 | C27: =C19*C23 -> 967200
A28: Región Sur | B28: =B20*B24 -> 385000 | C28: =C20*C24 -> 686400
A30: Distribuidores
A31: Unidades | B31: 35000 | C31: 52000
A32: Región Norte | B32: =B31*G8*D8 -> 3500 | C32: =C31*G9*C9 -> 9360
A33: Región Sur | B33: =B31*H8*D8 -> 4375 | C33: =C31*H9*D9 -> 3120
A35: Precio de venta DIST.
A36: Región Norte | B36: =I8 -> 4.14 | C36: =I9 -> 6.51
A37: Región Sur | B37: =J8 -> 3.96 | C37: =J9 -> 6.93
A39: Importes (DIST) | B39: =SUM(B40:B41) -> 31815 | C39: =SUM(C40:C41) -> 82555.2
A40: Región Norte | B40: =B32*B36 -> 14490 | C40: =C32*C36 -> 60933.6
A41: Región Sur | B41: =B33*B37 -> 17325 | C41: =C33*C37 -> 21621.6
A42: Total | B42: =B26-B39 -> 755685 | C42: =C26-C39 -> 1571044.8 | D42: OK
A44: Total región norte | B44: =B27+C27-B40-C40 -> 1294276.4
A45: Total región sur | B45: =B28+C28-B41-C41 -> 1032453.4
A46: Total | B46: =B44+B45 -> 2326729.8 | C46: OK

Sheet EJ 3
A1: EJERCICIO 3
A6: PRODUCTO | B6: Crecimiento anual de volumen de ventas | C6: Vol. Ventas año anterior | D6: Inv. Inicial | E6: Inv final (*) | F6: Ventas
A7: A | B7: 0.05 | C7: 2400 | D7: 300 | E7: 0.25 | F7: =C7*(1+B7) -> 2520
A8: B | B8: 0.08 | C8: 3200 | D8: 500 | E8: 0.25 | F8: =C8*(1+B8) -> 3456
A9: C | B9: 0.12 | C9: 3750 | D9: 800 | E9: 0.25 | F9: =C9*(1+B9) -> 4200
A11: * Sobre las ventas pronosticadas del próximo año
B13: A | C13: B | D13: C
A14: Volumen de ventas | B14: =F7 -> 2520 | C14: =F8 -> 3456 | D14: =F9 -> 4200
A15: Inventario final | B15: =F7*E7 -> 630 | C15: =F8*E8 -> 864 | D15: =F9*E9 -> 1050
A16: Inventario inicial | B16: =D7 -> 300 | C16: =D8 -> 500 | D16: =D9 -> 800
A17: Producción requerida | B17: =B14+B15-B16 -> 2850 | C17: =C14+C15-C16 -> 3820 | D17: =D14+D15-D16 -> 4450 | E17: OK

Sheet EJ 4
A1: EJERCICIO 4
A6: PRODUCTO | B6: Crecimiento anual de volumen de ventas | C6: Vol. Ventas año anterior | D6: Inv. Inicial | E6: Inv final (*) m | F6: Ventas | G6: Ventas promedios mensuales | H6: Inventario final
A7: A | B7: 0.05 | C7: 2400 | D7: 300 | E7: 2 | F7: =C7*(1+B7) -> 2520 | G7: =F7/12 -> 210 | H7: =G7*E7 -> 420
A8: B | B8: 0.08 | C8: 3200 | D8: 500 | E8: 1,5 | F8: =C8*(1+B8) -> 3456 | G8: =F8/12 -> 288 | H8: =288*1.5 -> 432
A9: C | B9: 0.12 | C9: 3750 | D9: 800 | E9: 1 | F9: =C9*(1+B9) -> 4200 | G9: =F9/12 -> 350 | H9: =G9 -> 350
A11: * meses de venta promedio del proximo año
B13: A | C13: B | D13: C
A14: Volumen de ventas | B14: =F7 -> 2520 | C14: =F8 -> 3456 | D14: =F9 -> 4200
A15: Inventario final | B15: =H7 -> 420 | C15: =H8 -> 432 | D15: =H9 -> 350
A16: Inventario inicial | B16: =D7 -> 300 | C16: =D8 -> 500 | D16: =D9 -> 800
A17: Producción requerida | B17: =B14+B15-B16 -> 2640 | C17: =C14+C15-C16 -> 3388 | D17: =D14+D15-D16 -> 3750 | E17: OK

Sheet EJ 5
A1: EJERCICIO 5
A9: PRODUCTO | B9: Crecimiento anual de volumen de ventas | C9: Vol. Ventas año anterior | D9: Inv. Inicial | E9: Inv final (*) | F9: Ventas | G9: Inv final
A10: A | B10: 0.03 | C10: 2400 | D10: 300 | E10: 0.25 | F10: =C10*(1+B10) -> 2472 | G10: =F10*E10 -> 618
A11: B | B11: 0.05 | C11: 3200 | D11: 500 | E11: 0.15 | F11: =C11*(1+B11) -> 3360 | G11: =F11*E11 -> 504
A12: C | E12: 0.2 | F12: 2000 | G12: =F12*E12 -> 400
A14: * Sobre las ventas pronosticadas del proximo año
A16: PRODUCTO | B16: Ventas | C16: Inv final | D16: Inv inicial | E16: Producción requerida
A17: A | B17: 2472 | C17: 618 | D17: =D10 -> 300 | E17: =B17+C17-D17 -> 2790 | F17: OK
A18: B | B18: 3360 | C18: 504 | D18: =D11 -> 500 | E18: =B18+C18-D18 -> 3364 | F18: OK
A19: C | B19: 2000 | C19: 400 | D19: 0 | E19: =B19+C19-D19 -> 2400 | F19: OK

Sheet EJ 6
A1: EJERCICIO 6
A7: Producto | B7: Crec. Anual de Vol. de vtas. | C7: Vol. Vtas. año ant. | D7: Inv. Inicial | E7: Inv. Final (*) | F7: Costo de adquisición
A8: A | B8: 0.03 | C8: 12000 | D8: 1500 | E8: 0.1 | F8: 1.3
A9: B | B9: 0.05 | C9: 16000 | D9: 1300 | E9: 0.1 | F9: 2.6
A10: C | B10: 0.075 | C10: 8000 | D10: 1400 | E10: 0.2 | F10: 6.35
A11: D | B11: 0.1 | C11: 20000 | D11: 850 | E11: 0.05 | F11: 4.8
A13: * Sobre las ventas pronosticadas del proximo año
A15: Producto | B15: Ventas | C15: Inv final | D15: Inv. Inicial | E15: Producción requerida | F15: Costo de adquisición | G15: Costo total
A16: A | B16: =C8*(1+B8) -> 12360 | C16: =B16*E8 -> 1236 | D16: 1500 | E16: =B16+C16-D16 -> 12096 | F16: 1.3 | G16: =E16*F16 -> 15724.8
A17: B | B17: =C9*(1+B9) -> 16800 | C17: =B17*E9 -> 1680 | D17: 1300 | E17: =B17+C17-D17 -> 17180 | F17: 2.6 | G17: =E17*F17 -> 44668
A18: C | B18: =C10*(1+B10) -> 8600 | C18: =B18*E10 -> 1720 | D18: 1400 | E18: =B18+C18-D18 -> 8920 | F18: 6.35 | G18: =E18*F18 -> 56642
A19: D | B19: =C11*(1+B11) -> 22000 | C19: =B19*E11 -> 1100 | D19: 850 | E19: =B19+C19-D19 -> 22250 | F19: 4.8 | G19: =E19*F19 -> 106800
E20: =SUM(E16:E19) -> 60446 | F20: OK | G20: =SUM(G16:G19) -> 223834.8 | H20: OK

Sheet EJ 7
A1: EJERCICIO 7
A9: Producto | B9: Crec. Anual de Vol. de vtas. | C9: Vol. Vtas. año ant. | D9: Inv. Inicial | E9: Inv. Final (*) | F9: Costo de adquisición | G9: Rotación
A10: A | B10: 0.03 | C10: 12000 | D10: 1500 | E10: 0.1 | F10: 1.3 | G10: 45
A11: B | B11: 0.05 | C11: 16000 | D11: 1300 | E11: 0.1 | F11: 2.6 | G11: 30
A12: C | B12: 0.075 | C12: 8000 | D12: 1400 | E12: 0.2 | F12: 6.35 | G12: 60
A13: D | B13: 0.1 | C13: 20000 | D13: 850 | E13: 0.05 | F13: 4.8 | G13: 15
A16: Producto | B16: Ventas | C16: Inv final | D16: Inv. Inicial | E16: Producción requerida | F16: Costo de adquisición | G16: Costo total
A17: A | B17: =C10*(1+B10) -> 12360 | C17: =C10/365*G10 -> 1479.4521 | D17: 1500 | E17: =B17+C17-D17 -> 12339.452 | F17: 1.3 | G17: =E17*F17 -> 16041.288
A18: B | B18: =C11*(1+B11) -> 16800 | C18: =C11/360*G11 -> 1333.3333 | D18: 1300 | E18: =B18+C18-D18 -> 16833.333 | F18: 2.6 | G18: =E18*F18 -> 43766.667
A19: C | B19: =C12*(1+B12) -> 8600 | C19: =C12/360*G12 -> 1333.3333 | D19: 1400 | E19: =B19+C19-D19 -> 8533.3333 | F19: 6.35 | G19: =E19*F19 -> 54186.667
A20: D | B20: =C13*(1+B13) -> 22000 | C20: =C13/360*G13 -> 833.33333 | D20: 850 | E20: =B20+C20-D20 -> 21983.333 | F20: 4.8 | G20: =E20*F20 -> 105520

Sheet EJ 8
A1: EJERCICIO 8
A8: Producto | B8: Producción prevista | C8: Insumos utilizados (estandar x unidad a producir)
C9: 1 | D9: 2 | E9: 3 | F9: 4 | G9: 5
A10: A | B10: 75000 | C10: 1.5 | D10: 50 | E10: 120 | F10: 2 | G10: 1
A11: B | B11: 20000 | C11: 0.8 | D11: 40 | E11: 150 | F11: 2.5
A12: C | B12: 45000 | C12: 2 | D12: 30 | E12: 100 | G12: 1.5
A13: D | B13: 30000 | C13: 1 | D13: 70 | E13: 120 | F13: 1.5
A14: Costo unitario | C14: 30 | D14: 10 | E14: 4.5 | F14: 125 | G14: 56
A17: Producto | B17: Producción prevista | C17: 1 | D17: 2 | E17: 3 | F17: 4 | G17: 5 | H17: Costo por producto
A19: A | B19: 75000 | C19: =$B$19*C10 -> 112500 | D19: =$B$19*D10 -> 3750000 | E19: =$B$19*E10 -> 9000000 | F19: =$B$19*F10 -> 150000 | G19: =$B$19*G10 -> 75000 | H19: =C19*$C$14+D19*$D$14+E19*$E$14+F19*$F$14+G19*$G$14 -> 104325000 | I19: OK
A20: B | B20: 20000 | C20: =$B$20*C11 -> 16000 | D20: =$B$20*D11 -> 800000 | E20: =$B$20*E11 -> 3000000 | F20: =$B$20*F11 -> 50000 | G20: =$B$20*G11 -> 0 | H20: =C20*$C$14+D20*$D$14+E20*$E$14+F20*$F$14+G20*$G$14 -> 28230000 | I20: OK
A21: C | B21: 45000 | C21: =$B$21*C12 -> 90000 | D21: =$B$21*D12 -> 1350000 | E21: =$B$21*E12 -> 4500000 | F21: =$B$21*F12 -> 0 | G21: =$B$21*G12 -> 67500 | H21: =C21*$C$14+D21*$D$14+E21*$E$14+F21*$F$14+G21*$G$14 -> 40230000 | I21: OK
A22: D | B22: 30000 | C22: =$B$22*C13 -> 30000 | D22: =$B$22*D13 -> 2100000 | E22: =$B$22*E13 -> 3600000 | F22: =$B$22*F13 -> 45000 | G22: =$B$22*G13 -> 0 | H22: =C22*$C$14+D22*$D$14+E22*$E$14+F22*$F$14+G22*$G$14 -> 43725000 | I22: OK
A23: Total | B23: =SUM(B19:B22) -> 170000 | C23: =SUM(C19:C22) -> 248500 | D23: =SUM(D19:D22) -> 8000000 | E23: =SUM(E19:E22) -> 20100000 | F23: =SUM(F19:F22) -> 245000 | G23: =SUM(G19:G22) -> 142500 | H23: =C23*$C$14+D23*$D$14+E23*$E$14+F23*$F$14+G23*$G$14 -> 216510000 | I23: OK
A24: Costo total | C24: =C23*C14 -> 7455000 | D24: =D23*D14 -> 80000000 | E24: =E23*E14 -> 90450000 | F24: =F23*F14 -> 30625000 | G24: =G23*G14 -> 7980000

Sheet EJ 9
A1: EJERCICIO 9
A10: Producto | B10: Producción prevista | C10: Insumos utilizados (estandar x unidad a producir)
C11: 1 | D11: 2 | E11: 3 | F11: 4 | G11: 5
A12: A | B12: 75000 | C12: 1.5 | D12: 50 | E12: 120 | F12: 2 | G12: 1
A13: B | B13: 20000 | C13: 0.8 | D13: 40 | E13: 150 | F13: 2.5
A14: C | B14: 45000 | C14: 2 | D14: 30 | E14: 100 | G14: 1.5
A15: D | B15: 30000 | C15: 1 | D15: 70 | E15: 120 | F15: 1.5
A16: Costo unitario | C16: 30 | D16: 10 | E16: 4.5 | F16: 125 | G16: 56
A18: Producto | B18: Producción prevista | C18: 1 | D18: 2 | E18: 3 | F18: 4 | G18: 5
A19: A | B19: 75000 | C19: 112500 | D19: 3750000 | E19: 9000000 | F19: 150000 | G19: 75000
A20: B | B20: 20000 | C20: 16000 | D20: 800000 | E20: 3000000 | F20: 50000 | G20: 0
A21: C | B21: 45000 | C21: 90000 | D21: 1350000 | E21: 4500000 | F21: 0 | G21: 67500
A22: D | B22: 30000 | C22: 30000 | D22: 2100000 | E22: 3600000 | F22: 45000 | G22: 0
A23: Total | B23: =SUM(B19:B22) -> 170000 | C23: =SUM(C19:C22) -> 248500 | D23: =SUM(D19:D22) -> 8000000 | E23: =SUM(E19:E22) -> 20100000 | F23: =SUM(F19:F22) -> 245000 | G23: =SUM(G19:G22) -> 142500
A24: Inventario final | C24: =+D30 -> 41416.667 | D24: =+D31 -> 1333333.3 | E24: =+D32 -> 3350000 | F24: =+D33 -> 40833.333 | G24: =+D34 -> 23750
A25: Inventario inicial | C25: 30000 | D25: 1000000 | E25: 5000000 | F25: 20000 | G25: 30000
A26: MP a comprar | C26: =C23+C24-C25 -> 259916.67 | D26: =D23+D24-D25 -> 8333333.3 | E26: =E23+E24-E25 -> 18450000 | F26: =F23+F24-F25 -> 265833.33 | G26: =G23+G24-G25 -> 136250
A27: Presupuesto | C27: =C26*C16 -> 7797500 | D27: =D26*D16 -> 83333333 | E27: =E26*E16 -> 83025000 | F27: =F26*F16 -> 33229167 | G27: =G26*G16 -> 7630000 | H27: OK
A29: MP | B29: Consumos total | C29: Consumos promedio | D29: Inventario final
A30: 1 | B30: =C23 -> 248500 | C30: =B30/12 -> 20708.333 | D30: =C30*2 -> 41416.667
A31: 2 | B31: =D23 -> 8000000 | C31: =B31/12 -> 666666.67 | D31: =C31*2 -> 1333333.3
A32: 3 | B32: =E23 -> 20100000 | C32: =B32/12 -> 1675000 | D32: =C32*2 -> 3350000
A33: 4 | B33: =F23 -> 245000 | C33: =B33/12 -> 20416.667 | D33: =C33*2 -> 40833.333
A34: 5 | B34: =G23 -> 142500 | C34: =B34/12 -> 11875 | D34: =C34*2 -> 23750

Sheet EJ 10
A1: EJERCICIO 10
A8: Producto | B8: Tiempos (horas cada 1000 unidades producidas) | G8: Producción anual (KG)
B9: Etapa 1 | C9: Etapa 2 | D9: Etapa 3 | E9: Etapa 4 | F9: Etapa 5
A10: Leche | B10: 2 | C10: 1.5 | D10: 0.5 | E10: 1 | G10: 1350000
A11: Queso | B11: 1 | C11: 0.5 | D11: 2 | F11: 1 | G11: 400000
A12: Crema | B12: 1.5 | C12: 1 | E12: 2 | F12: 0.5 | G12: 750000
A13: Costo por hr MOD | B13: 3000 | C13: 3250 | D13: 2750 | E13: 3000 | F13: 3500
A15: Producto | B15: Cantidad a producir | C15: Tiempos (horas cada 1000 unidades producidas) | H15: Total por producto
C16: Etapa 1 | D16: Etapa 2 | E16: Etapa 3 | F16: Etapa 4 | G16: Etapa 5
A17: Leche | B17: =G10/1000 -> 1350 | C17: =B10*$B$17 -> 2700 | D17: =C10*$B$17 -> 2025 | E17: =D10*$B$17 -> 675 | F17: =E10*$B$17 -> 1350 | G17: =F10*$B$17 -> 0 | H17: =+C17*$B$13+D17*$C$13+E17*$D$13+F17*$E$13+G17*$F$13 -> 20587500 | I17: OK
A18: Queso | B18: =G11/1000 -> 400 | C18: =B11*$B$18 -> 400 | D18: =C11*$B$18 -> 200 | E18: =D11*$B$18 -> 800 | F18: =E11*$B$18 -> 0 | G18: =F11*$B$18 -> 400 | H18: =+C18*$B$13+D18*$C$13+E18*$D$13+F18*$E$13+G18*$F$13 -> 5450000 | I18: OK
A19: Crema | B19: =G12/1000 -> 750 | C19: =B12*$B$19 -> 1125 | D19: =C12*$B$19 -> 750 | E19: =D12*$B$19 -> 0 | F19: =E12*$B$19 -> 1500 | G19: =F12*$B$19 -> 375 | H19: =+C19*$B$13+D19*$C$13+E19*$D$13+F19*$E$13+G19*$F$13 -> 11625000 | I19: OK
A20: Total | C20: =SUM(C17:C19) -> 4225 | D20: =SUM(D17:D19) -> 2975 | E20: =SUM(E17:E19) -> 1475 | F20: =SUM(F17:F19) -> 2850 | G20: =SUM(G17:G19) -> 775 | H20: =+C20*$B$13+D20*$C$13+E20*$D$13+F20*$E$13+G20*$F$13 -> 37662500
A21: Costo hs | C21: =C20*B13 -> 12675000 | D21: =D20*C13 -> 9668750 | E21: =E20*D13 -> 4056250 | F21: =F20*E13 -> 8550000 | G21: =G20*F13 -> 2712500 | H21: =SUM(C21:G21) -> 37662500

Sheet EJ 11
A8: PRODUCTO | B8: PRODUCCIÓN
A9: A | B9: 50000
A10: B | B10: 80000
B20: Presupuesto CIF | C20: Base de actividad | D20: Std HM A | E20: Std HM B | F20: Empleados | G20: Total HM A | H20: Total HM B | I20: Total Hr. Maquina
A21: Dpto. Prod 1 | B21: 765000 | C21: HM | D21: 4 | E21: 3 | F21: 40 | G21: =+D21*$B$9 -> 200000 | H21: =+E21*$B$10 -> 240000 | I21: =+((H21+G21)*2)/100 -> 8800
A22: Dpto. Prod 2 | B22: 420000 | C22: HM | D22: 2.5 | E22: 1 | F22: 25 | G22: =+D22*$B$9 -> 125000 | H22: =+E22*$B$10 -> 80000 | I22: =+((H22+G22)*4)/100 -> 8200
A23: Dpto. Servicios Grales | B23: 80000 | C23: # emp | F23: 10
A24: Dpto. De mantenimiento | B24: 175000 | C24: Hs de mant | F24: 5
A26: PRODUCTO A
B27: Ref | C27: Dpto. Servicios Grales | D27: Dpto. De mantenimiento | E27: Dpto. Prod 1 | F27: Dpto. Prod 2 | G27: Costo total
A28: Costos Dptos Directos | C28: =B23 -> 80000 | D28: =B24 -> 175000 | E28: =B21 -> 765000 | F28: =B22 -> 420000 | G28: =SUM(C28:F28) -> 1440000
A29: Asignaciones
B30: Empleados | D30: 5 | E30: 40 | F30: 25 | G30: =SUM(C30:F30) -> 70
A31: Generales | C31: =C28 -> 80000 | D31: =$C$31*D30/$G$30 -> 5714.2857 | E31: =$C$31*E30/$G$30 -> 45714.286 | F31: =$C$31*F30/$G$30 -> 28571.429
B32: Hs mantenimiento | E32: =+I21 -> 8800 | F32: =+I22 -> 8200 | G32: =E32+F32 -> 17000
A33: Mantenimiento | D33: =D28+D31 -> 180714.29 | E33: =$D$33*E32/$G$32 -> 93546.218 | F33: =$D$33*F32/$G$32 -> 87168.067
A34: Total | E34: =E28+E31+E33 -> 904260.5 | F34: =F28+F31+F33 -> 535739.5 | G34: =SUM(E34:F34) -> 1440000
A35: HM deptos | E35: =+G21+H21 -> 440000 | F35: =+G22+H22 -> 205000 | G35: =+F35+E35 -> 645000
A36: CUOTA CIF por HM | E36: =+E34/E35 -> 2.0551375 | F36: =+F34/F35 -> 2.6133634
B39: Std HM
A40: Producto | B40: A | C40: B | D40: CUOTA CIF por HM
A41: Depto 1 | B41: =+D21 -> 4 | C41: =+E21 -> 3 | D41: =+E36 -> 2.0551375
A42: Depto 2 | B42: =+D22 -> 2.5 | C42: =+E22 -> 1 | D42: =+F36 -> 2.6133634
A43: CIF POR PRODUCTO | B43: =+(B41*$D$41)+(B42*$D$42) -> 14.753959 | C43: =+(C41*$D$41)+(C42*$D$42) -> 8.7787759

Sheet EJ 12
A5: Proyección ventas anuales | B5: 504000 | C5: unidades
A6: Inv. Inicial PT | B6: 12000 | C6: unidades
A7: Inv. Final PT | B7: =(B5/12)*0.8 -> 33600 | C7: unidades
A8: Stock inicial MP | B8: 85000 | C8: kg
A9: Stock final MP | B9: 15000 | C9: kg
A11: Ventas distribuidores | B11: 0.7 | C11: =B5*B11 -> 352800 | D11: unidades
A12: Ventas clientes finales | B12: 0.3 | C12: =B5*B12 -> 151200 | D12: unidades
A13: Precio de vta Dist | B13: =B14*0.8 -> 36 | C13: por unidad
A14: Precio de vta clientes f | B14: 45 | C14: por unidad
A17: Costo std. Producto | B17: 15 | C17: unidad
A18: Costo de mp | B18: 7 | C18: el kg
A19: MP por producto | B19: 1.2 | C19: kg
A21: Gastos com y admin | B21: 3650000
A24: PRESUPUESTO DE VENTAS
A26: Distribuidores | B26: Clientes Finales
A27: =C11 -> 352800 | B27: =C12 -> 151200
A28: =B13 -> 36 | B28: =B14 -> 45
A29: =A27*A28 -> 12700800 | B29: =B27*B28 -> 6804000
B30: Total | C30: =B29+A29 -> 19504800
A33: PRESUPUESTO DE PRODUCCIÓN
A35: Volumen de ventas | B35: =B5 -> 504000
A36: Inv final | B36: =B7 -> 33600
A37: Inv inicial | B37: =B6 -> 12000
A38: Producción requerida | B38: =B35+B36-B37 -> 525600
A41: PRESUPUESTO DE COMPRA DE MP
A43: Producción requerida | B43: =B38 -> 525600 | C43: unidades
A44: MP requerida | B44: =B43*B19 -> 630720 | C44: kg
A45: Stock final | B45: =B9 -> 15000 | C45: kg
A46: Stock inicial | B46: =B8 -> 85000 | C46: kg
A47: Compra de MP | B47: =B44+B45-B46 -> 560720 | C47: kg
A48: Presupuesto compra MP | B48: =B47*B18 -> 3925040
A51: UTILIDAD BRUTA PROYECTADA
A53: Utilidad bruta = ventas - costo de la mercadería vendida
A55: Ventas | B55: =C30 -> 19504800
A56: CMV | B56: =B5*B17 -> 7560000
A57: Utilidad bruta | B57: =+B55-B56 -> 11944800

Sheet EJ 13
A4: Inv. Inicial PT | B4: 2200 | C4: unidades
A5: Inv. Final PT | B5: 1500 | C5: unidades
A6: Producción requerida | B6: 28700 | C6: unidades
A7: Consumo std. MP | B7: 3 | C7: kg/unidad
A8: Costo MP | B8: 12 | C8: el kg
A9: Stock MP inicial | B9: =B6*B7*0.1 -> 8610 | C9: kg
A10: Stock MP final | B10: =B6*B7*0.15 -> 12915 | C10: kg
A11: Utilidad Bruta | B11: 216 | C11: por producto
A12: Precio de vta PT | B12: =B11*1/0.6 -> 360
A13: Presupuesto CIF | B13: 229600
A16: PRESUPUESTO DE VENTAS
A18: Unidades Vendidas | B18: =B6+B4-B5 -> 29400
A19: Precio | B19: =B12 -> 360
A20: Total | B20: =B18*B19 -> 10584000
A23: PRESUPUESTO DE COMPRA DE MP
A25: Producción requerida | B25: =B6 -> 28700
A26: MP requerida | B26: =B6*B7 -> 86100
A27: Inv. Final | B27: =B10 -> 12915
A28: Inv. Inicial | B28: =B9 -> 8610
A29: MP a comprar | B29: =B26+B27-B28 -> 90405
A30: Presupuesto compra MP | B30: =B29*B8 -> 1084860
A33: PRESUPUESTO DE MOD
A35: Como no hay turnos ni hs de MOD, uso el cuadro que sale del H.
A37: Costo de MP | B37: =B25*B8*B7 -> 1033200
A38: Costo de MOD | B38: =B40-B39-B37 -> 2870000
A39: Costo CIF | B39: =B13 -> 229600
A40: Costo de producción | B40: =B25*(B12-B11) -> 4132800
A42: CMV
A43: CMV = Costo total producción +Inv final PT- Inv. Inicial PT
A45: CMV= Ventas - Utilidad bruta
A46: CMV | B46: =B20-B18*B11 -> 4233600

Sheet EJ 14
A4: Inv inicial PT | B4: =B14*0.1 -> 5000 | C4: 10% producción requerida
A5: Inv final PT | B5: =B14*0.08 -> 4000 | C5: 8% producción requerida
A6: Unidades vendidas | B6: 51000 | C6: unidades
A7: Hs MOD | B7: 2.5 | C7: hs/PT | D7: Producción requerida = ventas + inv final PT -Inventario inicial
A8: Tarifa MOD | B8: 30 | C8: $/hs | D8: X= ventas +0,08*X-0,1*X
A9: Stock inicial MP | B9: 6000 | C9: kg | D9: Ventas= X - 0,08X+0,1X
A10: Stock final MP | B10: 4000 | C10: kg | D10: Ventas | E10: =1-0.08+0.1 -> 1.02 | F10: X
A11: Precio MP | B11: 5 | C11: el kg | D11: X | E11: =B6/1.02 -> 50000
A12: CMV | B12: 7650000
A13: GIF | B13: 1500000
A14: Producción requerida | B14: =E11 -> 50000
A16: PRESUPUESTO MOD
A18: Hs necesarias MOD | B18: =B14*B7 -> 125000
A19: Presupuesto MOD | B19: =B8*B18 -> 3750000
A22: PRESUPUESTO COMPRA DE MP
F23: Costo unitario de producción | G23: =B12/B6 -> 150
A24: Producción requerida | B24: =B14 -> 50000 | F24: Costo unitario MOD | G24: =+B19/B14 -> 75
A25: MP requerida | B25: =+G29*B24 -> 450000 | F25: Costo unitario GIF | G25: =B13/50000 -> 30
A26: Inv. Final | B26: =B10 -> 4000
A27: Inv. Inicial | B27: =B9 -> 6000 | F27: Costo unitario MP | G27: =G23-G24-G25 -> 45
A28: MP a comprar | B28: =+B25+B26-B27 -> 448000
A29: Presupuesto compra MP | B29: =+B28*B11 -> 2240000 | F29: MP para 1 unidad | G29: =G27/B11 -> 9 | H29: kg | J29: 45 $ | K29: [kg]
J30: 5$/kg
A32: Costo MP
A33: Costo MOD | B33: =B19 -> 3750000
A34: CIF | B34: =B13 -> 1500000
A36: Costo de producción
A38: CMV = Costo total de producción + Inv inicial de PT - Inv final de PT
A39: CMV | B39: =B12 -> 7650000
A40: No tengo el $ del PT

Sheet EJ 15
A1: Ventas Reales
A2: Enero | B2: 50000 | C2: =B2/2 -> 25000 | D2: Margen de utilidad del 100% sobre el costo: significa que si compre a $10, me salio $5
A3: Febrero | B3: 70000 | C3: =B3/2 -> 35000 | D3: Existencia de mcs por 30 días, compra con 1 mes de anticipación
A5: Ventas presupuestadas | B5: Vendo | C5: Compro a | D5: Cobranzas:
A6: Marzo | B6: 65000 | C6: =B6/2 -> 32500 | D6: Vende a crédito a 30 días
A7: Abril | B7: 50000 | C7: =B7/2 -> 25000 | D7: Compra a crédito a 60 días
A8: Mayo | B8: 65000 | C8: =B8/2 -> 32500
A9: Junio | B9: 75000 | C9: =B9/2 -> 37500 | D9: Comisiones a vendedores se pagan en el mes de la venta, 10% sobre ventas
A10: Julio | B10: 60000 | C10: =B10/2 -> 30000
A11: Agosto | B11: 70000 | C11: =B11/2 -> 35000 | D11: Saldo final de caja al 28 de feb es $10000
D12: 10000
A13: Gastos mensuales
A14: Sueldos | B14: 20000
A15: Alquileres | B15: 4000
A16: Amortizaciones | B16: 1000
A17: Servicios | B17: 1000
A18: Seguros | B18: 500
A20: Compro | B20: Vendo | C20: Pago a 60 días | D20: Cobro a 30 días | F20: Ventas presupuestadas
A21: Enero | B21: Febrero | C21: Marzo | D21: Marzo | F21: Marzo | G21: 65000
A22: Febrero | B22: Marzo | C22: Abril | D22: Abril | F22: Abril | G22: 50000
A23: Marzo | B23: Abril | C23: Mayo | D23: Mayo | F23: Mayo | G23: 65000
A24: Abril | B24: Mayo | C24: Junio | D24: Junio | F24: Junio | G24: 75000
A25: Mayo | B25: Junio | C25: Julio | D25: Julio | F25: Julio | G25: 60000
A26: Junio | B26: Julio | C26: Agosto | D26: Agosto | F26: Agosto | G26: 70000
A27: Julio | B27: Agosto | C27: Septiembre | D27: Septiembre
A28: Agosto | B28: Septiembre | C28: Octubre | D28: Octubre
A30: ESTADO DE FLUJO DE EFECTIVO PROYECTADO
A32: c | B32: Marzo | C32: Abril | D32: Mayo | E32: Junio | F32: Julio | G32: Agosto
A33: Fuentes de entrada
A34: Saldo de caja inicial | B34: =D12 -> 10000 | C34: =B45 -> 13000 | D34: =C45 -> 15000 | E34: =D45 -> 8000 | F34: =E45 -> 7500 | G34: =F45 -> 13500
A35: Cobranzas a clientes | B35: =B3 -> 70000 | C35: =B6 -> 65000 | D35: =B7 -> 50000 | E35: =B8 -> 65000 | F35: =B9 -> 75000 | G35: =B10 -> 60000
A36: Efectivo disponible | B36: =SUM(B34:B35) -> 80000 | C36: =SUM(C34:C35) -> 78000 | D36: =SUM(D34:D35) -> 65000 | E36: =SUM(E34:E35) -> 73000 | F36: =SUM(F34:F35) -> 82500 | G36: =SUM(G34:G35) -> 73500 | H36: =SUM(B36:G36) -> 452000
A37: Fuentes de salida
A38: Pagos | B38: =E50 -> 35000 | C38: =F50 -> 32500 | D38: =G50 -> 25000 | E38: =H50 -> 32500 | F38: =I50 -> 37500 | G38: =J50 -> 30000
A39: Comisiones | B39: =B6*0.1 -> 6500 | C39: =B7*0.1 -> 5000 | D39: =B8*0.1 -> 6500 | E39: =B9*0.1 -> 7500 | F39: =B10*0.1 -> 6000 | G39: =B11*0.1 -> 7000 | H39: =SUM(B39:G39) -> 38500
A40: Sueldos | B40: 20000 | C40: 20000 | D40: 20000 | E40: 20000 | F40: 20000 | G40: 20000
A41: Alquileres | B41: 4000 | C41: 4000 | D41: 4000 | E41: 4000 | F41: 4000 | G41: 4000
A42: Servicios | B42: 1000 | C42: 1000 | D42: 1000 | E42: 1000 | F42: 1000 | G42: 1000
A43: Seguros | B43: 500 | C43: 500 | D43: 500 | E43: 500 | F43: 500 | G43: 500
A44: Total salidas de efectivo | B44: =-SUM(B38:B43) -> -67000 | C44: =-SUM(C38:C43) -> -63000 | D44: =-SUM(D38:D43) -> -57000 | E44: =-SUM(E38:E43) -> -65500 | F44: =-SUM(F38:F43) -> -69000 | G44: =-SUM(G38:G43) -> -62500 | H44: =SUM(B44:G44) -> -384000
...

Sheet EJ 16
B1: Ventas reales | C1: Costo
A2: Noviembre | B2: 85000 | C2: =B2/(1+1.6) -> 32692.308
A3: Diciembre | B3: 140000 | C3: =B3/(1+1.6) -> 53846.154
B5: Ventas presupuestadas | C5: Costo | E5: Gastos mensuales
A6: Enero | B6: 120000 | C6: =B6/(1+1.6) -> 46153.846 | E6: Sueldos | F6: 55000
A7: Febrero | B7: 100000 | C7: =B7/(1+1.6) -> 38461.538 | E7: Alquileres | F7: 6000
A8: Marzo | B8: 130000 | C8: =B8/(1+1.6) -> 50000 | E8: Amortizaciones | F8: 2000
A9: Abril | B9: 90000 | C9: =B9/(1+1.6) -> 34615.385 | E9: Servicios | F9: 1000
A10: Mayo | B10: 140000 | C10: =B10/(1+1.6) -> 53846.154 | E10: Seguros | F10: 500
A11: Junio | B11: 110000 | C11: =B11/(1+1.6) -> 42307.692
A12: Julio | B12: 100000 | C12: =B12/(1+1.6) -> 38461.538
A14: Margen de utilidad del 160% sobre el costo
A15: Compra con 1 mes de anticipación
A16: Politica de cobranzas: 40% al contado, 30% a 30 días y 30% a 60 días
A17: Política de pago: 50% al contado y 50% a 60 días
A18: Comisiones a los vendedores en el mes de las ventas y son del 4% sobre las mismas
A19: Caja final al 31 de diciembre es $25.000 | C19: 25000
A21: Se compra con 1 mes de anticipación
A22: Política de pago: 50% al contado y 50% a 60 días
A23: Compras | C23: Octubre | D23: Noviembre | E23: Diciembre | F23: Enero | G23: Febrero | H23: Marzo | I23: Abril | J23: Mayo | K23: Junio | L23: Julio | M23: Agosto
A24: Noviembre | B24: 32692.308 | C24: =B24/2 -> 16346.154 | E24: 16346.154
A25: Diciembre | B25: 53846.154 | D25: =B25/2 -> 26923.077 | F25: =B25/2 -> 26923.077
A26: Enero | B26: 46153.846 | E26: =B26/2 -> 23076.923 | G26: =B26/2 -> 23076.923
A27: Febrero | B27: 38461.538 | F27: =B27/2 -> 19230.769 | H27: =+F27 -> 19230.769
A28: Marzo | B28: 50000 | G28: =+B28/2 -> 25000 | I28: =+G28 -> 25000
A29: Abril | B29: 34615.385 | H29: =+B29/2 -> 17307.692 | J29: =H29 -> 17307.692
A30: Mayo | B30: 53846.154 | I30: =B30/2 -> 26923.077 | K30: 26923.077
A31: Junio | B31: 42307.692 | J31: =B31/2 -> 21153.846 | L31: =J31 -> 21153.846
A32: Julio | B32: 38461.538 | K32: =B32/2 -> 19230.769 | M32: =K32 -> 19230.769
A33: Totales | B33: =SUM(B24:B32) -> 390384.62 | C33: =SUM(C24:C32) -> 16346.154 | D33: =SUM(D24:D32) -> 26923.077 | E33: =SUM(E24:E32) -> 39423.077 | F33: =SUM(F24:F32) -> 46153.846 | G33: =SUM(G24:G32) -> 48076.923 | H33: =SUM(H24:H32) -> 36538.462 | I33: =SUM(I24:I32) -> 51923.077 | ... M33: =SUM(M24:M32) -> 19230.769
A35: Politica de cobranzas: 40% al contado, 30% a 30 días y 30% a 60 días
A36: Cobros | C36: Noviembre | D36: Diciembre | E36: Enero | F36: Febrero | G36: Marzo | H36: Abril | I36: Mayo | J36: Junio | K36: Julio | L36: Agosto | M36: Septiembre
A37: Noviembre | B37: 85000 | C37: =B37*0.4 -> 34000 | D37: =B37*0.3 -> 25500 | E37: =B37*0.3 -> 25500
A38: Diciembre | B38: 140000 | D38: =B38*0.4 -> 56000 | E38: =B38*0.3 -> 42000 | F38: =B38*0.3 -> 42000
A39: Enero | B39: 120000 | E39: =B39*0.4 -> 48000 | F39: =B39*0.3 -> 36000 | G39: =B39*0.3 -> 36000
A40: Febrero | B40: 100000 | F40: =B40*0.4 -> 40000 | G40: =B40*0.3 -> 30000 | H40: =B40*0.3 -> 30000
A41: Marzo | B41: 130000 | G41: =B41*0.4 -> 52000 | H41: =B41*0.3 -> 39000 | I41: =B41*0.3 -> 39000
A42: Abril | B42: 90000 | H42: =B42*0.4 -> 36000 | I42: =B42*0.3 -> 27000 | J42: =B42*0.3 -> 27000
A43: Mayo | B43: 140000 | I43: =B43*0.4 -> 56000 | J43: =B43*0.3 -> 42000 | K43: =B43*0.3 -> 42000
A44: Junio | B44: 110000 | J44: =B44*0.4 -> 44000 | K44: =B44*0.3 -> 33000 | L44: =B44*0.3 -> 33000
...

Sheet EJ 17
A1: De acuerdo al siguiente balance al 31 de diciembre de la empresa analizada en el ejercicio anterior, realizar el balance proyectado al 30 de junio.
A3: BALANCE AL 31-12
A5: ACTIVO | B5: Al 31-12 | C5: Al 31-06
A6: Caja | B6: 25000 | C6: =+'EJ 16'!G62 -> 46592.308
A7: Deudores por ventas | B7: 109500 | C7: =+'EJ 16'!K43+'EJ 16'!K44+'EJ 16'!L44 -> 108000
A8: Mercaderías | B8: 46154 | C8: =+'EJ 16'!B32 -> 38461.538
A9: Bienes de uso | B9: 150000 | C9: =+B9 -> 150000
A10: Amortización acumulada bienes de uso | B10: -30000 | C10: =+B10-'EJ 16'!D71 -> -42000
A11: TOTAL ACTIVO | B11: 300654 | C11: =+SUM(C6:C10) -> 301053.85
A13: PASIVO Y PN
A14: PASIVO
A15: Proveedores | B15: 50000 | C15: =+'EJ 16'!L31+'EJ 16'!M32 -> 40384.615
A16: TOTAL PASIVO | B16: 50000 | C16: =+C15 -> 40384.615
A17: PATRIMONIO NETO
A18: Capital | B18: 200000 | C18: =+B18 -> 200000
A19: Resultados Acumulados | B19: 50654 | C19: =+B19+'EJ 16'!D76 -> 60669.385
A20: TOTAL PN | B20: 260654 | C20: =+SUM(C18:C19) -> 260669.38
A21: PASIVO + PN | B21: 300654 | C21: =+C20+C16 -> 301054

Sheet EJ 18
A4: Ventas presupuestadas
A5: Junio | B5: 50000
A6: Julio | B6: 50000
A7: Agosto | B7: 70000
A8: Septiembre | B8: 60000
A10: Minimo de caja de $4000 al finalizar cada mes del período presupuestado (marzo-agosto)
A11: En caso de estar por debajo se buscará financiamiento externo con TNA del 24% (intereses pagaderos a mes vencido)
A13: Con el Balance al 28 de febrero, presupuestar la caja del semestre, el R. eco del periodo y B. proyectado al 31-08
A15: ACTIVO | B15: Al 29-02
A16: Caja | B16: 10000
A17: Deudores por ventas | B17: 70000
A18: Mercaderías | B18: 32500
A19: Bienes de uso | B19: 200000
A20: Amortización acumulada bienes de uso | B20: -8000
A21: TOTAL ACTIVO | B21: =SUM(B16:B20) -> 304500
A23: PASIVO Y PN
A24: PASIVO
A25: Proveedores | B25: 67500
A26: TOTAL PASIVO | B26: =B25 -> 67500
A27: PATRIMONIO NETO
A28: Capital | B28: 200000
A29: Resultados Acumulados | B29: 37000
A30: TOTAL PN | B30: 237000
A31: PASIVO + PN | B31: =B21 -> 304500
A33: PRESUPUESTO DE CAJA MARZO - AGOSTO
A34: Ventas presupuestadas | B34: Vendo | C34: Compro a | D34: Cobranzas:
A35: Marzo | B35: 65000 | C35: =B35/2 -> 32500 | D35: Vende a crédito a 30 días
A36: Abril | B36: 50000 | C36: =B36/2 -> 25000 | D36: Compra a crédito a 60 días
A37: Mayo | B37: 65000 | C37: =B37/2 -> 32500
A38: Junio | B38: 50000 | C38: =B38/2 -> 25000 | D38: Comisiones a vendedores se pagan en el mes de la venta, 10% sobre ventas
A39: Julio | B39: 50000 | C39: =B39/2 -> 25000
A40: Agosto | B40: 70000 | C40: =B40/2 -> 35000 | D40: Saldo final de caja al 28 de feb es $10000
A41: Septiembre | B41: 60000 | C41: =B41/2 -> 30000 | D41: 10000
A43: Enero | B43: 50000 | C43: =B43/2 -> 25000
A44: Febrero | B44: 70000 | C44: =B44/2 -> 35000
A46: Paga MP a 60 días, se compra lo del mes siguiente
B47: Diciembre | C47: Enero | D47: Febrero | E47: Marzo | F47: Abril | G47: Mayo | H47: Junio | I47: Julio | J47: Agosto | K47: Septiembre
A48: Compra MP | B48: 25000 | C48: 35000 | D48: 32500 | E48: 25000 | F48: =+C37 -> 32500 | G48: =+C38 -> 25000 | H48: =+C39 -> 25000 | I48: =+C40 -> 35000 | J48: =+C41 -> 30000 | K48: 0
A49: Pago MP | B49: 0 | C49: 0 | D49: 25000 | E49: 35000 | F49: 32500 | G49: 25000 | H49: 32500 | I49: =+G48 -> 25000 | J49: =+G48 -> 25000 | K49: =+I48 -> 35000 | L49: 30000
A52: Cobra ventas a 30 días
...

Sheet EJ 19
A1: Aporte de los socios en enero
A2: Efectivo | B2: 300000
A3: B.U | B3: 1500000
B5: Enero | C5: Febrero | D5: Marzo | E5: Abril | H5: Enero | I5: Febrero | J5: Marzo | K5: Abril
A6: Ventas | B6: 500000 | C6: 650000 | D6: 750000 | E6: 450000 | G6: Compra MP | H6: =B6-B6*$H$9 -> 75000 | I6: =C6-C6*$H$9 -> 97500 | J6: =D6-D6*$H$9 -> 112500 | K6: =E6-E6*$H$9 -> 67500
A7: Gastos admin | B7: 150000 | C7: 150000 | D7: 150000 | E7: 150000
A8: Gastos comer | B8: 220000 | C8: 220000 | D8: 220000 | E8: 220000
A9: Amortizaciones | B9: 8000 | C9: 8000 | D9: 8000 | E9: 8000 | G9: Ut bruta | H9: 0.85
G10: Ut bruta= Ventas - CMV
A11: Ut. Bruta s/vtas | B11: 0.85 | G11: CMV = Ventas - Ventas*Ut bruta
A12: Imp a las Gcias | B12: 0.35
A14: Compra mercaderías con un mes de anticipación. La Mc de enero se compra excepcionalmente en enero
A16: Política de pago de Mcs: 60% contado y 40% a 30 días
A17: Política de cobranzas: 50% contado, 30% a 30 días y 20% a 60 días.
A19: PRESUPUESTO DE EFECTIVO
B21: Enero | C21: Febrero | D21: Marzo | E21: Abril
A22: Fuentes de entrada
A23: Saldo de caja inicial | B23: =B2 -> 300000 | C23: =+B31 -> 76500 | D23: =+C31 -> 45000 | E23: =+D31 -> 259500
A24: Cobranzas a clientes | B24: =+C40 -> 250000 | C24: =+D40 -> 475000 | D24: =+E40 -> 670000 | E24: =+F40 -> 580000
A25: Efectivo disponible | B25: =+SUM(B23:B24) -> 550000 | C25: =+SUM(C23:C24) -> 551500 | D25: =+SUM(D23:D24) -> 715000 | E25: =+SUM(E23:E24) -> 839500
A26: Fuentes de salida
A27: Pagos | B27: =C49 -> 103500 | C27: =D49 -> 136500 | D27: =E49 -> 85500 | E27: =F49 -> 27000
A28: G. Admin | B28: =+B7 -> 150000 | C28: =+C7 -> 150000 | D28: =+D7 -> 150000 | E28: =+E7 -> 150000
A29: G. Comer | B29: =+B8 -> 220000 | C29: =+C8 -> 220000 | D29: =+D8 -> 220000 | E29: =+E8 -> 220000
A30: Total salidas de efectivo | B30: =+SUM(B27:B29) -> 473500 | C30: =+SUM(C27:C29) -> 506500 | D30: =+SUM(D27:D29) -> 455500 | E30: =+SUM(E27:E29) -> 397000
A31: SALDO DE CAJA FINAL | B31: =+B25-B30 -> 76500 | C31: =+C25-C30 -> 45000 | D31: =+D25-D30 -> 259500 | E31: =+E25-E30 -> 442500
D32: Saldo final al 31-03
A34: Política de cobranzas: 50% contado, 30% a 30 días y 20% a 60 días.
A35: Cobros | C35: Enero | D35: Febrero | E35: Marzo | F35: Abril | G35: Mayo | H35: Junio
A36: Enero | B36: =+B6 -> 500000 | C36: =+B36/2 -> 250000 | D36: =B36*0.3 -> 150000 | E36: =B36*0.2 -> 100000 | J36: Deudores por ventas al 31/3 | K36: =+F38+G38+F37 -> 505000
A37: Febrero | B37: =+C6 -> 650000 | D37: =+B37/2 -> 325000 | E37: =B37*0.3 -> 195000 | F37: =B37*0.2 -> 130000
A38: Marzo | B38: =+D6 -> 750000 | E38: =+B38/2 -> 375000 | F38: =B38*0.3 -> 225000 | G38: =B38*0.2 -> 150000
A39: Abril | B39: =+E6 -> 450000 | F39: =+B39/2 -> 225000 | G39: =B39*0.3 -> 135000 | H39: =B39*0.2 -> 90000
A40: Totales | B40: =SUM(B36:B39) -> 2350000 | C40: =SUM(C36:C39) -> 250000 | D40: =SUM(D36:D39) -> 475000 | E40: =SUM(E36:E39) -> 670000 | F40: =SUM(F36:F39) -> 580000 | G40: =SUM(G36:G39) -> 285000 | H40: =SUM(H36:H39) -> 90000
A43: Política de pago de Mcs: 60% contado y 40% a 30 días
A44: Pagos de MP | C44: Enero | D44: Febrero | E44: Marzo | F44: Abril | G44: Mayo
A45: Enero | B45: =+H6 -> 75000 | C45: =(+B45+B46)*0.6 -> 103500 | D45: =(+B45+B46)*0.4 -> 69000 | J45: Proveedores al 31/3 | K45: =+F47 -> 27000
A46: Febrero | B46: =+I6 -> 97500 | D46: =+B47*0.6 -> 67500 | E46: =+B47*0.4 -> 45000
A47: Marzo | B47: =+J6 -> 112500 | E47: =+B48*0.6 -> 40500 | F47: =+B48*0.4 -> 27000
A48: Abril | B48: =+K6 -> 67500 | J48: Mercaderías al 31/3 | K48: =+B48 -> 67500
...

Sheet EJ 20
A1: La empresa MNO terminó el año con la siguiente situación patrimonial
A3: ACTIVO | C3: PASIVO
A4: Caja | B4: 800000 | C4: Proveedores | D4: 628571
A5: Deudores x vtas | B5: 600000 | C5: TOTAL PASIVO | D5: 628571
A6: Mcs | B6: 628571 | C6: PATRIMONIO NETO
A7: B.U | B7: 1500000 | C7: Capital | D7: 1500000
A8: Amort. B.U | B8: -80000 | C8: Resultados acumulados | D8: 1320000
A9: TOTAL ACTIVO | B9: 3448571 | C9: TOTAL PN | D9: 2820000
C10: PASIVO + PN | D10: 3448571
B12: Enero | C12: Febrero | D12: Marzo | E12: Abril | F12: Mayo
A13: Ventas | B13: 1100000 | C13: 900000 | D13: 1400000 | E13: 1100000 | F13: 1300000
A14: Compra MP | B14: =+B13/(1+0.75) -> 628571.43 | C14: =+C13/(1+0.75) -> 514285.71 | D14: =+D13/(1+0.75) -> 800000 | E14: =+E13/(1+0.75) -> 628571.43 | F14: =+F13/(1+0.75) -> 742857.14
A15: G. comer | B15: 160000 | C15: 160000 | D15: 160000 | E15: 160000 | F15: 160000
A16: G admin | B16: 210000 | C16: 210000 | D16: 210000 | E16: 210000 | F16: 210000
A17: Amortizaciones | B17: 4000 | C17: 4000 | D17: 4000 | E17: 4000 | F17: 4000
A19: Datos:
A20: Mg utilidad s/costo | B20: 0.75 | C20: =1-0.75 -> 0.25
A21: Inventarios | B21: 30 días
A22: Política de cobros: contado 40%, 30% a 30 días y 30% a 60 días
A23: Política de pagos: contado 70%, 30% a 60 días.
A24: El saldo de créditos por ventas al 31-12 se estima cobrar en febrero su totalidad
A25: El saldo total de deuda con proveedores al 31-12 se estima pagar en marzo
A26: Los gastos se pagan en el mes de devengamiento
A27: Comisiones vendedor | B27: 0.03 | C27: Se pagan al mes siguiente de la venta
A28: Impuesto a las G. | B28: 0.35
A30: Determinar el balance proyectado al 30 de abril
A32: PRESUPUESTO DE EFECTIVO PROYECTADO
B33: Enero | C33: Febrero | D33: Marzo | E33: Abril | F33: Mayo
A34: Fuentes de entrada
A35: Saldo de caja inicial | B35: =+B4 -> 800000 | C35: =+B44 -> 510000 | D35: =+C44 -> 837000 | E35: =+D44 -> 377143.29 | F35: =+E44 -> 335143.29
A36: Cobranzas a clientes | B36: =+C53 -> 440000 | C36: =+B5+D53 -> 1290000 | D36: =+E53 -> 1160000 | E36: =+F53 -> 1130000 | F36: =+G53 -> 1270000
A37: Efectivo disponible | B37: =SUM(B35:B36) -> 1240000 | C37: =SUM(C35:C36) -> 1800000 | D37: =SUM(D35:D36) -> 1997000 | E37: =SUM(E35:E36) -> 1507143.3 | F37: =SUM(F35:F36) -> 1605143.3
A38: Fuentes de salida
A39: Pagos | B39: =+C62 -> 360000 | C39: =+D62 -> 560000 | D39: =+E62+D4 -> 1222856.7 | E39: =+F62 -> 760000 | F39: =+G62 -> 188571.43
A40: Comisiones | B40: 0 | C40: =+B13*$B$27 -> 33000 | D40: =+C13*$B$27 -> 27000 | E40: =+D13*$B$27 -> 42000 | F40: =+E13*$B$27 -> 33000
A41: G. Admin | B41: =+B16 -> 210000 | C41: =+C16 -> 210000 | D41: =+D16 -> 210000 | E41: =+E16 -> 210000 | F41: =+F16 -> 210000
A42: G. Comer | B42: =B15 -> 160000 | C42: =C15 -> 160000 | D42: =D15 -> 160000 | E42: =E15 -> 160000 | F42: =F15 -> 160000
A43: Total salidas de efectivo | B43: =+SUM(B39:B42) -> 730000 | C43: =+SUM(C39:C42) -> 963000 | D43: =+SUM(D39:D42) -> 1619856.7 | E43: =+SUM(E39:E42) -> 1172000 | F43: =+SUM(F39:F42) -> 591571.43
A44: SALDO DE CAJA FINAL | B44: =+B37-B43 -> 510000 | C44: =+C37-C43 -> 837000 | D44: =+D37-D43 -> 377143.29 | E44: =+E37-E43 -> 335143.29 | F44: =+F37-F43 -> 1013571.9
A46: Política de cobros: contado 40%, 30% a 30 días y 30% a 60 días
...

Sheet EJ 21
A1: Aporte socios en enero
A2: Caja | B2: 1000000
A3: BU | B3: 700000
B5: Enero | C5: Febrero | D5: Marzo | E5: Abril
A6: Ventas | B6: 3400000 | C6: 2800000 | D6: 3100000 | E6: 4000000
A7: Costo de MP | B7: =+B6*0.15 -> 510000 | C7: =+C6*0.15 -> 420000 | D7: =+D6*0.15 -> 465000 | E7: =+E6*0.15 -> 600000
A8: G. Admin | B8: 380000 | C8: 380000 | D8: 380000 | E8: 380000
A9: G. Comer | B9: 1250000 | C9: 1250000 | D9: 1250000 | E9: 1250000
A10: Amortizaciones | B10: 15000 | C10: 15000 | D10: 15000 | E10: 15000
A12: Compra de Mcs con 1 mes de anticipación. La mercadería en enero se compra ese mismo mes excepción.
A13: Política de cobranzas: 30% contado y 70% a 30 días
A14: Política de pago de mcs: 40% al contado y 60% a 60 días
A15: Si el saldo de caja supera los $2.000.000 los excedentes se depositan a PF | F15: TNA | G15: 0.36
A17: IIGG devengado | B17: 0.35
A18: Ut. Bruta s/vtas | B18: 0.85
A20: Determinar el balance proyectado al 31 de marzo
B22: Enero | C22: Febrero | D22: Marzo | E22: Abril
A23: Fuentes de entrada
A24: Saldo de caja inicial | B24: =+B2 -> 1000000 | C24: =+B32 -> 18000 | D24: =+C32 -> 1422000 | E24: =+D32 -> 1884000
A25: Cobranzas a clientes | B25: =+C41 -> 1020000 | C25: =+D41 -> 3220000 | D25: =+E41 -> 2890000 | E25: =+F41 -> 3370000
A26: Efectivo disponible | B26: =SUM(B24:B25) -> 2020000 | C26: =SUM(C24:C25) -> 3238000 | D26: =SUM(D24:D25) -> 4312000 | E26: =SUM(E24:E25) -> 5254000
A27: Fuentes de salida
A28: Pagos | B28: =+C50 -> 372000 | C28: =+D50 -> 186000 | D28: =+E50 -> 798000 | E28: =+F50 -> 279000
A29: G. Admin | B29: =+B8 -> 380000 | C29: =+C8 -> 380000 | D29: =+D8 -> 380000 | E29: =+E8 -> 380000
A30: G. Comer | B30: =+B9 -> 1250000 | C30: =+C9 -> 1250000 | D30: =+D9 -> 1250000 | E30: =+E9 -> 1250000
A31: Total salidas de efectivo | B31: =+SUM(B28:B30) -> 2002000 | C31: =+SUM(C28:C30) -> 1816000 | D31: =+SUM(D28:D30) -> 2428000 | E31: =+SUM(E28:E30) -> 1909000
A32: SALDO DE CAJA FINAL | B32: =+B26-B31 -> 18000 | C32: =+C26-C31 -> 1422000 | D32: =+D26-D31 -> 1884000 | E32: =+E26-E31 -> 3345000
A35: Política de cobranzas: 30% contado y 70% a 30 días
A36: Cobros | C36: Enero | D36: Febrero | E36: Marzo | F36: Abril | G36: Mayo
A37: Enero | B37: =+B6 -> 3400000 | C37: =+B37*0.3 -> 1020000 | D37: =+B37*0.7 -> 2380000 | I37: Créditos al 31-03 | J37: =+F39 -> 2170000
A38: Febrero | B38: =+C6 -> 2800000 | D38: =+B38*0.3 -> 840000 | E38: =+B38*0.7 -> 1960000
A39: Marzo | B39: =+D6 -> 3100000 | E39: =+B39*0.3 -> 930000 | F39: =+B39*0.7 -> 2170000
A40: Abril | B40: =+E6 -> 4000000 | F40: =+B40*0.3 -> 1200000 | G40: =+B40*0.7 -> 2800000
A41: Totales | B41: =SUM(B37:B40) -> 13300000 | C41: =SUM(C37:C40) -> 1020000 | D41: =SUM(D37:D40) -> 3220000 | E41: =SUM(E37:E40) -> 2890000 | F41: =SUM(F37:F40) -> 3370000 | G41: =SUM(G37:G40) -> 2800000
A44: Política de pago de mcs: 40% al contado y 60% a 60 días
A45: Pagos de MP | C45: Enero | D45: Febrero | E45: Marzo | F45: Abril | G45: Mayo
A46: Enero | B46: =+B7 -> 510000 | C46: =+B46*0.4+B47*0.4 -> 372000 | E46: =+B46*0.6+B47*0.6 -> 558000
A47: Febrero | B47: =+C7 -> 420000 | D47: =+B48*0.4 -> 186000 | F47: =+B48*0.6 -> 279000
A48: Marzo | B48: =+D7 -> 465000 | E48: =+B49*0.4 -> 240000 | G48: =+B49*0.6 -> 360000 | I48: Mcs al 31-03 | J48: =+B49 -> 600000
A49: Abril | B49: =+E7 -> 600000
...

Sheet EJ REPASO
B1: Enero | C1: Febrero | D1: Marzo | H1: Depto 1 | I1: Depto 2
A2: Ventas | B2: 30000 | C2: 40000 | D2: 60000 | E2: unidades | G2: Hs MOD/PT | H2: 0.5 | I2: 1
A3: Inv final (PT) | B3: =+B2*0.5 -> 15000 | C3: =+C2*0.5 -> 20000 | D3: =+D2*0.5 -> 30000 | E3: unidades | G3: $/hr | H3: 6 | I3: 5
A4: Inv inicial (PT) | B4: 14000 | C4: 15000 | D4: 20000 | E4: unidades | G4: CIF mensual | H4: =70000*0.9 -> 63000 | I4: =50000*(1-6%) -> 47000
A5: Ventas Bs. As | B5: =+B2*0.6 -> 18000 | C5: =+C2*0.6 -> 24000 | D5: =+D2*0.6 -> 36000 | E5: unidades | G5: Amort CIF | H5: =70000*0.1 -> 7000 | I5: =50000*0.06 -> 3000
A6: Ventas Cordoba | B6: =+B2*0.4 -> 12000 | C6: =+C2*0.4 -> 16000 | D6: =+D2*0.4 -> 24000 | E6: unidades
B8: Precio de Vta | H8: Mensual | K8: Producción | L8: 250 | M8: m2
A9: Bs As | B9: 70 | G9: Gastos generales | H9: =50000*0.9 -> 45000 | I9: Se distribuye según m2 | K9: Comer | L9: 100 | M9: m2
A10: Cordoba | B10: =+B9*(1+4%) -> 72.8 | G10: Amort. G.G | H10: =50000*0.1 -> 5000 | K10: Admin | L10: 150 | M10: m2
G11: G admin | H11: =150000*(1-2%) -> 147000
B12: MP A | C12: MP B | G12: Amort. G.Adm | H12: =150000-H11 -> 3000
A13: PT | B13: 2.5 | C13: 4 | G13: G. Comer | H13: =100000*0.95 -> 95000
A14: Inv inicial MP | B14: 50000 | C14: 60000 | G14: Amort G. Comer | H14: =100000-H13 -> 5000
A15: Inv final MP | B15: =+B14/2 -> 25000 | C15: =+C14/2 -> 30000
A16: Costo | B16: 2.5 | C16: 6
A18: IIGG | B18: 0.35
A19: Política de cobranzas: 50% contado, 25% a 30 días y 25% a 60 días. El saldo anterior de créditos se prevé cobrar en enero
A20: Política de pago de MP: 80% al conatdo y 20% a 30 días. El saldo anterior de proveedores se prevé pagar en enero
A21: Los sueldos de MOD se pagan a mes vencido. Los gastos en su mes de devengamiento.
A22: Durante el trimestre el único pago a realizar por IMPUESTOS es de $150.000 en febrero
A24: BALANCE AL 31-12
A25: ACTIVO | C25: PASIVO
A26: Activo corriente | B26: =+SUM(B27:B31) -> 2562212 | C26: Pasivo corriente | D26: =+SUM(D27:D30) -> 1100000
A27: Caja | B27: 1000000 | C27: Proveedores | D27: 450000
A28: Créditos por ventas | B28: 500000 | C28: Sueldos a pagar | D28: 500000
A29: Inventario MP | B29: 485000 | C29: IIGG a pagar | D29: 150000
A30: Inventario PT | B30: 577212 | C30: Otros | D30: 0
A31: Otros | B31: 0 | C31: Pasivo no corriente | D31: =+SUM(D32:D33) -> 0
A32: Activo no corriente | B32: =+SUM(B33:B35) -> 2300000 | C32: Docs a pagar | D32: 0
A33: Propiedad, planta, equipo | B33: 3000000 | C33: Otros | D33: 0
A34: Depreciación acum. | B34: -700000 | C34: TOTAL PASIVO | D34: =+D31+D26 -> 1100000
A35: Otros | B35: 0 | C35: PATRIMONIO NETO
A36: TOTAL ACTIVO | B36: =+B26+B32 -> 4862212 | C36: Capital social | D36: 2500000
C37: Utilidades ret. | D37: 1262212
C38: TOTAL PN | D38: =+D36+D37 -> 3762212
C39: TOTAL PASIVO + PN | D39: =+D38+D34 -> 4862212
B42: Enero | C42: Febrero | D42: Marzo
A43: Ventas | B43: 30000 | C43: 40000 | D43: 60000 | E43: unidades
A44: Ventas Bs As | B44: 18000 | C44: 24000 | D44: 36000 | E44: unidades
A45: Ventas Cba | B45: 12000 | C45: 16000 | D45: 24000 | E45: unidades
...

Sheet EJ REPASO 2
A1: PRESUPUESTO DE VENTAS
B2: Enero | C2: Febrero | D2: Marzo
A3: Ventas totales | B3: 30000 | C3: 40000 | D3: 60000
A4: Ventas Bs As | B4: =+B3*0.6 -> 18000 | C4: =+C3*0.6 -> 24000 | D4: =+D3*0.6 -> 36000
A5: Ventas Cba | B5: =+B3*0.4 -> 12000 | C5: =+C3*0.4 -> 16000 | D5: =+D3*0.4 -> 24000
A6: Precio de venta
A7: Bs As | B7: 70 | C7: 70 | D7: 70
A8: Cba | B8: =+B7*(1+4%) -> 72.8 | C8: =+C7*(1+4%) -> 72.8 | D8: =+D7*(1+4%) -> 72.8
A9: Importes
A10: Bs As | B10: =+B7*B4 -> 1260000 | C10: =+C7*C4 -> 1680000 | D10: =+D7*D4 -> 2520000
A11: Cba | B11: =+B8*B5 -> 873600 | C11: =+C8*C5 -> 1164800 | D11: =+D8*D5 -> 1747200
A12: Total | B12: =+B10+B11 -> 2133600 | C12: =+C10+C11 -> 2844800 | D12: =+D10+D11 -> 4267200
A14: PROGRAMA DE PRODUCCIÓN
B15: Enero | C15: Febrero | D15: Marzo | E15: Total
A16: Ventas | B16: =+B3 -> 30000 | C16: =+C3 -> 40000 | D16: =+D3 -> 60000 | E16: =+SUM(B16:D16) -> 130000
A17: Inventario Final | B17: =+B16*0.5 -> 15000 | C17: =+C16*0.5 -> 20000 | D17: =+D16*0.5 -> 30000 | E17: =+SUM(B17:D17) -> 65000
A18: Inventario inicial | B18: 14000 | C18: =+B17 -> 15000 | D18: =+C17 -> 20000 | E18: =+SUM(B18:D18) -> 49000
A19: Producción req. | B19: =+B16+B17-B18 -> 31000 | C19: =+C16+C17-C18 -> 45000 | D19: =+D16+D17-D18 -> 70000 | E19: =+SUM(B19:D19) -> 146000
A21: PRESUPUESTO DE MATERIAS PRIMAS
B22: Enero | C22: Febrero | D22: Marzo | E22: Total
A23: Producción req. | B23: =+B19 -> 31000 | C23: =+C19 -> 45000 | D23: =+D19 -> 70000 | E23: =+SUM(B23:D23) -> 146000
A24: Material A | B24: 2.5 | C24: 2.5 | D24: 2.5
A25: Material B | B25: 4 | C25: 4 | D25: 4
A27: MP requerida | B27: =+B29+B28 -> 201500 | C27: =+C29+C28 -> 292500 | D27: =+D29+D28 -> 455000 | E27: =+SUM(B27:D27) -> 949000
A28: Material A | B28: =+B23*B24 -> 77500 | C28: =+C23*C24 -> 112500 | D28: =+D23*D24 -> 175000 | E28: =+SUM(B28:D28) -> 365000
A29: Material B | B29: =+B23*B25 -> 124000 | C29: =+C23*C25 -> 180000 | D29: =+D23*D25 -> 280000 | E29: =+SUM(B29:D29) -> 584000
A31: Material A | B31: Enero | C31: Febrero | D31: Marzo | E31: Total
A32: MP Requerida | B32: =+B28 -> 77500 | C32: =+C28 -> 112500 | D32: =+D28 -> 175000 | E32: =+SUM(B32:D32) -> 365000
A33: Inv. Final | B33: =+B32*0.5 -> 38750 | C33: =+C32*0.5 -> 56250 | D33: =+D32*0.5 -> 87500 | E33: =+SUM(B33:D33) -> 182500
A34: Inv. Inicial | B34: 50000 | C34: =+B33 -> 38750 | D34: =+C33 -> 56250 | E34: =+SUM(B34:D34) -> 145000
A35: MP a comprar | B35: =+B32+B33-B34 -> 66250 | C35: =+C32+C33-C34 -> 130000 | D35: =+D32+D33-D34 -> 206250 | E35: =+SUM(B35:D35) -> 402500
A36: Costo unitario | B36: 2.5 | C36: 2.5 | D36: 2.5
A37: Compras MP | B37: =+B35*B36 -> 165625 | C37: =+C35*C36 -> 325000 | D37: =+D35*D36 -> 515625 | E37: =+SUM(B37:D37) -> 1006250
A39: Material B | B39: Enero | C39: Febrero | D39: Marzo | E39: Total
A40: MP Requerida | B40: =+B29 -> 124000 | C40: =+C29 -> 180000 | D40: =+D29 -> 280000 | E40: =+SUM(B40:D40) -> 584000
A41: Inv. Final | B41: =+B40*0.5 -> 62000 | C41: =+C40*0.5 -> 90000 | D41: =+D40*0.5 -> 140000 | E41: =+SUM(B41:D41) -> 292000
A42: Inv. Inicial | B42: 60000 | C42: =+B41 -> 62000 | D42: =+C41 -> 90000 | E42: =+SUM(B42:D42) -> 212000
A43: MP a comprar | B43: =+B40+B41-B42 -> 126000 | C43: =+C40+C41-C42 -> 208000 | D43: =+D40+D41-D42 -> 330000 | E43: =+SUM(B43:D43) -> 664000
A44: Costo unitario | B44: 6 | C44: 6 | D44: 6
A45: Compras MP | B45: =+B43*B44 -> 756000 | C45: =+C43*C44 -> 1248000 | D45: =+D43*D44 -> 1980000 | E45: =+SUM(B45:D45) -> 3984000
...

Sheet Hoja1
