Workbook

Sheet 0. Capacidades x hora - turno
A1: NECESIDAD ANUAL MP | O1: NECESIDAD ANUAL MP
A2: Sección Operativa | B2: Alimentación | C2: Agregado | D2: Desperdicios | H2: Producción | I2: Capacidad kg/ciclo | J2: Ciclos /turno | K2: Capacidad real (kg/h) | L2: Hs activas/turno | O2: Sección Operativa | P2: Alimentación | Q2: Agregado | R2: Desperdicios | V2: Producción
D3: Recuperable | F3: No recuperable | R3: Recuperable | T3: No recuperable
A4: Amasado | B4: =+H4/(1-D4-F4) -> 601.74234 | C4: - | E4: =+B4*D4 -> 0 | H4: =+B5 -> 601.74234 | I4: 50 | J4: =+H4/I4 -> 12.034847 | K4: 212.15 | L4: =+H4/K4 -> 2.8364004 | O4: Amasado | P4: =+B4/8 -> 75.217792 | Q4: - | S4: =+P4*R4 -> 0 | V4: =+P5 -> 75.217792
A5: Moldeado | B5: =+H5/(1-D5-F5) -> 601.74234 | C5: - | D5: 0.01 | E5: =+B5*D5 -> 6.0174234 | F5: 0.01 | G5: =+F5*B5 -> 6.0174234 | H5: =+B6 -> 589.70749 | I5: - | K5: 120 | L5: =+H5/K5 -> 4.9142291 | O5: Moldeado | P5: =+B5/8 -> 75.217792 | Q5: - | R5: 0.01 | S5: =+P5*R5 -> 0.75217792 | T5: 0.01 | U5: =+T5*P5 -> 0.75217792 | V5: =+P6 -> 73.713436
A6: Horneado | B6: =+H6/(1-D6-F6) -> 589.70749 | C6: - | E6: =+B6*D6 -> 0 | F6: 0.07 | G6: =+F6*B6 -> 41.279524 | H6: =+B7 -> 548.42796 | I6: - | K6: 81.8 | L6: =+H6/K6 -> 6.7044983 | O6: Horneado | P6: =+B6/8 -> 73.713436 | Q6: - | S6: =+P6*R6 -> 0 | T6: 0.07 | U6: =+T6*P6 -> 5.1599405 | V6: =+P7 -> 68.553496
A7: Enfriado | B7: =+H7/(1-D7-F7) -> 548.42796 | C7: - | D7: 0.04 | E7: =+B7*D7 -> 21.937119 | F7: 0.01 | G7: =+F7*B7 -> 5.4842797 | H7: =+B8 -> 521.00657 | I7: - | K7: 80.3 | L7: =+H7/K7 -> 6.4882511 | O7: Enfriado | P7: =+B7/8 -> 68.553496 | Q7: - | R7: 0.04 | S7: =+P7*R7 -> 2.7421398 | T7: 0.01 | U7: =+T7*P7 -> 0.68553496 | V7: =+P8 -> 65.125821
A8: Fraccionado | B8: =+H8/(1-D8-F8) -> 521.00657 | C8: - | E8: =+B8*D8 -> 0 | G8: =+F8*B8 -> 0 | H8: =+B9 -> 521.00657 | I8: - | K8: - | O8: Fraccionado | P8: =+B8/8 -> 65.125821 | Q8: - | S8: =+P8*R8 -> 0 | U8: =+T8*P8 -> 0 | V8: =+P9 -> 65.125821
A9: Envasado primario | B9: =+H9/(1-D9-F9) -> 521.00657 | C9: - | D9: 0.04 | E9: =+B9*D9 -> 20.840263 | G9: =+F9*B9 -> 0 | H9: =+B10 -> 500.1663 | K9: 248.4 | L9: =+H9/K9 -> 2.0135519 | O9: Envasado primario | P9: =+B9/8 -> 65.125821 | Q9: - | R9: 0.04 | S9: =+P9*R9 -> 2.6050328 | U9: =+T9*P9 -> 0 | V9: =+P10 -> 62.520788
A10: Envasado secundario | B10: =+H10/(1-D10-F10) -> 500.1663 | C10: - | H10: =+B11 -> 500.1663 | K10: - | O10: Envasado secundario | P10: =+B10/8 -> 62.520788 | Q10: - | V10: =+P11 -> 62.520788
A11: Paletizado | B11: =+H11/(1-D11-F11) -> 500.1663 | C11: - | H11: =+H12 -> 500.1663 | K11: - | O11: Paletizado | P11: =+B11/8 -> 62.520788 | Q11: - | V11: =+V12
A12: TOTALES | B12: =+B4 -> 601.74234 | C12: - | E12: =+SUM(E4:E11) -> 48.794805 | G12: =+SUM(G4:G11) -> 52.781227 | H12: =+'2. PCP - Programa & Lotes'!C26 -> 500.1663 | O12: TOTALES | P12: =+P4 -> 75.217792 | Q12: - | S12: =+SUM(S4:S11) -> 6.0993506 | U12: =+SUM(U4:U11) -> 6.5976534 | V12: =+'2. PCP - Programa & Lotes'!P26
A14: Desperdicio total | B14: 0.168803 | G14: Desvios | H14: 0 | O14: Desperdicio total | P14: 0.168803 | U14: Desvios | V14: 0
A15: Desperdicio no recuperable | B15: 0.087714 | C15: 0.912286 | J15: =B4+B21 -> 1153.1664 | K15: =J15-120 -> 1033.1664 | O15: Desperdicio no recuperable | P15: 0.087714 | Q15: 0.912286
A17: Linea B - Panificados | O17: Linea B - Panificados
A18: NECESIDAD ANUAL MP | O18: NECESIDAD ANUAL MP
A19: Sección Operativa | B19: Alimentación | C19: Agregado | D19: Desperdicios | H19: Producción | I19: Capacidad/ciclo | J19: Ciclos /turno | K19: Capacidad real (kg/h) | L19: Hs activas/turno | O19: Sección Operativa | P19: Alimentación | Q19: Agregado | R19: Desperdicios | V19: Producción
D20: Recuperable | F20: No recuperable | R20: Recuperable | T20: No recuperable
A21: Batido | B21: =+H21/(1-D21-F21) -> 551.42408 | C21: - | E21: - | G21: - | H21: =+B22 -> 551.42408 | I21: 37.5 | J21: =+ROUNDUP(H21/I21,0) -> 15 | K21: =+F57 -> 95.625 | L21: =+H21/K21 -> 5.7665263 | O21: Batido | P21: =+B21/8 -> 68.92801 | Q21: - | S21: - | U21: - | V21: =+P22 -> 68.92801
A22: Dosificado | B22: =+H22/(1-D22-F22) -> 551.42408 | C22: - | E22: - | G22: =+F22*B22 -> 0 | H22: =+B23/0.4 -> 551.42408 | J22: =(H22*0.4/0.4+H22*0.6/0.18) -> 2389.5044 | K22: =+F58 -> 100.1784 | L22: =+H22/K22 -> 5.5044209 | O22: Dosificado | P22: =+B22/8 -> 68.92801 | Q22: - | S22: - | U22: =+T22*P22 -> 0 | V22: =+P23/0.4 -> 68.92801
A23: Fermentado | B23: =+H23/(1-D23-F23) -> 220.56963 | C23: - | E23: - | G23: =+F23*B23 -> 0 | H23: =+B24*0.4 -> 220.56963 | K23: =+F59 -> 40.608 | L23: =+H23/K23 -> 5.4316793 | O23: Fermentado | P23: =+B23/8 -> 27.571204 | Q23: - | S23: - | U23: =+T23*P23 -> 0 | V23: =+P24*0.4 -> 27.571204
A24: Horneado | B24: =+H24/(1-D24-F24) -> 551.42408 | C24: - | E24: - | F24: 0.13 | G24: =+F24*B24 -> 71.685131 | H24: =+B25 -> 479.73895 | I24: =+F60 -> 40.608 | J24: =+ROUNDUP(H24/I24,0) -> 12 | K24: =+F60*2 -> 81.216 | L24: =+H24/K24 -> 5.9069512 | O24: Horneado | P24: =+B24/8 -> 68.92801 | Q24: - | S24: - | T24: 0.13 | U24: =+T24*P24 -> 8.9606413 | V24: =+P25 -> 59.967369
A25: Desmolde | B25: =+H25/(1-D25-F25) -> 479.73895 | C25: - | E25: - | G25: =+F25*B25 -> 0 | H25: =+B26 -> 479.73895 | K25: - | L25: - | O25: Desmolde | P25: =+B25/8 -> 59.967369 | Q25: - | S25: - | U25: =+T25*P25 -> 0 | V25: =+P26 -> 59.967369
A26: Enfriado | B26: =+H26/(1-D26-F26) -> 479.73895 | C26: - | E26: - | F26: 0.07 | G26: =+F26*B26 -> 33.581727 | H26: =+B27 -> 446.15722 | K26: - | L26: - | O26: Enfriado | P26: =+B26/8 -> 59.967369 | Q26: - | S26: - | T26: 0.07 | U26: =+T26*P26 -> 4.1977158 | V26: =+P27 -> 55.769653
A27: Envasado primario | B27: =+H27/(1-D27-F27) -> 446.15722 | C27: - | E27: - | G27: =+F27*B27 -> 0 | H27: =+B28 -> 446.15722 | K27: =+F61 -> 136.68 | L27: =+H27/K27 -> 3.2642466 | O27: Envasado primario | P27: =+B27/8 -> 55.769653 | Q27: - | S27: - | U27: =+T27*P27 -> 0 | V27: =+P28 -> 55.769653
A28: Envasado secundario | B28: =+H28/(1-D28-F28) -> 446.15722 | C28: - | E28: - | G28: =+F28*B28 -> 0 | H28: =+H29 -> 446.15722 | K28: - | O28: Envasado secundario | P28: =+B28/8 -> 55.769653 | Q28: - | S28: - | U28: =+T28*P28 -> 0 | V28: =+V29
A29: TOTALES | B29: =+B21 -> 551.42408 | C29: - | E29: - | G29: =+SUM(G21:G28) -> 105.26686 | H29: =+'2. PCP - Programa & Lotes'!D26 -> 446.15722 | O29: TOTALES | P29: =+P21 -> 68.92801 | Q29: - | S29: - | U29: =+SUM(U21:U28) -> 13.158357 | V29: =+'2. PCP - Programa & Lotes'!Q26
F32: =B21*0.22 -> 121.3133 | G32: =F32/15 -> 8.0875532
K33: =+H29*0.4 -> 178.46289 | L33: =+K33/0.18 -> 991.4605
K34: =+H29*0.6 -> 267.69433 | L34: =+K34/0.4 -> 669.23584 | O34: BATIDORA PLANETARIA | T34: AMASADORA
I35: =2390/7 -> 341.42857 | J35: =I35/60 -> 5.6904762 | L35: =+SUM(L33:L34)/8 -> 207.58704 | O35: CAPACIDAD | T35: CAPACIDAD
J36: =H22*0.4 -> 220.56963 | O36: Capacidad máxima (kg) | Q36: 37.5 | T36: Capacidad máxima (kg) | V36: 50
O37: Tiempo batido prom (h) | Q37: 0.33 | T37: Tiempo amasado prom (h) | V37: 0.2
O38: Capacidad teórica (kg/h) | Q38: 112.5 | T38: Capacidad teórica (kg/h) | V38: 250
A41: Linea A - Galletitas
A42: CAPACIDAD REAL
A43: Sección Operativa | B43: Capacidad teórica (kg/h) | C43: Horas activas/año | D43: Capacidad teórica/año | E43: Rendimiento operativo | F43: Capacidad real (kg/h) | G43: Capacidad real/año
A45: Amasado | B45: 125 | C45: 5736 | D45: 717000 | E45: 0.85 | F45: 106.3 | G45: 609450
A46: Moldeado | B46: 128 | C46: 5736 | D46: 732235 | E46: 0.94 | F46: 120 | G46: 688301
A47: Horneado | B47: 95 | C47: 5736 | D47: 542396 | E47: 0.87 | F47: 81.8 | G47: 469173
...

Sheet 1. Resumen Ejecutivo
B2: PLANTA DE ALIMENTOS LIBRES DE GLUTEN (CELI)
B3: Proyecto Final de Ingeniería Industrial - UTN FRBA | Articulación Dinámica PCP vs. Layout
B4: REFERENCIA DE FORMATO: | C4: Parámetro Configurable (Modificable) | E4: Fórmula Automática / Vinculada
B6: 1. OBJETIVO DEL ESTUDIO TÉCNICO-LOGÍSTICO
B7: El presente modelo articula los datos maestros de Planeamiento y Control de la Producción (PCP), balance de masa (BOM) y dimensionamiento de equipos al Año 10 con la distribución en planta (Layout).
B8: Todas las hojas se encuentran 100% vinculadas dinámicamente: cualquier modificación en la demanda, baches o rendimientos del PCP impacta de forma automática en los stocks, frecuencias y horas de traslado del layout.
B10: 2. INDICADORES MAESTROS DE PLANTA (VINCULADOS AL PCP Y LAYOUT)
B12: PRODUCCIÓN TOTAL AÑO 10 | E12: RÉGIMEN OPERATIVO | H12: SALIDA POR TURNO
B13: ='2. PCP - Programa & Lotes'!F20 -> 678513.97 | E13: 239 días / 3 turnos | H13: ='2. PCP - Programa & Lotes'!J20 -> 946.32353
B14: kg PT / año | Línea A: Galletitas | Línea B: Panificados | E14: 5.736 hs activas/año (15 turnos/sem) | H14: kg PT / turno | Promedio ponderado total planta
B16: PALLETS A EXPEDICIÓN | E16: POLÍTICA DE STOCK PT | H16: HORAS TRASLADO / TURNO
B17: ='4. Dimensionamiento Stocks'!C9 -> 60 | E17: ='4. Dimensionamiento Stocks'!C10 -> 10 | H17: ='3. Cuantificación Frecuencias'!N33 -> #VALUE!
B18: pallets / semana | Galletitas: 30 pal/sem | Panif: 10 pal/sem | E18: días hábiles | Capacidad: 160 posiciones de rack | H18: hs / turno | Tiempo total en movimientos internos
B21: 3. METODOLOGÍA DE ARTICULACIÓN DINÁMICA ENTRE HOJAS
B23: Etapa Metodológica | C23: Descripción y Justificación Técnica | D23: Solapa de Referencia
B24: PASO 1: PCP MAESTRO (ENTRADA) | C24: Cálculo de turnos por SKU, batches por hora y masa a preparar según rendimientos del BOM. | D24: Solapa: 2. PCP - Programa & Lotes
B25: PASO 2: CUANTIFICACIÓN DE FRECUENCIAS | C25: Análisis detallado tramo por tramo (pesos, velocidades, tiempos de maniobra y cálculo dinámico de horas). | D25: Solapa: 3. Cuantificación Frecuencias
B26: PASO 3: DIMENSIONAMIENTO DE STOCKS | C26: Cálculo automático de posiciones de racks PT (160 pal), MP (52 pal) y pulmones WIP alimentado por el PCP. | D26: Solapa: 4. Dimensionamiento Stocks
B27: PASO 4: MATRIZ DESDE-HASTA (VIAJES Y MASA) | C27: Matrices 18x18 con nombres de sectores en horizontal vinculadas a la solapa de cuantificación de frecuencias. | D27: Solapas: 5. Desde-Hasta (Viajes) / 6. (Masa)
B28: PASO 5: EVALUACIÓN Y OPTIMIZACIÓN CAD | C28: Cálculo del Momento de Transporte Ponderado (M = fij * dij y M_peso = fij * dij * peso) cruzando distancias CAD. | D28: Solapa: 7. Carga-Distancia & Horas

Sheet 2. PCP - Programa & Lotes
B2: PLANEAMIENTO Y CONTROL DE PRODUCCIÓN (PCP) - AÑO 10 (HOJA MAESTRA)
B3: Desglose por SKU, Programa Maestro (MPS), Batches de Producción y Régimen de Turnos
B4: REFERENCIA DE FORMATO: | C4: Parámetro Configurable (Modificable) | E4: Fórmula Automática / Vinculada
B6: 1. DESGLOSE DE PRODUCCIÓN POR PRODUCTO (MIX DE VENTAS AÑO 10)
B8: Línea | C8: Cód. | D8: Denominación del Producto | E8: Present. | F8: PT Anual (kg) | G8: % Mix | H8: PT Mensual (kg) | I8: PT Diario (kg) | J8: PT Turno (kg) | K8: Cajas / Turno | L8: Pallets / Sem | M8: Frecuencia / Campaña
B9: Línea A - Galletitas | C9: A001 | D9: Chocolate con chips picante | E9: 150g | F9: 101019.36 | G9: =F9/$F$20 -> 0.14888324 | H9: =F9/12 -> 8418.28 | I9: =F9/239 -> 422.67515 | J9: =I9/3 -> 140.89172 | K9: =J9/(0.15*20) -> 46.963905 | L9: =(F9/47.8)/(0.15*20*105) -> 6.7091293 | M9: Campaña quincenal (8-9 turnos/mes)
B10: Línea A - Galletitas | C10: A002 | D10: Galletitas símil chocolinas free | E10: 150g | F10: 13132.52 | G10: =F10/$F$20 -> 0.019354826 | H10: =F10/12 -> 1094.3767 | I10: =F10/239 -> 54.947782 | J10: =I10/3 -> 18.315927 | K10: =J10/(0.15*20) -> 6.1053092 | L10: =(F10/47.8)/(0.15*20*105) -> 0.87218702 | M10: Campaña quincenal (1-2 turnos/mes)
B11: Línea A - Galletitas | C11: A003 | D11: Galletitas símil chocolinas | E11: 150g | F11: 30642.71 | G11: =F11/$F$20 -> 0.045161502 | H11: =F11/12 -> 2553.5592 | I11: =F11/239 -> 128.21218 | J11: =I11/3 -> 42.737392 | K11: =J11/(0.15*20) -> 14.245797 | L11: =(F11/47.8)/(0.15*20*105) -> 2.0351139 | M11: Campaña quincenal (2-3 turnos/mes)
B12: Línea A - Galletitas | C12: A004 | D12: Pepas chocolate y batata | E12: 150g | F12: 94284.9 | G12: =F12/$F$20 -> 0.13895793 | H12: =F12/12 -> 7857.075 | I12: =F12/239 -> 394.49749 | J12: =I12/3 -> 131.49916 | K12: =J12/(0.15*20) -> 43.833054 | L12: =(F12/47.8)/(0.15*20*105) -> 6.2618649 | M12: Campaña quincenal (8 turnos/mes)
B13: Línea A - Galletitas | C13: A005 | D13: Bizcochos sabor queso free | E13: 150g | F13: 13132.52 | G13: =F13/$F$20 -> 0.019354826 | H13: =F13/12 -> 1094.3767 | I13: =F13/239 -> 54.947782 | J13: =I13/3 -> 18.315927 | K13: =J13/(0.15*20) -> 6.1053092 | L13: =(F13/47.8)/(0.15*20*105) -> 0.87218702 | M13: Campaña quincenal (1-2 turnos/mes)
B14: Línea A - Galletitas | C14: A006 | D14: Bizcochos sabor queso | E14: 150g | F14: 30642.71 | G14: =F14/$F$20 -> 0.045161502 | H14: =F14/12 -> 2553.5592 | I14: =F14/239 -> 128.21218 | J14: =I14/3 -> 42.737392 | K14: =J14/(0.15*20) -> 14.245797 | L14: =(F14/47.8)/(0.15*20*105) -> 2.0351139 | M14: Campaña quincenal (2-3 turnos/mes)
B15: Línea A - Galletitas | C15: A007 | D15: Polvorones free | E15: 150g | F15: 22729.36 | G15: =F15/$F$20 -> 0.033498735 | H15: =F15/12 -> 1894.1133 | I15: =F15/239 -> 95.101925 | J15: =I15/3 -> 31.700642 | K15: =J15/(0.15*20) -> 10.566881 | L15: =(F15/47.8)/(0.15*20*105) -> 1.5095544 | M15: Campaña quincenal (2 turnos/mes)
B16: Línea A - Galletitas | C16: A008 | D16: Polvorones | E16: 150g | F16: 53035.16 | G16: =F16/$F$20 -> 0.078163696 | H16: =F16/12 -> 4419.5967 | I16: =F16/239 -> 221.90444 | J16: =I16/3 -> 73.968145 | K16: =J16/(0.15*20) -> 24.656048 | L16: =(F16/47.8)/(0.15*20*105) -> 3.5222926 | M16: Campaña quincenal (4-5 turnos/mes)
B17: Línea B - Panificados | C17: B001 | D17: Pan de molde | E17: 400g | F17: 117855.92 | G17: =F17/$F$20 -> 0.17369712 | H17: =F17/12 -> 9821.3267 | I17: =F17/239 -> 493.121 | J17: =I17/3 -> 164.37367 | K17: =J17/(0.4*10) -> 41.093417 | L17: =(F17/47.8)/(0.4*10*80) -> 7.7050157 | M17: Lunes y Miércoles (TM, TT, TN)
B18: Línea B - Panificados | C18: B002 | D18: Budines vainilla / cítricos | E18: 180g | F18: 141427.2 | G18: =F18/$F$20 -> 0.20843668 | H18: =F18/12 -> 11785.6 | I18: =F18/239 -> 591.74561 | J18: =I18/3 -> 197.24854 | K18: =J18/(0.18*20) -> 54.79126 | L18: =(F18/47.8)/(0.18*20*90) -> 9.1318766 | M18: Martes, Jueves y Viernes
B19: Línea B - Panificados | C19: B003 | D19: Budines chocolate free | E19: 180g | F19: 60611.61 | G19: =F19/$F$20 -> 0.089329937 | H19: =F19/12 -> 5050.9675 | I19: =F19/239 -> 253.60506 | J19: =I19/3 -> 84.535021 | K19: =J19/(0.18*20) -> 23.48195 | L19: =(F19/47.8)/(0.18*20*90) -> 3.9136584 | M19: Jueves y Viernes
B20: TOTAL GENERAL PLANTA CELI | F20: =SUM(F9:F19) -> 678513.97 | G20: =SUM(G9:G19) -> 1 | H20: =SUM(H9:H19) -> 56542.831 | I20: =SUM(I9:I19) -> 2838.9706 | J20: =SUM(J9:J19) -> 946.32353 | K20: =SUM(K9:K19) -> 286.08873 | L20: =SUM(L9:L19) -> 44.567994 | M20: 40 pallets / semana a régimen
B23: 2. PARÁMETROS OPERATIVOS DE PROCESO Y TAMAÑOS DE BATCH
B25: Parámetro Técnico / Operativo | C25: Línea A - Galletitas | D25: Línea B - Panificados | E25: Unidad | F25: Impacto en el Layout / Manejo de Materiales
B26: Salida PT Neta por Turno (kg) | C26: =SUM(J9:J16) -> 500.1663 | D26: =SUM(J17:J19) -> 446.15722 | E26: kg PT / turno | F26: Salida neta de producto terminado de cada línea
B27: Rendimiento Global de Proceso (%) | C27: 0.9122 | D27: 0.809 | E27: % masa a PT | F27: Pérdidas de humedad, cocción y mermas (BOM)
B28: Masa total a preparar por turno | C28: =C26/C27 -> 548.30772 | D28: =D26/D27 -> 551.49224 | E28: kg masa / turno | F28: Flujo que ingresa a Pesado y Amasado/Batido
B29: Capacidad unitaria de máquina (Batea x6) | C29: =25*6 -> 150 | D29: =25*6 -> 150 | E29: kg / batch | F29: Amasadora HJ25B (25kg) vs. Batidora Moretti (45kg)
B30: Cantidad de Batches por Turno | C30: =ROUNDUP(C28/C29, 0) -> 4 | D30: =ROUNDUP(D28/D29, 0) -> 4 | E30: tandas / turno | F30: Define los viajes Pesado <-> Amasado en Desde-Hasta
B31: Capacidad de la Unidad Intermedia | C31: =50 -> 50 | D31: 40.5 | E31: kg / unidad | F31: Batea volcable (25kg) vs. Carro 15 bandejas (40,5kg)
B32: Carros / Bateas por Turno en Proceso | C32: =ROUNDUP(C28/C31, 0) -> 11 | D32: =ROUNDUP(D28/D31, 0) -> 14 | E32: unid. rodantes / turno | F32: Tráfico pesado en hornos, fermentador y enfriamiento
B33: Tiempo de Residencia en Enfriado | C33: 15 | D33: 75 | E33: minutos | F33: Exige pulmón estático de 4 carros en Panificados
B34: Salida de Cajas Secundarias | C34: =SUM(K9:K16) -> 166.7221 | D34: =SUM(K17:K19) -> 119.36663 | E34: cajas / turno | F34: Flujo hacia mesa de encajonado manual
B35: Generación de Pallets PT | C35: =+ROUNDUP(SUM(L9:L16)/15,0) -> 2 | D35: =+ROUNDUP(SUM(L17:L19)/15,0) -> 2 | E35: pallets / turno | F35: Traslado con zorra hidráulica a depósito PT
B37: VERSION 2 PARA DESDE/HASTA
B38: Parámetro Técnico / Operativo | C38: Línea A - Galletitas | D38: Línea B - Panificados | E38: Unidad | F38: Impacto en el Layout / Manejo de Materiales
B39: Salida PT Neta por Turno (kg) | C39: =SUM(J9:J16) -> 500.1663 | D39: =SUM(J17:J19) -> 446.15722 | E39: kg PT / turno | F39: Salida neta de producto terminado de cada línea
B40: Rendimiento Global de Proceso (%) | C40: 0.9122 | D40: 0.809 | E40: % masa a PT | F40: Pérdidas de humedad, cocción y mermas (BOM)
B41: Masa total a preparar por turno | C41: =C39/C40 -> 548.30772 | D41: =D39/D40 -> 551.49224 | E41: kg masa / turno | F41: Flujo que ingresa a Pesado y Amasado/Batido
B42: Capacidad unitaria de máquina (Batea x6) | C42: =25*6 -> 150 | D42: =25*6 -> 150 | E42: kg / batch | F42: Amasadora HJ25B (25kg) vs. Batidora Moretti (45kg) | G42: Nuevas bateas en carros
B43: Capacidad de la Unidad Intermedia | C43: 100 | D43: 100 | E43: kg / unidad | F43: Batea volcable (25kg) vs. Carro 15 bandejas (40,5kg) | G43: Nuevas bateas con ruedas
B44: Carros / Bateas por Turno en Proceso | C44: =ROUNDUP(C41/C43, 0) -> 6 | D44: =ROUNDUP(D41/D43, 0) -> 6 | E44: unid. rodantes / turno | F44: Tráfico pesado en hornos, fermentador y enfriamiento
B45: Tiempo de Residencia en Enfriado | C45: 15 | D45: 75 | E45: minutos | F45: Exige pulmón estático de 4 carros en Panificados
B46: Salida de Cajas Secundarias | C46: =+ROUNDUP(SUM(K9:K16),0) -> 167 | D46: =SUM(K17:K19) -> 119.36663 | E46: cajas / turno | F46: Flujo hacia mesa de encajonado manual | G46: Redondeo al inmediato superior
B47: Generación de Pallets PT | C47: =+ROUNDUP(SUM(L9:L16)/15,0) -> 2 | D47: =+ROUNDUP(SUM(L17:L19)/15,0) -> 2 | E47: pallets / turno | F47: Traslado con zorra hidráulica a depósito PT | G47: Redondeo al inmediato superior
...

Sheet 3. Cuantificación Frecuencias
B2: CUANTIFICACIÓN FINA DE FRECUENCIAS, VELOCIDADES Y TIEMPOS DE TRASLADO
B3: Desglose Operativo por Tramo, Medios de Manutención, Peso, Velocidad y Horas de Transporte por Turno
B4: REFERENCIA DE FORMATO: | C4: Parámetro Configurable (Modificable) | E4: Fórmula Automática / Vinculada
B6: N° Tramo | C6: Origen | D6: Destino | E6: Material / Carga Transportada | F6: Medio de Transporte | G6: Peso por Viaje (kg) | H6: Frecuencia f (viajes/turno) | I6: Flujo Masa (kg/turno) | J6: Distancia d (m) | K6: Velocidad v (m/min) | L6: Tiempo Maniobra (min) | M6: Tiempo por Ciclo (min) | N6: Horas Traslado (hs/turno) | O6: Esfuerzo Carga-Dist (kg·m/turno) | P6: Ponderación flujo másico | Q6: Intensidad masa | R6: Intensidad frecuencia
B7: TR-01 | C7: 1. Depósito MP | D7: 2. Aduana MP | E7: Bolsas harinas, féculas, azúcar, aditivos | F7: Zorra hidráulica HELI BF25 | G7: =I7/2 -> 549.89998 | H7: =ROUNDUP(('2. PCP - Programa & Lotes'!C28+'2. PCP - Programa & Lotes'!D28)/G7, 0) -> 2 | I7: ='2. PCP - Programa & Lotes'!C28+'2. PCP - Programa & Lotes'!D28 -> 1099.8 | J7: 4.5 | K7: 36 | L7: 0.5 | M7: =IF(H7>0, (2*J7/K7) + L7, 0) -> 0.75 | N7: =H7*M7/60 -> 0.025 | O7: =H7*J7*G7 -> 4949.0998 | P7: =+ROUNDUP(I7/110,0) -> 10 | Q7: Alta | R7: Media | S7: A | T7: =I7/25 -> 43.991999 | U7: bolsas
B8: TR-02 | C8: 2. Aduana MP | D8: 2. Sección Pesado | G8: 150 | H8: 4 | I8: =G8*H8 -> 600 | P8: =+ROUNDUP(I8/110,0) -> 6 | Q8: Alta | R8: Media | S8: A
B9: TR-03 | C9: 2. Sección Pesado | D9: 3. Amasado G | E9: Insumos pesados fraccionados para amasadora | F9: Tachos / Contenedores rodantes | G9: ='2. PCP - Programa & Lotes'!C29 -> 150 | H9: =+ROUNDUP('2. PCP - Programa & Lotes'!C28/'3. Cuantificación Frecuencias'!G9,0) -> 4 | I9: =+H9*G9 -> 600 | J9: 3.5 | K9: 48 | L9: 0.3 | M9: =IF(H9>0, (2*J9/K9) + L9, 0) -> 0.44583333 | N9: =H9*M9/60 -> 0.029722222 | O9: =H9*J9*G9 -> 2100 | P9: =+ROUNDUP(I9/110,0) -> 6 | Q9: Media | R9: Media | S9: E
B10: TR-04 | C10: 3. Amasado G | D10: 4. Moldeado G | E10: Amasijo volcado de amasadora a tolva | F10: Batea rodante volcable | G10: 100 | H10: =+ROUNDUP('2. PCP - Programa & Lotes'!C41/'3. Cuantificación Frecuencias'!G10,0) -> 6 | I10: =+H10*G10 -> 600 | J10: 3 | K10: 42 | L10: 0.35 | M10: =IF(H10>0, (2*J10/K10) + L10, 0) -> 0.49285714 | N10: =H10*M10/60 -> 0.049285714 | O10: =H10*J10*G10 -> 1800 | P10: =+ROUNDUP(I10/110,0) -> 6 | Q10: Media | R10: Alta | S10: A
B11: TR-05 | C11: 4. Moldeado G | D11: 5. Horno Túnel G | E11: Galletitas crudas formadas | F11: Cinta transportadora continua [C] | G11: N/A | H11: N/A | I11: N/A | J11: 5 | K11: 60 | L11: 0 | M11: =IF(H11>0, (2*J11/K11) + L11, 0) -> 0.16666667 | N11: =H11*M11/60 -> #VALUE! | O11: =H11*J11*G11 -> #VALUE! | P11: 0 | Q11: Alta | R11: - | S11: A
B12: TR-06 | C12: 5. Horno Túnel G | D12: 6. Cinta Enfriado G | E12: Galletitas cocidas calientes | F12: Cinta transportadora continua [C] | G12: N/A | H12: N/A | I12: N/A | J12: 6 | K12: 60 | L12: 0 | M12: =IF(H12>0, (2*J12/K12) + L12, 0) -> 0.2 | N12: =H12*M12/60 -> #VALUE! | O12: =H12*J12*G12 -> #VALUE! | P12: 0 | Q12: Alta | R12: - | S12: A
B13: TR-07 | C13: 6. Cinta Enfriado G | D13: 7. Envasado 1° G | E13: Galletitas a temperatura ambiente | F13: Cinta inclinada de alimentación [C] | G13: N/A | H13: N/A | I13: N/A | J13: 4 | K13: 60 | L13: 0 | M13: =IF(H13>0, (2*J13/K13) + L13, 0) -> 0.13333333 | N13: =H13*M13/60 -> #VALUE! | O13: =H13*J13*G13 -> #VALUE! | P13: 0 | Q13: Alta | R13: - | S13: A
B14: TR-08 | C14: 7. Envasado 1° G | D14: 17. Depósito PT | E14: Pallet Arlog conformado con 105 cajas | F14: Zorra hidráulica HELI BF25 | G14: 315 | H14: ='2. PCP - Programa & Lotes'!C35 -> 2 | I14: =+H14*G14 -> 630 | J14: 5 | K14: 36 | L14: 0.75 | M14: =IF(H14>0, (2*J14/K14) + L14, 0) -> 1.0277778 | N14: =H14*M14/60 -> 0.034259259 | O14: =H14*J14*G14 -> 3150 | P14: =+ROUNDUP(I14/110,0) -> 6 | Q14: Media | R14: Baja | S14: I
B15: TR-09 | C15: 2. Sección Pesado | D15: 9. Batido Panif. | E15: Premezclas, huevo, aceite fraccionados | F15: Tachos / Contenedores rodantes | G15: =+'2. PCP - Programa & Lotes'!D42 -> 150 | H15: =+ROUNDUP('2. PCP - Programa & Lotes'!D41/'3. Cuantificación Frecuencias'!G15,0) -> 4 | I15: =+H15*G15 -> 600 | J15: 5.5 | K15: 48 | L15: 0.35 | M15: =IF(H15>0, (2*J15/K15) + L15, 0) -> 0.57916667 | N15: =H15*M15/60 -> 0.038611111 | O15: =H15*J15*G15 -> 3300 | P15: =+ROUNDUP(I15/110,0) -> 6 | Q15: Media | R15: Media | S15: E
B16: TR-10 | C16: 9. Batido Panif. | D16: 10. Dosificado P. | E16: Batido homogéneo volcado a tolva | F16: Batea rodante volcable | G16: =+'2. PCP - Programa & Lotes'!D43 -> 100 | H16: =+ROUNDUP('2. PCP - Programa & Lotes'!D41/'3. Cuantificación Frecuencias'!G16,0) -> 6 | I16: =+H16*G16 -> 600 | J16: 3 | K16: 42 | L16: 0.35 | M16: =IF(H16>0, (2*J16/K16) + L16, 0) -> 0.49285714 | N16: =H16*M16/60 -> 0.049285714 | O16: =H16*J16*G16 -> 1800 | P16: =+ROUNDUP(I16/110,0) -> 6 | Q16: Media | R16: Alta | S16: A
B17: TR-11 | C17: 10. Dosificado P. | D17: 11. Fermentado P. | E17: Carros porta-bandejas con moldes (Pan) | F17: Carro con 15 bandejas (45x70) | G17: 43.2 | H17: =+ROUNDUP('2. PCP - Programa & Lotes'!$D$41*0.4/'3. Cuantificación Frecuencias'!G17,0) -> 6 | I17: =+H17*G17 -> 259.2 | J17: 3 | K17: 42 | L17: 0.4 | M17: =IF(H17>0, (2*J17/K17) + L17, 0) -> 0.54285714 | N17: =H17*M17/60 -> 0.054285714 | O17: =H17*J17*G17 -> 777.6 | P17: =+ROUNDUP(I17/110,0) -> 3 | Q17: Baja | R17: Alta | S17: E
B18: TR-12 | C18: 10. Dosificado P. | D18: 12. Hornos Rotat. P. | E18: Carros porta-bandejas con moldes (Pan) | F18: Carro con 15 bandejas (45x70) | G18: 43.2 | H18: =+ROUNDUP('2. PCP - Programa & Lotes'!D28*0.6/'3. Cuantificación Frecuencias'!G18,0) -> 8 | I18: =+H18*G18 -> 345.6 | P18: =+ROUNDUP(I18/110,0) -> 4 | Q18: Media | R18: Alta | S18: A
B19: TR-13 | C19: 11. Fermentado P. | D19: 12. Hornos Rotat. P. | E19: Carros leudados hacia hornos Pauna SIGMA | F19: Carro con 15 bandejas (45x70) | G19: 43.2 | H19: =+ROUNDUP('2. PCP - Programa & Lotes'!$D$41*0.4/'3. Cuantificación Frecuencias'!G19,0) -> 6 | I19: =+H19*G19 -> 259.2 | J19: 4 | K19: 42 | L19: 0.4 | M19: =IF(H19>0, (2*J19/K19) + L19, 0) -> 0.59047619 | N19: =H19*M19/60 -> 0.059047619 | O19: =H19*J19*G19 -> 1036.8 | P19: =+ROUNDUP(I19/110,0) -> 3 | Q19: Baja | R19: Alta | S19: E
B20: TR-14 | C20: 12. Hornos Rotat. P. | D20: 13. Enfriado P. | E20: Carros calientes a 180°C saliendo de cocción | F20: Carro con 15 bandejas (45x70) | G20: 43.2 | H20: ='2. PCP - Programa & Lotes'!D32 -> 14 | I20: =+H20*G20 -> 604.8 | J20: 3.5 | K20: 36 | L20: 0.45 | M20: =IF(H20>0, (2*J20/K20) + L20, 0) -> 0.64444444 | N20: =H20*M20/60 -> 0.15037037 | O20: =H20*J20*G20 -> 2116.8 | P20: =+ROUNDUP(I20/110,0) -> 6 | Q20: Media | R20: Alta | S20: A
B21: TR-15 | C21: 13. Enfriado P. | D21: 15. Envasado 1° P. | E21: Bandejas frías hacia rebanadora y Flow-Pack | F21: Manual / Carro porta-bandejas | G21: 30 | H21: ='2. PCP - Programa & Lotes'!D32 -> 14 | I21: =+H21*G21 -> 420 | J21: 4 | K21: 42 | L21: 0.35 | M21: =IF(H21>0, (2*J21/K21) + L21, 0) -> 0.54047619 | N21: =H21*M21/60 -> 0.12611111 | O21: =H21*J21*G21 -> 1680 | P21: =+ROUNDUP(I21/110,0) -> 4 | Q21: Media | R21: Alta | S21: A
B22: TR-16 | C22: 15. Envasado 1° P. | D22: 17. Depósito PT | E22: Pallet terminado enfardado con cajas | F22: Zorra hidráulica HELI BF25 | G22: 250 | H22: ='2. PCP - Programa & Lotes'!D35 -> 2 | I22: =+H22*G22 -> 500 | J22: 5 | K22: 36 | L22: 0.75 | M22: =IF(H22>0, (2*J22/K22) + L22, 0) -> 1.0277778 | N22: =H22*M22/60 -> 0.034259259 | O22: =H22*J22*G22 -> 2500 | P22: =+ROUNDUP(I22/110,0) -> 5 | Q22: Media | R22: Baja | S22: I
B23: TR-17 | C23: 4. Moldeado G | D23: =+C10 -> 3. Amasado G | E23: Desechos recuperables | F23: Tachos de reproceso | G23: =+'0. Capacidades x hora - turno'!E5 -> 6.0174234 | H23: 1 | I23: =+H23*G23 -> 6.0174234 | J23: 8 | K23: 48 | L23: 0.3 | M23: =IF(H23>0, (2*J23/K23) + L23, 0) -> 0.63333333 | N23: =H23*M23/60 -> 0.010555556 | O23: =H23*J23*G23 -> 48.139387 | P23: =+ROUNDUP(I23/110,0) -> 1 | Q23: Baja | R23: Baja | S23: O
B24: TR-18 | C24: 6. Cinta Enfriado G | D24: 3. Amasado G | E24: Desechos recuperables | G24: =+'0. Capacidades x hora - turno'!E7 -> 21.937119 | H24: 1 | I24: =+H24*G24 -> 21.937119 | P24: =+ROUNDUP(I24/110,0) -> 1 | Q24: Baja | R24: Baja | S24: O
B25: TR-19 | C25: 4. Moldeado G | D25: 18. Lavado / Scrap | E25: Desechos no recuperables y limpieza | G25: =+'0. Capacidades x hora - turno'!G5 -> 6.0174234 | H25: 1 | I25: =+H25*G25 -> 6.0174234 | P25: =+ROUNDUP(I25/110,0) -> 1 | Q25: Baja | R25: Baja | S25: O
B26: TR-20 | C26: 6. Cinta Enfriado G | D26: 18. Lavado / Scrap | E26: Desechos no recuperables y limpieza | G26: =+'0. Capacidades x hora - turno'!G7 -> 5.4842797 | H26: 1 | I26: =+H26*G26 -> 5.4842797 | P26: =+ROUNDUP(I26/110,0) -> 1 | Q26: Baja | R26: Baja | S26: O
B27: TR-21 | C27: 13. Enfriado P. | D27: 18. Lavado / Scrap | E27: Desechos no recuperables y limpieza | F27: Contenedor de residuos | G27: 50 | H27: =+ROUNDUP(('0. Capacidades x hora - turno'!G5+'0. Capacidades x hora - turno'!G7+'0. Capacidades x hora - turno'!G26)/'3. Cuantificación Frecuencias'!G27,0) -> 1 | I27: =+H27*G27 -> 50 | J27: 10 | K27: 42 | L27: 0.4 | M27: =IF(H27>0, (2*J27/K27) + L27, 0) -> 0.87619048 | N27: =H27*M27/60 -> 0.014603175 | O27: =H27*J27*G27 -> 500 | P27: =+ROUNDUP(I27/110,0) -> 1 | Q27: Baja | R27: Baja | S27: O
B28: TR-22 | C28: 9. Batido Panif. | D28: Calidad crudo | E28: Una muestra por batido | F28: Probeta | H28: =+ROUNDUP('0. Capacidades x hora - turno'!B21/'0. Capacidades x hora - turno'!Q36,0) -> 15 | I28: =+H28*G28 -> 0 | P28: =+ROUNDUP(I28/110,0) -> 0 | Q28: Baja | R28: Alta | S28: I
B29: TR-23 | C29: 3. Amasado G | D29: Calidad crudo | E29: Una muestra por amasado | F29: Probeta | H29: 12 | I29: =+H29*G29 -> 0 | P29: =+ROUNDUP(I29/110,0) -> 0 | Q29: Baja | R29: Alta | S29: I
B30: TR-24 | C30: 6. Cinta Enfriado G | D30: Calidad cocido | E30: Una muestra cada media hora | H30: 16 | I30: =+H30*G30 -> 0 | P30: =+ROUNDUP(I30/110,0) -> 0 | Q30: Baja | R30: Alta | S30: I
B31: TR-25 | C31: 7. Envasado 1° G | D31: Calidad cocido | E31: Una muestra cada media hora | H31: 16 | I31: =+H31*G31 -> 0 | P31: =+ROUNDUP(I31/110,0) -> 0 | Q31: Baja | R31: Alta | S31: I
B32: TR-26 | C32: 13. Enfriado P. | D32: Calidad cocido | E32: Una muestra cada media hora | H32: 16 | I32: =+H32*G32 -> 0 | P32: =+ROUNDUP(I32/110,0) -> 0 | Q32: Baja | R32: Alta | S32: I
B33: TOTALES DE PLANTA | H33: =+SUM(H7:H32) -> 158 | I33: =+SUM(I7:I32) -> 7208.0562 | N33: =SUM(N7:N27) -> #VALUE! | O33: =SUM(O7:O27) -> #VALUE!
B36: RESUMEN DE RECURSOS DE MANEJO DE MATERIALES
B37: Horas totales de traslado y manipulación por turno | C37: =N33 -> #VALUE! | D37: hs / turno | E37: Tiempo total que demandan los movimientos internos en cada turno de 8h
B38: Equivalente en Jornadas de Operario de Manutención | C38: =C37/8 -> #VALUE! | D38: operarios equiv. / turno | E38: Cantidad de operarios a tiempo completo dedicados al transporte interno
B39: Esfuerzo Total Carga-Distancia Ponderado por Masa | C39: =O33 -> #VALUE! | D39: kg · m / turno | E39: Indicador global de esfuerzo logístico interno (a minimizar en CAD)

Sheet 4. Dimensionamiento Stocks
B2: DIMENSIONAMIENTO DE ALMACENES Y STOCKS (PCP -> LAYOUT)
B3: Cálculo de Posiciones de Racks, Superficies de Depósitos (MP y PT) y Pulmones Intermedios (WIP)
B4: REFERENCIA DE FORMATO: | C4: Parámetro Configurable (Modificable) | E4: Fórmula Automática / Vinculada
B6: Parámetro de Dimensionamiento | C6: Valor / Fórmula | D6: Unidad | E6: Criterio Técnico / Normativa
B7: Salida semanal de Galletitas (PT) | C7: ='2. PCP - Programa & Lotes'!C35*15 -> 30 | D7: pallets / sem | E7: Vinculado a PCP: Pallets/turno Galletitas * 15 turnos
B8: Salida semanal de Panificados (PT) | C8: ='2. PCP - Programa & Lotes'!D35*15 -> 30 | D8: pallets / sem | E8: Vinculado a PCP: Pallets/turno Panificados * 15 turnos
B9: Total de Pallets generados por semana | C9: =C7+C8 -> 60 | D9: pallets / sem | E9: Flujo total a absorber por el depósito PT
B10: Política de Cobertura de Stock PT | C10: 10 | D10: días hábiles | E10: Equivale a 2 semanas de producción a régimen (Fundamentado por SLA 98% y ciclo)
B11: Capacidad de Almacenamiento Requerida (PT) | C11: =C9*(C10/5) -> 120 | D11: posiciones pallet | E11: Stock Máximo = Pallets/sem * Semanas de cobertura
B12: Tipo de Pallet Normalizado | C12: Arlog (1.200 x 1.000 mm) | D12: - | E12: Altura máxima con carga estibada: 1,85 m
B13: Configuración de Estanterías | C13: Racks Selectivos pesados | D13: - | E13: 3 niveles de altura (2 pallets por módulo de 2,70 m)
B14: Niveles de Estiba en Racks | C14: 3 | D14: niveles | E14: Altura de rack útil: aprox. 6,00 m
B15: Cantidad de Módulos de Racks en Planta | C15: =ROUNDUP(C11/(C14*2), 0) -> 20 | D15: módulos dobles | E15: Cada módulo doble aloja 6 pallets (3 niveles x 2 pallets)
B16: Superficie Estática de Racks (Ss) | C16: =C15*2.7*1.1 -> 59.4 | D16: m² | E16: Huella de las estructuras de almacenamiento
B17: Ancho de Pasillo para Autoelevador | C17: 3 | D17: metros | E17: Radio de giro y maniobra autoelevador eléctrico HELI ORME-CMM-16
B18: Área de Maniobra y Pasillos (Sg + Se) | C18: 95 | D18: m² | E18: Espacio para circulación y carga/descarga segura
B19: Área de Enfilmado, Picking y Dársena | C19: 25 | D19: m² | E19: Plato giratorio stretch + pulmón de precarga a camión
B20: SUPERFICIE TOTAL REQUERIDA DEPÓSITO PT | C20: =C16+C18+C19 -> 179.4 | D20: m² | E20: Dimensión mínima a verificar en el archivo CAD
B22: Parámetro de Dimensionamiento | C22: Valor / Fórmula | D22: Unidad | E22: Criterio Técnico / Normativa
B23: Consumo semanal de MP (Galletitas) | C23: ='2. PCP - Programa & Lotes'!C28*15 -> 8224.6158 | D23: kg / sem | E23: Vinculado a PCP: Masa/turno Galletitas * 15 turnos
B24: Consumo semanal de MP (Panificados) | C24: ='2. PCP - Programa & Lotes'!D28*15 -> 8272.3836 | D24: kg / sem | E24: Vinculado a PCP: Masa/turno Panificados * 15 turnos
B25: Consumo total semanal de Materias Primas | C25: =C23+C24 -> 16496.999 | D25: kg / sem | E25: Aprox. 17,3 toneladas semanales de insumos
B26: Política de Cobertura de Stock MP | C26: 15 | D26: días hábiles | E26: 10 días de lote de compra + 5 días stock seguridad
B27: Capacidad de Almacenamiento MP Requerida | C27: =ROUNDUP((C25*(C26/5))/1000, 0) -> 50 | D27: posiciones pallet | E27: Equivale a 3 semanas de consumo en racks (1000 kg/pal)
B28: Zona de Cuarentena y Muestreo Sin TACC | C28: 12 | D28: m² | E28: Área delimitada para control de gluten (<10 ppm)
B29: Superficie Estática de Racks MP (3 niveles) | C29: =ROUNDUP(C27/6, 0)*2.7*1.1 -> 26.73 | D29: m² | E29: Estructura para almacenar las posiciones en 3 alturas
B30: Pasillo y Maniobra Autoelevador MP | C30: 45 | D30: m² | E30: Circulación y abastecimiento a Sección Pesado
B31: Dársena de Recepción y Descarga | C31: 15 | D31: m² | E31: Área bajo techo frente a portón de descarga
B32: SUPERFICIE TOTAL REQUERIDA DEPÓSITO MP | C32: =C28+C29+C30+C31 -> 98.73 | D32: m² | E32: Dimensión mínima a verificar en el archivo CAD
B35: Sector / Buffer Intermedio | C35: Capacidad Física Requerida | D35: Superficie Estimada (m²) | E35: Justificación Operativa / Requisito Sanitario
B36: Pulmón de Carros de Enfriamiento (Panificados) | C36: 4 carros en paralelo | D36: 18 | E36: Carros calientes en reposo térmico (60-90 min) previo a envasado
B37: Pulmón de Fermentación (Pan de Molde) | C37: Cámara + 2 carros buffer | D37: 8.5 | E37: Carros cargados en espera de horneado
B38: Buffer de Palletizado (Envasado 2° Galletitas) | C38: 1 pallet conformando + 1 listo | D38: 6 | E38: Espacio para estiba manual y zorra hidráulica
B39: Buffer de Palletizado (Envasado 2° Panificados) | C39: 1 pallet conformando | D39: 4.5 | E39: Espacio para estiba de cajas multiproducto
B40: Pulmón de Bateas y Tachos Limpios (Lavado) | C40: Área de baches listos | D40: 6 | E40: Recipientes limpios en espera de fraccionamiento

Sheet 5. Desde-Hasta (Viajes)
B2: MATRIZ DESDE - HASTA DE FRECUENCIAS DE TRANSPORTE (fij)
B3: Frecuencia de Movimientos por Turno de 8 Horas al Año 10 (Viajes / Turno) - Construida íntegramente desde 3. Cuantificación Frecuencias
B4: REFERENCIA DE FORMATO: | C4: Parámetro Configurable (Modificable) | E4: Fórmula Automática / Vinculada
B6: DESDE \ HASTA | C6: 1. Dep. MP | D6: 2. Pesado | E6: 3. Amasado G | F6: 4. Moldeado G | G6: 5. Horno Túnel G | H6: 6. Enfriado G | I6: 7. Env. 1° G | J6: 8. Batido Panif. | K6: 9. Dosificado P. | L6: 10. Fermentado P. | M6: 11. Hornos Rotat. P. | N6: 12. Enfriado P. | O6: 13. Env. 1° P. | P6: 14. Dep. PT | Q6: 15. Lav./Scrap | R6: 16. Recirc. Mermas | S6: 17. Evac. Residuos | T6: 18. Calidad crudo | U6: 19. Calidad cocido | V6: SALIDAS
B7: 1. Depósito MP | C7: - | D7: ='3. Cuantificación Frecuencias'!H7 -> 2 | V7: =SUM(C7:U7) -> 2
B8: 2. Sección Pesado | D8: - | E8: ='3. Cuantificación Frecuencias'!H9 -> 4 | J8: ='3. Cuantificación Frecuencias'!H15 -> 4 | V8: =SUM(C8:U8) -> 8
B9: 3. Amasado G | E9: - | F9: ='3. Cuantificación Frecuencias'!H10 -> 6 | T9: ='3. Cuantificación Frecuencias'!H29 -> 12 | V9: =SUM(C9:U9) -> 18
B10: 4. Moldeado G | F10: - | G10: ='3. Cuantificación Frecuencias'!H11 -> N/A | V10: =SUM(C10:U10) -> 0
B11: 5. Horno Túnel G | G11: - | H11: ='3. Cuantificación Frecuencias'!H12 -> N/A | V11: =SUM(C11:U11) -> 0
B12: 6. Cinta Enfriado G | H12: - | I12: ='3. Cuantificación Frecuencias'!H13 -> N/A | U12: ='3. Cuantificación Frecuencias'!H30 -> 16 | V12: =SUM(C12:U12) -> 16
B13: 7. Envasado 1° G | I13: - | P13: ='3. Cuantificación Frecuencias'!H14 -> 2 | U13: ='3. Cuantificación Frecuencias'!H31 -> 16 | V13: =SUM(C13:U13) -> 18
B14: 8. Batido Panif. | J14: - | K14: ='3. Cuantificación Frecuencias'!H16 -> 6 | T14: ='3. Cuantificación Frecuencias'!H28 -> 15 | V14: =SUM(C14:U14) -> 21
B15: 9. Dosificado P. | K15: - | L15: ='3. Cuantificación Frecuencias'!H17 -> 6 | V15: =SUM(C15:U15) -> 6
B16: 10. Fermentado P. | L16: - | M16: ='3. Cuantificación Frecuencias'!H19 -> 6 | V16: =SUM(C16:U16) -> 6
B17: 11. Hornos Rotat. P. | M17: - | N17: ='3. Cuantificación Frecuencias'!H20 -> 14 | V17: =SUM(C17:U17) -> 14
B18: 12. Enfriado P. | N18: - | O18: ='3. Cuantificación Frecuencias'!H21 -> 14 | U18: ='3. Cuantificación Frecuencias'!H32 -> 16 | V18: =SUM(C18:U18) -> 30
B19: 13. Envasado 1° P. | O19: - | P19: ='3. Cuantificación Frecuencias'!H22 -> 2 | V19: =SUM(C19:U19) -> 2
B20: 14. Depósito PT | P20: - | V20: =SUM(C20:U20) -> 0
B21: 15. Lavado / Scrap | Q21: - | V21: =SUM(C21:U21) -> 0
B22: 16. Recirculación Mermas | E22: ='3. Cuantificación Frecuencias'!H23 -> 1 | R22: - | V22: =SUM(C22:U22) -> 1
B23: 17. Evacuación Residuos | Q23: ='3. Cuantificación Frecuencias'!H27 -> 1 | S23: - | V23: =SUM(C23:U23) -> 1
B24: 18. Calidad crudo | T24: - | V24: =SUM(C24:U24) -> 0
B25: 19. Calidad cocido | U25: - | V25: =SUM(C25:U25) -> 0
B26: ENTRADAS | C26: =SUM(C7:C25) -> 0 | D26: =SUM(D7:D25) -> 2 | E26: =SUM(E7:E25) -> 5 | F26: =SUM(F7:F25) -> 6 | G26: =SUM(G7:G25) -> 0 | H26: =SUM(H7:H25) -> 0 | I26: =SUM(I7:I25) -> 0 | J26: =SUM(J7:J25) -> 4 | ... V26: =SUM(V7:V25) -> 143
B29: REFERENCIAS DE TIPOS DE FLUJO
B30: N/A [C] | C30: Flujo mecánico continuo | D30: En la Hoja 3 la frecuencia/masa figura como N/A por tratarse de una cinta continua; se mantiene la referencia directa.
B31: Azul / Vinculado | C31: Flujo vinculado a Hoja 3 | D31: Valor obtenido mediante fórmula que referencia directamente 3. Cuantificación Frecuencias.
B32: Calidad | C32: Movimiento de muestra | D32: La frecuencia se contabiliza como movimiento; en flujo de masa las muestras figuran con 0 kg/turno según la Hoja 3.

Sheet 6. Desde-Hasta (Flujo Masa)
B2: MATRIZ DESDE - HASTA DE FLUJO DE MASA (kg / Turno)
B3: Flujo Másico Transportado por Turno de 8 Horas (Año 10) - Construida íntegramente desde 3. Cuantificación Frecuencias
B4: REFERENCIA DE FORMATO: | C4: Parámetro Configurable (Modificable) | E4: Fórmula Automática / Vinculada
B6: DESDE \ HASTA | C6: 1. Dep. MP | D6: 2. Pesado | E6: 3. Amasado G | F6: 4. Moldeado G | G6: 5. Horno Túnel G | H6: 6. Enfriado G | I6: 7. Env. 1° G | J6: 8. Batido Panif. | K6: 9. Dosificado P. | L6: 10. Fermentado P. | M6: 11. Hornos Rotat. P. | N6: 12. Enfriado P. | O6: 13. Env. 1° P. | P6: 14. Dep. PT | Q6: 15. Lav./Scrap | R6: 16. Recirc. Mermas | S6: 17. Evac. Residuos | T6: 18. Calidad crudo | U6: 19. Calidad cocido | V6: SALIDAS (kg)
B7: 1. Depósito MP | C7: - | D7: ='3. Cuantificación Frecuencias'!I7 -> 1099.8 | U7: =SUM(C7:T7) -> 1099.8 | V7: =SUM(C7:U7) -> 2199.5999
B8: 2. Sección Pesado | D8: - | E8: ='3. Cuantificación Frecuencias'!I9 -> 600 | J8: ='3. Cuantificación Frecuencias'!I15 -> 600 | U8: =SUM(C8:T8) -> 1200 | V8: =SUM(C8:U8) -> 2400
B9: 3. Amasado G | E9: - | F9: ='3. Cuantificación Frecuencias'!I10 -> 600 | T9: ='3. Cuantificación Frecuencias'!I29 -> 0 | U9: =SUM(C9:T9) -> 600 | V9: =SUM(C9:U9) -> 1200
B10: 4. Moldeado G | F10: - | G10: ='3. Cuantificación Frecuencias'!I11 -> N/A | U10: =SUM(C10:T10) -> 0 | V10: =SUM(C10:U10) -> 0
B11: 5. Horno Túnel G | G11: - | H11: ='3. Cuantificación Frecuencias'!I12 -> N/A | U11: =SUM(C11:T11) -> 0 | V11: =SUM(C11:U11) -> 0
B12: 6. Cinta Enfriado G | H12: - | I12: ='3. Cuantificación Frecuencias'!I13 -> N/A | U12: =SUM(C12:T12) -> 0 | V12: =SUM(C12:U12) -> 0
B13: 7. Envasado 1° G | I13: - | P13: ='3. Cuantificación Frecuencias'!I14 -> 630 | U13: =SUM(C13:T13) -> 630 | V13: =SUM(C13:U13) -> 1260
B14: 8. Batido Panif. | J14: - | K14: ='3. Cuantificación Frecuencias'!I16 -> 600 | T14: ='3. Cuantificación Frecuencias'!I28 -> 0 | U14: =SUM(C14:T14) -> 600 | V14: =SUM(C14:U14) -> 1200
B15: 9. Dosificado P. | K15: - | L15: ='3. Cuantificación Frecuencias'!I17 -> 259.2 | U15: =SUM(C15:T15) -> 259.2 | V15: =SUM(C15:U15) -> 518.4
B16: 10. Fermentado P. | L16: - | M16: ='3. Cuantificación Frecuencias'!I19 -> 259.2 | U16: =SUM(C16:T16) -> 259.2 | V16: =SUM(C16:U16) -> 518.4
B17: 11. Hornos Rotat. P. | M17: - | N17: ='3. Cuantificación Frecuencias'!I20 -> 604.8 | U17: =SUM(C17:T17) -> 604.8 | V17: =SUM(C17:U17) -> 1209.6
B18: 12. Enfriado P. | N18: - | O18: ='3. Cuantificación Frecuencias'!I21 -> 420 | U18: =SUM(C18:T18) -> 420 | V18: =SUM(C18:U18) -> 840
B19: 13. Envasado 1° P. | O19: - | P19: ='3. Cuantificación Frecuencias'!I22 -> 500 | U19: =SUM(C19:T19) -> 500 | V19: =SUM(C19:U19) -> 1000
B20: 14. Depósito PT | P20: - | U20: =SUM(C20:T20) -> 0 | V20: =SUM(C20:U20) -> 0
B21: 15. Lavado / Scrap | Q21: - | U21: =SUM(C21:T21) -> 0 | V21: =SUM(C21:U21) -> 0
B22: 16. Recirculación Mermas | E22: ='3. Cuantificación Frecuencias'!I23 -> 6.0174234 | R22: - | U22: =SUM(C22:T22) -> 6.0174234 | V22: =SUM(C22:U22) -> 12.034847
B23: 17. Evacuación Residuos | Q23: ='3. Cuantificación Frecuencias'!I27 -> 50 | S23: - | U23: =SUM(C23:T23) -> 50 | V23: =SUM(C23:U23) -> 100
B24: 18. Calidad crudo | T24: - | U24: =SUM(C24:T24) -> 0 | V24: =SUM(C24:U24) -> 0
B25: 19. Calidad cocido | C25: =SUM(C7:C24) -> 0 | D25: =SUM(D7:D24) -> 1099.8 | E25: =SUM(E7:E24) -> 606.01742 | F25: =SUM(F7:F24) -> 600 | G25: =SUM(G7:G24) -> 0 | H25: =SUM(H7:H24) -> 0 | I25: =SUM(I7:I24) -> 0 | J25: =SUM(J7:J24) -> 600 | ... U25: =SUM(U7:U24) -> 6229.0174 | V25: =SUM(C25:U25) -> 12458.035
B26: ENTRADAS (kg) | C26: =SUM(C7:C25) -> 0 | D26: =SUM(D7:D25) -> 2199.5999 | E26: =SUM(E7:E25) -> 1212.0348 | F26: =SUM(F7:F25) -> 1200 | G26: =SUM(G7:G25) -> 0 | H26: =SUM(H7:H25) -> 0 | I26: =SUM(I7:I25) -> 0 | J26: =SUM(J7:J25) -> 1200 | ... V26: =SUM(V7:V25) -> 24916.07
B29: REFERENCIAS DE TIPOS DE FLUJO
B30: N/A [C] | C30: Flujo mecánico continuo | D30: En la Hoja 3 la frecuencia/masa figura como N/A por tratarse de una cinta continua; se mantiene la referencia directa.
B31: Azul / Vinculado | C31: Flujo vinculado a Hoja 3 | D31: Valor obtenido mediante fórmula que referencia directamente 3. Cuantificación Frecuencias.
B32: Calidad | C32: Movimiento de muestra | D32: La frecuencia se contabiliza como movimiento; en flujo de masa las muestras figuran con 0 kg/turno según la Hoja 3.

Sheet 7. Carga-Distancia & Horas
B2: HERRAMIENTA DE EVALUACIÓN DE LAYOUT (CARGA - DISTANCIA Y HORAS)
B3: Cálculo del Momento de Transporte (M = fij * dij), Esfuerzo Ponderado (kg·m) y Horas de Mano de Obra
B4: REFERENCIA DE FORMATO: | I4: Parámetro Configurable | L4: Fórmula Automática / Vinculada
B6: 1. CENTROIDES Y COORDENADAS DEL PLANO AUTOCAD (MODIFICABLES)
B8: N° | C8: Sector / Máquina | D8: Línea | E8: Coord X (m) | F8: Coord Y (m) | G8: Superficie (m²) | H8: Estado en Layout CAD
B9: 1 | C9: Depósito MP e Insumos | D9: Común | E9: 4 | F9: 18 | G9: 95 | H9: Ubicado en cabecera de recepción
B10: 2 | C10: Sección Pesado / Fraccionamiento | D10: Común | E10: 8.5 | F10: 18 | G10: 12 | H10: Adyacente a Depósito MP
B11: 3 | C11: Amasado Galletitas (Amasadora HJ25B) | D11: Galletitas | E11: 12 | F11: 20 | G11: 6.5 | H11: Alimentación de línea A
B12: 4 | C12: Moldeado Galletitas (Ralem R800) | D12: Galletitas | E12: 15 | F12: 20 | G12: 4 | H12: Inicio de línea continua
B13: 5 | C13: Horno Túnel Galletitas (GD-BTOM10) | D13: Galletitas | E13: 20 | F13: 20 | G13: 12 | H13: Línea recta (6 x 1,3 m)
B14: 6 | C14: Cinta de Enfriado Galletitas | D14: Galletitas | E14: 26 | F14: 20 | G14: 11.5 | H14: Transferencia a envasado
B15: 7 | C15: Envasado 1° Galletitas (Zon Pack) | D15: Galletitas | E15: 30 | F15: 20 | G15: 7.5 | H15: Envasadora vertical
B16: 8 | C16: Envasado 2° Galletitas (Mesa manual) | D16: Galletitas | E16: 32.5 | F16: 20 | G16: 5 | H16: Encajonado y conformado pallet
B17: 9 | C17: Batido Panificados (Moretti Ultra 60) | D17: Panificados | E17: 12 | F17: 14 | G17: 8.5 | H17: Alimentación de línea B
B18: 10 | C18: Dosificado Panificados (Indurpack) | D18: Panificados | E18: 15 | F18: 14 | G18: 6.5 | H18: Carga de carros con bandejas
B19: 11 | C19: Fermentador Panes (NKF-36RS) | D19: Panificados | E19: 18 | F19: 14 | G19: 6.5 | H19: Cámara de leudado
B20: 12 | C20: Hornos Rotativos Pauna SIGMA (2 u.) | D20: Panificados | E20: 22 | F20: 14 | G20: 14 | H20: Batería de cocción por carros
... B26: 18 | C26: Lavado de Bateas y Gestión Scrap | D26: Servicios | E26: 8.5 | F26: 12 | G26: 15 | H26: Zona periférica limpia
B29: 2. ANÁLISIS DE INTENSIDAD DE TRÁFICO, MOMENTO DE TRANSPORTE Y HORAS DE TRASLADO
B31: Tramo | C31: Origen | D31: Destino | E31: Frecuencia f (viajes/turno) | F31: Distancia d (m) | G31: Peso/Viaje (kg) | H31: Momento M (viajes·m / turno) | I31: Esfuerzo Masa (kg·m / turno) | J31: Velocidad (m/min) | K31: Tiempo Maniobra (min) | L31: Horas Traslado (hs/turno) | M31: Nivel de Criticidad
B32: T01 | C32: 2. Sección Pesado | D32: 3. Amasado Galletitas | E32: ='5. Desde-Hasta (Viajes)'!E8 -> 4 | F32: =ROUND(SQRT((E11-E10)^2+(F11-F10)^2), 1) -> 4 | G32: ='3. Cuantificación Frecuencias'!G9 -> 150 | H32: =E32*F32 -> 16 | I32: =H32*G32 -> 2400 | J32: ='3. Cuantificación Frecuencias'!K9 -> 48 | K32: ='3. Cuantificación Frecuencias'!L9 -> 0.3 | L32: =E32*((2*F32/J32)+K32)/60 -> 0.031111111 | M32: CRÍTICO (Alta Frecuencia) | O32: =L32*60 -> 1.8666667 | P32: =L32/8 -> 0.0038888889
B33: T02 | C33: 3. Amasado Galletitas | D33: 4. Moldeado Galletitas | E33: ='5. Desde-Hasta (Viajes)'!F9 -> 6 | F33: =ROUND(SQRT((E12-E11)^2+(F12-F11)^2), 1) -> 3 | G33: ='3. Cuantificación Frecuencias'!G10 -> 100 | H33: =E33*F33 -> 18 | I33: =H33*G33 -> 1800 | J33: ='3. Cuantificación Frecuencias'!K10 -> 42 | K33: ='3. Cuantificación Frecuencias'!L10 -> 0.35 | L33: =E33*((2*F33/J33)+K33)/60 -> 0.049285714 | M33: CRÍTICO (Alta Frecuencia) | O33: =L33*60 -> 2.9571429 | P33: =L33/8 -> 0.0061607143
B34: T03 | C34: 2. Sección Pesado | D34: 9. Batido Panificados | E34: ='5. Desde-Hasta (Viajes)'!J8 -> 4 | F34: =ROUND(SQRT((E17-E10)^2+(F17-F10)^2), 1) -> 5.3 | G34: ='3. Cuantificación Frecuencias'!G15 -> 150 | H34: =E34*F34 -> 21.2 | I34: =H34*G34 -> 3180 | J34: ='3. Cuantificación Frecuencias'!K15 -> 48 | K34: ='3. Cuantificación Frecuencias'!L15 -> 0.35 | L34: =E34*((2*F34/J34)+K34)/60 -> 0.038055556 | M34: ALTO | O34: =L34*60 -> 2.2833333 | P34: =L34/8 -> 0.0047569444
B35: T04 | C35: 9. Batido Panificados | D35: 10. Dosificado Panif. | E35: ='5. Desde-Hasta (Viajes)'!K14 -> 6 | F35: =ROUND(SQRT((E18-E17)^2+(F18-F17)^2), 1) -> 3 | G35: ='3. Cuantificación Frecuencias'!G16 -> 100 | H35: =E35*F35 -> 18 | I35: =H35*G35 -> 1800 | J35: ='3. Cuantificación Frecuencias'!K16 -> 42 | K35: ='3. Cuantificación Frecuencias'!L16 -> 0.35 | L35: =E35*((2*F35/J35)+K35)/60 -> 0.049285714 | M35: ALTO | O35: =L35*60 -> 2.9571429 | P35: =L35/8 -> 0.0061607143
B36: T05 | C36: 10. Dosificado Panif. | D36: 11. Fermentador Panes | E36: ='5. Desde-Hasta (Viajes)'!L15 -> 6 | F36: =ROUND(SQRT((E19-E18)^2+(F19-F18)^2), 1) -> 3 | G36: ='3. Cuantificación Frecuencias'!G17 -> 43.2 | H36: =E36*F36 -> 18 | I36: =H36*G36 -> 777.6 | J36: ='3. Cuantificación Frecuencias'!K17 -> 42 | K36: ='3. Cuantificación Frecuencias'!L17 -> 0.4 | L36: =E36*((2*F36/J36)+K36)/60 -> 0.054285714 | M36: ALTO | O36: =L36*60 -> 3.2571429 | P36: =L36/8 -> 0.0067857143
B37: T06 | C37: 11. Fermentador Panes | D37: 12. Hornos Rotativos | E37: ='5. Desde-Hasta (Viajes)'!M16 -> 6 | F37: =ROUND(SQRT((E20-E19)^2+(F20-F19)^2), 1) -> 4 | G37: ='3. Cuantificación Frecuencias'!G19 -> 43.2 | H37: =E37*F37 -> 24 | I37: =H37*G37 -> 1036.8 | J37: ='3. Cuantificación Frecuencias'!K19 -> 42 | K37: ='3. Cuantificación Frecuencias'!L19 -> 0.4 | L37: =E37*((2*F37/J37)+K37)/60 -> 0.059047619 | M37: ALTO | O37: =L37*60 -> 3.5428571 | P37: =L37/8 -> 0.0073809524
B38: T07 | C38: 12. Hornos Rotativos | D38: 13. Enfriado Panif. | E38: ='5. Desde-Hasta (Viajes)'!N17 -> 14 | F38: =ROUND(SQRT((E21-E20)^2+(F21-F20)^2), 1) -> 3.5 | G38: ='3. Cuantificación Frecuencias'!G20 -> 43.2 | H38: =E38*F38 -> 49 | I38: =H38*G38 -> 2116.8 | J38: ='3. Cuantificación Frecuencias'!K20 -> 36 | K38: ='3. Cuantificación Frecuencias'!L20 -> 0.45 | L38: =E38*((2*F38/J38)+K38)/60 -> 0.15037037 | M38: CRÍTICO (Seguridad 180°C) | O38: =L38*60 -> 9.0222222 | P38: =L38/8 -> 0.018796296
B39: T08 | C39: 13. Enfriado Panif. | D39: 14. Rebanado / Env 1° | E39: ='5. Desde-Hasta (Viajes)'!O18 -> 14 | F39: =ROUND(SQRT((E22-E21)^2+(F22-F21)^2), 1) -> 3 | G39: ='3. Cuantificación Frecuencias'!G21 -> 30 | H39: =E39*F39 -> 42 | I39: =H39*G39 -> 1260 | J39: ='3. Cuantificación Frecuencias'!K21 -> 42 | K39: ='3. Cuantificación Frecuencias'!L21 -> 0.35 | L39: =E39*((2*F39/J39)+K39)/60 -> 0.115 | M39: MEDIO | O39: =L39*60 -> 6.9 | P39: =L39/8 -> 0.014375
B40: T09 | C40: 1. Depósito MP | D40: 2. Sección Pesado | E40: ='5. Desde-Hasta (Viajes)'!D7 -> 2 | F40: =ROUND(SQRT((E10-E9)^2+(F10-F9)^2), 1) -> 4.5 | G40: ='3. Cuantificación Frecuencias'!G7 -> 549.89998 | H40: =E40*F40 -> 9 | I40: =H40*G40 -> 4949.0998 | J40: ='3. Cuantificación Frecuencias'!K7 -> 36 | K40: ='3. Cuantificación Frecuencias'!L7 -> 0.5 | L40: =E40*((2*F40/J40)+K40)/60 -> 0.025 | M40: MEDIO (Carga Pesada) | O40: =L40*60 -> 1.5 | P40: =L40/8 -> 0.003125
B41: T10 | C41: 7. Envasado 1° G | D41: 14. Depósito PT | E41: ='3. Cuantificación Frecuencias'!H14 -> 2 | F41: =ROUND(SQRT((E25-E15)^2+(F25-F15)^2), 1) -> 7.2 | G41: ='3. Cuantificación Frecuencias'!G14 -> 315 | H41: =E41*F41 -> 14.4 | I41: =H41*G41 -> 4536 | J41: ='3. Cuantificación Frecuencias'!K14 -> 36 | K41: ='3. Cuantificación Frecuencias'!L14 -> 0.75 | L41: =E41*((2*F41/J41)+K41)/60 -> 0.038333333 | M41: BAJO (Pallets) | O41: =L41*60 -> 2.3 | P41: =L41/8 -> 0.0047916667
B42: T11 | C42: 13. Envasado 1° P | D42: 14. Depósito PT | E42: ='3. Cuantificación Frecuencias'!H22 -> 2 | F42: =ROUND(SQRT((E25-E23)^2+(F25-F23)^2), 1) -> 5.9 | G42: ='3. Cuantificación Frecuencias'!G22 -> 250 | H42: =E42*F42 -> 11.8 | I42: =H42*G42 -> 2950 | J42: ='3. Cuantificación Frecuencias'!K22 -> 36 | K42: ='3. Cuantificación Frecuencias'!L22 -> 0.75 | L42: =E42*((2*F42/J42)+K42)/60 -> 0.035925926 | M42: BAJO (Pallets) | O42: =L42*60 -> 2.1555556 | P42: =L42/8 -> 0.0044907407
B43: TOTALES GENERALES | H43: =SUM(H32:H42) -> 241.4 | I43: =SUM(I32:I42) -> 26806.3 | L43: =SUM(L32:L42) -> 0.64570106 | M43: Minimizar en CAD | O43: =SUM(O32:O42) -> 38.742063 | P43: =SUM(P32:P42) -> 0.080712632

Sheet 8. Carga REL
A1: CARGA DE RELACIONES – MÉTODO REL | G1: Código | H1: Significado
A2: 17 áreas del croquis. Se toman las letras cargadas en 3. Cuantificación Frecuencias; combinaciones sin vínculo = U. | G2: A | H2: Absolutamente necesario
G3: E | H3: Especialmente importante
A4: Relación | B4: Área A | C4: Área B | D4: Grado REL | E4: Observación | G4: I | H4: Importante
A5: 1-2 | B5: 1. Depósito MP | C5: 2. Sección Pesado | D5: ='3. Cuantificación Frecuencias'!$S$7 -> A | E5: Hoja 3 – TR-01 | G5: O | H5: Ordinario / conveniente
A6: 1-3 | B6: 1. Depósito MP | C6: 3. Amasado G | D6: ="U" -> U | E6: Sin relación directa relevante | G6: U | H6: Sin importancia de proximidad
A7: 1-4 | B7: 1. Depósito MP | C7: 4. Moldeado G | D7: ="U" -> U | E7: Sin relación directa relevante | G7: X | H7: Proximidad indeseable
A8: 1-5 | B8: 1. Depósito MP | C8: 5. Horno Túnel G | D8: ="U" -> U | E8: Sin relación directa relevante
A9: 1-6 | B9: 1. Depósito MP | C9: 6. Cinta Enfriado G | D9: ="U" -> U | E9: Sin relación directa relevante
A10: 1-7 | B10: 1. Depósito MP | C10: 7. Envasado 1° G | D10: ="U" -> U | E10: Sin relación directa relevante
A11: 1-8 | B11: 1. Depósito MP | C11: 8. Batido Panif. | D11: ="U" -> U | E11: Sin relación directa relevante
A12: 1-9 | B12: 1. Depósito MP | C12: 9. Dosificado P. | D12: ="U" -> U | E12: Sin relación directa relevante
A13: 1-10 | B13: 1. Depósito MP | C13: 10. Fermentado P. | D13: ="U" -> U | E13: Sin relación directa relevante
A14: 1-11 | B14: 1. Depósito MP | C14: 11. Hornos Rotat. P. | D14: ="U" -> U | E14: Sin relación directa relevante
A15: 1-12 | B15: 1. Depósito MP | C15: 12. Enfriado P. | D15: ="U" -> U | E15: Sin relación directa relevante
A16: 1-13 | B16: 1. Depósito MP | C16: 13. Envasado 1° P. | D16: ="U" -> U | E16: Sin relación directa relevante
A17: 1-14 | B17: 1. Depósito MP | C17: 14. Depósito PT | D17: ="U" -> U | E17: Sin relación directa relevante
A18: 1-15 | B18: 1. Depósito MP | C18: 15. Lavado / Scrap | D18: ="U" -> U | E18: Sin relación directa relevante
A19: 1-16 | B19: 1. Depósito MP | C19: 16. Calidad crudo | D19: ="U" -> U | E19: Sin relación directa relevante
A20: 1-17 | B20: 1. Depósito MP | C20: 17. Calidad cocido | D20: ="U" -> U | E20: Sin relación directa relevante
A21: 2-3 | B21: 2. Sección Pesado | C21: 3. Amasado G | D21: ='3. Cuantificación Frecuencias'!$S$9 -> E | E21: Hoja 3 – TR-02
A22: 2-4 | B22: 2. Sección Pesado | C22: 4. Moldeado G | D22: ="U" -> U | E22: Sin relación directa relevante
A23: 2-5 | B23: 2. Sección Pesado | C23: 5. Horno Túnel G | D23: ="U" -> U | E23: Sin relación directa relevante
A24: 2-6 | B24: 2. Sección Pesado | C24: 6. Cinta Enfriado G | D24: ="U" -> U | E24: Sin relación directa relevante
A25: 2-7 | B25: 2. Sección Pesado | C25: 7. Envasado 1° G | D25: ="U" -> U | E25: Sin relación directa relevante
A26: 2-8 | B26: 2. Sección Pesado | C26: 8. Batido Panif. | D26: ='3. Cuantificación Frecuencias'!$S$15 -> E | E26: Hoja 3 – TR-08
A27: 2-9 | B27: 2. Sección Pesado | C27: 9. Dosificado P. | D27: ="U" -> U | E27: Sin relación directa relevante
A28: 2-10 | B28: 2. Sección Pesado | C28: 10. Fermentado P. | D28: ="U" -> U | E28: Sin relación directa relevante
A29: 2-11 | B29: 2. Sección Pesado | C29: 11. Hornos Rotat. P. | D29: ="U" -> U | E29: Sin relación directa relevante
A30: 2-12 | B30: 2. Sección Pesado | C30: 12. Enfriado P. | D30: ="U" -> U | E30: Sin relación directa relevante
A31: 2-13 | B31: 2. Sección Pesado | C31: 13. Envasado 1° P. | D31: ="U" -> U | E31: Sin relación directa relevante
A32: 2-14 | B32: 2. Sección Pesado | C32: 14. Depósito PT | D32: ="U" -> U | E32: Sin relación directa relevante
A33: 2-15 | B33: 2. Sección Pesado | C33: 15. Lavado / Scrap | D33: ="U" -> U | E33: Sin relación directa relevante
A34: 2-16 | B34: 2. Sección Pesado | C34: 16. Calidad crudo | D34: ="U" -> U | E34: Sin relación directa relevante
A35: 2-17 | B35: 2. Sección Pesado | C35: 17. Calidad cocido | D35: ="U" -> U | E35: Sin relación directa relevante
A36: 3-4 | B36: 3. Amasado G | C36: 4. Moldeado G | D36: ='3. Cuantificación Frecuencias'!$S$10 -> A | E36: Hoja 3 – TR-03
A37: 3-5 | B37: 3. Amasado G | C37: 5. Horno Túnel G | D37: ="U" -> U | E37: Sin relación directa relevante
A38: 3-6 | B38: 3. Amasado G | C38: 6. Cinta Enfriado G | D38: ='3. Cuantificación Frecuencias'!$S$24 -> O | E38: Hoja 3 – TR-16
A39: 3-7 | B39: 3. Amasado G | C39: 7. Envasado 1° G | D39: ="U" -> U | E39: Sin relación directa relevante
A40: 3-8 | B40: 3. Amasado G | C40: 8. Batido Panif. | D40: ="U" -> U | E40: Sin relación directa relevante
...

Sheet 9. Diagrama REL
A1: MATRIZ / DIAGRAMA REL – RELACIONES ENTRE ÁREAS
A2: Matriz derivada de 8. Carga REL. Diagrama inferior con la distribución del croquis del usuario.
B4: DESDE / HASTA | C4: DMP | D4: Pes | E4: A | F4: M | G4: Htun | H4: EnfrG | I4: EnvG | J4: B | K4: DOS | L4: FER | M4: Hrot | N4: EnfrP | O4: EnvP | P4: DPT | Q4: Scrap | R4: CCrud | S4: CCoc | U4: Código | V4: Representación | W4: Código | X4: Significado
B5: DMP | C5: - | D5: ='8. Carga REL'!$D$5 -> A | E5: ='8. Carga REL'!$D$6 -> U | F5: ='8. Carga REL'!$D$7 -> U | G5: ='8. Carga REL'!$D$8 -> U | H5: ='8. Carga REL'!$D$9 -> U | I5: ='8. Carga REL'!$D$10 -> U | J5: ='8. Carga REL'!$D$11 -> U | K5: ='8. Carga REL'!$D$12 -> U | L5: ='8. Carga REL'!$D$13 -> U | M5: ='8. Carga REL'!$D$14 -> U | N5: ='8. Carga REL'!$D$15 -> U | O5: ='8. Carga REL'!$D$16 -> U | P5: ='8. Carga REL'!$D$17 -> U | Q5: ='8. Carga REL'!$D$18 -> U | R5: ='8. Carga REL'!$D$19 -> U | S5: ='8. Carga REL'!$D$20 -> U | U5: A | V5: 4 líneas rojas | W5: A | X5: Absolutamente necesario
B6: Pes | C6: ='8. Carga REL'!$D$5 -> A | D6: - | E6: ='8. Carga REL'!$D$21 -> E | F6: ='8. Carga REL'!$D$22 -> U | G6: ='8. Carga REL'!$D$23 -> U | H6: ='8. Carga REL'!$D$24 -> U | I6: ='8. Carga REL'!$D$25 -> U | J6: ='8. Carga REL'!$D$26 -> E | K6: ='8. Carga REL'!$D$27 -> U | L6: ='8. Carga REL'!$D$28 -> U | M6: ='8. Carga REL'!$D$29 -> U | N6: ='8. Carga REL'!$D$30 -> U | O6: ='8. Carga REL'!$D$31 -> U | P6: ='8. Carga REL'!$D$32 -> U | Q6: ='8. Carga REL'!$D$33 -> U | R6: ='8. Carga REL'!$D$34 -> U | S6: ='8. Carga REL'!$D$35 -> U | U6: E | V6: 3 líneas amarillas | W6: E | X6: Especialmente importante
B7: A | C7: ='8. Carga REL'!$D$6 -> U | D7: ='8. Carga REL'!$D$21 -> E | E7: - | F7: ='8. Carga REL'!$D$36 -> A | G7: ='8. Carga REL'!$D$37 -> U | H7: ='8. Carga REL'!$D$38 -> O | I7: ='8. Carga REL'!$D$39 -> U | J7: ='8. Carga REL'!$D$40 -> U | K7: ='8. Carga REL'!$D$41 -> U | L7: ='8. Carga REL'!$D$42 -> U | M7: ='8. Carga REL'!$D$43 -> U | N7: ='8. Carga REL'!$D$44 -> U | O7: ='8. Carga REL'!$D$45 -> U | P7: ='8. Carga REL'!$D$46 -> U | Q7: ='8. Carga REL'!$D$47 -> U | R7: ='8. Carga REL'!$D$48 -> O | S7: ='8. Carga REL'!$D$49 -> U | U7: I | V7: 2 líneas verdes | W7: I | X7: Importante
B8: M | C8: ='8. Carga REL'!$D$7 -> U | D8: ='8. Carga REL'!$D$22 -> U | E8: ='8. Carga REL'!$D$36 -> A | F8: - | G8: ='8. Carga REL'!$D$50 -> A | H8: ='8. Carga REL'!$D$51 -> U | I8: ='8. Carga REL'!$D$52 -> U | J8: ='8. Carga REL'!$D$53 -> U | K8: ='8. Carga REL'!$D$54 -> U | L8: ='8. Carga REL'!$D$55 -> U | M8: ='8. Carga REL'!$D$56 -> U | N8: ='8. Carga REL'!$D$57 -> U | O8: ='8. Carga REL'!$D$58 -> U | P8: ='8. Carga REL'!$D$59 -> U | Q8: ='8. Carga REL'!$D$60 -> O | R8: ='8. Carga REL'!$D$61 -> U | S8: ='8. Carga REL'!$D$62 -> U | U8: O | V8: 1 línea azul | W8: O | X8: Ordinario / conveniente
B9: Htun | C9: ='8. Carga REL'!$D$8 -> U | D9: ='8. Carga REL'!$D$23 -> U | E9: ='8. Carga REL'!$D$37 -> U | F9: ='8. Carga REL'!$D$50 -> A | G9: - | H9: ='8. Carga REL'!$D$63 -> A | I9: ='8. Carga REL'!$D$64 -> U | J9: ='8. Carga REL'!$D$65 -> U | K9: ='8. Carga REL'!$D$66 -> U | L9: ='8. Carga REL'!$D$67 -> U | M9: ='8. Carga REL'!$D$68 -> U | N9: ='8. Carga REL'!$D$69 -> X | O9: ='8. Carga REL'!$D$70 -> U | P9: ='8. Carga REL'!$D$71 -> U | Q9: ='8. Carga REL'!$D$72 -> U | R9: ='8. Carga REL'!$D$73 -> U | S9: ='8. Carga REL'!$D$74 -> U | U9: U | V9: Sin línea | W9: U | X9: Sin importancia de proximidad
B10: EnfrG | C10: ='8. Carga REL'!$D$9 -> U | D10: ='8. Carga REL'!$D$24 -> U | E10: ='8. Carga REL'!$D$38 -> O | F10: ='8. Carga REL'!$D$51 -> U | G10: ='8. Carga REL'!$D$63 -> A | H10: - | I10: ='8. Carga REL'!$D$75 -> A | J10: ='8. Carga REL'!$D$76 -> U | K10: ='8. Carga REL'!$D$77 -> U | L10: ='8. Carga REL'!$D$78 -> U | M10: ='8. Carga REL'!$D$79 -> U | N10: ='8. Carga REL'!$D$80 -> U | O10: ='8. Carga REL'!$D$81 -> U | P10: ='8. Carga REL'!$D$82 -> U | Q10: ='8. Carga REL'!$D$83 -> O | R10: ='8. Carga REL'!$D$84 -> U | S10: ='8. Carga REL'!$D$85 -> I | U10: X | V10: Zigzag café | W10: X | X10: Proximidad indeseable
B11: EnvG | C11: ='8. Carga REL'!$D$10 -> U | D11: ='8. Carga REL'!$D$25 -> U | E11: ='8. Carga REL'!$D$39 -> U | F11: ='8. Carga REL'!$D$52 -> U | G11: ='8. Carga REL'!$D$64 -> U | H11: ='8. Carga REL'!$D$75 -> A | I11: - | J11: ='8. Carga REL'!$D$86 -> U | K11: ='8. Carga REL'!$D$87 -> U | L11: ='8. Carga REL'!$D$88 -> U | M11: ='8. Carga REL'!$D$89 -> U | N11: ='8. Carga REL'!$D$90 -> U | O11: ='8. Carga REL'!$D$91 -> U | P11: ='8. Carga REL'!$D$92 -> I | Q11: ='8. Carga REL'!$D$93 -> U | R11: ='8. Carga REL'!$D$94 -> U | S11: ='8. Carga REL'!$D$95 -> I
