Workbook

Sheet Programacion
A1: Semana | B1: Dia | C1: Producto | D1: Codigo | E1: Turnos | F1: Amasijos x turno | G1: Kg x amasijo | H1: Kg mezcla total
A2: Semana 1 | B2: Lunes | C2: Bizcochos sabor queso 150gr | D2: A05 | E2: 2 | F2: 12 | G2: 50 | H2: =E2*F2*G2 -> 1200
A3: Semana 1 | B3: Lunes | C3: Bizcochos sabor queso free | D3: A06 | E3: 1 | F3: 12 | G3: 50 | H3: =E3*F3*G3 -> 600
A4: Semana 1 | B4: Martes | C4: Galletitas simil chocolina | D4: A03 | E4: 3 | F4: 12 | G4: 50 | H4: =E4*F4*G4 -> 1800
A5: Semana 1 | B5: Miercoles | C5: Galletita simil chocolina free | D5: A02 | E5: 1 | F5: 12 | G5: 50 | H5: =E5*F5*G5 -> 600
A6: Semana 1 | B6: Miercoles | C6: Pepas de batata | D6: A04 | E6: 2 | F6: 12 | G6: 50 | H6: =E6*F6*G6 -> 1200
A7: Semana 1 | B7: Jueves | C7: Pepas de batata | D7: A04 | E7: 3 | F7: 12 | G7: 50 | H7: =E7*F7*G7 -> 1800
A8: Semana 1 | B8: Viernes | C8: Pepas de batata | D8: A04 | E8: 3 | F8: 12 | G8: 50 | H8: =E8*F8*G8 -> 1800
A9: Semana 2 | B9: Lunes | C9: Polvorones | D9: A08 | E9: 3 | F9: 12 | G9: 50 | H9: =E9*F9*G9 -> 1800
A10: Semana 2 | B10: Martes | C10: Polvorones | D10: A08 | E10: 2 | F10: 12 | G10: 50 | H10: =E10*F10*G10 -> 1200
A11: Semana 2 | B11: Martes | C11: Polvorones free | D11: A07 | E11: 1 | F11: 12 | G11: 50 | H11: =E11*F11*G11 -> 600
A12: Semana 2 | B12: Miercoles | C12: Polvorones free | D12: A07 | E12: 1 | F12: 12 | G12: 50 | H12: =E12*F12*G12 -> 600
A13: Semana 2 | B13: Miercoles | C13: Galletitas con chip | D13: A01 | E13: 2 | F13: 12 | G13: 50 | H13: =E13*F13*G13 -> 1200
... A15: Semana 2 | B15: Viernes | C15: Galletitas con chip | D15: A01 | E15: 3 | F15: 12 | G15: 50 | H15: =E15*F15*G15 -> 1800
A17: Mapeo confirmado por Bren: Polvorones=A08, Polvorones free=A07, Galletitas con chip=A01, Bizcochos sabor queso=A05, Bizcochos sabor queso free=A06.

Sheet Formulas
A1: Codigo | B1: Producto | C1: Ingrediente | D1: Porcentaje
A2: A01 | B2: Galletitas con chip (Chocolate con chips picante) | C2: FÉCULA DE MAÍZ | D2: 0.24645
A3: A01 | B3: Galletitas con chip (Chocolate con chips picante) | C3: HARINA DE ARROZ | D3: 0.1674
A4: A01 | B4: Galletitas con chip (Chocolate con chips picante) | C4: ACEITE VEGETAL INTERESTERIFICADO | D4: 0.1395
A5: A01 | B5: Galletitas con chip (Chocolate con chips picante) | C5: AZÚCAR | D5: 0.1302
A6: A01 | B6: Galletitas con chip (Chocolate con chips picante) | C6: CHIPS DE CHOCOLATE | D6: 0.0837
A7: A01 | B7: Galletitas con chip (Chocolate con chips picante) | C7: JARABE DE GLUCOSA | D7: 0.0558
A8: A01 | B8: Galletitas con chip (Chocolate con chips picante) | C8: CACAO ALCALINO | D8: 0.0372
A9: A01 | B9: Galletitas con chip (Chocolate con chips picante) | C9: HUEVO EN POLVO DESHIDRATADO | D9: 0.0186
A10: A01 | B10: Galletitas con chip (Chocolate con chips picante) | C10: MIEL | D10: 0.0186
A11: A01 | B11: Galletitas con chip (Chocolate con chips picante) | C11: GOMA XÁNTICA | D11: 0.00744
A12: A01 | B12: Galletitas con chip (Chocolate con chips picante) | C12: SAL | D12: 0.00465
A13: A01 | B13: Galletitas con chip (Chocolate con chips picante) | C13: BICARBONATO DE AMONIO | D13: 0.00465
... A163: B03 | B163: Budin con chips de chocolate | C163: SORBATO DE POTASIO | D163: 0.00178

Sheet Detalle_Consumo
A1: Semana | B1: Dia | C1: Producto | D1: Codigo | E1: Ingrediente | F1: Porcentaje | G1: Kg mezcla | H1: Kg consumido
A2: =Programacion!A2 -> Semana 1 | B2: =Programacion!B2 -> Lunes | C2: =Programacion!C2 -> Bizcochos sabor queso 150gr | D2: =Programacion!D2 -> A05 | E2: =Formulas!C63 -> HARINA DE ARROZ | F2: =Formulas!D63 -> 0.2325 | G2: =Programacion!H2 -> 1200 | H2: =F2*G2 -> 279
A3: =Programacion!A2 -> Semana 1 | B3: =Programacion!B2 -> Lunes | C3: =Programacion!C2 -> Bizcochos sabor queso 150gr | D3: =Programacion!D2 -> A05 | E3: =Formulas!C64 -> FÉCULA DE MAÍZ | F3: =Formulas!D64 -> 0.1767 | G3: =Programacion!H2 -> 1200 | H3: =F3*G3 -> 212.04
A4: =Programacion!A2 -> Semana 1 | B4: =Programacion!B2 -> Lunes | C4: =Programacion!C2 -> Bizcochos sabor queso 150gr | D4: =Programacion!D2 -> A05 | E4: =Formulas!C65 -> FÉCULA DE MANDIOCA | F4: =Formulas!D65 -> 0.1395 | G4: =Programacion!H2 -> 1200 | H4: =F4*G4 -> 167.4
A5: =Programacion!A2 -> Semana 1 | B5: =Programacion!B2 -> Lunes | C5: =Programacion!C2 -> Bizcochos sabor queso 150gr | D5: =Programacion!D2 -> A05 | E5: =Formulas!C66 -> QUESO DESCREMADO EN POLVO | F5: =Formulas!D66 -> 0.1209 | G5: =Programacion!H2 -> 1200 | H5: =F5*G5 -> 145.08
A6: =Programacion!A2 -> Semana 1 | B6: =Programacion!B2 -> Lunes | C6: =Programacion!C2 -> Bizcochos sabor queso 150gr | D6: =Programacion!D2 -> A05 | E6: =Formulas!C67 -> ACEITE DE GIRASOL ALTO OLEICO | F6: =Formulas!D67 -> 0.0744 | G6: =Programacion!H2 -> 1200 | H6: =F6*G6 -> 89.28
A7: =Programacion!A2 -> Semana 1 | B7: =Programacion!B2 -> Lunes | C7: =Programacion!C2 -> Bizcochos sabor queso 150gr | D7: =Programacion!D2 -> A05 | E7: =Formulas!C68 -> ACEITE VEGETAL INTERESTERIFICADO | F7: =Formulas!D68 -> 0.0558 | G7: =Programacion!H2 -> 1200 | H7: =F7*G7 -> 66.96
A8: =Programacion!A2 -> Semana 1 | B8: =Programacion!B2 -> Lunes | C8: =Programacion!C2 -> Bizcochos sabor queso 150gr | D8: =Programacion!D2 -> A05 | E8: =Formulas!C69 -> CLARA DE HUEVO EN POLVO | F8: =Formulas!D69 -> 0.0465 | G8: =Programacion!H2 -> 1200 | H8: =F8*G8 -> 55.8
A9: =Programacion!A2 -> Semana 1 | B9: =Programacion!B2 -> Lunes | C9: =Programacion!C2 -> Bizcochos sabor queso 150gr | D9: =Programacion!D2 -> A05 | E9: =Formulas!C70 -> DEXTROSA | F9: =Formulas!D70 -> 0.0372 | G9: =Programacion!H2 -> 1200 | H9: =F9*G9 -> 44.64
A10: =Programacion!A2 -> Semana 1 | B10: =Programacion!B2 -> Lunes | C10: =Programacion!C2 -> Bizcochos sabor queso 150gr | D10: =Programacion!D2 -> A05 | E10: =Formulas!C71 -> SAL | F10: =Formulas!D71 -> 0.01395 | G10: =Programacion!H2 -> 1200 | H10: =F10*G10 -> 16.74
A11: =Programacion!A2 -> Semana 1 | B11: =Programacion!B2 -> Lunes | C11: =Programacion!C2 -> Bizcochos sabor queso 150gr | D11: =Programacion!D2 -> A05 | E11: =Formulas!C72 -> ESENCIA DE QUESO | F11: =Formulas!D72 -> 0.0093 | G11: =Programacion!H2 -> 1200 | H11: =F11*G11 -> 11.16
A12: =Programacion!A2 -> Semana 1 | B12: =Programacion!B2 -> Lunes | C12: =Programacion!C2 -> Bizcochos sabor queso 150gr | D12: =Programacion!D2 -> A05 | E12: =Formulas!C73 -> GOMA XÁNTICA | F12: =Formulas!D73 -> 0.0093 | G12: =Programacion!H2 -> 1200 | H12: =F12*G12 -> 11.16
A13: =Programacion!A2 -> Semana 1 | B13: =Programacion!B2 -> Lunes | C13: =Programacion!C2 -> Bizcochos sabor queso 150gr | D13: =Programacion!D2 -> A05 | E13: =Formulas!C74 -> POLVO PARA HORNEAR | F13: =Formulas!D74 -> 0.0093 | G13: =Programacion!H2 -> 1200 | H13: =F13*G13 -> 11.16
A14: =Programacion!A2 -> Semana 1 | B14: =Programacion!B2 -> Lunes | C14: =Programacion!C2 -> Bizcochos sabor queso 150gr | D14: =Programacion!D2 -> A05 | E14: =Formulas!C75 -> BICARBONATO DE SODIO | F14: =Formulas!D75 -> 0.00465 | G14: =Programacion!H2 -> 1200 | H14: =F14*G14 -> 5.58
A15: =Programacion!A2 -> Semana 1 | B15: =Programacion!B2 -> Lunes | C15: =Programacion!C2 -> Bizcochos sabor queso 150gr | D15: =Programacion!D2 -> A05 | E15: =Formulas!C76 -> AGUA | F15: =Formulas!D76 -> 0.07 | G15: =Programacion!H2 -> 1200 | H15: =F15*G15 -> 84
A16: =Programacion!A3 -> Semana 1 | B16: =Programacion!B3 -> Lunes | C16: =Programacion!C3 -> Bizcochos sabor queso free | D16: =Programacion!D3 -> A06 | E16: =Formulas!C77 -> HARINA DE ARROZ | F16: =Formulas!D77 -> 0.2325 | G16: =Programacion!H3 -> 600 | H16: =F16*G16 -> 139.5
A17: =Programacion!A3 -> Semana 1 | B17: =Programacion!B3 -> Lunes | C17: =Programacion!C3 -> Bizcochos sabor queso free | D17: =Programacion!D3 -> A06 | E17: =Formulas!C78 -> FÉCULA DE MAÍZ | F17: =Formulas!D78 -> 0.1767 | G17: =Programacion!H3 -> 600 | H17: =F17*G17 -> 106.02
A18: =Programacion!A3 -> Semana 1 | B18: =Programacion!B3 -> Lunes | C18: =Programacion!C3 -> Bizcochos sabor queso free | D18: =Programacion!D3 -> A06 | E18: =Formulas!C79 -> FÉCULA DE MANDIOCA | F18: =Formulas!D79 -> 0.1302 | G18: =Programacion!H3 -> 600 | H18: =F18*G18 -> 78.12
A19: =Programacion!A3 -> Semana 1 | B19: =Programacion!B3 -> Lunes | C19: =Programacion!C3 -> Bizcochos sabor queso free | D19: =Programacion!D3 -> A06 | E19: =Formulas!C80 -> QUESO RALLADO | F19: =Formulas!D80 -> 0.1116 | G19: =Programacion!H3 -> 600 | H19: =F19*G19 -> 66.96
A20: =Programacion!A3 -> Semana 1 | B20: =Programacion!B3 -> Lunes | C20: =Programacion!C3 -> Bizcochos sabor queso free | D20: =Programacion!D3 -> A06 | E20: =Formulas!C81 -> GRASA VACUNA | F20: =Formulas!D81 -> 0.093 | G20: =Programacion!H3 -> 600 | H20: =F20*G20 -> 55.8
A21: =Programacion!A3 -> Semana 1 | B21: =Programacion!B3 -> Lunes | C21: =Programacion!C3 -> Bizcochos sabor queso free | D21: =Programacion!D3 -> A06 | E21: =Formulas!C82 -> ACEITE DE GIRASOL ALTO OLEICO | F21: =Formulas!D82 -> 0.0558 | G21: =Programacion!H3 -> 600 | H21: =F21*G21 -> 33.48
A22: =Programacion!A3 -> Semana 1 | B22: =Programacion!B3 -> Lunes | C22: =Programacion!C3 -> Bizcochos sabor queso free | D22: =Programacion!D3 -> A06 | E22: =Formulas!C83 -> HUEVO EN POLVO DESHIDRATADO | F22: =Formulas!D83 -> 0.0465 | G22: =Programacion!H3 -> 600 | H22: =F22*G22 -> 27.9
A23: =Programacion!A3 -> Semana 1 | B23: =Programacion!B3 -> Lunes | C23: =Programacion!C3 -> Bizcochos sabor queso free | D23: =Programacion!D3 -> A06 | E23: =Formulas!C84 -> DEXTROSA | F23: =Formulas!D84 -> 0.0372 | G23: =Programacion!H3 -> 600 | H23: =F23*G23 -> 22.32
A24: =Programacion!A3 -> Semana 1 | B24: =Programacion!B3 -> Lunes | C24: =Programacion!C3 -> Bizcochos sabor queso free | D24: =Programacion!D3 -> A06 | E24: =Formulas!C85 -> SAL | F24: =Formulas!D85 -> 0.01395 | G24: =Programacion!H3 -> 600 | H24: =F24*G24 -> 8.37
A25: =Programacion!A3 -> Semana 1 | B25: =Programacion!B3 -> Lunes | C25: =Programacion!C3 -> Bizcochos sabor queso free | D25: =Programacion!D3 -> A06 | E25: =Formulas!C86 -> ESENCIA DE QUESO | F25: =Formulas!D86 -> 0.0093 | G25: =Programacion!H3 -> 600 | H25: =F25*G25 -> 5.58
A26: =Programacion!A3 -> Semana 1 | B26: =Programacion!B3 -> Lunes | C26: =Programacion!C3 -> Bizcochos sabor queso free | D26: =Programacion!D3 -> A06 | E26: =Formulas!C87 -> GOMA XÁNTICA | F26: =Formulas!D87 -> 0.0093 | G26: =Programacion!H3 -> 600 | H26: =F26*G26 -> 5.58
A27: =Programacion!A3 -> Semana 1 | B27: =Programacion!B3 -> Lunes | C27: =Programacion!C3 -> Bizcochos sabor queso free | D27: =Programacion!D3 -> A06 | E27: =Formulas!C88 -> POLVO PARA HORNEAR | F27: =Formulas!D88 -> 0.0093 | G27: =Programacion!H3 -> 600 | H27: =F27*G27 -> 5.58
A28: =Programacion!A3 -> Semana 1 | B28: =Programacion!B3 -> Lunes | C28: =Programacion!C3 -> Bizcochos sabor queso free | D28: =Programacion!D3 -> A06 | E28: =Formulas!C89 -> BICARBONATO DE SODIO | F28: =Formulas!D89 -> 0.00465 | G28: =Programacion!H3 -> 600 | H28: =F28*G28 -> 2.79
A29: =Programacion!A3 -> Semana 1 | B29: =Programacion!B3 -> Lunes | C29: =Programacion!C3 -> Bizcochos sabor queso free | D29: =Programacion!D3 -> A06 | E29: =Formulas!C90 -> AGUA | F29: =Formulas!D90 -> 0.07 | G29: =Programacion!H3 -> 600 | H29: =F29*G29 -> 42
A30: =Programacion!A4 -> Semana 1 | B30: =Programacion!B4 -> Martes | C30: =Programacion!C4 -> Galletitas simil chocolina | D30: =Programacion!D4 -> A03 | E30: =Formulas!C35 -> HARINA DE ARROZ | F30: =Formulas!D35 -> 0.2511 | G30: =Programacion!H4 -> 1800 | H30: =F30*G30 -> 451.98
A31: =Programacion!A4 -> Semana 1 | B31: =Programacion!B4 -> Martes | C31: =Programacion!C4 -> Galletitas simil chocolina | D31: =Programacion!D4 -> A03 | E31: =Formulas!C36 -> FÉCULA DE MAÍZ | F31: =Formulas!D36 -> 0.2046 | G31: =Programacion!H4 -> 1800 | H31: =F31*G31 -> 368.28
A32: =Programacion!A4 -> Semana 1 | B32: =Programacion!B4 -> Martes | C32: =Programacion!C4 -> Galletitas simil chocolina | D32: =Programacion!D4 -> A03 | E32: =Formulas!C37 -> AZÚCAR | F32: =Formulas!D37 -> 0.1674 | G32: =Programacion!H4 -> 1800 | H32: =F32*G32 -> 301.32
A33: =Programacion!A4 -> Semana 1 | B33: =Programacion!B4 -> Martes | C33: =Programacion!C4 -> Galletitas simil chocolina | D33: =Programacion!D4 -> A03 | E33: =Formulas!C38 -> ACEITE VEGETAL INTERESTERIFICADO | F33: =Formulas!D38 -> 0.1302 | G33: =Programacion!H4 -> 1800 | H33: =F33*G33 -> 234.36
A34: =Programacion!A4 -> Semana 1 | B34: =Programacion!B4 -> Martes | C34: =Programacion!C4 -> Galletitas simil chocolina | D34: =Programacion!D4 -> A03 | E34: =Formulas!C39 -> CACAO ALCALINO | F34: =Formulas!D39 -> 0.0558 | G34: =Programacion!H4 -> 1800 | H34: =F34*G34 -> 100.44
A35: =Programacion!A4 -> Semana 1 | B35: =Programacion!B4 -> Martes | C35: =Programacion!C4 -> Galletitas simil chocolina | D35: =Programacion!D4 -> A03 | E35: =Formulas!C40 -> LECHE EN POLVO | F35: =Formulas!D40 -> 0.0558 | G35: =Programacion!H4 -> 1800 | H35: =F35*G35 -> 100.44
A36: =Programacion!A4 -> Semana 1 | B36: =Programacion!B4 -> Martes | C36: =Programacion!C4 -> Galletitas simil chocolina | D36: =Programacion!D4 -> A03 | E36: =Formulas!C41 -> HUEVO EN POLVO DESHIDRATADO | F36: =Formulas!D41 -> 0.0372 | G36: =Programacion!H4 -> 1800 | H36: =F36*G36 -> 66.96
A37: =Programacion!A4 -> Semana 1 | B37: =Programacion!B4 -> Martes | C37: =Programacion!C4 -> Galletitas simil chocolina | D37: =Programacion!D4 -> A03 | E37: =Formulas!C42 -> GOMA XÁNTICA | F37: =Formulas!D42 -> 0.0093 | G37: =Programacion!H4 -> 1800 | H37: =F37*G37 -> 16.74
A38: =Programacion!A4 -> Semana 1 | B38: =Programacion!B4 -> Martes | C38: =Programacion!C4 -> Galletitas simil chocolina | D38: =Programacion!D4 -> A03 | E38: =Formulas!C43 -> BICARBONATO DE SODIO | F38: =Formulas!D43 -> 0.00744 | G38: =Programacion!H4 -> 1800 | H38: =F38*G38 -> 13.392
A39: =Programacion!A4 -> Semana 1 | B39: =Programacion!B4 -> Martes | C39: =Programacion!C4 -> Galletitas simil chocolina | D39: =Programacion!D4 -> A03 | E39: =Formulas!C44 -> BICARBONATO DE CALCIO | F39: =Formulas!D44 -> 0.00744 | G39: =Programacion!H4 -> 1800 | H39: =F39*G39 -> 13.392
A40: =Programacion!A4 -> Semana 1 | B40: =Programacion!B4 -> Martes | C40: =Programacion!C4 -> Galletitas simil chocolina | D40: =Programacion!D4 -> A03 | E40: =Formulas!C45 -> ESENCIA DE CHOCOLATE | F40: =Formulas!D45 -> 0.00372 | G40: =Programacion!H4 -> 1800 | H40: =F40*G40 -> 6.696
...

Sheet Resumen_Semana1
A1: Materia Prima | B1: Lunes | C1: Martes | D1: Miercoles | E1: Jueves | F1: Viernes | G1: Total Semana 1 (kg)
A2: HARINA DE ARROZ | B2: =SUMIFS(Detalle_Consumo!$H:$H,Detalle_Consumo!$A:$A,"Semana 1",Detalle_Consumo!$B:$B,"Lunes",Detalle_Consumo!$E:$E,$A2) -> 418.5 | C2: =SUMIFS(Detalle_Consumo!$H:$H,Detalle_Consumo!$A:$A,"Semana 1",Detalle_Consumo!$B:$B,"Martes",Detalle_Consumo!$E:$E,$A2) -> 451.98 | D2: =SUMIFS(Detalle_Consumo!$H:$H,Detalle_Consumo!$A:$A,"Semana 1",Detalle_Consumo!$B:$B,"Miercoles",Detalle_Consumo!$E:$E,$A2) -> 303.3288 | E2: =SUMIFS(Detalle_Consumo!$H:$H,Detalle_Consumo!$A:$A,"Semana 1",Detalle_Consumo!$B:$B,"Jueves",Detalle_Consumo!$E:$E,$A2) -> 229.0032 | F2: =SUMIFS(Detalle_Consumo!$H:$H,Detalle_Consumo!$A:$A,"Semana 1",Detalle_Consumo!$B:$B,"Viernes",Detalle_Consumo!$E:$E,$A2) -> 229.0032 | G2: =SUM(B2:F2) -> 1631.8152
A3: FÉCULA DE MAÍZ | B3: =SUMIFS(Detalle_Consumo!$H:$H,Detalle_Consumo!$A:$A,"Semana 1",Detalle_Consumo!$B:$B,"Lunes",Detalle_Consumo!$E:$E,$A3) -> 318.06 | C3: =SUMIFS(Detalle_Consumo!$H:$H,Detalle_Consumo!$A:$A,"Semana 1",Detalle_Consumo!$B:$B,"Martes",Detalle_Consumo!$E:$E,$A3) -> 368.28 | D3: =SUMIFS(Detalle_Consumo!$H:$H,Detalle_Consumo!$A:$A,"Semana 1",Detalle_Consumo!$B:$B,"Miercoles",Detalle_Consumo!$E:$E,$A3) -> 394.1712 | E3: =SUMIFS(Detalle_Consumo!$H:$H,Detalle_Consumo!$A:$A,"Semana 1",Detalle_Consumo!$B:$B,"Jueves",Detalle_Consumo!$E:$E,$A3) -> 390.3768 | F3: =SUMIFS(Detalle_Consumo!$H:$H,Detalle_Consumo!$A:$A,"Semana 1",Detalle_Consumo!$B:$B,"Viernes",Detalle_Consumo!$E:$E,$A3) -> 390.3768 | G3: =SUM(B3:F3) -> 1861.2648
A4: FÉCULA DE MANDIOCA | B4: =SUMIFS(Detalle_Consumo!$H:$H,Detalle_Consumo!$A:$A,"Semana 1",Detalle_Consumo!$B:$B,"Lunes",Detalle_Consumo!$E:$E,$A4) -> 245.52 | C4: =SUMIFS(Detalle_Consumo!$H:$H,Detalle_Consumo!$A:$A,"Semana 1",Detalle_Consumo!$B:$B,"Martes",Detalle_Consumo!$E:$E,$A4) -> 0 | D4: =SUMIFS(Detalle_Consumo!$H:$H,Detalle_Consumo!$A:$A,"Semana 1",Detalle_Consumo!$B:$B,"Miercoles",Detalle_Consumo!$E:$E,$A4) -> 0 | E4: =SUMIFS(Detalle_Consumo!$H:$H,Detalle_Consumo!$A:$A,"Semana 1",Detalle_Consumo!$B:$B,"Jueves",Detalle_Consumo!$E:$E,$A4) -> 0 | F4: =SUMIFS(Detalle_Consumo!$H:$H,Detalle_Consumo!$A:$A,"Semana 1",Detalle_Consumo!$B:$B,"Viernes",Detalle_Consumo!$E:$E,$A4) -> 0 | G4: =SUM(B4:F4) -> 245.52
A5: QUESO DESCREMADO EN POLVO | B5: =SUMIFS(Detalle_Consumo!$H:$H,Detalle_Consumo!$A:$A,"Semana 1",Detalle_Consumo!$B:$B,"Lunes",Detalle_Consumo!$E:$E,$A5) -> 145.08 | C5: =SUMIFS(Detalle_Consumo!$H:$H,Detalle_Consumo!$A:$A,"Semana 1",Detalle_Consumo!$B:$B,"Martes",Detalle_Consumo!$E:$E,$A5) -> 0 | D5: =SUMIFS(Detalle_Consumo!$H:$H,Detalle_Consumo!$A:$A,"Semana 1",Detalle_Consumo!$B:$B,"Miercoles",Detalle_Consumo!$E:$E,$A5) -> 0 | E5: =SUMIFS(Detalle_Consumo!$H:$H,Detalle_Consumo!$A:$A,"Semana 1",Detalle_Consumo!$B:$B,"Jueves",Detalle_Consumo!$E:$E,$A5) -> 0 | F5: =SUMIFS(Detalle_Consumo!$H:$H,Detalle_Consumo!$A:$A,"Semana 1",Detalle_Consumo!$B:$B,"Viernes",Detalle_Consumo!$E:$E,$A5) -> 0 | G5: =SUM(B5:F5) -> 145.08
A6: ACEITE DE GIRASOL ALTO OLEICO | B6: =SUMIFS(Detalle_Consumo!$H:$H,Detalle_Consumo!$A:$A,"Semana 1",Detalle_Consumo!$B:$B,"Lunes",Detalle_Consumo!$E:$E,$A6) -> 122.76 | C6: =SUMIFS(Detalle_Consumo!$H:$H,Detalle_Consumo!$A:$A,"Semana 1",Detalle_Consumo!$B:$B,"Martes",Detalle_Consumo!$E:$E,$A6) -> 0 | D6: =SUMIFS(Detalle_Consumo!$H:$H,Detalle_Consumo!$A:$A,"Semana 1",Detalle_Consumo!$B:$B,"Miercoles",Detalle_Consumo!$E:$E,$A6) -> 0 | E6: =SUMIFS(Detalle_Consumo!$H:$H,Detalle_Consumo!$A:$A,"Semana 1",Detalle_Consumo!$B:$B,"Jueves",Detalle_Consumo!$E:$E,$A6) -> 0 | F6: =SUMIFS(Detalle_Consumo!$H:$H,Detalle_Consumo!$A:$A,"Semana 1",Detalle_Consumo!$B:$B,"Viernes",Detalle_Consumo!$E:$E,$A6) -> 0 | G6: =SUM(B6:F6) -> 122.76
A7: ACEITE VEGETAL INTERESTERIFICADO | B7: =SUMIFS(Detalle_Consumo!$H:$H,Detalle_Consumo!$A:$A,"Semana 1",Detalle_Consumo!$B:$B,"Lunes",Detalle_Consumo!$E:$E,$A7) -> 66.96 | C7: =SUMIFS(Detalle_Consumo!$H:$H,Detalle_Consumo!$A:$A,"Semana 1",Detalle_Consumo!$B:$B,"Martes",Detalle_Consumo!$E:$E,$A7) -> 234.36 | D7: =SUMIFS(Detalle_Consumo!$H:$H,Detalle_Consumo!$A:$A,"Semana 1",Detalle_Consumo!$B:$B,"Miercoles",Detalle_Consumo!$E:$E,$A7) -> 202.6656 | E7: =SUMIFS(Detalle_Consumo!$H:$H,Detalle_Consumo!$A:$A,"Semana 1",Detalle_Consumo!$B:$B,"Jueves",Detalle_Consumo!$E:$E,$A7) -> 186.8184 | F7: =SUMIFS(Detalle_Consumo!$H:$H,Detalle_Consumo!$A:$A,"Semana 1",Detalle_Consumo!$B:$B,"Viernes",Detalle_Consumo!$E:$E,$A7) -> 186.8184 | G7: =SUM(B7:F7) -> 877.6224
A8: CLARA DE HUEVO EN POLVO | B8: =SUMIFS(Detalle_Consumo!$H:$H,Detalle_Consumo!$A:$A,"Semana 1",Detalle_Consumo!$B:$B,"Lunes",Detalle_Consumo!$E:$E,$A8) -> 55.8 | C8: =SUMIFS(Detalle_Consumo!$H:$H,Detalle_Consumo!$A:$A,"Semana 1",Detalle_Consumo!$B:$B,"Martes",Detalle_Consumo!$E:$E,$A8) -> 0 | D8: =SUMIFS(Detalle_Consumo!$H:$H,Detalle_Consumo!$A:$A,"Semana 1",Detalle_Consumo!$B:$B,"Miercoles",Detalle_Consumo!$E:$E,$A8) -> 0 | E8: =SUMIFS(Detalle_Consumo!$H:$H,Detalle_Consumo!$A:$A,"Semana 1",Detalle_Consumo!$B:$B,"Jueves",Detalle_Consumo!$E:$E,$A8) -> 0 | F8: =SUMIFS(Detalle_Consumo!$H:$H,Detalle_Consumo!$A:$A,"Semana 1",Detalle_Consumo!$B:$B,"Viernes",Detalle_Consumo!$E:$E,$A8) -> 0 | G8: =SUM(B8:F8) -> 55.8
A9: DEXTROSA | B9: =SUMIFS(Detalle_Consumo!$H:$H,Detalle_Consumo!$A:$A,"Semana 1",Detalle_Consumo!$B:$B,"Lunes",Detalle_Consumo!$E:$E,$A9) -> 66.96 | C9: =SUMIFS(Detalle_Consumo!$H:$H,Detalle_Consumo!$A:$A,"Semana 1",Detalle_Consumo!$B:$B,"Martes",Detalle_Consumo!$E:$E,$A9) -> 0 | D9: =SUMIFS(Detalle_Consumo!$H:$H,Detalle_Consumo!$A:$A,"Semana 1",Detalle_Consumo!$B:$B,"Miercoles",Detalle_Consumo!$E:$E,$A9) -> 0 | E9: =SUMIFS(Detalle_Consumo!$H:$H,Detalle_Consumo!$A:$A,"Semana 1",Detalle_Consumo!$B:$B,"Jueves",Detalle_Consumo!$E:$E,$A9) -> 0 | F9: =SUMIFS(Detalle_Consumo!$H:$H,Detalle_Consumo!$A:$A,"Semana 1",Detalle_Consumo!$B:$B,"Viernes",Detalle_Consumo!$E:$E,$A9) -> 0 | G9: =SUM(B9:F9) -> 66.96
A10: SAL | B10: =SUMIFS(Detalle_Consumo!$H:$H,Detalle_Consumo!$A:$A,"Semana 1",Detalle_Consumo!$B:$B,"Lunes",Detalle_Consumo!$E:$E,$A10) -> 25.11 | C10: =SUMIFS(Detalle_Consumo!$H:$H,Detalle_Consumo!$A:$A,"Semana 1",Detalle_Consumo!$B:$B,"Martes",Detalle_Consumo!$E:$E,$A10) -> 0 | D10: =SUMIFS(Detalle_Consumo!$H:$H,Detalle_Consumo!$A:$A,"Semana 1",Detalle_Consumo!$B:$B,"Miercoles",Detalle_Consumo!$E:$E,$A10) -> 2.232 | E10: =SUMIFS(Detalle_Consumo!$H:$H,Detalle_Consumo!$A:$A,"Semana 1",Detalle_Consumo!$B:$B,"Jueves",Detalle_Consumo!$E:$E,$A10) -> 0 | F10: =SUMIFS(Detalle_Consumo!$H:$H,Detalle_Consumo!$A:$A,"Semana 1",Detalle_Consumo!$B:$B,"Viernes",Detalle_Consumo!$E:$E,$A10) -> 0 | G10: =SUM(B10:F10) -> 27.342
A11: ESENCIA DE QUESO | B11: =SUMIFS(Detalle_Consumo!$H:$H,Detalle_Consumo!$A:$A,"Semana 1",Detalle_Consumo!$B:$B,"Lunes",Detalle_Consumo!$E:$E,$A11) -> 16.74 | C11: =SUMIFS(Detalle_Consumo!$H:$H,Detalle_Consumo!$A:$A,"Semana 1",Detalle_Consumo!$B:$B,"Martes",Detalle_Consumo!$E:$E,$A11) -> 0 | D11: =SUMIFS(Detalle_Consumo!$H:$H,Detalle_Consumo!$A:$A,"Semana 1",Detalle_Consumo!$B:$B,"Miercoles",Detalle_Consumo!$E:$E,$A11) -> 0 | E11: =SUMIFS(Detalle_Consumo!$H:$H,Detalle_Consumo!$A:$A,"Semana 1",Detalle_Consumo!$B:$B,"Jueves",Detalle_Consumo!$E:$E,$A11) -> 0 | F11: =SUMIFS(Detalle_Consumo!$H:$H,Detalle_Consumo!$A:$A,"Semana 1",Detalle_Consumo!$B:$B,"Viernes",Detalle_Consumo!$E:$E,$A11) -> 0 | G11: =SUM(B11:F11) -> 16.74
A12: GOMA XÁNTICA | B12: =SUMIFS(Detalle_Consumo!$H:$H,Detalle_Consumo!$A:$A,"Semana 1",Detalle_Consumo!$B:$B,"Lunes",Detalle_Consumo!$E:$E,$A12) -> 16.74 | C12: =SUMIFS(Detalle_Consumo!$H:$H,Detalle_Consumo!$A:$A,"Semana 1",Detalle_Consumo!$B:$B,"Martes",Detalle_Consumo!$E:$E,$A12) -> 16.74 | D12: =SUMIFS(Detalle_Consumo!$H:$H,Detalle_Consumo!$A:$A,"Semana 1",Detalle_Consumo!$B:$B,"Miercoles",Detalle_Consumo!$E:$E,$A12) -> 10.40112 | E12: =SUMIFS(Detalle_Consumo!$H:$H,Detalle_Consumo!$A:$A,"Semana 1",Detalle_Consumo!$B:$B,"Jueves",Detalle_Consumo!$E:$E,$A12) -> 7.23168 | F12: =SUMIFS(Detalle_Consumo!$H:$H,Detalle_Consumo!$A:$A,"Semana 1",Detalle_Consumo!$B:$B,"Viernes",Detalle_Consumo!$E:$E,$A12) -> 7.23168 | G12: =SUM(B12:F12) -> 58.34448
A13: POLVO PARA HORNEAR | B13: =SUMIFS(Detalle_Consumo!$H:$H,Detalle_Consumo!$A:$A,"Semana 1",Detalle_Consumo!$B:$B,"Lunes",Detalle_Consumo!$E:$E,$A13) -> 16.74 | C13: =SUMIFS(Detalle_Consumo!$H:$H,Detalle_Consumo!$A:$A,"Semana 1",Detalle_Consumo!$B:$B,"Martes",Detalle_Consumo!$E:$E,$A13) -> 0 | D13: =SUMIFS(Detalle_Consumo!$H:$H,Detalle_Consumo!$A:$A,"Semana 1",Detalle_Consumo!$B:$B,"Miercoles",Detalle_Consumo!$E:$E,$A13) -> 0 | E13: =SUMIFS(Detalle_Consumo!$H:$H,Detalle_Consumo!$A:$A,"Semana 1",Detalle_Consumo!$B:$B,"Jueves",Detalle_Consumo!$E:$E,$A13) -> 0 | F13: =SUMIFS(Detalle_Consumo!$H:$H,Detalle_Consumo!$A:$A,"Semana 1",Detalle_Consumo!$B:$B,"Viernes",Detalle_Consumo!$E:$E,$A13) -> 0 | G13: =SUM(B13:F13) -> 16.74
... A35: ÁCIDO CÍTRICO | B35: =SUMIFS(Detalle_Consumo!$H:$H,Detalle_Consumo!$A:$A,"Semana 1",Detalle_Consumo!$B:$B,"Lunes",Detalle_Consumo!$E:$E,$A35) -> 0 | C35: =SUMIFS(Detalle_Consumo!$H:$H,Detalle_Consumo!$A:$A,"Semana 1",Detalle_Consumo!$B:$B,"Martes",Detalle_Consumo!$E:$E,$A35) -> 0 | D35: =SUMIFS(Detalle_Consumo!$H:$H,Detalle_Consumo!$A:$A,"Semana 1",Detalle_Consumo!$B:$B,"Miercoles",Detalle_Consumo!$E:$E,$A35) -> 1.5624 | E35: =SUMIFS(Detalle_Consumo!$H:$H,Detalle_Consumo!$A:$A,"Semana 1",Detalle_Consumo!$B:$B,"Jueves",Detalle_Consumo!$E:$E,$A35) -> 2.3436 | F35: =SUMIFS(Detalle_Consumo!$H:$H,Detalle_Consumo!$A:$A,"Semana 1",Detalle_Consumo!$B:$B,"Viernes",Detalle_Consumo!$E:$E,$A35) -> 2.3436 | G35: =SUM(B35:F35) -> 6.2496
A36: TOTAL GENERAL (kg) | B36: =SUM(B2:B35) -> 1800 | C36: =SUM(C2:C35) -> 1800 | D36: =SUM(D2:D35) -> 1800 | E36: =SUM(E2:E35) -> 1800 | F36: =SUM(F2:F35) -> 1800 | G36: =SUM(G2:G35) -> 9000

Sheet Resumen_Semana2
A1: Materia Prima | B1: Lunes | C1: Martes | D1: Miercoles | E1: Jueves | F1: Viernes | G1: Total Semana 2 (kg)
A2: FÉCULA DE MAÍZ | B2: =SUMIFS(Detalle_Consumo!$H:$H,Detalle_Consumo!$A:$A,"Semana 2",Detalle_Consumo!$B:$B,"Lunes",Detalle_Consumo!$E:$E,$A2) -> 468.72 | C2: =SUMIFS(Detalle_Consumo!$H:$H,Detalle_Consumo!$A:$A,"Semana 2",Detalle_Consumo!$B:$B,"Martes",Detalle_Consumo!$E:$E,$A2) -> 446.4 | D2: =SUMIFS(Detalle_Consumo!$H:$H,Detalle_Consumo!$A:$A,"Semana 2",Detalle_Consumo!$B:$B,"Miercoles",Detalle_Consumo!$E:$E,$A2) -> 429.66 | E2: =SUMIFS(Detalle_Consumo!$H:$H,Detalle_Consumo!$A:$A,"Semana 2",Detalle_Consumo!$B:$B,"Jueves",Detalle_Consumo!$E:$E,$A2) -> 443.61 | F2: =SUMIFS(Detalle_Consumo!$H:$H,Detalle_Consumo!$A:$A,"Semana 2",Detalle_Consumo!$B:$B,"Viernes",Detalle_Consumo!$E:$E,$A2) -> 443.61 | G2: =SUM(B2:F2) -> 2232
A3: HARINA DE ARROZ | B3: =SUMIFS(Detalle_Consumo!$H:$H,Detalle_Consumo!$A:$A,"Semana 2",Detalle_Consumo!$B:$B,"Lunes",Detalle_Consumo!$E:$E,$A3) -> 351.54 | C3: =SUMIFS(Detalle_Consumo!$H:$H,Detalle_Consumo!$A:$A,"Semana 2",Detalle_Consumo!$B:$B,"Martes",Detalle_Consumo!$E:$E,$A3) -> 357.12 | D3: =SUMIFS(Detalle_Consumo!$H:$H,Detalle_Consumo!$A:$A,"Semana 2",Detalle_Consumo!$B:$B,"Miercoles",Detalle_Consumo!$E:$E,$A3) -> 323.64 | E3: =SUMIFS(Detalle_Consumo!$H:$H,Detalle_Consumo!$A:$A,"Semana 2",Detalle_Consumo!$B:$B,"Jueves",Detalle_Consumo!$E:$E,$A3) -> 301.32 | F3: =SUMIFS(Detalle_Consumo!$H:$H,Detalle_Consumo!$A:$A,"Semana 2",Detalle_Consumo!$B:$B,"Viernes",Detalle_Consumo!$E:$E,$A3) -> 301.32 | G3: =SUM(B3:F3) -> 1634.94
A4: AZÚCAR | B4: =SUMIFS(Detalle_Consumo!$H:$H,Detalle_Consumo!$A:$A,"Semana 2",Detalle_Consumo!$B:$B,"Lunes",Detalle_Consumo!$E:$E,$A4) -> 267.84 | C4: =SUMIFS(Detalle_Consumo!$H:$H,Detalle_Consumo!$A:$A,"Semana 2",Detalle_Consumo!$B:$B,"Martes",Detalle_Consumo!$E:$E,$A4) -> 178.56 | D4: =SUMIFS(Detalle_Consumo!$H:$H,Detalle_Consumo!$A:$A,"Semana 2",Detalle_Consumo!$B:$B,"Miercoles",Detalle_Consumo!$E:$E,$A4) -> 156.24 | E4: =SUMIFS(Detalle_Consumo!$H:$H,Detalle_Consumo!$A:$A,"Semana 2",Detalle_Consumo!$B:$B,"Jueves",Detalle_Consumo!$E:$E,$A4) -> 234.36 | F4: =SUMIFS(Detalle_Consumo!$H:$H,Detalle_Consumo!$A:$A,"Semana 2",Detalle_Consumo!$B:$B,"Viernes",Detalle_Consumo!$E:$E,$A4) -> 234.36 | G4: =SUM(B4:F4) -> 1071.36
A5: ACEITE VEGETAL INTERESTERIFICADO | B5: =SUMIFS(Detalle_Consumo!$H:$H,Detalle_Consumo!$A:$A,"Semana 2",Detalle_Consumo!$B:$B,"Lunes",Detalle_Consumo!$E:$E,$A5) -> 251.1 | C5: =SUMIFS(Detalle_Consumo!$H:$H,Detalle_Consumo!$A:$A,"Semana 2",Detalle_Consumo!$B:$B,"Martes",Detalle_Consumo!$E:$E,$A5) -> 239.94 | D5: =SUMIFS(Detalle_Consumo!$H:$H,Detalle_Consumo!$A:$A,"Semana 2",Detalle_Consumo!$B:$B,"Miercoles",Detalle_Consumo!$E:$E,$A5) -> 239.94 | E5: =SUMIFS(Detalle_Consumo!$H:$H,Detalle_Consumo!$A:$A,"Semana 2",Detalle_Consumo!$B:$B,"Jueves",Detalle_Consumo!$E:$E,$A5) -> 251.1 | F5: =SUMIFS(Detalle_Consumo!$H:$H,Detalle_Consumo!$A:$A,"Semana 2",Detalle_Consumo!$B:$B,"Viernes",Detalle_Consumo!$E:$E,$A5) -> 251.1 | G5: =SUM(B5:F5) -> 1233.18
A6: JARABE DE GLUCOSA | B6: =SUMIFS(Detalle_Consumo!$H:$H,Detalle_Consumo!$A:$A,"Semana 2",Detalle_Consumo!$B:$B,"Lunes",Detalle_Consumo!$E:$E,$A6) -> 100.44 | C6: =SUMIFS(Detalle_Consumo!$H:$H,Detalle_Consumo!$A:$A,"Semana 2",Detalle_Consumo!$B:$B,"Martes",Detalle_Consumo!$E:$E,$A6) -> 66.96 | D6: =SUMIFS(Detalle_Consumo!$H:$H,Detalle_Consumo!$A:$A,"Semana 2",Detalle_Consumo!$B:$B,"Miercoles",Detalle_Consumo!$E:$E,$A6) -> 66.96 | E6: =SUMIFS(Detalle_Consumo!$H:$H,Detalle_Consumo!$A:$A,"Semana 2",Detalle_Consumo!$B:$B,"Jueves",Detalle_Consumo!$E:$E,$A6) -> 100.44 | F6: =SUMIFS(Detalle_Consumo!$H:$H,Detalle_Consumo!$A:$A,"Semana 2",Detalle_Consumo!$B:$B,"Viernes",Detalle_Consumo!$E:$E,$A6) -> 100.44 | G6: =SUM(B6:F6) -> 435.24
A7: EDULZUGAR | B7: =SUMIFS(Detalle_Consumo!$H:$H,Detalle_Consumo!$A:$A,"Semana 2",Detalle_Consumo!$B:$B,"Lunes",Detalle_Consumo!$E:$E,$A7) -> 50.22 | C7: =SUMIFS(Detalle_Consumo!$H:$H,Detalle_Consumo!$A:$A,"Semana 2",Detalle_Consumo!$B:$B,"Martes",Detalle_Consumo!$E:$E,$A7) -> 33.48 | D7: =SUMIFS(Detalle_Consumo!$H:$H,Detalle_Consumo!$A:$A,"Semana 2",Detalle_Consumo!$B:$B,"Miercoles",Detalle_Consumo!$E:$E,$A7) -> 0 | E7: =SUMIFS(Detalle_Consumo!$H:$H,Detalle_Consumo!$A:$A,"Semana 2",Detalle_Consumo!$B:$B,"Jueves",Detalle_Consumo!$E:$E,$A7) -> 0 | F7: =SUMIFS(Detalle_Consumo!$H:$H,Detalle_Consumo!$A:$A,"Semana 2",Detalle_Consumo!$B:$B,"Viernes",Detalle_Consumo!$E:$E,$A7) -> 0 | G7: =SUM(B7:F7) -> 83.7
A8: PANACEA | B8: =SUMIFS(Detalle_Consumo!$H:$H,Detalle_Consumo!$A:$A,"Semana 2",Detalle_Consumo!$B:$B,"Lunes",Detalle_Consumo!$E:$E,$A8) -> 50.22 | C8: =SUMIFS(Detalle_Consumo!$H:$H,Detalle_Consumo!$A:$A,"Semana 2",Detalle_Consumo!$B:$B,"Martes",Detalle_Consumo!$E:$E,$A8) -> 55.8 | D8: =SUMIFS(Detalle_Consumo!$H:$H,Detalle_Consumo!$A:$A,"Semana 2",Detalle_Consumo!$B:$B,"Miercoles",Detalle_Consumo!$E:$E,$A8) -> 22.32 | E8: =SUMIFS(Detalle_Consumo!$H:$H,Detalle_Consumo!$A:$A,"Semana 2",Detalle_Consumo!$B:$B,"Jueves",Detalle_Consumo!$E:$E,$A8) -> 0 | F8: =SUMIFS(Detalle_Consumo!$H:$H,Detalle_Consumo!$A:$A,"Semana 2",Detalle_Consumo!$B:$B,"Viernes",Detalle_Consumo!$E:$E,$A8) -> 0 | G8: =SUM(B8:F8) -> 128.34
A9: POLVO PARA HORNEAR | B9: =SUMIFS(Detalle_Consumo!$H:$H,Detalle_Consumo!$A:$A,"Semana 2",Detalle_Consumo!$B:$B,"Lunes",Detalle_Consumo!$E:$E,$A9) -> 33.48 | C9: =SUMIFS(Detalle_Consumo!$H:$H,Detalle_Consumo!$A:$A,"Semana 2",Detalle_Consumo!$B:$B,"Martes",Detalle_Consumo!$E:$E,$A9) -> 33.48 | D9: =SUMIFS(Detalle_Consumo!$H:$H,Detalle_Consumo!$A:$A,"Semana 2",Detalle_Consumo!$B:$B,"Miercoles",Detalle_Consumo!$E:$E,$A9) -> 11.16 | E9: =SUMIFS(Detalle_Consumo!$H:$H,Detalle_Consumo!$A:$A,"Semana 2",Detalle_Consumo!$B:$B,"Jueves",Detalle_Consumo!$E:$E,$A9) -> 0 | F9: =SUMIFS(Detalle_Consumo!$H:$H,Detalle_Consumo!$A:$A,"Semana 2",Detalle_Consumo!$B:$B,"Viernes",Detalle_Consumo!$E:$E,$A9) -> 0 | G9: =SUM(B9:F9) -> 78.12
A10: LECITINA DE SOJA | B10: =SUMIFS(Detalle_Consumo!$H:$H,Detalle_Consumo!$A:$A,"Semana 2",Detalle_Consumo!$B:$B,"Lunes",Detalle_Consumo!$E:$E,$A10) -> 16.74 | C10: =SUMIFS(Detalle_Consumo!$H:$H,Detalle_Consumo!$A:$A,"Semana 2",Detalle_Consumo!$B:$B,"Martes",Detalle_Consumo!$E:$E,$A10) -> 11.16 | D10: =SUMIFS(Detalle_Consumo!$H:$H,Detalle_Consumo!$A:$A,"Semana 2",Detalle_Consumo!$B:$B,"Miercoles",Detalle_Consumo!$E:$E,$A10) -> 0 | E10: =SUMIFS(Detalle_Consumo!$H:$H,Detalle_Consumo!$A:$A,"Semana 2",Detalle_Consumo!$B:$B,"Jueves",Detalle_Consumo!$E:$E,$A10) -> 0 | F10: =SUMIFS(Detalle_Consumo!$H:$H,Detalle_Consumo!$A:$A,"Semana 2",Detalle_Consumo!$B:$B,"Viernes",Detalle_Consumo!$E:$E,$A10) -> 0 | G10: =SUM(B10:F10) -> 27.9
A11: GOMA XÁNTICA | B11: =SUMIFS(Detalle_Consumo!$H:$H,Detalle_Consumo!$A:$A,"Semana 2",Detalle_Consumo!$B:$B,"Lunes",Detalle_Consumo!$E:$E,$A11) -> 16.74 | C11: =SUMIFS(Detalle_Consumo!$H:$H,Detalle_Consumo!$A:$A,"Semana 2",Detalle_Consumo!$B:$B,"Martes",Detalle_Consumo!$E:$E,$A11) -> 16.74 | D11: =SUMIFS(Detalle_Consumo!$H:$H,Detalle_Consumo!$A:$A,"Semana 2",Detalle_Consumo!$B:$B,"Miercoles",Detalle_Consumo!$E:$E,$A11) -> 14.508 | E11: =SUMIFS(Detalle_Consumo!$H:$H,Detalle_Consumo!$A:$A,"Semana 2",Detalle_Consumo!$B:$B,"Jueves",Detalle_Consumo!$E:$E,$A11) -> 13.392 | F11: =SUMIFS(Detalle_Consumo!$H:$H,Detalle_Consumo!$A:$A,"Semana 2",Detalle_Consumo!$B:$B,"Viernes",Detalle_Consumo!$E:$E,$A11) -> 13.392 | G11: =SUM(B11:F11) -> 74.772
A12: PROPIONATO DE CALCIO | B12: =SUMIFS(Detalle_Consumo!$H:$H,Detalle_Consumo!$A:$A,"Semana 2",Detalle_Consumo!$B:$B,"Lunes",Detalle_Consumo!$E:$E,$A12) -> 16.74 | C12: =SUMIFS(Detalle_Consumo!$H:$H,Detalle_Consumo!$A:$A,"Semana 2",Detalle_Consumo!$B:$B,"Martes",Detalle_Consumo!$E:$E,$A12) -> 16.74 | D12: =SUMIFS(Detalle_Consumo!$H:$H,Detalle_Consumo!$A:$A,"Semana 2",Detalle_Consumo!$B:$B,"Miercoles",Detalle_Consumo!$E:$E,$A12) -> 5.58 | E12: =SUMIFS(Detalle_Consumo!$H:$H,Detalle_Consumo!$A:$A,"Semana 2",Detalle_Consumo!$B:$B,"Jueves",Detalle_Consumo!$E:$E,$A12) -> 0 | F12: =SUMIFS(Detalle_Consumo!$H:$H,Detalle_Consumo!$A:$A,"Semana 2",Detalle_Consumo!$B:$B,"Viernes",Detalle_Consumo!$E:$E,$A12) -> 0 | G12: =SUM(B12:F12) -> 39.06
A13: BICARBONATO DE AMONIO | B13: =SUMIFS(Detalle_Consumo!$H:$H,Detalle_Consumo!$A:$A,"Semana 2",Detalle_Consumo!$B:$B,"Lunes",Detalle_Consumo!$E:$E,$A13) -> 16.74 | C13: =SUMIFS(Detalle_Consumo!$H:$H,Detalle_Consumo!$A:$A,"Semana 2",Detalle_Consumo!$B:$B,"Martes",Detalle_Consumo!$E:$E,$A13) -> 19.53 | D13: =SUMIFS(Detalle_Consumo!$H:$H,Detalle_Consumo!$A:$A,"Semana 2",Detalle_Consumo!$B:$B,"Miercoles",Detalle_Consumo!$E:$E,$A13) -> 13.95 | E13: =SUMIFS(Detalle_Consumo!$H:$H,Detalle_Consumo!$A:$A,"Semana 2",Detalle_Consumo!$B:$B,"Jueves",Detalle_Consumo!$E:$E,$A13) -> 8.37 | F13: =SUMIFS(Detalle_Consumo!$H:$H,Detalle_Consumo!$A:$A,"Semana 2",Detalle_Consumo!$B:$B,"Viernes",Detalle_Consumo!$E:$E,$A13) -> 8.37 | G13: =SUM(B13:F13) -> 66.96
... A28: JALAPEÑO DESHIDRATADO EN POLVO | B28: =SUMIFS(Detalle_Consumo!$H:$H,Detalle_Consumo!$A:$A,"Semana 2",Detalle_Consumo!$B:$B,"Lunes",Detalle_Consumo!$E:$E,$A28) -> 0 | C28: =SUMIFS(Detalle_Consumo!$H:$H,Detalle_Consumo!$A:$A,"Semana 2",Detalle_Consumo!$B:$B,"Martes",Detalle_Consumo!$E:$E,$A28) -> 0 | D28: =SUMIFS(Detalle_Consumo!$H:$H,Detalle_Consumo!$A:$A,"Semana 2",Detalle_Consumo!$B:$B,"Miercoles",Detalle_Consumo!$E:$E,$A28) -> 2.232 | E28: =SUMIFS(Detalle_Consumo!$H:$H,Detalle_Consumo!$A:$A,"Semana 2",Detalle_Consumo!$B:$B,"Jueves",Detalle_Consumo!$E:$E,$A28) -> 3.348 | F28: =SUMIFS(Detalle_Consumo!$H:$H,Detalle_Consumo!$A:$A,"Semana 2",Detalle_Consumo!$B:$B,"Viernes",Detalle_Consumo!$E:$E,$A28) -> 3.348 | G28: =SUM(B28:F28) -> 8.928
A29: TOTAL GENERAL (kg) | B29: =SUM(B2:B28) -> 1800 | C29: =SUM(C2:C28) -> 1800 | D29: =SUM(D2:D28) -> 1800 | E29: =SUM(E2:E28) -> 1800 | F29: =SUM(F2:F28) -> 1800 | G29: =SUM(G2:G28) -> 9000

Sheet Programacion_PanesBudines
A1: Dia | B1: Producto | C1: Codigo | D1: Turnos | E1: Batidos x turno | F1: Kg x batido | G1: Kg mezcla total
A2: Lunes | B2: Pan de molde | C2: B01 | D2: 3 | E2: 6 | F2: 30 | G2: =D2*E2*F2 -> 540
A3: Martes | B3: Budin de vainilla / citricos | C3: B02 | D3: 2 | E3: 6 | F3: 30 | G3: =D3*E3*F3 -> 360
A4: Martes | B4: Budin con chips de chocolate | C4: B03 | D4: 1 | E4: 6 | F4: 30 | G4: =D4*E4*F4 -> 180
A5: Miercoles | B5: Pan de molde | C5: B01 | D5: 3 | E5: 6 | F5: 30 | G5: =D5*E5*F5 -> 540
A6: Jueves | B6: Budin con chips de chocolate | C6: B03 | D6: 2 | E6: 6 | F6: 30 | G6: =D6*E6*F6 -> 360
A7: Jueves | B7: Budin de vainilla / citricos | C7: B02 | D7: 1 | E7: 6 | F7: 30 | G7: =D7*E7*F7 -> 180
A8: Viernes | B8: Budin de vainilla / citricos | C8: B02 | D8: 2 | E8: 6 | F8: 30 | G8: =D8*E8*F8 -> 360
A9: Viernes | B9: Budin con chips de chocolate | C9: B03 | D9: 1 | E9: 6 | F9: 30 | G9: =D9*E9*F9 -> 180
A11: Supuestos confirmados por Bren: 30 kg por batido, 6 batidos por turno. "BUDIN" alterna entre B02 y B03 turno a turno de forma continua en toda la semana (no se reinicia cada dia).

Sheet Detalle_Consumo_PanesBudines
A1: Dia | B1: Producto | C1: Codigo | D1: Ingrediente | E1: Porcentaje | F1: Kg mezcla | G1: Kg consumido
A2: =Programacion_PanesBudines!A2 -> Lunes | B2: =Programacion_PanesBudines!B2 -> Pan de molde | C2: =Programacion_PanesBudines!C2 -> B01 | D2: =Formulas!C121 -> AGUA | E2: =Formulas!D121 -> 0.473 | F2: =Programacion_PanesBudines!G2 -> 540 | G2: =E2*F2 -> 255.42
A3: =Programacion_PanesBudines!A2 -> Lunes | B3: =Programacion_PanesBudines!B2 -> Pan de molde | C3: =Programacion_PanesBudines!C2 -> B01 | D3: =Formulas!C122 -> HARINA DE ARROZ | E3: =Formulas!D122 -> 0.136 | F3: =Programacion_PanesBudines!G2 -> 540 | G3: =E3*F3 -> 73.44
A4: =Programacion_PanesBudines!A2 -> Lunes | B4: =Programacion_PanesBudines!B2 -> Pan de molde | C4: =Programacion_PanesBudines!C2 -> B01 | D4: =Formulas!C123 -> FÉCULA DE MAÍZ | E4: =Formulas!D123 -> 0.102 | F4: =Programacion_PanesBudines!G2 -> 540 | G4: =E4*F4 -> 55.08
A5: =Programacion_PanesBudines!A2 -> Lunes | B5: =Programacion_PanesBudines!B2 -> Pan de molde | C5: =Programacion_PanesBudines!C2 -> B01 | D5: =Formulas!C124 -> FÉCULA DE MANDIOCA | E5: =Formulas!D124 -> 0.085 | F5: =Programacion_PanesBudines!G2 -> 540 | G5: =E5*F5 -> 45.9
A6: =Programacion_PanesBudines!A2 -> Lunes | B6: =Programacion_PanesBudines!B2 -> Pan de molde | C6: =Programacion_PanesBudines!C2 -> B01 | D6: =Formulas!C125 -> ACEITE DE GIRASOL ALTO OLEICO | E6: =Formulas!D125 -> 0.051 | F6: =Programacion_PanesBudines!G2 -> 540 | G6: =E6*F6 -> 27.54
A7: =Programacion_PanesBudines!A2 -> Lunes | B7: =Programacion_PanesBudines!B2 -> Pan de molde | C7: =Programacion_PanesBudines!C2 -> B01 | D7: =Formulas!C126 -> AZÚCAR | E7: =Formulas!D126 -> 0.034 | F7: =Programacion_PanesBudines!G2 -> 540 | G7: =E7*F7 -> 18.36
A8: =Programacion_PanesBudines!A2 -> Lunes | B8: =Programacion_PanesBudines!B2 -> Pan de molde | C8: =Programacion_PanesBudines!C2 -> B01 | D8: =Formulas!C127 -> LECHE EN POLVO | E8: =Formulas!D127 -> 0.034 | F8: =Programacion_PanesBudines!G2 -> 540 | G8: =E8*F8 -> 18.36
A9: =Programacion_PanesBudines!A2 -> Lunes | B9: =Programacion_PanesBudines!B2 -> Pan de molde | C9: =Programacion_PanesBudines!C2 -> B01 | D9: =Formulas!C128 -> PSYLLIUM | E9: =Formulas!D128 -> 0.0255 | F9: =Programacion_PanesBudines!G2 -> 540 | G9: =E9*F9 -> 13.77
A10: =Programacion_PanesBudines!A2 -> Lunes | B10: =Programacion_PanesBudines!B2 -> Pan de molde | C10: =Programacion_PanesBudines!C2 -> B01 | D10: =Formulas!C129 -> FIBRA C 200 | E10: =Formulas!D129 -> 0.02125 | F10: =Programacion_PanesBudines!G2 -> 540 | G10: =E10*F10 -> 11.475
A11: =Programacion_PanesBudines!A2 -> Lunes | B11: =Programacion_PanesBudines!B2 -> Pan de molde | C11: =Programacion_PanesBudines!C2 -> B01 | D11: =Formulas!C130 -> LEVADURA | E11: =Formulas!D130 -> 0.017 | F11: =Programacion_PanesBudines!G2 -> 540 | G11: =E11*F11 -> 9.18
A12: =Programacion_PanesBudines!A2 -> Lunes | B12: =Programacion_PanesBudines!B2 -> Pan de molde | C12: =Programacion_PanesBudines!C2 -> B01 | D12: =Formulas!C131 -> GOMA XÁNTICA | E12: =Formulas!D131 -> 0.01275 | F12: =Programacion_PanesBudines!G2 -> 540 | G12: =E12*F12 -> 6.885
A13: =Programacion_PanesBudines!A2 -> Lunes | B13: =Programacion_PanesBudines!B2 -> Pan de molde | C13: =Programacion_PanesBudines!C2 -> B01 | D13: =Formulas!C132 -> SAL | E13: =Formulas!D132 -> 0.0085 | F13: =Programacion_PanesBudines!G2 -> 540 | G13: =E13*F13 -> 4.59
A14: =Programacion_PanesBudines!A3 -> Martes | B14: =Programacion_PanesBudines!B3 -> Budin de vainilla / citricos | C14: =Programacion_PanesBudines!C3 -> B02 | D14: =Formulas!C133 -> AZÚCAR | E14: =Formulas!D133 -> 0.1958 | F14: =Programacion_PanesBudines!G3 -> 360 | G14: =E14*F14 -> 70.488
A15: =Programacion_PanesBudines!A3 -> Martes | B15: =Programacion_PanesBudines!B3 -> Budin de vainilla / citricos | C15: =Programacion_PanesBudines!C3 -> B02 | D15: =Formulas!C134 -> MARGARINA | E15: =Formulas!D134 -> 0.1424 | F15: =Programacion_PanesBudines!G3 -> 360 | G15: =E15*F15 -> 51.264
A16: =Programacion_PanesBudines!A3 -> Martes | B16: =Programacion_PanesBudines!B3 -> Budin de vainilla / citricos | C16: =Programacion_PanesBudines!C3 -> B02 | D16: =Formulas!C135 -> HARINA DE ARROZ | E16: =Formulas!D135 -> 0.1246 | F16: =Programacion_PanesBudines!G3 -> 360 | G16: =E16*F16 -> 44.856
A17: =Programacion_PanesBudines!A3 -> Martes | B17: =Programacion_PanesBudines!B3 -> Budin de vainilla / citricos | C17: =Programacion_PanesBudines!C3 -> B02 | D17: =Formulas!C136 -> FÉCULA DE MAÍZ | E17: =Formulas!D136 -> 0.1068 | F17: =Programacion_PanesBudines!G3 -> 360 | G17: =E17*F17 -> 38.448
A18: =Programacion_PanesBudines!A3 -> Martes | B18: =Programacion_PanesBudines!B3 -> Budin de vainilla / citricos | C18: =Programacion_PanesBudines!C3 -> B02 | D18: =Formulas!C137 -> AGUA | E18: =Formulas!D137 -> 0.2079 | F18: =Programacion_PanesBudines!G3 -> 360 | G18: =E18*F18 -> 74.844
A19: =Programacion_PanesBudines!A3 -> Martes | B19: =Programacion_PanesBudines!B3 -> Budin de vainilla / citricos | C19: =Programacion_PanesBudines!C3 -> B02 | D19: =Formulas!C138 -> HUEVO EN POLVO DESHIDRATADO | E19: =Formulas!D138 -> 0.0534 | F19: =Programacion_PanesBudines!G3 -> 360 | G19: =E19*F19 -> 19.224
A20: =Programacion_PanesBudines!A3 -> Martes | B20: =Programacion_PanesBudines!B3 -> Budin de vainilla / citricos | C20: =Programacion_PanesBudines!C3 -> B02 | D20: =Formulas!C139 -> FÉCULA DE MANDIOCA | E20: =Formulas!D139 -> 0.0534 | F20: =Programacion_PanesBudines!G3 -> 360 | G20: =E20*F20 -> 19.224
A21: =Programacion_PanesBudines!A3 -> Martes | B21: =Programacion_PanesBudines!B3 -> Budin de vainilla / citricos | C21: =Programacion_PanesBudines!C3 -> B02 | D21: =Formulas!C140 -> LECHE EN POLVO | E21: =Formulas!D140 -> 0.0445 | F21: =Programacion_PanesBudines!G3 -> 360 | G21: =E21*F21 -> 16.02
A22: =Programacion_PanesBudines!A3 -> Martes | B22: =Programacion_PanesBudines!B3 -> Budin de vainilla / citricos | C22: =Programacion_PanesBudines!C3 -> B02 | D22: =Formulas!C141 -> PANACEA | E22: =Formulas!D141 -> 0.0178 | F22: =Programacion_PanesBudines!G3 -> 360 | G22: =E22*F22 -> 6.408
A23: =Programacion_PanesBudines!A3 -> Martes | B23: =Programacion_PanesBudines!B3 -> Budin de vainilla / citricos | C23: =Programacion_PanesBudines!C3 -> B02 | D23: =Formulas!C142 -> POLVO PARA HORNEAR | E23: =Formulas!D142 -> 0.0178 | F23: =Programacion_PanesBudines!G3 -> 360 | G23: =E23*F23 -> 6.408
A24: =Programacion_PanesBudines!A3 -> Martes | B24: =Programacion_PanesBudines!B3 -> Budin de vainilla / citricos | C24: =Programacion_PanesBudines!C3 -> B02 | D24: =Formulas!C143 -> GOMA XÁNTICA | E24: =Formulas!D143 -> 0.0089 | F24: =Programacion_PanesBudines!G3 -> 360 | G24: =E24*F24 -> 3.204
A25: =Programacion_PanesBudines!A3 -> Martes | B25: =Programacion_PanesBudines!B3 -> Budin de vainilla / citricos | C25: =Programacion_PanesBudines!C3 -> B02 | D25: =Formulas!C144 -> PROPIONATO DE CALCIO | E25: =Formulas!D144 -> 0.0089 | F25: =Programacion_PanesBudines!G3 -> 360 | G25: =E25*F25 -> 3.204
A26: =Programacion_PanesBudines!A3 -> Martes | B26: =Programacion_PanesBudines!B3 -> Budin de vainilla / citricos | C26: =Programacion_PanesBudines!C3 -> B02 | D26: =Formulas!C145 -> ESENCIA DE VAINILLA / NARANJA / LIMÓN | E26: =Formulas!D145 -> 0.01068 | F26: =Programacion_PanesBudines!G3 -> 360 | G26: =E26*F26 -> 3.8448
A27: =Programacion_PanesBudines!A3 -> Martes | B27: =Programacion_PanesBudines!B3 -> Budin de vainilla / citricos | C27: =Programacion_PanesBudines!C3 -> B02 | D27: =Formulas!C146 -> SAL | E27: =Formulas!D146 -> 0.00445 | F27: =Programacion_PanesBudines!G3 -> 360 | G27: =E27*F27 -> 1.602
A28: =Programacion_PanesBudines!A3 -> Martes | B28: =Programacion_PanesBudines!B3 -> Budin de vainilla / citricos | C28: =Programacion_PanesBudines!C3 -> B02 | D28: =Formulas!C147 -> SORBATO DE POTASIO | E28: =Formulas!D147 -> 0.00267 | F28: =Programacion_PanesBudines!G3 -> 360 | G28: =E28*F28 -> 0.9612
A29: =Programacion_PanesBudines!A4 -> Martes | B29: =Programacion_PanesBudines!B4 -> Budin con chips de chocolate | C29: =Programacion_PanesBudines!C4 -> B03 | D29: =Formulas!C148 -> AZÚCAR | E29: =Formulas!D148 -> 0.178 | F29: =Programacion_PanesBudines!G4 -> 180 | G29: =E29*F29 -> 32.04
A30: =Programacion_PanesBudines!A4 -> Martes | B30: =Programacion_PanesBudines!B4 -> Budin con chips de chocolate | C30: =Programacion_PanesBudines!C4 -> B03 | D30: =Formulas!C149 -> MARGARINA | E30: =Formulas!D149 -> 0.1335 | F30: =Programacion_PanesBudines!G4 -> 180 | G30: =E30*F30 -> 24.03
A31: =Programacion_PanesBudines!A4 -> Martes | B31: =Programacion_PanesBudines!B4 -> Budin con chips de chocolate | C31: =Programacion_PanesBudines!C4 -> B03 | D31: =Formulas!C150 -> HARINA DE ARROZ | E31: =Formulas!D150 -> 0.1157 | F31: =Programacion_PanesBudines!G4 -> 180 | G31: =E31*F31 -> 20.826
A32: =Programacion_PanesBudines!A4 -> Martes | B32: =Programacion_PanesBudines!B4 -> Budin con chips de chocolate | C32: =Programacion_PanesBudines!C4 -> B03 | D32: =Formulas!C151 -> FÉCULA DE MAÍZ | E32: =Formulas!D151 -> 0.0979 | F32: =Programacion_PanesBudines!G4 -> 180 | G32: =E32*F32 -> 17.622
A33: =Programacion_PanesBudines!A4 -> Martes | B33: =Programacion_PanesBudines!B4 -> Budin con chips de chocolate | C33: =Programacion_PanesBudines!C4 -> B03 | D33: =Formulas!C152 -> AGUA | E33: =Formulas!D152 -> 0.199 | F33: =Programacion_PanesBudines!G4 -> 180 | G33: =E33*F33 -> 35.82
A34: =Programacion_PanesBudines!A4 -> Martes | B34: =Programacion_PanesBudines!B4 -> Budin con chips de chocolate | C34: =Programacion_PanesBudines!C4 -> B03 | D34: =Formulas!C153 -> CHIPS DE CHOCOLATE | E34: =Formulas!D153 -> 0.0801 | F34: =Programacion_PanesBudines!G4 -> 180 | G34: =E34*F34 -> 14.418
A35: =Programacion_PanesBudines!A4 -> Martes | B35: =Programacion_PanesBudines!B4 -> Budin con chips de chocolate | C35: =Programacion_PanesBudines!C4 -> B03 | D35: =Formulas!C154 -> HUEVO EN POLVO DESHIDRATADO | E35: =Formulas!D154 -> 0.0534 | F35: =Programacion_PanesBudines!G4 -> 180 | G35: =E35*F35 -> 9.612
A36: =Programacion_PanesBudines!A4 -> Martes | B36: =Programacion_PanesBudines!B4 -> Budin con chips de chocolate | C36: =Programacion_PanesBudines!C4 -> B03 | D36: =Formulas!C155 -> FÉCULA DE MANDIOCA | E36: =Formulas!D155 -> 0.0445 | F36: =Programacion_PanesBudines!G4 -> 180 | G36: =E36*F36 -> 8.01
A37: =Programacion_PanesBudines!A4 -> Martes | B37: =Programacion_PanesBudines!B4 -> Budin con chips de chocolate | C37: =Programacion_PanesBudines!C4 -> B03 | D37: =Formulas!C156 -> LECHE EN POLVO | E37: =Formulas!D156 -> 0.0356 | F37: =Programacion_PanesBudines!G4 -> 180 | G37: =E37*F37 -> 6.408
A38: =Programacion_PanesBudines!A4 -> Martes | B38: =Programacion_PanesBudines!B4 -> Budin con chips de chocolate | C38: =Programacion_PanesBudines!C4 -> B03 | D38: =Formulas!C157 -> PANACEA | E38: =Formulas!D157 -> 0.0178 | F38: =Programacion_PanesBudines!G4 -> 180 | G38: =E38*F38 -> 3.204
A39: =Programacion_PanesBudines!A4 -> Martes | B39: =Programacion_PanesBudines!B4 -> Budin con chips de chocolate | C39: =Programacion_PanesBudines!C4 -> B03 | D39: =Formulas!C158 -> POLVO PARA HORNEAR | E39: =Formulas!D158 -> 0.0178 | F39: =Programacion_PanesBudines!G4 -> 180 | G39: =E39*F39 -> 3.204
A40: =Programacion_PanesBudines!A4 -> Martes | B40: =Programacion_PanesBudines!B4 -> Budin con chips de chocolate | C40: =Programacion_PanesBudines!C4 -> B03 | D40: =Formulas!C159 -> GOMA XÁNTICA | E40: =Formulas!D159 -> 0.0089 | F40: =Programacion_PanesBudines!G4 -> 180 | G40: =E40*F40 -> 1.602
...

Sheet Resumen_PanesBudines
A1: Materia Prima | B1: Lunes | C1: Martes | D1: Miercoles | E1: Jueves | F1: Viernes | G1: Total Semana (kg)
A2: AGUA | B2: =SUMIFS(Detalle_Consumo_PanesBudines!$G:$G,Detalle_Consumo_PanesBudines!$A:$A,"Lunes",Detalle_Consumo_PanesBudines!$D:$D,$A2) -> 255.42 | C2: =SUMIFS(Detalle_Consumo_PanesBudines!$G:$G,Detalle_Consumo_PanesBudines!$A:$A,"Martes",Detalle_Consumo_PanesBudines!$D:$D,$A2) -> 110.664 | D2: =SUMIFS(Detalle_Consumo_PanesBudines!$G:$G,Detalle_Consumo_PanesBudines!$A:$A,"Miercoles",Detalle_Consumo_PanesBudines!$D:$D,$A2) -> 255.42 | E2: =SUMIFS(Detalle_Consumo_PanesBudines!$G:$G,Detalle_Consumo_PanesBudines!$A:$A,"Jueves",Detalle_Consumo_PanesBudines!$D:$D,$A2) -> 109.062 | F2: =SUMIFS(Detalle_Consumo_PanesBudines!$G:$G,Detalle_Consumo_PanesBudines!$A:$A,"Viernes",Detalle_Consumo_PanesBudines!$D:$D,$A2) -> 110.664 | G2: =SUM(B2:F2) -> 841.23
A3: HARINA DE ARROZ | B3: =SUMIFS(Detalle_Consumo_PanesBudines!$G:$G,Detalle_Consumo_PanesBudines!$A:$A,"Lunes",Detalle_Consumo_PanesBudines!$D:$D,$A3) -> 73.44 | C3: =SUMIFS(Detalle_Consumo_PanesBudines!$G:$G,Detalle_Consumo_PanesBudines!$A:$A,"Martes",Detalle_Consumo_PanesBudines!$D:$D,$A3) -> 65.682 | D3: =SUMIFS(Detalle_Consumo_PanesBudines!$G:$G,Detalle_Consumo_PanesBudines!$A:$A,"Miercoles",Detalle_Consumo_PanesBudines!$D:$D,$A3) -> 73.44 | E3: =SUMIFS(Detalle_Consumo_PanesBudines!$G:$G,Detalle_Consumo_PanesBudines!$A:$A,"Jueves",Detalle_Consumo_PanesBudines!$D:$D,$A3) -> 64.08 | F3: =SUMIFS(Detalle_Consumo_PanesBudines!$G:$G,Detalle_Consumo_PanesBudines!$A:$A,"Viernes",Detalle_Consumo_PanesBudines!$D:$D,$A3) -> 65.682 | G3: =SUM(B3:F3) -> 342.324
A4: FÉCULA DE MAÍZ | B4: =SUMIFS(Detalle_Consumo_PanesBudines!$G:$G,Detalle_Consumo_PanesBudines!$A:$A,"Lunes",Detalle_Consumo_PanesBudines!$D:$D,$A4) -> 55.08 | C4: =SUMIFS(Detalle_Consumo_PanesBudines!$G:$G,Detalle_Consumo_PanesBudines!$A:$A,"Martes",Detalle_Consumo_PanesBudines!$D:$D,$A4) -> 56.07 | D4: =SUMIFS(Detalle_Consumo_PanesBudines!$G:$G,Detalle_Consumo_PanesBudines!$A:$A,"Miercoles",Detalle_Consumo_PanesBudines!$D:$D,$A4) -> 55.08 | E4: =SUMIFS(Detalle_Consumo_PanesBudines!$G:$G,Detalle_Consumo_PanesBudines!$A:$A,"Jueves",Detalle_Consumo_PanesBudines!$D:$D,$A4) -> 54.468 | F4: =SUMIFS(Detalle_Consumo_PanesBudines!$G:$G,Detalle_Consumo_PanesBudines!$A:$A,"Viernes",Detalle_Consumo_PanesBudines!$D:$D,$A4) -> 56.07 | G4: =SUM(B4:F4) -> 276.768
A5: FÉCULA DE MANDIOCA | B5: =SUMIFS(Detalle_Consumo_PanesBudines!$G:$G,Detalle_Consumo_PanesBudines!$A:$A,"Lunes",Detalle_Consumo_PanesBudines!$D:$D,$A5) -> 45.9 | C5: =SUMIFS(Detalle_Consumo_PanesBudines!$G:$G,Detalle_Consumo_PanesBudines!$A:$A,"Martes",Detalle_Consumo_PanesBudines!$D:$D,$A5) -> 27.234 | D5: =SUMIFS(Detalle_Consumo_PanesBudines!$G:$G,Detalle_Consumo_PanesBudines!$A:$A,"Miercoles",Detalle_Consumo_PanesBudines!$D:$D,$A5) -> 45.9 | E5: =SUMIFS(Detalle_Consumo_PanesBudines!$G:$G,Detalle_Consumo_PanesBudines!$A:$A,"Jueves",Detalle_Consumo_PanesBudines!$D:$D,$A5) -> 25.632 | F5: =SUMIFS(Detalle_Consumo_PanesBudines!$G:$G,Detalle_Consumo_PanesBudines!$A:$A,"Viernes",Detalle_Consumo_PanesBudines!$D:$D,$A5) -> 27.234 | G5: =SUM(B5:F5) -> 171.9
A6: ACEITE DE GIRASOL ALTO OLEICO | B6: =SUMIFS(Detalle_Consumo_PanesBudines!$G:$G,Detalle_Consumo_PanesBudines!$A:$A,"Lunes",Detalle_Consumo_PanesBudines!$D:$D,$A6) -> 27.54 | C6: =SUMIFS(Detalle_Consumo_PanesBudines!$G:$G,Detalle_Consumo_PanesBudines!$A:$A,"Martes",Detalle_Consumo_PanesBudines!$D:$D,$A6) -> 0 | D6: =SUMIFS(Detalle_Consumo_PanesBudines!$G:$G,Detalle_Consumo_PanesBudines!$A:$A,"Miercoles",Detalle_Consumo_PanesBudines!$D:$D,$A6) -> 27.54 | E6: =SUMIFS(Detalle_Consumo_PanesBudines!$G:$G,Detalle_Consumo_PanesBudines!$A:$A,"Jueves",Detalle_Consumo_PanesBudines!$D:$D,$A6) -> 0 | F6: =SUMIFS(Detalle_Consumo_PanesBudines!$G:$G,Detalle_Consumo_PanesBudines!$A:$A,"Viernes",Detalle_Consumo_PanesBudines!$D:$D,$A6) -> 0 | G6: =SUM(B6:F6) -> 55.08
A7: AZÚCAR | B7: =SUMIFS(Detalle_Consumo_PanesBudines!$G:$G,Detalle_Consumo_PanesBudines!$A:$A,"Lunes",Detalle_Consumo_PanesBudines!$D:$D,$A7) -> 18.36 | C7: =SUMIFS(Detalle_Consumo_PanesBudines!$G:$G,Detalle_Consumo_PanesBudines!$A:$A,"Martes",Detalle_Consumo_PanesBudines!$D:$D,$A7) -> 102.528 | D7: =SUMIFS(Detalle_Consumo_PanesBudines!$G:$G,Detalle_Consumo_PanesBudines!$A:$A,"Miercoles",Detalle_Consumo_PanesBudines!$D:$D,$A7) -> 18.36 | E7: =SUMIFS(Detalle_Consumo_PanesBudines!$G:$G,Detalle_Consumo_PanesBudines!$A:$A,"Jueves",Detalle_Consumo_PanesBudines!$D:$D,$A7) -> 99.324 | F7: =SUMIFS(Detalle_Consumo_PanesBudines!$G:$G,Detalle_Consumo_PanesBudines!$A:$A,"Viernes",Detalle_Consumo_PanesBudines!$D:$D,$A7) -> 102.528 | G7: =SUM(B7:F7) -> 341.1
A8: LECHE EN POLVO | B8: =SUMIFS(Detalle_Consumo_PanesBudines!$G:$G,Detalle_Consumo_PanesBudines!$A:$A,"Lunes",Detalle_Consumo_PanesBudines!$D:$D,$A8) -> 18.36 | C8: =SUMIFS(Detalle_Consumo_PanesBudines!$G:$G,Detalle_Consumo_PanesBudines!$A:$A,"Martes",Detalle_Consumo_PanesBudines!$D:$D,$A8) -> 22.428 | D8: =SUMIFS(Detalle_Consumo_PanesBudines!$G:$G,Detalle_Consumo_PanesBudines!$A:$A,"Miercoles",Detalle_Consumo_PanesBudines!$D:$D,$A8) -> 18.36 | E8: =SUMIFS(Detalle_Consumo_PanesBudines!$G:$G,Detalle_Consumo_PanesBudines!$A:$A,"Jueves",Detalle_Consumo_PanesBudines!$D:$D,$A8) -> 20.826 | F8: =SUMIFS(Detalle_Consumo_PanesBudines!$G:$G,Detalle_Consumo_PanesBudines!$A:$A,"Viernes",Detalle_Consumo_PanesBudines!$D:$D,$A8) -> 22.428 | G8: =SUM(B8:F8) -> 102.402
A9: PSYLLIUM | B9: =SUMIFS(Detalle_Consumo_PanesBudines!$G:$G,Detalle_Consumo_PanesBudines!$A:$A,"Lunes",Detalle_Consumo_PanesBudines!$D:$D,$A9) -> 13.77 | C9: =SUMIFS(Detalle_Consumo_PanesBudines!$G:$G,Detalle_Consumo_PanesBudines!$A:$A,"Martes",Detalle_Consumo_PanesBudines!$D:$D,$A9) -> 0 | D9: =SUMIFS(Detalle_Consumo_PanesBudines!$G:$G,Detalle_Consumo_PanesBudines!$A:$A,"Miercoles",Detalle_Consumo_PanesBudines!$D:$D,$A9) -> 13.77 | E9: =SUMIFS(Detalle_Consumo_PanesBudines!$G:$G,Detalle_Consumo_PanesBudines!$A:$A,"Jueves",Detalle_Consumo_PanesBudines!$D:$D,$A9) -> 0 | F9: =SUMIFS(Detalle_Consumo_PanesBudines!$G:$G,Detalle_Consumo_PanesBudines!$A:$A,"Viernes",Detalle_Consumo_PanesBudines!$D:$D,$A9) -> 0 | G9: =SUM(B9:F9) -> 27.54
A10: FIBRA C 200 | B10: =SUMIFS(Detalle_Consumo_PanesBudines!$G:$G,Detalle_Consumo_PanesBudines!$A:$A,"Lunes",Detalle_Consumo_PanesBudines!$D:$D,$A10) -> 11.475 | C10: =SUMIFS(Detalle_Consumo_PanesBudines!$G:$G,Detalle_Consumo_PanesBudines!$A:$A,"Martes",Detalle_Consumo_PanesBudines!$D:$D,$A10) -> 0 | D10: =SUMIFS(Detalle_Consumo_PanesBudines!$G:$G,Detalle_Consumo_PanesBudines!$A:$A,"Miercoles",Detalle_Consumo_PanesBudines!$D:$D,$A10) -> 11.475 | E10: =SUMIFS(Detalle_Consumo_PanesBudines!$G:$G,Detalle_Consumo_PanesBudines!$A:$A,"Jueves",Detalle_Consumo_PanesBudines!$D:$D,$A10) -> 0 | F10: =SUMIFS(Detalle_Consumo_PanesBudines!$G:$G,Detalle_Consumo_PanesBudines!$A:$A,"Viernes",Detalle_Consumo_PanesBudines!$D:$D,$A10) -> 0 | G10: =SUM(B10:F10) -> 22.95
A11: LEVADURA | B11: =SUMIFS(Detalle_Consumo_PanesBudines!$G:$G,Detalle_Consumo_PanesBudines!$A:$A,"Lunes",Detalle_Consumo_PanesBudines!$D:$D,$A11) -> 9.18 | C11: =SUMIFS(Detalle_Consumo_PanesBudines!$G:$G,Detalle_Consumo_PanesBudines!$A:$A,"Martes",Detalle_Consumo_PanesBudines!$D:$D,$A11) -> 0 | D11: =SUMIFS(Detalle_Consumo_PanesBudines!$G:$G,Detalle_Consumo_PanesBudines!$A:$A,"Miercoles",Detalle_Consumo_PanesBudines!$D:$D,$A11) -> 9.18 | E11: =SUMIFS(Detalle_Consumo_PanesBudines!$G:$G,Detalle_Consumo_PanesBudines!$A:$A,"Jueves",Detalle_Consumo_PanesBudines!$D:$D,$A11) -> 0 | F11: =SUMIFS(Detalle_Consumo_PanesBudines!$G:$G,Detalle_Consumo_PanesBudines!$A:$A,"Viernes",Detalle_Consumo_PanesBudines!$D:$D,$A11) -> 0 | G11: =SUM(B11:F11) -> 18.36
A12: GOMA XÁNTICA | B12: =SUMIFS(Detalle_Consumo_PanesBudines!$G:$G,Detalle_Consumo_PanesBudines!$A:$A,"Lunes",Detalle_Consumo_PanesBudines!$D:$D,$A12) -> 6.885 | C12: =SUMIFS(Detalle_Consumo_PanesBudines!$G:$G,Detalle_Consumo_PanesBudines!$A:$A,"Martes",Detalle_Consumo_PanesBudines!$D:$D,$A12) -> 4.806 | D12: =SUMIFS(Detalle_Consumo_PanesBudines!$G:$G,Detalle_Consumo_PanesBudines!$A:$A,"Miercoles",Detalle_Consumo_PanesBudines!$D:$D,$A12) -> 6.885 | E12: =SUMIFS(Detalle_Consumo_PanesBudines!$G:$G,Detalle_Consumo_PanesBudines!$A:$A,"Jueves",Detalle_Consumo_PanesBudines!$D:$D,$A12) -> 4.806 | F12: =SUMIFS(Detalle_Consumo_PanesBudines!$G:$G,Detalle_Consumo_PanesBudines!$A:$A,"Viernes",Detalle_Consumo_PanesBudines!$D:$D,$A12) -> 4.806 | G12: =SUM(B12:F12) -> 28.188
A13: SAL | B13: =SUMIFS(Detalle_Consumo_PanesBudines!$G:$G,Detalle_Consumo_PanesBudines!$A:$A,"Lunes",Detalle_Consumo_PanesBudines!$D:$D,$A13) -> 4.59 | C13: =SUMIFS(Detalle_Consumo_PanesBudines!$G:$G,Detalle_Consumo_PanesBudines!$A:$A,"Martes",Detalle_Consumo_PanesBudines!$D:$D,$A13) -> 2.0826 | D13: =SUMIFS(Detalle_Consumo_PanesBudines!$G:$G,Detalle_Consumo_PanesBudines!$A:$A,"Miercoles",Detalle_Consumo_PanesBudines!$D:$D,$A13) -> 4.59 | E13: =SUMIFS(Detalle_Consumo_PanesBudines!$G:$G,Detalle_Consumo_PanesBudines!$A:$A,"Jueves",Detalle_Consumo_PanesBudines!$D:$D,$A13) -> 1.7622 | F13: =SUMIFS(Detalle_Consumo_PanesBudines!$G:$G,Detalle_Consumo_PanesBudines!$A:$A,"Viernes",Detalle_Consumo_PanesBudines!$D:$D,$A13) -> 2.0826 | G13: =SUM(B13:F13) -> 15.1074
... A22: ESENCIA DE VAINILLA | B22: =SUMIFS(Detalle_Consumo_PanesBudines!$G:$G,Detalle_Consumo_PanesBudines!$A:$A,"Lunes",Detalle_Consumo_PanesBudines!$D:$D,$A22) -> 0 | C22: =SUMIFS(Detalle_Consumo_PanesBudines!$G:$G,Detalle_Consumo_PanesBudines!$A:$A,"Martes",Detalle_Consumo_PanesBudines!$D:$D,$A22) -> 0.801 | D22: =SUMIFS(Detalle_Consumo_PanesBudines!$G:$G,Detalle_Consumo_PanesBudines!$A:$A,"Miercoles",Detalle_Consumo_PanesBudines!$D:$D,$A22) -> 0 | E22: =SUMIFS(Detalle_Consumo_PanesBudines!$G:$G,Detalle_Consumo_PanesBudines!$A:$A,"Jueves",Detalle_Consumo_PanesBudines!$D:$D,$A22) -> 1.602 | F22: =SUMIFS(Detalle_Consumo_PanesBudines!$G:$G,Detalle_Consumo_PanesBudines!$A:$A,"Viernes",Detalle_Consumo_PanesBudines!$D:$D,$A22) -> 0.801 | G22: =SUM(B22:F22) -> 3.204
A23: TOTAL GENERAL (kg) | B23: =SUM(B2:B22) -> 540 | C23: =SUM(C2:C22) -> 540 | D23: =SUM(D2:D22) -> 540 | E23: =SUM(E2:E22) -> 540 | F23: =SUM(F2:F22) -> 540 | G23: =SUM(G2:G22) -> 2700

Sheet Resumen_2Semanas
A1: CONSUMO DE MATERIA PRIMA - TOTAL 2 SEMANAS (Galletitas + Panes y Budines)
A5: Materia Prima | B5: Galletitas Sem 1 (kg) | C5: Galletitas Sem 2 (kg) | D5: Panes y Budines Sem 1 (kg) | E5: Panes y Budines Sem 2 (kg) | F5: TOTAL 2 Semanas (kg) | G5: Peso de pallet | H5: Pallets por producto cada 2 semanas
A6: FÉCULA DE MAÍZ | B6: =SUMIF(Resumen_Semana1!$A$2:$A$35,$A6,Resumen_Semana1!$G$2:$G$35) -> 1861.2648 | C6: =SUMIF(Resumen_Semana2!$A$2:$A$28,$A6,Resumen_Semana2!$G$2:$G$28) -> 2232 | D6: =SUMIF(Resumen_PanesBudines!$A$2:$A$22,$A6,Resumen_PanesBudines!$G$2:$G$22) -> 276.768 | E6: =SUMIF(Resumen_PanesBudines!$A$2:$A$22,$A6,Resumen_PanesBudines!$G$2:$G$22) -> 276.768 | F6: =SUM(B6:E6) -> 4646.8008 | G6: 1000 | H6: =+F6/G6 -> 4.6468008 | I6: 5
A7: HARINA DE ARROZ | B7: =SUMIF(Resumen_Semana1!$A$2:$A$35,$A7,Resumen_Semana1!$G$2:$G$35) -> 1631.8152 | C7: =SUMIF(Resumen_Semana2!$A$2:$A$28,$A7,Resumen_Semana2!$G$2:$G$28) -> 1634.94 | D7: =SUMIF(Resumen_PanesBudines!$A$2:$A$22,$A7,Resumen_PanesBudines!$G$2:$G$22) -> 342.324 | E7: =SUMIF(Resumen_PanesBudines!$A$2:$A$22,$A7,Resumen_PanesBudines!$G$2:$G$22) -> 342.324 | F7: =SUM(B7:E7) -> 3951.4032 | G7: 1000 | H7: =+F7/G7 -> 3.9514032 | I7: 5
A8: ACEITE VEGETAL INTERESTERIFICADO | B8: =SUMIF(Resumen_Semana1!$A$2:$A$35,$A8,Resumen_Semana1!$G$2:$G$35) -> 877.6224 | C8: =SUMIF(Resumen_Semana2!$A$2:$A$28,$A8,Resumen_Semana2!$G$2:$G$28) -> 1233.18 | D8: =SUMIF(Resumen_PanesBudines!$A$2:$A$22,$A8,Resumen_PanesBudines!$G$2:$G$22) -> 0 | E8: =SUMIF(Resumen_PanesBudines!$A$2:$A$22,$A8,Resumen_PanesBudines!$G$2:$G$22) -> 0 | F8: =SUM(B8:E8) -> 2110.8024 | G8: 960 | H8: =+F8/G8 -> 2.1987525 | I8: 3
A9: AZÚCAR | B9: =SUMIF(Resumen_Semana1!$A$2:$A$35,$A9,Resumen_Semana1!$G$2:$G$35) -> 988.776 | C9: =SUMIF(Resumen_Semana2!$A$2:$A$28,$A9,Resumen_Semana2!$G$2:$G$28) -> 1071.36 | D9: =SUMIF(Resumen_PanesBudines!$A$2:$A$22,$A9,Resumen_PanesBudines!$G$2:$G$22) -> 341.1 | E9: =SUMIF(Resumen_PanesBudines!$A$2:$A$22,$A9,Resumen_PanesBudines!$G$2:$G$22) -> 341.1 | F9: =SUM(B9:E9) -> 2742.336 | G9: 1500 | H9: =+F9/G9 -> 1.828224 | I9: 2
A10: MERMELADA DE BATATA | B10: =SUMIF(Resumen_Semana1!$A$2:$A$35,$A10,Resumen_Semana1!$G$2:$G$35) -> 874.944 | C10: =SUMIF(Resumen_Semana2!$A$2:$A$28,$A10,Resumen_Semana2!$G$2:$G$28) -> 0 | D10: =SUMIF(Resumen_PanesBudines!$A$2:$A$22,$A10,Resumen_PanesBudines!$G$2:$G$22) -> 0 | E10: =SUMIF(Resumen_PanesBudines!$A$2:$A$22,$A10,Resumen_PanesBudines!$G$2:$G$22) -> 0 | F10: =SUM(B10:E10) -> 874.944 | G10: 500 | H10: =+F10/G10 -> 1.749888 | I10: 2
A11: JARABE DE GLUCOSA | B11: =SUMIF(Resumen_Semana1!$A$2:$A$35,$A11,Resumen_Semana1!$G$2:$G$35) -> 192.8448 | C11: =SUMIF(Resumen_Semana2!$A$2:$A$28,$A11,Resumen_Semana2!$G$2:$G$28) -> 435.24 | D11: =SUMIF(Resumen_PanesBudines!$A$2:$A$22,$A11,Resumen_PanesBudines!$G$2:$G$22) -> 0 | E11: =SUMIF(Resumen_PanesBudines!$A$2:$A$22,$A11,Resumen_PanesBudines!$G$2:$G$22) -> 0 | F11: =SUM(B11:E11) -> 628.0848 | G11: 1500 | H11: =+F11/G11 -> 0.4187232 | I11: 0.5
