Workbook

Sheet Análisis
B2: INVERSIÓN EN ACTIVO FIJO | C2: SAN NICOLÁS | D2: ALBERTI | E2: SAN LUIS
B3: Costo terreno [USD/m2] | C3: 166 | D3: 40 | E3: 1.81
B4: Superficie terreno [m2] | C4: 5000 | D4: 5000 | E4: 5000
B5: Inversión en terreno [USD] | C5: =C3*C4 -> 830000 | D5: =D3*D4 -> 200000 | E5: =E3*E4 -> 9050
B6: Inversión nave industrial [USD] | C6: 2062500 | D6: 2062500 | E6: 2062500
B7: Inversión equipos [USD] | C7: 687500 | D7: 687500 | E7: 687500
B8: TOTAL ACTIVO FIJO [USD] | C8: =C5+C6+C7 -> 3580000 | D8: =D5+D6+D7 -> 2950000 | E8: =E5+E6+E7 -> 2759050
B10: AMORTIZACIONES | C10: SAN NICOLÁS | D10: ALBERTI | E10: SAN LUIS
B11: Vida útil terreno [años] | C11: 10 | D11: 10 | E11: 10
B12: Vida útil nave industrial [años] | C12: 10 | D12: 10 | E12: 10
B13: Vida útil equipos [años] | C13: 5 | D13: 5 | E13: 5
B14: Amortiz. anual terreno [USD/año] | C14: =C5/C11 -> 83000 | D14: =D5/D11 -> 20000 | E14: =E5/E11 -> 905
B15: Amortiz. anual nave industrial [USD/año] | C15: =C6/C12 -> 206250 | D15: =D6/D12 -> 206250 | E15: =E6/E12 -> 206250
B16: Amortiz. anual equipos [USD/año] | C16: =C7/C13 -> 137500 | D16: =D7/D13 -> 137500 | E16: =E7/E13 -> 137500
B17: TOTAL AMORTIZACIÓN ANUAL [USD/año] | C17: =C14+C15+C16 -> 426750 | D17: =D14+D15+D16 -> 363750 | E17: =E14+E15+E16 -> 344655
B19: PRECIO DE VENTA | C19: SAN NICOLÁS | D19: ALBERTI | E19: SAN LUIS | F19: Precio corregido
B20: Costo de producción por cuchara [USD] | C20: 840000 | D20: 840000 | E20: 840000
B21: Margen bruto [%] | C21: 0.2 | D21: 0.2 | E21: 0.2
B22: Costo transporte MP por cuchara [USD] | C22: =C31 -> 25812 | D22: =D31 -> 56280 | E22: =E31 -> 65088
B23: Costo transporte PT prom. pond. por cuchara [USD] | C23: =(E35*I49+E36*I50+E37*I51)/I52 -> 8492.4444 | D23: =(H35*P49+H36*P50+H37*P51)/P52 -> 9795.4074 | E23: =(K35*W49+K36*W50+K37*W51)/W52 -> 19093.333
B24: Costo total por cuchara [USD] | C24: =C20+C22+C23 -> 874304.44 | D24: =D20+D22+D23 -> 906075.41 | E24: =E20+E22+E23 -> 924181.33
B25: PRECIO DE VENTA [USD/cuchara] | C25: =C24/(1-C21) -> 1092880.6 | D25: =D24/(1-D21) -> 1132594.3 | E25: =E24/(1-E21) -> 1155226.7 | F25: =AVERAGE(C25:E25) -> 1126900.5 | G25: Como hay un único precio de mercado y 3 alternativas debido a los costos de cada localización, se toma un único precio promedio
B27: TRANSPORTE DE MATERIA PRIMA | C27: SAN NICOLÁS | D27: ALBERTI | E27: SAN LUIS
B28: Costo MP [USD/km] | C28: 18 | D28: 14 | E28: 12
B29: Distancia al proveedor (AMBA) [km] | C29: 239 | D29: 670 | E29: 904
B30: Semirremolques por cuchara | C30: 6 | D30: 6 | E30: 6
B31: Costo transporte MP por cuchara [USD] | C31: =C28*C29*C30 -> 25812 | D31: =D28*D29*D30 -> 56280 | E31: =E28*E29*E30 -> 65088
B33: TRANSPORTE DE PRODUCTO TERMINADO | C33: SAN NICOLÁS | F33: ALBERTI | I33: SAN LUIS | L33: Distancias corregidas
B34: Cliente | C34: Costo/km [USD] | D34: Dist. [km] | E34: Costo/cuchara [USD] | F34: Costo/km [USD] | G34: Dist. [km] | H34: Costo/cuchara [USD] | I34: Costo/km [USD] | J34: Dist. [km] | K34: Costo/cuchara [USD]
B35: Metcon (San Nicolás) | C35: 22 | D35: 10 | E35: =C35*D35 -> 220 | F35: 22 | G35: 362 | H35: =F35*G35 -> 7964 | I35: 24 | J35: 733 | K35: =I35*J35 -> 17592
B36: Zapla (Jujuy) | C36: 14 | D36: 254 | E36: =C36*D36 -> 3556 | F36: 12 | G36: 508 | H36: =F36*G36 -> 6096 | I36: 24 | J36: 727 | K36: =I36*J36 -> 17448
B37: Acerbrag (Bragado) | C37: 18 | D37: 1288 | E37: =C37*D37 -> 23184 | F37: 16 | G37: 906 | H37: =F37*G37 -> 14496 | I37: 18 | J37: 1232 | K37: =I37*J37 -> 22176
B40: CRÉDITO FISCAL | C40: SAN NICOLÁS | D40: ALBERTI | E40: SAN LUIS | F40: Análisis de crédito fiscal corregido. Se puede ver en fila la fila 79 esta reducción para San Luis
B41: Crédito fiscal [USD] (3% × AF) | C41: 0 | D41: 0 | E41: =E8*0.03 -> 82771.5 | F41: Crédito fiscal 10 años. Se descuenta de los impuestos a pagar cada año.
B44: ACTIVO DE TRABAJO | C44: SAN NICOLÁS | D44: ALBERTI | E44: SAN LUIS | F44: Justificación de activo de trabajo añadida
B45: Inversión activo de trabajo [USD] | C45: =ROUND((C20*D52+C31*D52+E35*D49+E36*D50+E37*D51)/12,0) -> 72169 | D45: =ROUND((C20*K52+D31*K52+H35*K49+H36*K50+H37*K51)/12,0) -> 75354 | E45: =ROUND((C20*R52+E31*R52+K35*R49+K36*R50+K37*R51)/12,0) -> 76890 | F45: 1 mes de costos operativos variables del Año 1 (producción + transporte MP + transporte PT). Criterio: período mínimo de capital inmovilizado antes del primer cobro.
B47: VENTAS [unidades] - Equipo 523 | C47: SAN NICOLÁS | J47: ALBERTI | Q47: SAN LUIS
B48: Cliente | D48: Año 1 | E48: Año 2 | F48: Año 3 | G48: Año 4 | H48: Año 5 | I48: TOTAL | K48: Año 1 | L48: Año 2 | M48: Año 3 | N48: Año 4 | O48: Año 5 | P48: TOTAL | R48: Año 1 | S48: Año 2 | T48: Año 3 | U48: Año 4 | V48: Año 5 | W48: TOTAL
B49: Metcon | C49: 0 | D49: 1 | E49: 3 | F49: 3 | G49: 3 | H49: 3 | I49: =SUM(D49:H49) -> 13 | J49: 0 | K49: 1 | L49: 3 | M49: 3 | N49: 3 | O49: 3 | P49: =SUM(K49:O49) -> 13 | Q49: 0 | R49: 1 | S49: 3 | T49: 3 | U49: 3 | V49: 3 | W49: =SUM(R49:V49) -> 13
B50: Zapla | C50: 0 | D50: 0 | E50: 0 | F50: 0 | G50: 0 | H50: 5 | I50: =SUM(D50:H50) -> 5 | J50: 0 | K50: 0 | L50: 0 | M50: 0 | N50: 0 | O50: 5 | P50: =SUM(K50:O50) -> 5 | Q50: 0 | R50: 0 | S50: 0 | T50: 0 | U50: 0 | V50: 5 | W50: =SUM(R50:V50) -> 5
...

Sheet Ponderación
A1: Modelo de ponderación
A2: Lj = Σ Pi × Vfi /Vfi normalizado: mejor valor del factor = 1.00. Costos: menor = mejor (Vfi = MIN/valor). Beneficios: mayor = mejor (Vfi = valor/MAX).
A3: Factor | B3: Ponderación | C3: SAN NICOLÁS | D3: ALBERTI | E3: SAN LUIS
A4: FACTORES CUANTITATIVOS
A5: VAN ( 9%) [USD] | B5: 0.15 | C5: =Análisis!C113 -> 1405668.8 | D5: =Análisis!D113 -> 1304876.1 | E5: =Análisis!E113 -> 1380941.4
A6: Costo transp. MP [USD] | B6: 0.3 | C6: =Análisis!I70 -> 696924 | D6: =Análisis!P70 -> 1519560 | E6: =Análisis!W70 -> 1757376
A7: Costo transp. PT [USD] | B7: 0.25 | C7: =Análisis!I74 -> 229296 | D7: =Análisis!P74 -> 264476 | E7: =Análisis!W74 -> 515520
A8: Beneficio neto [USD] | B8: 0.1 | C8: =Análisis!C115 -> 3473287.1 | D8: =Análisis!D115 -> 3072372.1 | E8: =Análisis!E115 -> 3108584.1
A9: Impuestos [USD] | B9: 0.1 | C9: =Análisis!E90 -> 1213056.2 | D9: =Análisis!E100 -> 1071155.2 | E9: =Análisis!E110 -> 641558.21
A10: FACTORES CUALITATIVOS
A11: Disponibilidad de MO calificada | B11: 0.05 | C11: 8 | D11: 5 | E11: 4 | F11: Justificación en documento word adjunto
A12: Gestión ambiental in situ | B12: 0.05 | C12: 4 | D12: 9 | E12: 7 | F12: Justificación en documento word adjunto
A14: PUNTAJES NORMALIZADOS (Vfi)
A15: Factor | B15: Ponderación (Pi) | C15: SAN NICOLÁS | D15: ALBERTI | E15: SAN LUIS | F15: Dirección
A16: VAN (tasa 9%) [USD] | B16: =B5 -> 0.15 | C16: =IF(MAX(C5,D5,E5)=0,0,C5/MAX(C5,D5,E5)) -> 1 | D16: =IF(MAX(C5,D5,E5)=0,0,D5/MAX(C5,D5,E5)) -> 0.9282956 | E16: =IF(MAX(C5,D5,E5)=0,0,E5/MAX(C5,D5,E5)) -> 0.98240885 | F16: mayor = mejor
A17: Costo transp. MP [USD] | B17: =B6 -> 0.3 | C17: =IF(C6=0,0,MIN(C6,D6,E6)/C6) -> 1 | D17: =IF(D6=0,0,MIN(C6,D6,E6)/D6) -> 0.45863539 | E17: =IF(E6=0,0,MIN(C6,D6,E6)/E6) -> 0.3965708 | F17: menor = mejor
A18: Costo transp. PT [USD] | B18: =B7 -> 0.25 | C18: =IF(C7=0,0,MIN(C7,D7,E7)/C7) -> 1 | D18: =IF(D7=0,0,MIN(C7,D7,E7)/D7) -> 0.86698226 | E18: =IF(E7=0,0,MIN(C7,D7,E7)/E7) -> 0.44478585 | F18: menor = mejor
A19: Beneficio neto [USD] | B19: =B8 -> 0.1 | C19: =IF(MAX(C8,D8,E8)=0,0,C8/MAX(C8,D8,E8)) -> 1 | D19: =IF(MAX(C8,D8,E8)=0,0,D8/MAX(C8,D8,E8)) -> 0.88457188 | E19: =IF(MAX(C8,D8,E8)=0,0,E8/MAX(C8,D8,E8)) -> 0.89499774 | F19: mayor = mejor
A20: Impuestos [USD] | B20: =B9 -> 0.1 | C20: =IF(C9=0,0,MIN(C9,D9,E9)/C9) -> 0.52887756 | D20: =IF(D9=0,0,MIN(C9,D9,E9)/D9) -> 0.59894047 | E20: =IF(E9=0,0,MIN(C9,D9,E9)/E9) -> 1 | F20: menor = mejor
A21: Disponibilidad de MO calificada | B21: =B11 -> 0.05 | C21: =IF(MAX(C11,D11,E11)=0,0,C11/MAX(C11,D11,E11)) -> 1 | D21: =IF(MAX(C11,D11,E11)=0,0,D11/MAX(C11,D11,E11)) -> 0.625 | E21: =IF(MAX(C11,D11,E11)=0,0,E11/MAX(C11,D11,E11)) -> 0.5 | F21: mayor = mejor
A22: Gestión ambiental in situ | B22: =B12 -> 0.05 | C22: =IF(MAX(C12,D12,E12)=0,0,C12/MAX(C12,D12,E12)) -> 0.44444444 | D22: =IF(MAX(C12,D12,E12)=0,0,D12/MAX(C12,D12,E12)) -> 1 | E22: =IF(MAX(C12,D12,E12)=0,0,E12/MAX(C12,D12,E12)) -> 0.77777778 | F22: mayor = mejor
A24: RESULTADO
A25: Localización | B25: Puntaje | C25: Ranking
A26: SAN NICOLÁS | B26: =SUMPRODUCT(B16:B22,C16:C22) -> 0.92510998 | C26: 1°
A27: ALBERTI | B27: =SUMPRODUCT(B16:B22,D16:D22) -> 0.72318176 | C27: 2°
A28: SAN LUIS | B28: =SUMPRODUCT(B16:B22,E16:E22) -> 0.63091769 | C28: 3°
A30: LOCALIZACIÓN ÓPTIMA: SAN NICOLÁS
