Workbook

Sheet Carátula
K1: UNIVERSIDAD TECNOLÓGICA NACIONAL FACULTAD REGIONAL BUENOS AIRES
A2: DEPARTAMENTO DE INGENIERÍA INDUSTRIAL
A3: ASIGNATURA | L3: CÓDIGO | S3: CICLO LECTIVO
A4: EVALUACIÓN DE PROYECTOS | L4: 32590 | S4: 2024
A5: ESTUDIANTES | B5: NOMBRE Y APELLIDO | E5: Lucio Cahe | T5: LEGAJO 150.459-9 | W5: 1504599
B6: NOMBRE Y APELLIDO | E6: Santiago Greco | T6: LEGAJO 177.980-1 | W6: 1779801
B7: NOMBRE Y APELLIDO | E7: Joan Manonelles | T7: LEGAJO 173.276-6 | W7: 1732766
B8: NOMBRE Y APELLIDO | E8: Penélope Mattia | T8: LEGAJO 175.443-9 | W8: 1754439
B9: NOMBRE Y APELLIDO | E9: Ignacio Morón | T9: LEGAJO 162.519-6 | W9: 1625196
O10: DIVISIÓN | R10: AÑO | U10: EQUIPO
O11: I–4053 | R11: 4to | U11: 10
A12: DOCENTES | B12: Docentes Adjuntos: | I12: Ing. Juan José Cosentino
B13: Jefe de Trabajos Prácticos | I13: Ing. Lucas Martín Costantino
B14: Ayudantes: | I14: Ing. Matías A. Carpinacci Sireix Ing. Miguel A. Beltrán Ing. Nicolás Elías Sabaryn
A15: Parte 5: Dimensionamiento Económico
A16: TEMA: Harina de soja con huerta hidropónica
A18: OBSERVACIONES
A19: FIRMA DEL ESTUDIANTE | G19: FIRMA DEL JTP / ATP | P19: NOTA
A20: ENTREGA | C20: Fecha ENTREGA | H20: Fecha VISADO | N20: FECHAS DESTACADAS
A21: 1ra | C21: 8 | D21: 10 | F21: 24 | N21: FECHA DE INICIO
A22: 2da | C22: 29 | D22: 10 | F22: 24
A23: 3ra | N23: FECHA DE FINALIZACIÓN
A24: 4ta

Sheet Ejercicio 1
A1: EJERCICIO 1
A2: SECCIONES | C2: DESPERDICIOS (litros)
C3: Recuperables | D3: No recuperables
A4: 1 | B4: Descascarado | C4: 0 | D4: 115 | E4: 2% del peso
A5: 2 | B5: Molido grueso | C5: 0 | D5: 0
A6: 3 | B6: Extrusión | C6: 0 | D6: 0
A7: 4 | B7: Prensado | C7: 0 | D7: 750 | E7: Sale aceite
A8: 5 | B8: Secado / Enfriado | C8: 0 | D8: 0
A9: 6 | B9: Molienda | C9: 0 | D9: 0
A10: 7 | B10: Empaquetado | C10: 0 | D10: 0
B13: Volumen total ingresado = | C13: =C22 -> 5865
B14: Consumo real MP = | C14: =C13 -> 5865
B15: % Desperdicio operativo = | C15: =(D29+E29)/F28 -> 0.173
B16: % Desperdicio real = | C16: =(E29)/F28 -> 0.173
A19: SECCIONES | C19: ALIMENTACION (Anual) | D19: DESPERDICIOS (Toneladas) | F19: PRODUCCIONES SECCIONALES (Tn/ Anual) | G19: PRODUCCIONES SECCIONALES (Kg/Anual)
D20: Recuperables | E20: No recuperables
A21: 1 | B21: Separador | C21: 5865 | D21: 0 | E21: 0 | F21: 5865 | G21: =F21*1000 -> 5865000
A22: 2 | B22: Descascarado | C22: =F22*1.02 -> 5865 | D22: 0 | E22: =0.02*F22 -> 115 | F22: =C23 -> 5750 | G22: =F22*1000 -> 5750000 | H22: 2% del peso
A23: 3 | B23: Molido grueso | C23: =F23 -> 5750 | D23: 0 | E23: 0 | F23: =C24 -> 5750 | G23: =F23*1000 -> 5750000
A24: 4 | B24: Extrusión | C24: =D24+E24+F24 -> 5750 | D24: 0 | E24: 0 | F24: =C25 -> 5750 | G24: =F24*1000 -> 5750000
A25: 5 | B25: Prensado | C25: =D25+E25+F25 -> 5750 | D25: 0 | E25: =0.15*F25 -> 750 | F25: =C26 -> 5000 | G25: =F25*1000 -> 5000000
A26: 6 | B26: Secado / Enfriado | C26: =F26 -> 5000 | D26: 0 | E26: 0 | F26: =C27 -> 5000 | G26: =F26*1000 -> 5000000
A27: 7 | B27: Molienda | C27: =F27+D27+E27 -> 5000 | D27: 0 | E27: 0 | F27: =C28 -> 5000 | G27: =F27*1000 -> 5000000
A28: 8 | B28: Empaquetado | C28: =F28+D28+E28 -> 5000 | D28: 0 | E28: 0 | F28: =I28 -> 5000 | G28: =F28*1000 -> 5000000 | I28: =InfoInicial!B17 -> 5000 | J28: Toneladas anuales
A29: Totales | C29: =C22 -> 5865 | D29: =SUM(D22:D28) -> 0 | E29: =SUM(E22:E28) -> 865 | F29: =F28 -> 5000 | G29: =F29*1000 -> 5000000

Sheet Ejercicio 2 
A1: EJERCICIO 2
A2: Dias totales del año = | B2: 365
A3: Feriados del año = | B3: 10
A4: Vacaciones = | B4: 15
A5: Dias totales laborales = | B5: 340 | C5: 7 | D5: A la semana
A7: Equipos rotativos = | B7: 1
A8: Horas de cada turno = | B8: 8
A9: Turnos diarios = | B9: 2
A11: HORAS ACTIVAS/AÑO | B11: =B5*B8*B9 -> 5440 | C11: Horas
A12: HORAS/AÑO POR EQUIPO DE OPERARIOS | B12: =B11/B7 -> 5440 | C12: Horas

Sheet Ejercicio 3
A1: EJERCICIO 3
A2: SECCIONES OPERATIVAS | C2: CAPACIDAD TEORICA / MAQUINA X HORA | E2: HORAS ACTIVA / AÑO | F2: CAPACIDAD TEORICA / MAQUINA X AÑO | G2: RENDIMIENTO OPERATIVO | H2: CAPACIDAD REAL / MAQUINA X AÑO
A3: 1 | B3: Separador | C3: 8000 | D3: Kg/h | E3: ='Ejercicio 2 '!$B$11 -> 5440 | F3: =C3*E3 -> 43520000 | G3: 0.95 | H3: =F3*G3 -> 41344000
A4: 2 | B4: Descascarado | C4: =(150*1000)/24 -> 6250 | D4: Kg/h | E4: ='Ejercicio 2 '!$B$11 -> 5440 | F4: =C4*E4 -> 34000000 | G4: 0.95 | H4: =F4*G4 -> 32300000
A5: 3 | B5: Molido grueso | C5: 1000 | D5: Kg/h | E5: ='Ejercicio 2 '!$B$11 -> 5440 | F5: =C5*E5 -> 5440000 | G5: 0.95 | H5: =F5*G5 -> 5168000
A6: 4 | B6: Extrusión | C6: 1000 | D6: Kg/h | E6: ='Ejercicio 2 '!$B$11 -> 5440 | F6: =C6*E6 -> 5440000 | G6: 0.95 | H6: =F6*G6 -> 5168000
A7: 5 | B7: Prensado | C7: =(70*1000)/24 -> 2916.6667 | D7: Kg/h | E7: ='Ejercicio 2 '!$B$11 -> 5440 | F7: =C7*E7 -> 15866667 | G7: 0.95 | H7: =F7*G7 -> 15073333
A8: 6 | B8: Secado / Enfriado | C8: =10*1000 -> 10000 | D8: Kg/h | E8: ='Ejercicio 2 '!$B$11 -> 5440 | F8: =C8*E8 -> 54400000 | G8: 0.95 | H8: =F8*G8 -> 51680000
A9: 7 | B9: Molienda | C9: =4*1000 -> 4000 | D9: Kg/h | E9: ='Ejercicio 2 '!$B$11 -> 5440 | F9: =C9*E9 -> 21760000 | G9: 0.95 | H9: =F9*G9 -> 20672000
A10: 8 | B10: Empaquetado | C10: =(4*60)*50 -> 12000 | D10: Kg/h | E10: ='Ejercicio 2 '!$B$11 -> 5440 | F10: =C10*E10 -> 65280000 | G10: 0.95 | H10: =F10*G10 -> 62016000

Sheet Ejercicio 4 y 5
A1: EJERCICIO 4 Y 5
A2: SECCIONES OPERATIVAS | C2: PROGRAMA ANUAL DE PRODUCCION | D2: CAPACIDAD REAL/MAQXAÑO | E2: CANTIDAD MAQS NECESARIAS | F2: CAPACIDAD REAL/SECCION X AÑO | G2: APROVECHAMIENTO SECCIONAL (%)
A4: 1 | B4: Separador | C4: ='Ejercicio 1'!G21 -> 5865000 | D4: ='Ejercicio 3'!H3 -> 41344000 | E4: =ROUNDUP(C4/D4,0) -> 1 | F4: =D4*E4 -> 41344000 | G4: =(C4/F4) -> 0.14185855
A5: 2 | B5: Descascarado | C5: ='Ejercicio 1'!G22 -> 5750000 | D5: ='Ejercicio 3'!H4 -> 32300000 | E5: =ROUNDUP(C5/D5,0) -> 1 | F5: =D5*E5 -> 32300000 | G5: =(C5/F5) -> 0.17801858
A6: 3 | B6: Molido grueso | C6: ='Ejercicio 1'!G23 -> 5750000 | D6: ='Ejercicio 3'!H5 -> 5168000 | E6: =ROUNDUP(C6/D6,0) -> 2 | F6: =D6*E6 -> 10336000 | G6: =(C6/F6) -> 0.55630805
A7: 4 | B7: Extrusión | C7: ='Ejercicio 1'!G24 -> 5750000 | D7: ='Ejercicio 3'!H6 -> 5168000 | E7: =ROUNDUP(C7/D7,0) -> 2 | F7: =D7*E7 -> 10336000 | G7: =(C7/F7) -> 0.55630805
A8: 5 | B8: Prensado | C8: ='Ejercicio 1'!G25 -> 5000000 | D8: ='Ejercicio 3'!H7 -> 15073333 | E8: 2 | F8: =D8*E8 -> 30146667 | G8: =(C8/F8) -> 0.16585582 | H8: Si bien, en términos de capacidades, sólo resulta necesaria una prensa en la sección operativa, es recomendable el agregado de una adicional, minimizando el costo perdido por paradas de máquinas debido a desperfectos y obteniendo un mayor porcentaje de extracción
A9: 6 | B9: Secado / Enfriado | C9: ='Ejercicio 1'!G26 -> 5000000 | D9: ='Ejercicio 3'!H8 -> 51680000 | E9: =ROUNDUP(C9/D9,0) -> 1 | F9: =D9*E9 -> 51680000 | G9: =(C9/F9) -> 0.096749226
A10: 7 | B10: Molienda | C10: ='Ejercicio 1'!G27 -> 5000000 | D10: ='Ejercicio 3'!H9 -> 20672000 | E10: =ROUNDUP(C10/D10,0) -> 1 | F10: =D10*E10 -> 20672000 | G10: =(C10/F10) -> 0.24187307
A11: 8 | B11: Empaquetado | C11: ='Ejercicio 1'!G28 -> 5000000 | D11: ='Ejercicio 3'!H10 -> 62016000 | E11: =ROUNDUP(C11/D11,0) -> 1 | F11: =D11*E11 -> 62016000 | G11: =(C11/F11) -> 0.080624355

Sheet Ejercicio 6
A1: EJERCICIO 6 | H1: 345 | I1: días laborales
A2: Venta volúmen [Tn]
A3: Anual | C3: Mensual | H3: =(H1*12)/365 -> 11.342466 | I3: meses laborales
A4: =InfoInicial!B17 -> 5000 | C4: =A4/H4 -> 434.78261 | H4: 11.5
A6: Mes | B6: Ritmo de producción al inicio | C6: Ritmo de producción al final | D6: Producción Prom. | E6: Producción Mensual Prom. | F6: Producción Propuesta
A7: 1 | B7: 0 | C7: 0.04 | D7: 0.02 | E7: =$C$4 -> 434.78261 | F7: =D7*E7 -> 8.6956522
A8: 2 | B8: 0.04 | C8: 0.16 | D8: 0.1 | E8: =E7 -> 434.78261 | F8: =D8*E8 -> 43.478261
A9: 3 | B9: 0.16 | C9: 1 | D9: 0.58 | E9: =E8 -> 434.78261 | F9: =D9*E9 -> 252.17391
E10: TOTAL = | F10: =SUM(F7:F9) -> 304.34783 | H10: Resto del año
B11: Año 1 | C11: Año 2 a 10 | H11: =B12-F10 -> 3695.6522
A12: Producción | B12: =F10+(11.5-3)*C4 -> 4000 | C12: =A4 -> 5000 | E12: RESTO DEL AÑO | F12: 3696

Sheet Ejercicio 7 y 8
A1: EJERCICIO 7 | G1: EJERCICIO 8
A2: Venta [Tn] | H2: Año 1 | I2: Año 2 a 10
A3: Anual | C3: Cuatrimestral | G3: Producción | H3: ='Ejercicio 6'!B12 -> 4000 | I3: ='Ejercicio 6'!C12 -> 5000
A4: =InfoInicial!B17 -> 5000 | C4: =A4/4 -> 1250
G5: Ventas del año 1 = | H5: =H3-C7 -> 3375
A6: Volumen de produccion cuatrimestral = | C6: =C4 -> 1250 | D6: Tn | G6: Ventas del año 2 a 10 = | H6: =I3 -> 5000
A7: Stock promedio elaborados = | C7: =C6/2 -> 625 | D7: Tn
A10: Se opera sin la formación de un stock de seguridad

Sheet Ejercicio 9
A1: EJERCICIO 9
A2: Punto A
A3: Ciclo de elaboracion = | B3: 7 | C3: días
A4: Ciclos anuales = | B4: =ROUND(340/B3,0) -> 49 | C4: ciclos
A6: Periodo de puesta en marcha (3 meses) = | B6: ='Ejercicio 6'!F10*1.173 -> 357 | C6: con 17,3% de desperdicio
A7: Resto del año = | B7: ='Ejercicio 6'!H11*1.173 -> 4335 | C7: con 17,3% de desperdicio
A8: total materia prima para la producción | B8: =B7+B6 -> 4692
A9: Produccion año 1 = | B9: ='Ejercicio 6'!B12 -> 4000
A10: Desperdicio no recuperable = | B10: =B8-B9 -> 692
A12: Punto B
A13: Cantidad de ciclos productivos = | B13: =B4 -> 49 | C13: ciclos
A14: Vol. Anual / días año * longitud proceso = | B14: ='Ejercicio 1'!C22/340*'Ejercicio 2 '!C5 -> 120.75 | C14: Tn
A16: Desglose por ciclo productivo (en régimen)
A17: Producto elaborado = | B17: MP / Coef desperdicio operativo = | D17: =B14/1.173 -> 102.94118 | F17: Coef Desp Operativo (Ej1) = 17.3%
A18: Desperdicio no recuperable = | B18: MP * % Desperdicio real = | D18: =D17*1.173 -> 120.75 | F18: Desperdicio Real (Ej1) = 17.3%
A19: Desperdicio recuperable = | B19: MP * % Recuperable = | D19: 0 | F19: Recuperable (Ej1) = 0%
C20: TOTAL = | D20: =SUM(D17:D19) -> 223.69118
A22: Punto C
A23: Consumo total MP año 1 = MP Produccion + MP Mercaderia en curso y SE = | C23: =D20+B6+B7 -> 4915.6912 | D23: Tn
A25: Punto D
A26: Consumo MP años 2 a 10 = | B26: ='Ejercicio 1'!C22*1.1 -> 6451.5 | C26: Tn

Sheet Ejercicio 10
A1: EJERCICIO 10
A2: Al final del mes | B2: Stock | C2: Compras | E2: Total de compras anuales= | F2: ='Ejercicio 9'!B26 -> 6451.5 | G2: Tn | I2: =340/365 -> 0.93150685
A3: Enero | B3: - | C3: - | E3: 12 Compras por año= | F3: =F2/I3 -> 577.15625 | G3: Tn | I3: =12*I2 -> 11.178082
A4: Febrero | B4: - | C4: - | E4: Consumo mensual= | F4: =F3 -> 577.15625 | G4: Tn
A5: Marzo | B5: =F3*3 -> 1731.4688 | C5: =B5 -> 1731.4688
A6: Abril | B6: - | C6: =B6 -> -
A7: Mayo | B7: - | C7: =B7 -> - | E7: El período de tiempo entre siembra y cosecha son 3 meses
A8: Junio | B8: =B5 -> 1731.4688 | C8: =B8 -> 1731.4688
A9: Julio | B9: - | C9: =B9 -> -
A10: Agosto | B10: - | C10: =B10 -> -
A11: Septiembre | B11: =B8 -> 1731.4688 | C11: =B11 -> 1731.4688
A12: Octubre | B12: - | C12: =B12 -> -
A13: Noviembre | B13: - | C13: =B13 -> -
A14: Diciembre | B14: =B11 -> 1731.4688 | C14: =B14 -> 1731.4688

Sheet Ejercicio 11
A1: EJERCICIO 11
B2: U. de medida | C2: Período Instalación | D2: Año 1 | E2: Año 2 a 10
A3: Ventas | B3: t. PT | C3: 0 | D3: ='Ejercicio 7 y 8'!H5 -> 3375 | E3: ='Ejercicio 7 y 8'!H6 -> 5000
A4: Stock Promedio de elaborados | B4: t. PT | C4: 0 | D4: ='Ejercicio 7 y 8'!C7 -> 625 | E4: ='Ejercicio 7 y 8'!C7 -> 625
A5: Producción | B5: t. MP | C5: 0 | D5: ='Ejercicio 6'!B12 -> 4000 | E5: ='Ejercicio 6'!C12 -> 5000
A6: Desperdicio No Recuperables | B6: t. MP | C6: 0 | D6: ='Ejercicio 9'!B10 -> 692 | E6: ='Ejercicio 9'!D18 -> 120.75
A7: En Curso y Semielaborados | B7: t. MP | C7: 0 | D7: ='Ejercicio 9'!D20 -> 223.69118 | E7: ='Ejercicio 9'!D20 -> 223.69118
A8: Consumo de MP | B8: t. MP | C8: 0 | D8: ='Ejercicio 9'!C23 -> 4915.6912 | E8: ='Ejercicio 9'!B26 -> 6451.5
A9: Stock de MP | B9: t. MP | C9: ='Ejercicio 10'!F4*3 -> 1731.4688 | D9: =AVERAGE('Ejercicio 10'!B3:B14) -> 1731.4688 | E9: =D9 -> 1731.4688
A10: Compra de MP | B10: t. MP | C10: =C9 -> 1731.4688 | D10: =D8 -> 4915.6912 | E10: =E8 -> 6451.5

Sheet InfoInicial
A2: Tasa porcentual de IVA | B2: 0.21
A3: Tasa porcentual de Impuesto a las Ganancias | B3: 0.35
A4: Honorarios al Directorio | B4: 0 | C4: Variable sobre Utilidad economica antes de HD e IG
A6: Tiempo de Amortización Activos Fijos: | B6: Se considera una depreciación lineal y un valor residual nulo
A7: edificios y obras complementarias | B7: 30 | C7: años
A8: instalaciones industriales | B8: 10 | C8: años
A9: máquinas, equipos y accesorios | B9: 10 | C9: años
A10: rodados y equipos auxiliares | B10: 5 | C10: años
A11: muebles y útiles | B11: 5 | C11: años
A12: repuestos iniciales | B12: 3 | C12: años
A13: Otros Activos y Cargos Diferidos | B13: 5 | C13: años | G13: Imprevistos sin Especificar | I13: 0.02
A15: Nombre del Producto | B15: Harina de Soja
A17: Ventas Anuales Promedio | B17: 5000 | C17: en Unidades | D17: -> Toneladas
A18: Precio Promedio | B18: 450 | C18: en $ | H18: https://www.bolsadecereales.com/fob
A20: Cantidad de personal total
A21: en Producción | B21: 8 | C21: personas
A22: en Comercialización | B22: 1 | C22: personas
A23: en Administración | B23: 3 | C23: personas
A25: Tamaño de la planta en metros cuadrados | B25: 2500 | C25: m2
A26: Periodo de Instalación | B26: 9 | C26: en meses
A27: Período de Puesta en Marcha | B27: 3 | C27: en meses
A30: Tasa de Cambio | B30: 1300 | C30: $ por cada | D30: 1 | E30: U$S
A33: Tasa de Credito Bancario | B33: 0.5 | C33: anual
A34: Rubro a financiar | B34: Activo Fijo
A35: % sobre el total del Rubro | B35: 0.3
A37: Dias de Financiación de Proveedores | B37: 30
A38: % sobre Compras | B38: 0.5
A39: Tasa de financiación | B39: 0.12 | C39: anual

Sheet Materia Prima
C4: Granos | F4: Bolsas de Polipropileno
B5: Tonelada | C5: ='Ejercicio 10'!F2 -> 6451.5 | F5: Año 1 | G5: =1000*3375 -> 3375000 | H5: kg | I5: =G5/50 -> 67500 | J5: Bolsas | K5: =I5*H8 -> 40486500
B6: Precio x u | C6: 90000 | F6: Año 2 a 10 | G6: =1000*5000 -> 5000000 | H6: kg | I6: =G6/50 -> 100000 | J6: Bolsas | K6: =I6*H8 -> 59980000
B7: Total | C7: =C5*C6 -> 5.80635e+08
G8: Precio unitario | H8: =29990/50 -> 599.8 | I8: https://articulo.mercadolibre.com.ar/MLA-1297825597-bolsa-de-rafia-blanca-56x97-x50unidades-50-55kg-_JM#polycard_client=search-nordic&position=21&search_layout=stack&type=item&tracking_id=21379e5e-2703-47be-a018-e752532858f4
B10: Año 1 | C10: =C7*0.75 -> 4.3547625e+08
B11: Año 2 a 10 | C11: =C7 -> 5.80635e+08
B14: Stock Materia Prima año 0 | D14: ='Ejercicio 11'!C9*C6 -> 1.5583219e+08
B18: 90000 | D18: =6451.5*1000 -> 6451500
B19: =D19*B18/D18 -> 0.55800977 | D19: 40

Sheet Materiales área producción
A1: Referencias
A2: Mantenimiento | B2: 0.01
A3: Repuestos | B3: 0.016
A4: Producción | B4: 0.015
A5: Personal | B5: 0.03
A8: PRODUCCIÓN | B8: Año | C8: 1 | D8: 2 | E8: 3 | F8: 4 | G8: 5 | H8: 6 | I8: 7 | J8: 8 | K8: 9 | L8: 10
B9: Mantenimiento | C9: =$B$2*('DE-Inv AF y Am'!$B$20+'DE-Inv AF y Am'!$D$20) -> 28400068 | D9: =$B$2*('DE-Inv AF y Am'!$B$20+'DE-Inv AF y Am'!$D$20) -> 28400068 | E9: =$B$2*('DE-Inv AF y Am'!$B$20+'DE-Inv AF y Am'!$D$20) -> 28400068 | F9: =$B$2*('DE-Inv AF y Am'!$B$20+'DE-Inv AF y Am'!$D$20) -> 28400068 | G9: =$B$2*('DE-Inv AF y Am'!$B$20+'DE-Inv AF y Am'!$D$20) -> 28400068 | H9: =$B$2*('DE-Inv AF y Am'!$B$20+'DE-Inv AF y Am'!$D$20) -> 28400068 | I9: =$B$2*('DE-Inv AF y Am'!$B$20+'DE-Inv AF y Am'!$D$20) -> 28400068 | J9: =$B$2*('DE-Inv AF y Am'!$B$20+'DE-Inv AF y Am'!$D$20) -> 28400068 | ... L9: =$B$2*('DE-Inv AF y Am'!$B$20+'DE-Inv AF y Am'!$D$20) -> 28400068
B10: Repuestos | C10: =$B$3*('DE-Inv AF y Am'!$B$12+'DE-Inv AF y Am'!$D$11) -> 884000 | D10: =$B$3*('DE-Inv AF y Am'!$B$12+'DE-Inv AF y Am'!$D$11) -> 884000 | E10: =$B$3*('DE-Inv AF y Am'!$B$12+'DE-Inv AF y Am'!$D$11) -> 884000 | F10: =$B$3*('DE-Inv AF y Am'!$B$12+'DE-Inv AF y Am'!$D$11) -> 884000 | G10: =$B$3*('DE-Inv AF y Am'!$B$12+'DE-Inv AF y Am'!$D$11) -> 884000 | H10: =$B$3*('DE-Inv AF y Am'!$B$12+'DE-Inv AF y Am'!$D$11) -> 884000 | I10: =$B$3*('DE-Inv AF y Am'!$B$12+'DE-Inv AF y Am'!$D$11) -> 884000 | J10: =$B$3*('DE-Inv AF y Am'!$B$12+'DE-Inv AF y Am'!$D$11) -> 884000 | ... L10: =$B$3*('DE-Inv AF y Am'!$B$12+'DE-Inv AF y Am'!$D$11) -> 884000
B11: Producción | C11: =$B$4*'DE-Costos'!B4 -> 7139441.3 | D11: =$B$4*'DE-Costos'!C4 -> 9609225 | E11: =$B$4*'DE-Costos'!D4 -> 9609225 | F11: =$B$4*'DE-Costos'!E4 -> 9609225 | G11: =$B$4*'DE-Costos'!F4 -> 9609225 | H11: =$B$4*'DE-Costos'!G4 -> 9609225 | I11: =$B$4*'DE-Costos'!H4 -> 9609225 | J11: =$B$4*'DE-Costos'!I4 -> 9609225 | ... L11: =$B$4*'DE-Costos'!K4 -> 9609225
B12: Personal | C12: =$B$5*('DE-Costos'!B5+'DE-Costos'!B8) -> 1606466.2 | D12: =$B$5*('DE-Costos'!C5+'DE-Costos'!C8) -> 1606466.2 | E12: =$B$5*('DE-Costos'!D5+'DE-Costos'!D8) -> 1606466.2 | F12: =$B$5*('DE-Costos'!E5+'DE-Costos'!E8) -> 1606466.2 | G12: =$B$5*('DE-Costos'!F5+'DE-Costos'!F8) -> 1606466.2 | H12: =$B$5*('DE-Costos'!G5+'DE-Costos'!G8) -> 1606466.2 | I12: =$B$5*('DE-Costos'!H5+'DE-Costos'!H8) -> 1606466.2 | J12: =$B$5*('DE-Costos'!I5+'DE-Costos'!I8) -> 1606466.2 | ... L12: =$B$5*('DE-Costos'!K5+'DE-Costos'!K8) -> 1606466.2
B13: TOTAL | C13: =SUM(C9:C12) -> 38029975 | D13: =SUM(D9:D12) -> 40499759 | E13: =SUM(E9:E12) -> 40499759 | F13: =SUM(F9:F12) -> 40499759 | G13: =SUM(G9:G12) -> 40499759 | H13: =SUM(H9:H12) -> 40499759 | I13: =SUM(I9:I12) -> 40499759 | J13: =SUM(J9:J12) -> 40499759 | ... L13: =SUM(L9:L12) -> 40499759

Sheet Gastos Merc en curso y SE
A1: Produccion año 1 | B1: ='Ejercicio 11'!D5 -> 4000 | C1: Tn | D1: Dividimos el valor de gastos del area de fabricacion por la cantidad fabricada en año 1 y año 2 a 10. Luego lo mutliplicamos por la cantidad de semielaborados (Ejercicio 11)
A2: Produccion año 2 a 10 | B2: ='Ejercicio 11'!E5 -> 5000 | C2: Tn
B6: Año 1 | C6: Año 2 a 10
A7: Materia prima | B7: =('DE-Costos'!B4/'Gastos Merc en curso y SE'!$B$1)*'Ejercicio 11'!$D$7 -> 26617167 | C7: =('DE-Costos'!C4/'Gastos Merc en curso y SE'!$B$2)*'Ejercicio 11'!$E$7 -> 28659985
A8: Mano de obra directa | B8: =('DE-Costos'!B5/'Gastos Merc en curso y SE'!$B$1)*'Ejercicio 11'!$D$7 -> 1655879.4 | C8: =('DE-Costos'!C5/'Gastos Merc en curso y SE'!$B$2)*'Ejercicio 11'!$E$7 -> 1324703.5
A9: Amortizaciones | B9: =('DE-Costos'!B7/'Gastos Merc en curso y SE'!$B$1)*'Ejercicio 11'!$D$7 -> 8979537.7 | C9: =('DE-Costos'!C7/'Gastos Merc en curso y SE'!$B$2)*'Ejercicio 11'!$E$7 -> 7183630.2
A10: Personal indirecto | B10: =('DE-Costos'!B8/'Gastos Merc en curso y SE'!$B$1)*'Ejercicio 11'!$D$7 -> 1338723.3 | C10: =('DE-Costos'!C8/'Gastos Merc en curso y SE'!$B$2)*'Ejercicio 11'!$E$7 -> 1070978.7
A11: Materiales | B11: =('DE-Costos'!B9/'Gastos Merc en curso y SE'!$B$1)*'Ejercicio 11'!$D$7 -> 2126742.5 | C11: =('DE-Costos'!C9/'Gastos Merc en curso y SE'!$B$2)*'Ejercicio 11'!$E$7 -> 1811887.7
A12: Energía eléctrica | B12: =('DE-Costos'!B10/'Gastos Merc en curso y SE'!$B$1)*'Ejercicio 11'!$D$7 -> 6577691.2 | C12: =('DE-Costos'!C10/'Gastos Merc en curso y SE'!$B$2)*'Ejercicio 11'!$E$7 -> 5539108.3
A13: Combustibles | B13: =('DE-Costos'!B11/'Gastos Merc en curso y SE'!$B$1)*'Ejercicio 11'!$D$7 -> 0 | C13: =('DE-Costos'!C11/'Gastos Merc en curso y SE'!$B$2)*'Ejercicio 11'!$E$7 -> 0
A14: Tasas e impuestos | B14: =('DE-Costos'!B12/'Gastos Merc en curso y SE'!$B$1)*'Ejercicio 11'!$D$7 -> 1752001.1 | C14: =('DE-Costos'!C12/'Gastos Merc en curso y SE'!$B$2)*'Ejercicio 11'!$E$7 -> 1401600.8
A15: Seguros | B15: =('DE-Costos'!B13/'Gastos Merc en curso y SE'!$B$1)*'Ejercicio 11'!$D$7 -> 6622045.3 | C15: =('DE-Costos'!C13/'Gastos Merc en curso y SE'!$B$2)*'Ejercicio 11'!$E$7 -> 5115346.8
A16: Imprevistos | B16: =('DE-Costos'!B14/'Gastos Merc en curso y SE'!$B$1)*'Ejercicio 11'!$D$7 -> 1113395.7 | C16: =('DE-Costos'!C14/'Gastos Merc en curso y SE'!$B$2)*'Ejercicio 11'!$E$7 -> 1042144.8

Sheet Seguros
A1: Bienes de uso | B1: Valor original | C1: Año 1 | E1: Años 2 a 10
C2: Coeficiente | D2: Prima | E2: Coeficiente | F2: Prima
A3: Edificio | B3: ='DE-Inv AF y Am'!B7 -> 1.9338843e+09 | C3: 0.01 | D3: =B3*C3 -> 19338843 | E3: 0.008 | F3: =B3*E3 -> 15471074
A4: Instalaciones | B4: ='DE-Inv AF y Am'!B8 -> 0 | C4: 0.015 | D4: =B4*C4 -> 0 | E4: 0.01 | F4: =B4*E4 -> 0
A5: Máquinas | B5: ='DE-Inv AF y Am'!B12 -> 55250000 | C5: 0.015 | D5: =B5*C5 -> 828750 | E5: 0.008 | F5: =B5*E5 -> 442000
A6: Rodados y equipos | B6: ='DE-Inv AF y Am'!B16 -> 713037970 | C6: 0.11 | D6: =B6*C6 -> 78434177 | E6: 0.11 | F6: =B6*E6 -> 78434177
A7: Muebles y útiles | B7: ='DE-Inv AF y Am'!B17 -> 51585600 | C7: 0.015 | D7: =B7*C7 -> 773784 | E7: 0.015 | F7: =B7*E7 -> 773784
B8: Totales | D8: =SUM(D3:D7) -> 99375554 | F8: =SUM(F3:F7) -> 95121035
C10: Año 1 | E10: Año 2 al 10
B11: Bienes de cambio | C11: Coeficiente | D11: Prima | E11: Coeficiente | F11: Prima
B12: Stock de materia prima | C12: 0.02 | D12: =C12*'DE-Costos'!$B$4 -> 9519255 | E12: 0.02 | F12: =E12*'DE-Costos'!$C$4 -> 12812300
B13: Stock de materiales | C13: 0.01 | D13: =C13*'DE-Costos'!$B$4 -> 4759627.5 | E13: 0.01
B14: Mercadería en proceso | C14: 0.01 | D14: =C14*'DE-Costos'!$B$4 -> 4759627.5 | E14: 0.01 | F14: =E14*'DE-Costos'!$C$4 -> 6406150
B15: Totales | D15: =SUM(D12:D14) -> 19038510 | F15: =SUM(F12:F14) -> 19218450
B18: Resumen: | C18: Prima | D18: Año 1 | E18: Año 2 a 10
C19: Bienes de uso | D19: =D8 -> 99375554 | E19: =F8 -> 95121035
C20: Bienes de cambio | D20: =D15 -> 19038510 | E20: =F15 -> 19218450
C21: Total | D21: =SUM(D19:D20) -> 1.1841406e+08 | E21: =SUM(E19:E20) -> 1.1433949e+08

Sheet Tasas e Impuestos
A1: Tasa municipal | B1: 0.008 | E1: Distribución por Área
A2: Impuesto inmobiliario | B2: 0.01 | E2: Producción | F2: Administración | G2: Comercialización
E3: 0.9 | F3: 0.05 | G3: 0.05
A7: Edificio y obras complementarias: | B7: ='DE-Inv AF y Am'!B43 -> 1.9338843e+09
A9: - | B9: Producción | C9: Administración | D9: Comercialización
A10: Tasa municipal | B10: =B1*$E$3*$B$7 -> 13923967 | C10: =B1*$F$3*$B$7 -> 773553.72 | D10: =B1*$G$3*$B$7 -> 773553.72
A11: Impuesto inmobiliario | B11: =B2*$E$3*$B$7 -> 17404959 | C11: =B2*$F$3*$B$7 -> 966942.15 | D11: =B2*$G$3*$B$7 -> 966942.15
A12: total anual año 1 a 10 | B12: =SUM(B10:B11) -> 31328926 | C12: =SUM(C10:C11) -> 1740495.9 | D12: =SUM(D10:D11) -> 1740495.9

Sheet DE-Inv AF y Am
J2: CALCULOS AUXILIARES | Q2: Muebles Y Utiles | R2: Precio x Un. | S2: Cantidad | T2: Total | V2: Instalaciones industriales | W2: Total
A3: Inversión Inicial en Activo Fijo | B3: Gasto interno (en $) | D3: Gasto Externo (en U$S) | Q3: Escritorios | R3: 86000 | S3: 12 | T3: =R3*S3 -> 1032000 | V3: Circuitos Iluminación | W3: 9000000
B4: Año 0 | C4: Año 1 | D4: Año 0 | E4: Año 1 | J4: https://inmueble.mercadolibre.com.ar/MLA-1411251467-2500-m2-pacheco-sobre-4200-m2-de-terreno-ubicado-a-300-mts-de-au-panamericana-_JM#position=10&search_layout=grid&type=item&tracking_id=0bfa1e80-f939-4613-b9c2-5152c3262cbb | K4: Terreno | L4: 1800000 | M4: USD | Q4: Sillas de oficina | R4: 114000 | S4: 20 | T4: =R4*S4 -> 2280000 | V4: Desague | W4: 3700000
Q5: Notebooks/PC | R5: 1180000 | S5: 12 | T5: =R5*S5 -> 14160000 | V5: Bombas | W5: 600000
A6: a) Bienes de Uso | Q6: Impresora | R6: 445000 | S6: 1 | T6: =R6*S6 -> 445000 | V6: Tanque de agua | W6: 900000
A7: Terreno y sus mejoras: | B7: =(L4*InfoInicial!B30)/1.21 -> 1.9338843e+09 | Q7: Telefonos | R7: 540000 | S7: 12 | T7: =R7*S7 -> 6480000 | V7: Sanitarias | W7: 1600000
A8: Edificio y obras complementarias: | B8: 0 | J8: Rodados y Eq. Aux | K8: Precio x Un. | L8: Cantidad | M8: Total | Q8: Set de utiles | R8: 15000 | S8: 12 | T8: =R8*S8 -> 180000 | V8: Deteccion de incendio | W8: 1200000
A9: Instalaciones industriales: | B9: =W11 -> 27800000 | J9: Autoelevador | K9: 22000000 | L9: 1 | M9: =K9*L9 -> 22000000 | Q9: Mesas Comedor | R9: 400000 | S9: 4 | T9: =R9*S9 -> 1600000 | V9: Sistema Tuberías | W9: 800000
A10: Máquinas operativas: | J10: Zorra hidraulica | K10: 500000 | L10: 2 | M10: =K10*L10 -> 1000000 | Q10: Sillas Comedor | R10: 420000 | S10: 25 | T10: =R10*S10 -> 10500000 | V10: Fuerza motriz | W10: 10000000
A11: importadas, valor FOB, con repuestos: | B11: 0 | J11: Cinta Transportadora | K11: 1200000 | L11: 1 | M11: =K11*L11 -> 1200000 | Q11: Tachos de basura | R11: 93000 | S11: 7 | T11: =R11*S11 -> 651000 | W11: =SUM(W3:W10) -> 27800000
A12: nacionales, precio en fábrica del proveedor: | B12: =SUM($M$27:$M$34) -> 55250000 | J12: Medidor digital de humedad para granos de soja | K12: 175000 | L12: 1 | M12: =K12*L12 -> 175000 | Q12: Proyectores | R12: 190000 | S12: 5 | T12: =R12*S12 -> 950000
J13: Medidor digital de humedad para harinas de soja | K13: 425000 | L13: 1 | M13: =K13*L13 -> 425000
A14: Gastos conexos a la importación de maquinaria: | B14: 0 | J14: Termómetro infrarojo | K14: 42500 | L14: 1 | M14: =K14*L14 -> 42500 | Q14: Mingitorios | R14: 700000 | S14: 3 | T14: =R14*S14 -> 2100000
A15: Transporte y montaje de la maquinaria: | B15: =B12*0.05 -> 2762500 | J15: Medidor de PH | K15: 68274 | L15: 1 | M15: =K15*L15 -> 68274 | Q15: Inodoro | R15: 80000 | S15: 5 | T15: =R15*S15 -> 400000
A16: Rodados y equipos auxiliares: | B16: =M19 -> 713037970 | J16: Pallets de madera normalizados | K16: =M47 -> 2600 | L16: =N45 -> 358 | M16: =K16*L16 -> 930800 | Q16: Lavamanos | R16: 160000 | S16: 3 | T16: =R16*S16 -> 480000
A17: Muebles y útiles: | B17: =T30 -> 51585600 | J17: Tubos PVC | K17: =L57 -> 1688 | L17: =N53 -> 291667 | M17: =K17*L17 -> 492333896 | Q17: Dispenser de agua | R17: 150000 | S17: 4 | T17: =R17*S17 -> 600000
A18: Infraestructura en predio propio: | J18: Bomba de agua | K18: =L61 -> 22270 | L18: =P53 -> 8750 | M18: =K18*L18 -> 194862500 | Q18: Aire Acondicionado | R18: 560000 | S18: 3 | T18: =R18*S18 -> 1680000
A19: Imprevistos: | B19: =SUM(B7:B18)*InfoInicial!I13 -> 55686407 | L19: Total | M19: =SUM(M9:M18) -> 713037970 | Q19: Matafuegos | R19: 69000 | S19: 3 | T19: =R19*S19 -> 207000
A20: Total Bienes de uso: | B20: =SUM(B7:B19) -> 2.8400068e+09 | Q20: Horno Eléctrico | R20: 150000 | S20: 3 | T20: =R20*S20 -> 450000
Q21: Heladera c/freezer | R21: 580000 | S21: 3 | T21: =R21*S21 -> 1740000
A22: b) Gastos asimilables o cargos diferidos: | Q22: Lavavajillas | R22: 770000 | S22: 2 | T22: =R22*S22 -> 1540000
A23: Investigaciones y estudios: | B23: 300000 | Q23: Cafetera | R23: 260000 | S23: 1 | T23: =R23*S23 -> 260000
A24: Constitución y organización de la empresa: | B24: 623000 | Q24: Microondas | R24: 200000 | S24: 1 | T24: =R24*S24 -> 200000
A25: Gastos de Administración e Ingeniería | B25: 18050000 | Q25: Mesa de Trabajo | R25: 180000 | S25: 3 | T25: =R25*S25 -> 540000
A26: durante el período de instalación: | B26: 0 | J26: Máquinas Operativas | K26: Precio x Un. | L26: Cantidad | M26: Total | N26: Nacional | Q26: Detector de humo | R26: 16000 | S26: 4 | T26: =R26*S26 -> 64000
A27: Gastos de puesta en marcha: | B27: 0 | C27: 9152278.7 | J27: Separadora | K27: 5850000 | L27: 1 | M27: =K27*L27 -> 5850000 | N27: x | Q27: Estanterias | R27: 160000 | S27: 10 | T27: =R27*S27 -> 1600000
A28: Patentes y Licencias: | B28: 150000 | J28: Descascaradora | K28: 9750000 | L28: 1 | M28: =K28*L28 -> 9750000 | N28: x | Q28: Locker | R28: 422200 | S28: 3 | T28: =R28*S28 -> 1266600 | U28: (Locker de 8 puertas la unidad)
A29: Infraestructura en predio ajeno: | J29: Molino Grueso | K29: 3000000 | L29: 2 | M29: =K29*L29 -> 6000000 | N29: x | Q29: Ventiladores | R29: 45000 | S29: 4 | T29: =R29*S29 -> 180000
A30: Imprevistos: | B30: =SUM(B23:B29)*InfoInicial!I13 -> 382460 | C30: =SUM(C23:C29)*InfoInicial!I13 -> 183045.57 | J30: Extrusora | K30: 4750000 | L30: 2 | M30: =K30*L30 -> 9500000 | N30: x | S30: Total | T30: =SUM(T3:T29) -> 51585600
A31: Total gastos asimilables o cargos diferidos: | B31: =SUM(B23:B30) -> 19505460 | C31: =SUM(C23:C30) -> 9335324.3 | J31: Prensa | K31: 8500000 | L31: 1 | M31: =K31*L31 -> 8500000 | N31: x
J32: Secadora de Granos | K32: 7400000 | L32: 1 | M32: =K32*L32 -> 7400000 | N32: x
A33: c) Total Inversiones iniciales Activo Fijo, sin IVA | B33: =B20+B31 -> 2.8595122e+09 | C33: =C20+C31 -> 9335324.3 | J33: Molienda | K33: 3250000 | L33: 1 | M33: =K33*L33 -> 3250000 | N33: x
J34: Empaquetadora | K34: 5000000 | L34: 1 | M34: =K34*L34 -> 5000000 | N34: x
A35: d) IVA: | B35: =B33*0.21 -> 6.0049757e+08 | C35: =C33*0.21 -> 1960418.1
A37: e) TOTAL INVERSIONES INICIALES ACTIVO FIJO | B37: =B33+B35 -> 3.4600098e+09 | C37: =C33+C35 -> 11295742 | J37: http://pa.bibdigital.ucc.edu.ar/3437/1/TM_Bruera%20%282%29.pdf | K37: Planta de Acopio y Secado de granos, referencia
J38: https://www.moralesyasociados.com.ar/costo-de-constituir-una-srl-o-una-sa/#:~:text=Tanto%20en%20CABA%20como%20en,disponga%20la%20compa%C3%B1ia%20de%20seguros). | K38: Estudio de Abogados
J39: https://www.uoyepweb.org.ar/escala-salarial/ | K39: Escala Salarial
A40: Rubro | B40: Inversión | C40: Coeficiente | D40: Alícuotas de amortización | G40: Valor residual
B41: original | D41: Años 1/3 | E41: Años 4/5 | F41: Años 6/10
A42: Bienes de Uso
...

Sheet DE-Costos
A1: COSTO TOTAL DE PRODUCCION
B2: Gastos en el Area de Producción | O2: CALCULOS AUXILIARES
A3: Rubros | B3: Año 1 | C3: Año 2 | D3: Año 3 | E3: Año 4 | F3: Año 5 | G3: Año 6 | H3: Año 7 | I3: Año 8 | J3: Año 9 | K3: Año 10
A4: Materia prima | B4: ='Materia Prima'!C10+'Materia Prima'!K5 -> 4.7596275e+08 | C4: ='Materia Prima'!$C$11+'Materia Prima'!$K$6 -> 6.40615e+08 | D4: ='Materia Prima'!$C$11+'Materia Prima'!$K$6 -> 6.40615e+08 | E4: ='Materia Prima'!$C$11+'Materia Prima'!$K$6 -> 6.40615e+08 | F4: ='Materia Prima'!$C$11+'Materia Prima'!$K$6 -> 6.40615e+08 | G4: ='Materia Prima'!$C$11+'Materia Prima'!$K$6 -> 6.40615e+08 | H4: ='Materia Prima'!$C$11+'Materia Prima'!$K$6 -> 6.40615e+08 | I4: ='Materia Prima'!$C$11+'Materia Prima'!$K$6 -> 6.40615e+08 | J4: ='Materia Prima'!$C$11+'Materia Prima'!$K$6 -> 6.40615e+08 | K4: ='Materia Prima'!$C$11+'Materia Prima'!$K$6 -> 6.40615e+08 | P4: https://www.boletinoficial.gob.ar/detalleAviso/primera/308813/20240607#:~:text=ART%C3%8DCULO%205.,asciende%20a%2095%2C624%20%24%2FkWh. | Q4: Tomando de referencia que el valor de KWH es de 95,624$/kwh
A5: Mano de obra directa | B5: =$W$34 -> 29610097 | C5: =$W$34 -> 29610097 | D5: =$W$34 -> 29610097 | E5: =$W$34 -> 29610097 | F5: =$W$34 -> 29610097 | G5: =$W$34 -> 29610097 | H5: =$W$34 -> 29610097 | I5: =$W$34 -> 29610097 | ... K5: =$W$34 -> 29610097 | P5: Maquinaria | Q5: Cant | R5: Consumo Unitario (KWh) | S5: Hs Activas al Año | T5: Consumo Anual (KW) | U5: Costo KWH
A6: Gastos de fabricación: | P6: Separadora de Granos | Q6: 1 | R6: 3.5 | S6: 5440 | T6: =Q6*R6*S6 -> 19040 | U6: =T6*95.624 -> 1820681
A7: Amortizaciones | B7: ='DE-Inv AF y Am'!$D$55*0.9 -> 1.6057026e+08 | C7: ='DE-Inv AF y Am'!$D$55*0.9 -> 1.6057026e+08 | D7: ='DE-Inv AF y Am'!$D$55*0.9 -> 1.6057026e+08 | E7: ='DE-Inv AF y Am'!$D$55*0.9 -> 1.6057026e+08 | F7: ='DE-Inv AF y Am'!$D$55*0.9 -> 1.6057026e+08 | G7: ='DE-Inv AF y Am'!$D$55*0.9 -> 1.6057026e+08 | H7: ='DE-Inv AF y Am'!$D$55*0.9 -> 1.6057026e+08 | I7: ='DE-Inv AF y Am'!$D$55*0.9 -> 1.6057026e+08 | ... K7: ='DE-Inv AF y Am'!$D$55*0.9 -> 1.6057026e+08 | P7: Descascadora | Q7: 1 | R7: 15 | S7: 5440 | T7: =Q7*R7*S7 -> 81600 | U7: =T7*95.624 -> 7802918.4
A8: Personal indirecto | B8: =$W$33 -> 23938778 | C8: =$W$33 -> 23938778 | D8: =$W$33 -> 23938778 | E8: =$W$33 -> 23938778 | F8: =$W$33 -> 23938778 | G8: =$W$33 -> 23938778 | H8: =$W$33 -> 23938778 | I8: =$W$33 -> 23938778 | ... K8: =$W$33 -> 23938778 | P8: Molino Grueso | Q8: 2 | R8: 0.55 | S8: 5440 | T8: =Q8*R8*S8 -> 5984 | U8: =T8*95.624 -> 572214.02
A9: Materiales | B9: ='Materiales área producción'!C13 -> 38029975 | C9: ='Materiales área producción'!D13 -> 40499759 | D9: ='Materiales área producción'!E13 -> 40499759 | E9: ='Materiales área producción'!F13 -> 40499759 | F9: ='Materiales área producción'!G13 -> 40499759 | G9: ='Materiales área producción'!H13 -> 40499759 | H9: ='Materiales área producción'!I13 -> 40499759 | I9: ='Materiales área producción'!J13 -> 40499759 | ... K9: ='Materiales área producción'!L13 -> 40499759 | P9: Extrusora | Q9: 2 | R9: 92.5 | S9: 5440 | T9: =Q9*R9*S9 -> 1006400 | U9: =T9*95.624 -> 96235994
A10: Energía eléctrica | B10: =0.95*U13 -> 1.1762093e+08 | C10: =$U$13 -> 1.2381151e+08 | D10: =$U$13 -> 1.2381151e+08 | E10: =$U$13 -> 1.2381151e+08 | F10: =$U$13 -> 1.2381151e+08 | G10: =$U$13 -> 1.2381151e+08 | H10: =$U$13 -> 1.2381151e+08 | I10: =$U$13 -> 1.2381151e+08 | J10: =$U$13 -> 1.2381151e+08 | K10: =$U$13 -> 1.2381151e+08 | P10: Prensadora | Q10: 1 | R10: 30 | S10: 5440 | T10: =Q10*R10*S10 -> 163200 | U10: =T10*95.624 -> 15605837
A11: Combustibles | B11: 0 | C11: 0 | D11: 0 | E11: 0 | F11: 0 | G11: 0 | H11: 0 | I11: 0 | J11: 0 | K11: 0 | P11: Molienda | Q11: 1 | R11: 1.21 | S11: 5440 | T11: =Q11*R11*S11 -> 6582.4 | U11: =T11*95.624 -> 629435.42
A12: Tasas e impuestos | B12: ='Tasas e Impuestos'!$B$12 -> 31328926 | C12: ='Tasas e Impuestos'!$B$12 -> 31328926 | D12: ='Tasas e Impuestos'!$B$12 -> 31328926 | E12: ='Tasas e Impuestos'!$B$12 -> 31328926 | F12: ='Tasas e Impuestos'!$B$12 -> 31328926 | G12: ='Tasas e Impuestos'!$B$12 -> 31328926 | H12: ='Tasas e Impuestos'!$B$12 -> 31328926 | I12: ='Tasas e Impuestos'!$B$12 -> 31328926 | ... K12: ='Tasas e Impuestos'!$B$12 -> 31328926 | P12: Empaquetadora | Q12: 1 | R12: 2.2 | S12: 5440 | T12: =Q12*R12*S12 -> 11968 | U12: =T12*95.624 -> 1144428
A13: Seguros | B13: =Seguros!$D$21 -> 1.1841406e+08 | C13: =Seguros!$E$21 -> 1.1433949e+08 | D13: =Seguros!$E$21 -> 1.1433949e+08 | E13: =Seguros!$E$21 -> 1.1433949e+08 | F13: =Seguros!$E$21 -> 1.1433949e+08 | G13: =Seguros!$E$21 -> 1.1433949e+08 | H13: =Seguros!$E$21 -> 1.1433949e+08 | I13: =Seguros!$E$21 -> 1.1433949e+08 | J13: =Seguros!$E$21 -> 1.1433949e+08 | K13: =Seguros!$E$21 -> 1.1433949e+08 | U13: =SUM(U6:U12) -> 1.2381151e+08
A14: Imprevistos | B14: =SUM(B4:B13)*InfoInicial!$I$13 -> 19909516 | C14: =SUM(C4:C13)*InfoInicial!$I$13 -> 23294276 | D14: =SUM(D4:D13)*InfoInicial!$I$13 -> 23294276 | E14: =SUM(E4:E13)*InfoInicial!$I$13 -> 23294276 | F14: =SUM(F4:F13)*InfoInicial!$I$13 -> 23294276 | G14: =SUM(G4:G13)*InfoInicial!$I$13 -> 23294276 | H14: =SUM(H4:H13)*InfoInicial!$I$13 -> 23294276 | I14: =SUM(I4:I13)*InfoInicial!$I$13 -> 23294276 | ... K14: =SUM(K4:K13)*InfoInicial!$I$13 -> 23294276
A15: Gastos Total de Producción | B15: =SUM(B4:B14) -> 1.0153853e+09 | C15: =SUM(C4:C14) -> 1.1880081e+09 | D15: =SUM(D4:D14) -> 1.1880081e+09 | E15: =SUM(E4:E14) -> 1.1880081e+09 | F15: =SUM(F4:F14) -> 1.1880081e+09 | G15: =SUM(G4:G14) -> 1.1880081e+09 | H15: =SUM(H4:H14) -> 1.1880081e+09 | I15: =SUM(I4:I14) -> 1.1880081e+09 | ... K15: =SUM(K4:K14) -> 1.1880081e+09
P16: Equipo | Q16: Cantidad | R16: Consumo Unitario (KWh) | S16: Hs Activas al Año | T16: Consumo Anual (KW) | U16: Costo KWH
A17: % Gasto Variable | B17: =1-B18 -> 0.53536606 | C17: =1-C18 -> 0.59824917 | D17: =1-D18 -> 0.59824917 | E17: =1-E18 -> 0.59824917 | F17: =1-F18 -> 0.59824917 | G17: =1-G18 -> 0.59824917 | H17: =1-H18 -> 0.59824917 | I17: =1-I18 -> 0.59824917 | ... K17: =1-K18 -> 0.59824917 | P17: Ventiladores | Q17: 4 | R17: 0.06 | S17: 1188 | T17: =Q17*R17*S17 -> 285.12 | U17: =T17*95.624 -> 27264.315
A18: % Gasto Constante | B18: =(B7+B8+B10+B11+B12+B13+B14)/B15 -> 0.46463394 | C18: =(C7+C8+C10+C11+C12+C13+C14)/C15 -> 0.40175083 | D18: =(D7+D8+D10+D11+D12+D13+D14)/D15 -> 0.40175083 | E18: =(E7+E8+E10+E11+E12+E13+E14)/E15 -> 0.40175083 | F18: =(F7+F8+F10+F11+F12+F13+F14)/F15 -> 0.40175083 | G18: =(G7+G8+G10+G11+G12+G13+G14)/G15 -> 0.40175083 | H18: =(H7+H8+H10+H11+H12+H13+H14)/H15 -> 0.40175083 | I18: =(I7+I8+I10+I11+I12+I13+I14)/I15 -> 0.40175083 | ... K18: =(K7+K8+K10+K11+K12+K13+K14)/K15 -> 0.40175083 | P18: Computadoras | Q18: 12 | R18: 0.02 | S18: 5440 | T18: =Q18*R18*S18 -> 1305.6 | U18: =T18*95.624 -> 124846.69
P19: Aire Acondicionado | Q19: 3 | R19: 1.013 | S19: 4200 | T19: =Q19*R19*S19 -> 12763.8 | U19: =T19*95.624 -> 1220525.6
B20: Gastos a activar | P20: Impresora | Q20: 1 | R20: 0.6 | S20: 1560 | T20: =Q20*R20*S20 -> 936 | U20: =T20*95.624 -> 89504.064
B21: Mercadería en Curso y Semielaborada | L21: Puesta en marcha | P21: Microondas | Q21: 1 | R21: 0.64 | S21: 600 | T21: =Q21*R21*S21 -> 384 | U21: =T21*95.624 -> 36719.616
A22: Rubros | B22: Año 1 | C22: Año 2 | D22: Año 3 | E22: Año 4 | F22: Año 5 | G22: Año 6 | H22: Año 7 | I22: Año 8 | J22: Año 9 | K22: Año 10 | L22: Año 1 | P22: Luminarias | Q22: 20 | R22: 0.1 | S22: 5440 | T22: =Q22*R22*S22 -> 10880 | U22: =T22*95.624 -> 1040389.1
A23: Materia prima | B23: ='Gastos Merc en curso y SE'!B7 -> 26617167 | C23: ='Gastos Merc en curso y SE'!$C$7 -> 28659985 | D23: ='Gastos Merc en curso y SE'!$C$7 -> 28659985 | E23: ='Gastos Merc en curso y SE'!$C$7 -> 28659985 | F23: ='Gastos Merc en curso y SE'!$C$7 -> 28659985 | G23: ='Gastos Merc en curso y SE'!$C$7 -> 28659985 | H23: ='Gastos Merc en curso y SE'!$C$7 -> 28659985 | I23: ='Gastos Merc en curso y SE'!$C$7 -> 28659985 | J23: ='Gastos Merc en curso y SE'!$C$7 -> 28659985 | K23: ='Gastos Merc en curso y SE'!$C$7 -> 28659985 | L23: =(B23/11.5)*3 -> 6943608.8 | P23: Lavavajilla | Q23: 1 | R23: 0.0285 | S23: 8640 | T23: =Q23*R23*S23 -> 246.24 | U23: =T23*95.624 -> 23546.454
A24: Mano de obra directa | B24: ='Gastos Merc en curso y SE'!B8 -> 1655879.4 | C24: ='Gastos Merc en curso y SE'!$C$8 -> 1324703.5 | D24: ='Gastos Merc en curso y SE'!$C$8 -> 1324703.5 | E24: ='Gastos Merc en curso y SE'!$C$8 -> 1324703.5 | F24: ='Gastos Merc en curso y SE'!$C$8 -> 1324703.5 | G24: ='Gastos Merc en curso y SE'!$C$8 -> 1324703.5 | H24: ='Gastos Merc en curso y SE'!$C$8 -> 1324703.5 | I24: ='Gastos Merc en curso y SE'!$C$8 -> 1324703.5 | J24: ='Gastos Merc en curso y SE'!$C$8 -> 1324703.5 | K24: ='Gastos Merc en curso y SE'!$C$8 -> 1324703.5 | L24: =(B24/11.5)*3 -> 431968.53 | P24: Heladera | Q24: 1 | R24: 0.09 | S24: 8640 | T24: =Q24*R24*S24 -> 777.6 | U24: =T24*95.624 -> 74357.222
A25: Gastos de fabricación: | L25: =(B25/11.5)*3 -> 0 | P25: Cafetera | Q25: 1 | R25: 0.9 | S25: 1440 | T25: =Q25*R25*S25 -> 1296 | U25: =T25*95.624 -> 123928.7
A26: Amortizaciones | B26: ='Gastos Merc en curso y SE'!B9 -> 8979537.7 | C26: ='Gastos Merc en curso y SE'!$C$9 -> 7183630.2 | D26: ='Gastos Merc en curso y SE'!$C$9 -> 7183630.2 | E26: ='Gastos Merc en curso y SE'!$C$9 -> 7183630.2 | F26: ='Gastos Merc en curso y SE'!$C$9 -> 7183630.2 | G26: ='Gastos Merc en curso y SE'!$C$9 -> 7183630.2 | H26: ='Gastos Merc en curso y SE'!$C$9 -> 7183630.2 | I26: ='Gastos Merc en curso y SE'!$C$9 -> 7183630.2 | J26: ='Gastos Merc en curso y SE'!$C$9 -> 7183630.2 | K26: ='Gastos Merc en curso y SE'!$C$9 -> 7183630.2 | L26: 0 | P26: Horno Eléctrico | Q26: 1 | R26: 0.75 | S26: 1080 | T26: =Q26*R26*S26 -> 810 | U26: =T26*95.624 -> 77455.44
A27: Personal indirecto | B27: ='Gastos Merc en curso y SE'!B10 -> 1338723.3 | C27: ='Gastos Merc en curso y SE'!$C$10 -> 1070978.7 | D27: ='Gastos Merc en curso y SE'!$C$10 -> 1070978.7 | E27: ='Gastos Merc en curso y SE'!$C$10 -> 1070978.7 | F27: ='Gastos Merc en curso y SE'!$C$10 -> 1070978.7 | G27: ='Gastos Merc en curso y SE'!$C$10 -> 1070978.7 | H27: ='Gastos Merc en curso y SE'!$C$10 -> 1070978.7 | I27: ='Gastos Merc en curso y SE'!$C$10 -> 1070978.7 | J27: ='Gastos Merc en curso y SE'!$C$10 -> 1070978.7 | K27: ='Gastos Merc en curso y SE'!$C$10 -> 1070978.7 | L27: 0 | P27: Proyector | Q27: 2 | R27: 0.568 | S27: 420 | T27: =Q27*R27*S27 -> 477.12 | U27: =T27*95.624 -> 45624.123
A28: Materiales | B28: ='Gastos Merc en curso y SE'!B11 -> 2126742.5 | C28: ='Gastos Merc en curso y SE'!$C$11 -> 1811887.7 | D28: ='Gastos Merc en curso y SE'!$C$11 -> 1811887.7 | E28: ='Gastos Merc en curso y SE'!$C$11 -> 1811887.7 | F28: ='Gastos Merc en curso y SE'!$C$11 -> 1811887.7 | G28: ='Gastos Merc en curso y SE'!$C$11 -> 1811887.7 | H28: ='Gastos Merc en curso y SE'!$C$11 -> 1811887.7 | I28: ='Gastos Merc en curso y SE'!$C$11 -> 1811887.7 | J28: ='Gastos Merc en curso y SE'!$C$11 -> 1811887.7 | K28: ='Gastos Merc en curso y SE'!$C$11 -> 1811887.7 | L28: =(B28/11.5)*3 -> 554802.38 | U28: =SUM(U17:U27) -> 2884161.4
A29: Energía eléctrica | B29: ='Gastos Merc en curso y SE'!B12 -> 6577691.2 | C29: ='Gastos Merc en curso y SE'!$C$12 -> 5539108.3 | D29: ='Gastos Merc en curso y SE'!$C$12 -> 5539108.3 | E29: ='Gastos Merc en curso y SE'!$C$12 -> 5539108.3 | F29: ='Gastos Merc en curso y SE'!$C$12 -> 5539108.3 | G29: ='Gastos Merc en curso y SE'!$C$12 -> 5539108.3 | H29: ='Gastos Merc en curso y SE'!$C$12 -> 5539108.3 | I29: ='Gastos Merc en curso y SE'!$C$12 -> 5539108.3 | J29: ='Gastos Merc en curso y SE'!$C$12 -> 5539108.3 | K29: ='Gastos Merc en curso y SE'!$C$12 -> 5539108.3 | L29: =(B29/11.5)*3 -> 1715919.4
A30: Combustibles | B30: ='Gastos Merc en curso y SE'!B13 -> 0 | C30: ='Gastos Merc en curso y SE'!C13 -> 0 | L30: =(B30/11.5)*3 -> 0
A31: Tasas e impuestos | B31: ='Gastos Merc en curso y SE'!B14 -> 1752001.1 | C31: ='Gastos Merc en curso y SE'!$C$14 -> 1401600.8 | D31: ='Gastos Merc en curso y SE'!$C$14 -> 1401600.8 | E31: ='Gastos Merc en curso y SE'!$C$14 -> 1401600.8 | F31: ='Gastos Merc en curso y SE'!$C$14 -> 1401600.8 | G31: ='Gastos Merc en curso y SE'!$C$14 -> 1401600.8 | H31: ='Gastos Merc en curso y SE'!$C$14 -> 1401600.8 | I31: ='Gastos Merc en curso y SE'!$C$14 -> 1401600.8 | J31: ='Gastos Merc en curso y SE'!$C$14 -> 1401600.8 | K31: ='Gastos Merc en curso y SE'!$C$14 -> 1401600.8 | L31: 0 | P31: https://www.argentina.gob.ar/transporte/cnrt/transparencia/escalas-salariales | Q31: https://www.ignacioonline.com.ar/categorias-empleados-de-comercio-de-comercio-cct-130-75/ | R31: Escalas Salariales
A32: Seguros | B32: ='Gastos Merc en curso y SE'!B15 -> 6622045.3 | C32: ='Gastos Merc en curso y SE'!$C$15 -> 5115346.8 | D32: ='Gastos Merc en curso y SE'!$C$15 -> 5115346.8 | E32: ='Gastos Merc en curso y SE'!$C$15 -> 5115346.8 | F32: ='Gastos Merc en curso y SE'!$C$15 -> 5115346.8 | G32: ='Gastos Merc en curso y SE'!$C$15 -> 5115346.8 | H32: ='Gastos Merc en curso y SE'!$C$15 -> 5115346.8 | I32: ='Gastos Merc en curso y SE'!$C$15 -> 5115346.8 | J32: ='Gastos Merc en curso y SE'!$C$15 -> 5115346.8 | K32: ='Gastos Merc en curso y SE'!$C$15 -> 5115346.8 | L32: 0 | P32: Puesto | Q32: Salario Bruto x Mes | R32: Salario Bruto x Año | S32: Cantidad | T32: Sub total | U32: Cargas Sociales | V32: Aguinaldo Anual | W32: Total
A33: Imprevistos | B33: ='Gastos Merc en curso y SE'!B16 -> 1113395.7 | C33: ='Gastos Merc en curso y SE'!$C$16 -> 1042144.8 | D33: ='Gastos Merc en curso y SE'!$C$16 -> 1042144.8 | E33: ='Gastos Merc en curso y SE'!$C$16 -> 1042144.8 | F33: ='Gastos Merc en curso y SE'!$C$16 -> 1042144.8 | G33: ='Gastos Merc en curso y SE'!$C$16 -> 1042144.8 | H33: ='Gastos Merc en curso y SE'!$C$16 -> 1042144.8 | I33: ='Gastos Merc en curso y SE'!$C$16 -> 1042144.8 | J33: ='Gastos Merc en curso y SE'!$C$16 -> 1042144.8 | K33: ='Gastos Merc en curso y SE'!$C$16 -> 1042144.8 | L33: =(B33/11.5)*3 -> 290451.06 | P33: Jefe de calidad | Q33: 1185088 | R33: =Q33*12 -> 14221056 | S33: 1 | T33: =R33*S33 -> 14221056 | U33: =R33*0.6 -> 8532633.6 | V33: =Q33 -> 1185088 | W33: =T33+U33+V33 -> 23938778
A34: Total gastos a activar | B34: =SUM(B23:B33) -> 56783183 | C34: =SUM(C23:C33) -> 53149385 | D34: =SUM(D23:D33) -> 53149385 | E34: =SUM(E23:E33) -> 53149385 | F34: =SUM(F23:F33) -> 53149385 | G34: =SUM(G23:G33) -> 53149385 | H34: =SUM(H23:H33) -> 53149385 | I34: =SUM(I23:I33) -> 53149385 | ... K34: =SUM(K23:K33) -> 53149385 | L34: =SUM($L$23:$L$33) -> 9936750.2 | P34: Operario | Q34: 284166 | R34: =Q34*12 -> 3409992 | S34: 8 | T34: =R34*S34 -> 27279936 | U34: =R34*0.6 -> 2045995.2 | V34: =Q34 -> 284166 | W34: =T34+U34+V34 -> 29610097
L35: 9152278.7 | P35: Gerente de administracion | Q35: 1452453 | R35: =Q35*12 -> 17429436 | S35: 1 | T35: =R35*S35 -> 17429436 | U35: =R35*0.6 -> 10457662 | V35: =Q35 -> 1452453 | W35: =T35+U35+V35 -> 29339551
B36: Costo en el Area de Producción | P36: Encargado administrativo | Q36: 855278 | R36: =Q36*12 -> 10263336 | S36: 1 | T36: =R36*S36 -> 10263336 | U36: =R36*0.6 -> 6158001.6 | V36: =Q36 -> 855278 | W36: =T36+U36+V36 -> 17276616
B37: Año 1 | C37: Año 2 | D37: Año 3 | E37: Año 4 | F37: Año 5 | G37: Año 6 | H37: Año 7 | I37: Año 8 | J37: Año 9 | K37: Año 10 | P37: Encargado RRHH | Q37: 744500 | R37: =Q37*12 -> 8934000 | S37: 1 | T37: =R37*S37 -> 8934000 | U37: =R37*0.6 -> 5360400 | V37: =Q37 -> 744500 | W37: =T37+U37+V37 -> 15038900
A38: Gastos Total de Producción | B38: =+B15 -> 1.0153853e+09 | C38: =+C15 -> 1.1880081e+09 | D38: =+D15 -> 1.1880081e+09 | E38: =+E15 -> 1.1880081e+09 | F38: =+F15 -> 1.1880081e+09 | G38: =+G15 -> 1.1880081e+09 | H38: =+H15 -> 1.1880081e+09 | I38: =+I15 -> 1.1880081e+09 | ... K38: =+K15 -> 1.1880081e+09 | P38: Encargado de ventas | Q38: 855278 | R38: =Q38*12 -> 10263336 | S38: 1 | T38: =R38*S38 -> 10263336 | U38: =R38*0.6 -> 6158001.6 | V38: =Q38 -> 855278 | W38: =T38+U38+V38 -> 17276616
A39: Menos:
A40: Gasto de puesta en marcha (-) | B40: =L34 -> 9936750.2 | C40: 0 | E40: 0 | F40: 0 | G40: 0 | H40: 0 | I40: 0 | J40: 0 | K40: 0
...

Sheet DE-InvAT
A1: INVERSIONES EN ACTIVO DE TRABAJO
A2: Rubros | B2: Año 0 | C2: Año 1 | D2: Año 2 | E2: Año 3 | F2: Año 4 | G2: Año 5 | H2: Año 6 | I2: Año 7 | J2: Año 8 | K2: Año 9 | L2: Año 10
A3: 1. Activo de Trabajo: (valor contable) | B3: =B4+B5 -> 39487500 | C3: =C4+C5 -> 2.207774e+08 | D3: =D4+D5 -> 2.9891096e+08 | E3: =E4+E5 -> 2.9891096e+08 | F3: =F4+F5 -> 2.9891096e+08 | G3: =G4+G5 -> 2.9891096e+08 | H3: =H4+H5 -> 2.9891096e+08 | I3: =I4+I5 -> 2.9891096e+08 | ... L3: =L4+L5 -> 2.9891096e+08
A4: a) Disponibilidad Mínima en Caja y Bancos: | B4: ='DE-Costos'!B94*0.02 -> 39487500 | C4: ='DE-Costos'!$C$94*0.02 -> 58500000 | D4: ='DE-Costos'!$C$94*0.02 -> 58500000 | E4: ='DE-Costos'!$C$94*0.02 -> 58500000 | F4: ='DE-Costos'!$C$94*0.02 -> 58500000 | G4: ='DE-Costos'!$C$94*0.02 -> 58500000 | H4: ='DE-Costos'!$C$94*0.02 -> 58500000 | I4: ='DE-Costos'!$C$94*0.02 -> 58500000 | J4: ='DE-Costos'!$C$94*0.02 -> 58500000 | ... L4: ='DE-Costos'!$C$94*0.02 -> 58500000
A5: b) Crédito por Ventas | B5: 0 | C5: ='DE-Costos'!B94*(30/365) -> 1.622774e+08 | D5: ='DE-Costos'!C94*(30/365) -> 2.4041096e+08 | E5: ='DE-Costos'!D94*(30/365) -> 2.4041096e+08 | F5: ='DE-Costos'!E94*(30/365) -> 2.4041096e+08 | G5: ='DE-Costos'!F94*(30/365) -> 2.4041096e+08 | H5: ='DE-Costos'!G94*(30/365) -> 2.4041096e+08 | I5: ='DE-Costos'!H94*(30/365) -> 2.4041096e+08 | J5: ='DE-Costos'!I94*(30/365) -> 2.4041096e+08 | ... L5: ='DE-Costos'!K94*(30/365) -> 2.4041096e+08 | M5: El plazo promedio de financiación a clientes es de 30 días
A7: c) Bienes de cambio: | B7: =SUM(B8:B11) -> 1.9773552e+08 | C7: =SUM(C8:C11) -> 6.9635951e+08 | D7: =SUM(D8:D11) -> 8.4108052e+08 | E7: =SUM(E8:E11) -> 8.406263e+08 | F7: =SUM(F8:F11) -> 8.406263e+08 | G7: =SUM(G8:G11) -> 8.406263e+08 | H7: =SUM(H8:H11) -> 8.406263e+08 | I7: =SUM(I8:I11) -> 8.406263e+08 | ... L7: =SUM(L8:L11) -> 8.406263e+08
A8: Stock de materias prima: | B8: ='Materia Prima'!D14 -> 1.5583219e+08 | C8: ='Materia Prima'!C10 -> 4.3547625e+08 | D8: ='Materia Prima'!$C$11 -> 5.80635e+08 | E8: ='Materia Prima'!$C$11 -> 5.80635e+08 | F8: ='Materia Prima'!$C$11 -> 5.80635e+08 | G8: ='Materia Prima'!$C$11 -> 5.80635e+08 | H8: ='Materia Prima'!$C$11 -> 5.80635e+08 | I8: ='Materia Prima'!$C$11 -> 5.80635e+08 | J8: ='Materia Prima'!$C$11 -> 5.80635e+08 | K8: ='Materia Prima'!$C$11 -> 5.80635e+08 | L8: ='Materia Prima'!$C$11 -> 5.80635e+08
A9: Stock de materiales: | B9: =9/12*C9 -> 41903337 | C9: ='DE-Costos'!B9+'DE-Costos'!B54+'DE-Costos'!B73 -> 55871115 | D9: ='DE-Costos'!C9+'DE-Costos'!C54+'DE-Costos'!C73 -> 58340899 | E9: ='DE-Costos'!D9+'DE-Costos'!D54+'DE-Costos'!D73 -> 58340899 | F9: ='DE-Costos'!E9+'DE-Costos'!E54+'DE-Costos'!E73 -> 58340899 | G9: ='DE-Costos'!F9+'DE-Costos'!F54+'DE-Costos'!F73 -> 58340899 | H9: ='DE-Costos'!G9+'DE-Costos'!G54+'DE-Costos'!G73 -> 58340899 | I9: ='DE-Costos'!H9+'DE-Costos'!H54+'DE-Costos'!H73 -> 58340899 | J9: ='DE-Costos'!I9+'DE-Costos'!I54+'DE-Costos'!I73 -> 58340899 | ... L9: ='DE-Costos'!K9+'DE-Costos'!K54+'DE-Costos'!K73 -> 58340899
A10: Mercadería en curso y semielaborada | B10: 0 | C10: ='DE-Costos'!B34 -> 56783183 | D10: ='DE-Costos'!C34 -> 53149385 | E10: ='DE-Costos'!D34 -> 53149385 | F10: ='DE-Costos'!E34 -> 53149385 | G10: ='DE-Costos'!F34 -> 53149385 | H10: ='DE-Costos'!G34 -> 53149385 | I10: ='DE-Costos'!H34 -> 53149385 | J10: ='DE-Costos'!I34 -> 53149385 | ... L10: ='DE-Costos'!K34 -> 53149385
A11: Stock de elaborados | B11: 0 | C11: =B11+'DE-Costos'!B111 -> 1.4822896e+08 | D11: =C11+'DE-Costos'!C111 -> 1.4895524e+08 | E11: =D11+'DE-Costos'!D111 -> 1.4850101e+08 | F11: =E11+'DE-Costos'!E111 -> 1.4850101e+08 | G11: =F11+'DE-Costos'!F111 -> 1.4850101e+08 | H11: =G11+'DE-Costos'!G111 -> 1.4850101e+08 | I11: =H11+'DE-Costos'!H111 -> 1.4850101e+08 | J11: =I11+'DE-Costos'!I111 -> 1.4850101e+08 | ... L11: =K11+'DE-Costos'!K111 -> 1.4850101e+08
A13: d) Total Activo de Trabajo, sin IVA: | B13: =B3+B7 -> 2.3722302e+08 | C13: =C3+C7 -> 9.1713691e+08 | D13: =D3+D7 -> 1.1399915e+09 | E13: =E3+E7 -> 1.1395373e+09 | F13: =F3+F7 -> 1.1395373e+09 | G13: =G3+G7 -> 1.1395373e+09 | H13: =H3+H7 -> 1.1395373e+09 | I13: =I3+I7 -> 1.1395373e+09 | ... L13: =L3+L7 -> 1.1395373e+09
A14: 2. Menos:
A15: Amortizaciones en Mercadería en proceso | B15: 0 | C15: ='DE-Costos'!B26 -> 8979537.7 | D15: ='DE-Costos'!C26 -> 7183630.2 | E15: ='DE-Costos'!D26 -> 7183630.2 | F15: ='DE-Costos'!E26 -> 7183630.2 | G15: ='DE-Costos'!F26 -> 7183630.2 | H15: ='DE-Costos'!G26 -> 7183630.2 | I15: ='DE-Costos'!H26 -> 7183630.2 | J15: ='DE-Costos'!I26 -> 7183630.2 | ... L15: ='DE-Costos'!K26 -> 7183630.2
A16: Amortizaciones en Stock de elaborado | B16: 0 | C16: =('DE-Costos'!B7-'DE-Costos'!B26)/'Ejercicio 11'!$D$5*'Ejercicio 11'!$D4 -> 23686051 | D16: =('DE-Costos'!C7-'DE-Costos'!C26)/'Ejercicio 11'!$E$5*'Ejercicio 11'!$E$4 -> 19173329 | E16: =('DE-Costos'!D7-'DE-Costos'!D26)/'Ejercicio 11'!$E$5*'Ejercicio 11'!$E$4 -> 19173329 | F16: =('DE-Costos'!E7-'DE-Costos'!E26)/'Ejercicio 11'!$E$5*'Ejercicio 11'!$E$4 -> 19173329 | G16: =('DE-Costos'!F7-'DE-Costos'!F26)/'Ejercicio 11'!$E$5*'Ejercicio 11'!$E$4 -> 19173329 | H16: =('DE-Costos'!G7-'DE-Costos'!G26)/'Ejercicio 11'!$E$5*'Ejercicio 11'!$E$4 -> 19173329 | I16: =('DE-Costos'!H7-'DE-Costos'!H26)/'Ejercicio 11'!$E$5*'Ejercicio 11'!$E$4 -> 19173329 | J16: =('DE-Costos'!I7-'DE-Costos'!I26)/'Ejercicio 11'!$E$5*'Ejercicio 11'!$E$4 -> 19173329 | K16: =('DE-Costos'!J7-'DE-Costos'!J26)/'Ejercicio 11'!$E$5*'Ejercicio 11'!$E$4 -> 19173329 | L16: =('DE-Costos'!K7-'DE-Costos'!K26)/'Ejercicio 11'!$E$5*'Ejercicio 11'!$E$4 -> 19173329
A17: Utilidades en Crédito por ventas | B17: 0 | C17: =C5*'DE-Costos'!B127 -> 54062427 | D17: =D5*'DE-Costos'!C127 -> 83988023 | E17: =E5*'DE-Costos'!D127 -> 84119090 | F17: =F5*'DE-Costos'!E127 -> 84143357 | G17: =G5*'DE-Costos'!F127 -> 84143357 | H17: =H5*'DE-Costos'!G127 -> 84143357 | I17: =I5*'DE-Costos'!H127 -> 84143357 | J17: =J5*'DE-Costos'!I127 -> 84143357 | ... L17: =L5*'DE-Costos'!K127 -> 84143357
A18: Amortizaciones en Crédito por ventas | B18: 0 | C18: =('DE-Inv AF y Am'!D55-C15-C16)/365/30 -> 13310.12 | D18: =C18 -> 13310.12 | E18: =D18 -> 13310.12 | F18: =('DE-Inv AF y Am'!E55-D15-D16)/365/30 -> 13886.251 | G18: =F18 -> 13886.251 | H18: =('DE-Inv AF y Am'!F55-E15-E16)/365/30 -> -1623.3524 | I18: =H18 -> -1623.3524 | J18: =I18 -> -1623.3524 | K18: =J18 -> -1623.3524 | L18: =K18 -> -1623.3524
A20: 3. Inversiones en Activo de Trabajo, sin IVA | B20: =B13-SUM(B15:B18) -> 2.3722302e+08 | C20: =C13-SUM(C15:C18) -> 8.3039558e+08 | D20: =D13-SUM(D15:D18) -> 1.0296332e+09 | E20: =E13-SUM(E15:E18) -> 1.0290479e+09 | F20: =F13-SUM(F15:F18) -> 1.0290231e+09 | G20: =G13-SUM(G15:G18) -> 1.0290231e+09 | H20: =H13-SUM(H15:H18) -> 1.0290386e+09 | I20: =I13-SUM(I15:I18) -> 1.0290386e+09 | ... L20: =L13-SUM(L15:L18) -> 1.0290386e+09 | M20: ='DE-Cal Inv.'!N16 -> 1.0290386e+09
A22: 4. Incrementos de Activo de Trabajo | B22: =B13 -> 2.3722302e+08 | C22: =C13-B13 -> 6.7991389e+08 | D22: =D13-C13 -> 2.2285457e+08 | E22: =E13-D13 -> -454224.69 | F22: =F13-E13 -> 0 | G22: =G13-F13 -> 0 | H22: =H13-G13 -> 0 | I22: =I13-H13 -> 0 | J22: =J13-I13 -> 0 | ... L22: =L13-K13 -> 0
A23: Incrementos de Inversión en Activo de Trabajo | B23: =B20 -> 2.3722302e+08 | C23: =C20-B20 -> 5.9317256e+08 | D23: =D20-C20 -> 1.992376e+08 | E23: =E20-D20 -> -585291.42 | F23: =F20-E20 -> -24842.929 | G23: =G20-F20 -> 0 | H23: =H20-G20 -> 15509.603 | I23: =I20-H20 -> 0 | J23: =J20-I20 -> 0 | ... L23: =L20-K20 -> 0
A25: 5. Incrementos IVA sobre Inversiones
A26: Crédito por Ventas | B26: =B5*0.21 -> 0 | C26: =C5*0.21 -> 34078253 | D26: =D5*0.21 -> 50486301 | E26: =E5*0.21 -> 50486301 | F26: =F5*0.21 -> 50486301 | G26: =G5*0.21 -> 50486301 | H26: =H5*0.21 -> 50486301 | I26: =I5*0.21 -> 50486301 | ... L26: =L5*0.21 -> 50486301
A27: Bienes de cambio:
A28: Stock de materia prima | B28: =B8*0.21 -> 32724759 | C28: =C8*0.21 -> 91450013 | D28: =D8*0.21 -> 1.2193335e+08 | E28: =E8*0.21 -> 1.2193335e+08 | F28: =F8*0.21 -> 1.2193335e+08 | G28: =G8*0.21 -> 1.2193335e+08 | H28: =H8*0.21 -> 1.2193335e+08 | I28: =I8*0.21 -> 1.2193335e+08 | ... L28: =L8*0.21 -> 1.2193335e+08
A29: Stock de materiales | B29: =B9*0.21 -> 8799700.7 | C29: =C9*0.21 -> 11732934 | D29: =D9*0.21 -> 12251589 | E29: =E9*0.21 -> 12251589 | F29: =F9*0.21 -> 12251589 | G29: =G9*0.21 -> 12251589 | H29: =H9*0.21 -> 12251589 | I29: =I9*0.21 -> 12251589 | ... L29: =L9*0.21 -> 12251589
A30: Mercadería en proceso | B30: =B10*0.21 -> 0 | C30: =C10*0.21 -> 11924468 | D30: =D10*0.21 -> 11161371 | E30: =E10*0.21 -> 11161371 | F30: =F10*0.21 -> 11161371 | G30: =G10*0.21 -> 11161371 | H30: =H10*0.21 -> 11161371 | I30: =I10*0.21 -> 11161371 | ... L30: =L10*0.21 -> 11161371
A31: Stock de elaborados | B31: =B11*0.21 -> 0 | C31: =C11*0.21 -> 31128082 | D31: =D11*0.21 -> 31280600 | E31: =E11*0.21 -> 31185212 | F31: =F11*0.21 -> 31185212 | G31: =G11*0.21 -> 31185212 | H31: =H11*0.21 -> 31185212 | I31: =I11*0.21 -> 31185212 | ... L31: =L11*0.21 -> 31185212
A32: Total incrementos IVA sobre inversiones | B32: =SUM(B26:B31) -> 41524460 | C32: =SUM(C26:C31) -> 1.8031375e+08 | D32: =SUM(D26:D31) -> 2.2711321e+08 | E32: =SUM(E26:E31) -> 2.2701782e+08 | F32: =SUM(F26:F31) -> 2.2701782e+08 | G32: =SUM(G26:G31) -> 2.2701782e+08 | H32: =SUM(H26:H31) -> 2.2701782e+08 | I32: =SUM(I26:I31) -> 2.2701782e+08 | ... L32: =SUM(L26:L31) -> 2.2701782e+08
A34: 6. Incrementos Inversiones en Activo de Trabajo | B34: =B23+B32 -> 2.7874748e+08 | C34: =C23+C32 -> 7.7348631e+08 | D34: =D23+D32 -> 4.2635081e+08 | E34: =E23+E32 -> 2.2643253e+08 | F34: =F23+F32 -> 2.2699298e+08 | G34: =G23+G32 -> 2.2701782e+08 | H34: =H23+H32 -> 2.2703333e+08 | I34: =I23+I32 -> 2.2701782e+08 | ... L34: =L23+L32 -> 2.2701782e+08

Sheet DE-Cal Inv.
A1: Calendario de Inversiones
A2: Rubros | B2: Año 0: Preinversion | C2: Año 0: Instalación | D2: Año 1 | E2: Año 2 | F2: Año 3 | G2: Año 4 | H2: Año 5 | I2: Año 6 | J2: Año 7 | K2: Año 8 | L2: Año 9 | M2: Año 10 | N2: Totales
A3: Inversiones en Activo Fijo
A4: Bienes de uso | B4: 0 | C4: ='DE-Inv AF y Am'!B20 -> 2.8400068e+09 | D4: 0 | E4: 0 | F4: 0 | G4: 0 | H4: 0 | I4: 0 | J4: 0 | K4: 0 | L4: 0 | M4: 0 | N4: =SUM(B4:M4) -> 2.8400068e+09
A5: Asimilables | B5: ='DE-Inv AF y Am'!B31 -> 19505460 | D5: ='DE-Inv AF y Am'!C31 -> 9335324.3 | E5: 0 | F5: 0 | G5: 0 | H5: 0 | I5: 0 | J5: 0 | K5: 0 | L5: 0 | M5: 0 | N5: =SUM(B5:M5) -> 28840784
A6: Subtotal Activo Fijo | B6: =SUM(B4:B5) -> 19505460 | C6: =SUM(C4:C5) -> 2.8400068e+09 | D6: =SUM(D4:D5) -> 9335324.3 | E6: =SUM(E4:E5) -> 0 | F6: =SUM(F4:F5) -> 0 | G6: =SUM(G4:G5) -> 0 | H6: =SUM(H4:H5) -> 0 | I6: =SUM(I4:I5) -> 0 | ... M6: =SUM(M4:M5) -> 0 | N6: =SUM(B6:M6) -> 2.8688476e+09
A8: Inversiones en A. de Trabajo
A9: Disp. mínimas C y B | B9: 0 | C9: ='DE-InvAT'!B4 -> 39487500 | D9: ='DE-InvAT'!C4-'DE-InvAT'!B4 -> 19012500 | E9: ='DE-InvAT'!D4-'DE-InvAT'!C4 -> 0 | F9: ='DE-InvAT'!E4-'DE-InvAT'!D4 -> 0 | G9: ='DE-InvAT'!F4-'DE-InvAT'!E4 -> 0 | H9: ='DE-InvAT'!G4-'DE-InvAT'!F4 -> 0 | I9: ='DE-InvAT'!H4-'DE-InvAT'!G4 -> 0 | J9: ='DE-InvAT'!I4-'DE-InvAT'!H4 -> 0 | K9: ='DE-InvAT'!J4-'DE-InvAT'!I4 -> 0 | ... M9: ='DE-InvAT'!L4-'DE-InvAT'!K4 -> 0 | N9: =SUM(B9:M9) -> 58500000
A10: Crédito por ventas | B10: 0 | C10: ='DE-InvAT'!B5-'DE-InvAT'!B17-'DE-InvAT'!B18 -> 0 | D10: ='DE-InvAT'!C5-'DE-InvAT'!B5-'DE-InvAT'!C17-'DE-InvAT'!C18-C10 -> 1.0820166e+08 | E10: =('DE-InvAT'!D5-'DE-InvAT'!D17-'DE-InvAT'!D18)-('DE-InvAT'!C5-'DE-InvAT'!C17-'DE-InvAT'!C18) -> 48207965 | F10: =('DE-InvAT'!E5-'DE-InvAT'!E17-'DE-InvAT'!E18)-('DE-InvAT'!D5-'DE-InvAT'!D17-'DE-InvAT'!D18) -> -131066.73 | G10: =('DE-InvAT'!F5-'DE-InvAT'!F17-'DE-InvAT'!F18)-('DE-InvAT'!E5-'DE-InvAT'!E17-'DE-InvAT'!E18) -> -24842.929 | H10: =('DE-InvAT'!G5-'DE-InvAT'!G17-'DE-InvAT'!G18)-('DE-InvAT'!F5-'DE-InvAT'!F17-'DE-InvAT'!F18) -> 0 | I10: =('DE-InvAT'!H5-'DE-InvAT'!H17-'DE-InvAT'!H18)-('DE-InvAT'!G5-'DE-InvAT'!G17-'DE-InvAT'!G18) -> 15509.603 | J10: =('DE-InvAT'!I5-'DE-InvAT'!I17-'DE-InvAT'!I18)-('DE-InvAT'!H5-'DE-InvAT'!H17-'DE-InvAT'!H18) -> 0 | K10: =('DE-InvAT'!J5-'DE-InvAT'!J17-'DE-InvAT'!J18)-('DE-InvAT'!I5-'DE-InvAT'!I17-'DE-InvAT'!I18) -> 0 | L10: =('DE-InvAT'!K5-'DE-InvAT'!K17-'DE-InvAT'!K18)-('DE-InvAT'!J5-'DE-InvAT'!J17-'DE-InvAT'!J18) -> 0 | M10: =('DE-InvAT'!L5-'DE-InvAT'!L17-'DE-InvAT'!L18)-('DE-InvAT'!K5-'DE-InvAT'!K17-'DE-InvAT'!K18) -> 0 | N10: =SUM(B10:M10) -> 1.5626923e+08
A11: Bienes de cambio: | B11: 0
A12: Stock de Materia Prima | B12: 0 | C12: ='DE-InvAT'!B8 -> 1.5583219e+08 | D12: ='DE-InvAT'!C8-'DE-InvAT'!B8 -> 2.7964406e+08 | E12: ='DE-InvAT'!D8-'DE-InvAT'!C8 -> 145158750 | F12: ='DE-InvAT'!E8-'DE-InvAT'!D8 -> 0 | G12: ='DE-InvAT'!F8-'DE-InvAT'!E8 -> 0 | H12: ='DE-InvAT'!G8-'DE-InvAT'!F8 -> 0 | I12: ='DE-InvAT'!H8-'DE-InvAT'!G8 -> 0 | J12: ='DE-InvAT'!I8-'DE-InvAT'!H8 -> 0 | K12: ='DE-InvAT'!J8-'DE-InvAT'!I8 -> 0 | ... M12: ='DE-InvAT'!L8-'DE-InvAT'!K8 -> 0 | N12: =SUM(B12:M12) -> 5.80635e+08
A13: Stock de Materiales | B13: 0 | C13: ='DE-InvAT'!B9 -> 41903337 | D13: ='DE-InvAT'!C9-'DE-InvAT'!B9 -> 13967779 | E13: ='DE-InvAT'!D9-'DE-InvAT'!C9 -> 2469783.8 | F13: ='DE-InvAT'!E9-'DE-InvAT'!D9 -> 0 | G13: ='DE-InvAT'!F9-'DE-InvAT'!E9 -> 0 | H13: ='DE-InvAT'!G9-'DE-InvAT'!F9 -> 0 | I13: ='DE-InvAT'!H9-'DE-InvAT'!G9 -> 0 | J13: ='DE-InvAT'!I9-'DE-InvAT'!H9 -> 0 | K13: ='DE-InvAT'!J9-'DE-InvAT'!I9 -> 0 | ... M13: ='DE-InvAT'!L9-'DE-InvAT'!K9 -> 0 | N13: =SUM(B13:M13) -> 58340899
A14: Mercadería en proceso | B14: 0 | C14: 0 | D14: =('DE-InvAT'!C10-'DE-InvAT'!C15)-('DE-InvAT'!B10-'DE-InvAT'!B15) -> 47803645 | E14: =('DE-InvAT'!D10-'DE-InvAT'!D15)-('DE-InvAT'!C10-'DE-InvAT'!C15) -> -1837890 | F14: =('DE-InvAT'!E10-'DE-InvAT'!E15)-('DE-InvAT'!D10-'DE-InvAT'!D15) -> 0 | G14: =('DE-InvAT'!F10-'DE-InvAT'!F15)-('DE-InvAT'!E10-'DE-InvAT'!E15) -> 0 | H14: =('DE-InvAT'!G10-'DE-InvAT'!G15)-('DE-InvAT'!F10-'DE-InvAT'!F15) -> 0 | I14: =('DE-InvAT'!H10-'DE-InvAT'!H15)-('DE-InvAT'!G10-'DE-InvAT'!G15) -> 0 | J14: =('DE-InvAT'!I10-'DE-InvAT'!I15)-('DE-InvAT'!H10-'DE-InvAT'!H15) -> 0 | K14: =('DE-InvAT'!J10-'DE-InvAT'!J15)-('DE-InvAT'!I10-'DE-InvAT'!I15) -> 0 | ... M14: =('DE-InvAT'!L10-'DE-InvAT'!L15)-('DE-InvAT'!K10-'DE-InvAT'!K15) -> 0 | N14: =SUM(B14:M14) -> 45965755
A15: Stock de Elaborados | B15: 0 | C15: ='DE-InvAT'!B11 -> 0 | D15: =('DE-InvAT'!C11-'DE-InvAT'!C16)-('DE-InvAT'!B11-'DE-InvAT'!B16) -> 1.2454291e+08 | E15: =('DE-InvAT'!D11-'DE-InvAT'!D16)-('DE-InvAT'!C11-'DE-InvAT'!C16) -> 5238994.2 | F15: =('DE-InvAT'!E11-'DE-InvAT'!E16)-('DE-InvAT'!D11-'DE-InvAT'!D16) -> -454224.69 | G15: =('DE-InvAT'!F11-'DE-InvAT'!F16)-('DE-InvAT'!E11-'DE-InvAT'!E16) -> 0 | H15: =('DE-InvAT'!G11-'DE-InvAT'!G16)-('DE-InvAT'!F11-'DE-InvAT'!F16) -> 0 | I15: =('DE-InvAT'!H11-'DE-InvAT'!H16)-('DE-InvAT'!G11-'DE-InvAT'!G16) -> 0 | J15: =('DE-InvAT'!I11-'DE-InvAT'!I16)-('DE-InvAT'!H11-'DE-InvAT'!H16) -> 0 | K15: =('DE-InvAT'!J11-'DE-InvAT'!J16)-('DE-InvAT'!I11-'DE-InvAT'!I16) -> 0 | ... M15: =('DE-InvAT'!L11-'DE-InvAT'!L16)-('DE-InvAT'!K11-'DE-InvAT'!K16) -> 0 | N15: =SUM(B15:M15) -> 1.2932768e+08
