Workbook

Sheet 0. Resumen Ejecutivo
B2: CELI S.A. - DASHBOARD EJECUTIVO DE INSTALACIONES Y SERVICIOS INDUSTRIALES
B3: Proyecto Final UTN FRBA - Grupo 8 | Planta Industrial Pilar (Nave 720 m²) | Régimen: 3 Turnos (24/5) - 5.712 h/año
B5: POTENCIA INSTALADA | D5: POTENCIA DEMANDADA MÁX. | F5: CONSUMO ELÉCTRICO ANUAL | H5: POTENCIA TÉRMICA GAS
B6: ='1. Potencia Eléctrica'!K35 -> 77.828 | D6: ='1. Potencia Eléctrica'!N35 -> 49.727 | F6: ='1. Potencia Eléctrica'!S35 -> 231350.2 | H6: ='3. Instalación de Gas'!H9 -> 185000
B7: kW | D7: kW | F7: kWh/año | H7: kcal/h
B9: CONSUMO ANUAL GAS | D9: CAUDAL AIRE COMPRIMIDO | F9: CONSUMO DIARIO AGUA | H9: PRESUPUESTO ANUAL SERVICIOS
B10: ='3. Instalación de Gas'!O9 -> 129662.76 | D10: ='4. Aire Comprimido'!C13 -> 193.2 | F10: ='5. Agua y Saneamiento'!G18 -> 5.1328734 | H10: ='6. Costos Tarifarios'!G34 -> 92789951
B11: m³/año | D11: L/min | F11: m³/día | H11: $/año (Oficial ENRE/ENARGAS)
B13: MATRIZ CONSOLIDADA DE SERVICIOS INDUSTRIALES E INSTALACIONES
B14: Servicio / Instalación | C14: Parámetro Técnico Clave | D14: Unidad | E14: Valor Mensual | F14: Valor Anual | G14: Proveedor / Ente | H14: Costo Mensual Est. ($) | I14: Costo Anual Est. ($) | J14: Hoja de Detalle
B15: Energía Eléctrica (Fuerza Motriz) | C15: Potencia Demandada Máxima | D15: kW | E15: ='1. Potencia Eléctrica'!N35 -> 49.727 | F15: ='1. Potencia Eléctrica'!K35 -> 77.828 | G15: EDENOR (Tarifa T3 MT) | H15: ='6. Costos Tarifarios'!E31 -> 3819876.7 | I15: ='6. Costos Tarifarios'!G31 -> 45838521 | J15: 1. Potencia Eléctrica
B16: Sistema de Iluminación (Dec. 351/79) | C16: Artefactos LED Instalados | D16: unid. | E16: ='2. Luminarias y Lux'!T30 -> 93 | F16: ='2. Luminarias y Lux'!W30 -> 20481.376 | G16: Campanas High Bay / Paneles | H16: - | I16: (Incluido en Eléctrico) | J16: 2. Luminarias y Lux
B17: Gas Natural de Red | C17: Caudal Medio Operativo | D17: m³/h | E17: ='3. Instalación de Gas'!C15 -> 22.605083 | F17: ='3. Instalación de Gas'!O9 -> 129662.76 | G17: Naturgy BAN (SGP3) | H17: ='6. Costos Tarifarios'!E32 -> 3462619.2 | I17: ='6. Costos Tarifarios'!G32 -> 41551430 | J17: 3. Instalación de Gas
B18: Aire Comprimido Industrial | C18: Caudal Libre Entregado (8 bar) | D18: L/min | E18: ='4. Aire Comprimido'!C13 -> 193.2 | F18: ='4. Aire Comprimido'!C14*60*5712 -> 3972810.2 | G18: Compresor Schulz 5.5 HP | H18: - | I18: (Incluido en Eléctrico) | J18: 4. Aire Comprimido
B19: Agua de Proceso y Saneamiento | C19: Consumo Medio de Planta | D19: m³/mes | E19: ='5. Agua y Saneamiento'!G18*22 -> 112.92321 | F19: ='5. Agua y Saneamiento'!H18 -> 1221.6239 | G19: Red PIP + Cisterna 40m³ | H19: ='6. Costos Tarifarios'!E33 -> 450000 | I19: ='6. Costos Tarifarios'!G33 -> 5400000 | J19: 5. Agua y Saneamiento
B20: TOTAL PRESUPUESTO ANUAL ESTIMADO DE SERVICIOS E INSTALACIONES | H20: ='6. Costos Tarifarios'!E34 -> 7732495.9 | I20: ='6. Costos Tarifarios'!G34 -> 92789951 | J20: 100% INTEGRADO

Sheet 1. Potencia Eléctrica
B2: PLANTA CELI S.A. - RELEVAMIENTO DE POTENCIA ELÉCTRICA Y CONSUMO ENERGÉTICO
B3: Relevamiento de Fuerza Motriz, Servicios Auxiliares e Iluminación | Parque Industrial Pilar | Régimen: 3 Turnos (24/5) - 5.712 h/año
B5: ID | C5: Sector / Área | D5: Línea | E5: Equipo | F5: Marca y Modelo Relevado | G5: Cant. | H5: Pot. Unit. (kW) | I5: Tensión (V) | J5: Fases / Frec. | K5: Pot. Inst. (kW) | L5: Factor Utiliz. (Fu) | M5: Factor Simult. (Fs) | N5: Pot. Dem. (kW) | O5: cos φ | P5: Pot. Apar. (kW) | Q5: Hs Operat./Año | R5: Aprovechamiento | S5: Consumo Anual (kWh/año) | T5: Fuente / Referencia Técnica
B6: LÍNEA A: GALLETITAS DULCES Y CRACKERS (PROCESO CONTINUO)
B7: 1 | C7: Amasado | D7: Línea A | E7: Amasadora rápida | F7: Catania HJ25B espiral | G7: 1 | H7: 2.2 | I7: 220 V | J7: Monofásica 50Hz | K7: 2.2 | L7: 0.75 | M7: 1 | N7: =K7*L7*M7 -> 1.65 | O7: 0.85 | P7: =N7/O7 -> 1.9411765 | Q7: 5736 | R7: 0.35 | S7: =N7*Q7*R7 -> 3312.54 | T7: Calculos vf.xlsx Hoja 'BOM y balanceo' R5
B8: 2 | C8: Moldeado | D8: Línea A | E8: Laminadora / Rotativa | F8: Ralem R800 formadora | G8: 1 | H8: 2.5 | I8: 380 V | J8: Trifásica 50Hz | K8: =G8*H8 -> 2.5 | L8: 0.8 | M8: 1 | N8: =K8*L8*M8 -> 2 | O8: 0.85 | P8: =N8/O8 -> 2.3529412 | Q8: 5736 | R8: 0.63 | S8: =N8*Q8*R8 -> 7227.36 | T8: Calculos vf.xlsx Hoja 'BOM y balanceo' R6
B9: 3 | C9: Horneado | D9: Línea A | E9: Horno túnel continuo | F9: Polin Túnel Gas 12m (Tracción/Turbinas) | G9: 1 | H9: 24 | I9: 380 V | J9: Trifásica 50Hz | K9: =G9*H9 -> 24 | L9: 0.7 | M9: 1 | N9: =K9*L9*M9 -> 16.8 | O9: 0.85 | P9: =N9/O9 -> 19.764706 | Q9: 5736 | R9: 0.9 | S9: =N9*Q9*R9 -> 86728.32 | T9: Calculos vf.xlsx Hoja 'BOM y balanceo' R7
B10: 4 | C10: Enfriado | D10: Línea A | E10: Cinta de enfriamiento | F10: Golden Way Cintas modulares 7m | G10: 1 | H10: 2.2 | I10: 380 V | J10: Trifásica 50Hz | K10: =G10*H10 -> 2.2 | L10: 0.65 | M10: 1 | N10: =K10*L10*M10 -> 1.43 | O10: 0.85 | P10: =N10/O10 -> 1.6823529 | Q10: 5736 | R10: 0.85 | S10: =N10*Q10*R10 -> 6972.108 | T10: Calculos vf.xlsx Hoja 'BOM y balanceo' R8
B11: 5 | C11: Empaque | D11: Línea A | E11: Envasadora Flowpack | F11: Zon Pack Flowpack horizontal servomotor | G11: 1 | H11: 6.5 | I11: 380 V | J11: Trifásica 50Hz | K11: =G11*H11 -> 6.5 | L11: 0.7 | M11: 1 | N11: =K11*L11*M11 -> 4.55 | O11: 0.85 | P11: =N11/O11 -> 5.3529412 | Q11: 5736 | R11: 0.25 | S11: =N11*Q11*R11 -> 6524.7 | T11: Calculos vf.xlsx Hoja 'BOM y balanceo' R9
B12: SUBTOTAL LÍNEA A (GALLETITAS) | G12: =SUM(G7:G11) -> 5 | K12: =SUM(K7:K11) -> 37.4 | N12: =SUM(N7:N11) -> 26.43 | P12: =SUM(P7:P11) -> 31.094118 | S12: =SUM(S7:S11) -> 110765.03
B13: LÍNEA B: PANIFICADOS Y BUDINES (PROCESO POR BATCH)
B14: 8 | C14: Pesado | D14: Línea B | E14: Balanza de precisión | F14: Moretti Ultra 60 macro/micro | G14: 1 | H14: 0.25 | I14: 220 V | J14: Monofásica 50Hz | K14: =G14*H14 -> 0.25 | L14: 0.5 | M14: 1 | N14: =K14*L14*M14 -> 0.125 | O14: 1 | P14: =N14/O14 -> 0.125 | Q14: 5736 | R14: 1 | S14: =N14*Q14 -> 717 | T14: Calculos vf.xlsx Hoja 'BOM y balanceo' R12
B15: 9 | C15: Batido | D15: Línea B | E15: Batidora planetaria | F15: Moretti Planeta 60 industrial | G15: 1 | H15: 2.5 | I15: 380 V | J15: Trifásica 50Hz | K15: =G15*H15 -> 2.5 | L15: 0.7 | M15: 1 | N15: =K15*L15*M15 -> 1.75 | O15: 0.85 | P15: =N15/O15 -> 2.0588235 | Q15: 5736 | R15: 0.72 | S15: =N15*Q15 -> 10038 | T15: Calculos vf.xlsx Hoja 'BOM y balanceo' R13
B16: 10 | C16: Dosificado | D16: Línea B | E16: Dosificadora de tolva | F16: Indurpack G1WGD-1000 neumática/eléc | G16: 1 | H16: 0.1 | I16: 220 V | J16: Monofásica 50Hz | K16: =G16*H16 -> 0.1 | L16: 0.6 | M16: 1 | N16: =K16*L16*M16 -> 0.06 | O16: 1 | P16: =N16/O16 -> 0.06 | Q16: 5736 | R16: 0.69 | S16: =N16*Q16 -> 344.16 | T16: Calculos vf.xlsx Hoja 'BOM y balanceo' R14
B17: 11 | C17: Fermentación | D17: Línea B | E17: Cámara fermentadora | F17: Nick Tech CF-240 calor/humedad | G17: 1 | H17: 1.8 | I17: 220 V | J17: Monofásica 50Hz | K17: =G17*H17 -> 1.8 | L17: 0.65 | M17: 1 | N17: =K17*L17*M17 -> 1.17 | O17: 0.9 | P17: =N17/O17 -> 1.3 | Q17: 5736 | R17: 0.68 | S17: =N17*Q17 -> 6711.12 | T17: Calculos vf.xlsx Hoja 'BOM y balanceo' R15
B18: 12 | C18: Horneado | D18: Línea B | E18: Horno rotativo a gas | F18: Pauna SIGMA rotativo carro (Horno 1) | G18: 1 | H18: 1.84 | I18: 380 V | J18: Trifásica 50Hz | K18: =G18*H18 -> 1.84 | L18: 0.75 | M18: 1 | N18: =K18*L18*M18 -> 1.38 | O18: 0.85 | P18: =N18/O18 -> 1.6235294 | Q18: 5736 | R18: 0.85 | S18: =N18*Q18 -> 7915.68 | T18: Calculos vf.xlsx Hoja 'BOM y balanceo' R16
B19: 13 | C19: Horneado | D19: Línea B | E19: Horno rotativo a gas | F19: Pauna SIGMA rotativo carro (Horno 2) | G19: 1 | H19: 1.84 | I19: 380 V | J19: Trifásica 50Hz | K19: =G19*H19 -> 1.84 | L19: 0.75 | M19: 1 | N19: =K19*L19*M19 -> 1.38 | O19: 0.85 | P19: =N19/O19 -> 1.6235294 | Q19: 5736 | R19: 0.85 | S19: =N19*Q19 -> 7915.68 | T19: Calculos vf.xlsx Hoja 'BOM y balanceo' R16
C20: Enfriado | D20: Línea B | E20: Equipo aire acondicionado | F20: Split de conductos Cardiff Inverter 36H | G20: 1 | H20: 3.5 | I20: 220 V | J20: Monofásica 50Hz | K20: 3.5 | L20: 0.75 | M20: 1 | N20: =K20*L20*M20 -> 2.625 | O20: 0.95 | P20: =N20/O20 -> 2.7631579 | Q20: 5736 | R20: 1 | S20: =N20*Q20 -> 15057
C21: Enfriado | D21: Línea B | E21: Equipo aire acondicionado | F21: Split de conductos Cardiff Inverter 36H | G21: 1 | H21: 3.5 | I21: 220 V | J21: Monofásica 50Hz | K21: 3.5 | L21: 0.75 | M21: 1 | N21: =K21*L21*M21 -> 2.625 | O21: 0.95 | P21: =N21/O21 -> 2.7631579 | Q21: 5736 | R21: 1 | S21: =N21*Q21 -> 15057
B22: 14 | C22: Desmolde/Corte | D22: Línea B | E22: Cortadora / Rebanadora | F22: Braesi FB-12 rebanadora industrial | G22: 1 | H22: 0.5 | I22: 220 V | J22: Monofásica 50Hz | K22: =G22*H22 -> 0.5 | L22: 0.4 | M22: 0.6 | N22: =K22*L22*M22 -> 0.12 | O22: 0.85 | P22: =N22/O22 -> 0.14117647 | Q22: 5736 | R22: 0.41 | S22: =N22*Q22 -> 688.32 | T22: Calculos vf.xlsx Hoja 'BOM y balanceo' R18
B23: 15 | C23: Envasado | D23: Línea B | E23: Envasadora Flowpack | F23: Brunetti EFH700X servocontrolada | G23: 1 | H23: 3.6 | I23: 380 V | J23: Trifásica 50Hz | K23: =G23*H23 -> 3.6 | L23: 0.7 | M23: 0.85 | N23: =K23*L23*M23 -> 2.142 | O23: 0.9 | P23: =N23/O23 -> 2.38 | Q23: 5736 | R23: 0.41 | S23: =N23*Q23 -> 12286.512 | T23: Calculos vf.xlsx Hoja 'BOM y balanceo' R19
B24: SUBTOTAL LÍNEA B (PANIFICADOS) | G24: =SUM(G14:G23) -> 10 | K24: =SUM(K14:K23) -> 19.43 | N24: =SUM(N14:N23) -> 13.377 | P24: =SUM(P14:P23) -> 14.838375 | S24: =SUM(S14:S23) -> 76730.472
B25: SERVICIOS AUXILIARES, ILUMINACIÓN GENERAL E INSTALACIONES
B26: 16 | C26: Servicios | D26: Auxiliares | E26: Compresor tornillo aire | F26: Atlas Copco G2 FF | G26: 1 | H26: 2.2 | I26: 380 V | J26: Trifásica 50Hz | K26: =G26*H26 -> 2.2 | L26: 0.65 | M26: 0.7 | N26: =K26*L26*M26 -> 1.001 | O26: 0.85 | P26: =N26/O26 -> 1.1776471 | Q26: 5736 | S26: =N26*Q26 -> 5741.736 | T26: Hoja '4. Aire Comprimido'
B27: 17 | C27: Servicios | D27: Auxiliares | E27: Secador frigorífico aire | F27: Schulz ADS 20 (+3°C rocío) | G27: 1 | H27: 0.45 | I27: 220 V | J27: Monofásica 50Hz | K27: =G27*H27 -> 0.45 | L27: 0.7 | M27: 0.8 | N27: =K27*L27*M27 -> 0.252 | O27: 0.85 | P27: =N27/O27 -> 0.29647059 | Q27: 5736 | S27: =N27*Q27 -> 1445.472 | T27: Hoja '4. Aire Comprimido'
B28: 18 | C28: Almacén | D28: Auxiliares | E28: Cargador autoelevador | F28: HELI Cargador batería Litio 80V | G28: 1 | H28: 7.5 | I28: 380 V | J28: Trifásica 50Hz | K28: =G28*H28 -> 7.5 | L28: 0.6 | M28: 0.5 | N28: =K28*L28*M28 -> 2.25 | O28: 1 | P28: =N28/O28 -> 2.25 | Q28: 2000 | S28: =N28*Q28 -> 4500 | T28: Calculos vf.xlsx Hoja 'Inversiones' R4
B29: 19 | C29: Servicios | D29: Auxiliares | E29: Bombas presurizadoras agua | F29: Rowa / Motorarg 2 HP (1 activa + 1 res) | G29: 1 | H29: 1.5 | I29: 380 V | J29: Trifásica 50Hz | K29: =G29*H29 -> 1.5 | L29: 0.5 | M29: 0.6 | N29: =K29*L29*M29 -> 0.45 | O29: 0.85 | P29: =N29/O29 -> 0.52941176 | Q29: 5736 | S29: =N29*Q29 -> 2581.2 | T29: Hoja '5. Agua y Saneamiento'
B30: 20 | C30: Administración | D30: Auxiliares | E30: Climatización Oficinas | F30: Split Inverter Frío/Calor 4500 fg | G30: 1 | H30: 1.6 | I30: 220 V | J30: Monofásica 50Hz | K30: =G30*H30 -> 1.6 | L30: 0.4 | M30: 0.6 | N30: =K30*L30*M30 -> 0.384 | O30: 0.95 | P30: =N30/O30 -> 0.40421053 | Q30: 2500 | S30: =N30*Q30 -> 960 | T30: Confort térmico oficinas 60m²
B31: 21 | C31: Calidad | D31: Auxiliares | E31: Climatización Laboratorios | F31: Split Inverter Frío/Calor 3000 fg | G31: 1 | H31: 1.1 | I31: 220 V | J31: Monofásica 50Hz | K31: =G31*H31 -> 1.1 | L31: 0.5 | M31: 0.7 | N31: =K31*L31*M31 -> 0.385 | O31: 0.95 | P31: =N31/O31 -> 0.40526316 | Q31: 5736 | S31: =N31*Q31 -> 2208.36 | T31: Laboratorio calidad crudo/cocido
B32: 22 | C32: Administración | D32: Auxiliares | E32: Equipos Informática y Red | F32: 8 PC + Servidor + Impresora | G32: 1 | H32: 2.5 | I32: 220 V | J32: Monofásica 50Hz | K32: =G32*H32 -> 2.5 | L32: 0.6 | M32: 0.7 | N32: =K32*L32*M32 -> 1.05 | O32: 0.95 | P32: =N32/O32 -> 1.1052632 | Q32: 2500 | S32: =N32*Q32 -> 2625 | T32: Calculos vf.xlsx Hoja 'Inversiones' R10
B33: 23 | C33: Iluminación | D33: Planta | E33: Sistema Iluminación LED | F33: Luminarias nave, depósitos y oficinas | G33: 1 | H33: ='2. Luminarias y Lux'!U30 -> 4.148 | I33: 220 V | J33: Monofásica 50Hz | K33: =G33*H33 -> 4.148 | L33: 1 | M33: 1 | N33: =K33*L33*M33 -> 4.148 | O33: 0.95 | P33: =N33/O33 -> 4.3663158 | Q33: 5736 | S33: =N33*Q33 -> 23792.928 | T33: Hoja '2. Luminarias y Lux'
B34: SUBTOTAL SERVICIOS AUXILIARES E INSTALACIONES | G34: =SUM(G26:G33) -> 8 | K34: =SUM(K26:K33) -> 20.998 | N34: =SUM(N26:N33) -> 9.92 | P34: =SUM(P26:P33) -> 10.534582 | S34: =SUM(S26:S33) -> 43854.696
B35: TOTAL GENERAL PLANTA INDUSTRIAL CELI S.A. | G35: =G12+G24+G34 -> 23 | K35: =K12+K24+K34 -> 77.828 | N35: =N12+N24+N34 -> 49.727 | P35: =P12+P24+P34 -> 56.467074 | S35: =S12+S24+S34 -> 231350.2
B37: PARÁMETROS ELÉCTRICOS DE DISEÑO Y DIMENSIONAMIENTO DE ACOMETIDA
B38: Potencia Total Demandada activa (P_dem_act): | C38: =N35 -> 49.727 | D38: kW
B39: Factor de Potencia de Planta adoptado (cos φ): | C39: =C38/C40 -> 0.88063709 | D39: -
B40: Potencia Aparente máxima Demandada (S_inst): | C40: =P35 -> 56.467074 | D40: kVA
B41: Potencia total instalada (Pot_inst) | C41: =K35 -> 77.828 | D41: kW
B42: Potencia Aparente instalada (S_inst): | C42: =C41/C39 -> 88.376927 | D42: kVA
B43: Capacidad de Transformador Industrial Recomendada: | C43: 100 | D43: kVA (Norma IRAM 2250)
...

Sheet 2. Luminarias y Lux
B2: PLANTA CELI S.A. - CÁLCULO LUMINOTÉCNICO Y CUMPLIMIENTO DECRETO 351/79
B3: Articulado con 'Iluminación + Matafuegos.xlsx' | Método del Flujo Luminoso para Niveles de Diseño y Protocolo Res. SRT 84/12
B5: ID | C5: Sector / Puesto | D5: Tipo de Área | E5: Largo a (m) | F5: Ancho b (m) | G5: Alto H (m) | H5: Superficie S (m²) | I5: Índice Local (IL) | J5: Puntos Med. (Res. SRT 84/12) | K5: Lux Mín. Dto. 351/79 | L5: Nivel Diseño Adoptado (lx) | M5: Coef. Utiliz. (μ) | N5: Factor Mant. (fm) | O5: Flujo Total Req. (lm) | P5: Artefacto Seleccionado | Q5: Pot. Unit. (W) | R5: Flujo Lámpara (lm) | S5: Cant. Calc. | T5: Cant. Adop. | U5: Pot. Total (kW) | V5: Hs Encendido/Año | W5: Consumo Anual (kWh/año) | X5: Nivel Medio Logrado (lx) | Y5: Cumplimiento Normativo
B6: 1 | C6: Deposito MP | D6: Almacén Materias Primas | E6: 8.3 | F6: 6.3 | G6: 6.5 | H6: =E6*F6 -> 52.29 | I6: =(E6*F6)/(G6*(E6+F6)) -> 0.55100105 | J6: =(I6+2)^2 -> 6.5076064 | K6: 100 | L6: 200 | M6: 0.65 | N6: 0.8 | O6: =(L6*H6)/(M6*N6) -> 20111.538 | P6: Campana LED High Bay IP65 100W | Q6: 100 | R6: 13500 | S6: =O6/R6 -> 1.4897436 | T6: =ROUNDUP(S6,0) -> 2 | U6: =T6*Q6/1000 -> 0.2 | V6: 5712 | W6: =U6*V6 -> 1142.4 | X6: =(T6*R6*M6*N6)/H6 -> 268.50258 | Y6: =IF(X6>=K6,"CUMPLE DTO 351/79","NO CUMPLE") -> CUMPLE DTO 351/79
B7: 2 | C7: Aduana MP (recepcion y control) | D7: Control y Desinfección | E7: 3.8 | F7: 3.8 | G7: 6.5 | H7: =E7*F7 -> 14.44 | I7: =(E7*F7)/(G7*(E7+F7)) -> 0.29230769 | J7: =(I7+2)^2 -> 5.2546746 | K7: 300 | L7: 500 | M7: 0.6 | N7: 0.8 | O7: =(L7*H7)/(M7*N7) -> 15041.667 | P7: Artefacto Lineal Estanco LED 2x18W | Q7: 36 | R7: 3600 | S7: =O7/R7 -> 4.1782407 | T7: =ROUNDUP(S7,0) -> 5 | U7: =T7*Q7/1000 -> 0.18 | V7: 5712 | W7: =U7*V7 -> 1028.16 | X7: =(T7*R7*M7*N7)/H7 -> 598.33795 | Y7: =IF(X7>=K7,"CUMPLE DTO 351/79","NO CUMPLE") -> CUMPLE DTO 351/79
B8: 3 | C8: Seccion Pesado (macro y micro) | D8: Pesaje y Fraccionamiento | E8: 2 | F8: 3.8 | G8: 6.5 | H8: =E8*F8 -> 7.6 | I8: =(E8*F8)/(G8*(E8+F8)) -> 0.20159151 | J8: =(I8+2)^2 -> 4.8470052 | K8: 400 | L8: 500 | M8: 0.6 | N8: 0.8 | O8: =(L8*H8)/(M8*N8) -> 7916.6667 | P8: Artefacto Lineal Estanco LED 2x18W | Q8: 36 | R8: 3600 | S8: =O8/R8 -> 2.1990741 | T8: =ROUNDUP(S8,0) -> 3 | U8: =T8*Q8/1000 -> 0.108 | V8: 5712 | W8: =U8*V8 -> 616.896 | X8: =(T8*R8*M8*N8)/H8 -> 682.10526 | Y8: =IF(X8>=K8,"CUMPLE DTO 351/79","NO CUMPLE") -> CUMPLE DTO 351/79
B9: 4 | C9: Amasado | D9: Elaboración Galletitas | E9: 2.4 | F9: 2.2 | G9: 6.5 | H9: =E9*F9 -> 5.28 | I9: =(E9*F9)/(G9*(E9+F9)) -> 0.17658863 | J9: =(I9+2)^2 -> 4.7375381 | K9: 200 | L9: 300 | M9: 0.6 | N9: 0.8 | O9: =(L9*H9)/(M9*N9) -> 3300 | P9: Artefacto Lineal Estanco LED 2x18W | Q9: 36 | R9: 3600 | S9: =O9/R9 -> 0.91666667 | T9: =ROUNDUP(S9,0) -> 1 | U9: =T9*Q9/1000 -> 0.036 | V9: 5712 | W9: =U9*V9 -> 205.632 | X9: =(T9*R9*M9*N9)/H9 -> 327.27273 | Y9: =IF(X9>=K9,"CUMPLE DTO 351/79","NO CUMPLE") -> CUMPLE DTO 351/79
B10: 5 | C10: Moldeado | D10: Moldeo y Formado | E10: 2.5 | F10: 2.3 | G10: 6.5 | H10: =E10*F10 -> 5.75 | I10: =(E10*F10)/(G10*(E10+F10)) -> 0.18429487 | J10: =(I10+2)^2 -> 4.7711441 | K10: 400 | L10: 500 | M10: 0.6 | N10: 0.8 | O10: =(L10*H10)/(M10*N10) -> 5989.5833 | P10: Artefacto Lineal Estanco LED 2x18W | Q10: 36 | R10: 3600 | S10: =O10/R10 -> 1.6637731 | T10: =ROUNDUP(S10,0) -> 2 | U10: =T10*Q10/1000 -> 0.072 | V10: 5712 | W10: =U10*V10 -> 411.264 | X10: =(T10*R10*M10*N10)/H10 -> 601.04348 | Y10: =IF(X10>=K10,"CUMPLE DTO 351/79","NO CUMPLE") -> CUMPLE DTO 351/79
B11: 6 | C11: Horno Tunel | D11: Horneado Continuo Galletitas | E11: 8.6 | F11: 2.3 | G11: 6.5 | H11: =E11*F11 -> 19.78 | I11: =(E11*F11)/(G11*(E11+F11)) -> 0.27918137 | J11: =(I11+2)^2 -> 5.1946677 | K11: 300 | L11: 500 | M11: 0.6 | N11: 0.8 | O11: =(L11*H11)/(M11*N11) -> 20604.167 | P11: Campana LED High Bay IP65 100W | Q11: 100 | R11: 13500 | S11: =O11/R11 -> 1.5262346 | T11: =ROUNDUP(S11,0) -> 2 | U11: =T11*Q11/1000 -> 0.2 | V11: 5712 | W11: =U11*V11 -> 1142.4 | X11: =(T11*R11*M11*N11)/H11 -> 655.20728 | Y11: =IF(X11>=K11,"CUMPLE DTO 351/79","NO CUMPLE") -> CUMPLE DTO 351/79
B12: 7 | C12: Cinta Enfriado | D12: Enfriamiento Galletitas | E12: 7 | F12: 1.2 | G12: 6.5 | H12: =E12*F12 -> 8.4 | I12: =(E12*F12)/(G12*(E12+F12)) -> 0.1575985 | J12: =(I12+2)^2 -> 4.6552313 | K12: 300 | L12: 750 | M12: 0.6 | N12: 0.8 | O12: =(L12*H12)/(M12*N12) -> 13125 | P12: Artefacto Lineal Estanco LED 2x18W | Q12: 36 | R12: 3600 | S12: =O12/R12 -> 3.6458333 | T12: =ROUNDUP(S12,0) -> 4 | U12: =T12*Q12/1000 -> 0.144 | V12: 5712 | W12: =U12*V12 -> 822.528 | X12: =(T12*R12*M12*N12)/H12 -> 822.85714 | Y12: =IF(X12>=K12,"CUMPLE DTO 351/79","NO CUMPLE") -> CUMPLE DTO 351/79
B13: 8 | C13: Envasado 1 | D13: Envasado Primario Galletitas | E13: 4.3 | F13: 4 | G13: 6.5 | H13: =E13*F13 -> 17.2 | I13: =(E13*F13)/(G13*(E13+F13)) -> 0.31881372 | J13: =(I13+2)^2 -> 5.3768971 | K13: 300 | L13: 500 | M13: 0.65 | N13: 0.8 | O13: =(L13*H13)/(M13*N13) -> 16538.462 | P13: Artefacto Lineal Estanco LED 2x18W | Q13: 36 | R13: 3600 | S13: =O13/R13 -> 4.5940171 | T13: =ROUNDUP(S13,0) -> 5 | U13: =T13*Q13/1000 -> 0.18 | V13: 5712 | W13: =U13*V13 -> 1028.16 | X13: =(T13*R13*M13*N13)/H13 -> 544.18605 | Y13: =IF(X13>=K13,"CUMPLE DTO 351/79","NO CUMPLE") -> CUMPLE DTO 351/79
B14: 9 | C14: Batido Panif. | D14: Batido de Masas Panificados | E14: 2.2 | F14: 1.6 | G14: 6.5 | H14: =E14*F14 -> 3.52 | I14: =(E14*F14)/(G14*(E14+F14)) -> 0.14251012 | J14: =(I14+2)^2 -> 4.5903496 | K14: 400 | L14: 500 | M14: 0.6 | N14: 0.8 | O14: =(L14*H14)/(M14*N14) -> 3666.6667 | P14: Artefacto Lineal Estanco LED 2x18W | Q14: 36 | R14: 3600 | S14: =O14/R14 -> 1.0185185 | T14: =ROUNDUP(S14,0) -> 2 | U14: =T14*Q14/1000 -> 0.072 | V14: 5712 | W14: =U14*V14 -> 411.264 | X14: =(T14*R14*M14*N14)/H14 -> 981.81818 | Y14: =IF(X14>=K14,"CUMPLE DTO 351/79","NO CUMPLE") -> CUMPLE DTO 351/79
B15: 10 | C15: Dosificado | D15: Dosificación en Molde | E15: 2 | F15: 1.5 | G15: 6.5 | H15: =E15*F15 -> 3 | I15: =(E15*F15)/(G15*(E15+F15)) -> 0.13186813 | J15: =(I15+2)^2 -> 4.5448617 | K15: 400 | L15: 500 | M15: 0.6 | N15: 0.8 | O15: =(L15*H15)/(M15*N15) -> 3125 | P15: Artefacto Lineal Estanco LED 2x18W | Q15: 36 | R15: 3600 | S15: =O15/R15 -> 0.86805556 | T15: =ROUNDUP(S15,0) -> 1 | U15: =T15*Q15/1000 -> 0.036 | V15: 5712 | W15: =U15*V15 -> 205.632 | X15: =(T15*R15*M15*N15)/H15 -> 576 | Y15: =IF(X15>=K15,"CUMPLE DTO 351/79","NO CUMPLE") -> CUMPLE DTO 351/79
B16: 11 | C16: Fermentador | D16: Cámara Fermentación | E16: 1.5 | F16: 1.2 | G16: 6.5 | H16: =E16*F16 -> 1.8 | I16: =(E16*F16)/(G16*(E16+F16)) -> 0.1025641 | J16: =(I16+2)^2 -> 4.4207758 | K16: 100 | L16: 200 | M16: 0.6 | N16: 0.8 | O16: =(L16*H16)/(M16*N16) -> 750 | P16: Plafon Downlight LED IP44 18W | Q16: 18 | R16: 1600 | S16: =O16/R16 -> 0.46875 | T16: =ROUNDUP(S16,0) -> 1 | U16: =T16*Q16/1000 -> 0.018 | V16: 5712 | W16: =U16*V16 -> 102.816 | X16: =(T16*R16*M16*N16)/H16 -> 426.66667 | Y16: =IF(X16>=K16,"CUMPLE DTO 351/79","NO CUMPLE") -> CUMPLE DTO 351/79
B17: 12 | C17: Hornos Rotativos | D17: Horneado Panificados | E17: 5.2 | F17: 3.7 | G17: 6.5 | H17: =E17*F17 -> 19.24 | I17: =(E17*F17)/(G17*(E17+F17)) -> 0.33258427 | J17: =(I17+2)^2 -> 5.4409494 | K17: 300 | L17: 500 | M17: 0.65 | N17: 0.8 | O17: =(L17*H17)/(M17*N17) -> 18500 | P17: Campana LED High Bay IP65 100W | Q17: 100 | R17: 13500 | S17: =O17/R17 -> 1.3703704 | T17: =ROUNDUP(S17,0) -> 2 | U17: =T17*Q17/1000 -> 0.2 | V17: 5712 | W17: =U17*V17 -> 1142.4 | X17: =(T17*R17*M17*N17)/H17 -> 729.72973 | Y17: =IF(X17>=K17,"CUMPLE DTO 351/79","NO CUMPLE") -> CUMPLE DTO 351/79
... B29: 24 | C29: Circulaciones y Pasillos | D29: Circulación Interna | E29: 25 | F29: 2 | G29: 4 | H29: =E29*F29 -> 50 | I29: =(E29*F29)/(G29*(E29+F29)) -> 0.46296296 | J29: =(I29+2)^2 -> 6.0661866 | K29: 100 | L29: 150 | M29: 0.5 | N29: 0.8 | O29: =(L29*H29)/(M29*N29) -> 18750 | P29: Artefacto Lineal Estanco LED 1x18W | Q29: 18 | R29: 1800 | S29: =O29/R29 -> 10.416667 | T29: =ROUNDUP(S29,0) -> 11 | U29: =T29*Q29/1000 -> 0.198 | V29: 5712 | W29: =U29*V29 -> 1130.976 | X29: =(T29*R29*M29*N29)/H29 -> 158.4 | Y29: =IF(X29>=K29,"CUMPLE DTO 351/79","NO CUMPLE") -> CUMPLE DTO 351/79
B30: TOTALES SISTEMA DE ILUMINACIÓN PLANTA CELI | H30: =SUM(H6:H29) -> 607.29 | J30: =SUM(J6:J29) -> 140.84595 | O30: =SUM(O6:O29) -> 391057.21 | T30: =SUM(T6:T29) -> 93 | U30: =SUM(U6:U29) -> 4.148 | W30: =SUM(W6:W29) -> 20481.376 | Y30: 100% CUMPLE

Sheet 3. Instalación de Gas
B2: PLANTA CELI S.A. - RELEVAMIENTO DE GAS NATURAL DE RED Y CONSUMO TÉRMICO
B3: Gasoducto Industrial Parque Industrial Pilar | Distribuidora: Naturgy BAN S.A. | Norma NAG-200
B5: ID | C5: Equipo Consumidor | D5: Línea | E5: Ubicación | F5: Tipo Quemador | G5: Combustible | H5: Pot. Térmica (kcal/h) | I5: Pot. Térmica (kW) | J5: Rendimiento (η) | K5: P.C.S. (kcal/m³) | L5: Caudal Pico (m³/h) | M5: Hs Uso/Día | N5: Días/Año | O5: Consumo Anual (m³/año) | P5: Fuente / Referencia
B6: 1 | C6: Horno Túnel Continuo Polin | D6: Línea A Galletitas | E6: Nave Producción Sector [6] | F6: Atmosférico multigas con control mod. | G6: Gas Natural de Red | H6: 85000 | I6: =H6*0.001163 -> 98.855 | J6: 0.88 | K6: 9300 | L6: =H6/(K6*J6) -> 10.386119 | M6: 24 | N6: 239 | O6: =L6*M6*N6 -> 59574.78 | P6: Calculos vf.xlsx Hoja 'BOM y balanceo' R7
B7: 2 | C7: Horno Rotativo Pauna SIGMA (Horno 1) | D7: Línea B Panificados | E7: Nave Producción Sector [12] | F7: Quemador presurizado automático | G7: Gas Natural de Red | H7: 50000 | I7: =H7*0.001163 -> 58.15 | J7: 0.88 | K7: 9300 | L7: =H7/(K7*J7) -> 6.1094819 | M7: 24 | N7: 239 | O7: =L7*M7*N7 -> 35043.988 | P7: Calculos vf.xlsx Hoja 'BOM y balanceo' R16
B8: 3 | C8: Horno Rotativo Pauna SIGMA (Horno 2) | D8: Línea B Panificados | E8: Nave Producción Sector [12] | F8: Quemador presurizado automático | G8: Gas Natural de Red | H8: 50000 | I8: =H8*0.001163 -> 58.15 | J8: 0.88 | K8: 9300 | L8: =H8/(K8*J8) -> 6.1094819 | M8: 24 | N8: 239 | O8: =L8*M8*N8 -> 35043.988 | P8: Calculos vf.xlsx Hoja 'BOM y balanceo' R16
B9: TOTAL CONSUMO TÉRMICO Y GAS NATURAL | H9: =SUM(H6:H8) -> 185000 | I9: =SUM(I6:I8) -> 215.155 | L9: =SUM(L6:L8) -> 22.605083 | O9: =SUM(O6:O8) -> 129662.76
B11: PARÁMETROS DE DISEÑO DE LA INSTALACIÓN INTERNA DE GAS (NAG-200)
B12: Potencia Térmica Total Instalada: | C12: =H9 -> 185000 | D12: kcal/h
B13: Potencia Térmica Total en kW: | C13: =I9 -> 215.155 | D13: kW
B14: Poder Calorífico Superior del Gas (PCS): | C14: 9300 | D14: kcal/m³ (Naturgy BAN)
B15: Caudal Máximo Simultáneo de Diseño: | C15: =L9 -> 22.605083 | D15: m³/h
B16: Presión de Suministro en Red Externa (Media Presión): | C16: 1.5 | D16: bar (Red Industrial PIP)
B17: Presión de Trabajo en Quemadores Internos: | C17: 20 | D17: mbar (Baja Presión Regulada)
B18: Medidor de Gas Industrial Recomendado: | C18: Medidor rotativo G-25 (Capacidad: hasta 40 m³/h) | D18: -
B19: Diámetro Cañería Colectora Principal de Gas: | C19: 1.1/2" (Ø 40 mm) ASTM A-53 con revestimiento epoxi | D19: -

Sheet 4. Aire Comprimido
B2: PLANTA CELI S.A. - RELEVAMIENTO DE AIRE COMPRIMIDO INDUSTRIAL (ISO 8573-1)
B3: Central Compresora a Tornillo, Tratamiento Grado Alimenticio y Red Neumática de Planta
B5: ID | C5: Equipo Consumidor Neumático | D5: Línea / Proceso | E5: Sector | F5: Presión Trabajo (bar) | G5: Caudal Nom. (L/min) | H5: Caudal (m³/h) | I5: Ciclos/min | J5: Factor Simult. (Fs) | K5: Caudal Requerido (L/min) | L5: Caudal Requerido (m³/h) | M5: Tipo de Consumo / Aplicación
B6: 1 | C6: Dosificadora Indurpack G1WGD-1000 | D6: Línea B Panificados | E6: Dosificado Sector [10] | F6: 6 | G6: 140 | H6: =G6*0.06 -> 8.4 | I6: 30 | J6: 1 | K6: =G6*J6 -> 140 | L6: =K6*0.06 -> 8.4 | M6: Calculos vf.xlsx Hoja 'BOM y balanceo' R14. Cilindros neumáticos.
B7: SUBTOTAL CONSUMO NEUMÁTICO BASE | G7: =SUM(G6) -> 140 | H7: =SUM(H6) -> 8.4 | K7: =SUM(K6) -> 140 | L7: =SUM(L6) -> 8.4
B9: DIMENSIONAMIENTO DE LA CENTRAL COMPRESORA Y TRATAMIENTO DE AIRE
B10: Consumo Simultáneo Base de Equipos: | C10: =K7 -> 140 | D10: L/min
B11: Factor por Fugas en Red y Acoples (15%): | C11: =C10*0.15 -> 21 | D11: L/min
B12: Margen de Seguridad y Ampliación Futura (20%): | C12: =(C10+C11)*0.2 -> 32.2 | D12: L/min
B13: Caudal Total Requerido de Central Compresora: | C13: =C10+C11+C12 -> 193.2 | D13: L/min
B14: Caudal Requerido en m³/h: | C14: =C13*0.06 -> 11.592 | D14: m³/h
B15: Presión de Trabajo Efectiva de Red: | C15: 8 | D15: bar (Manométrica)
B16: Compresor Industrial Seleccionado: | C16: Atlas Copco G2 FF compresor de tornillo – 3 HP / 2,2 kW | D16: -
B17: Caudal Libre Entregado (FAD) del Compresor: | C17: 342 | D17: L/min a 8 bar (opera al 56,5% de factor de carga)
B18: Tanque Receptor: | C18: 200 | D18: Litros (integrado, provisional)
B19: Calidad de Aire Alimentario (Norma ISO 8573-1): | C19: Clase 1.4.1 (Filtro 0.01 µm + Secador frigorífico rocío +3°C) | D19: -

Sheet 5. Agua y Saneamiento
B2: PLANTA CELI S.A. - BALANCE HÍDRICO, AGUA DE PROCESO Y SANEAMIENTO
B3: Consumo de Receta (BOM), Limpieza BPM Libre de Gluten, Dotación Sanitaria y Cisterna
B4: 1. CONSUMO DE AGUA DE PROCESO COMO MATERIA PRIMA (RECETA BOM)
B5: Línea de Producto | C5: Producción Anual (kg) | D5: Agua en Receta (%) | E5: Agua Requerida (kg/año) | F5: Agua Requerida (m³/año) | G5: Fuente
B6: Pan de Molde Blanco Sin TACC | C6: 117855.9 | D6: 0.38 | E6: =C6*D6 -> 44785.242 | F6: =E6/1000 -> 44.785242 | G6: Calculos vf.xlsx Hoja 'Produccion' R50 (Año 10) y 'BOM' (38% agua receta)
B7: Budines Tradicionales Sin TACC | C7: 141427.2 | D7: 0.11 | E7: =C7*D7 -> 15556.992 | F7: =E7/1000 -> 15.556992 | G7: Calculos vf.xlsx Hoja 'Produccion' R51 (Año 10) y 'BOM' (11% agua receta)
B8: Budines Frutos Secos / Free Sin TACC | C8: 60611.6 | D8: 0.1 | E8: =C8*D8 -> 6061.16 | F8: =E8/1000 -> 6.06116 | G8: Calculos vf.xlsx Hoja 'Produccion' R52 (Año 10) y 'BOM' (10% agua receta)
B9: Galletitas Dulces y Saladas Sin TACC | C9: 358619.2 | D9: 0.07 | E9: =C9*D9 -> 25103.344 | F9: =E9/1000 -> 25.103344 | G9: Calculos vf.xlsx Hoja 'Produccion' R42:R49 (Año 10) y 'BOM' (7% agua receta)
B10: SUBTOTAL AGUA DE PROCESO (RECETA) | C10: =SUM(C6:C9) -> 678513.9 | E10: =SUM(E6:E9) -> 91506.738 | F10: =SUM(F6:F9) -> 91.506738 | G10: Consumo directo en mezclado y amasado
B12: 2. BALANCE TOTAL DE AGUA DIARIO Y ANUAL DE PLANTA (PROCESO + BPM + SANITARIO)
B13: Destino / Uso del Agua | C13: Criterio Técnico / Base de Cálculo | D13: Dotación Unitaria | E13: Unidades | F13: Consumo Diario (L/día) | G13: Consumo Diario (m³/día) | H13: Consumo Anual (m³/año)
B14: Agua de Proceso en Recetas | C14: Promedio diario sobre 239 días de producción activa | D14: =F10*1000/239 -> 382.87338 | E14: L/día | F14: =D14 -> 382.87338 | G14: =F14/1000 -> 0.38287338 | H14: =G14*238 -> 91.123865
B15: Limpieza y Sanitización BPM Sin TACC | C15: Lavado CIP de tolvas, líneas, carros, bandejas y pisos | D15: 1800 | E15: L/día | F15: =D15 -> 1800 | G15: =F15/1000 -> 1.8 | H15: =G15*238 -> 428.4
B16: Consumo Sanitario del Personal | C16: Dotación reglamentaria OSN / Dto. 351/79: 45 L/persona-día | D16: 45 | E16: 55 personas | F16: =D16*55 -> 2475 | G16: =F16/1000 -> 2.475 | H16: =G16*238 -> 589.05
B17: Servicios Auxiliares y Mantenimiento | C17: Riego, purgas y limpieza externa | D17: 475 | E17: L/día | F17: =D17 -> 475 | G17: =F17/1000 -> 0.475 | H17: =G17*238 -> 113.05
B18: TOTAL CONSUMO MEDIO DE AGUA PLANTA CELI S.A. | F18: =SUM(F14:F17) -> 5132.8734 | G18: =SUM(G14:G17) -> 5.1328734 | H18: =SUM(H14:H17) -> 1221.6239
B20: DIMENSIONAMIENTO DE RESERVA HÍDRICA Y CISTERNA DE PLANTA
B21: Consumo Diario Medio de Planta: | C21: =G18 -> 5.1328734 | D21: m³/día
B22: Días de Autonomía de Consumo Requeridos: | C22: 2 | D22: Días de producción continua
B23: Reserva Técnica de Proceso y Sanitaria: | C23: =C21*C22 -> 10.265747 | D23: m³ (10.000 Litros)
B24: Reserva Técnica Contra Incendio Reglamentaria (Dec. 351/79): | C24: 30 | D24: m³ (2 hidrantes x 250 L/min x 60 min)
B25: Capacidad Total Recomendada de Cisterna Unificada: | C25: =C23+C24 -> 40.265747 | D25: m³ (40.000 Litros)
B26: Sistema de Bombeo Presurizado: | C26: 2 electrobombas centrífugas 2 HP (1 activa + 1 reserva) | D26: -
B27: Tratamiento de Agua de Red Requerido: | C27: Filtro de sedimentos 5 µm + Carbón activado + Cloración en línea | D27: -

Sheet 6. Costos Tarifarios
B2: PLANTA CELI S.A. - CUADROS TARIFARIOS Y COSTOS DE SERVICIOS INDUSTRIALES
B3: Tarifas Vigentes en Parque Industrial Pilar (EDENOR T3 MT y Naturgy BAN SGP3) | Enlaces Oficiales ENRE y ENARGAS
B5: 1. ENERGÍA ELÉCTRICA - EDENOR S.A. (TARIFA T3 GRAN DEMANDA - MEDIA TENSIÓN)
B6: Marco Regulatorio: ENRE (Resoluciones Cuadros Tarifarios Edenor) | Enlace Oficial: https://www.argentina.gob.ar/enre/tarifas/cuadros-tarifarios-edenor
B7: Concepto de Facturación | C7: Unidad | D7: Tarifa Unitaria ($) | E7: Consumo Base Mensual | F7: Costo Mensual ($) | G7: Costo Anual ($) | H7: Observaciones y Fuente
B8: Cargo Fijo Mensual | C8: $/mes | D8: 189126.46 | E8: 1 | F8: =D8*E8 -> 189126.46 | G8: =F8*12 -> 2269517.5 | H8: Cargo fijo comercial reglamentario ENRE T3 MT
B9: Cargo por Potencia Contratada | C9: $/kW-mes | D9: 9425.5 | E9: ='1. Potencia Eléctrica'!N35 -> 49.727 | F9: =D9*E9 -> 468701.84 | G9: =F9*12 -> 5624422.1 | H9: Facturación sobre Potencia Demandada Máxima (65,4 kW)
B10: Cargo por Potencia Adquirida | C10: $/kW-mes | D10: 11315.8 | E10: ='1. Potencia Eléctrica'!N35 -> 49.727 | F10: =D10*E10 -> 562700.79 | G10: =F10*12 -> 6752409.4 | H10: Cargo por capacidad de transporte y compra en MEM
B11: Energía Activa - Horas Pico (18:00 a 23:00) | C11: $/kWh | D11: 137.769 | E11: =('1. Potencia Eléctrica'!S35/12)*0.35 -> 6747.714 | F11: =D11*E11 -> 929625.82 | G11: =F11*12 -> 11155510 | H11: 35% del consumo en banda pico (alta exigencia del sistema)
B12: Energía Activa - Horas Resto (05:00 a 18:00) | C12: $/kWh | D12: 133.55 | E12: =('1. Potencia Eléctrica'!S35/12)*0.45 -> 8675.6323 | F12: =D12*E12 -> 1158630.7 | G12: =F12*12 -> 13903568 | H12: 45% del consumo en banda resto (jornada diurna continua)
B13: Energía Activa - Horas Valle (23:00 a 05:00) | C13: $/kWh | D13: 132.55 | E13: =('1. Potencia Eléctrica'!S35/12)*0.2 -> 3855.8366 | F13: =D13*E13 -> 511091.14 | G13: =F13*12 -> 6133093.7 | H13: 20% del consumo en banda valle nocturna (tarifa reducida)
B14: SUBTOTAL SERVICIO ELÉCTRICO EDENOR S.A. | F14: =SUM(F8:F13) -> 3819876.7 | G14: =SUM(G8:G13) -> 45838521 | H14: Factura eléctrica mensual media estimada (sin impuestos)
B16: 2. GAS NATURAL DE RED - NATURGY BAN S.A. (TARIFA SGP3 INDUSTRIAL)
B17: Marco Regulatorio: ENARGAS (Cuadros Tarifarios Distribución) | Enlace Oficial: https://www.enargas.gob.ar/secciones/tarifas/cuadros-tarifarios.php
B18: Concepto de Facturación | C18: Unidad | D18: Tarifa Unitaria ($) | E18: Consumo Base Mensual | F18: Costo Mensual ($) | G18: Costo Anual ($) | H18: Observaciones y Fuente
B19: Cargo Fijo Mensual Comercial | C19: $/mes | D19: 77664.89 | E19: 1 | F19: =D19*E19 -> 77664.89 | G19: =F19*12 -> 931978.68 | H19: Cargo fijo reglamentario ENARGAS para usuarios SGP3
B20: Cargo por m³ Consumido | C20: $/m³ | D20: 313.27 | E20: ='3. Instalación de Gas'!O9/12 -> 10805.23 | F20: =D20*E20 -> 3384954.3 | G20: =F20*12 -> 40619452 | H20: Caudal mensual medio de hornos (7.515 m³/mes)
B21: SUBTOTAL SERVICIO GAS NATURGY BAN | F21: =SUM(F19:F20) -> 3462619.2 | G21: =SUM(G19:G20) -> 41551430 | H21: Factura mensual media de gas natural estimada
B23: 3. PROVISIÓN DE AGUA Y SERVICIOS SANITARIOS - PARQUE INDUSTRIAL PILAR
B24: Proveedor: Consorcio Parque Industrial Pilar
B25: Concepto de Facturación | C25: Unidad | D25: Tarifa Unitaria ($) | E25: Consumo Base Mensual | F25: Costo Mensual ($) | G25: Costo Anual ($) | H25: Observaciones y Fuente
B26: Abono Red de Agua Industrial y Control Hídrico | C26: $/mes | D26: 450000 | E26: 1 | F26: =D26*E26 -> 450000 | G26: =F26*12 -> 5400000 | H26: Canon mensual red PIP, cloración y controles bacteriológicos
B27: SUBTOTAL PROVISIÓN DE AGUA Y SANEAMIENTO | F27: =F26 -> 450000 | G27: =G26 -> 5400000 | H27: Costo mensual de provisión hídrica y control sanitario
B29: 4. RESUMEN CONSOLIDADO DE COSTOS DE SERVICIOS E INSTALACIONES
B30: Servicio / Suministro | C30: Proveedor / Ente Regulador | D30: Enlace Oficial Web | E30: Costo Mensual ($) | F30: % Costo Mensual | G30: Costo Anual ($) | H30: % Costo Anual | I30: Impacto Operativo
B31: Energía Eléctrica (Fuerza Motriz + Iluminación + Auxiliares) | C31: EDENOR S.A. / ENRE | D31: https://www.argentina.gob.ar/enre/cuadros_tarifarios | E31: =F14 -> 3819876.7 | F31: =E31/$E$34 -> 0.49400307 | G31: =G14 -> 45838521 | H31: =G31/$G$34 -> 0.49400307 | I31: Costo Operativo Directo/Indirecto
B32: Gas Natural de Red (Hornos Túnel y Rotativos) | C32: Naturgy BAN S.A. / ENARGAS | D32: https://wss.enargas.gov.ar:9092/service.asmx/ObtenerArchivo?Tipo=13&Numero=0539&Ano=2026 | E32: =F21 -> 3462619.2 | F32: =E32/$E$34 -> 0.44780097 | G32: =G21 -> 41551430 | H32: =G32/$G$34 -> 0.44780097 | I32: Costo Operativo de Horneado
B33: Provisión de Agua y Mantenimiento Hídrico | C33: Consorcio Parque Industrial Pilar | E33: =F27 -> 450000 | F33: =E33/$E$34 -> 0.058195957 | G33: =G27 -> 5400000 | H33: =G33/$G$34 -> 0.058195957 | I33: Costo Operativo Sanitario/BPM
B34: TOTAL PRESUPUESTO ANUAL DE SERVICIOS E INSTALACIONES | E34: =SUM(E31:E33) -> 7732495.9 | F34: =SUM(F31:F33) -> 1 | G34: =SUM(G31:G33) -> 92789951 | H34: =SUM(H31:H33) -> 1 | I34: Costo consolidado para Hoja 'Costos' y Flujo
