Workbook

Sheet Demanda
F2: Estimación anual de la demanda
F4: Población | H4: Cuantifiación
F5: Población total Arg | H5: 46000000
F6: % Celíacos | H6: 0.01
F7: Subpoblación celíacos | H7: =H6*H5 -> 460000
F8: Factor conviviente - demanda periférica | H8: =1.6 -> 1.6
F9: Mercado potencial | H9: =H8*H7 -> 736000
F10: % Habitantes grandes aglomerados | H10: 0.453
F11: Mercado objetivo - AMBA | H11: =H10*H9 -> 333408
F13: Consumo teórico anual por persona (según INDEC)
F14: Producto | H14: Consumo
F15: Panificados | H15: =1.2*12 -> 14.4 | I15: kg
F16: Galletitas saladas | H16: 5.04 | I16: kg
F17: Galletitas dulces | H17: 2.52 | I17: kg
F18: Total | H18: =SUM(H15:H17) -> 21.96 | I18: kg
F20: Consumo anual mercado objetivo | O20: Consumo anual mercado objetivo
F21: Producto | H21: Consumo | J21: Ventas anuales | L21: % Mkt Share | O21: Producto | Q21: Consumo | S21: Ventas anuales | U21: % Mkt Share
F22: Panificados | H22: =H15*$H$11 -> 4801075.2 | I22: kg | J22: =SUM(Produccion!E22:E24) -> 163800 | K22: kg | L22: =J22/H22*100 -> 3.4117358 | M22: % | O22: Panificados | Q22: =H22/1000 -> 4801.0752 | R22: Tn | S22: =J22/1000 -> 163.8 | T22: Tn | U22: =S22/Q22*100 -> 3.4117358 | V22: %
F23: Galletitas saladas | H23: =H16*$H$11 -> 1680376.3 | I23: kg | J23: =SUM(Produccion!E18) -> 4680 | K23: kg | L23: =J23/H23*100 -> 0.27850904 | M23: % | O23: Galletitas saladas | Q23: =H23/1000 -> 1680.3763 | R23: Tn | S23: =J23/1000 -> 4.68 | T23: Tn | U23: =S23/Q23*100 -> 0.27850904 | V23: %
F24: Galletitas dulces | H24: =H17*$H$11 -> 840188.16 | I24: kg | J24: =Produccion!E14+Produccion!E15+Produccion!E17+Produccion!E20 -> 150165 | K24: kg | L24: =J24/H24*100 -> 17.872782 | M24: % | O24: Galletitas dulces | Q24: =H24/1000 -> 840.18816 | R24: Tn | S24: =J24/1000 -> 150.165 | T24: Tn | U24: =S24/Q24*100 -> 17.872782 | V24: %
F25: Total | H25: =SUM(H22:H24) -> 7321639.7 | I25: kg | J25: =SUM(J22:J24) -> 318645 | K25: kg | L25: =J25/H25*100 -> 4.3520989 | M25: % | O25: Total | Q25: =SUM(Q22:Q24) -> 7321.6397 | R25: Tn | S25: =SUM(S22:S24) -> 318.645 | T25: Tn | U25: =S25/Q25*100 -> 4.3520989 | V25: %
F28: Ventas SMAMS 2025 [kg] | H28: 1462828.9
F29: %Mkt share de SMAMS | H29: =H28/H25 -> 0.19979526
F31: Ventas anuales nuestro proyecto [kg] | H31: =Produccion!E25 -> 385950
F32: %Mkt share de nuestro proyecto | H32: =H31/H25 -> 0.052713602

Sheet Produccion
D2: Produccion | H2: Personal | J2: Producción por turno y eficiencia | O2: Escala de producción
D3: Producto | E3: Linea | F3: Turnos | G3: Horario | H3: RH/turno | I3: RH | J3: Cajas/turno | K3: Cajas/h | L3: kg/caja | M3: kg/turno | N3: kg/h | O3: kg/dia | P3: kg/año | Q3: Tn/año | R3: $/kg | S3: FC ($M)
D4: Pepas | E4: A | F4: 2 | G4: M, T | H4: 9 | I4: =F4*H4 -> 18 | J4: 900 | K4: =J4/8 -> 112.5 | L4: 2.7 | M4: =J4*L4 -> 2430 | N4: =M4/8 -> 303.75 | O4: =M4*F4 -> 4860 | P4: =O4*24*12 -> 1399680 | Q4: =P4/1000 -> 1399.68 | R4: 10000 | S4: =P4*R4/1000000 -> 13996.8
D5: Polvorones | E5: A | F5: 1 | G5: N | H5: 6 | I5: =F5*H5 -> 6 | J5: 500 | K5: =J5/8 -> 62.5 | L5: 2.7 | M5: =J5*L5 -> 1350 | N5: =M5/8 -> 168.75 | O5: =M5*F5 -> 1350 | P5: =O5*24*12 -> 388800 | Q5: =P5/1000 -> 388.8 | R5: 10000 | S5: =P5*R5/1000000 -> 3888
D6: Budines | E6: B | F6: 1 | G6: M, T | H6: 8 | I6: =F6*H6 -> 8 | J6: 350 | K6: =J6/8 -> 43.75 | L6: 3 | M6: =J6*L6 -> 1050 | N6: =M6/8 -> 131.25 | O6: =M6*F6 -> 1050 | P6: =O6*24*12 -> 302400 | Q6: =P6/1000 -> 302.4 | R6: 15000 | S6: =P6*R6/1000000 -> 4536
D7: Total | F7: =AVERAGE(F4:F6) -> 1.3333333 | H7: =SUM(H4:H6) -> 23 | I7: =SUM(I4:I6) -> 32 | J7: =SUM(J4:J6) -> 1750 | K7: =SUM(K4:K6) -> 218.75 | L7: =AVERAGE(L4:L6) -> 2.8 | M7: =SUM(M4:M6) -> 4830 | N7: =SUM(N4:N6) -> 603.75 | O7: =SUM(O4:O6) -> 7260 | P7: =SUM(P4:P6) -> 2090880 | Q7: =SUM(Q4:Q6) -> 2090.88 | R7: =SUM(R4:R6) -> 35000 | S7: =SUM(S4:S6) -> 22420.8
D9: Linea A
D10: Linea B | H10: =16+18 -> 34
B13: Linea | C13: COD | D13: Producto | E13: kg/año | F13: Tn/año | G13: $/kg | H13: FC [$MM] | I13: kg/mes | J13: kg/dia | K13: Turnos | L13: kg/h | N13: Ventas smams | P13: Factor | R13: % saludable | S13: % no saludable
B14: A | C14: A001 | D14: Chocolate con chips picante | E14: =N14*$P$14 -> 48000 | F14: =E14/1000 -> 48 | G14: 13700 | H14: =E14*G14/1000000 -> 657.6 | I14: =E14/12 -> 4000 | J14: =I14/20 -> 200 | K14: 2 | L14: =J14/(8*K14) -> 12.5 | N14: 80000 | P14: 0.6 | R14: 0.3 | S14: 0.7
B15: A | C15: A002 | D15: Galletitas simil chocolinas (S/ azúcares) | E15: =N15*$P$14*R14 -> 8325 | F15: =E15/1000 -> 8.325 | G15: =12600 -> 12600 | H15: =E15*G15/1000000 -> 104.895 | I15: =E15/12 -> 693.75 | J15: =I15/20 -> 34.6875 | K15: 2 | L15: =J15/(8*K15) -> 2.1679688 | N15: 46250
B16: A | C16: A003 | D16: Galletitas simil chocolinas | E16: =N16*$P$14*S14 -> 19425 | F16: =E16/1000 -> 19.425 | G16: 10500 | H16: =E16*G16/1000000 -> 203.9625 | I16: =E16/12 -> 1618.75 | J16: =I16/20 -> 80.9375 | K16: 2 | L16: =J16/(8*K16) -> 5.0585938 | N16: 46250
B17: A | C17: A004 | D17: Pepas chocolate y batata | E17: =N17*$P$14 -> 78000 | F17: =E17/1000 -> 78 | G17: =12000 -> 12000 | H17: =E17*G17/1000000 -> 936 | I17: =E17/12 -> 6500 | J17: =I17/20 -> 325 | K17: 2 | L17: =J17/(8*K17) -> 20.3125 | N17: 130000
B18: A | C18: A005 | D18: Bizcochos sabor queso (?) | E18: =N18*$P$14*R14 -> 4680 | F18: =E18/1000 -> 4.68 | G18: 7000 | H18: =E18*G18/1000000 -> 32.76 | I18: =E18/12 -> 390 | J18: =I18/20 -> 19.5 | K18: 2 | L18: =J18/(8*K18) -> 1.21875 | N18: 26000
B19: A | C19: A006 | D19: Bizcochos sabor queso | E19: =N19*$P$14*S14 -> 10920 | F19: =E19/1000 -> 10.92 | G19: 7000 | H19: =E19*G19/1000000 -> 76.44 | I19: =E19/12 -> 910 | J19: =I19/20 -> 45.5 | K19: 2 | L19: =J19/(8*K19) -> 2.84375 | N19: 26000
B20: A | C20: A007 | D20: Polvorones (S/ azúcares) | E20: =N20*$P$14*R14 -> 15840 | F20: =E20/1000 -> 15.84 | G20: =G21*1.2 -> 13800 | H20: =E20*G20/1000000 -> 218.592 | I20: =E20/12 -> 1320 | J20: =I20/20 -> 66 | K20: 2 | L20: =J20/(8*K20) -> 4.125 | N20: 88000
B21: A | C21: A008 | D21: Polvorones | E21: =N21*$P$14*S14 -> 36960 | F21: =E21/1000 -> 36.96 | G21: =11500 -> 11500 | H21: =E21*G21/1000000 -> 425.04 | I21: =E21/12 -> 3080 | J21: =I21/20 -> 154 | K21: 2 | L21: =J21/(8*K21) -> 9.625 | N21: 88000
B22: B | C22: B001 | D22: Pan de molde | E22: =N22*$P$14 -> 75000 | F22: =E22/1000 -> 75 | G22: 12700 | H22: =E22*G22/1000000 -> 952.5 | I22: =E22/12 -> 6250 | J22: =I22/20 -> 312.5 | K22: 2 | L22: =J22/(8*K22) -> 19.53125 | N22: 125000
B23: B | C23: B002 | D23: Budines | E23: =N23*$P$14 -> 70800 | F23: =E23/1000 -> 70.8 | G23: 12000 | H23: =E23*G23/1000000 -> 849.6 | I23: =E23/12 -> 5900 | J23: =I23/20 -> 295 | K23: 2 | L23: =J23/(8*K23) -> 18.4375 | N23: 118000
B24: B | C24: B003 | D24: Budines saludables (S/ azúcares) | E24: =N24*$P$14 -> 18000 | F24: =E24/1000 -> 18 | G24: 12000 | H24: =E24*G24/1000000 -> 216 | I24: =E24/12 -> 1500 | J24: =I24/20 -> 75 | K24: 2 | L24: =J24/(8*K24) -> 4.6875 | N24: 30000
B25: Total | D25: Total | E25: =SUM(E14:E24) -> 385950 | F25: =SUM(F14:F23) -> 367.95 | G25: =AVERAGE(G14:G23) -> 11280 | H25: =SUM(H14:H23) -> 4457.3895 | I25: =AVERAGE(I14:I23) -> 3066.25 | J25: =AVERAGE(J14:J23) -> 153.3125 | K25: =AVERAGE(K14:K23) -> 2 | L25: =AVERAGE(L14:L23) -> 9.5820312
B28: LINEA A | D28: Capacidad esperada (kg/h) | E28: =SUM(L14:L21) -> 57.851562 | I28: =100000*1400 -> 140000000
D29: Capacidad real (kg/h) | E29: =100 -> 100 | F29: Revisar capacidad de horno tunel
D30: Aprovechamiento | E30: =E28/E29 -> 0.57851562
B32: LINEA B | D32: Capacidad esperada (kg/h) | E32: =SUM(L22:L24) -> 42.65625
D33: Capacidad real (kg/h) | E33: 50 | F33: Revisar capacidad de horno rotativo | M33: =164000/12 -> 13666.667
D34: Aprovechamiento | E34: =E32/E33 -> 0.853125
B36: El aprovechamiento debe estar entre 60/90%. Esto se mejora bajando la capacidad de la maquina o aumentando la producción, sin agregar máquinas

Sheet Plan de ventas
D2: [ARS MM]
C4: Ventas # con 5,27% de mercado
B5: Producto | C5: Cantidad [paquetes] | D5: Precio [$/paquete]
A6: 150 | B6: Chocolate con chips picante 150gr. | C6: =ROUNDUP(Produccion!E14*1000/A6,0) -> 320000 | D6: =Produccion!G14/1000*A6 -> 2055
A7: 150 | B7: Galletitas simil chocolinas (S/ azúcares) 150gr. | C7: =ROUNDUP(Produccion!E15*1000/A7,0) -> 55500 | D7: =Produccion!G15/1000*A7 -> 1890
A8: 150 | B8: Galletitas simil chocolinas 150gr. | C8: =ROUNDUP(Produccion!E16*1000/A8,0) -> 129500 | D8: =Produccion!G16/1000*A8 -> 1575
A9: 150 | B9: Pepas chocolate y batata 150gr. | C9: =ROUNDUP(Produccion!E17*1000/A9,0) -> 520000 | D9: =Produccion!G17/1000*A9 -> 1800
A10: 150 | B10: Bizcochos sabor queso saludables 150gr. | C10: =ROUNDUP(Produccion!E18*1000/A10,0) -> 31200 | D10: =Produccion!G18/1000*A10 -> 1050
A11: 150 | B11: Bizcochos sabor queso 150gr. | C11: =ROUNDUP(Produccion!E19*1000/A11,0) -> 72800 | D11: =Produccion!G19/1000*A11 -> 1050
A12: 150 | B12: Polvorones (S/ azúcares) 150gr. | C12: =ROUNDUP(Produccion!E20*1000/A12,0) -> 105600 | D12: =Produccion!G20/1000*A12 -> 2070
A13: 150 | B13: Polvorones 150gr. | C13: =ROUNDUP(Produccion!E21*1000/A13,0) -> 246400 | D13: =Produccion!G21/1000*A13 -> 1725
A14: 400 | B14: Pan de molde 400gr. | C14: =ROUNDUP(Produccion!E22*1000/A14,0) -> 187500 | D14: =Produccion!G22/1000*A14 -> 5080
A15: 180 | B15: Budines 180gr. | C15: =ROUNDUP(Produccion!E23*1000/A15,0) -> 393334 | D15: =Produccion!G23/1000*A15 -> 2160
A16: 180 | B16: Budines saludables (S/ azúcares) 180gr. | C16: =ROUNDUP(Produccion!E24*1000/A16,0) -> 100000 | D16: =Produccion!G24/1000*A16 -> 2160
B17: TOTAL | C17: =SUM(C6:C16) -> 2161834 | D17: =SUM(D6:D16) -> 22615
C19: [Miles de unidades] | D19: [Miles de unidades] | E19: [Miles de unidades] | F19: [Miles de unidades] | G19: [Miles de unidades] | H19: [Miles de unidades] | I19: [Miles de unidades] | J19: [Miles de unidades] | K19: [Miles de unidades] | L19: [Miles de unidades]
B20: Producto | C20: Año 1 | D20: Año 2 | E20: Año 3 | F20: Año 4 | G20: Año 5 | H20: Año 6 | I20: Año 7 | J20: Año 8 | K20: Año 9 | L20: Año 10
B21: Chocolate con chips picante 150gr. | C21: =ROUNDUP((C6/4*0.5)+C6/4*3,0)/1000 -> 280 | D21: =C6/1000 -> 320 | E21: =ROUNDUP(D21*1.04,0) -> 333 | F21: =ROUNDUP(E21*1.04,0) -> 347 | G21: =ROUNDUP(F21*1.04*1.005,0) -> 363 | H21: =ROUNDUP(G21*1.04*1.005,0) -> 380 | I21: =ROUNDUP(H21*1.04*1.005,0) -> 398 | J21: =ROUNDUP(I21*1.04*1.005,0) -> 416 | K21: =ROUNDUP(J21*1.04*1.005,0) -> 435 | L21: =ROUNDUP(K21*1.04*1.005,0) -> 455
B22: Galletitas simil chocolinas (S/ azúcares) 150gr. | C22: =ROUNDUP((C7/4*0.5)+C7/4*3,0)/1000 -> 48.563 | D22: =C7/1000 -> 55.5 | E22: =ROUNDUP(D22*1.04,0) -> 58 | F22: =ROUNDUP(E22*1.04,0) -> 61 | G22: =ROUNDUP(F22*1.04*1.005,0) -> 64 | H22: =ROUNDUP(G22*1.04*1.005,0) -> 67 | I22: =ROUNDUP(H22*1.04*1.005,0) -> 71 | J22: =ROUNDUP(I22*1.04*1.005,0) -> 75 | K22: =ROUNDUP(J22*1.04*1.005,0) -> 79 | L22: =ROUNDUP(K22*1.04*1.005,0) -> 83
B23: Galletitas simil chocolinas 150gr. | C23: =ROUNDUP((C8/4*0.5)+C8/4*3,0)/1000 -> 113.313 | D23: =C8/1000 -> 129.5 | E23: =ROUNDUP(D23*1.04,0) -> 135 | F23: =ROUNDUP(E23*1.04,0) -> 141 | G23: =ROUNDUP(F23*1.04*1.005,0) -> 148 | H23: =ROUNDUP(G23*1.04*1.005,0) -> 155 | I23: =ROUNDUP(H23*1.04*1.005,0) -> 163 | J23: =ROUNDUP(I23*1.04*1.005,0) -> 171 | K23: =ROUNDUP(J23*1.04*1.005,0) -> 179 | L23: =ROUNDUP(K23*1.04*1.005,0) -> 188
B24: Pepas chocolate y batata 150gr. | C24: =ROUNDUP((C9/4*0.5)+C9/4*3,0)/1000 -> 455 | D24: =C9/1000 -> 520 | E24: =ROUNDUP(D24*1.04,0) -> 541 | F24: =ROUNDUP(E24*1.04,0) -> 563 | G24: =ROUNDUP(F24*1.04*1.005,0) -> 589 | H24: =ROUNDUP(G24*1.04*1.005,0) -> 616 | I24: =ROUNDUP(H24*1.04*1.005,0) -> 644 | J24: =ROUNDUP(I24*1.04*1.005,0) -> 674 | K24: =ROUNDUP(J24*1.04*1.005,0) -> 705 | L24: =ROUNDUP(K24*1.04*1.005,0) -> 737
B25: Bizcochos sabor queso saludables 150gr. | C25: =ROUNDUP((C10/4*0.5)+C10/4*3,0)/1000 -> 27.3 | D25: =C10/1000 -> 31.2 | E25: =ROUNDUP(D25*1.04,0) -> 33 | F25: =ROUNDUP(E25*1.04,0) -> 35 | G25: =ROUNDUP(F25*1.04*1.005,0) -> 37 | H25: =ROUNDUP(G25*1.04*1.005,0) -> 39 | I25: =ROUNDUP(H25*1.04*1.005,0) -> 41 | J25: =ROUNDUP(I25*1.04*1.005,0) -> 43 | K25: =ROUNDUP(J25*1.04*1.005,0) -> 45 | L25: =ROUNDUP(K25*1.04*1.005,0) -> 48
B26: Bizcochos sabor queso 150gr. | C26: =ROUNDUP((C11/4*0.5)+C11/4*3,0)/1000 -> 63.7 | D26: =C11/1000 -> 72.8 | E26: =ROUNDUP(D26*1.04,0) -> 76 | F26: =ROUNDUP(E26*1.04,0) -> 80 | G26: =ROUNDUP(F26*1.04*1.005,0) -> 84 | H26: =ROUNDUP(G26*1.04*1.005,0) -> 88 | I26: =ROUNDUP(H26*1.04*1.005,0) -> 92 | J26: =ROUNDUP(I26*1.04*1.005,0) -> 97 | K26: =ROUNDUP(J26*1.04*1.005,0) -> 102 | L26: =ROUNDUP(K26*1.04*1.005,0) -> 107
B27: Polvorones (S/ azúcares) 150gr. | C27: =ROUNDUP((C12/4*0.5)+C12/4*3,0)/1000 -> 92.4 | D27: =C12/1000 -> 105.6 | E27: =ROUNDUP(D27*1.04,0) -> 110 | F27: =ROUNDUP(E27*1.04,0) -> 115 | G27: =ROUNDUP(F27*1.04*1.005,0) -> 121 | H27: =ROUNDUP(G27*1.04*1.005,0) -> 127 | I27: =ROUNDUP(H27*1.04*1.005,0) -> 133 | J27: =ROUNDUP(I27*1.04*1.005,0) -> 140 | K27: =ROUNDUP(J27*1.04*1.005,0) -> 147 | L27: =ROUNDUP(K27*1.04*1.005,0) -> 154
B28: Polvorones 150gr. | C28: =ROUNDUP((C13/4*0.5)+C13/4*3,0)/1000 -> 215.6 | D28: =C13/1000 -> 246.4 | E28: =ROUNDUP(D28*1.04,0) -> 257 | F28: =ROUNDUP(E28*1.04,0) -> 268 | G28: =ROUNDUP(F28*1.04*1.005,0) -> 281 | H28: =ROUNDUP(G28*1.04*1.005,0) -> 294 | I28: =ROUNDUP(H28*1.04*1.005,0) -> 308 | J28: =ROUNDUP(I28*1.04*1.005,0) -> 322 | K28: =ROUNDUP(J28*1.04*1.005,0) -> 337 | L28: =ROUNDUP(K28*1.04*1.005,0) -> 353
B29: Pan de molde 400gr. | C29: =ROUNDUP((C14/4*0.5)+C14/4*3,0)/1000 -> 164.063 | D29: =C14/1000 -> 187.5 | E29: =ROUNDUP(D29*1.04,0) -> 195 | F29: =ROUNDUP(E29*1.04,0) -> 203 | G29: =ROUNDUP(F29*1.04*1.005,0) -> 213 | H29: =ROUNDUP(G29*1.04*1.005,0) -> 223 | I29: =ROUNDUP(H29*1.04*1.005,0) -> 234 | J29: =ROUNDUP(I29*1.04*1.005,0) -> 245 | K29: =ROUNDUP(J29*1.04*1.005,0) -> 257 | L29: =ROUNDUP(K29*1.04*1.005,0) -> 269
B30: Budines 180gr. | C30: =ROUNDUP((C15/4*0.5)+C15/4*3,0)/1000 -> 344.168 | D30: =C15/1000 -> 393.334 | E30: =ROUNDUP(D30*1.04,0) -> 410 | F30: =ROUNDUP(E30*1.04,0) -> 427 | G30: =ROUNDUP(F30*1.04*1.005,0) -> 447 | H30: =ROUNDUP(G30*1.04*1.005,0) -> 468 | I30: =ROUNDUP(H30*1.04*1.005,0) -> 490 | J30: =ROUNDUP(I30*1.04*1.005,0) -> 513 | K30: =ROUNDUP(J30*1.04*1.005,0) -> 537 | L30: =ROUNDUP(K30*1.04*1.005,0) -> 562
B31: Budines saludables (S/ azúcares) 180gr. | C31: =ROUNDUP((C16/4*0.5)+C16/4*3,0)/1000 -> 87.5 | D31: =C16/1000 -> 100 | E31: =ROUNDUP(D31*1.04,0) -> 104 | F31: =ROUNDUP(E31*1.04,0) -> 109 | G31: =ROUNDUP(F31*1.04*1.005,0) -> 114 | H31: =ROUNDUP(G31*1.04*1.005,0) -> 120 | I31: =ROUNDUP(H31*1.04*1.005,0) -> 126 | J31: =ROUNDUP(I31*1.04*1.005,0) -> 132 | K31: =ROUNDUP(J31*1.04*1.005,0) -> 138 | L31: =ROUNDUP(K31*1.04*1.005,0) -> 145
B32: TOTAL | C32: =SUM(C21:C31) -> 1891.607 | D32: =SUM(D21:D31) -> 2161.834 | E32: =SUM(E21:E31) -> 2252 | F32: =SUM(F21:F31) -> 2349 | G32: =SUM(G21:G31) -> 2461 | H32: =SUM(H21:H31) -> 2577 | I32: =SUM(I21:I31) -> 2700 | J32: =SUM(J21:J31) -> 2828 | ... L32: =SUM(L21:L31) -> 3101
D34: [ARS MM] | E34: [ARS MM] | F34: [ARS MM] | G34: [ARS MM] | H34: [ARS MM] | I34: [ARS MM] | J34: [ARS MM] | K34: [ARS MM] | L34: [ARS MM] | M34: [ARS MM]
B35: Producto | C35: Precio [$/paquete] | D35: Año 1 | E35: Año 2 | F35: Año 3 | G35: Año 4 | H35: Año 5 | I35: Año 6 | J35: Año 7 | K35: Año 8 | L35: Año 9 | M35: Año 10
B36: Chocolate con chips picante 150gr. | C36: =D6 -> 2055 | D36: =$C36*C21*1000/1000000 -> 575.4 | E36: =$C36*D21*1000/1000000 -> 657.6 | F36: =$C36*E21*1000/1000000 -> 684.315 | G36: =$C36*F21*1000/1000000 -> 713.085 | H36: =$C36*G21*1000/1000000 -> 745.965 | I36: =$C36*H21*1000/1000000 -> 780.9 | J36: =$C36*I21*1000/1000000 -> 817.89 | K36: =$C36*J21*1000/1000000 -> 854.88 | ... M36: =$C36*L21*1000/1000000 -> 935.025
B37: Galletitas simil chocolinas (S/ azúcares) 150gr. | C37: =D7 -> 1890 | D37: =$C37*C22*1000/1000000 -> 91.78407 | E37: =$C37*D22*1000/1000000 -> 104.895 | F37: =$C37*E22*1000/1000000 -> 109.62 | G37: =$C37*F22*1000/1000000 -> 115.29 | H37: =$C37*G22*1000/1000000 -> 120.96 | I37: =$C37*H22*1000/1000000 -> 126.63 | J37: =$C37*I22*1000/1000000 -> 134.19 | K37: =$C37*J22*1000/1000000 -> 141.75 | ... M37: =$C37*L22*1000/1000000 -> 156.87
B38: Galletitas simil chocolinas 150gr. | C38: =D8 -> 1575 | D38: =$C38*C23*1000/1000000 -> 178.46797 | E38: =$C38*D23*1000/1000000 -> 203.9625 | F38: =$C38*E23*1000/1000000 -> 212.625 | G38: =$C38*F23*1000/1000000 -> 222.075 | H38: =$C38*G23*1000/1000000 -> 233.1 | I38: =$C38*H23*1000/1000000 -> 244.125 | J38: =$C38*I23*1000/1000000 -> 256.725 | K38: =$C38*J23*1000/1000000 -> 269.325 | ... M38: =$C38*L23*1000/1000000 -> 296.1
B39: Pepas chocolate y batata 150gr. | C39: =D9 -> 1800 | D39: =$C39*C24*1000/1000000 -> 819 | E39: =$C39*D24*1000/1000000 -> 936 | F39: =$C39*E24*1000/1000000 -> 973.8 | G39: =$C39*F24*1000/1000000 -> 1013.4 | H39: =$C39*G24*1000/1000000 -> 1060.2 | I39: =$C39*H24*1000/1000000 -> 1108.8 | J39: =$C39*I24*1000/1000000 -> 1159.2 | K39: =$C39*J24*1000/1000000 -> 1213.2 | ... M39: =$C39*L24*1000/1000000 -> 1326.6
B40: Bizcochos sabor queso saludables 150gr. | C40: =D10 -> 1050 | D40: =$C40*C25*1000/1000000 -> 28.665 | E40: =$C40*D25*1000/1000000 -> 32.76 | F40: =$C40*E25*1000/1000000 -> 34.65 | G40: =$C40*F25*1000/1000000 -> 36.75 | H40: =$C40*G25*1000/1000000 -> 38.85 | I40: =$C40*H25*1000/1000000 -> 40.95 | J40: =$C40*I25*1000/1000000 -> 43.05 | K40: =$C40*J25*1000/1000000 -> 45.15 | ... M40: =$C40*L25*1000/1000000 -> 50.4
B41: Bizcochos sabor queso 150gr. | C41: =D11 -> 1050 | D41: =$C41*C26*1000/1000000 -> 66.885 | E41: =$C41*D26*1000/1000000 -> 76.44 | F41: =$C41*E26*1000/1000000 -> 79.8 | G41: =$C41*F26*1000/1000000 -> 84 | H41: =$C41*G26*1000/1000000 -> 88.2 | I41: =$C41*H26*1000/1000000 -> 92.4 | J41: =$C41*I26*1000/1000000 -> 96.6 | K41: =$C41*J26*1000/1000000 -> 101.85 | ... M41: =$C41*L26*1000/1000000 -> 112.35
B42: Polvorones (S/ azúcares) 150gr. | C42: =D12 -> 2070 | D42: =$C42*C27*1000/1000000 -> 191.268 | E42: =$C42*D27*1000/1000000 -> 218.592 | F42: =$C42*E27*1000/1000000 -> 227.7 | G42: =$C42*F27*1000/1000000 -> 238.05 | H42: =$C42*G27*1000/1000000 -> 250.47 | I42: =$C42*H27*1000/1000000 -> 262.89 | J42: =$C42*I27*1000/1000000 -> 275.31 | K42: =$C42*J27*1000/1000000 -> 289.8 | ... M42: =$C42*L27*1000/1000000 -> 318.78
B43: Polvorones 150gr. | C43: =D13 -> 1725 | D43: =$C43*C28*1000/1000000 -> 371.91 | E43: =$C43*D28*1000/1000000 -> 425.04 | F43: =$C43*E28*1000/1000000 -> 443.325 | G43: =$C43*F28*1000/1000000 -> 462.3 | H43: =$C43*G28*1000/1000000 -> 484.725 | I43: =$C43*H28*1000/1000000 -> 507.15 | J43: =$C43*I28*1000/1000000 -> 531.3 | K43: =$C43*J28*1000/1000000 -> 555.45 | ... M43: =$C43*L28*1000/1000000 -> 608.925
B44: Pan de molde 400gr. | C44: =D14 -> 5080 | D44: =$C44*C29*1000/1000000 -> 833.44004 | E44: =$C44*D29*1000/1000000 -> 952.5 | F44: =$C44*E29*1000/1000000 -> 990.6 | G44: =$C44*F29*1000/1000000 -> 1031.24 | H44: =$C44*G29*1000/1000000 -> 1082.04 | I44: =$C44*H29*1000/1000000 -> 1132.84 | J44: =$C44*I29*1000/1000000 -> 1188.72 | K44: =$C44*J29*1000/1000000 -> 1244.6 | ... M44: =$C44*L29*1000/1000000 -> 1366.52
...

Sheet Inversiones
B2: Activo fijo | Q2: Planta | T2: Activo trabajo
B3: Concepto | C3: ARS [MM] | D3: % | G3: Categoría | H3: Equipo | I3: Cantidad | J3: Precio USD | K3: Precio $ | L3: Total $ | N3: TC | O3: 1360 | Q3: Area | R3: m2 | T3: Concepto | U3: ARS MM | V3: Plazo | W3: AT
B4: Nave industrial | C4: =900000*O3/1000000 -> 1224 | D4: =C4/$C$9 -> 0.68804941 | F4: Rodados y equipos aux | G4: Uso general | H4: Autoelevador | I4: 1 | J4: 15000 | L4: =IF(J4="",I4*K4,I4*J4*$O$3) -> 20400000 | Q4: Producción y oficinas | R4: 680 | T4: Compras MP | U4: =Costos!C5 -> 1004.4812 | V4: 30 | W4: =U4/365*V4 -> 82.560095
B5: Obras complementarias | C5: =R7*0.7*R9/1000000 -> 186.2 | D5: =C5/$C$9 -> 0.10466895 | H5: Zorra | I5: 2 | K5: 450000 | L5: =IF(J5="",I5*K5,I5*J5*$O$3) -> 900000 | Q5: Deposito producto terminado | R5: 450 | T5: Ventas PT | U5: ='Plan de ventas'!D47 -> 4089.223 | V5: 45 | W5: =U5/365*V5 -> 504.15078
B6: Máquinas operativas | C6: =L35/1000000 -> 336.792 | D6: =C6/$C$9 -> 0.18932152 | H6: Balanza micro pesado | I6: 1 | K6: 200000 | L6: =IF(J6="",I6*K6,I6*J6*$O$3) -> 200000 | Q6: Deposito mp | R6: 200
B7: Rodados y equipos auxiliares | C7: =L8/1000000 -> 22.2 | D7: =C7/$C$9 -> 0.012479328 | H7: Balanza macro pesado | I7: 1 | K7: 700000 | L7: =IF(J7="",I7*K7,I7*J7*$O$3) -> 700000 | Q7: Total | R7: =SUM(R4:R6) -> 1330 | W7: Inversion AT
B8: Muebles y útiles | C8: =L18/1000000 -> 9.75 | D8: =C8/$C$9 -> 0.0054807858 | G8: Total | L8: =SUM(L4:L7) -> 22200000 | W8: =W5-W4 -> 421.59068
B9: Total | C9: =SUM(C4:C8) -> 1778.942 | D9: =SUM(D4:D8) -> 1 | Q9: Costo construcción m2 | R9: =200000 -> 200000
F10: Muebles y utiles | H10: Impresora Injket | I10: 1 | K10: 200000 | L10: =IF(J10="",I10*K10,I10*J10*$O$3) -> 200000
H11: Computadoras | I11: 8 | K11: 500000 | L11: =IF(J11="",I11*K11,I11*J11*$O$3) -> 4000000
H12: Sillas | I12: 15 | K12: 150000 | L12: =IF(J12="",I12*K12,I12*J12*$O$3) -> 2250000
H13: Mesas | I13: 3 | K13: 200000 | L13: =IF(J13="",I13*K13,I13*J13*$O$3) -> 600000
H14: Sanitario (inodoro + lavamano) | I14: 6 | K14: 450000 | L14: =IF(J14="",I14*K14,I14*J14*$O$3) -> 2700000
G18: Total | L18: =SUM(L10:L17) -> 9750000
F20: Maquinas | G20: Línea de Galletitas | H20: Amasadora Industrial | I20: 1 | J20: 13500 | L20: =IF(J20="",I20*K20,I20*J20*$O$3) -> 18360000
H21: Rotativa con dulcera | I21: 1 | J21: 15000 | L21: =IF(J21="",I21*K21,I21*J21*$O$3) -> 20400000
H22: Moldes formadores | I22: 4 | J22: 5000 | L22: =IF(J22="",I22*K22,I22*J22*$O$3) -> 27200000
H23: Horno de Túnel (Continuo) | I23: 1 | J23: 100000 | L23: =IF(J23="",I23*K23,I23*J23*$O$3) -> 136000000
H24: Cinta de Enfriamiento | I24: 1 | J24: 12000 | L24: =IF(J24="",I24*K24,I24*J24*$O$3) -> 16320000
H25: Envasadora | I25: 1 | J25: 4000 | L25: =IF(J25="",I25*K25,I25*J25*$O$3) -> 5440000
G26: Línea de panificados | H26: Batidora Industrial | I26: 1 | K26: 2500000 | L26: =IF(J26="",I26*K26,I26*J26*$O$3) -> 2500000
H27: Dosificadora Volumétrica de Pistones | I27: 1 | K27: 2000000 | L27: =IF(J27="",I27*K27,I27*J27*$O$3) -> 2000000
H28: Carros para horno | I28: 4 | K28: 510000 | L28: =IF(J28="",I28*K28,I28*J28*$O$3) -> 2040000
H29: Horno Rotativo | I29: 2 | K29: 15000000 | L29: =IF(J29="",I29*K29,I29*J29*$O$3) -> 30000000
H30: Fermentadora de pan | I30: 1 | K30: 1900000 | L30: =IF(J30="",I30*K30,I30*J30*$O$3) -> 1900000
H31: Cortadora de pan | I31: 1 | J31: 500 | L31: =IF(J31="",I31*K31,I31*J31*$O$3) -> 680000
H32: Carros de enfriamiento | I32: 4 | K32: 400000 | L32: =IF(J32="",I32*K32,I32*J32*$O$3) -> 1600000
H33: Detector de metales | I33: 1 | J33: 3200 | L33: =IF(J33="",I33*K33,I33*J33*$O$3) -> 4352000
H34: Envasadora | I34: 1 | J34: 50000 | L34: =IF(J34="",I34*K34,I34*J34*$O$3) -> 68000000
G35: Total | L35: =SUM(L20:L34) -> 336792000

Sheet Costos
B2: Resumen costos anuales | F2: Mano de obra | M2: Materia prima
B3: Concepto | C3: ARS [MM] | D3: % | F3: Sector | G3: Posición | H3: Tipo | I3: Cantidad | J3: Sueldo basico [ARS] | K3: Total anual [ARS] | M3: COD | N3: Producto | O3: Costo MP / Kg ($) | P3: Q anual (kg) | Q3: Costo anual ($) | S3: $/kg | T3: Costo/precio
B4: Mano de obra | C4: =$K$14/1000000 -> 1356.5203 | D4: =C4/$C$7 -> 0.40218705 | F4: Producción | G4: Operario | H4: Directo | I4: 37 | J4: 1072000 | K4: =I4*J4*12*1.24 -> 590200320 | M4: A001 | N4: Chocolate con chips picante | O4: 1775.67 | P4: =VLOOKUP(M4,Produccion!C:E,3,0) -> 48000 | Q4: =O4*P4 -> 85232160 | S4: =VLOOKUP(M4,Produccion!C:G,5,0) -> 13700 | T4: =O4/S4 -> 0.12961095 | W4: A001 | X4: Chocolate con chips picante | Y4: 1775.67
B5: Materia prima | C5: =Q15/1000000 -> 1004.4812 | D5: =C5/$C$7 -> 0.29781295 | F5: Calidad | G5: Analistas | H5: Indirecto | I5: 3 | J5: 2200000 | K5: =I5*J5*12*1.24 -> 98208000 | M5: A002 | N5: Galletitas simil chocolinas | O5: =1723 -> 1723 | P5: =VLOOKUP(M5,Produccion!C:E,3,0) -> 8325 | Q5: =O5*P5 -> 14343975 | S5: =VLOOKUP(M5,Produccion!C:G,5,0) -> 12600 | T5: =O5/S5 -> 0.13674603 | W5: A002 | X5: Galletitas simil chocolinas | Y5: 1498.67
B6: Otros costos | C6: =SUM(C4:C5)/0.7*0.3 -> 1011.8578 | D6: =C6/$C$7 -> 0.3 | F6: Admin y Finanzas | G6: Analistas | H6: Indirecto | I6: 4 | J6: 2200000 | K6: =I6*J6*12*1.24 -> 130944000 | M6: A003 | N6: Galletitas simil chocolinas | O6: 1498.67 | P6: =VLOOKUP(M6,Produccion!C:E,3,0) -> 19425 | Q6: =O6*P6 -> 29111665 | S6: =VLOOKUP(M6,Produccion!C:G,5,0) -> 10500 | T6: =O6/S6 -> 0.14273048 | W6: A003 | X6: Pepas chocolate y batata | Y6: 2404.98
B7: Total | C7: =SUM(C4:C6) -> 3372.8593 | D7: =SUM(D4:D6) -> 1 | F7: Producción | G7: Supervisores | H7: Directo | I7: 2 | J7: 2000000 | K7: =I7*J7*12*1.24 -> 59520000 | M7: A004 | N7: Pepas chocolate y batata | O7: 2405 | P7: =VLOOKUP(M7,Produccion!C:E,3,0) -> 78000 | Q7: =O7*P7 -> 187590000 | S7: =VLOOKUP(M7,Produccion!C:G,5,0) -> 12000 | T7: =O7/S7 -> 0.20041667 | W7: A004 | X7: Bizcochos salados | Y7: 974.85
F8: Producción | G8: Jefes | H8: Directo | I8: 4 | J8: 2500000 | K8: =I8*J8*12*1.24 -> 148800000 | M8: A005 | N8: Bizcochos sabor queso | O8: 975 | P8: =VLOOKUP(M8,Produccion!C:E,3,0) -> 4680 | Q8: =O8*P8 -> 4563000 | S8: =VLOOKUP(M8,Produccion!C:G,5,0) -> 7000 | T8: =O8/S8 -> 0.13928571 | W8: A005 | X8: Polvorones | Y8: 1958.97
F9: Admin y Finanzas | G9: Gerente | H9: Indirecto | I9: 1 | J9: 3400000 | K9: =I9*J9*12*1.24 -> 50592000 | M9: A006 | N9: Bizcochos sabor queso | O9: 975 | P9: =VLOOKUP(M9,Produccion!C:E,3,0) -> 10920 | Q9: =O9*P9 -> 10647000 | S9: =VLOOKUP(M9,Produccion!C:G,5,0) -> 7000 | T9: =O9/S9 -> 0.13928571 | W9: B001 | X9: Pan de molde | Y9: 3034.2
F10: Calidad | G10: Gerente | H10: Indirecto | I10: 1 | J10: 3400000 | K10: =I10*J10*12*1.24 -> 50592000 | M10: A007 | N10: Polvorones | O10: 2253 | P10: =VLOOKUP(M10,Produccion!C:E,3,0) -> 15840 | Q10: =O10*P10 -> 35687520 | S10: =VLOOKUP(M10,Produccion!C:G,5,0) -> 13800 | T10: =O10/S10 -> 0.16326087 | W10: B002 | X10: Budines | Y10: 3798.74
F11: Producción | G11: Gerente | H11: Directo | I11: 1 | J11: 3400000 | K11: =I11*J11*12*1.24 -> 50592000 | M11: A008 | N11: Polvorones | O11: 1959 | P11: =VLOOKUP(M11,Produccion!C:E,3,0) -> 36960 | Q11: =O11*P11 -> 72404640 | S11: =VLOOKUP(M11,Produccion!C:G,5,0) -> 11500 | T11: =O11/S11 -> 0.17034783 | W11: B003 | X11: Budines | Y11: 3798.74
F12: Ventas | G12: Gerente | H12: Indirecto | I12: 1 | J12: 3400000 | K12: =I12*J12*12*1.24 -> 50592000 | M12: B001 | N12: Pan de molde | O12: 3034 | P12: =VLOOKUP(M12,Produccion!C:E,3,0) -> 75000 | Q12: =O12*P12 -> 227550000 | S12: =VLOOKUP(M12,Produccion!C:G,5,0) -> 12700 | T12: =O12/S12 -> 0.23889764
F13: Gerencia | G13: CEO | H13: Indirecto | I13: 1 | J13: 8500000 | K13: =I13*J13*12*1.24 -> 126480000 | M13: B002 | N13: Budines | O13: 3799 | P13: =VLOOKUP(M13,Produccion!C:E,3,0) -> 70800 | Q13: =O13*P13 -> 268969200 | S13: =VLOOKUP(M13,Produccion!C:G,5,0) -> 12000 | T13: =O13/S13 -> 0.31658333
F14: Total | I14: =SUM(I4:I13) -> 55 | J14: =SUM(J4:J13) -> 32072000 | K14: =SUM(K4:K13) -> 1356520320 | M14: B003 | N14: Budines saludables | O14: 3799 | P14: =VLOOKUP(M14,Produccion!C:E,3,0) -> 18000 | Q14: =O14*P14 -> 68382000 | S14: =VLOOKUP(M14,Produccion!C:G,5,0) -> 12000 | T14: =O14/S14 -> 0.31658333
M15: Total | Q15: =SUM(Q4:Q14) -> 1004481160
F17: Apertura mano de obra
F18: Concepto | G18: ARS [MM] | H18: %
F19: Mano de obra directa | G19: =SUMIF(H4:H13,"Directo",J4:J13) -> 8972000 | H19: =G19/$G$21 -> 0.27974557
F20: Mano de obra indirecta | G20: =SUMIF(H4:H13,"Indirecto",J4:J13) -> 23100000 | H20: =G20/$G$21 -> 0.72025443
F21: Total | G21: =SUM(G19:G20) -> 32072000 | H21: =SUM(H19:H20) -> 1

Sheet Flujo
D1: =IF(E2="x","y","") | E1: =IF(F2="x","y","") -> y | F1: =IF(G2="x","y","") | G1: =IF(H2="x","y","") | H1: =IF(I2="x","y","") | I1: =IF(J2="x","y","") | J1: =IF(K2="x","y","") | K1: =IF(L2="x","y","") | ... M1: =IF(N2="x","y","")
B2: Flujo de fondos [ARS MM] | D2: =IF(AND(D10>0,C10<0),"x","") | E2: =IF(AND(E10>0,D10<0),"x","") | F2: =IF(AND(F10>0,E10<0),"x","") -> x | G2: =IF(AND(G10>0,F10<0),"x","") | H2: =IF(AND(H10>0,G10<0),"x","") | I2: =IF(AND(I10>0,H10<0),"x","") | J2: =IF(AND(J10>0,I10<0),"x","") | K2: =IF(AND(K10>0,J10<0),"x","") | ... M2: =IF(AND(M10>0,L10<0),"x","")
B3: Concepto/Año | C3: 0 | D3: 1 | E3: 2 | F3: 3 | G3: 4 | H3: 5 | I3: 6 | J3: 7 | K3: 8 | L3: 9 | M3: 10 | N3: Total
B4: Ingresos | C4: 0 | D4: ='Plan de ventas'!D47 -> 4089.223 | E4: ='Plan de ventas'!E47 -> 4673.3909 | F4: ='Plan de ventas'!F47 -> 4866.675 | G4: ='Plan de ventas'!G47 -> 5073.95 | H4: ='Plan de ventas'!H47 -> 5316.27 | I4: ='Plan de ventas'!I47 -> 5566.765 | J4: ='Plan de ventas'!J47 -> 5833.545 | K4: ='Plan de ventas'!K47 -> 6109.205 | ... M4: ='Plan de ventas'!M47 -> 6698.69 | N4: =SUM(C4:M4) -> 54625.399
B5: Egresos | C5: =Inversiones!C9 -> 1778.942 | D5: =Costos!$C$7+Inversiones!W8 -> 3794.4499 | E5: =Costos!$C$7 -> 3372.8593 | F5: =Costos!$C$7 -> 3372.8593 | G5: =Costos!$C$7 -> 3372.8593 | H5: =Costos!$C$7 -> 3372.8593 | I5: =Costos!$C$7 -> 3372.8593 | J5: =Costos!$C$7 -> 3372.8593 | K5: =Costos!$C$7 -> 3372.8593 | L5: =Costos!$C$7 -> 3372.8593 | M5: =Costos!$C$7-Inversiones!W8 -> 2951.2686 | N5: =SUM(C5:M5) -> 35507.535
B6: Utilidad | C6: =C4-C5 -> -1778.942 | D6: =D4-D5 -> 294.77303 | E6: =E4-E5 -> 1300.5317 | F6: =F4-F5 -> 1493.8157 | G6: =G4-G5 -> 1701.0907 | H6: =H4-H5 -> 1943.4107 | I6: =I4-I5 -> 2193.9057 | J6: =J4-J5 -> 2460.6857 | ... M6: =M4-M5 -> 3747.4214 | N6: =SUM(C6:M6) -> 19117.864
B7: Honorarios directorio (5%) | C7: 0 | D7: =D6*5% -> 14.738651 | E7: =E6*5% -> 65.026584 | F7: =F6*5% -> 74.690787 | G7: =G6*5% -> 85.054537 | H7: =H6*5% -> 97.170537 | I7: =I6*5% -> 109.69529 | J7: =J6*5% -> 123.03429 | K7: =K6*5% -> 136.81729 | ... M7: =M6*5% -> 187.37107 | N7: =SUM(C7:M7) -> 1044.8403
B8: IIGG (35%) | C8: 0 | D8: =D6*35% -> 103.17056 | E8: =E6*35% -> 455.18609 | F8: =F6*35% -> 522.83551 | G8: =G6*35% -> 595.38176 | H8: =H6*35% -> 680.19376 | I8: =I6*35% -> 767.86701 | J8: =J6*35% -> 861.24001 | K8: =K6*35% -> 957.72101 | ... M8: =M6*35% -> 1311.5975 | N8: =SUM(C8:M8) -> 7313.8822
B9: Saldo | C9: =C6-C7-C8 -> -1778.942 | D9: =D6-D7-D8 -> 176.86382 | E9: =E6-E7-E8 -> 780.31901 | F9: =F6-F7-F8 -> 896.28945 | G9: =G6-G7-G8 -> 1020.6544 | H9: =H6-H7-H8 -> 1166.0464 | I9: =I6-I7-I8 -> 1316.3434 | J9: =J6-J7-J8 -> 1476.4114 | ... M9: =M6-M7-M8 -> 2248.4529 | N9: =SUM(C9:M9) -> 10759.142
B10: Saldo Acumulado | C10: =C9 -> -1778.942 | D10: =C10+D9 -> -1602.0782 | E10: =D10+E9 -> -821.75917 | F10: =E10+F9 -> 74.530272 | G10: =F10+G9 -> 1095.1847 | H10: =G10+H9 -> 2261.2312 | I10: =H10+I9 -> 3577.5746 | J10: =I10+J9 -> 5053.9861 | K10: =J10+K9 -> 6695.7935 | ... N10: =M10+N9 -> 21518.284
B12: Beneficio neto [ARS MM] | C12: =N6-N7-N8 -> 10759.142
B13: Recupero inversión | C13: =HLOOKUP("x",$D$2:$M$3,2,0) & " años y " & ROUNDUP(-(HLOOKUP("y",$D$1:$M$10,10,0))*365/HLOOKUP("x",$D$2:$M$9,8,0),0) & " días" -> 3 años y 335 días | G13: =HLOOKUP("x",$D$2:$M$3,2,0)+(-(HLOOKUP("y",$D$1:$M$10,10,0))*365/HLOOKUP("x",$D$2:$M$9,8,0))/365 -> 3.9168458
B14: TIR [%] | C14: =IRR(C9:M9) -> 0.42549993
B15: VAN [ARS MM] | C15: {=NPV(F15,C9:M9)} -> 3000.0289 | E15: wacc | F15: 0.15
