Workbook

Sheet Resumen General
B2: CONSOLIDADO GENERAL DE SUPERFICIES Y BALANCE DE PLANTA
B3: Proyecto Final UTN FRBA - Grupo 8 | Planta de Alimentos Libres de Gluten (CELI) | Comparativa Guerchet vs Layout
B5: PARÁMETROS DEL MÉTODO DE GUERCHET:
B6: Coeficiente de Evolución k = | D6: 0.75 | E6: Justificación k = 0,75: Industria alimenticia con transporte de carritos rodantes, zorras manuales y operarios en pie.
B8: N° | C8: Sector / Área | D8: Línea | E8: Equipo Principal | F8: Cant. | G8: Ss (m²) [A0] | H8: Lados N | I8: Sg (m²) | J8: Se (m²) | K8: St Guerchet (m²) | L8: St Layout (m²) | M8: Estado Dimensionamiento
B9: 1 | C9: Sección Pesado | D9: Común | E9: Balanza de piso + mesa micropesado | F9: 1 | G9: 1.2 | H9: 3 | I9: =G9*H9 | J9: =(G9+I9)*$D$6 | K9: =G9+I9+J9 | L9: ='Sección Pesado'!G14 | M9: Definitivo
B10: 2 | C10: Amasado | D10: Galletitas | E10: Amasadora doble Z Catania HJ25B | F10: 1 | G10: 0.39 | H10: 3 | I10: =G10*H10 | J10: =(G10+I10)*$D$6 | K10: =G10+I10+J10 | L10: ='Amasado Galletitas'!G14 | M10: Definitivo
B11: 3 | C11: Moldeado / Formado | D11: Galletitas | E11: Moldeadora Rotativa Ralem R800 | F11: 1 | G11: 1.616 | H11: 2 | I11: =G11*H11 | J11: =(G11+I11)*$D$6 | K11: =G11+I11+J11 | L11: ='Moldeado Galletitas'!G14 | M11: Definitivo
B12: 4 | C12: Horneado | D12: Galletitas | E12: Horno Túnel Polin GD-BTOM10 (6x1,3m) | F12: 1 | G12: 7.8 | H12: 2 | I12: =G12*H12 | J12: =(G12+I12)*$D$6 | K12: =G12+I12+J12 | L12: ='Horneado Galletitas'!G14 | M12: Definitivo
B13: 5 | C13: Enfriado | D13: Galletitas | E13: Cinta de enfriamiento Golden Way | F13: 1 | G13: 4 | H13: 2 | I13: =G13*H13 | J13: =(G13+I13)*$D$6 | K13: =G13+I13+J13 | L13: ='Enfriado Galletitas'!G14 | M13: Definitivo
B14: 6 | C14: Envasado 1° | D14: Galletitas | E14: Envasadora Vertical Zon Pack + Detector | F14: 1 | G14: 1.484 | H14: 3 | I14: =G14*H14 | J14: =(G14+I14)*$D$6 | K14: =G14+I14+J14 | L14: ='Envasado 1° Galletitas'!G14 | M14: Definitivo
B15: 7 | C15: Envasado 2° | D15: Galletitas | E15: Mesa de encajonado manual AISI 304 | F15: 1 | G15: 0.96 | H15: 3 | I15: =G15*H15 | J15: =(G15+I15)*$D$6 | K15: =G15+I15+J15 | L15: ='Envasado 2° Galletitas'!G14 | M15: Definitivo
B16: 8 | C16: Batido | D16: Panificados | E16: Batidora Planetaria Moretti Ultra 60 | F16: 1 | G16: 1.001 | H16: 3 | I16: =G16*H16 | J16: =(G16+I16)*$D$6 | K16: =G16+I16+J16 | L16: ='Batido Panificados'!G14 | M16: Definitivo
B17: 9 | C17: Dosificado | D17: Panificados | E17: Dosificadora Neumática Indurpack G1WGD | F17: 1 | G17: 0.348 | H17: 3 | I17: =G17*H17 | J17: =(G17+I17)*$D$6 | K17: =G17+I17+J17 | L17: ='Dosificado Panificados'!G14 | M17: Definitivo
B18: 10 | C18: Fermentado | D18: Panificados | E18: Cámara Fermentadora NKF-36RS | F18: 1 | G18: 0.568 | H18: 2 | I18: =G18*H18 | J18: =(G18+I18)*$D$6 | K18: =G18+I18+J18 | L18: ='Fermentado Panificados'!G14 | M18: Definitivo
B19: 11 | C19: Horneado | D19: Panificados | E19: Batería 2 Hornos Rotativos Pauna SIGMA | F19: 2 | G19: 6.24 | H19: 2 | I19: =G19*H19 | J19: =(G19+I19)*$D$6 | K19: =G19+I19+J19 | L19: ='Horneado Panificados'!G14 | M19: Definitivo
B20: 12 | C20: Enfriado | D20: Panificados | E20: Batería de Carros de Enfriamiento | F20: 1 | G20: 4.8 | H20: 3 | I20: =G20*H20 | J20: =(G20+I20)*$D$6 | K20: =G20+I20+J20 | L20: ='Enfriado Panificados'!G14 | M20: Definitivo
B21: 13 | C21: Rebanado Pan | D21: Panificados | E21: Rebanadora Continua Braesi FB-12 G2 | F21: 1 | G21: 0.344 | H21: 2 | I21: =G21*H21 | J21: =(G21+I21)*$D$6 | K21: =G21+I21+J21 | L21: ='Rebanadora Pan'!G14 | M21: Definitivo
B22: 14 | C22: Envasado 1° | D22: Panificados | E22: Envasadora Flow-Pack Brunetti EFH700X | F22: 1 | G22: 5.125 | H22: 3 | I22: =G22*H22 | J22: =(G22+I22)*$D$6 | K22: =G22+I22+J22 | L22: ='Envasado 1° Panificados'!G14 | M22: Definitivo
B23: 15 | C23: Envasado 2° | D23: Panificados | E23: Mesa de encajonado manual AISI 304 | F23: 1 | G23: 0.96 | H23: 3 | I23: =G23*H23 | J23: =(G23+I23)*$D$6 | K23: =G23+I23+J23 | L23: ='Envasado 2° Panificados'!G14 | M23: Definitivo
B24: 16 | C24: Depósito MP | D24: Logística | E24: Racks Selectivos MP (3 niveles / 24 pallets) | F24: 1 | G24: 14.4 | H24: 2 | I24: =G24*H24 | J24: =(G24+I24)*$D$6 | K24: =G24+I24+J24 | L24: ='Depósito MP'!G14 | M24: Estimado (SLP)*
B25: 17 | C25: Depósito PT | D25: Logística | E25: Racks Selectivos PT (3 niveles / 24 pallets) | F25: 1 | G25: 14.4 | H25: 2 | I25: =G25*H25 | J25: =(G25+I25)*$D$6 | K25: =G25+I25+J25 | L25: ='Depósito PT'!G14 | M25: Estimado (SLP)*
C26: TOTAL PLANTA CELI | G26: =SUM(G9:G25) | I26: =SUM(I9:I25) | J26: =SUM(J9:J25) | K26: =SUM(K9:K25) | L26: =SUM(L9:L25)

Sheet Diagrama Relacional
B2: FUNDAMENTOS DEL LAYOUT – DIAGRAMA RELACIONAL DE SUPERFICIES (SLP)
B3: Proyecto Final UTN FRBA - Grupo 8 | Planta CELI | Vinculación entre Matriz de Relaciones (REL) y Áreas Asignadas
B5: Nodo | C5: Sector / Puesto | D5: Línea | E5: Superficie (m²) | F5: Vínculo A (4L) | G5: Vínculo E (3L) | H5: Vínculo I (2L) | I5: Vínculo X | J5: Criterio / Estado de Dimensionamiento
B6: 1 | C6: Depósito MP y Recepción | D6: Logística | E6: ='Depósito MP'!G14 | F6: Nodo 2 | G6: - | H6: Nodo 10 | I6: Nodo 9 | J6: Superficie Preliminar (~50 m²)* a fijar por lote de compra
B7: 11 | C7: Filtro Sanitario / Aduana | D7: Personal | E7: 20 | F7: - | G7: Nodos 2, 3A, 3B | H7: - | I7: - | J7: Barrera sanitaria obligatoria libre de gluten (~20 m²)*
B8: 2 | C8: Sección Pesado y Micropesado | D8: Común | E8: ='Sección Pesado'!G14 | F8: Nodos 3A, 3B | G8: Nodos 10, 11 | H8: - | I8: - | J8: Dimensionamiento definitivo de puesto (12,16 m²)
B9: 3A | C9: Amasado Galletitas | D9: Galletitas | E9: ='Amasado Galletitas'!G14 | F9: Nodo 4A | G9: Nodo 11 | H9: - | I9: - | J9: Amasadora doble Z volcable Catania HJ25B (7,89 m²)
B10: 4A | C10: Moldeado / Formado | D10: Galletitas | E10: ='Moldeado Galletitas'!G14 | F10: Nodo 5A | G10: - | H10: Nodo 12 | I10: - | J10: Rotativa Ralem R800 y dulcera (11,82 m²)
B11: 5A | C11: Horneado Galletitas | D11: Galletitas | E11: ='Horneado Galletitas'!G14 | F11: Nodo 6A | G11: Nodo 12 | H11: - | I11: - | J11: Horno Túnel Polin 6x1,3m exterior (33,10 m²) [Actualizado]
B12: 6A | C12: Enfriado Galletitas | D12: Galletitas | E12: ='Enfriado Galletitas'!G14 | F12: Nodo 7A | G12: - | H12: - | I12: - | J12: Cinta continua Golden Way 5x0,8m (20,64 m²)
B13: 7A | C13: Envasado 1° Flow-pack | D13: Galletitas | E13: ='Envasado 1° Galletitas'!G14 | F13: Nodo 8A | G13: Nodo 10 | H13: Nodo 12 | I13: - | J13: Envasadora vertical Zon Pack + Detector (11,26 m²)
B14: 8A | C14: Envasado 2° Encajonado | D14: Galletitas | E14: ='Envasado 2° Galletitas'!G14 | F14: Nodo 9 | G14: - | H14: - | I14: - | J14: Mesa manual AISI 304 y paletizado (8,60 m²)
B15: 3B | C15: Batido Panificados | D15: Panificados | E15: ='Batido Panificados'!G14 | F15: Nodo 4B | G15: Nodo 11 | H15: - | I15: - | J15: Batidora planetaria Moretti 60L (8,89 m²)
B16: 4B | C16: Dosificado Panificados | D16: Panificados | E16: ='Dosificado Panificados'!G14 | F16: Nodo 5B | G16: - | H16: Nodo 12 | I16: - | J16: Dosificadora neumática Indurpack (7,63 m²)
B17: 5B | C17: Fermentado Panificados | D17: Panificados | E17: ='Fermentado Panificados'!G14 | F17: Nodo 6B | G17: - | H17: - | I17: - | J17: Cámara termohigrométrica NKF-36RS (7,75 m²)
B18: 6B | C18: Horneado Panificados | D18: Panificados | E18: ='Horneado Panificados'!G14 | F18: Nodo 7B | G18: Nodo 12 | H18: - | I18: - | J18: Batería 2 Hornos rotativos Pauna SIGMA (27,24 m²)
B19: 7B | C19: Enfriado Panificados | D19: Panificados | E19: ='Enfriado Panificados'!G14 | F19: Nodo 8B | G19: - | H19: - | I19: - | J19: Sector de 4 carros en reposo convectivo (19,80 m²)
B20: 8B | C20: Rebanado / Envasado 1° | D20: Panificados | E20: ='Envasado 1° Panificados'!G14 | F20: Nodo 8C | G20: Nodo 10 | H20: Nodo 12 | I20: - | J20: Rebanadora Braesi + Flow-pack Brunetti (28,00 m²)
B21: 8C | C21: Envasado 2° Encajonado | D21: Panificados | E21: ='Envasado 2° Panificados'!G14 | F21: Nodo 9 | G21: - | H21: - | I21: - | J21: Mesa manual AISI 304 y paletizado (8,60 m²)
B22: 10 | C22: Lab. Calidad / Inocuidad | D22: Auxiliar | E22: 15 | F22: - | G22: Nodos 2, 7A, 8B | H22: Nodos 1, 9 | I22: - | J22: Superficie Preliminar (~15 m²)* para control de PCC
B23: 12 | C23: Mantenimiento / Servicios | D23: Auxiliar | E23: 15 | F23: - | G23: Nodos 5A, 6B | H23: Nodos 4A, 7A, 8B | I23: - | J23: Superficie Preliminar (~15 m²)* para taller y compresores
B24: 9 | C24: Depósito PT y Expedición | D24: Logística | E24: ='Depósito PT'!G14 | F24: - | G24: - | H24: Nodo 10 | I24: Nodo 1 | J24: Superficie Preliminar (~50 m²)* a fijar por política stock

Sheet Layout General en U
B2: PLANO ESQUEMÁTICO DE DISTRIBUCIÓN DE PLANTA EN "U" (LAYOUT 2D)
B3: Proyecto Final UTN FRBA - Grupo 8 | Planta CELI | Nave Industrial 24,0 m x 30,0 m | Dársenas de Camiones al Frente
C5: ◄ PATIO EXTERIOR COMÚN DE MANIOBRAS PARA CAMIONES (CALLE DE ACCESO) ►
E6: CAMIÓN MP (Descarga Insumos) | O6: PATIO CENTRAL MANIOBRA | AM6: CAMIÓN PT (Despacho Producto)
D11: DÁRSENA 1: RECEPCIÓN MP | P11: FILTRO SANITARIO / VESTUARIOS | W11: ADMINISTRACIÓN / OFICINA | AE11: PASILLO ACCESO | AL11: DÁRSENA 2: EXPEDICIÓN PT
D14: 1. DEPÓSITO MP (Racks Selectivos 3 niveles - 50 m²) Harinas, Féculas, Azúcar, Grasas | P14: PASILLO MP (2,0 m) | T14: 12. Mantenimiento Compresores / Gas (15 m²) | Z14: MURO CIEGO | AB14: 10. Laboratorio Calidad Inocuidad Sin TACC (15 m²) | AH14: PASILLO PT (2,0 m) | AL14: 9. DEPÓSITO PRODUCTO TERMINADO (50 m²) Racks Selectivos PT + Enfilmadora Film
AL26: 8A. Encajonado / Paletizado Galletitas (9 m²)
AL30: 8C. Encajonado / Paletizado Panificados (9 m²)
D34: 2. SECCIÓN PESADO Y MICROPESADO (12 m²) Balanza de Piso + Mesa Inox Micropesaje | T34: 4B. Dosificado Indurpack (8 m²) | AB34: 5B. Fermentador NKF-36RS (8 m²) | AL34: 8B. Rebanadora + Flow-Pack Panificados (28 m²)
D44: 3A. Amasado G. Catania HJ25B (8 m²) | J44: 3B. Batido P. Moretti 60L (9 m²) | T44: 6B. Batería 2 Hornos Rotativos Pauna SIGMA (27 m²) | AL44: 7B. Sector Enfriamiento 4 Carros (20 m²)
D52: 4A. Moldeado Rotativa Ralem R800 + Dulcera (12 m²) | T52: 5A. HORNO TÚNEL POLIN (6,00 m x 1,30 m) - 33 m² | AF52: PASILLO | AH52: 6A. Cinta Enfriado Golden Way (5m x 0,8m) - 21 m² | AR52: 7A. Envasadora Vertical + Detector Metales (11 m²)
C59: PASILLO TÉCNICO DE CIRCULACIÓN TRASERO Y SALIDA DE VAHOS (2,0 m)

Sheet Evaluación de Alternativas
B2: MATRIZ DE EVALUACIÓN MULTICRITERIO Y COMPARACIÓN DE ALTERNATIVAS DE LAYOUT
B3: Proyecto Final UTN FRBA - Grupo 8 | Planta CELI | Metodología SLP (Richard Muther) - Selección por Factores Ponderados
B5: N° | C5: Criterio de Evaluación de Planta | D5: Peso (%) | E5: Calif. Alt. A (1-10) | F5: Puntaje Alt. A | G5: Calif. Alt. B (1-10) | H5: Puntaje Alt. B | I5: Justificación de Ingeniería / Ventaja Comparativa
B6: 1 | C6: Distancia de acarreo de Producto Terminado (PT) | D6: 0.25 | E6: 6 | F6: =D6*E6 | G6: 10 | H6: =D6*G6 | I6: Alt. B tiene distancia < 2m (envasado pegado a PT), frente a 22m en Alt. A.
B7: 2 | C7: Concentración y sinergia del sector de envasado | D7: 0.2 | E7: 6 | F7: =D7*E7 | G7: 9 | H7: =D7*G7 | I7: Alt. B unifica el empaque de Galletitas y Panificados en una sola nave limpia compartida.
B8: 3 | C8: Zonificación higiénica y separación sucia/limpia (Sin TACC) | D8: 0.15 | E8: 8 | F8: =D8*E8 | G8: 9 | H8: =D8*G8 | I8: Alt. B divide nítidamente la elaboración térmica (derecha) del empaque y PT (izquierda).
B9: 4 | C9: Alineación mecánica de máquinas continuas (Horno Túnel) | D9: 0.15 | E9: 7 | F9: =D9*E9 | G9: 9 | H9: =D9*G9 | I9: Alt. B dispone el Horno Túnel de 6m longitudinalmente en línea recta con la rotativa.
B10: 5 | C10: Aislamiento térmico y evacuación de vahos de hornos | D10: 0.15 | E10: 8 | F10: =D10*E10 | G10: 9 | H10: =D10*G10 | I10: Alt. B independiza el enfriado de panes mediante tabique aislante respecto al horno rotativo.
B11: 6 | C11: Flexibilidad para futuras ampliaciones de capacidad | D11: 0.1 | E11: 7 | F11: =D11*E11 | G11: 8 | H11: =D11*G11 | I11: Alt. B permite extender las líneas longitudinalmente hacia el fondo sin interferir con PT.
C12: TOTAL PUNTUACIÓN PONDERADA | D12: =SUM(D6:D11) | E12: - | F12: =SUM(F6:F11) | G12: GANADORA | H12: =SUM(H6:H11) | I12: La Alternativa B resulta seleccionada con 9,15 pts vs 6,95 pts de Alt. A

Sheet Sección Pesado
B2: SECCIÓN PESADO Y MICROPESADO | L2: Escala: 1 celda ≈ 0.20 m x 0.20 m
B3: Línea: Común (Galletitas y Panificados) | Balanza de plataforma industrial + Mesa micropesado
S4: A7
B5: Subarea | C5: Descripción / Denominación | D5: Largo (m) | E5: Ancho (m) | F5: Cant. | G5: Superficie (m²) | H5: Justificación | I5: Función
B6: A0 | C6: Balanza de plataforma + Mesa micropesado | D6: 1.2 | E6: 1 | F6: 1 | G6: =D6*E6*F6 | H6: Fabricante (plataforma 1x1m + báscula digital) | I6: Pesaje de bines, bolsas e ingredientes menores
B7: A1 | C7: MP en espera (Pallet / bines desde depósito) | D7: 1.2 | E7: 1 | F7: 1 | G7: =D7*E7*F7 | H7: Huella de pallet normalizado Arlog (1,2 x 1,0 m) | I7: Espera de materias primas a fraccionar
B8: A2 | C8: Área de operación y pesaje de operario | D8: 1.5 | E8: 1.2 | F8: 1 | G8: =D8*E8*F8 | H8: Radio ergonómico de giro y manipulación de bolsas | I8: Carga manual, vaciado, tara y pesaje neto | R8: A3 | AB8: A6
B9: A3 | C9: Mesa de fraccionamiento y salida de bines | D9: 1.2 | E9: 0.8 | F9: 1 | G9: =D9*E9*F9 | H9: Mesa estándar acero inoxidable AISI 304 | I9: Fraccionamiento fino de aditivos y pesadas menores
B10: A4 | C10: Tablero / terminal báscula e impresora | D10: 0.6 | E10: 0.5 | F10: 1 | G10: =D10*E10*F10 | H10: Columna con pantalla LCD e impresora térmica | I10: Registro de lote, peso neto y etiquetas de pesaje
B11: A5 | C11: Espacio de seguridad perimetral | D11: 0.5 | E11: 1 | F11: 2 | G11: =D11*E11*F11 | H11: 0,5 m de seguridad según normas de higiene | I11: Seguridad lateral y distanciamiento de pared
B12: A6 | C12: Pasillo de circulación y zorra hidráulica | D12: 1.2 | E12: 3.5 | F12: 1 | G12: =D12*E12*F12 | H12: Ancho mínimo de maniobra para zorra manual | I12: Circulación de materiales y personal
B13: A7 | C13: Buffer de bines pesados en espera (SE) | D13: 1.2 | E13: 1 | F13: 1 | G13: =D13*E13*F13 | H13: Batea/carro de transporte a amasado/batido | I13: Buffer de ingredientes pesados listos para proceso
B14: TOTAL | C14: Superficie Total Asignada al Puesto | G14: =SUM(G6:G13) | N14: A4 | R14: A0 Balanza de Piso + Mesa | Z14: A5
B16: PARÁMETROS TÉCNICOS DEL EQUIPO / PUESTO | E16: ESPECIFICACIÓN / VALOR
B17: Equipo Principal | E17: Balanza de plataforma MST-150B + Báscula digital
B18: Capacidad Máxima | E18: 150 kg (resolución 20 g) / Mesa 50 kg (resolución 1 g)
B19: Dimensiones Plataforma | E19: 1000 mm x 1000 mm | Altura plataforma: 120 mm
B20: Mesa de Micropesado | E20: Acero Inox AISI 304 (1200 x 800 mm, h=850 mm) | M20: A1 | R20: A2
B21: Alimentación Eléctrica | E21: 220 V / 50 Hz con batería de respaldo
B22: Insumos Manipulados | E22: Féculas, harinas, aditivos, leudantes, esencias, sal, azúcar
B24: Proyecto Final UTN FRBA | Grupo 8 - Planta CELI (Alimentos Sin Gluten) | Relevamiento de Superficies y Layout
M29: REFERENCIAS DE LAYOUT:
M30: A0: Máquina Principal | A1: MP en espera | A2: Operación/Alimentación | A3: Salida de Producto
M31: A4: Tablero / Mando | A5: Seguridad Lateral | A6: Pasillo Circulación | A7: Buffer Semielaborado (SE)

Sheet Amasado Galletitas
B2: AMASADO - LÍNEA GALLETITAS | L2: Escala: 1 celda ≈ 0.20 m x 0.20 m
B3: Línea A - Galletitas | Amasadora Doble Z Volcable Catania HJ25B (50 L / 25 kg)
S4: A7
B5: Subarea | C5: Descripción / Denominación | D5: Largo (m) | E5: Ancho (m) | F5: Cant. | G5: Superficie (m²) | H5: Justificación | I5: Función
B6: A0 | C6: Máquina Amasadora Doble Z Volcable | D6: 0.78 | E6: 0.5 | F6: 1 | G6: =D6*E6*F6 | H6: Fabricante Catania (HJ25B: 780 x 500 mm) | I6: Mezclado y amasado de masas densas sin gluten
B7: A1 | C7: MP pesada en espera (Bines con ingredientes) | D7: 0.8 | E7: 0.6 | F7: 1 | G7: =D7*E7*F7 | H7: Contenedores plásticos rodantes alimentarios | I7: Espera de carga de materias primas dosificadas
B8: A2 | C8: Alimentación + Operación del amasador | D8: 1.2 | E8: 1 | F8: 1 | G8: =D8*E8*F8 | H8: Espacio de trabajo frontal del operario | I8: Carga manual de ingredientes y control de amasado | R8: A3 | AB8: A6
B9: A3 | C9: Zona de vuelco / descarga de masa amasada | D9: 0.9 | E9: 0.7 | F9: 1 | G9: =D9*E9*F9 | H9: Radio de descarga de batea basculante 90° | I9: Vuelco de la masa elaborada hacia batea móvil
B10: A4 | C10: Tablero eléctrico de comando y variador | D10: 0.6 | E10: 0.4 | F10: 1 | G10: =D10*E10*F10 | H10: Gabinete estanco IP65 para pulsadores y mando | I10: Comando de velocidad, temporizador y parada emergencia
B11: A5 | C11: Espacio de seguridad lateral y vuelco | D11: 0.5 | E11: 0.8 | F11: 2 | G11: =D11*E11*F11 | H11: 0,5 m de seguridad lateral respecto a tabiques | I11: Seguridad operativa y acceso a limpieza/mantenimiento
B12: A6 | C12: Pasillo de circulación y transporte de batea | D12: 1 | E12: 2.5 | F12: 1 | G12: =D12*E12*F12 | H12: Pasillo de circulación interna (mínimo 1,00 m) | I12: Tránsito peatonal y traslado rodante de bateas
B13: A7 | C13: Buffer de batea con reposo de masa (SE) | D13: 0.8 | E13: 0.8 | F13: 1 | G13: =D13*E13*F13 | H13: Carro porta-batea de acero inox en reposo | I13: Buffer de masa lista antes de alimentar moldeadora
B14: TOTAL | C14: Superficie Total Asignada al Puesto | G14: =SUM(G6:G13) | N14: A4 | R14: A0 Amasadora Doble Z | Z14: A5
B16: PARÁMETROS TÉCNICOS DEL EQUIPO / PUESTO | E16: ESPECIFICACIÓN / VALOR
B17: Marca y Modelo | E17: Catania HJ25B (Amasadora doble Z volcable)
B18: Capacidad de Batea | E18: 50 Litros / 25 kg de masa por bache
B19: Dimensiones del Equipo | E19: 780 mm (Largo) x 500 mm (Ancho) x 950 mm (Alto)
B20: Superficie Estática (Ss) | E20: 0,39 m² (según memoria de cálculo BOM y Balanceo) | M20: A1 | R20: A2
B21: Potencia y Voltaje | E21: 1,50 kW (1500 W) | 220 V / 50 Hz monofásica/trifásica
B22: Tiempo de Bache / Ciclo | E22: 12 a 15 min por ciclo de amasado (Capacidad teórica: 125 kg/h)
B24: Proyecto Final UTN FRBA | Grupo 8 - Planta CELI (Alimentos Sin Gluten) | Relevamiento de Superficies y Layout
M29: REFERENCIAS DE LAYOUT:
M30: A0: Máquina Principal | A1: MP en espera | A2: Operación/Alimentación | A3: Salida de Producto
M31: A4: Tablero / Mando | A5: Seguridad Lateral | A6: Pasillo Circulación | A7: Buffer Semielaborado (SE)

Sheet Moldeado Galletitas
B2: MOLDEADO / FORMADO - LÍNEA GALLETITAS | L2: Escala: 1 celda ≈ 0.20 m x 0.20 m
B3: Línea A - Galletitas | Máquina Rotativa Ralem R800 + Dulcera + Cinta Transferencia
S4: A7
B5: Subarea | C5: Descripción / Denominación | D5: Largo (m) | E5: Ancho (m) | F5: Cant. | G5: Superficie (m²) | H5: Justificación | I5: Función
B6: A0 | C6: Máquina Moldeadora Rotativa + Dulcera | D6: 2.02 | E6: 0.8 | F6: 1 | G6: =D6*E6*F6 | H6: Fabricante Ralem (Rotativa R800: 2020 x 800 mm) | I6: Laminación, corte rotativo de masa y dosificado
B7: A1 | C7: Batea de masa amasada en espera | D7: 0.8 | E7: 0.8 | F7: 1 | G7: =D7*E7*F7 | H7: Carro de transporte rodante desde Amasado | I7: Espera de masa lista para alimentar la tolva
B8: A2 | C8: Alimentación de tolva + Puesto de operador | D8: 1.5 | E8: 1 | F8: 1 | G8: =D8*E8*F8 | H8: Acceso ergonómico superior y panel de mandos | I8: Carga de masa a tolva y calibración de rodillos | R8: A3 | AB8: A6
B9: A3 | C9: Cinta de acople y transferencia a Horno | D9: 1 | E9: 0.8 | F9: 1 | G9: =D9*E9*F9 | H9: Cinta de empalme con la banda metálica del horno | I9: Alineación y depósito de galletitas en malla de cocción
B10: A4 | C10: Tablero eléctrico, variadores y retorno scrap | D10: 0.8 | E10: 0.5 | F10: 1 | G10: =D10*E10*F10 | H10: Gabinete de control y cinta de retorno de recorte | I10: Regulación de velocidad sincronizada y recuperación
B11: A5 | C11: Espacio de seguridad lateral y limpieza | D11: 0.5 | E11: 2 | F11: 2 | G11: =D11*E11*F11 | H11: 0,5 m a ambos laterales para acceso y sanidad | I11: Seguridad y mantenimiento de rodillos formadores
B12: A6 | C12: Pasillo de circulación y supervisión | D12: 1 | E12: 3.5 | F12: 1 | G12: =D12*E12*F12 | H12: Pasillo técnico longitudinal de la línea | I12: Circulación de operarios y control dimensional
B13: A7 | C13: Bandeja colectora de recorte / scrap (SE) | D13: 0.6 | E13: 0.6 | F13: 1 | G13: =D13*E13*F13 | H13: Bandeja de recolección de masa sobrante | I13: Retorno de recortes no conformados hacia amasadora
B14: TOTAL | C14: Superficie Total Asignada al Puesto | G14: =SUM(G6:G13) | N14: A4 | R14: A0 Moldeadora Rotativa R800 | Z14: A5
B16: PARÁMETROS TÉCNICOS DEL EQUIPO / PUESTO | E16: ESPECIFICACIÓN / VALOR
B17: Marca y Modelo | E17: Ralem Rotativa R800 + Dosificadora de Dulce
B18: Ancho de Cilindro / Malla | E18: 700 mm útil (Ancho total máquina: 800 mm)
B19: Dimensiones del Equipo | E19: 2020 mm (Largo) x 800 mm (Ancho) x 2020 mm (Alto)
B20: Superficie Estática (Ss) | E20: 1,616 m² (según BOM y Balanceo) | M20: A1 | R20: A2
B21: Potencia y Voltaje | E21: 2,50 kW | 220 V / 380 V trifásica
B22: Capacidad Teórica | E22: 127,66 kg/h (9 galletas/fila, rodillo ø150 mm)
B24: Proyecto Final UTN FRBA | Grupo 8 - Planta CELI (Alimentos Sin Gluten) | Relevamiento de Superficies y Layout
M29: REFERENCIAS DE LAYOUT:
M30: A0: Máquina Principal | A1: MP en espera | A2: Operación/Alimentación | A3: Salida de Producto
M31: A4: Tablero / Mando | A5: Seguridad Lateral | A6: Pasillo Circulación | A7: Buffer Semielaborado (SE)

Sheet Horneado Galletitas
B2: HORNEADO - HORNO TÚNEL CICLOTÉRMICO | L2: Escala: 1 celda ≈ 0.25 m x 0.25 m (Largo: 24 celdas | Ancho: 5 celdas)
B3: Línea A - Galletitas | Horno Túnel Polin GD-BTOM10 (Cámara 6,00 m Largo x 1,30 m Ancho Total)
S4: A7 | AB4: A6
B5: Subarea | C5: Descripción / Denominación | D5: Largo (m) | E5: Ancho (m) | F5: Cant. | G5: Superficie (m²) | H5: Justificación | I5: Función
B6: A0 | C6: Horno Túnel Ciclotérmico Modular | D6: 6 | E6: 1.3 | F6: 1 | G6: =D6*E6*F6 | H6: Fabricante Polin (Cámara 6,0m x 1,3m exterior) | I6: Cocción continua sobre banda metálica con tiro modulado
B7: A1 | C7: Embocadura y tensión de banda de entrada | D7: 1.2 | E7: 1.3 | F7: 1 | G7: =D7*E7*F7 | H7: Mecanismo de tracción, centrado y raspador | I7: Recepción continua de galletas crudas desde rotativa | S7: A3
B8: A2 | C8: Pasarela lateral de inspección y visores | D8: 6 | E8: 1 | F8: 1 | G8: =D8*E8*F8 | H8: Pasarela de supervisión con visores pyrex templados | I8: Control visual de cocción y ajuste de termocuplas
B9: A3 | C9: Salida de galletitas horneadas y descarga | D9: 1.2 | E9: 1.3 | F9: 1 | G9: =D9*E9*F9 | H9: Zona de descarga y despegue con cuchilla de aire | I9: Transferencia suave hacia cinta de enfriamiento
B10: A4 | C10: Rampa de gas, quemador y tablero PID | D10: 1.5 | E10: 0.8 | F10: 1 | G10: =D10*E10*F10 | H10: Grupo térmico gas natural + tablero electrónico | I10: Alimentación segura de gas, tren de válvulas y PID | N10: A4 | S10: A0 Horno Túnel Polin (6m x 1,3m) | X10: A2
B11: A5 | C11: Aislamiento térmico perimetral y seguridad | D11: 0.6 | E11: 6 | F11: 1 | G11: =D11*E11*F11 | H11: 0,6 m de separación por radiación térmica de muros | I11: Protección al personal contra quemaduras y calor radiante
B12: A6 | C12: Pasillo principal de circulación y mantenimiento | D12: 1.2 | E12: 8.4 | F12: 1 | G12: =D12*E12*F12 | H12: Pasillo ancho para tránsito y mantenimiento pesado | I12: Circulación longitudinal principal de la nave
B13: A7 | C13: Campana de extracción de vahos y chimenea | D13: 1 | E13: 1.3 | F13: 1 | G13: =D13*E13*F13 | H13: Campana de captación en cabezales y tiro forzado | I13: Evacuación de humedad y productos de combustión
B14: TOTAL | C14: Superficie Total Asignada al Puesto | G14: =SUM(G6:G13)
B16: PARÁMETROS TÉCNICOS DEL EQUIPO / PUESTO | E16: ESPECIFICACIÓN / VALOR
B17: Marca y Proveedor | E17: Ing. Polin e C. S.p.A. (Cyclothermic Tunnel Oven)
B18: Dimensiones Exteriores | E18: 6000 mm (Largo) x 1300 mm (Ancho total con aislamiento) x 2000 mm (Alto)
B19: Ancho de Banda Útil | E19: 700 mm (Malla de acero al carbono perforado) | N19: A5
B20: Superficie Estática (Ss) | E20: 7,80 m² (Actualizado en BOM y Balanceo: 6,00 m x 1,30 m)
B21: Fuente de Alimentación | E21: Gas Natural (Quemador modular 52 kW) + 380 V Trifásica
B22: Temperatura y Tiempo | E22: 160°C a 240°C regulable | Tiempo de cocción: 6,5 minutos
B24: Proyecto Final UTN FRBA | Grupo 8 - Planta CELI (Alimentos Sin Gluten) | Relevamiento de Superficies y Layout
S29: A1
M36: REFERENCIAS DE LAYOUT:
M37: A0: Máquina Principal | A1: MP en espera | A2: Operación/Alimentación | A3: Salida de Producto
M38: A4: Tablero / Mando | A5: Seguridad Lateral | A6: Pasillo Circulación | A7: Buffer Semielaborado (SE)

Sheet Enfriado Galletitas
B2: ENFRIADO - CINTA CONTINUA | L2: Escala: 1 celda ≈ 0.25 m x 0.25 m (Largo: 20 celdas | Ancho: 4 celdas)
B3: Línea A - Galletitas | Cinta de Enfriamiento por Convección Golden Way (5,00 m Largo x 0,80 m Ancho)
S4: A7 | AB4: A6
B5: Subarea | C5: Descripción / Denominación | D5: Largo (m) | E5: Ancho (m) | F5: Cant. | G5: Superficie (m²) | H5: Justificación | I5: Función
B6: A0 | C6: Cinta Transportadora de Enfriamiento por Aire | D6: 5 | E6: 0.8 | F6: 1 | G6: =D6*E6*F6 | H6: Fabricante Golden Way (Largo 5,0 m para t_enfriado) | I6: Descenso térmico controlado hasta temperatura ambiente
B7: A1 | C7: Entrada continua desde descarga del horno | D7: 0.8 | E7: 0.8 | F7: 1 | G7: =D7*E7*F7 | H7: Acople de transición mecánica y rampa guiada | I7: Recepción de galletitas cocidas calientes | S7: A3
B8: A2 | C8: Área de inspección de calidad y alineación | D8: 5 | E8: 0.9 | F8: 1 | G8: =D8*E8*F8 | H8: Puesto de control visual a lo largo de la cinta | I8: Detección y descarte de unidades rotas o deformadas
B9: A3 | C9: Descarga y caída a tolva de envasado | D9: 1 | E9: 0.8 | F9: 1 | G9: =D9*E9*F9 | H9: Rampa de gravedad en acero inoxidable pulido | I9: Alimentación hacia el elevador Z de la envasadora
B10: A4 | C10: Motorreductor, variador de avance y sopladores | D10: 0.8 | E10: 0.5 | F10: 1 | G10: =D10*E10*F10 | H10: Grupo motriz inferior con ventiladores axiales | I10: Impulsión de banda y flujo de aire filtrado | N10: A4 | S10: A0 Cinta de Enfriado (5m x 0,8m) | W10: A2
B11: A5 | C11: Espacio de seguridad lateral y limpieza | D11: 0.5 | E11: 5 | F11: 1 | G11: =D11*E11*F11 | H11: 0,5 m lateral libre para acceso sanitario | I11: Limpieza diaria de migas y bandejas inferiores
B12: A6 | C12: Pasillo de circulación lateral | D12: 1 | E12: 6.5 | F12: 1 | G12: =D12*E12*F12 | H12: Pasillo de circulación intersectorial | I12: Tránsito peatonal y supervisión continua
B13: A7 | C13: Pulmón dinámico acumulador ante paradas (SE) | D13: 1.5 | E13: 0.8 | F13: 1 | G13: =D13*E13*F13 | H13: Bandejas acumuladoras de desvío de emergencia | I13: Buffer de amortiguamiento si la envasadora se detiene
B14: TOTAL | C14: Superficie Total Asignada al Puesto | G14: =SUM(G6:G13)
B16: PARÁMETROS TÉCNICOS DEL EQUIPO / PUESTO | E16: ESPECIFICACIÓN / VALOR
B17: Marca y Proveedor | E17: Hebei Golden Way Machinery (SUS304 Food Grade)
B18: Dimensiones de la Cinta | E18: 5000 mm (Largo) x 800 mm (Ancho) x 1000 mm (Alto) | N18: A5
B19: Superficie Estática (Ss) | E19: 4,00 m² (según BOM y Balanceo: 5,0 m x 0,8 m)
B20: Potencia y Voltaje | E20: 2,20 kW | 220 V / 380 V con motovariador electrónico
B21: Tiempo de Enfriamiento | E21: 4 a 8 minutos (ajustable por velocidad de avance)
B22: Capacidad de Caudal | E22: 82,74 kg/h (sincronizada con régimen de horno)
B24: Proyecto Final UTN FRBA | Grupo 8 - Planta CELI (Alimentos Sin Gluten) | Relevamiento de Superficies y Layout
S27: A1
M34: REFERENCIAS DE LAYOUT:
M35: A0: Máquina Principal | A1: MP en espera | A2: Operación/Alimentación | A3: Salida de Producto
M36: A4: Tablero / Mando | A5: Seguridad Lateral | A6: Pasillo Circulación | A7: Buffer Semielaborado (SE)

Sheet Envasado 1° Galletitas
B2: ENVASADO PRIMARIO - LÍNEA GALLETITAS | L2: Escala: 1 celda ≈ 0.20 m x 0.20 m
B3: Línea A - Galletitas | Envasadora Vertical ZON PACK ZH-BL-10 + Detector de Metales
S4: A7
B5: Subarea | C5: Descripción / Denominación | D5: Largo (m) | E5: Ancho (m) | F5: Cant. | G5: Superficie (m²) | H5: Justificación | I5: Función
B6: A0 | C6: Envasadora Vertical Flow-Pack + Multicabezal | D6: 1.53 | E6: 0.97 | F6: 1 | G6: =D6*E6*F6 | H6: Fabricante ZON PACK (ZH-BL-10: 1530 x 970 mm) | I6: Formado de tubo, pesaje, dosificado y sellado hermético
B7: A1 | C7: Elevador de cangilones / Tolva de alimentación | D7: 1.2 | E7: 0.8 | F7: 1 | G7: =D7*E7*F7 | H7: Elevador Z de acero inoxidable grado alimentario | I7: Elevación continua de galletas hacia la tolva superior
B8: A2 | C8: Puesto del operador y recambio de bobinas | D8: 1.5 | E8: 1.2 | F8: 1 | G8: =D8*E8*F8 | H8: Espacio frontal para montaje de rollos de film (20 kg) | I8: Operación táctil HMI, carga de film y fotocélula | R8: A3 | AB8: A6
B9: A3 | C9: Cinta inclinada de salida de paquetes listos | D9: 1.5 | E9: 0.6 | F9: 1 | G9: =D9*E9*F9 | H9: Cinta transportadora de descarga con rampa | I9: Transporte de paquetes hacia el detector de metales
B10: A4 | C10: Tablero HMI, codificador láser e inyector N2 | D10: 0.8 | E10: 0.5 | F10: 1 | G10: =D10*E10*F10 | H10: Módulos auxiliares de trazabilidad e inertización | I10: Fechado de lote/vencimiento e inyección de gas protector
B11: A5 | C11: Espacio de seguridad y servicio de mordazas | D11: 0.5 | E11: 1.5 | F11: 2 | G11: =D11*E11*F11 | H11: 0,5 m perimetral para cambio de teflón y resistencias | I11: Mantenimiento seguro y cambio de formatos de tubo
B12: A6 | C12: Pasillo de circulación intersectorial | D12: 1 | E12: 3.5 | F12: 1 | G12: =D12*E12*F12 | H12: Pasillo libre de tránsito de materiales | I12: Circulación de personal y reposición de bobinas
B13: A7 | C13: Detector de metales en línea con rechazo neumático | D13: 1.2 | E13: 0.6 | F13: 1 | G13: =D13*E13*F13 | H13: Punto Crítico de Control (PCC) según plan HACCP | I13: Detección de metales ferrosos/no ferrosos y descarte
B14: TOTAL | C14: Superficie Total Asignada al Puesto | G14: =SUM(G6:G13) | N14: A4 | R14: A0 Envasadora Vertical ZH-BL-10 | Z14: A5
B16: PARÁMETROS TÉCNICOS DEL EQUIPO / PUESTO | E16: ESPECIFICACIÓN / VALOR
B17: Marca y Modelo | E17: ZON PACK ZH-BL-10 (Envasadora vertical flow-pack)
B18: Dimensiones del Equipo | E18: 1530 mm (Largo) x 970 mm (Ancho) x 1700 mm (Alto)
B19: Superficie Estática (Ss) | E19: 1,4841 m² (según BOM y Balanceo: 1,53 m x 0,97 m)
B20: Potencia y Voltaje | E20: 6,50 kW | 220 V / 50 Hz monofásica/trifásica | M20: A1 | R20: A2
B21: Velocidad de Envasado | E21: 30 a 70 paquetes/minuto (Capacidad: 270 kg/h)
B22: Formato de Empaque | E22: Paquete flow-pack 150 g con atmósfera inerte (N2)
B24: Proyecto Final UTN FRBA | Grupo 8 - Planta CELI (Alimentos Sin Gluten) | Relevamiento de Superficies y Layout
M29: REFERENCIAS DE LAYOUT:
M30: A0: Máquina Principal | A1: MP en espera | A2: Operación/Alimentación | A3: Salida de Producto
M31: A4: Tablero / Mando | A5: Seguridad Lateral | A6: Pasillo Circulación | A7: Buffer Semielaborado (SE)

Sheet Envasado 2° Galletitas
B2: ENVASADO SECUNDARIO - LÍNEA GALLETITAS | L2: Escala: 1 celda ≈ 0.20 m x 0.20 m
B3: Línea A - Galletitas | Mesa de Trabajo Ergonómica, Encajonado y Paletizado
S4: A7
B5: Subarea | C5: Descripción / Denominación | D5: Largo (m) | E5: Ancho (m) | F5: Cant. | G5: Superficie (m²) | H5: Justificación | I5: Función
B6: A0 | C6: Mesa de Trabajo en Acero Inoxidable AISI 304 | D6: 1.2 | E6: 0.8 | F6: 1 | G6: =D6*E6*F6 | H6: Mesa estándar ergonómica de empaque (1200x800mm) | I6: Superficie de apoyo para conformado y llenado de cajas
B7: A1 | C7: Buffer de paquetes recibidos desde detector | D7: 0.8 | E7: 0.6 | F7: 1 | G7: =D7*E7*F7 | H7: Bandeja acumuladora proveniente de envasado 1° | I7: Recepción de paquetes flow-pack verificados
B8: A2 | C8: Puesto del operario de encajonado | D8: 1.2 | E8: 1 | F8: 1 | G8: =D8*E8*F8 | H8: Espacio ergonómico de pie sobre alfombra antifatiga | I8: Conformado de cajas, colocación de 20 unidades y control | R8: A3 | AB8: A6
B9: A3 | C9: Soporte para cajas corrugadas plegadas | D9: 0.8 | E9: 0.6 | F9: 1 | G9: =D9*E9*F9 | H9: Estante inferior/lateral para cajas desarmadas | I9: Alimentación rápida de cajas vacías
B10: A4 | C10: Precintadora manual y dispensador de rótulos | D10: 0.5 | E10: 0.4 | F10: 1 | G10: =D10*E10*F10 | H10: Dispensador de cinta adhesiva y etiquetas código barras | I10: Cerrado superior e inferior y etiquetado de trazabilidad
B11: A5 | C11: Espacio de seguridad y ergonomía postural | D11: 0.5 | E11: 1.2 | F11: 1 | G11: =D11*E11*F11 | H11: Zona libre perimetral sin obstáculos de tropiezo | I11: Seguridad y rotación postural del trabajador
B12: A6 | C12: Pasillo de circulación y retiro de zorras | D12: 1.2 | E12: 3 | F12: 1 | G12: =D12*E12*F12 | H12: Ancho mínimo para tránsito de zorras hidráulicas | I12: Retiro de pallets conformados hacia Depósito PT
B13: A7 | C13: Pallet en conformación con cajas terminadas (PT) | D13: 1.2 | E13: 1 | F13: 1 | G13: =D13*E13*F13 | H13: Pallet Arlog (1,2 x 1,0 m) en proceso de estibado | I13: Estiba de cajas terminadas previo al stretch filmado
B14: TOTAL | C14: Superficie Total Asignada al Puesto | G14: =SUM(G6:G13) | N14: A4 | R14: A0 Mesa de Encajonado Manual | Z14: A5
B16: PARÁMETROS TÉCNICOS DEL EQUIPO / PUESTO | E16: ESPECIFICACIÓN / VALOR
B17: Tipo de Puesto | E17: Mesa de envasado secundario manual en acero inoxidable
B18: Dimensiones de la Mesa | E18: 1200 mm (Largo) x 800 mm (Ancho) x 800 mm (Alto)
B19: Superficie Estática (Ss) | E19: 0,96 m² (según BOM y Balanceo: 1,20 m x 0,80 m)
B20: Formato de Embalaje | E20: Caja de cartón corrugado x 20 paquetes (3,00 kg netos) | M20: A1 | R20: A2
B21: Equipamiento Auxiliar | E21: Dispensador de cinta de embalaje, etiquetadora y balanza de control
B22: Rendimiento | E22: 1 caja/minuto por operario (Capacidad holgada para línea)
B24: Proyecto Final UTN FRBA | Grupo 8 - Planta CELI (Alimentos Sin Gluten) | Relevamiento de Superficies y Layout
M29: REFERENCIAS DE LAYOUT:
M30: A0: Máquina Principal | A1: MP en espera | A2: Operación/Alimentación | A3: Salida de Producto
M31: A4: Tablero / Mando | A5: Seguridad Lateral | A6: Pasillo Circulación | A7: Buffer Semielaborado (SE)

Sheet Batido Panificados
B2: BATIDO - LÍNEA PANIFICADOS | L2: Escala: 1 celda ≈ 0.20 m x 0.20 m
B3: Línea B - Panificados | Batidora Planetaria Industrial Moretti Ultra 60 (60 L / 37,5 kg)
S4: A7
B5: Subarea | C5: Descripción / Denominación | D5: Largo (m) | E5: Ancho (m) | F5: Cant. | G5: Superficie (m²) | H5: Justificación | I5: Función
B6: A0 | C6: Batidora Planetaria Industrial de 60 Litros | D6: 1.1 | E6: 0.91 | F6: 1 | G6: =D6*E6*F6 | H6: Fabricante Moretti (Ultra 60: 1100 x 910 mm) | I6: Batido, emulsión y aireado de masas de budín y pan
B7: A1 | C7: Bines con ingredientes secos y líquidos dosificados | D7: 0.8 | E7: 0.6 | F7: 1 | G7: =D7*E7*F7 | H7: Contenedores rodantes plásticos grado alimentario | I7: Espera de ingredientes pesados listos para verter
B8: A2 | C8: Puesto del operador y sistema de elevación | D8: 1.3 | E8: 1.1 | F8: 1 | G8: =D8*E8*F8 | H8: Área de izado y desmontaje del tacho de 60L | I8: Carga de materias primas, encastre y control de batido | R8: A3 | AB8: A6
B9: A3 | C9: Zona de extracción de tacho con masa batida | D9: 1 | E9: 0.9 | F9: 1 | G9: =D9*E9*F9 | H9: Zona de desacople y descenso del tacho con bache listo | I9: Retiro rodante del tacho hacia el puesto de dosificado
B10: A4 | C10: Tablero eléctrico, temporizador y selector | D10: 0.6 | E10: 0.4 | F10: 1 | G10: =D10*E10*F10 | H10: Gabinete estanco integrado con parada de emergencia | I10: Control de velocidades, temporizado y seguridad de rejilla
B11: A5 | C11: Espacio de seguridad lateral y apertura de rejilla | D11: 0.5 | E11: 1 | F11: 2 | G11: =D11*E11*F11 | H11: 0,5 m lateral para resguardo y fácil lavado | I11: Seguridad contra atrapamiento y limpieza profunda
B12: A6 | C12: Pasillo de circulación interna de panificados | D12: 1 | E12: 2.8 | F12: 1 | G12: =D12*E12*F12 | H12: Pasillo de tránsito para operarios y carros | I12: Circulación peatonal y traslado rodante de tachos
B13: A7 | C13: Tacho auxiliar de repuesto / carro porta-tacho | D13: 0.8 | E13: 0.8 | F13: 1 | G13: =D13*E13*F13 | H13: Segundo tacho de acero inoxidable para rotación continua | I13: Permite iniciar el pesaje del siguiente lote sin demoras
B14: TOTAL | C14: Superficie Total Asignada al Puesto | G14: =SUM(G6:G13) | N14: A4 | R14: A0 Batidora Moretti Ultra 60 | Z14: A5
B16: PARÁMETROS TÉCNICOS DEL EQUIPO / PUESTO | E16: ESPECIFICACIÓN / VALOR
B17: Marca y Modelo | E17: Moretti Ultra 60 (Batidora Planetaria Comercial Pesada)
B18: Capacidad de Tacho | E18: 60 Litros / 37,5 kg de masa batida líquida/semilíquida
B19: Dimensiones del Equipo | E19: 1100 mm (Largo) x 910 mm (Ancho) x 1580 mm (Alto)
B20: Superficie Estática (Ss) | E20: 1,001 m² (según BOM y Balanceo: 1,10 m x 0,91 m) | M20: A1 | R20: A2
B21: Potencia y Voltaje | E21: 2,50 kW | 380 V trifásica (3 velocidades mecánicas)
B22: Tiempo de Batido | E22: 18 a 20 min por bache (Capacidad teórica: 112,5 kg/h)
B24: Proyecto Final UTN FRBA | Grupo 8 - Planta CELI (Alimentos Sin Gluten) | Relevamiento de Superficies y Layout
M29: REFERENCIAS DE LAYOUT:
M30: A0: Máquina Principal | A1: MP en espera | A2: Operación/Alimentación | A3: Salida de Producto
M31: A4: Tablero / Mando | A5: Seguridad Lateral | A6: Pasillo Circulación | A7: Buffer Semielaborado (SE)

Sheet Dosificado Panificados
B2: DOSIFICADO - LÍNEA PANIFICADOS | L2: Escala: 1 celda ≈ 0.20 m x 0.20 m
B3: Línea B - Panificados | Dosificadora Volumétrica Neumática Indurpack G1WGD-1000
S4: A7
B5: Subarea | C5: Descripción / Denominación | D5: Largo (m) | E5: Ancho (m) | F5: Cant. | G5: Superficie (m²) | H5: Justificación | I5: Función
B6: A0 | C6: Dosificadora Neumática sobre Mesa Inox | D6: 1.16 | E6: 0.3 | F6: 1 | G6: =D6*E6*F6 | H6: Fabricante Indurpack (Tolva 40L, pistón SUS304) | I6: Dosificación volumétrica exacta en moldes de pan y budín
B7: A1 | C7: Carro con moldes y bandejas vacías aceitadas | D7: 0.9 | E7: 0.7 | F7: 1 | G7: =D7*E7*F7 | H7: Carro porta-bandejas estándar (450 x 700 mm) | I7: Alimentación de bandejas vacías hacia la boquilla
B8: A2 | C8: Puesto de trabajo del operador con pedal | D8: 1.2 | E8: 1 | F8: 1 | G8: =D8*E8*F8 | H8: Puesto ergonómico sentado/parado con accionador | I8: Posicionamiento de moldes bajo pico y disparo | R8: A3 | AB8: A6
B9: A3 | C9: Mesa de transferencia de bandejas llenas | D9: 1.2 | E9: 0.6 | F9: 1 | G9: =D9*E9*F9 | H9: Mesa de rodillos libres en acero inoxidable | I9: Recepción de moldes cargados y verificación de peso
B10: A4 | C10: Unidad de Mantenimiento Neumático (FRL) | D10: 0.5 | E10: 0.4 | F10: 1 | G10: =D10*E10*F10 | H10: Filtro, regulador de presión y manómetro | I10: Alimentación de aire comprimido seco y regulación
B11: A5 | C11: Espacio de seguridad lateral y limpieza | D11: 0.5 | E11: 1.2 | F11: 1 | G11: =D11*E11*F11 | H11: Distancia libre para desmontaje y lavado de tolva | I11: Sanitización CIP y seguridad operativa
B12: A6 | C12: Pasillo de circulación y maniobra de carros | D12: 1 | E12: 3 | F12: 1 | G12: =D12*E12*F12 | H12: Pasillo interno de circulación de carros | I12: Circulación de personal y transporte de carros
B13: A7 | C13: Carro porta-bandejas cargado listo (SE) | D13: 0.9 | E13: 0.7 | F13: 1 | G13: =D13*E13*F13 | H13: Carro con 15 bandejas cargadas con moldes | I13: Espera previa a fermentación (pan) o cocción (budín)
B14: TOTAL | C14: Superficie Total Asignada al Puesto | G14: =SUM(G6:G13) | N14: A4 | R14: A0 Dosificadora Indurpack G1WGD | Z14: A5
B16: PARÁMETROS TÉCNICOS DEL EQUIPO / PUESTO | E16: ESPECIFICACIÓN / VALOR
B17: Marca y Modelo | E17: Indurpack G1WGD-1000 (Dosificadora neumática de pistón)
B18: Capacidad de Tolva | E18: 40 Litros en acero inoxidable SUS304
B19: Dimensiones del Equipo | E19: 1160 mm (Largo) x 300 mm (Ancho) x 450 mm (Alto)
B20: Superficie Estática (Ss) | E20: 0,348 m² (en BOM: 1,16 m x 0,30 m sobre bancada) | M20: A1 | R20: A2
B21: Alimentación y Consumo | E21: 220 V / 50 Hz + Aire comprimido 0,4-0,6 MPa (100 W)
B22: Rango de Dosificación | E22: 100 a 1000 mL por ciclo (10 a 30 dosificaciones/min)
B24: Proyecto Final UTN FRBA | Grupo 8 - Planta CELI (Alimentos Sin Gluten) | Relevamiento de Superficies y Layout
M29: REFERENCIAS DE LAYOUT:
M30: A0: Máquina Principal | A1: MP en espera | A2: Operación/Alimentación | A3: Salida de Producto
M31: A4: Tablero / Mando | A5: Seguridad Lateral | A6: Pasillo Circulación | A7: Buffer Semielaborado (SE)

Sheet Fermentado Panificados
B2: FERMENTADO - CÁMARA CONTROLADA | L2: Escala: 1 celda ≈ 0.20 m x 0.20 m
B3: Línea B - Panificados | Cámara Fermentadora Nick Technology NKF-36RS (36 Bandejas)
S4: A7
B5: Subarea | C5: Descripción / Denominación | D5: Largo (m) | E5: Ancho (m) | F5: Cant. | G5: Superficie (m²) | H5: Justificación | I5: Función
B6: A0 | C6: Cámara Fermentadora Termohigrométrica | D6: 0.98 | E6: 0.58 | F6: 1 | G6: =D6*E6*F6 | H6: Fabricante Nick Technology (NKF-36RS: 980x580mm) | I6: Leudado biológico controlado para pan de molde
B7: A1 | C7: Carro con bandejas dosificadas en espera | D7: 0.9 | E7: 0.7 | F7: 1 | G7: =D7*E7*F7 | H7: Carro proveniente de la estación de dosificado | I7: Espera antes del ingreso a la cámara de fermentación
B8: A2 | C8: Zona de apertura de puertas y carga/descarga | D8: 1.2 | E8: 1 | F8: 1 | G8: =D8*E8*F8 | H8: Radio de apertura de puertas batientes (90°) y paso | I8: Carga manual de bandejas en las guías internas | R8: A3 | AB8: A6
B9: A3 | C9: Carro para recepción de producto fermentado | D9: 0.9 | E9: 0.7 | F9: 1 | G9: =D9*E9*F9 | H9: Carro limpio listo para recibir producto con leudado | I9: Descarga de bandejas leudadas hacia horno rotativo
B10: A4 | C10: Tablero electrónico de control de microclima | D10: 0.5 | E10: 0.4 | F10: 1 | G10: =D10*E10*F10 | H10: Módulo de control digital de temperatura y humedad | I10: Regulación de resistencia calefactora y humidificador
B11: A5 | C11: Espacio de ventilación trasera y lateral | D11: 0.5 | E11: 1 | F11: 1 | G11: =D11*E11*F11 | H11: 0,5 m de separación de tabiques para disipación | I11: Ventilación de condensados y seguridad eléctrica
B12: A6 | C12: Pasillo de circulación de carros | D12: 1.2 | E12: 2.8 | F12: 1 | G12: =D12*E12*F12 | H12: Pasillo de circulación apto para carros rodantes | I12: Transporte fluido entre dosificado, cámara y horno
B13: A7 | C13: Pulmón de carros fermentados pre-horneo (SE) | D13: 0.9 | E13: 0.7 | F13: 1 | G13: =D13*E13*F13 | H13: Carro con panes leudados en tiempo crítico de espera | I13: Pulmón de sincronización con la tanda del horno rotativo
B14: TOTAL | C14: Superficie Total Asignada al Puesto | G14: =SUM(G6:G13) | N14: A4 | R14: A0 Fermentador NKF-36RS | Z14: A5
B16: PARÁMETROS TÉCNICOS DEL EQUIPO / PUESTO | E16: ESPECIFICACIÓN / VALOR
B17: Marca y Proveedor | E17: BestBake / Nick Technology (NKF-36RS)
B18: Capacidad de Carga | E18: 36 bandejas (450 x 700 mm) distribuidas en 2 columnas
B19: Dimensiones del Equipo | E19: 980 mm (Largo) x 580 mm (Ancho) x 2050 mm (Alto)
B20: Superficie Estática (Ss) | E20: 0,5684 m² (según BOM y Balanceo: 0,98 m x 0,58 m) | M20: A1 | R20: A2
B21: Potencia y Voltaje | E21: 1,80 kW | 220 V / 50 Hz monofásica
B22: Parámetros de Proceso | E22: Temperatura: 32°C a 38°C | Humedad Relativa: 75% a 85%
B24: Proyecto Final UTN FRBA | Grupo 8 - Planta CELI (Alimentos Sin Gluten) | Relevamiento de Superficies y Layout
M29: REFERENCIAS DE LAYOUT:
M30: A0: Máquina Principal | A1: MP en espera | A2: Operación/Alimentación | A3: Salida de Producto
M31: A4: Tablero / Mando | A5: Seguridad Lateral | A6: Pasillo Circulación | A7: Buffer Semielaborado (SE)

Sheet Horneado Panificados
B2: HORNEADO - BATERÍA HORNOS ROTATIVOS | L2: Escala: 1 celda ≈ 0.25 m x 0.25 m
B3: Línea B - Panificados | Batería de 2 Hornos Rotativos Pauna SIGMA B-7090 a Carro
Q4: A7 | AA4: A6
B5: Subarea | C5: Descripción / Denominación | D5: Largo (m) | E5: Ancho (m) | F5: Cant. | G5: Superficie (m²) | H5: Justificación | I5: Función
B6: A0 | C6: Batería de 2 Hornos Rotativos a Carro | D6: 1.95 | E6: 3.4 | F6: 1 | G6: =D6*E6*F6 | H6: Fabricante Pauna (2 hornos SIGMA B-7090 acoplados) | I6: Cocción por convección forzada y rotación de carro
B7: A1 | C7: Carros con producto leudado / dosificado en espera | D7: 1.6 | E7: 0.9 | F7: 1 | G7: =D7*E7*F7 | H7: Espacio para 2 carros listos para horneo sincronizado | I7: Espera inmediata frente a la embocadura de los hornos | Q7: A3
B8: A2 | C8: Área de maniobra térmica y carga/descarga | D8: 2 | E8: 3.4 | F8: 1 | G8: =D8*E8*F8 | H8: Radio de giro y enganche/desenganche al rotor superior | I8: Introducción y extracción de carros calientes con EPP
B9: A3 | C9: Zona de desalojo y salida de carros calientes | D9: 1.8 | E9: 1.2 | F9: 1 | G9: =D9*E9*F9 | H9: Zona de desalojo rápido de carros a 200°C | I9: Extracción hacia el área de reposo y enfriamiento
B10: A4 | C10: Tableros de control con vaporizador y rampa gas | D10: 1.2 | E10: 0.6 | F10: 1 | G10: =D10*E10*F10 | H10: Paneles de comando, quemadores y electroválvulas vapor | I10: Programación de recetas térmicas, inyección de vapor y alarmas
B11: A5 | C11: Aislamiento térmico perimetral y seguridad | D11: 0.8 | E11: 4 | F11: 1 | G11: =D11*E11*F11 | H11: 0,8 m libre contra irradiación térmica de paredes | I11: Protección de operarios e instalaciones contra calor
B12: A6 | C12: Pasillo de circulación principal para carros | D12: 1.5 | E12: 5 | F12: 1 | G12: =D12*E12*F12 | H12: Pasillo ancho para maniobra pesada de carros calientes | I12: Circulación segura en área de alta temperatura | L12: A4 | Q12: A0 Hornos Rotativos (x2)
B13: A7 | C13: Campanas de extracción de vahos y chimenea | D13: 2 | E13: 1 | F13: 1 | G13: =D13*E13*F13 | H13: Campanas de acero inox con tiro forzado sobre puertas | I13: Extracción de vahos y vapores calientes al abrir
B14: TOTAL | C14: Superficie Total Asignada al Puesto | G14: =SUM(G6:G13)
B16: PARÁMETROS TÉCNICOS DEL EQUIPO / PUESTO | E16: ESPECIFICACIÓN / VALOR
B17: Marca y Modelo | E17: Pauna SIGMA B-7090 (Batería de 2 unidades industriales) | L17: A5
B18: Capacidad por Horno | E18: 1 carro de 15 bandejas (700x900 mm / 450x700 mm)
B19: Dimensiones por Unidad | E19: 1950 mm (Largo) x 1600 mm (Ancho) x 2550 mm (Alto)
B20: Superficie Estática (Ss) | E20: 6,24 m² (2 unidades x 3,12 m² c/u según BOM)
B21: Potencia Térmica / Combustible | E21: 70.000 kcal/h c/u (Gas Natural) + 1,84 kW potencia motriz | L21: A1 | Q21: A2
B22: Tiempo de Horneado | E22: 45 min por horneada (Capacidad total batería: 90,24 kg/h)
B24: Proyecto Final UTN FRBA | Grupo 8 - Planta CELI (Alimentos Sin Gluten) | Relevamiento de Superficies y Layout
L30: REFERENCIAS DE LAYOUT:
L31: A0: Máquina Principal | A1: MP en espera | A2: Operación/Alimentación | A3: Salida de Producto
L32: A4: Tablero / Mando | A5: Seguridad Lateral | A6: Pasillo Circulación | A7: Buffer Semielaborado (SE)

Sheet Enfriado Panificados
B2: ENFRIADO - SECTOR DE CARROS | L2: Escala: 1 celda ≈ 0.25 m x 0.25 m
B3: Línea B - Panificados | Estacionamiento Estático de Carros Porta-Bandejas (Enfriamiento 60 min)
Q4: A7 | AA4: A6
B5: Subarea | C5: Descripción / Denominación | D5: Largo (m) | E5: Ancho (m) | F5: Cant. | G5: Superficie (m²) | H5: Justificación | I5: Función
B6: A0 | C6: Batería de 4 Carros Porta-Bandejas en Reposo | D6: 3 | E6: 1.6 | F6: 1 | G6: =D6*E6*F6 | H6: 4 carros estándar en paralelo con espaciado convectivo | I6: Enfriamiento natural por aire ambiental de panes y budines
B7: A1 | C7: Ingreso de carros recién salidos del horno | D7: 1.2 | E7: 0.9 | F7: 1 | G7: =D7*E7*F7 | H7: Punto de acceso directo desde horneado rotativo | I7: Estacionamiento de carros calientes entrantes | Q7: A3
B8: A2 | C8: Pasillo interno de inspección y desmolde | D8: 3 | E8: 1 | F8: 1 | G8: =D8*E8*F8 | H8: Pasillo peatonal entre filas de carros | I8: Control de temperatura interna y desmolde de budines
B9: A3 | C9: Salida de carros templados hacia rebanado/empaque | D9: 1.2 | E9: 0.9 | F9: 1 | G9: =D9*E9*F9 | H9: Carros con producto a temperatura ambiente | I9: Egreso de carros hacia rebanadora de pan y flow-pack
B10: A4 | C10: Mesa de desmolde y estantería de moldes limpios | D10: 1.2 | E10: 0.8 | F10: 1 | G10: =D10*E10*F10 | H10: Mesa de apoyo auxiliar en acero inoxidable | I10: Desmolde manual y apilado ordenado de moldes vacíos
B11: A5 | C11: Espacio perimetral de convección de aire | D11: 0.6 | E11: 4 | F11: 1 | G11: =D11*E11*F11 | H11: Distancia libre para flujo convectivo de aire natural | I11: Garantizar disipación homogénea de calor y humedad
B12: A6 | C12: Pasillo de circulación intersectorial | D12: 1.2 | E12: 4.5 | F12: 1 | G12: =D12*E12*F12 | H12: Pasillo de circulación principal para carros | I12: Traslado rodante de carros y tránsito general | L12: A4 | Q12: A0 Sector Carros Enfriado
B13: A7 | C13: Pulmón de bandejas con producto desmoldado (SE) | D13: 1.2 | E13: 0.9 | F13: 1 | G13: =D13*E13*F13 | H13: Carro porta-bandejas con budines listos para envoltura | I13: Pulmón de amortiguamiento antes del envasado primario
B14: TOTAL | C14: Superficie Total Asignada al Puesto | G14: =SUM(G6:G13)
B16: PARÁMETROS TÉCNICOS DEL EQUIPO / PUESTO | E16: ESPECIFICACIÓN / VALOR
B17: Tipo de Sector | E17: Sector delimitado para enfriamiento convectivo natural de carros | L17: A5
B18: Capacidad de Estacionamiento | E18: 4 carros porta-bandejas en paralelo con espaciado de aire
B19: Dimensiones de la Batería | E19: 3000 mm (Largo) x 1600 mm (Ancho) x 1800 mm (Alto)
B20: Superficie Estática (Ss) | E20: 4,80 m² (Área asignada total del sector: 8,00 m² según BOM)
B21: Tiempo de Residencia Térmica | E21: 60 minutos para descenso a temperatura segura (<30°C) | L21: A1 | Q21: A2
B22: Operaciones Asociadas | E22: Desmolde manual de budines y verificación de panes
B24: Proyecto Final UTN FRBA | Grupo 8 - Planta CELI (Alimentos Sin Gluten) | Relevamiento de Superficies y Layout
L30: REFERENCIAS DE LAYOUT:
L31: A0: Máquina Principal | A1: MP en espera | A2: Operación/Alimentación | A3: Salida de Producto
L32: A4: Tablero / Mando | A5: Seguridad Lateral | A6: Pasillo Circulación | A7: Buffer Semielaborado (SE)

Sheet Rebanadora Pan
B2: REBANADO - LÍNEA PAN DE MOLDE | L2: Escala: 1 celda ≈ 0.20 m x 0.20 m
B3: Línea B - Panificados | Cortadora / Rebanadora Continua de Pan Braesi FB-12 G2
S4: A7
B5: Subarea | C5: Descripción / Denominación | D5: Largo (m) | E5: Ancho (m) | F5: Cant. | G5: Superficie (m²) | H5: Justificación | I5: Función
B6: A0 | C6: Máquina Rebanadora de Pan de Molde | D6: 0.72 | E6: 0.48 | F6: 1 | G6: =D6*E6*F6 | H6: Fabricante Braesi (FB-12 G2: 721 x 477 mm) | I6: Corte simultáneo y uniforme de pan de molde sin desgranar
B7: A1 | C7: Bandeja con panes enteros fríos en espera | D7: 0.7 | E7: 0.5 | F7: 1 | G7: =D7*E7*F7 | H7: Contenedor de panes desmoldados listos para corte | I7: Espera de panes fríos para ingresar a máquina
B8: A2 | C8: Puesto del operador y rampa de embolse | D8: 1.2 | E8: 1 | F8: 1 | G8: =D8*E8*F8 | H8: Espacio ergonómico de empuje y recepción rápida | I8: Alimentación de panes y sostenimiento del paquete | R8: A3 | AB8: A6
B9: A3 | C9: Rampa de salida y soporte de rodajas | D9: 0.7 | E9: 0.5 | F9: 1 | G9: =D9*E9*F9 | H9: Bandeja acanalada receptora con guías de alineación | I9: Mantenimiento del pan armado para su embolsado
B10: A4 | C10: Botonera de mando, ajuste de tensión y paro | D10: 0.4 | E10: 0.3 | F10: 1 | G10: =D10*E10*F10 | H10: Columna de mando y palanca de tensión de cuchillas | I10: Control de marcha, parada y recambio de cuchillas
B11: A5 | C11: Espacio de seguridad y guarda protectora | D11: 0.5 | E11: 0.8 | F11: 1 | G11: =D11*E11*F11 | H11: Protección perimetral de mecanismos móviles de corte | I11: Seguridad contra atrapamiento y corte del operador
B12: A6 | C12: Pasillo de circulación interna | D12: 1 | E12: 2.5 | F12: 1 | G12: =D12*E12*F12 | H12: Pasillo de circulación intersectorial | I12: Tránsito peatonal y traslado de producto
B13: A7 | C13: Bandeja pulmón de panes rebanados (SE) | D13: 0.8 | E13: 0.6 | F13: 1 | G13: =D13*E13*F13 | H13: Bandeja de transferencia hacia la envasadora | I13: Buffer de pan cortado previo a termoenvasado
B14: TOTAL | C14: Superficie Total Asignada al Puesto | G14: =SUM(G6:G13) | N14: A4 | R14: A0 Rebanadora Braesi FB-12 | Z14: A5
B16: PARÁMETROS TÉCNICOS DEL EQUIPO / PUESTO | E16: ESPECIFICACIÓN / VALOR
B17: Marca y Modelo | E17: Braesi FB-12 G2 (Rebanadora de pan de mesa/pie)
B18: Capacidad Máxima | E18: Hasta 360 piezas de pan/hora (Capacidad teórica: 144 kg/h)
B19: Dimensiones del Equipo | E19: 721 mm (Largo) x 477 mm (Ancho) x 1417 mm (Alto)
B20: Superficie Estática (Ss) | E20: 0,3439 m² (según BOM y Balanceo: 0,72 m x 0,48 m) | M20: A1 | R20: A2
B21: Potencia y Consumo | E21: 0,50 kW | 220 V / 50 Hz monofásica
B22: Cuchillas y Corte | E22: Acero al carbono especial, paso de rebanada estándar 12 mm
B24: Proyecto Final UTN FRBA | Grupo 8 - Planta CELI (Alimentos Sin Gluten) | Relevamiento de Superficies y Layout
M29: REFERENCIAS DE LAYOUT:
M30: A0: Máquina Principal | A1: MP en espera | A2: Operación/Alimentación | A3: Salida de Producto
M31: A4: Tablero / Mando | A5: Seguridad Lateral | A6: Pasillo Circulación | A7: Buffer Semielaborado (SE)

Sheet Envasado 1° Panificados
B2: ENVASADO PRIMARIO - PAN Y BUDÍN | L2: Escala: 1 celda ≈ 0.25 m x 0.25 m (Largo: 17 celdas | Ancho: 5 celdas)
B3: Línea B - Panificados | Envasadora Horizontal Flow-Pack Brunetti EFH700X (4,38m Largo x 1,17m Ancho)
S4: A7 | AB4: A6
B5: Subarea | C5: Descripción / Denominación | D5: Largo (m) | E5: Ancho (m) | F5: Cant. | G5: Superficie (m²) | H5: Justificación | I5: Función
B6: A0 | C6: Máquina Envasadora Horizontal Flow-Pack | D6: 4.38 | E6: 1.17 | F6: 1 | G6: =D6*E6*F6 | H6: Fabricante Brunetti (EFH700X: 4380 x 1170 mm) | I6: Envasado horizontal automático, fechado y termosellado
B7: A1 | C7: Carro con budines enteros y panes rebanados | D7: 1.2 | E7: 0.8 | F7: 1 | G7: =D7*E7*F7 | H7: Carro de transferencia desde enfriado/rebanado | I7: Espera de productos listos para alimentar cadena | S7: A3
B8: A2 | C8: Cadena de arrastre y puesto de operario alimentador | D8: 4 | E8: 1 | F8: 1 | G8: =D8*E8*F8 | H8: Longitud de la cinta de tacos sincronizada | I8: Alimentación manual sincronizada de budines y panes
B9: A3 | C9: Cinta de salida y paso por detector de metales | D9: 1.5 | E9: 0.6 | F9: 1 | G9: =D9*E9*F9 | H9: Cinta de evacuación de paquetes termosellados | I9: Descarga suave y control de inocuidad PCC
B10: A4 | C10: Tablero HMI táctil, servomotores y portabobinas | D10: 1.2 | E10: 0.6 | F10: 1 | G10: =D10*E10*F10 | H10: Estructura porta bobina superior con servocontrol | I10: Regulación de longitud de paquete, temperatura y fotocélula | M10: A4 | S10: A0 Envasadora Brunetti EFH700X
B11: A5 | C11: Espacio de seguridad lateral y mantenimiento mordazas | D11: 0.6 | E11: 4 | F11: 1 | G11: =D11*E11*F11 | H11: 0,6 m a lo largo del equipo para seguridad mecánica | I11: Acceso seguro a mordazas rotativas y cuchillas de corte
B12: A6 | C12: Pasillo de circulación principal y carga de film | D12: 1.2 | E12: 5.5 | F12: 1 | G12: =D12*E12*F12 | H12: Pasillo ancho para tránsito y carga de bobinas pesadas | I12: Circulación de zorras y reposición de insumos
B13: A7 | C13: Mesa rotativa acumuladora / buffer de salida (SE) | D13: 1.2 | E13: 1 | F13: 1 | G13: =D13*E13*F13 | H13: Mesa plato rotativo en acero inoxidable AISI 304 | I13: Acumulación de paquetes previo al encajonado final
B14: TOTAL | C14: Superficie Total Asignada al Puesto | G14: =SUM(G6:G13)
B16: PARÁMETROS TÉCNICOS DEL EQUIPO / PUESTO | E16: ESPECIFICACIÓN / VALOR
B17: Marca y Modelo | E17: Brunetti Hermanos EFH700X (Flow-Pack Horizontal) | M17: A5
B18: Dimensiones del Equipo | E18: 4380 mm (Largo) x 1170 mm (Ancho) x 1500 mm (Alto)
B19: Superficie Estática (Ss) | E19: 5,125 m² (según catálogo: 4,38 m x 1,17 m, en BOM asignado 6,57 m²)
B20: Potencia y Voltaje | E20: 3,60 kW | 220 V / 380 V trifásica
B21: Velocidad de Envasado | E21: 10 a 15 paquetes/minuto (Capacidad teórica: 160,8 kg/h)
B22: Formatos Aptos | E22: Pan de molde entero/rebanado (400g) y Budines (180g) en atmósfera modificada
B24: Proyecto Final UTN FRBA | Grupo 8 - Planta CELI (Alimentos Sin Gluten) | Relevamiento de Superficies y Layout
M25: A1 | S25: A2
M33: REFERENCIAS DE LAYOUT:
M34: A0: Máquina Principal | A1: MP en espera | A2: Operación/Alimentación | A3: Salida de Producto
M35: A4: Tablero / Mando | A5: Seguridad Lateral | A6: Pasillo Circulación | A7: Buffer Semielaborado (SE)

Sheet Envasado 2° Panificados
B2: ENVASADO SECUNDARIO - PANIFICADOS | L2: Escala: 1 celda ≈ 0.20 m x 0.20 m
B3: Línea B - Panificados | Mesa de Trabajo Ergonómica, Encajonado y Paletizado
S4: A7
B5: Subarea | C5: Descripción / Denominación | D5: Largo (m) | E5: Ancho (m) | F5: Cant. | G5: Superficie (m²) | H5: Justificación | I5: Función
B6: A0 | C6: Mesa de Trabajo en Acero Inoxidable AISI 304 | D6: 1.2 | E6: 0.8 | F6: 1 | G6: =D6*E6*F6 | H6: Mesa estándar ergonómica de empaque (1200x800mm) | I6: Superficie de apoyo para conformado y llenado de cajas
B7: A1 | C7: Buffer de paquetes recibidos desde mesa rotativa | D7: 0.8 | E7: 0.6 | F7: 1 | G7: =D7*E7*F7 | H7: Plato rotativo acumulador de envasado primario | I7: Recepción de paquetes flow-pack verificados
B8: A2 | C8: Puesto del operario de encajonado | D8: 1.2 | E8: 1 | F8: 1 | G8: =D8*E8*F8 | H8: Espacio ergonómico de pie sobre alfombra antifatiga | I8: Conformado de cajas, colocación de producto y control | R8: A3 | AB8: A6
B9: A3 | C9: Soporte para cajas corrugadas plegadas | D9: 0.8 | E9: 0.6 | F9: 1 | G9: =D9*E9*F9 | H9: Estante inferior/lateral para cajas desarmadas | I9: Alimentación rápida de cajas vacías
B10: A4 | C10: Precintadora manual y dispensador de rótulos | D10: 0.5 | E10: 0.4 | F10: 1 | G10: =D10*E10*F10 | H10: Dispensador de cinta adhesiva y etiquetas código barras | I10: Cerrado superior e inferior y etiquetado de trazabilidad
B11: A5 | C11: Espacio de seguridad y ergonomía postural | D11: 0.5 | E11: 1.2 | F11: 1 | G11: =D11*E11*F11 | H11: Zona libre perimetral sin obstáculos de tropiezo | I11: Seguridad y rotación postural del trabajador
B12: A6 | C12: Pasillo de circulación y retiro de zorras | D12: 1.2 | E12: 3 | F12: 1 | G12: =D12*E12*F12 | H12: Ancho mínimo para tránsito de zorras hidráulicas | I12: Retiro de pallets conformados hacia Depósito PT
B13: A7 | C13: Pallet en conformación con cajas terminadas (PT) | D13: 1.2 | E13: 1 | F13: 1 | G13: =D13*E13*F13 | H13: Pallet Arlog (1,2 x 1,0 m) en proceso de estibado | I13: Estiba de cajas terminadas previo al stretch filmado
B14: TOTAL | C14: Superficie Total Asignada al Puesto | G14: =SUM(G6:G13) | N14: A4 | R14: A0 Mesa de Encajonado Panificados | Z14: A5
B16: PARÁMETROS TÉCNICOS DEL EQUIPO / PUESTO | E16: ESPECIFICACIÓN / VALOR
B17: Tipo de Puesto | E17: Mesa de encajonado secundario manual en acero inoxidable AISI 304
B18: Dimensiones de la Mesa | E18: 1200 mm (Largo) x 800 mm (Ancho) x 800 mm (Alto)
B19: Superficie Estática (Ss) | E19: 0,96 m² (según BOM y Balanceo: 1,20 m x 0,80 m)
B20: Formato de Embalaje | E20: Caja corrugada multiproducto (Panes x 10 unid / Budines x 20 unid) | M20: A1 | R20: A2
B21: Equipamiento Auxiliar | E21: Precintadora de cinta adhesiva, fechador manual y balanza de control
B22: Rendimiento | E22: 1 caja/minuto por puesto (Capacidad holgada)
B24: Proyecto Final UTN FRBA | Grupo 8 - Planta CELI (Alimentos Sin Gluten) | Relevamiento de Superficies y Layout
M29: REFERENCIAS DE LAYOUT:
M30: A0: Máquina Principal | A1: MP en espera | A2: Operación/Alimentación | A3: Salida de Producto
M31: A4: Tablero / Mando | A5: Seguridad Lateral | A6: Pasillo Circulación | A7: Buffer Semielaborado (SE)

Sheet Depósito MP
B2: DEPÓSITO DE MATERIAS PRIMAS E INSUMOS (ESTIMACIÓN PRELIMINAR) | L2: Escala: 1 celda ≈ 0.40 m x 0.40 m (Superficie Estimada: ~50 m²)
