Workbook

Sheet Demanda
B2: Estimación anual de la demanda
B4: Población | D4: Cuantifiación
B5: Población total Arg | D5: 46000000
B6: % Celíacos | D6: 0.01
B7: Subpoblación celíacos | D7: =D6*D5 -> 460000
B8: Factor conviviente - demanda periférica | D8: =1.5 -> 1.5
B9: Mercado potencial | D9: =D8*D7 -> 690000
B10: % Habitantes grandes aglomerados | D10: 0.453
B11: Mercado objetivo - Aglomerados | D11: =D10*D9 -> 312570
B13: Consumo teórico anual por persona (según INDEC)
B14: Producto | D14: Consumo
B15: Panificados | D15: =1.2*12 -> 14.4 | E15: kg
B16: Galletitas saladas | D16: 5.04 | E16: kg
B17: Galletitas dulces | D17: 2.52 | E17: kg
B18: Total | D18: =SUM(D15:D17) -> 21.96 | E18: kg
B20: Consumo anual mercado objetivo | K20: Consumo anual mercado objetivo
B21: Producto | D21: Consumo | F21: Ventas anuales | H21: % Mkt Share | K21: Producto | M21: Consumo | O21: Ventas anuales | Q21: % Mkt Share
B22: Panificados | D22: =D15*$D$11 -> 4501008 | E22: kg | F22: =SUM(Produccion!E22:E24) -> 190000 | G22: kg | H22: =F22/D22*100 -> 4.2212767 | I22: % | K22: Panificados | M22: =D22/1000 -> 4501.008 | N22: Tn | O22: =F22/1000 -> 190 | P22: Tn | Q22: =O22/M22*100 -> 4.2212767 | R22: %
B23: Galletitas saladas | D23: =D16*$D$11 -> 1575352.8 | E23: kg | F23: =SUM(Produccion!E18) -> 7800 | G23: kg | H23: =F23/D23*100 -> 0.49512719 | I23: % | K23: Galletitas saladas | M23: =D23/1000 -> 1575.3528 | N23: Tn | O23: =F23/1000 -> 7.8 | P23: Tn | Q23: =O23/M23*100 -> 0.49512719 | R23: %
B24: Galletitas dulces | D24: =D17*$D$11 -> 787676.4 | E24: kg | F24: =Produccion!E14+Produccion!E15+Produccion!E17+Produccion!E20 -> 137300 | G24: kg | H24: =F24/D24*100 -> 17.431016 | I24: % | K24: Galletitas dulces | M24: =D24/1000 -> 787.6764 | N24: Tn | O24: =F24/1000 -> 137.3 | P24: Tn | Q24: =O24/M24*100 -> 17.431016 | R24: %
B25: Total | D25: =SUM(D22:D24) -> 6864037.2 | E25: kg | F25: =SUM(F22:F24) -> 335100 | G25: kg | H25: =F25/D25*100 -> 4.8819665 | I25: % | K25: Total | M25: =SUM(M22:M24) -> 6864.0372 | N25: Tn | O25: =SUM(O22:O24) -> 335.1 | P25: Tn | Q25: =O25/M25*100 -> 4.8819665 | R25: %
B28: Ventas SMAMS 2025 [kg] | D28: 1462828.9
B29: %Mkt share de SMAMS | D29: =D28/D25 -> 0.21311495
B31: Ventas anuales nuestro proyecto [kg] | D31: =Produccion!E25 -> 403000
B32: %Mkt share de nuestro proyecto | D32: =D31/D25 -> 0.058711803

Sheet Plan de ventas
B2: PRECIOS
H3: Supermercados | L3: Distribuidores
B4: COD | C4: Producto | E4: Peso [gr] | F4: Linea | G4: Costo MP/kg | H4: $/kg | I4: $/u | J4: $/u sugerido | K4: Margen | L4: $/kg | M4: $/u | N4: $/u sugerido | O4: Margen
B5: A03 | C5: Galletitas símil chocolinas | E5: 150 | F5: Clasicas | G5: 1499 | H5: 8127 | I5: 1220 | J5: 2067 | K5: 4.42 | L5: 9346 | M5: 1410 | N5: 2764 | O5: 5.23
B6: A06 | C6: Bizcochos sabor queso | E6: 150 | F6: Clasicas | G6: 975 | H6: 7989 | I6: 1200 | J6: 2033 | K6: 7.19 | L6: 9187 | M6: 1380 | N6: 2705 | O6: 8.42
B7: A08 | C7: Polvorones | E7: 150 | F7: Clasicas | G7: 1959 | H7: 7989 | I7: 1200 | J7: 2033 | K7: 3.08 | L7: 9187 | M7: 1380 | N7: 2705 | O7: 3.69
B8: B03 | C8: Budines free | E8: 180 | F8: Free | G8: 3799 | H8: 11296 | I8: 2040 | J8: 3456 | K8: 1.97 | L8: 12990 | M8: 2340 | N8: 4587 | O8: 2.42
B9: A02 | C9: Galletitas símil chocolinas free | E9: 150 | F9: Free | G9: 1723 | H9: 9102 | I9: 1370 | J9: 2321 | K9: 4.28 | L9: 10467 | M9: 1580 | N9: 3097 | O9: 5.08
B10: A07 | C10: Polvorones free | E10: 150 | F10: Free | G10: 2253 | H10: 8948 | I10: 1350 | J10: 2287 | K10: 2.97 | L10: 10290 | M10: 1550 | N10: 3038 | O10: 3.57
B11: A05 | C11: Bizcochos sabor queso free | E11: 150 | F11: Free | G11: 975 | H11: 7989 | I11: 1200 | J11: 2033 | K11: 7.19 | L11: 9187 | M11: 1380 | N11: 2705 | O11: 8.42
B12: A01 | C12: Chocolate con chips picante | E12: 150 | F12: Gourmet | G12: 1776 | H12: 9590 | I12: 1440 | J12: 2439 | K12: 4.4 | L12: 11028 | M12: 1660 | N12: 3254 | O12: 5.21
B13: A04 | C13: Pepas chocolate y batata | E13: 150 | F13: Gourmet | G13: 2405 | H13: 7935 | I13: 1200 | J13: 2033 | K13: 2.3 | L13: 9125 | M13: 1370 | N13: 2685 | O13: 2.79
B14: B01 | C14: Pan de molde | E14: 400 | F14: Panificados | G14: 3034 | H14: 9000 | I14: 3600 | J14: 6098 | K14: 1.97 | L14: 10350 | M14: 4140 | N14: 8115 | O14: 2.41
B15: B02 | C15: Budines | E15: 180 | F15: Panificados | G15: 3799 | H15: 11296 | I15: 2040 | J15: 3456 | K15: 1.97 | L15: 12990 | M15: 2340 | N15: 4587 | O15: 2.42
E17: Ventas # con 5,27% de mercado
B18: COD | C18: Producto | D18: Peso | E18: Cantidad [u] | F18: $ super | G18: % distr
B19: A01 | C19: Chocolate con chips picante 150gr. | D19: 150 | E19: =ROUNDUP(Produccion!E14*1000/D19,0) -> 400000 | F19: =VLOOKUP(B19,$B$4:$I$15,8,0) -> 1440 | G19: =VLOOKUP(B19,$B$4:$M$15,12,0) -> 1660
B20: A02 | C20: Galletitas símil chocolinas free 150gr. | D20: 150 | E20: =ROUNDUP(Produccion!E15*1000/D20,0) -> 52000 | F20: =VLOOKUP(B20,$B$4:$I$15,8,0) -> 1370 | G20: =VLOOKUP(B20,$B$4:$M$15,12,0) -> 1580
B21: A03 | C21: Galletitas símil chocolinas 150gr. | D21: 150 | E21: =ROUNDUP(Produccion!E16*1000/D21,0) -> 121334 | F21: =VLOOKUP(B21,$B$4:$I$15,8,0) -> 1220 | G21: =VLOOKUP(B21,$B$4:$M$15,12,0) -> 1410
B22: A04 | C22: Pepas chocolate y batata 150gr. | D22: 150 | E22: =ROUNDUP(Produccion!E17*1000/D22,0) -> 373334 | F22: =VLOOKUP(B22,$B$4:$I$15,8,0) -> 1200 | G22: =VLOOKUP(B22,$B$4:$M$15,12,0) -> 1370
B23: A05 | C23: Bizcochos sabor queso free 150gr. | D23: 150 | E23: =ROUNDUP(Produccion!E18*1000/D23,0) -> 52000 | F23: =VLOOKUP(B23,$B$4:$I$15,8,0) -> 1200 | G23: =VLOOKUP(B23,$B$4:$M$15,12,0) -> 1380
B24: A06 | C24: Bizcochos sabor queso 150gr. | D24: 150 | E24: =ROUNDUP(Produccion!E19*1000/D24,0) -> 121334 | F24: =VLOOKUP(B24,$B$4:$I$15,8,0) -> 1200 | G24: =VLOOKUP(B24,$B$4:$M$15,12,0) -> 1380
B25: A07 | C25: Polvorones free 150gr. | D25: 150 | E25: =ROUNDUP(Produccion!E20*1000/D25,0) -> 90000 | F25: =VLOOKUP(B25,$B$4:$I$15,8,0) -> 1350 | G25: =VLOOKUP(B25,$B$4:$M$15,12,0) -> 1550
B26: A08 | C26: Polvorones 150gr. | D26: 150 | E26: =ROUNDUP(Produccion!E21*1000/D26,0) -> 210000 | F26: =VLOOKUP(B26,$B$4:$I$15,8,0) -> 1200 | G26: =VLOOKUP(B26,$B$4:$M$15,12,0) -> 1380
B27: B01 | C27: Pan de molde 400gr. | D27: 400 | E27: =ROUNDUP(Produccion!E22*1000/D27,0) -> 175000 | F27: =VLOOKUP(B27,$B$4:$I$15,8,0) -> 3600 | G27: =VLOOKUP(B27,$B$4:$M$15,12,0) -> 4140
B28: B02 | C28: Budines vainilla/cítricos 180gr. | D28: 180 | E28: =ROUNDUP(Produccion!E23*1000/D28,0) -> 466667 | F28: =VLOOKUP(B28,$B$4:$I$15,8,0) -> 2040 | G28: =VLOOKUP(B28,$B$4:$M$15,12,0) -> 2340
B29: B03 | C29: Budines chocolate 180gr. | D29: 180 | E29: =ROUNDUP(Produccion!E24*1000/D29,0) -> 200000 | F29: =VLOOKUP(B29,$B$4:$I$15,8,0) -> 2040 | G29: =VLOOKUP(B29,$B$4:$M$15,12,0) -> 2340
C30: TOTAL | E30: =SUM(E19:E29) -> 2261669 | F30: =SUM(F19:F29) -> 17860 | G30: =SUM(G19:G29) -> 20530
F32: [Miles de unidades] | G32: [Miles de unidades] | H32: [Miles de unidades] | I32: [Miles de unidades] | J32: [Miles de unidades] | K32: [Miles de unidades] | L32: [Miles de unidades] | M32: [Miles de unidades] | N32: [Miles de unidades] | O32: [Miles de unidades] | S32: [kg] | T32: [kg] | U32: [kg] | V32: [kg] | W32: [kg] | X32: [kg] | Y32: [kg] | Z32: [kg] | AA32: [kg] | AB32: [kg]
B33: COD | C33: Producto | D33: Peso | E33: Linea | F33: Año 1 | G33: Año 2 | H33: Año 3 | I33: Año 4 | J33: Año 5 | K33: Año 6 | L33: Año 7 | M33: Año 8 | N33: Año 9 | O33: Año 10
B34: A01 | C34: Chocolate con chips picante 150gr. | D34: 150 | E34: Gourmet | F34: =ROUNDUP((E19/4*0.5)+E19/4*3,0)/1000 -> 350 | G34: =E19/1000 -> 400 | H34: =G34*1.04*1.02 -> 424.32 | I34: =H34*1.04*1.02 -> 450.11866 | J34: =I34*1.04*1.02 -> 477.48587 | K34: =J34*1.04*1.03 -> 511.48286 | L34: =K34*1.04*1.03 -> 547.90044 | M34: =L34*1.04*1.03 -> 586.91096 | N34: =M34*1.04*1.03 -> 628.69902 | O34: =N34*1.04*1.03 -> 673.46239
B35: A02 | C35: Galletitas símil chocolinas free 150gr. | D35: 150 | E35: Free | F35: =ROUNDUP((E20/4*0.5)+E20/4*3,0)/1000 -> 45.5 | G35: =E20/1000 -> 52 | H35: =G35*1.04*1.02 -> 55.1616 | I35: =H35*1.04*1.02 -> 58.515425 | J35: =I35*1.04*1.02 -> 62.073163 | K35: =J35*1.04*1.03 -> 66.492772 | L35: =K35*1.04*1.03 -> 71.227058 | M35: =L35*1.04*1.03 -> 76.298424 | N35: =M35*1.04*1.03 -> 81.730872 | O35: =N35*1.04*1.03 -> 87.55011
B36: A03 | C36: Galletitas símil chocolinas 150gr. | D36: 150 | E36: Clásicas | F36: =ROUNDUP((E21/4*0.5)+E21/4*3,0)/1000 -> 106.168 | G36: =E21/1000 -> 121.334 | H36: =G36*1.04*1.02 -> 128.71111 | I36: =H36*1.04*1.02 -> 136.53674 | J36: =I36*1.04*1.02 -> 144.83818 | K36: =J36*1.04*1.03 -> 155.15065 | L36: =K36*1.04*1.03 -> 166.19738 | M36: =L36*1.04*1.03 -> 178.03063 | N36: =M36*1.04*1.03 -> 190.70642 | O36: =N36*1.04*1.03 -> 204.28471
B37: A04 | C37: Pepas chocolate y batata 150gr. | D37: 150 | E37: Gourmet | F37: =ROUNDUP((E22/4*0.5)+E22/4*3,0)/1000 -> 326.668 | G37: =E22/1000 -> 373.334 | H37: =G37*1.04*1.02 -> 396.03271 | I37: =H37*1.04*1.02 -> 420.1115 | J37: =I37*1.04*1.02 -> 445.65427 | K37: =J37*1.04*1.03 -> 477.38486 | L37: =K37*1.04*1.03 -> 511.37466 | M37: =L37*1.04*1.03 -> 547.78454 | N37: =M37*1.04*1.03 -> 586.7868 | O37: =N37*1.04*1.03 -> 628.56602
B38: A05 | C38: Bizcochos sabor queso free 150gr. | D38: 150 | E38: Free | F38: =ROUNDUP((E23/4*0.5)+E23/4*3,0)/1000 -> 45.5 | G38: =E23/1000 -> 52 | H38: =G38*1.04*1.02 -> 55.1616 | I38: =H38*1.04*1.02 -> 58.515425 | J38: =I38*1.04*1.02 -> 62.073163 | K38: =J38*1.04*1.03 -> 66.492772 | L38: =K38*1.04*1.03 -> 71.227058 | M38: =L38*1.04*1.03 -> 76.298424 | N38: =M38*1.04*1.03 -> 81.730872 | O38: =N38*1.04*1.03 -> 87.55011
B39: A06 | C39: Bizcochos sabor queso 150gr. | D39: 150 | E39: Clásicas | F39: =ROUNDUP((E24/4*0.5)+E24/4*3,0)/1000 -> 106.168 | G39: =E24/1000 -> 121.334 | H39: =G39*1.04*1.02 -> 128.71111 | I39: =H39*1.04*1.02 -> 136.53674 | J39: =I39*1.04*1.02 -> 144.83818 | K39: =J39*1.04*1.03 -> 155.15065 | L39: =K39*1.04*1.03 -> 166.19738 | M39: =L39*1.04*1.03 -> 178.03063 | N39: =M39*1.04*1.03 -> 190.70642 | O39: =N39*1.04*1.03 -> 204.28471
B40: A07 | C40: Polvorones free 150gr. | D40: 150 | E40: Free | F40: =ROUNDUP((E25/4*0.5)+E25/4*3,0)/1000 -> 78.75 | G40: =E25/1000 -> 90 | H40: =G40*1.04*1.02 -> 95.472 | I40: =H40*1.04*1.02 -> 101.2767 | J40: =I40*1.04*1.02 -> 107.43432 | K40: =J40*1.04*1.03 -> 115.08364 | L40: =K40*1.04*1.03 -> 123.2776 | M40: =L40*1.04*1.03 -> 132.05497 | N40: =M40*1.04*1.03 -> 141.45728 | O40: =N40*1.04*1.03 -> 151.52904
B41: A08 | C41: Polvorones 150gr. | D41: 150 | E41: Clásicas | F41: =ROUNDUP((E26/4*0.5)+E26/4*3,0)/1000 -> 183.75 | G41: =E26/1000 -> 210 | H41: =G41*1.04*1.02 -> 222.768 | I41: =H41*1.04*1.02 -> 236.31229 | J41: =I41*1.04*1.02 -> 250.68008 | K41: =J41*1.04*1.03 -> 268.5285 | L41: =K41*1.04*1.03 -> 287.64773 | M41: =L41*1.04*1.03 -> 308.12825 | N41: =M41*1.04*1.03 -> 330.06698 | O41: =N41*1.04*1.03 -> 353.56775
B42: B01 | C42: Pan de molde 400gr. | D42: 400 | E42: Panificados | F42: =ROUNDUP((E27/4*0.5)+E27/4*3,0)/1000 -> 153.125 | G42: =E27/1000 -> 175 | H42: =G42*1.04*1.02 -> 185.64 | I42: =H42*1.04*1.02 -> 196.92691 | J42: =I42*1.04*1.02 -> 208.90007 | K42: =J42*1.04*1.03 -> 223.77375 | L42: =K42*1.04*1.03 -> 239.70644 | M42: =L42*1.04*1.03 -> 256.77354 | N42: =M42*1.04*1.03 -> 275.05582 | O42: =N42*1.04*1.03 -> 294.63979
B43: B02 | C43: Budines vainilla/cítricos 180gr. | D43: 180 | E43: Panificados | F43: =ROUNDUP((E28/4*0.5)+E28/4*3,0)/1000 -> 408.334 | G43: =E28/1000 -> 466.667 | H43: =G43*1.04*1.02 -> 495.04035 | I43: =H43*1.04*1.02 -> 525.13881 | J43: =I43*1.04*1.02 -> 557.06725 | K43: =J43*1.04*1.03 -> 596.73043 | L43: =K43*1.04*1.03 -> 639.21764 | M43: =L43*1.04*1.03 -> 684.72994 | N43: =M43*1.04*1.03 -> 733.48271 | O43: =N43*1.04*1.03 -> 785.70668
...

Sheet BOM
D2: Chocolate con chips picante - A01 | M2: Foto | R2: Calculo de receta promedio ponderada - kg de MP cada 100kg | AB2: 100 kg | AF2: 100 kg | AH2: =AL6 -> 426720.66 | AI2: =AL23 -> 343531.76 | AK2: Linea A - Galletitas | AU2: Linea A - Galletitas
D3: PT anual (kg) | E3: =SUMIFS('Plan de ventas'!$O$48:$O$60,'Plan de ventas'!$B$48:$B$60,D12)*1000 -> 101019.36 | R3: CÓDIGO | S3: DENOMINACIÓN | T3: A01 | U3: A02 | V3: A03 | W3: A04 | X3: A05 | Y3: A06 | Z3: A07 | AA3: A08 | AB3: A00 | AC3: B01 | AD3: B02 | AE3: B03 | AF3: B00 | AH3: A00 | AI3: B00 | AK3: NECESIDAD ANUAL MP | AU3: MAQUINAS
B4: Cajas / lote | E4: 1 | F4: ="Línea: Gourmet | Versión n°: 1"&CHAR(10)&CHAR(10)&"Lote = "&E4&" cajas × "&E5&" unid./caja = "&(E4*E5)&" unidades"&CHAR(10)&"Producto terminado = "&TEXT(E8,"#,##0.00")&" kg"&CHAR(10)&"Mezcla a preparar = "&TEXT(E9,"#,##0.00")&" kg (rendimiento "&TEXT(E7,"0%")&")" -> Línea: Gourmet | Versión n°: 1 Lote = 1 cajas × 20 unid./caja = 20 unidades Producto terminado = 3,00 kg Mezcla a preparar = 3,41 kg (rendimiento 88%) | S4: Volumen relativo (año 10) | T4: =SUMIFS('Plan de ventas'!$P$48:$P$60,'Plan de ventas'!$B$48:$B$60,T3) -> 0.28168974 | U4: =SUMIFS('Plan de ventas'!$P$48:$P$60,'Plan de ventas'!$B$48:$B$60,U3) -> 0.036619667 | V4: =SUMIFS('Plan de ventas'!$P$48:$P$60,'Plan de ventas'!$B$48:$B$60,V3) -> 0.085446359 | W4: =SUMIFS('Plan de ventas'!$P$48:$P$60,'Plan de ventas'!$B$48:$B$60,W3) -> 0.2629109 | X4: =SUMIFS('Plan de ventas'!$P$48:$P$60,'Plan de ventas'!$B$48:$B$60,X3) -> 0.036619667 | Y4: =SUMIFS('Plan de ventas'!$P$48:$P$60,'Plan de ventas'!$B$48:$B$60,Y3) -> 0.085446359 | Z4: =SUMIFS('Plan de ventas'!$P$48:$P$60,'Plan de ventas'!$B$48:$B$60,Z3) -> 0.063380192 | AA4: =SUMIFS('Plan de ventas'!$P$48:$P$60,'Plan de ventas'!$B$48:$B$60,AA3) -> 0.14788712 | AB4: =SUM(T4:AA4) -> 1 | AC4: =SUMIFS('Plan de ventas'!$P$48:$P$60,'Plan de ventas'!$B$48:$B$60,AC3) -> 0.36842094 | AD4: =SUMIFS('Plan de ventas'!$P$48:$P$60,'Plan de ventas'!$B$48:$B$60,AD3) -> 0.44210544 | AE4: =SUMIFS('Plan de ventas'!$P$48:$P$60,'Plan de ventas'!$B$48:$B$60,AE3) -> 0.18947362 | AF4: =SUM(AC4:AE4) -> 1 | AK4: Sección Operativa | AL4: Alimentación | AM4: Agregado | AN4: Desperdicios | AR4: Producción | AU4: Máquina | AV4: Modelo | AW4: Capacidad Teórica | AY4: Medidas | BA4: Peso | BC4: Consumo | BE4: Precio | BF4: Proveedor | BG4: Ubicación
B5: Unid. / caja | E5: 20 | R5: M001 | S5: FÉCULA DE MAÍZ | T5: =SUMIFS($L:$L,$C:$C,T$3,$D:$D,$R5)*100 -> 26.5 | U5: =SUMIFS($L:$L,$C:$C,U$3,$D:$D,$R5)*100 -> 24 | V5: =SUMIFS($L:$L,$C:$C,V$3,$D:$D,$R5)*100 -> 22 | W5: =SUMIFS($L:$L,$C:$C,W$3,$D:$D,$R5)*100 -> 23.32 | X5: =SUMIFS($L:$L,$C:$C,X$3,$D:$D,$R5)*100 -> 0 | Y5: =SUMIFS($L:$L,$C:$C,Y$3,$D:$D,$R5)*100 -> 0 | Z5: =SUMIFS($L:$L,$C:$C,Z$3,$D:$D,$R5)*100 -> 24 | AA5: =SUMIFS($L:$L,$C:$C,AA$3,$D:$D,$R5)*100 -> 28 | AB5: =SUMPRODUCT($T$4:$AA$4,T5:AA5) -> 22.016516 | AC5: =SUMIFS($L:$L,$C:$C,AC$3,$D:$D,$R5)*100 -> 0 | AD5: =SUMIFS($L:$L,$C:$C,AD$3,$D:$D,$R5)*100 -> 12 | AE5: =SUMIFS($L:$L,$C:$C,AE$3,$D:$D,$R5)*100 -> 11 | AF5: =SUMPRODUCT($AC$4:$AE$4,AC5:AE5) -> 7.3894751 | AH5: =AB5/100*$AL$6 -> 93949.022 | AI5: =AF5/100*$AL$23 -> 25385.194 | AN5: Recuperable | AP5: No recuperable | AU5: Amasadora | AW5: 130 | AX5: kg | AY5: 120x140x180 | AZ5: cm | BB5: kg | BC5: - | BD5: kw/h | BE5: 13000000
B6: Peso neto (g) | E6: 150 | R6: M006 | S6: SAL | T6: =SUMIFS($L:$L,$C:$C,T$3,$D:$D,$R6)*100 -> 0.5 | U6: =SUMIFS($L:$L,$C:$C,U$3,$D:$D,$R6)*100 -> 0.4 | V6: =SUMIFS($L:$L,$C:$C,V$3,$D:$D,$R6)*100 -> 0 | W6: =SUMIFS($L:$L,$C:$C,W$3,$D:$D,$R6)*100 -> 0 | X6: =SUMIFS($L:$L,$C:$C,X$3,$D:$D,$R6)*100 -> 1.5 | Y6: =SUMIFS($L:$L,$C:$C,Y$3,$D:$D,$R6)*100 -> 1.5 | Z6: =SUMIFS($L:$L,$C:$C,Z$3,$D:$D,$R6)*100 -> 0 | AA6: =SUMIFS($L:$L,$C:$C,AA$3,$D:$D,$R6)*100 -> 0.5 | AB6: =SUMPRODUCT($T$4:$AA$4,T6:AA6) -> 0.41253533 | AC6: =SUMIFS($L:$L,$C:$C,AC$3,$D:$D,$R6)*100 -> 1 | AD6: =SUMIFS($L:$L,$C:$C,AD$3,$D:$D,$R6)*100 -> 0.5 | AE6: =SUMIFS($L:$L,$C:$C,AE$3,$D:$D,$R6)*100 -> 0.3 | AF6: =SUMPRODUCT($AC$4:$AE$4,AC6:AE6) -> 0.64631574 | AH6: =AB6/100*$AL$6 -> 1760.3735 | AI6: =AF6/100*$AL$23 -> 2220.2998 | AK6: Amasado | AL6: =AR14*(1+AL16) -> 426720.66 | AM6: 0 | AO6: =AL6*AN6 -> 0 | AQ6: =AL6*AP6 -> 0 | AR6: =AL6+AM6-AO6-AQ6 -> 426720.66 | AS6: kg/año | AU6: Moldeadora | AV6: Ralem dulcera 600 | AX6: kg/h | AZ6: cm | BB6: kg | BC6: - | BD6: kw/h
B7: Rendim. (%) | E7: 0.88 | R7: M008 | S7: BICARBONATO DE AMONIO | T7: =SUMIFS($L:$L,$C:$C,T$3,$D:$D,$R7)*100 -> 0.5 | U7: =SUMIFS($L:$L,$C:$C,U$3,$D:$D,$R7)*100 -> 0 | V7: =SUMIFS($L:$L,$C:$C,V$3,$D:$D,$R7)*100 -> 0 | W7: =SUMIFS($L:$L,$C:$C,W$3,$D:$D,$R7)*100 -> 0 | X7: =SUMIFS($L:$L,$C:$C,X$3,$D:$D,$R7)*100 -> 0 | Y7: =SUMIFS($L:$L,$C:$C,Y$3,$D:$D,$R7)*100 -> 0 | Z7: =SUMIFS($L:$L,$C:$C,Z$3,$D:$D,$R7)*100 -> 1.5 | AA7: =SUMIFS($L:$L,$C:$C,AA$3,$D:$D,$R7)*100 -> 1 | AB7: =SUMPRODUCT($T$4:$AA$4,T7:AA7) -> 0.38380228 | AC7: =SUMIFS($L:$L,$C:$C,AC$3,$D:$D,$R7)*100 -> 0 | AD7: =SUMIFS($L:$L,$C:$C,AD$3,$D:$D,$R7)*100 -> 0 | AE7: =SUMIFS($L:$L,$C:$C,AE$3,$D:$D,$R7)*100 -> 0 | AF7: =SUMPRODUCT($AC$4:$AE$4,AC7:AE7) -> 0 | AH7: =AB7/100*$AL$6 -> 1637.7636 | AI7: =AF7/100*$AL$23 -> 0 | AK7: Moldeado | AL7: =AR6 -> 426720.66 | AM7: 0 | AN7: 0.03 | AO7: =AL7*AN7 -> 12801.62 | AP7: 0.02 | AQ7: =AL7*AP7 -> 8534.4132 | AR7: =AL7+AM7-AO7-AQ7 -> 405384.62 | AS7: kg/año | AU7: Horno tunel | AX7: kg/h | AZ7: cm | BB7: kg | BC7: - | BD7: kw/h
B8: PT (kg) | E8: =E4*E5*E6/1000 -> 3 | R8: M022 | S8: GOMA XÁNTICA | T8: =SUMIFS($L:$L,$C:$C,T$3,$D:$D,$R8)*100 -> 0.8 | U8: =SUMIFS($L:$L,$C:$C,U$3,$D:$D,$R8)*100 -> 1 | V8: =SUMIFS($L:$L,$C:$C,V$3,$D:$D,$R8)*100 -> 1 | W8: =SUMIFS($L:$L,$C:$C,W$3,$D:$D,$R8)*100 -> 0.432 | X8: =SUMIFS($L:$L,$C:$C,X$3,$D:$D,$R8)*100 -> 1 | Y8: =SUMIFS($L:$L,$C:$C,Y$3,$D:$D,$R8)*100 -> 1 | Z8: =SUMIFS($L:$L,$C:$C,Z$3,$D:$D,$R8)*100 -> 1 | AA8: =SUMIFS($L:$L,$C:$C,AA$3,$D:$D,$R8)*100 -> 1 | AB8: =SUMPRODUCT($T$4:$AA$4,T8:AA8) -> 0.79432866 | AC8: =SUMIFS($L:$L,$C:$C,AC$3,$D:$D,$R8)*100 -> 1.5 | AD8: =SUMIFS($L:$L,$C:$C,AD$3,$D:$D,$R8)*100 -> 1 | AE8: =SUMIFS($L:$L,$C:$C,AE$3,$D:$D,$R8)*100 -> 1 | AF8: =SUMPRODUCT($AC$4:$AE$4,AC8:AE8) -> 1.1842105 | AH8: =AB8/100*$AL$6 -> 3389.5645 | AI8: =AF8/100*$AL$23 -> 4068.139 | AK8: Horneado | AL8: =AR7 -> 405384.62 | AM8: 0 | AO8: =AL8*AN8 -> 0 | AP8: 0.04 | AQ8: =AL8*AP8 -> 16215.385 | AR8: =AL8+AM8-AO8-AQ8 -> 389169.24 | AS8: kg/año | AU8: Cinta de enfriamiento | AX8: kg/h | AZ8: cm | BB8: kg | BC8: - | BD8: kw/h
B9: Mezcla (kg) | E9: =E8/E7 -> 3.4090909 | R9: M028 | S9: PROPIONATO DE CALCIO | T9: =SUMIFS($L:$L,$C:$C,T$3,$D:$D,$R9)*100 -> 0 | U9: =SUMIFS($L:$L,$C:$C,U$3,$D:$D,$R9)*100 -> 0 | V9: =SUMIFS($L:$L,$C:$C,V$3,$D:$D,$R9)*100 -> 0 | W9: =SUMIFS($L:$L,$C:$C,W$3,$D:$D,$R9)*100 -> 0 | X9: =SUMIFS($L:$L,$C:$C,X$3,$D:$D,$R9)*100 -> 0 | Y9: =SUMIFS($L:$L,$C:$C,Y$3,$D:$D,$R9)*100 -> 0 | Z9: =SUMIFS($L:$L,$C:$C,Z$3,$D:$D,$R9)*100 -> 1 | AA9: =SUMIFS($L:$L,$C:$C,AA$3,$D:$D,$R9)*100 -> 1 | AB9: =SUMPRODUCT($T$4:$AA$4,T9:AA9) -> 0.21126731 | AC9: =SUMIFS($L:$L,$C:$C,AC$3,$D:$D,$R9)*100 -> 0 | AD9: =SUMIFS($L:$L,$C:$C,AD$3,$D:$D,$R9)*100 -> 1 | AE9: =SUMIFS($L:$L,$C:$C,AE$3,$D:$D,$R9)*100 -> 1 | AF9: =SUMPRODUCT($AC$4:$AE$4,AC9:AE9) -> 0.63157906 | AH9: =AB9/100*$AL$6 -> 901.52125 | AI9: =AF9/100*$AL$23 -> 2169.6746 | AK9: Enfriado | AL9: =AR8 -> 389169.24 | AM9: 0 | AN9: 0.03 | AO9: =AL9*AN9 -> 11675.077 | AP9: 0.02 | AQ9: =AL9*AP9 -> 7783.3848 | AR9: =AL9+AM9-AO9-AQ9 -> 369710.78 | AS9: kg/año | AU9: Envasadora vertical | AX9: kg/h | AZ9: cm | BB9: kg | BC9: - | BD9: kw/h
B10: ITEM | C10: PT | D10: MP | E10: DENOMINACION | F10: NIVEL | L10: % | M10: CANTIDAD | N10: UNIDAD | O10: OBSERVACIONES | R10: M030 | S10: HARINA DE ARROZ | T10: =SUMIFS($L:$L,$C:$C,T$3,$D:$D,$R10)*100 -> 18 | U10: =SUMIFS($L:$L,$C:$C,U$3,$D:$D,$R10)*100 -> 27 | V10: =SUMIFS($L:$L,$C:$C,V$3,$D:$D,$R10)*100 -> 27 | W10: =SUMIFS($L:$L,$C:$C,W$3,$D:$D,$R10)*100 -> 13.68 | X10: =SUMIFS($L:$L,$C:$C,X$3,$D:$D,$R10)*100 -> 25 | Y10: =SUMIFS($L:$L,$C:$C,Y$3,$D:$D,$R10)*100 -> 25 | Z10: =SUMIFS($L:$L,$C:$C,Z$3,$D:$D,$R10)*100 -> 22 | AA10: =SUMIFS($L:$L,$C:$C,AA$3,$D:$D,$R10)*100 -> 21 | AB10: =SUMPRODUCT($T$4:$AA$4,T10:AA10) -> 19.514463 | AC10: =SUMIFS($L:$L,$C:$C,AC$3,$D:$D,$R10)*100 -> 16 | AD10: =SUMIFS($L:$L,$C:$C,AD$3,$D:$D,$R10)*100 -> 14 | AE10: =SUMIFS($L:$L,$C:$C,AE$3,$D:$D,$R10)*100 -> 13 | AF10: =SUMPRODUCT($AC$4:$AE$4,AC10:AE10) -> 14.547368 | AH10: =AB10/100*$AL$6 -> 83272.247 | AI10: =AF10/100*$AL$23 -> 49974.83 | AK10: Fraccionado | AL10: =AR9 -> 369710.78 | AM10: 0 | AO10: =AL10*AN10 -> 0 | AQ10: =AL10*AP10 -> 0 | AR10: =AL10+AM10-AO10-AQ10 -> 369710.78 | AS10: kg/año | AU10: Envasadora | AX10: kg/h | AZ10: cm | BB10: kg | BC10: - | BD10: kw/h
F11: 0 | G11: 1 | H11: 2 | I11: 3 | J11: 4 | K11: 5 | R11: M031 | S11: JARABE DE GLUCOSA | T11: =SUMIFS($L:$L,$C:$C,T$3,$D:$D,$R11)*100 -> 6 | U11: =SUMIFS($L:$L,$C:$C,U$3,$D:$D,$R11)*100 -> 0 | V11: =SUMIFS($L:$L,$C:$C,V$3,$D:$D,$R11)*100 -> 0 | W11: =SUMIFS($L:$L,$C:$C,W$3,$D:$D,$R11)*100 -> 4.32 | X11: =SUMIFS($L:$L,$C:$C,X$3,$D:$D,$R11)*100 -> 0 | Y11: =SUMIFS($L:$L,$C:$C,Y$3,$D:$D,$R11)*100 -> 0 | Z11: =SUMIFS($L:$L,$C:$C,Z$3,$D:$D,$R11)*100 -> 0 | AA11: =SUMIFS($L:$L,$C:$C,AA$3,$D:$D,$R11)*100 -> 6 | AB11: =SUMPRODUCT($T$4:$AA$4,T11:AA11) -> 3.7132362 | AC11: =SUMIFS($L:$L,$C:$C,AC$3,$D:$D,$R11)*100 -> 0 | AD11: =SUMIFS($L:$L,$C:$C,AD$3,$D:$D,$R11)*100 -> 0 | AE11: =SUMIFS($L:$L,$C:$C,AE$3,$D:$D,$R11)*100 -> 0 | AF11: =SUMPRODUCT($AC$4:$AE$4,AC11:AE11) -> 0 | AH11: =AB11/100*$AL$6 -> 15845.146 | AI11: =AF11/100*$AL$23 -> 0 | AK11: Envasado primario | AL11: =AR10 -> 369710.78 | AM11: 0 | AO11: =AL11*AN11 -> 0 | AP11: 0.03 | AQ11: =AL11*AP11 -> 11091.323 | AR11: =AL11+AM11-AO11-AQ11 -> 358619.45 | AS11: kg/año | AX11: kg/h | AZ11: cm | BB11: kg | BC11: - | BD11: kw/h
B12: 1 | C12: A01 | D12: A01 | E12: Chocolate con chips picante (caja) | F12: X | L12: — | M12: =$E$4 -> 1 | N12: cajas | O12: Lote = 1 caja | R12: M036 | S12: ACEITE VEGETAL INTERESTERIFICADO | T12: =SUMIFS($L:$L,$C:$C,T$3,$D:$D,$R12)*100 -> 15 | U12: =SUMIFS($L:$L,$C:$C,U$3,$D:$D,$R12)*100 -> 14 | V12: =SUMIFS($L:$L,$C:$C,V$3,$D:$D,$R12)*100 -> 14 | W12: =SUMIFS($L:$L,$C:$C,W$3,$D:$D,$R12)*100 -> 11.16 | X12: =SUMIFS($L:$L,$C:$C,X$3,$D:$D,$R12)*100 -> 6 | Y12: =SUMIFS($L:$L,$C:$C,Y$3,$D:$D,$R12)*100 -> 0 | Z12: =SUMIFS($L:$L,$C:$C,Z$3,$D:$D,$R12)*100 -> 13 | AA12: =SUMIFS($L:$L,$C:$C,AA$3,$D:$D,$R12)*100 -> 15 | AB12: =SUMPRODUCT($T$4:$AA$4,T12:AA12) -> 12.130323 | AC12: =SUMIFS($L:$L,$C:$C,AC$3,$D:$D,$R12)*100 -> 0 | AD12: =SUMIFS($L:$L,$C:$C,AD$3,$D:$D,$R12)*100 -> 0 | AE12: =SUMIFS($L:$L,$C:$C,AE$3,$D:$D,$R12)*100 -> 0 | AF12: =SUMPRODUCT($AC$4:$AE$4,AC12:AE12) -> 0 | AH12: =AB12/100*$AL$6 -> 51762.596 | AI12: =AF12/100*$AL$23 -> 0 | AK12: Envasado secundario | AL12: =AR11 -> 358619.45 | AM12: 0 | AO12: =AL12*AN12 -> 0 | AQ12: =AL12*AP12 -> 0 | AR12: =AL12+AM12-AO12-AQ12 -> 358619.45 | AS12: kg/año | AX12: kg/h | AZ12: cm | BB12: kg | BC12: - | BD12: kw/h
B13: 2 | C13: A01 | D13: M001 | E13: FÉCULA DE MAÍZ | G13: X | L13: 0.265 | M13: =$E$9*L13 -> 0.90340909 | N13: Kg. | R13: M041 | S13: HUEVO EN POLVO DESHIDRATADO | T13: =SUMIFS($L:$L,$C:$C,T$3,$D:$D,$R13)*100 -> 2 | U13: =SUMIFS($L:$L,$C:$C,U$3,$D:$D,$R13)*100 -> 0 | V13: =SUMIFS($L:$L,$C:$C,V$3,$D:$D,$R13)*100 -> 4 | W13: =SUMIFS($L:$L,$C:$C,W$3,$D:$D,$R13)*100 -> 0 | X13: =SUMIFS($L:$L,$C:$C,X$3,$D:$D,$R13)*100 -> 0 | Y13: =SUMIFS($L:$L,$C:$C,Y$3,$D:$D,$R13)*100 -> 5 | Z13: =SUMIFS($L:$L,$C:$C,Z$3,$D:$D,$R13)*100 -> 0 | AA13: =SUMIFS($L:$L,$C:$C,AA$3,$D:$D,$R13)*100 -> 0 | AB13: =SUMPRODUCT($T$4:$AA$4,T13:AA13) -> 1.3323967 | AC13: =SUMIFS($L:$L,$C:$C,AC$3,$D:$D,$R13)*100 -> 0 | AD13: =SUMIFS($L:$L,$C:$C,AD$3,$D:$D,$R13)*100 -> 6 | AE13: =SUMIFS($L:$L,$C:$C,AE$3,$D:$D,$R13)*100 -> 6 | AF13: =SUMPRODUCT($AC$4:$AE$4,AC13:AE13) -> 3.7894744 | AH13: =AB13/100*$AL$6 -> 5685.612 | AI13: =AF13/100*$AL$23 -> 13018.048 | AK13: Paletizado | AL13: =AR12 -> 358619.45 | AM13: 0 | AO13: =AL13*AN13 -> 0 | AQ13: =AL13*AP13 -> 0 | AR13: =AL13+AM13-AO13-AQ13 -> 358619.45 | AS13: kg/año | AX13: kg/h | AZ13: cm | BB13: kg | BC13: - | BD13: kw/h
B14: 3 | C14: A01 | D14: M030 | E14: HARINA DE ARROZ | G14: X | L14: 0.18 | M14: =$E$9*L14 -> 0.61363636 | N14: Kg. | R14: M045 | S14: CACAO ALCALINO | T14: =SUMIFS($L:$L,$C:$C,T$3,$D:$D,$R14)*100 -> 4 | U14: =SUMIFS($L:$L,$C:$C,U$3,$D:$D,$R14)*100 -> 6 | V14: =SUMIFS($L:$L,$C:$C,V$3,$D:$D,$R14)*100 -> 6 | W14: =SUMIFS($L:$L,$C:$C,W$3,$D:$D,$R14)*100 -> 3.24 | X14: =SUMIFS($L:$L,$C:$C,X$3,$D:$D,$R14)*100 -> 0 | Y14: =SUMIFS($L:$L,$C:$C,Y$3,$D:$D,$R14)*100 -> 0 | Z14: =SUMIFS($L:$L,$C:$C,Z$3,$D:$D,$R14)*100 -> 6 | AA14: =SUMIFS($L:$L,$C:$C,AA$3,$D:$D,$R14)*100 -> 0 | AB14: =SUMPRODUCT($T$4:$AA$4,T14:AA14) -> 3.0912676 | AC14: =SUMIFS($L:$L,$C:$C,AC$3,$D:$D,$R14)*100 -> 0 | AD14: =SUMIFS($L:$L,$C:$C,AD$3,$D:$D,$R14)*100 -> 0 | AE14: =SUMIFS($L:$L,$C:$C,AE$3,$D:$D,$R14)*100 -> 0 | AF14: =SUMPRODUCT($AC$4:$AE$4,AC14:AE14) -> 0 | AH14: =AB14/100*$AL$6 -> 13191.077 | AI14: =AF14/100*$AL$23 -> 0 | AK14: TOTALES | AL14: =AL6 -> 426720.66 | AM14: =AM6 -> 0 | AO14: =AO6+AO7+AO8+AO9+AO11 -> 24476.697 | AQ14: =AQ6+AQ7+AQ8+AQ9+AQ11 -> 43624.506 | AR14: =SUMIFS('Plan de ventas'!$O48:$O60,'Plan de ventas'!$B$48:$B$60,"*A*")*1000 -> 358619.23 | AS14: kg/año | AX14: kg/h | AZ14: cm | BB14: kg | BC14: - | BD14: kw/h
B15: 4 | C15: A01 | D15: M036 | E15: ACEITE VEGETAL INTERESTERIFICADO | G15: X | L15: 0.15 | M15: =$E$9*L15 -> 0.51136364 | N15: Kg. | R15: M046 | S15: CHIPS DE CHOCOLATE | T15: =SUMIFS($L:$L,$C:$C,T$3,$D:$D,$R15)*100 -> 9 | U15: =SUMIFS($L:$L,$C:$C,U$3,$D:$D,$R15)*100 -> 0 | V15: =SUMIFS($L:$L,$C:$C,V$3,$D:$D,$R15)*100 -> 0 | W15: =SUMIFS($L:$L,$C:$C,W$3,$D:$D,$R15)*100 -> 0 | X15: =SUMIFS($L:$L,$C:$C,X$3,$D:$D,$R15)*100 -> 0 | Y15: =SUMIFS($L:$L,$C:$C,Y$3,$D:$D,$R15)*100 -> 0 | Z15: =SUMIFS($L:$L,$C:$C,Z$3,$D:$D,$R15)*100 -> 0 | AA15: =SUMIFS($L:$L,$C:$C,AA$3,$D:$D,$R15)*100 -> 0 | AB15: =SUMPRODUCT($T$4:$AA$4,T15:AA15) -> 2.5352077 | AC15: =SUMIFS($L:$L,$C:$C,AC$3,$D:$D,$R15)*100 -> 0 | AD15: =SUMIFS($L:$L,$C:$C,AD$3,$D:$D,$R15)*100 -> 0 | AE15: =SUMIFS($L:$L,$C:$C,AE$3,$D:$D,$R15)*100 -> 9 | AF15: =SUMPRODUCT($AC$4:$AE$4,AC15:AE15) -> 1.7052626 | AH15: =AB15/100*$AL$6 -> 10818.255 | AI15: =AF15/100*$AL$23 -> 5858.1186
B16: 5 | C16: A01 | D16: M052 | E16: AZÚCAR COMÚN | G16: X | L16: 0.14 | M16: =$E$9*L16 -> 0.47727273 | N16: Kg. | R16: M047 | S16: ESENCIA DE CHOCOLATE | T16: =SUMIFS($L:$L,$C:$C,T$3,$D:$D,$R16)*100 -> 0.3 | U16: =SUMIFS($L:$L,$C:$C,U$3,$D:$D,$R16)*100 -> 0.3 | V16: =SUMIFS($L:$L,$C:$C,V$3,$D:$D,$R16)*100 -> 0.4 | W16: =SUMIFS($L:$L,$C:$C,W$3,$D:$D,$R16)*100 -> 0 | X16: =SUMIFS($L:$L,$C:$C,X$3,$D:$D,$R16)*100 -> 0 | Y16: =SUMIFS($L:$L,$C:$C,Y$3,$D:$D,$R16)*100 -> 0 | Z16: =SUMIFS($L:$L,$C:$C,Z$3,$D:$D,$R16)*100 -> 0.5 | AA16: =SUMIFS($L:$L,$C:$C,AA$3,$D:$D,$R16)*100 -> 0 | AB16: =SUMPRODUCT($T$4:$AA$4,T16:AA16) -> 0.16136146 | AC16: =SUMIFS($L:$L,$C:$C,AC$3,$D:$D,$R16)*100 -> 0 | AD16: =SUMIFS($L:$L,$C:$C,AD$3,$D:$D,$R16)*100 -> 0 | AE16: =SUMIFS($L:$L,$C:$C,AE$3,$D:$D,$R16)*100 -> 0 | AF16: =SUMPRODUCT($AC$4:$AE$4,AC16:AE16) -> 0 | AH16: =AB16/100*$AL$6 -> 688.5627 | AI16: =AF16/100*$AL$23 -> 0 | AK16: Desperdicio total | AL16: 0.189899 | AQ16: Desvios | AR16: =AR13/AR14-1 -> 6.38792e-07
B17: 6 | C17: A01 | D17: M046 | E17: CHIPS DE CHOCOLATE | G17: X | L17: 0.09 | M17: =$E$9*L17 -> 0.30681818 | N17: Kg. | R17: M048 | S17: MIEL | T17: =SUMIFS($L:$L,$C:$C,T$3,$D:$D,$R17)*100 -> 2 | U17: =SUMIFS($L:$L,$C:$C,U$3,$D:$D,$R17)*100 -> 0 | V17: =SUMIFS($L:$L,$C:$C,V$3,$D:$D,$R17)*100 -> 0 | W17: =SUMIFS($L:$L,$C:$C,W$3,$D:$D,$R17)*100 -> 0 | X17: =SUMIFS($L:$L,$C:$C,X$3,$D:$D,$R17)*100 -> 0 | Y17: =SUMIFS($L:$L,$C:$C,Y$3,$D:$D,$R17)*100 -> 0 | Z17: =SUMIFS($L:$L,$C:$C,Z$3,$D:$D,$R17)*100 -> 0 | AA17: =SUMIFS($L:$L,$C:$C,AA$3,$D:$D,$R17)*100 -> 0 | AB17: =SUMPRODUCT($T$4:$AA$4,T17:AA17) -> 0.56337949 | AC17: =SUMIFS($L:$L,$C:$C,AC$3,$D:$D,$R17)*100 -> 0 | AD17: =SUMIFS($L:$L,$C:$C,AD$3,$D:$D,$R17)*100 -> 0 | AE17: =SUMIFS($L:$L,$C:$C,AE$3,$D:$D,$R17)*100 -> 0 | AF17: =SUMPRODUCT($AC$4:$AE$4,AC17:AE17) -> 0 | AH17: =AB17/100*$AL$6 -> 2404.0567 | AI17: =AF17/100*$AL$23 -> 0
B18: 7 | C18: A01 | D18: M031 | E18: JARABE DE GLUCOSA | G18: X | L18: 0.06 | M18: =$E$9*L18 -> 0.20454545 | N18: Kg. | R18: M049 | S18: JALAPEÑO DESHIDRATADO EN POLVO | T18: =SUMIFS($L:$L,$C:$C,T$3,$D:$D,$R18)*100 -> 0.2 | U18: =SUMIFS($L:$L,$C:$C,U$3,$D:$D,$R18)*100 -> 0 | V18: =SUMIFS($L:$L,$C:$C,V$3,$D:$D,$R18)*100 -> 0 | W18: =SUMIFS($L:$L,$C:$C,W$3,$D:$D,$R18)*100 -> 0 | X18: =SUMIFS($L:$L,$C:$C,X$3,$D:$D,$R18)*100 -> 0 | Y18: =SUMIFS($L:$L,$C:$C,Y$3,$D:$D,$R18)*100 -> 0 | Z18: =SUMIFS($L:$L,$C:$C,Z$3,$D:$D,$R18)*100 -> 0 | AA18: =SUMIFS($L:$L,$C:$C,AA$3,$D:$D,$R18)*100 -> 0 | AB18: =SUMPRODUCT($T$4:$AA$4,T18:AA18) -> 0.056337949 | AC18: =SUMIFS($L:$L,$C:$C,AC$3,$D:$D,$R18)*100 -> 0 | AD18: =SUMIFS($L:$L,$C:$C,AD$3,$D:$D,$R18)*100 -> 0 | AE18: =SUMIFS($L:$L,$C:$C,AE$3,$D:$D,$R18)*100 -> 0 | AF18: =SUMPRODUCT($AC$4:$AE$4,AC18:AE18) -> 0 | AH18: =AB18/100*$AL$6 -> 240.40567 | AI18: =AF18/100*$AL$23 -> 0
B19: 8 | C19: A01 | D19: M045 | E19: CACAO EN POLVO ALCALINO | G19: X | L19: 0.04 | M19: =$E$9*L19 -> 0.13636364 | N19: Kg. | R19: M052 | S19: AZÚCAR | T19: =SUMIFS($L:$L,$C:$C,T$3,$D:$D,$R19)*100 -> 14 | U19: =SUMIFS($L:$L,$C:$C,U$3,$D:$D,$R19)*100 -> 0 | V19: =SUMIFS($L:$L,$C:$C,V$3,$D:$D,$R19)*100 -> 18 | W19: =SUMIFS($L:$L,$C:$C,W$3,$D:$D,$R19)*100 -> 15.4 | X19: =SUMIFS($L:$L,$C:$C,X$3,$D:$D,$R19)*100 -> 0 | Y19: =SUMIFS($L:$L,$C:$C,Y$3,$D:$D,$R19)*100 -> 0 | Z19: =SUMIFS($L:$L,$C:$C,Z$3,$D:$D,$R19)*100 -> 0 | AA19: =SUMIFS($L:$L,$C:$C,AA$3,$D:$D,$R19)*100 -> 16 | AB19: =SUMPRODUCT($T$4:$AA$4,T19:AA19) -> 11.896713 | AC19: =SUMIFS($L:$L,$C:$C,AC$3,$D:$D,$R19)*100 -> 4 | AD19: =SUMIFS($L:$L,$C:$C,AD$3,$D:$D,$R19)*100 -> 22 | AE19: =SUMIFS($L:$L,$C:$C,AE$3,$D:$D,$R19)*100 -> 20 | AF19: =SUMPRODUCT($AC$4:$AE$4,AC19:AE19) -> 14.989476 | AH19: =AB19/100*$AL$6 -> 50765.73 | AI19: =AF19/100*$AL$23 -> 51493.61 | AK19: Linea B - Panificados | AU19: Linea B - Panificados
B20: 9 | C20: A01 | D20: M041 | E20: HUEVO EN POLVO DESHIDRATADO | G20: X | L20: 0.02 | M20: =$E$9*L20 -> 0.068181818 | N20: Kg. | R20: M056 | S20: BICARBONATO DE SODIO | T20: =SUMIFS($L:$L,$C:$C,T$3,$D:$D,$R20)*100 -> 0.5 | U20: =SUMIFS($L:$L,$C:$C,U$3,$D:$D,$R20)*100 -> 0.5 | V20: =SUMIFS($L:$L,$C:$C,V$3,$D:$D,$R20)*100 -> 0.8 | W20: =SUMIFS($L:$L,$C:$C,W$3,$D:$D,$R20)*100 -> 0 | X20: =SUMIFS($L:$L,$C:$C,X$3,$D:$D,$R20)*100 -> 0.5 | Y20: =SUMIFS($L:$L,$C:$C,Y$3,$D:$D,$R20)*100 -> 0.5 | Z20: =SUMIFS($L:$L,$C:$C,Z$3,$D:$D,$R20)*100 -> 0 | AA20: =SUMIFS($L:$L,$C:$C,AA$3,$D:$D,$R20)*100 -> 1 | AB20: =SUMPRODUCT($T$4:$AA$4,T20:AA20) -> 0.43643192 | AC20: =SUMIFS($L:$L,$C:$C,AC$3,$D:$D,$R20)*100 -> 0 | AD20: =SUMIFS($L:$L,$C:$C,AD$3,$D:$D,$R20)*100 -> 0 | AE20: =SUMIFS($L:$L,$C:$C,AE$3,$D:$D,$R20)*100 -> 0 | AF20: =SUMPRODUCT($AC$4:$AE$4,AC20:AE20) -> 0 | AH20: =AB20/100*$AL$6 -> 1862.3452 | AI20: =AF20/100*$AL$23 -> 0 | AK20: NECESIDAD ANUAL MP | AU20: MAQUINAS
B21: 10 | C21: A01 | D21: M048 | E21: MIEL | G21: X | L21: 0.02 | M21: =$E$9*L21 -> 0.068181818 | N21: Kg. | R21: M057 | S21: BICARBONATO DE CALCIO | T21: =SUMIFS($L:$L,$C:$C,T$3,$D:$D,$R21)*100 -> 0.3 | U21: =SUMIFS($L:$L,$C:$C,U$3,$D:$D,$R21)*100 -> 0.3 | V21: =SUMIFS($L:$L,$C:$C,V$3,$D:$D,$R21)*100 -> 0.8 | W21: =SUMIFS($L:$L,$C:$C,W$3,$D:$D,$R21)*100 -> 0 | X21: =SUMIFS($L:$L,$C:$C,X$3,$D:$D,$R21)*100 -> 0 | Y21: =SUMIFS($L:$L,$C:$C,Y$3,$D:$D,$R21)*100 -> 0 | Z21: =SUMIFS($L:$L,$C:$C,Z$3,$D:$D,$R21)*100 -> 0 | AA21: =SUMIFS($L:$L,$C:$C,AA$3,$D:$D,$R21)*100 -> 0 | AB21: =SUMPRODUCT($T$4:$AA$4,T21:AA21) -> 0.16384991 | AC21: =SUMIFS($L:$L,$C:$C,AC$3,$D:$D,$R21)*100 -> 0 | AD21: =SUMIFS($L:$L,$C:$C,AD$3,$D:$D,$R21)*100 -> 0 | AE21: =SUMIFS($L:$L,$C:$C,AE$3,$D:$D,$R21)*100 -> 0 | AF21: =SUMPRODUCT($AC$4:$AE$4,AC21:AE21) -> 0 | AH21: =AB21/100*$AL$6 -> 699.18141 | AI21: =AF21/100*$AL$23 -> 0 | AK21: Sección Operativa | AL21: Alimentación | AM21: Agregado | AN21: Desperdicios | AR21: Producción | AU21: Máquina | AV21: Modelo | AW21: Capacidad Teórica | AY21: Medidas | BA21: Peso | BC21: Consumo | BE21: Precio | BF21: Proveedor | BG21: Ubicación
B22: 11 | C22: A01 | D22: M022 | E22: GOMA XÁNTICA | G22: X | L22: 0.008 | M22: =$E$9*L22 -> 0.027272727 | N22: Kg. | R22: M089 | S22: ESENCIA DE VAINILLA | T22: =SUMIFS($L:$L,$C:$C,T$3,$D:$D,$R22)*100 -> 0.4 | U22: =SUMIFS($L:$L,$C:$C,U$3,$D:$D,$R22)*100 -> 0 | V22: =SUMIFS($L:$L,$C:$C,V$3,$D:$D,$R22)*100 -> 0 | W22: =SUMIFS($L:$L,$C:$C,W$3,$D:$D,$R22)*100 -> 0.14 | X22: =SUMIFS($L:$L,$C:$C,X$3,$D:$D,$R22)*100 -> 0 | Y22: =SUMIFS($L:$L,$C:$C,Y$3,$D:$D,$R22)*100 -> 0 | Z22: =SUMIFS($L:$L,$C:$C,Z$3,$D:$D,$R22)*100 -> 0 | AA22: =SUMIFS($L:$L,$C:$C,AA$3,$D:$D,$R22)*100 -> 0 | AB22: =SUMPRODUCT($T$4:$AA$4,T22:AA22) -> 0.14948342 | AC22: =SUMIFS($L:$L,$C:$C,AC$3,$D:$D,$R22)*100 -> 0 | AD22: =SUMIFS($L:$L,$C:$C,AD$3,$D:$D,$R22)*100 -> 0 | AE22: =SUMIFS($L:$L,$C:$C,AE$3,$D:$D,$R22)*100 -> 0.5 | AF22: =SUMPRODUCT($AC$4:$AE$4,AC22:AE22) -> 0.094736812 | AH22: =AB22/100*$AL$6 -> 637.87665 | AI22: =AF22/100*$AL$23 -> 325.45103 | AN22: Recuperable | AP22: No recuperable | AU22: Batidora | AX22: kg/h | AZ22: cm | BB22: kg | BC22: - | BD22: kw/h
B23: 12 | C23: A01 | D23: M006 | E23: SAL | G23: X | L23: 0.005 | M23: =$E$9*L23 -> 0.017045455 | N23: Kg. | R23: M104 | S23: PASTA DE PASAS DE UVA | T23: =SUMIFS($L:$L,$C:$C,T$3,$D:$D,$R23)*100 -> 0 | U23: =SUMIFS($L:$L,$C:$C,U$3,$D:$D,$R23)*100 -> 13 | V23: =SUMIFS($L:$L,$C:$C,V$3,$D:$D,$R23)*100 -> 0 | W23: =SUMIFS($L:$L,$C:$C,W$3,$D:$D,$R23)*100 -> 0 | X23: =SUMIFS($L:$L,$C:$C,X$3,$D:$D,$R23)*100 -> 0 | Y23: =SUMIFS($L:$L,$C:$C,Y$3,$D:$D,$R23)*100 -> 0 | Z23: =SUMIFS($L:$L,$C:$C,Z$3,$D:$D,$R23)*100 -> 16 | AA23: =SUMIFS($L:$L,$C:$C,AA$3,$D:$D,$R23)*100 -> 0 | AB23: =SUMPRODUCT($T$4:$AA$4,T23:AA23) -> 1.4901387 | AC23: =SUMIFS($L:$L,$C:$C,AC$3,$D:$D,$R23)*100 -> 0 | AD23: =SUMIFS($L:$L,$C:$C,AD$3,$D:$D,$R23)*100 -> 0 | AE23: =SUMIFS($L:$L,$C:$C,AE$3,$D:$D,$R23)*100 -> 0 | AF23: =SUMPRODUCT($AC$4:$AE$4,AC23:AE23) -> 0 | AH23: =AB23/100*$AL$6 -> 6358.7299 | AI23: =AF23/100*$AL$23 -> 0 | AK23: Batido | AL23: =AR32*(1+AL34) -> 343531.76 | AM23: 0 | AO23: =AL23*AN23 -> 0 | AQ23: =AL23*AP23 -> 0 | AR23: =AL23+AM23-AO23-AQ23 -> 343531.76 | AS23: kg/año | AU23: Dosificadora | AX23: kg/h | AZ23: cm | BB23: kg | BC23: - | BD23: kw/h
B24: 13 | C24: A01 | D24: M008 | E24: BICARBONATO DE AMONIO | G24: X | L24: 0.005 | M24: =$E$9*L24 -> 0.017045455 | N24: Kg. | R24: M105 | S24: ACEITE DE COCO | T24: =SUMIFS($L:$L,$C:$C,T$3,$D:$D,$R24)*100 -> 0 | U24: =SUMIFS($L:$L,$C:$C,U$3,$D:$D,$R24)*100 -> 5 | V24: =SUMIFS($L:$L,$C:$C,V$3,$D:$D,$R24)*100 -> 0 | W24: =SUMIFS($L:$L,$C:$C,W$3,$D:$D,$R24)*100 -> 0 | X24: =SUMIFS($L:$L,$C:$C,X$3,$D:$D,$R24)*100 -> 0 | Y24: =SUMIFS($L:$L,$C:$C,Y$3,$D:$D,$R24)*100 -> 0 | Z24: =SUMIFS($L:$L,$C:$C,Z$3,$D:$D,$R24)*100 -> 0 | AA24: =SUMIFS($L:$L,$C:$C,AA$3,$D:$D,$R24)*100 -> 0 | AB24: =SUMPRODUCT($T$4:$AA$4,T24:AA24) -> 0.18309833 | AC24: =SUMIFS($L:$L,$C:$C,AC$3,$D:$D,$R24)*100 -> 0 | AD24: =SUMIFS($L:$L,$C:$C,AD$3,$D:$D,$R24)*100 -> 0 | AE24: =SUMIFS($L:$L,$C:$C,AE$3,$D:$D,$R24)*100 -> 0 | AF24: =SUMPRODUCT($AC$4:$AE$4,AC24:AE24) -> 0 | AH24: =AB24/100*$AL$6 -> 781.31841 | AI24: =AF24/100*$AL$23 -> 0 | AK24: Dosificado | AL24: =AR23 -> 343531.76 | AM24: 0 | AO24: =AL24*AN24 -> 0 | AQ24: =AL24*AP24 -> 0 | AR24: =AL24+AM24-AO24-AQ24 -> 343531.76 | AS24: kg/año | AU24: Fermentadora | AX24: kg/h | AZ24: cm | BB24: kg | BC24: - | BD24: kw/h
B25: 14 | C25: A01 | D25: M056 | E25: BICARBONATO DE SODIO | G25: X | L25: 0.005 | M25: =$E$9*L25 -> 0.017045455 | N25: Kg. | R25: M106 | S25: FIBRA DE BAMBÚ | T25: =SUMIFS($L:$L,$C:$C,T$3,$D:$D,$R25)*100 -> 0 | U25: =SUMIFS($L:$L,$C:$C,U$3,$D:$D,$R25)*100 -> 4 | V25: =SUMIFS($L:$L,$C:$C,V$3,$D:$D,$R25)*100 -> 0 | W25: =SUMIFS($L:$L,$C:$C,W$3,$D:$D,$R25)*100 -> 0 | X25: =SUMIFS($L:$L,$C:$C,X$3,$D:$D,$R25)*100 -> 0 | Y25: =SUMIFS($L:$L,$C:$C,Y$3,$D:$D,$R25)*100 -> 0 | Z25: =SUMIFS($L:$L,$C:$C,Z$3,$D:$D,$R25)*100 -> 6 | AA25: =SUMIFS($L:$L,$C:$C,AA$3,$D:$D,$R25)*100 -> 0 | AB25: =SUMPRODUCT($T$4:$AA$4,T25:AA25) -> 0.52675982 | AC25: =SUMIFS($L:$L,$C:$C,AC$3,$D:$D,$R25)*100 -> 0 | AD25: =SUMIFS($L:$L,$C:$C,AD$3,$D:$D,$R25)*100 -> 0 | AE25: =SUMIFS($L:$L,$C:$C,AE$3,$D:$D,$R25)*100 -> 0 | AF25: =SUMPRODUCT($AC$4:$AE$4,AC25:AE25) -> 0 | AH25: =AB25/100*$AL$6 -> 2247.793 | AI25: =AF25/100*$AL$23 -> 0 | AK25: Fermentado | AL25: =AR24 -> 343531.76 | AM25: 0 | AO25: =AL25*AN25 -> 0 | AQ25: =AL25*AP25 -> 0 | AR25: =AL25+AM25-AO25-AQ25 -> 343531.76 | AS25: kg/año | AU25: Horno rotativo | AX25: kg/h | AZ25: cm | BB25: kg | BC25: - | BD25: kw/h
B26: 15 | C26: A01 | D26: M089 | E26: ESENCIA DE VAINILLA | G26: X | L26: 0.004 | M26: =$E$9*L26 -> 0.013636364 | N26: Kg. | R26: M107 | S26: PSYLLIUM | T26: =SUMIFS($L:$L,$C:$C,T$3,$D:$D,$R26)*100 -> 0 | U26: =SUMIFS($L:$L,$C:$C,U$3,$D:$D,$R26)*100 -> 3 | V26: =SUMIFS($L:$L,$C:$C,V$3,$D:$D,$R26)*100 -> 0 | W26: =SUMIFS($L:$L,$C:$C,W$3,$D:$D,$R26)*100 -> 0 | X26: =SUMIFS($L:$L,$C:$C,X$3,$D:$D,$R26)*100 -> 0 | Y26: =SUMIFS($L:$L,$C:$C,Y$3,$D:$D,$R26)*100 -> 0 | Z26: =SUMIFS($L:$L,$C:$C,Z$3,$D:$D,$R26)*100 -> 0 | AA26: =SUMIFS($L:$L,$C:$C,AA$3,$D:$D,$R26)*100 -> 0 | AB26: =SUMPRODUCT($T$4:$AA$4,T26:AA26) -> 0.109859 | AC26: =SUMIFS($L:$L,$C:$C,AC$3,$D:$D,$R26)*100 -> 3 | AD26: =SUMIFS($L:$L,$C:$C,AD$3,$D:$D,$R26)*100 -> 0 | AE26: =SUMIFS($L:$L,$C:$C,AE$3,$D:$D,$R26)*100 -> 0 | AF26: =SUMPRODUCT($AC$4:$AE$4,AC26:AE26) -> 1.1052628 | AH26: =AB26/100*$AL$6 -> 468.79105 | AI26: =AF26/100*$AL$23 -> 3796.9287 | AK26: Horneado | AL26: =AR25 -> 343531.76 | AM26: 0 | AO26: =AL26*AN26 -> 0 | AQ26: =AL26*AP26 -> 0 | AR26: =AL26+AM26-AO26-AQ26 -> 343531.76 | AS26: kg/año | AU26: Cinta de enfriamiento | AX26: kg/h | AZ26: cm | BB26: kg | BC26: - | BD26: kw/h
B27: 16 | C27: A01 | D27: M047 | E27: ESENCIA DE CHOCOLATE | G27: X | L27: 0.003 | M27: =$E$9*L27 -> 0.010227273 | N27: Kg. | R27: M108 | S27: EDULCORANTE | T27: =SUMIFS($L:$L,$C:$C,T$3,$D:$D,$R27)*100 -> 0 | U27: =SUMIFS($L:$L,$C:$C,U$3,$D:$D,$R27)*100 -> 1.5 | V27: =SUMIFS($L:$L,$C:$C,V$3,$D:$D,$R27)*100 -> 0 | W27: =SUMIFS($L:$L,$C:$C,W$3,$D:$D,$R27)*100 -> 0 | X27: =SUMIFS($L:$L,$C:$C,X$3,$D:$D,$R27)*100 -> 0 | Y27: =SUMIFS($L:$L,$C:$C,Y$3,$D:$D,$R27)*100 -> 0 | Z27: =SUMIFS($L:$L,$C:$C,Z$3,$D:$D,$R27)*100 -> 3 | AA27: =SUMIFS($L:$L,$C:$C,AA$3,$D:$D,$R27)*100 -> 0 | AB27: =SUMPRODUCT($T$4:$AA$4,T27:AA27) -> 0.24507008 | AC27: =SUMIFS($L:$L,$C:$C,AC$3,$D:$D,$R27)*100 -> 0 | AD27: =SUMIFS($L:$L,$C:$C,AD$3,$D:$D,$R27)*100 -> 0 | AE27: =SUMIFS($L:$L,$C:$C,AE$3,$D:$D,$R27)*100 -> 0 | AF27: =SUMPRODUCT($AC$4:$AE$4,AC27:AE27) -> 0 | AH27: =AB27/100*$AL$6 -> 1045.7646 | AI27: =AF27/100*$AL$23 -> 0 | AK27: Desmolde | AL27: =AR26 -> 343531.76 | AM27: 0 | AO27: =AL27*AN27 -> 0 | AQ27: =AL27*AP27 -> 0 | AR27: =AL27+AM27-AO27-AQ27 -> 343531.76 | AS27: kg/año | AU27: Envasadora | AX27: kg/h | AZ27: cm | BB27: kg | BC27: - | BD27: kw/h
B28: 17 | C28: A01 | D28: M057 | E28: BICARBONATO DE CALCIO | G28: X | L28: 0.003 | M28: =$E$9*L28 -> 0.010227273 | N28: Kg. | R28: M109 | S28: LECHE EN POLVO | T28: =SUMIFS($L:$L,$C:$C,T$3,$D:$D,$R28)*100 -> 0 | U28: =SUMIFS($L:$L,$C:$C,U$3,$D:$D,$R28)*100 -> 0 | V28: =SUMIFS($L:$L,$C:$C,V$3,$D:$D,$R28)*100 -> 6 | W28: =SUMIFS($L:$L,$C:$C,W$3,$D:$D,$R28)*100 -> 0 | X28: =SUMIFS($L:$L,$C:$C,X$3,$D:$D,$R28)*100 -> 0 | Y28: =SUMIFS($L:$L,$C:$C,Y$3,$D:$D,$R28)*100 -> 0 | Z28: =SUMIFS($L:$L,$C:$C,Z$3,$D:$D,$R28)*100 -> 0 | AA28: =SUMIFS($L:$L,$C:$C,AA$3,$D:$D,$R28)*100 -> 0 | AB28: =SUMPRODUCT($T$4:$AA$4,T28:AA28) -> 0.51267815 | AC28: =SUMIFS($L:$L,$C:$C,AC$3,$D:$D,$R28)*100 -> 4 | AD28: =SUMIFS($L:$L,$C:$C,AD$3,$D:$D,$R28)*100 -> 5 | AE28: =SUMIFS($L:$L,$C:$C,AE$3,$D:$D,$R28)*100 -> 4 | AF28: =SUMPRODUCT($AC$4:$AE$4,AC28:AE28) -> 4.4421054 | AH28: =AB28/100*$AL$6 -> 2187.7036 | AI28: =AF28/100*$AL$23 -> 15260.043 | AK28: Enfriado | AL28: =AR27 -> 343531.76 | AM28: 0 | AO28: =AL28*AN28 -> 0 | AP28: 0.04 | AQ28: =AL28*AP28 -> 13741.27 | AR28: =AL28+AM28-AO28-AQ28 -> 329790.49 | AS28: kg/año | AU28: Envasadora | AX28: kg/h | AZ28: cm | BB28: kg | BC28: - | BD28: kw/h
B29: 18 | C29: A01 | D29: M049 | E29: JALAPEÑO DESHIDRATADO EN POLVO | G29: X | L29: 0.002 | M29: =$E$9*L29 -> 0.0068181818 | N29: Kg. | R29: M110 | S29: JARABE DE MAÍZ ALTA FRUCTOSA | T29: =SUMIFS($L:$L,$C:$C,T$3,$D:$D,$R29)*100 -> 0 | U29: =SUMIFS($L:$L,$C:$C,U$3,$D:$D,$R29)*100 -> 0 | V29: =SUMIFS($L:$L,$C:$C,V$3,$D:$D,$R29)*100 -> 0 | W29: =SUMIFS($L:$L,$C:$C,W$3,$D:$D,$R29)*100 -> 7.92 | X29: =SUMIFS($L:$L,$C:$C,X$3,$D:$D,$R29)*100 -> 0 | Y29: =SUMIFS($L:$L,$C:$C,Y$3,$D:$D,$R29)*100 -> 0 | Z29: =SUMIFS($L:$L,$C:$C,Z$3,$D:$D,$R29)*100 -> 0 | AA29: =SUMIFS($L:$L,$C:$C,AA$3,$D:$D,$R29)*100 -> 0 | AB29: =SUMPRODUCT($T$4:$AA$4,T29:AA29) -> 2.0822543 | AC29: =SUMIFS($L:$L,$C:$C,AC$3,$D:$D,$R29)*100 -> 0 | AD29: =SUMIFS($L:$L,$C:$C,AD$3,$D:$D,$R29)*100 -> 0 | AE29: =SUMIFS($L:$L,$C:$C,AE$3,$D:$D,$R29)*100 -> 0 | AF29: =SUMPRODUCT($AC$4:$AE$4,AC29:AE29) -> 0 | AH29: =AB29/100*$AL$6 -> 8885.4093 | AI29: =AF29/100*$AL$23 -> 0 | AK29: Envasado primario | AL29: =AR28 -> 329790.49 | AM29: 0 | AO29: =AL29*AN29 -> 0 | AP29: 0.03 | AQ29: =AL29*AP29 -> 9893.7146 | AR29: =AL29+AM29-AO29-AQ29 -> 319896.77 | AS29: kg/año | AX29: kg/h | AZ29: cm | BB29: kg | BC29: - | BD29: kw/h
E30: AGUA
D31: TOTAL MEZCLA | L31: =L13+L14+L15+L16+L17+L18+L19+L20+L21+L22+L23+L24+L25+L26+L27+L28+L29 -> 1 | M31: =M13+M14+M15+M16+M17+M18+M19+M20+M21+M22+M23+M24+M25+M26+M27+M28+M29 -> 3.4090909 | N31: Kg. | R31: M111 | S31: LECITINA DE SOJA | T31: =SUMIFS($L:$L,$C:$C,T$3,$D:$D,$R31)*100 -> 0 | U31: =SUMIFS($L:$L,$C:$C,U$3,$D:$D,$R31)*100 -> 0 | V31: =SUMIFS($L:$L,$C:$C,V$3,$D:$D,$R31)*100 -> 0 | W31: =SUMIFS($L:$L,$C:$C,W$3,$D:$D,$R31)*100 -> 0.36 | X31: =SUMIFS($L:$L,$C:$C,X$3,$D:$D,$R31)*100 -> 0 | Y31: =SUMIFS($L:$L,$C:$C,Y$3,$D:$D,$R31)*100 -> 0 | Z31: =SUMIFS($L:$L,$C:$C,Z$3,$D:$D,$R31)*100 -> 0 | AA31: =SUMIFS($L:$L,$C:$C,AA$3,$D:$D,$R31)*100 -> 1 | AB31: =SUMPRODUCT($T$4:$AA$4,T31:AA31) -> 0.24253504 | AC31: =SUMIFS($L:$L,$C:$C,AC$3,$D:$D,$R31)*100 -> 0 | AD31: =SUMIFS($L:$L,$C:$C,AD$3,$D:$D,$R31)*100 -> 0 | AE31: =SUMIFS($L:$L,$C:$C,AE$3,$D:$D,$R31)*100 -> 0 | AF31: =SUMPRODUCT($AC$4:$AE$4,AC31:AE31) -> 0 | AH31: =AB31/100*$AL$6 -> 1034.9471 | AI31: =AF31/100*$AL$23 -> 0 | AK31: Envasado secundario | AL31: =AR29 -> 319896.77 | AM31: 0 | AO31: =AL31*AN31 -> 0 | AQ31: =AL31*AP31 -> 0 | AR31: =AL31+AM31-AO31-AQ31 -> 319896.77 | AS31: kg/año | AX31: kg/h | AZ31: cm | BB31: kg | BC31: - | BD31: kw/h
B32: EMBALAJE | R32: M112 | S32: ESENCIA DE LECHE CONDENSADA | T32: =SUMIFS($L:$L,$C:$C,T$3,$D:$D,$R32)*100 -> 0 | U32: =SUMIFS($L:$L,$C:$C,U$3,$D:$D,$R32)*100 -> 0 | V32: =SUMIFS($L:$L,$C:$C,V$3,$D:$D,$R32)*100 -> 0 | W32: =SUMIFS($L:$L,$C:$C,W$3,$D:$D,$R32)*100 -> 0.288 | X32: =SUMIFS($L:$L,$C:$C,X$3,$D:$D,$R32)*100 -> 0 | Y32: =SUMIFS($L:$L,$C:$C,Y$3,$D:$D,$R32)*100 -> 0 | Z32: =SUMIFS($L:$L,$C:$C,Z$3,$D:$D,$R32)*100 -> 0 | AA32: =SUMIFS($L:$L,$C:$C,AA$3,$D:$D,$R32)*100 -> 0 | AB32: =SUMPRODUCT($T$4:$AA$4,T32:AA32) -> 0.075718338 | AC32: =SUMIFS($L:$L,$C:$C,AC$3,$D:$D,$R32)*100 -> 0 | AD32: =SUMIFS($L:$L,$C:$C,AD$3,$D:$D,$R32)*100 -> 0 | AE32: =SUMIFS($L:$L,$C:$C,AE$3,$D:$D,$R32)*100 -> 0 | AF32: =SUMPRODUCT($AC$4:$AE$4,AC32:AE32) -> 0 | AH32: =AB32/100*$AL$6 -> 323.10579 | AI32: =AF32/100*$AL$23 -> 0 | AK32: TOTALES | AL32: =AL23 -> 343531.76 | AM32: =AM23 -> 0 | AO32: =AO23+AO24+AO25+AO26+AO28 -> 0 | AQ32: =AQ23+AQ24+AQ25+AQ26+AQ28 -> 13741.27 | AR32: =SUMIFS('Plan de ventas'!$O48:$O60,'Plan de ventas'!$B$48:$B$60,"*B*")*1000 -> 319894.73 | AS32: kg/año | AX32: kg/h | AZ32: cm | BB32: kg | BC32: - | BD32: kw/h
B33: 19 | C33: A01 | D33: M101 | E33: FILM FLOW-PACK (ENVOLTORIO PRIMARIO) | G33: X | L33: — | M33: =$E$4*$E$5 -> 20 | N33: uni. | O33: 1 por unidad | R33: M113 | S33: MERMELADA DE BATATA | T33: =SUMIFS($L:$L,$C:$C,T$3,$D:$D,$R33)*100 -> 0 | U33: =SUMIFS($L:$L,$C:$C,U$3,$D:$D,$R33)*100 -> 0 | V33: =SUMIFS($L:$L,$C:$C,V$3,$D:$D,$R33)*100 -> 0 | W33: =SUMIFS($L:$L,$C:$C,W$3,$D:$D,$R33)*100 -> 19.6 | X33: =SUMIFS($L:$L,$C:$C,X$3,$D:$D,$R33)*100 -> 0 | Y33: =SUMIFS($L:$L,$C:$C,Y$3,$D:$D,$R33)*100 -> 0 | Z33: =SUMIFS($L:$L,$C:$C,Z$3,$D:$D,$R33)*100 -> 0 | AA33: =SUMIFS($L:$L,$C:$C,AA$3,$D:$D,$R33)*100 -> 0 | AB33: =SUMPRODUCT($T$4:$AA$4,T33:AA33) -> 5.1530536 | AC33: =SUMIFS($L:$L,$C:$C,AC$3,$D:$D,$R33)*100 -> 0 | AD33: =SUMIFS($L:$L,$C:$C,AD$3,$D:$D,$R33)*100 -> 0 | AE33: =SUMIFS($L:$L,$C:$C,AE$3,$D:$D,$R33)*100 -> 0 | AF33: =SUMPRODUCT($AC$4:$AE$4,AC33:AE33) -> 0 | AH33: =AB33/100*$AL$6 -> 21989.144 | AI33: =AF33/100*$AL$23 -> 0
B34: 20 | C34: A01 | D34: M102 | E34: CAJA DE CARTÓN CORRUGADO | G34: X | L34: — | M34: =$E$4 -> 1 | N34: uni. | O34: 1 por caja | R34: M114 | S34: ÁCIDO CÍTRICO | T34: =SUMIFS($L:$L,$C:$C,T$3,$D:$D,$R34)*100 -> 0 | U34: =SUMIFS($L:$L,$C:$C,U$3,$D:$D,$R34)*100 -> 0 | V34: =SUMIFS($L:$L,$C:$C,V$3,$D:$D,$R34)*100 -> 0 | W34: =SUMIFS($L:$L,$C:$C,W$3,$D:$D,$R34)*100 -> 0.14 | X34: =SUMIFS($L:$L,$C:$C,X$3,$D:$D,$R34)*100 -> 0 | Y34: =SUMIFS($L:$L,$C:$C,Y$3,$D:$D,$R34)*100 -> 0 | Z34: =SUMIFS($L:$L,$C:$C,Z$3,$D:$D,$R34)*100 -> 0 | AA34: =SUMIFS($L:$L,$C:$C,AA$3,$D:$D,$R34)*100 -> 0 | AB34: =SUMPRODUCT($T$4:$AA$4,T34:AA34) -> 0.036807526 | AC34: =SUMIFS($L:$L,$C:$C,AC$3,$D:$D,$R34)*100 -> 0 | AD34: =SUMIFS($L:$L,$C:$C,AD$3,$D:$D,$R34)*100 -> 0 | AE34: =SUMIFS($L:$L,$C:$C,AE$3,$D:$D,$R34)*100 -> 0 | AF34: =SUMPRODUCT($AC$4:$AE$4,AC34:AE34) -> 0 | AH34: =AB34/100*$AL$6 -> 157.06532 | AI34: =AF34/100*$AL$23 -> 0 | AK34: Desperdicio total | AL34: 0.07389 | AQ34: Desvios | AR34: =AR31/AR32-1 -> 6.368e-06
B35: 21 | C35: A01 | D35: M103 | E35: CINTA DE CIERRE | G35: X | L35: — | M35: =$E$4 -> 1 | N35: uni. | O35: 1 por caja | R35: M115 | S35: ALMIDÓN DE MAÍZ | T35: =SUMIFS($L:$L,$C:$C,T$3,$D:$D,$R35)*100 -> 0 | U35: =SUMIFS($L:$L,$C:$C,U$3,$D:$D,$R35)*100 -> 0 | V35: =SUMIFS($L:$L,$C:$C,V$3,$D:$D,$R35)*100 -> 0 | W35: =SUMIFS($L:$L,$C:$C,W$3,$D:$D,$R35)*100 -> 0 | X35: =SUMIFS($L:$L,$C:$C,X$3,$D:$D,$R35)*100 -> 19 | Y35: =SUMIFS($L:$L,$C:$C,Y$3,$D:$D,$R35)*100 -> 19 | Z35: =SUMIFS($L:$L,$C:$C,Z$3,$D:$D,$R35)*100 -> 0 | AA35: =SUMIFS($L:$L,$C:$C,AA$3,$D:$D,$R35)*100 -> 0 | AB35: =SUMPRODUCT($T$4:$AA$4,T35:AA35) -> 2.3192545 | AC35: =SUMIFS($L:$L,$C:$C,AC$3,$D:$D,$R35)*100 -> 12 | AD35: =SUMIFS($L:$L,$C:$C,AD$3,$D:$D,$R35)*100 -> 0 | AE35: =SUMIFS($L:$L,$C:$C,AE$3,$D:$D,$R35)*100 -> 0 | AF35: =SUMPRODUCT($AC$4:$AE$4,AC35:AE35) -> 4.4210512 | AH35: =AB35/100*$AL$6 -> 9896.738 | AI35: =AF35/100*$AL$23 -> 15187.715
R36: M116 | S36: FÉCULA DE MANDIOCA | T36: =SUMIFS($L:$L,$C:$C,T$3,$D:$D,$R36)*100 -> 0 | U36: =SUMIFS($L:$L,$C:$C,U$3,$D:$D,$R36)*100 -> 0 | V36: =SUMIFS($L:$L,$C:$C,V$3,$D:$D,$R36)*100 -> 0 | W36: =SUMIFS($L:$L,$C:$C,W$3,$D:$D,$R36)*100 -> 0 | X36: =SUMIFS($L:$L,$C:$C,X$3,$D:$D,$R36)*100 -> 15 | Y36: =SUMIFS($L:$L,$C:$C,Y$3,$D:$D,$R36)*100 -> 14 | Z36: =SUMIFS($L:$L,$C:$C,Z$3,$D:$D,$R36)*100 -> 0 | AA36: =SUMIFS($L:$L,$C:$C,AA$3,$D:$D,$R36)*100 -> 0 | AB36: =SUMPRODUCT($T$4:$AA$4,T36:AA36) -> 1.745544 | AC36: =SUMIFS($L:$L,$C:$C,AC$3,$D:$D,$R36)*100 -> 10 | AD36: =SUMIFS($L:$L,$C:$C,AD$3,$D:$D,$R36)*100 -> 6 | AE36: =SUMIFS($L:$L,$C:$C,AE$3,$D:$D,$R36)*100 -> 5 | AF36: =SUMPRODUCT($AC$4:$AE$4,AC36:AE36) -> 7.2842101 | AH36: =AB36/100*$AL$6 -> 7448.5969 | AI36: =AF36/100*$AL$23 -> 25023.575
D37: Galletitas símil chocolinas free - A02 | M37: Foto | R37: M117 | S37: QUESO DESCREMADO EN POLVO | T37: =SUMIFS($L:$L,$C:$C,T$3,$D:$D,$R37)*100 -> 0 | U37: =SUMIFS($L:$L,$C:$C,U$3,$D:$D,$R37)*100 -> 0 | V37: =SUMIFS($L:$L,$C:$C,V$3,$D:$D,$R37)*100 -> 0 | W37: =SUMIFS($L:$L,$C:$C,W$3,$D:$D,$R37)*100 -> 0 | X37: =SUMIFS($L:$L,$C:$C,X$3,$D:$D,$R37)*100 -> 13 | Y37: =SUMIFS($L:$L,$C:$C,Y$3,$D:$D,$R37)*100 -> 0 | Z37: =SUMIFS($L:$L,$C:$C,Z$3,$D:$D,$R37)*100 -> 0 | AA37: =SUMIFS($L:$L,$C:$C,AA$3,$D:$D,$R37)*100 -> 0 | AB37: =SUMPRODUCT($T$4:$AA$4,T37:AA37) -> 0.47605567 | AC37: =SUMIFS($L:$L,$C:$C,AC$3,$D:$D,$R37)*100 -> 0 | AD37: =SUMIFS($L:$L,$C:$C,AD$3,$D:$D,$R37)*100 -> 0 | AE37: =SUMIFS($L:$L,$C:$C,AE$3,$D:$D,$R37)*100 -> 0 | AF37: =SUMPRODUCT($AC$4:$AE$4,AC37:AE37) -> 0 | AH37: =AB37/100*$AL$6 -> 2031.4279 | AI37: =AF37/100*$AL$23 -> 0
D38: PT anual (kg) | E38: =SUMIFS('Plan de ventas'!$O$48:$O$60,'Plan de ventas'!$B$48:$B$60,D47)*1000 -> 13132.517 | R38: M118 | S38: ACEITE DE GIRASOL ALTO OLEICO | T38: =SUMIFS($L:$L,$C:$C,T$3,$D:$D,$R38)*100 -> 0 | U38: =SUMIFS($L:$L,$C:$C,U$3,$D:$D,$R38)*100 -> 0 | V38: =SUMIFS($L:$L,$C:$C,V$3,$D:$D,$R38)*100 -> 0 | W38: =SUMIFS($L:$L,$C:$C,W$3,$D:$D,$R38)*100 -> 0 | X38: =SUMIFS($L:$L,$C:$C,X$3,$D:$D,$R38)*100 -> 8 | Y38: =SUMIFS($L:$L,$C:$C,Y$3,$D:$D,$R38)*100 -> 6 | Z38: =SUMIFS($L:$L,$C:$C,Z$3,$D:$D,$R38)*100 -> 0 | AA38: =SUMIFS($L:$L,$C:$C,AA$3,$D:$D,$R38)*100 -> 0 | AB38: =SUMPRODUCT($T$4:$AA$4,T38:AA38) -> 0.80563549 | AC38: =SUMIFS($L:$L,$C:$C,AC$3,$D:$D,$R38)*100 -> 0 | AD38: =SUMIFS($L:$L,$C:$C,AD$3,$D:$D,$R38)*100 -> 0 | AE38: =SUMIFS($L:$L,$C:$C,AE$3,$D:$D,$R38)*100 -> 0 | AF38: =SUMPRODUCT($AC$4:$AE$4,AC38:AE38) -> 0 | AH38: =AB38/100*$AL$6 -> 3437.813 | AI38: =AF38/100*$AL$23 -> 0
B39: Cajas / lote | E39: 1 | F39: ="Línea: Free | Versión n°: 1"&CHAR(10)&CHAR(10)&"Lote = "&E39&" cajas × "&E40&" unid./caja = "&(E39*E40)&" unidades"&CHAR(10)&"Producto terminado = "&TEXT(E43,"#,##0.00")&" kg"&CHAR(10)&"Mezcla a preparar = "&TEXT(E44,"#,##0.00")&" kg (rendimiento "&TEXT(E42,"0%")&")" -> Línea: Free | Versión n°: 1 Lote = 1 cajas × 20 unid./caja = 20 unidades Producto terminado = 3,00 kg Mezcla a preparar = 3,41 kg (rendimiento 88%) | R39: M119 | S39: CLARA DE HUEVO EN POLVO | T39: =SUMIFS($L:$L,$C:$C,T$3,$D:$D,$R39)*100 -> 0 | U39: =SUMIFS($L:$L,$C:$C,U$3,$D:$D,$R39)*100 -> 0 | V39: =SUMIFS($L:$L,$C:$C,V$3,$D:$D,$R39)*100 -> 0 | W39: =SUMIFS($L:$L,$C:$C,W$3,$D:$D,$R39)*100 -> 0 | X39: =SUMIFS($L:$L,$C:$C,X$3,$D:$D,$R39)*100 -> 5 | Y39: =SUMIFS($L:$L,$C:$C,Y$3,$D:$D,$R39)*100 -> 0 | Z39: =SUMIFS($L:$L,$C:$C,Z$3,$D:$D,$R39)*100 -> 0 | AA39: =SUMIFS($L:$L,$C:$C,AA$3,$D:$D,$R39)*100 -> 0 | AB39: =SUMPRODUCT($T$4:$AA$4,T39:AA39) -> 0.18309833 | AC39: =SUMIFS($L:$L,$C:$C,AC$3,$D:$D,$R39)*100 -> 0 | AD39: =SUMIFS($L:$L,$C:$C,AD$3,$D:$D,$R39)*100 -> 0 | AE39: =SUMIFS($L:$L,$C:$C,AE$3,$D:$D,$R39)*100 -> 0 | AF39: =SUMPRODUCT($AC$4:$AE$4,AC39:AE39) -> 0 | AH39: =AB39/100*$AL$6 -> 781.31841 | AI39: =AF39/100*$AL$23 -> 0
B40: Unid. / caja | E40: 20 | R40: M120 | S40: DEXTROSA | T40: =SUMIFS($L:$L,$C:$C,T$3,$D:$D,$R40)*100 -> 0 | U40: =SUMIFS($L:$L,$C:$C,U$3,$D:$D,$R40)*100 -> 0 | V40: =SUMIFS($L:$L,$C:$C,V$3,$D:$D,$R40)*100 -> 0 | W40: =SUMIFS($L:$L,$C:$C,W$3,$D:$D,$R40)*100 -> 0 | X40: =SUMIFS($L:$L,$C:$C,X$3,$D:$D,$R40)*100 -> 4 | Y40: =SUMIFS($L:$L,$C:$C,Y$3,$D:$D,$R40)*100 -> 4 | Z40: =SUMIFS($L:$L,$C:$C,Z$3,$D:$D,$R40)*100 -> 0 | AA40: =SUMIFS($L:$L,$C:$C,AA$3,$D:$D,$R40)*100 -> 0 | AB40: =SUMPRODUCT($T$4:$AA$4,T40:AA40) -> 0.4882641 | AC40: =SUMIFS($L:$L,$C:$C,AC$3,$D:$D,$R40)*100 -> 0 | AD40: =SUMIFS($L:$L,$C:$C,AD$3,$D:$D,$R40)*100 -> 0 | AE40: =SUMIFS($L:$L,$C:$C,AE$3,$D:$D,$R40)*100 -> 0 | AF40: =SUMPRODUCT($AC$4:$AE$4,AC40:AE40) -> 0 | AH40: =AB40/100*$AL$6 -> 2083.5238 | AI40: =AF40/100*$AL$23 -> 0
B41: Peso neto (g) | E41: 150 | R41: M121 | S41: ESENCIA DE QUESO | T41: =SUMIFS($L:$L,$C:$C,T$3,$D:$D,$R41)*100 -> 0 | U41: =SUMIFS($L:$L,$C:$C,U$3,$D:$D,$R41)*100 -> 0 | V41: =SUMIFS($L:$L,$C:$C,V$3,$D:$D,$R41)*100 -> 0 | W41: =SUMIFS($L:$L,$C:$C,W$3,$D:$D,$R41)*100 -> 0 | X41: =SUMIFS($L:$L,$C:$C,X$3,$D:$D,$R41)*100 -> 1 | Y41: =SUMIFS($L:$L,$C:$C,Y$3,$D:$D,$R41)*100 -> 1 | Z41: =SUMIFS($L:$L,$C:$C,Z$3,$D:$D,$R41)*100 -> 0 | AA41: =SUMIFS($L:$L,$C:$C,AA$3,$D:$D,$R41)*100 -> 0 | AB41: =SUMPRODUCT($T$4:$AA$4,T41:AA41) -> 0.12206603 | AC41: =SUMIFS($L:$L,$C:$C,AC$3,$D:$D,$R41)*100 -> 0 | AD41: =SUMIFS($L:$L,$C:$C,AD$3,$D:$D,$R41)*100 -> 0 | AE41: =SUMIFS($L:$L,$C:$C,AE$3,$D:$D,$R41)*100 -> 0 | AF41: =SUMPRODUCT($AC$4:$AE$4,AC41:AE41) -> 0 | AH41: =AB41/100*$AL$6 -> 520.88095 | AI41: =AF41/100*$AL$23 -> 0
...

Sheet BOM y balanceo
D2: Chocolate con chips picante - A01 | M2: Foto | R2: Calculo de receta promedio ponderada - kg de MP cada 100kg | AB2: 100 kg | AF2: 100 kg | AH2: =AL6 -> 431449.24 | AI2: =AL23 -> 395371.07 | AK2: Linea A - Galletitas | AU2: Linea A - Galletitas
D3: PT anual (kg) | E3: =SUMIFS('Plan de ventas'!$O$48:$O$60,'Plan de ventas'!$B$48:$B$60,D12)*1000 -> 101019.36 | R3: CÓDIGO | S3: DENOMINACIÓN | T3: A01 | U3: A02 | V3: A03 | W3: A04 | X3: A05 | Y3: A06 | Z3: A07 | AA3: A08 | AB3: A00 | AC3: B01 | AD3: B02 | AE3: B03 | AF3: B00 | AH3: A00 | AI3: B00 | AK3: NECESIDAD ANUAL MP | AU3: MAQUINAS
B4: Cajas / lote | E4: 1 | F4: ="Línea: Gourmet | Versión n°: 1"&CHAR(10)&CHAR(10)&"Lote = "&E4&" cajas × "&E5&" unid./caja = "&(E4*E5)&" unidades"&CHAR(10)&"Producto terminado = "&TEXT(E8,"#,##0.00")&" kg"&CHAR(10)&"Mezcla a preparar = "&TEXT(E9,"#,##0.00")&" kg (rendimiento "&TEXT(E7,"0%")&")" -> Línea: Gourmet | Versión n°: 1 Lote = 1 cajas × 20 unid./caja = 20 unidades Producto terminado = 3,00 kg Mezcla a preparar = 3,41 kg (rendimiento 88%) | S4: Volumen relativo (año 10) | T4: =SUMIFS('Plan de ventas'!$P$48:$P$60,'Plan de ventas'!$B$48:$B$60,T3) -> 0.28168974 | U4: =SUMIFS('Plan de ventas'!$P$48:$P$60,'Plan de ventas'!$B$48:$B$60,U3) -> 0.036619667 | V4: =SUMIFS('Plan de ventas'!$P$48:$P$60,'Plan de ventas'!$B$48:$B$60,V3) -> 0.085446359 | W4: =SUMIFS('Plan de ventas'!$P$48:$P$60,'Plan de ventas'!$B$48:$B$60,W3) -> 0.2629109 | X4: =SUMIFS('Plan de ventas'!$P$48:$P$60,'Plan de ventas'!$B$48:$B$60,X3) -> 0.036619667 | Y4: =SUMIFS('Plan de ventas'!$P$48:$P$60,'Plan de ventas'!$B$48:$B$60,Y3) -> 0.085446359 | Z4: =SUMIFS('Plan de ventas'!$P$48:$P$60,'Plan de ventas'!$B$48:$B$60,Z3) -> 0.063380192 | AA4: =SUMIFS('Plan de ventas'!$P$48:$P$60,'Plan de ventas'!$B$48:$B$60,AA3) -> 0.14788712 | AB4: =SUM(T4:AA4) -> 1 | AC4: =SUMIFS('Plan de ventas'!$P$48:$P$60,'Plan de ventas'!$B$48:$B$60,AC3) -> 0.36842094 | AD4: =SUMIFS('Plan de ventas'!$P$48:$P$60,'Plan de ventas'!$B$48:$B$60,AD3) -> 0.44210544 | AE4: =SUMIFS('Plan de ventas'!$P$48:$P$60,'Plan de ventas'!$B$48:$B$60,AE3) -> 0.18947362 | AF4: =SUM(AC4:AE4) -> 1 | AK4: Sección Operativa | AL4: Alimentación | AM4: Agregado | AN4: Desperdicios | AR4: Producción | AU4: Máquina | AV4: Modelo | AW4: Capacidad Teórica | AY4: Medidas | BA4: Peso | BC4: Consumo | BE4: Precio | BF4: Proveedor | BG4: Ubicación
B5: Unid. / caja | E5: 20 | R5: M001 | S5: FÉCULA DE MAÍZ | T5: =SUMIFS($L:$L,$C:$C,T$3,$D:$D,$R5)*100 -> 24.645 | U5: =SUMIFS($L:$L,$C:$C,U$3,$D:$D,$R5)*100 -> 22.32 | V5: =SUMIFS($L:$L,$C:$C,V$3,$D:$D,$R5)*100 -> 20.46 | W5: =SUMIFS($L:$L,$C:$C,W$3,$D:$D,$R5)*100 -> 21.6876 | X5: =SUMIFS($L:$L,$C:$C,X$3,$D:$D,$R5)*100 -> 0 | Y5: =SUMIFS($L:$L,$C:$C,Y$3,$D:$D,$R5)*100 -> 0 | Z5: =SUMIFS($L:$L,$C:$C,Z$3,$D:$D,$R5)*100 -> 22.32 | AA5: =SUMIFS($L:$L,$C:$C,AA$3,$D:$D,$R5)*100 -> 26.04 | AB5: =SUMPRODUCT($T$4:$AA$4,T5:AA5) -> 20.47536 | AC5: =SUMIFS($L:$L,$C:$C,AC$3,$D:$D,$R5)*100 -> 0 | AD5: =SUMIFS($L:$L,$C:$C,AD$3,$D:$D,$R5)*100 -> 10.68 | AE5: =SUMIFS($L:$L,$C:$C,AE$3,$D:$D,$R5)*100 -> 9.79 | AF5: =SUMPRODUCT($AC$4:$AE$4,AC5:AE5) -> 6.5766329 | AH5: =AB5/100*$AL$6 -> 88340.784 | AI5: =AF5/100*$AL$23 -> 26002.104 | AN5: Recuperable | AP5: No recuperable | AU5: Amasadora | AW5: 130 | AX5: kg | AY5: 120x140x180 | AZ5: cm | BB5: kg | BC5: - | BD5: kw/h | BE5: 13000000
B6: Peso neto (g) | E6: 150 | R6: M006 | S6: SAL | T6: =SUMIFS($L:$L,$C:$C,T$3,$D:$D,$R6)*100 -> 0.465 | U6: =SUMIFS($L:$L,$C:$C,U$3,$D:$D,$R6)*100 -> 0.372 | V6: =SUMIFS($L:$L,$C:$C,V$3,$D:$D,$R6)*100 -> 0 | W6: =SUMIFS($L:$L,$C:$C,W$3,$D:$D,$R6)*100 -> 0 | X6: =SUMIFS($L:$L,$C:$C,X$3,$D:$D,$R6)*100 -> 1.395 | Y6: =SUMIFS($L:$L,$C:$C,Y$3,$D:$D,$R6)*100 -> 1.395 | Z6: =SUMIFS($L:$L,$C:$C,Z$3,$D:$D,$R6)*100 -> 0 | AA6: =SUMIFS($L:$L,$C:$C,AA$3,$D:$D,$R6)*100 -> 0.465 | AB6: =SUMPRODUCT($T$4:$AA$4,T6:AA6) -> 0.38365786 | AC6: =SUMIFS($L:$L,$C:$C,AC$3,$D:$D,$R6)*100 -> 0.85 | AD6: =SUMIFS($L:$L,$C:$C,AD$3,$D:$D,$R6)*100 -> 0.445 | AE6: =SUMIFS($L:$L,$C:$C,AE$3,$D:$D,$R6)*100 -> 0.267 | AF6: =SUMPRODUCT($AC$4:$AE$4,AC6:AE6) -> 0.56048417 | AH6: =AB6/100*$AL$6 -> 1655.2889 | AI6: =AF6/100*$AL$23 -> 2215.9923 | AK6: Amasado | AL6: =+AR6/(1-AN6-AP6) -> 431449.24 | AM6: 0 | AR6: =+AL7 -> 431449.24 | AS6: kg/año | AT6: =+AL6-AO6-AQ6 -> 431449.24 | AU6: Moldeadora | AX6: kg/h | AZ6: cm | BB6: kg | BC6: - | BD6: kw/h
B7: Rendim. (%) | E7: 0.88 | R7: M008 | S7: BICARBONATO DE AMONIO | T7: =SUMIFS($L:$L,$C:$C,T$3,$D:$D,$R7)*100 -> 0.465 | U7: =SUMIFS($L:$L,$C:$C,U$3,$D:$D,$R7)*100 -> 0 | V7: =SUMIFS($L:$L,$C:$C,V$3,$D:$D,$R7)*100 -> 0 | W7: =SUMIFS($L:$L,$C:$C,W$3,$D:$D,$R7)*100 -> 0 | X7: =SUMIFS($L:$L,$C:$C,X$3,$D:$D,$R7)*100 -> 0 | Y7: =SUMIFS($L:$L,$C:$C,Y$3,$D:$D,$R7)*100 -> 0 | Z7: =SUMIFS($L:$L,$C:$C,Z$3,$D:$D,$R7)*100 -> 1.395 | AA7: =SUMIFS($L:$L,$C:$C,AA$3,$D:$D,$R7)*100 -> 0.93 | AB7: =SUMPRODUCT($T$4:$AA$4,T7:AA7) -> 0.35693612 | AC7: =SUMIFS($L:$L,$C:$C,AC$3,$D:$D,$R7)*100 -> 0 | AD7: =SUMIFS($L:$L,$C:$C,AD$3,$D:$D,$R7)*100 -> 0 | AE7: =SUMIFS($L:$L,$C:$C,AE$3,$D:$D,$R7)*100 -> 0 | AF7: =SUMPRODUCT($AC$4:$AE$4,AC7:AE7) -> 0 | AH7: =AB7/100*$AL$6 -> 1539.9982 | AI7: =AF7/100*$AL$23 -> 0 | AK7: Moldeado | AL7: =+AR7/(1-AN7-AP7) -> 431449.24 | AM7: 0 | AN7: 0.01 | AO7: =+AN7*AL7 -> 4314.4924 | AP7: 0.01 | AQ7: =+AP7*AL7 -> 4314.4924 | AR7: =+AL8 -> 422820.25 | AS7: kg/año | AT7: =+AL7-AO7-AQ7 -> 422820.25 | AU7: Horno tunel | AX7: kg/h | AZ7: cm | BB7: kg | BC7: - | BD7: kw/h
B8: PT (kg) | E8: =E4*E5*E6/1000 -> 3 | R8: M022 | S8: GOMA XÁNTICA | T8: =SUMIFS($L:$L,$C:$C,T$3,$D:$D,$R8)*100 -> 0.744 | U8: =SUMIFS($L:$L,$C:$C,U$3,$D:$D,$R8)*100 -> 0.93 | V8: =SUMIFS($L:$L,$C:$C,V$3,$D:$D,$R8)*100 -> 0.93 | W8: =SUMIFS($L:$L,$C:$C,W$3,$D:$D,$R8)*100 -> 0.40176 | X8: =SUMIFS($L:$L,$C:$C,X$3,$D:$D,$R8)*100 -> 0.93 | Y8: =SUMIFS($L:$L,$C:$C,Y$3,$D:$D,$R8)*100 -> 0.93 | Z8: =SUMIFS($L:$L,$C:$C,Z$3,$D:$D,$R8)*100 -> 0.93 | AA8: =SUMIFS($L:$L,$C:$C,AA$3,$D:$D,$R8)*100 -> 0.93 | AB8: =SUMPRODUCT($T$4:$AA$4,T8:AA8) -> 0.73872566 | AC8: =SUMIFS($L:$L,$C:$C,AC$3,$D:$D,$R8)*100 -> 1.275 | AD8: =SUMIFS($L:$L,$C:$C,AD$3,$D:$D,$R8)*100 -> 0.89 | AE8: =SUMIFS($L:$L,$C:$C,AE$3,$D:$D,$R8)*100 -> 0.89 | AF8: =SUMPRODUCT($AC$4:$AE$4,AC8:AE8) -> 1.0318421 | AH8: =AB8/100*$AL$6 -> 3187.2262 | AI8: =AF8/100*$AL$23 -> 4079.605 | AK8: Horneado | AL8: =+AR8/(1-AN8-AP8) -> 422820.25 | AM8: 0 | AP8: 0.07 | AQ8: =+AP8*AL8 -> 29597.418 | AR8: =+AL9 -> 393222.84 | AS8: kg/año | AT8: =+AL8-AO8-AQ8 -> 393222.84 | AU8: Cinta de enfriamiento | AX8: kg/h | AZ8: cm | BB8: kg | BC8: - | BD8: kw/h
B9: Mezcla (kg) | E9: =E8/E7 -> 3.4090909 | R9: M028 | S9: PROPIONATO DE CALCIO | T9: =SUMIFS($L:$L,$C:$C,T$3,$D:$D,$R9)*100 -> 0 | U9: =SUMIFS($L:$L,$C:$C,U$3,$D:$D,$R9)*100 -> 0 | V9: =SUMIFS($L:$L,$C:$C,V$3,$D:$D,$R9)*100 -> 0 | W9: =SUMIFS($L:$L,$C:$C,W$3,$D:$D,$R9)*100 -> 0 | X9: =SUMIFS($L:$L,$C:$C,X$3,$D:$D,$R9)*100 -> 0 | Y9: =SUMIFS($L:$L,$C:$C,Y$3,$D:$D,$R9)*100 -> 0 | Z9: =SUMIFS($L:$L,$C:$C,Z$3,$D:$D,$R9)*100 -> 0.93 | AA9: =SUMIFS($L:$L,$C:$C,AA$3,$D:$D,$R9)*100 -> 0.93 | AB9: =SUMPRODUCT($T$4:$AA$4,T9:AA9) -> 0.1964786 | AC9: =SUMIFS($L:$L,$C:$C,AC$3,$D:$D,$R9)*100 -> 0 | AD9: =SUMIFS($L:$L,$C:$C,AD$3,$D:$D,$R9)*100 -> 0.89 | AE9: =SUMIFS($L:$L,$C:$C,AE$3,$D:$D,$R9)*100 -> 0.89 | AF9: =SUMPRODUCT($AC$4:$AE$4,AC9:AE9) -> 0.56210537 | AH9: =AB9/100*$AL$6 -> 847.70541 | AI9: =AF9/100*$AL$23 -> 2222.402 | AK9: Enfriado | AL9: =+AR9/(1-AN9-AP9) -> 393222.84 | AM9: 0 | AN9: 0.04 | AO9: =+AN9*AL9 -> 15728.913 | AP9: 0.01 | AQ9: =+AP9*AL9 -> 3932.2283 | AR9: =+AL10 -> 373561.69 | AS9: kg/año | AT9: =+AL9-AO9-AQ9 -> 373561.69 | AU9: Envasadora vertical | AX9: kg/h | AZ9: cm | BB9: kg | BC9: - | BD9: kw/h
