Workbook

Sheet Balance Inicial
A1: Balance al 31-07-2017
B2: $
A3: Disponibilidades en M/N | B3: 1200000
A4: Inversiones Transitorias | B4: =+B40 -> 133000 | C4: a
A5: Cuentas por Cobrar | B5: 350000
A6: Intereses a Devengar | B6: =+B103 -> 78000 | C6: d
A7: Cargos Diferidos | B7: =+D55 -> 575000 | C7: b
A8: Terrenos | B8: 800000
A9: Edificios | B9: 1400000
A10: Instalaciones | B10: 1000000
A11: Vehículos y Muebles | B11: 950000
A12: Amortizaciones Acumuladas | B12: =-H118 -> -481175 | C12: e
A13: IVA Crédito Fiscal | B13: 180000
A14: ACTIVO TOTAL | B14: =+SUM(B3:B13) -> 6184825 | C14: =SUM(B3:B13) -> 6184825
A15: Cuentas por Pagar | B15: 670000
A16: Provisiones | B16: =+C65 -> 190000 | C16: c
A17: Préstamos | B17: =+B101 -> 360000 | C17: d
A18: Intereses Documentados | B18: =+B102 -> 94380 | C18: d
A19: Previsión Despidos | B19: 210000
A20: Remuneraciones a Pagar | B20: 700000
A21: Cargas Sociales a Pagar | B21: 390000
A22: Provisión Impuesto a las Ganancias | B22: 70000
A23: IVA Débito Fiscal | B23: 400445
A24: Pasivo Exigible | B24: =+SUM(B15:B23) -> 3084825
A25: Capital Social | B25: 2500000
A26: Reservas | B26: 250000
A27: Utilidades | B27: =+B14-B24-B25-B26 -> 350000 | C27: f
A28: Patrimonio Neto | B28: =+SUM(B25:B27) -> 3100000
A29: PASIVO TOTAL | B29: =+B28+B24 -> 6184825
A33: El 10/7 hizo
A34: =1000*140 -> 140000
A37: =1000*(140-133) -> 7000
A38: El 31/7 hizo | B38: DC
B39: Por lo tanto el saldo de Inversiones Transitorias al 31 de Julio será
B40: =+A34-A37 -> 133000 | C40: o directamente 1.000 x 133
A44: =+A45*1.21 -> 1669800
A45: 1380000
A47: =+A45*0.21 -> 289800
A52: Y cada fin de mes
A53: =+A45/12 -> 115000 | B53: Seguros
...

Sheet Libro Diario
E1: LIBRO DIARIO
A2: Movimientos | E2: Asientos
I3: DEBE | J3: HABER
C7: =+'Balance Inicial'!B20 -> 700000 | E7: Rem a Pagar (P) | I7: =+C7 -> 700000
E8: CS a Pagar (P) | I8: =+C11 -> 390000
F9: a Disponibilidades (A) | J9: =+I7+I8 -> 1090000
C11: =+'Balance Inicial'!B21 -> 390000
E21: Cuenta por Cobrar (A) | I21: =+C23 -> 1028500
B22: =+B27*0.5*0.9*1.21 -> 925650 | E22: Disponibilidades (A) | I22: =+B22 -> 925650
C23: =+B27*0.5*1.21 -> 1028500 | E23: Descuento Pronto pago (R-) | I23: =+B24 -> 85000
B24: =+B27*0.5*0.1 -> 85000 | E24: IVA Crédito Fiscal (A) | I24: =+C26 -> 17850
C25: =+B27*0.21 -> 357000 | F25: a Ventas (R+) | J25: =+B27 -> 1700000
A26: Dto.P.Pago | C26: =+B24*0.21 -> 17850 | F26: IVA Débito Fiscal (P) | J26: =+C25 -> 357000
B27: 1700000 | I27: =SUM(I21:I26) -> 2057000 | J27: =SUM(J21:J26) -> 2057000
B30: Ventas
A31: A fin de mes devengar 1700000x0,5x0,12/12/30x(31-10) | E31: =+B27/2*(0.12/12)/30*(31-10) -> 5950
B35: 130000 | E35: Plazo Fijo (A) | I35: =+B35 -> 130000
F36: a Disponibilidades (A) | J36: =+I35 -> 130000
E38: Intereses P.Fijo (A) | I38: =+B39 -> 1950
B39: =+B35*0.18/12 -> 1950 | F39: a Int.a Devengar (P) | J39: =+I38 -> 1950
A45: Son 1.000 acciones a 147 que estaban en stock a 133, o sea:
E47: Disponibilidades en M/N (A) | I47: =+C51 -> 147000
B48: =+'Balance Inicial'!B40 -> 133000 | F48: a Inversiones Transitorias (A) | J48: =+B48 -> 133000
F49: Rendimiento Acciones (R+) | J49: =+C53 -> 14000
I50: =+SUM(I47:I49) -> 147000 | J50: =+SUM(J47:J49) -> 147000
C51: =+B48+C53 -> 147000
C53: =+(147-133)*1000 -> 14000
C55: Rendimiento Acciones
A60: Aj.Ej.Ant
B61: =+B65-184000 -> 6000 | E61: Provisiones (P) | I61: =+B65 -> 190000
E62: IVA CF (A) | I62: =+C63 -> 38640
C63: =184000*0.21 -> 38640 | F63: a Disponibilidades (A) | J63: =+C66 -> 222640
F64: Ajuste Ej.Anteriores (R+) | J64: =+B61 -> 6000
B65: =+'Balance Inicial'!B16 -> 190000 | I65: =SUM(I61:I64) -> 228640 | J65: =SUM(J61:J64) -> 228640
C66: =184000*1.21 -> 222640
B74: 70000 | E74: Préstamos al Personal (A) | I74: =+B74 -> 70000
F75: a Disponibilidades (A) | J75: =+B74 -> 70000
E83: Disponibilidades (A) | I83: =+C84 -> 72600
B84: =240000/5*4 -> 192000 | C84: =60000*1.21 -> 72600 | E84: Amortizaciones Acumuladas (P) | I84: =+B84 -> 192000
F85: a Bienes de Uso (A) | J85: =+B89 -> 240000
...

Sheet Hoja1
A1: Balance al 31-07-2017
B2: $
A3: Disponibilidades en M/N | B3: 1200000
A4: Inversiones Transitorias | B4: =1000*133 -> 133000 | E4: BIEN DE USO | F4: VO | G4: VU | H4: VR | I4: AA 31-12-16 | J4: Am Mens | K4: AA 31-07-17
A5: Cuentas por Cobrar | B5: 350000 | E5: TERRENOS | F5: 800000 | G5: - | H5: - | I5: -
A6: Intereses a Devengar | B6: =900000*0.26/12*4 -> 78000 | E6: EDIFICIOS | F6: 1400000 | G6: 25 | H6: 530000 | I6: 81000 | J6: =(F6-H6)/(G6*12) -> 2900 | K6: =I6+J6*7 -> 101300
A7: Cargos Diferidos | B7: =1380000/12*5 -> 575000 | E7: INSTALACIONES | F7: 1000000 | G7: 20 | H7: 610000 | I7: 135000 | J7: =(F7-H7)/(G7*12) -> 1625 | K7: =I7+J7*7 -> 146375
A8: Terrenos | B8: 800000 | E8: VEHICULOS Y MUEBLES | F8: 990000 | G8: 5 | I8: 118000 | J8: =(F8-H8)/(G8*12) -> 16500 | K8: =I8+J8*7 -> 233500
A9: Edificios | B9: 1400000 | F9: 4190000 | I9: 334000 | J9: =SUM(J6:J8) -> 21025 | K9: =SUM(K6:K8) -> 481175
A10: Instalaciones | B10: 1000000
A11: Vehículos y Muebles | B11: 950000
A12: Amortizaciones Acumuladas | B12: =-K9 -> -481175
A13: IVA Crédito Fiscal | B13: 180000
A14: ACTIVO TOTAL | B14: =+SUM(B3:B13) -> 6184825
A15: Cuentas por Pagar | B15: 670000
A16: Provisiones | B16: =190000 -> 190000
A17: Préstamos | B17: =900000/10*4 -> 360000
A18: Intereses Documentados | B18: =900000*0.26/12*4*1.21 -> 94380
A19: Previsión Despidos | B19: 210000
A20: Remuneraciones a Pagar | B20: 700000
A21: Cargas Sociales a Pagar | B21: 390000
A22: Provisión Impuesto a las Ganancias | B22: 70000
A23: IVA Débito Fiscal | B23: 400445
A24: Pasivo Exigible | B24: =+SUM(B15:B23) -> 3084825
A25: Capital Social | B25: 2500000
A26: Reservas | B26: 250000
A27: Utilidades | B27: =+B14-B24-B25-B26 -> 350000
A28: Patrimonio Neto | B28: =+SUM(B25:B27) -> 3100000
A29: PASIVO TOTAL | B29: =+B28+B24 -> 6184825
A32: =+A20 -> Remuneraciones a Pagar | B32: =+B20 -> 700000
A33: =+A21 -> Cargas Sociales a Pagar | B33: =+B21 -> 390000
A34: Disp | C34: =+B32+B33 -> 1090000
A37: CxC | B37: =C41*0.5*1.21 -> 1028500
A38: Disp | B38: =C41*0.5*0.9*1.21 -> 925650
A39: Dto PP R- | B39: =C41*0.5*0.1 -> 85000
A40: IVA CF | B40: =+B39*0.21 -> 17850
A41: Ventas R+ | C41: 1700000
A42: IVA DF | C42: =C41*0.21 -> 357000
A44: PF | B44: 130000
A45: Disp | C45: =+B44 -> 130000
...
